{
  "version": 8,
  "blockIdVersion": 11,
  "anchorX": 0,
  "anchorY": 0,
  "anchorZ": 0,
  "blocks": [
    {
      "x": -15,
      "y": 0,
      "z": -15,
      "name": "Soil_Gravel"
    },
    {
      "x": -15,
      "y": 0,
      "z": -14,
      "name": "Soil_Gravel"
    },
    {
      "x": -15,
      "y": 0,
      "z": -13,
      "name": "Soil_Gravel"
    },
    {
      "x": -15,
      "y": 0,
      "z": -12,
      "name": "Soil_Gravel"
    },
    {
      "x": -15,
      "y": 0,
      "z": -11,
      "name": "Soil_Gravel"
    },
    {
      "x": -15,
      "y": 0,
      "z": -10,
      "name": "Soil_Gravel"
    },
    {
      "x": -15,
      "y": 0,
      "z": -9,
      "name": "Wood_Softwood_Planks"
    },
    {
      "x": -15,
      "y": 0,
      "z": -8,
      "name": "Wood_Softwood_Planks"
    },
    {
      "x": -15,
      "y": 0,
      "z": -7,
      "name": "Wood_Softwood_Planks"
    },
    {
      "x": -15,
      "y": 0,
      "z": -6,
      "name": "Wood_Softwood_Planks"
    },
    {
      "x": -15,
      "y": 0,
      "z": -5,
      "name": "Wood_Softwood_Planks"
    },
    {
      "x": -15,
      "y": 0,
      "z": -4,
      "name": "Wood_Softwood_Planks"
    },
    {
      "x": -15,
      "y": 0,
      "z": -3,
      "name": "Wood_Softwood_Planks"
    },
    {
      "x": -15,
      "y": 0,
      "z": -2,
      "name": "Wood_Softwood_Planks"
    },
    {
      "x": -15,
      "y": 0,
      "z": -1,
      "name": "Wood_Softwood_Planks"
    },
    {
      "x": -15,
      "y": 0,
      "z": 0,
      "name": "Wood_Softwood_Planks"
    },
    {
      "x": -15,
      "y": 0,
      "z": 1,
      "name": "Wood_Softwood_Planks"
    },
    {
      "x": -15,
      "y": 0,
      "z": 2,
      "name": "Wood_Softwood_Planks"
    },
    {
      "x": -15,
      "y": 0,
      "z": 3,
      "name": "Wood_Softwood_Planks"
    },
    {
      "x": -15,
      "y": 0,
      "z": 4,
      "name": "Wood_Softwood_Planks"
    },
    {
      "x": -15,
      "y": 0,
      "z": 5,
      "name": "Wood_Softwood_Planks"
    },
    {
      "x": -15,
      "y": 0,
      "z": 6,
      "name": "Wood_Softwood_Planks"
    },
    {
      "x": -15,
      "y": 0,
      "z": 7,
      "name": "Wood_Softwood_Planks"
    },
    {
      "x": -15,
      "y": 0,
      "z": 8,
      "name": "Wood_Softwood_Planks"
    },
    {
      "x": -15,
      "y": 0,
      "z": 9,
      "name": "Wood_Softwood_Planks"
    },
    {
      "x": -15,
      "y": 0,
      "z": 10,
      "name": "Wood_Softwood_Planks"
    },
    {
      "x": -15,
      "y": 0,
      "z": 11,
      "name": "Wood_Softwood_Planks"
    },
    {
      "x": -15,
      "y": 0,
      "z": 12,
      "name": "Wood_Softwood_Planks"
    },
    {
      "x": -15,
      "y": 0,
      "z": 13,
      "name": "Wood_Softwood_Planks"
    },
    {
      "x": -15,
      "y": 0,
      "z": 14,
      "name": "Wood_Softwood_Planks"
    },
    {
      "x": -15,
      "y": 0,
      "z": 15,
      "name": "Wood_Softwood_Planks"
    },
    {
      "x": -15,
      "y": 0,
      "z": 16,
      "name": "Wood_Softwood_Planks"
    },
    {
      "x": -14,
      "y": 0,
      "z": -15,
      "name": "Soil_Gravel"
    },
    {
      "x": -14,
      "y": 0,
      "z": -14,
      "name": "Soil_Gravel"
    },
    {
      "x": -14,
      "y": 0,
      "z": -13,
      "name": "Soil_Gravel"
    },
    {
      "x": -14,
      "y": 0,
      "z": -12,
      "name": "Soil_Gravel"
    },
    {
      "x": -14,
      "y": 0,
      "z": -11,
      "name": "Soil_Gravel"
    },
    {
      "x": -14,
      "y": 0,
      "z": -10,
      "name": "Soil_Gravel"
    },
    {
      "x": -14,
      "y": 0,
      "z": -9,
      "name": "Wood_Softwood_Planks"
    },
    {
      "x": -14,
      "y": 0,
      "z": -8,
      "name": "Wood_Softwood_Planks"
    },
    {
      "x": -14,
      "y": 0,
      "z": -7,
      "name": "Wood_Softwood_Planks"
    },
    {
      "x": -14,
      "y": 0,
      "z": -6,
      "name": "Wood_Softwood_Planks"
    },
    {
      "x": -14,
      "y": 0,
      "z": -5,
      "name": "Wood_Softwood_Planks"
    },
    {
      "x": -14,
      "y": 0,
      "z": -4,
      "name": "Wood_Softwood_Planks"
    },
    {
      "x": -14,
      "y": 0,
      "z": -3,
      "name": "Wood_Softwood_Planks"
    },
    {
      "x": -14,
      "y": 0,
      "z": -2,
      "name": "Wood_Softwood_Planks"
    },
    {
      "x": -14,
      "y": 0,
      "z": -1,
      "name": "Wood_Softwood_Planks"
    },
    {
      "x": -14,
      "y": 0,
      "z": 0,
      "name": "Wood_Softwood_Planks"
    },
    {
      "x": -14,
      "y": 0,
      "z": 1,
      "name": "Wood_Softwood_Planks"
    },
    {
      "x": -14,
      "y": 0,
      "z": 2,
      "name": "Wood_Softwood_Planks"
    },
    {
      "x": -14,
      "y": 0,
      "z": 3,
      "name": "Wood_Softwood_Planks"
    },
    {
      "x": -14,
      "y": 0,
      "z": 4,
      "name": "Wood_Softwood_Planks"
    },
    {
      "x": -14,
      "y": 0,
      "z": 5,
      "name": "Wood_Softwood_Planks"
    },
    {
      "x": -14,
      "y": 0,
      "z": 6,
      "name": "Wood_Softwood_Planks"
    },
    {
      "x": -14,
      "y": 0,
      "z": 7,
      "name": "Wood_Softwood_Planks"
    },
    {
      "x": -14,
      "y": 0,
      "z": 8,
      "name": "Wood_Softwood_Planks"
    },
    {
      "x": -14,
      "y": 0,
      "z": 9,
      "name": "Wood_Softwood_Planks"
    },
    {
      "x": -14,
      "y": 0,
      "z": 10,
      "name": "Wood_Softwood_Planks"
    },
    {
      "x": -14,
      "y": 0,
      "z": 11,
      "name": "Wood_Softwood_Planks"
    },
    {
      "x": -14,
      "y": 0,
      "z": 12,
      "name": "Wood_Softwood_Planks"
    },
    {
      "x": -14,
      "y": 0,
      "z": 13,
      "name": "Wood_Softwood_Planks"
    },
    {
      "x": -14,
      "y": 0,
      "z": 14,
      "name": "Wood_Softwood_Planks"
    },
    {
      "x": -14,
      "y": 0,
      "z": 15,
      "name": "Wood_Softwood_Planks"
    },
    {
      "x": -14,
      "y": 0,
      "z": 16,
      "name": "Wood_Softwood_Planks"
    },
    {
      "x": -13,
      "y": 0,
      "z": -15,
      "name": "Soil_Gravel"
    },
    {
      "x": -13,
      "y": 0,
      "z": -14,
      "name": "Soil_Gravel"
    },
    {
      "x": -13,
      "y": 0,
      "z": -13,
      "name": "Soil_Gravel"
    },
    {
      "x": -13,
      "y": 0,
      "z": -12,
      "name": "Soil_Gravel"
    },
    {
      "x": -13,
      "y": 0,
      "z": -11,
      "name": "Soil_Gravel"
    },
    {
      "x": -13,
      "y": 0,
      "z": -10,
      "name": "Soil_Gravel"
    },
    {
      "x": -13,
      "y": 0,
      "z": -9,
      "name": "Wood_Softwood_Planks"
    },
    {
      "x": -13,
      "y": 0,
      "z": -8,
      "name": "Wood_Softwood_Planks"
    },
    {
      "x": -13,
      "y": 0,
      "z": -7,
      "name": "Wood_Softwood_Planks"
    },
    {
      "x": -13,
      "y": 0,
      "z": -6,
      "name": "Wood_Softwood_Planks"
    },
    {
      "x": -13,
      "y": 0,
      "z": -5,
      "name": "Wood_Softwood_Planks"
    },
    {
      "x": -13,
      "y": 0,
      "z": -4,
      "name": "Wood_Softwood_Planks"
    },
    {
      "x": -13,
      "y": 0,
      "z": -3,
      "name": "Wood_Softwood_Planks"
    },
    {
      "x": -13,
      "y": 0,
      "z": -2,
      "name": "Wood_Softwood_Planks"
    },
    {
      "x": -13,
      "y": 0,
      "z": -1,
      "name": "Wood_Softwood_Planks"
    },
    {
      "x": -13,
      "y": 0,
      "z": 0,
      "name": "Wood_Softwood_Planks"
    },
    {
      "x": -13,
      "y": 0,
      "z": 1,
      "name": "Wood_Softwood_Planks"
    },
    {
      "x": -13,
      "y": 0,
      "z": 2,
      "name": "Wood_Softwood_Planks"
    },
    {
      "x": -13,
      "y": 0,
      "z": 3,
      "name": "Wood_Softwood_Planks"
    },
    {
      "x": -13,
      "y": 0,
      "z": 4,
      "name": "Wood_Softwood_Planks"
    },
    {
      "x": -13,
      "y": 0,
      "z": 5,
      "name": "Wood_Softwood_Planks"
    },
    {
      "x": -13,
      "y": 0,
      "z": 6,
      "name": "Wood_Softwood_Planks"
    },
    {
      "x": -13,
      "y": 0,
      "z": 7,
      "name": "Wood_Softwood_Planks"
    },
    {
      "x": -13,
      "y": 0,
      "z": 8,
      "name": "Wood_Softwood_Planks"
    },
    {
      "x": -13,
      "y": 0,
      "z": 9,
      "name": "Wood_Softwood_Planks"
    },
    {
      "x": -13,
      "y": 0,
      "z": 10,
      "name": "Wood_Softwood_Planks"
    },
    {
      "x": -13,
      "y": 0,
      "z": 11,
      "name": "Wood_Softwood_Planks"
    },
    {
      "x": -13,
      "y": 0,
      "z": 12,
      "name": "Wood_Softwood_Planks"
    },
    {
      "x": -13,
      "y": 0,
      "z": 13,
      "name": "Wood_Softwood_Planks"
    },
    {
      "x": -13,
      "y": 0,
      "z": 14,
      "name": "Wood_Softwood_Planks"
    },
    {
      "x": -13,
      "y": 0,
      "z": 15,
      "name": "Wood_Softwood_Planks"
    },
    {
      "x": -13,
      "y": 0,
      "z": 16,
      "name": "Wood_Softwood_Planks"
    },
    {
      "x": -12,
      "y": 0,
      "z": -15,
      "name": "Soil_Gravel"
    },
    {
      "x": -12,
      "y": 0,
      "z": -14,
      "name": "Soil_Gravel"
    },
    {
      "x": -12,
      "y": 0,
      "z": -13,
      "name": "Soil_Gravel"
    },
    {
      "x": -12,
      "y": 0,
      "z": -12,
      "name": "Soil_Gravel"
    },
    {
      "x": -12,
      "y": 0,
      "z": -11,
      "name": "Soil_Gravel"
    },
    {
      "x": -12,
      "y": 0,
      "z": -10,
      "name": "Soil_Gravel"
    },
    {
      "x": -12,
      "y": 0,
      "z": -9,
      "name": "Wood_Softwood_Planks"
    },
    {
      "x": -12,
      "y": 0,
      "z": -8,
      "name": "Wood_Softwood_Planks"
    },
    {
      "x": -12,
      "y": 0,
      "z": -7,
      "name": "Wood_Softwood_Planks"
    },
    {
      "x": -12,
      "y": 0,
      "z": -6,
      "name": "Wood_Softwood_Planks"
    },
    {
      "x": -12,
      "y": 0,
      "z": -5,
      "name": "Wood_Softwood_Planks"
    },
    {
      "x": -12,
      "y": 0,
      "z": -4,
      "name": "Wood_Softwood_Planks"
    },
    {
      "x": -12,
      "y": 0,
      "z": -3,
      "name": "Wood_Softwood_Planks"
    },
    {
      "x": -12,
      "y": 0,
      "z": -2,
      "name": "Wood_Softwood_Planks"
    },
    {
      "x": -12,
      "y": 0,
      "z": -1,
      "name": "Wood_Softwood_Planks"
    },
    {
      "x": -12,
      "y": 0,
      "z": 0,
      "name": "Wood_Softwood_Planks"
    },
    {
      "x": -12,
      "y": 0,
      "z": 1,
      "name": "Wood_Softwood_Planks"
    },
    {
      "x": -12,
      "y": 0,
      "z": 2,
      "name": "Wood_Softwood_Planks"
    },
    {
      "x": -12,
      "y": 0,
      "z": 3,
      "name": "Wood_Softwood_Planks"
    },
    {
      "x": -12,
      "y": 0,
      "z": 4,
      "name": "Wood_Softwood_Planks"
    },
    {
      "x": -12,
      "y": 0,
      "z": 5,
      "name": "Wood_Softwood_Planks"
    },
    {
      "x": -12,
      "y": 0,
      "z": 6,
      "name": "Wood_Softwood_Planks"
    },
    {
      "x": -12,
      "y": 0,
      "z": 7,
      "name": "Wood_Softwood_Planks"
    },
    {
      "x": -12,
      "y": 0,
      "z": 8,
      "name": "Wood_Softwood_Planks"
    },
    {
      "x": -12,
      "y": 0,
      "z": 9,
      "name": "Wood_Softwood_Planks"
    },
    {
      "x": -12,
      "y": 0,
      "z": 10,
      "name": "Wood_Softwood_Planks"
    },
    {
      "x": -12,
      "y": 0,
      "z": 11,
      "name": "Wood_Softwood_Planks"
    },
    {
      "x": -12,
      "y": 0,
      "z": 12,
      "name": "Wood_Softwood_Planks"
    },
    {
      "x": -12,
      "y": 0,
      "z": 13,
      "name": "Wood_Softwood_Planks"
    },
    {
      "x": -12,
      "y": 0,
      "z": 14,
      "name": "Wood_Softwood_Planks"
    },
    {
      "x": -12,
      "y": 0,
      "z": 15,
      "name": "Wood_Softwood_Planks"
    },
    {
      "x": -12,
      "y": 0,
      "z": 16,
      "name": "Wood_Softwood_Planks"
    },
    {
      "x": -11,
      "y": 0,
      "z": -15,
      "name": "Soil_Gravel"
    },
    {
      "x": -11,
      "y": 0,
      "z": -14,
      "name": "Soil_Gravel"
    },
    {
      "x": -11,
      "y": 0,
      "z": -13,
      "name": "Soil_Gravel"
    },
    {
      "x": -11,
      "y": 0,
      "z": -12,
      "name": "Soil_Gravel"
    },
    {
      "x": -11,
      "y": 0,
      "z": -11,
      "name": "Soil_Gravel"
    },
    {
      "x": -11,
      "y": 0,
      "z": -10,
      "name": "Soil_Gravel"
    },
    {
      "x": -11,
      "y": 0,
      "z": -9,
      "name": "Wood_Softwood_Planks"
    },
    {
      "x": -11,
      "y": 0,
      "z": -8,
      "name": "Wood_Softwood_Planks"
    },
    {
      "x": -11,
      "y": 0,
      "z": -7,
      "name": "Wood_Softwood_Planks"
    },
    {
      "x": -11,
      "y": 0,
      "z": -6,
      "name": "Wood_Softwood_Planks"
    },
    {
      "x": -11,
      "y": 0,
      "z": -5,
      "name": "Wood_Softwood_Planks"
    },
    {
      "x": -11,
      "y": 0,
      "z": -4,
      "name": "Wood_Softwood_Planks"
    },
    {
      "x": -11,
      "y": 0,
      "z": -3,
      "name": "Wood_Softwood_Planks"
    },
    {
      "x": -11,
      "y": 0,
      "z": -2,
      "name": "Wood_Softwood_Planks"
    },
    {
      "x": -11,
      "y": 0,
      "z": -1,
      "name": "Wood_Softwood_Planks"
    },
    {
      "x": -11,
      "y": 0,
      "z": 0,
      "name": "Wood_Softwood_Planks"
    },
    {
      "x": -11,
      "y": 0,
      "z": 1,
      "name": "Wood_Softwood_Planks"
    },
    {
      "x": -11,
      "y": 0,
      "z": 2,
      "name": "Wood_Softwood_Planks"
    },
    {
      "x": -11,
      "y": 0,
      "z": 3,
      "name": "Wood_Softwood_Planks"
    },
    {
      "x": -11,
      "y": 0,
      "z": 4,
      "name": "Wood_Softwood_Planks"
    },
    {
      "x": -11,
      "y": 0,
      "z": 5,
      "name": "Wood_Softwood_Planks"
    },
    {
      "x": -11,
      "y": 0,
      "z": 6,
      "name": "Wood_Softwood_Planks"
    },
    {
      "x": -11,
      "y": 0,
      "z": 7,
      "name": "Wood_Softwood_Planks"
    },
    {
      "x": -11,
      "y": 0,
      "z": 8,
      "name": "Wood_Softwood_Planks"
    },
    {
      "x": -11,
      "y": 0,
      "z": 9,
      "name": "Wood_Softwood_Planks"
    },
    {
      "x": -11,
      "y": 0,
      "z": 10,
      "name": "Wood_Softwood_Planks"
    },
    {
      "x": -11,
      "y": 0,
      "z": 11,
      "name": "Wood_Softwood_Planks"
    },
    {
      "x": -11,
      "y": 0,
      "z": 12,
      "name": "Wood_Softwood_Planks"
    },
    {
      "x": -11,
      "y": 0,
      "z": 13,
      "name": "Wood_Softwood_Planks"
    },
    {
      "x": -11,
      "y": 0,
      "z": 14,
      "name": "Wood_Softwood_Planks"
    },
    {
      "x": -11,
      "y": 0,
      "z": 15,
      "name": "Wood_Softwood_Planks"
    },
    {
      "x": -11,
      "y": 0,
      "z": 16,
      "name": "Wood_Softwood_Planks"
    },
    {
      "x": -10,
      "y": 0,
      "z": -15,
      "name": "Soil_Gravel"
    },
    {
      "x": -10,
      "y": 0,
      "z": -14,
      "name": "Soil_Gravel"
    },
    {
      "x": -10,
      "y": 0,
      "z": -13,
      "name": "Soil_Gravel"
    },
    {
      "x": -10,
      "y": 0,
      "z": -12,
      "name": "Soil_Gravel"
    },
    {
      "x": -10,
      "y": 0,
      "z": -11,
      "name": "Soil_Gravel"
    },
    {
      "x": -10,
      "y": 0,
      "z": -10,
      "name": "Soil_Gravel"
    },
    {
      "x": -10,
      "y": 0,
      "z": -9,
      "name": "Wood_Softwood_Planks"
    },
    {
      "x": -10,
      "y": 0,
      "z": -8,
      "name": "Wood_Softwood_Planks"
    },
    {
      "x": -10,
      "y": 0,
      "z": -7,
      "name": "Wood_Softwood_Planks"
    },
    {
      "x": -10,
      "y": 0,
      "z": -6,
      "name": "Wood_Softwood_Planks"
    },
    {
      "x": -10,
      "y": 0,
      "z": -5,
      "name": "Wood_Softwood_Planks"
    },
    {
      "x": -10,
      "y": 0,
      "z": -4,
      "name": "Wood_Softwood_Planks"
    },
    {
      "x": -10,
      "y": 0,
      "z": -3,
      "name": "Wood_Softwood_Planks"
    },
    {
      "x": -10,
      "y": 0,
      "z": -2,
      "name": "Soil_Clay"
    },
    {
      "x": -10,
      "y": 1,
      "z": -2,
      "name": "*Wood_Hardwood_Fence_State_Definitions_Corner",
      "rotation": 1
    },
    {
      "x": -10,
      "y": 2,
      "z": -2,
      "name": "*Wood_Hardwood_Fence_State_Definitions_Corner",
      "rotation": 1
    },
    {
      "x": -10,
      "y": 0,
      "z": -1,
      "name": "Soil_Clay"
    },
    {
      "x": -10,
      "y": 1,
      "z": -1,
      "name": "Wood_Hardwood_Fence",
      "rotation": 1
    },
    {
      "x": -10,
      "y": 2,
      "z": -1,
      "name": "Wood_Hardwood_Fence",
      "rotation": 1
    },
    {
      "x": -10,
      "y": 0,
      "z": 0,
      "name": "Soil_Clay"
    },
    {
      "x": -10,
      "y": 1,
      "z": 0,
      "name": "Wood_Hardwood_Fence",
      "rotation": 1
    },
    {
      "x": -10,
      "y": 2,
      "z": 0,
      "name": "Wood_Hardwood_Fence",
      "rotation": 1
    },
    {
      "x": -10,
      "y": 0,
      "z": 1,
      "name": "Soil_Clay"
    },
    {
      "x": -10,
      "y": 1,
      "z": 1,
      "name": "Wood_Hardwood_Fence",
      "rotation": 1
    },
    {
      "x": -10,
      "y": 2,
      "z": 1,
      "name": "Wood_Hardwood_Fence",
      "rotation": 1
    },
    {
      "x": -10,
      "y": 0,
      "z": 2,
      "name": "Soil_Clay"
    },
    {
      "x": -10,
      "y": 1,
      "z": 2,
      "name": "Wood_Hardwood_Fence",
      "rotation": 1
    },
    {
      "x": -10,
      "y": 2,
      "z": 2,
      "name": "Wood_Hardwood_Fence",
      "rotation": 1
    },
    {
      "x": -10,
      "y": 0,
      "z": 3,
      "name": "Soil_Clay"
    },
    {
      "x": -10,
      "y": 1,
      "z": 3,
      "name": "Wood_Hardwood_Fence",
      "rotation": 1
    },
    {
      "x": -10,
      "y": 2,
      "z": 3,
      "name": "Wood_Hardwood_Fence",
      "rotation": 1
    },
    {
      "x": -10,
      "y": 0,
      "z": 4,
      "name": "Soil_Clay"
    },
    {
      "x": -10,
      "y": 1,
      "z": 4,
      "name": "Wood_Hardwood_Fence",
      "rotation": 1
    },
    {
      "x": -10,
      "y": 2,
      "z": 4,
      "name": "Wood_Hardwood_Fence",
      "rotation": 1
    },
    {
      "x": -10,
      "y": 0,
      "z": 5,
      "name": "Soil_Clay"
    },
    {
      "x": -10,
      "y": 1,
      "z": 5,
      "name": "Wood_Hardwood_Fence",
      "rotation": 1
    },
    {
      "x": -10,
      "y": 2,
      "z": 5,
      "name": "Wood_Hardwood_Fence",
      "rotation": 1
    },
    {
      "x": -10,
      "y": 0,
      "z": 6,
      "name": "Soil_Clay"
    },
    {
      "x": -10,
      "y": 1,
      "z": 6,
      "name": "*Wood_Hardwood_Fence_State_Definitions_Corner",
      "rotation": 2
    },
    {
      "x": -10,
      "y": 2,
      "z": 6,
      "name": "*Wood_Hardwood_Fence_State_Definitions_Corner",
      "rotation": 2
    },
    {
      "x": -10,
      "y": 0,
      "z": 7,
      "name": "Wood_Softwood_Planks"
    },
    {
      "x": -10,
      "y": 0,
      "z": 8,
      "name": "Wood_Softwood_Planks"
    },
    {
      "x": -10,
      "y": 0,
      "z": 9,
      "name": "Wood_Softwood_Planks"
    },
    {
      "x": -10,
      "y": 0,
      "z": 10,
      "name": "Wood_Softwood_Planks"
    },
    {
      "x": -10,
      "y": 0,
      "z": 11,
      "name": "Wood_Softwood_Planks"
    },
    {
      "x": -10,
      "y": 0,
      "z": 12,
      "name": "Wood_Softwood_Planks"
    },
    {
      "x": -10,
      "y": 0,
      "z": 13,
      "name": "Wood_Softwood_Planks"
    },
    {
      "x": -10,
      "y": 0,
      "z": 14,
      "name": "Wood_Softwood_Planks"
    },
    {
      "x": -10,
      "y": 0,
      "z": 15,
      "name": "Wood_Softwood_Planks"
    },
    {
      "x": -10,
      "y": 0,
      "z": 16,
      "name": "Wood_Softwood_Planks"
    },
    {
      "x": -9,
      "y": 0,
      "z": -15,
      "name": "Soil_Gravel"
    },
    {
      "x": -9,
      "y": 0,
      "z": -14,
      "name": "Soil_Gravel"
    },
    {
      "x": -9,
      "y": 0,
      "z": -13,
      "name": "Soil_Gravel"
    },
    {
      "x": -9,
      "y": 0,
      "z": -12,
      "name": "Soil_Gravel"
    },
    {
      "x": -9,
      "y": 0,
      "z": -11,
      "name": "Soil_Gravel"
    },
    {
      "x": -9,
      "y": 0,
      "z": -10,
      "name": "Soil_Gravel"
    },
    {
      "x": -9,
      "y": 0,
      "z": -9,
      "name": "Wood_Softwood_Planks"
    },
    {
      "x": -9,
      "y": 0,
      "z": -8,
      "name": "Wood_Softwood_Planks"
    },
    {
      "x": -9,
      "y": 0,
      "z": -7,
      "name": "Wood_Softwood_Planks"
    },
    {
      "x": -9,
      "y": 0,
      "z": -6,
      "name": "Wood_Softwood_Planks"
    },
    {
      "x": -9,
      "y": 0,
      "z": -5,
      "name": "Wood_Softwood_Planks"
    },
    {
      "x": -9,
      "y": 0,
      "z": -4,
      "name": "Wood_Softwood_Planks"
    },
    {
      "x": -9,
      "y": 0,
      "z": -3,
      "name": "Wood_Softwood_Planks"
    },
    {
      "x": -9,
      "y": 0,
      "z": -2,
      "name": "Soil_Clay"
    },
    {
      "x": -9,
      "y": 1,
      "z": -2,
      "name": "Wood_Hardwood_Fence"
    },
    {
      "x": -9,
      "y": 2,
      "z": -2,
      "name": "Wood_Hardwood_Fence"
    },
    {
      "x": -9,
      "y": 0,
      "z": -1,
      "name": "Soil_Clay"
    },
    {
      "x": -9,
      "y": 0,
      "z": 0,
      "name": "Soil_Clay"
    },
    {
      "x": -9,
      "y": 0,
      "z": 1,
      "name": "Soil_Clay"
    },
    {
      "x": -9,
      "y": 0,
      "z": 2,
      "name": "Soil_Clay"
    },
    {
      "x": -9,
      "y": 0,
      "z": 3,
      "name": "Soil_Clay"
    },
    {
      "x": -9,
      "y": 0,
      "z": 4,
      "name": "Soil_Clay"
    },
    {
      "x": -9,
      "y": 0,
      "z": 5,
      "name": "Soil_Clay"
    },
    {
      "x": -9,
      "y": 0,
      "z": 6,
      "name": "Soil_Clay"
    },
    {
      "x": -9,
      "y": 1,
      "z": 6,
      "name": "Wood_Hardwood_Fence",
      "rotation": 2
    },
    {
      "x": -9,
      "y": 2,
      "z": 6,
      "name": "Wood_Hardwood_Fence",
      "rotation": 2
    },
    {
      "x": -9,
      "y": 0,
      "z": 7,
      "name": "Wood_Softwood_Planks"
    },
    {
      "x": -9,
      "y": 0,
      "z": 8,
      "name": "Wood_Softwood_Planks"
    },
    {
      "x": -9,
      "y": 0,
      "z": 9,
      "name": "Wood_Softwood_Planks"
    },
    {
      "x": -9,
      "y": 0,
      "z": 10,
      "name": "Wood_Softwood_Planks"
    },
    {
      "x": -9,
      "y": 0,
      "z": 11,
      "name": "Wood_Softwood_Planks"
    },
    {
      "x": -9,
      "y": 0,
      "z": 12,
      "name": "Wood_Softwood_Planks"
    },
    {
      "x": -9,
      "y": 0,
      "z": 13,
      "name": "Wood_Softwood_Planks"
    },
    {
      "x": -9,
      "y": 0,
      "z": 14,
      "name": "Wood_Softwood_Planks"
    },
    {
      "x": -9,
      "y": 0,
      "z": 15,
      "name": "Wood_Softwood_Planks"
    },
    {
      "x": -9,
      "y": 0,
      "z": 16,
      "name": "Wood_Softwood_Planks"
    },
    {
      "x": -8,
      "y": 0,
      "z": -15,
      "name": "Soil_Gravel"
    },
    {
      "x": -8,
      "y": 0,
      "z": -14,
      "name": "Soil_Gravel"
    },
    {
      "x": -8,
      "y": 0,
      "z": -13,
      "name": "Soil_Gravel"
    },
    {
      "x": -8,
      "y": 0,
      "z": -12,
      "name": "Soil_Gravel"
    },
    {
      "x": -8,
      "y": 0,
      "z": -11,
      "name": "Soil_Gravel"
    },
    {
      "x": -8,
      "y": 0,
      "z": -10,
      "name": "Soil_Gravel"
    },
    {
      "x": -8,
      "y": 0,
      "z": -9,
      "name": "Wood_Softwood_Planks"
    },
    {
      "x": -8,
      "y": 0,
      "z": -8,
      "name": "Wood_Softwood_Planks"
    },
    {
      "x": -8,
      "y": 0,
      "z": -7,
      "name": "Wood_Softwood_Planks"
    },
    {
      "x": -8,
      "y": 0,
      "z": -6,
      "name": "Wood_Softwood_Planks"
    },
    {
      "x": -8,
      "y": 0,
      "z": -5,
      "name": "Wood_Softwood_Planks"
    },
    {
      "x": -8,
      "y": 0,
      "z": -4,
      "name": "Wood_Softwood_Planks"
    },
    {
      "x": -8,
      "y": 0,
      "z": -3,
      "name": "Wood_Softwood_Planks"
    },
    {
      "x": -8,
      "y": 0,
      "z": -2,
      "name": "Soil_Clay"
    },
    {
      "x": -8,
      "y": 1,
      "z": -2,
      "name": "Wood_Hardwood_Fence"
    },
    {
      "x": -8,
      "y": 2,
      "z": -2,
      "name": "Wood_Hardwood_Fence"
    },
    {
      "x": -8,
      "y": 4,
      "z": -2,
      "name": "Wood_Ash_Trunk",
      "rotation": 5
    },
    {
      "x": -8,
      "y": 0,
      "z": -1,
      "name": "Soil_Clay"
    },
    {
      "x": -8,
      "y": 0,
      "z": 0,
      "name": "Soil_Clay"
    },
    {
      "x": -8,
      "y": 0,
      "z": 1,
      "name": "Soil_Clay"
    },
    {
      "x": -8,
      "y": 0,
      "z": 2,
      "name": "Soil_Clay"
    },
    {
      "x": -8,
      "y": 0,
      "z": 3,
      "name": "Soil_Clay"
    },
    {
      "x": -8,
      "y": 0,
      "z": 4,
      "name": "Soil_Clay"
    },
    {
      "x": -8,
      "y": 0,
      "z": 5,
      "name": "Soil_Clay"
    },
    {
      "x": -8,
      "y": 0,
      "z": 6,
      "name": "Soil_Clay"
    },
    {
      "x": -8,
      "y": 1,
      "z": 6,
      "name": "Wood_Hardwood_Fence",
      "rotation": 2
    },
    {
      "x": -8,
      "y": 2,
      "z": 6,
      "name": "Wood_Hardwood_Fence",
      "rotation": 2
    },
    {
      "x": -8,
      "y": 4,
      "z": 6,
      "name": "Wood_Ash_Trunk",
      "rotation": 5
    },
    {
      "x": -8,
      "y": 0,
      "z": 7,
      "name": "Wood_Softwood_Planks"
    },
    {
      "x": -8,
      "y": 0,
      "z": 8,
      "name": "Wood_Softwood_Planks"
    },
    {
      "x": -8,
      "y": 0,
      "z": 9,
      "name": "Wood_Softwood_Planks"
    },
    {
      "x": -8,
      "y": 0,
      "z": 10,
      "name": "Wood_Softwood_Planks"
    },
    {
      "x": -8,
      "y": 0,
      "z": 11,
      "name": "Wood_Softwood_Planks"
    },
    {
      "x": -8,
      "y": 0,
      "z": 12,
      "name": "Wood_Softwood_Planks"
    },
    {
      "x": -8,
      "y": 0,
      "z": 13,
      "name": "Wood_Softwood_Planks"
    },
    {
      "x": -8,
      "y": 0,
      "z": 14,
      "name": "Wood_Softwood_Planks"
    },
    {
      "x": -8,
      "y": 0,
      "z": 15,
      "name": "Wood_Softwood_Planks"
    },
    {
      "x": -8,
      "y": 0,
      "z": 16,
      "name": "Wood_Softwood_Planks"
    },
    {
      "x": -7,
      "y": 0,
      "z": -15,
      "name": "Soil_Gravel"
    },
    {
      "x": -7,
      "y": 0,
      "z": -14,
      "name": "Soil_Gravel"
    },
    {
      "x": -7,
      "y": 0,
      "z": -13,
      "name": "Soil_Gravel"
    },
    {
      "x": -7,
      "y": 0,
      "z": -12,
      "name": "Soil_Gravel"
    },
    {
      "x": -7,
      "y": 0,
      "z": -11,
      "name": "Soil_Gravel"
    },
    {
      "x": -7,
      "y": 0,
      "z": -10,
      "name": "Soil_Gravel"
    },
    {
      "x": -7,
      "y": 0,
      "z": -9,
      "name": "Wood_Softwood_Planks"
    },
    {
      "x": -7,
      "y": 0,
      "z": -8,
      "name": "Wood_Softwood_Planks"
    },
    {
      "x": -7,
      "y": 0,
      "z": -7,
      "name": "Wood_Softwood_Planks"
    },
    {
      "x": -7,
      "y": 0,
      "z": -6,
      "name": "Wood_Softwood_Planks"
    },
    {
      "x": -7,
      "y": 0,
      "z": -5,
      "name": "Wood_Softwood_Planks"
    },
    {
      "x": -7,
      "y": 0,
      "z": -4,
      "name": "Wood_Softwood_Planks"
    },
    {
      "x": -7,
      "y": 0,
      "z": -3,
      "name": "Wood_Softwood_Planks"
    },
    {
      "x": -7,
      "y": 0,
      "z": -2,
      "name": "Soil_Clay"
    },
    {
      "x": -7,
      "y": 1,
      "z": -2,
      "name": "Wood_Ash_Trunk_Full"
    },
    {
      "x": -7,
      "y": 2,
      "z": -2,
      "name": "Wood_Ash_Trunk_Full"
    },
    {
      "x": -7,
      "y": 3,
      "z": -2,
      "name": "Wood_Ash_Trunk_Full"
    },
    {
      "x": -7,
      "y": 4,
      "z": -2,
      "name": "Wood_Ash_Trunk_Full",
      "rotation": 5
    },
    {
      "x": -7,
      "y": 0,
      "z": -1,
      "name": "Soil_Clay"
    },
    {
      "x": -7,
      "y": 0,
      "z": 0,
      "name": "Soil_Clay"
    },
    {
      "x": -7,
      "y": 0,
      "z": 1,
      "name": "Plant_Crop_Mushroom_Block_Brown"
    },
    {
      "x": -7,
      "y": 0,
      "z": 2,
      "name": "Plant_Crop_Mushroom_Block_Brown"
    },
    {
      "x": -7,
      "y": 0,
      "z": 3,
      "name": "Plant_Crop_Mushroom_Block_Brown"
    },
    {
      "x": -7,
      "y": 0,
      "z": 4,
      "name": "Soil_Clay"
    },
    {
      "x": -7,
      "y": 0,
      "z": 5,
      "name": "Soil_Clay"
    },
    {
      "x": -7,
      "y": 0,
      "z": 6,
      "name": "Soil_Clay"
    },
    {
      "x": -7,
      "y": 1,
      "z": 6,
      "name": "Wood_Ash_Trunk_Full"
    },
    {
      "x": -7,
      "y": 2,
      "z": 6,
      "name": "Wood_Ash_Trunk_Full"
    },
    {
      "x": -7,
      "y": 3,
      "z": 6,
      "name": "Wood_Ash_Trunk_Full"
    },
    {
      "x": -7,
      "y": 4,
      "z": 6,
      "name": "Wood_Ash_Trunk_Full",
      "rotation": 5
    },
    {
      "x": -7,
      "y": 0,
      "z": 7,
      "name": "Wood_Softwood_Planks"
    },
    {
      "x": -7,
      "y": 0,
      "z": 8,
      "name": "Wood_Softwood_Planks"
    },
    {
      "x": -7,
      "y": 0,
      "z": 9,
      "name": "Wood_Softwood_Planks"
    },
    {
      "x": -7,
      "y": 0,
      "z": 10,
      "name": "Wood_Softwood_Planks"
    },
    {
      "x": -7,
      "y": 0,
      "z": 11,
      "name": "Wood_Softwood_Planks"
    },
    {
      "x": -7,
      "y": 0,
      "z": 12,
      "name": "Wood_Softwood_Planks"
    },
    {
      "x": -7,
      "y": 0,
      "z": 13,
      "name": "Wood_Softwood_Planks"
    },
    {
      "x": -7,
      "y": 0,
      "z": 14,
      "name": "Wood_Softwood_Planks"
    },
    {
      "x": -7,
      "y": 0,
      "z": 15,
      "name": "Wood_Softwood_Planks"
    },
    {
      "x": -7,
      "y": 0,
      "z": 16,
      "name": "Wood_Softwood_Planks"
    },
    {
      "x": -6,
      "y": 0,
      "z": -15,
      "name": "Soil_Gravel"
    },
    {
      "x": -6,
      "y": 0,
      "z": -14,
      "name": "Soil_Gravel"
    },
    {
      "x": -6,
      "y": 0,
      "z": -13,
      "name": "Soil_Gravel"
    },
    {
      "x": -6,
      "y": 0,
      "z": -12,
      "name": "Soil_Gravel"
    },
    {
      "x": -6,
      "y": 0,
      "z": -11,
      "name": "Soil_Gravel"
    },
    {
      "x": -6,
      "y": 0,
      "z": -10,
      "name": "Soil_Gravel"
    },
    {
      "x": -6,
      "y": 0,
      "z": -9,
      "name": "Wood_Softwood_Planks"
    },
    {
      "x": -6,
      "y": 0,
      "z": -8,
      "name": "Wood_Softwood_Planks"
    },
    {
      "x": -6,
      "y": 0,
      "z": -7,
      "name": "Wood_Softwood_Planks"
    },
    {
      "x": -6,
      "y": 0,
      "z": -6,
      "name": "Wood_Softwood_Planks"
    },
    {
      "x": -6,
      "y": 0,
      "z": -5,
      "name": "Wood_Softwood_Planks"
    },
    {
      "x": -6,
      "y": 0,
      "z": -4,
      "name": "Wood_Ash_Trunk_Full"
    },
    {
      "x": -6,
      "y": 1,
      "z": -4,
      "name": "Wood_Ash_Trunk_Full"
    },
    {
      "x": -6,
      "y": 2,
      "z": -4,
      "name": "Wood_Ash_Trunk_Full"
    },
    {
      "x": -6,
      "y": 3,
      "z": -4,
      "name": "Wood_Ash_Trunk_Full"
    },
    {
      "x": -6,
      "y": 4,
      "z": -4,
      "name": "Wood_Ash_Trunk_Full"
    },
    {
      "x": -6,
      "y": 5,
      "z": -4,
      "name": "Wood_Ash_Trunk"
    },
    {
      "x": -6,
      "y": 0,
      "z": -3,
      "name": "Wood_Hardwood_Planks"
    },
    {
      "x": -6,
      "y": 1,
      "z": -3,
      "name": "Wood_Hardwood_Planks"
    },
    {
      "x": -6,
      "y": 2,
      "z": -3,
      "name": "Wood_Hardwood_Planks"
    },
    {
      "x": -6,
      "y": 3,
      "z": -3,
      "name": "Wood_Hardwood_Planks"
    },
    {
      "x": -6,
      "y": 4,
      "z": -3,
      "name": "Wood_Ash_Trunk_Full",
      "rotation": 4
    },
    {
      "x": -6,
      "y": 0,
      "z": -2,
      "name": "Soil_Clay"
    },
    {
      "x": -6,
      "y": 3,
      "z": -2,
      "name": "Wood_Hardwood_Planks_Half",
      "rotation": 8
    },
    {
      "x": -6,
      "y": 4,
      "z": -2,
      "name": "Wood_Ash_Trunk_Full",
      "rotation": 4
    },
    {
      "x": -6,
      "y": 5,
      "z": -2,
      "name": "Wood_Hardwood_Planks_Half"
    },
    {
      "x": -6,
      "y": 0,
      "z": -1,
      "name": "Soil_Clay"
    },
    {
      "x": -6,
      "y": 4,
      "z": -1,
      "name": "Wood_Ash_Trunk_Full",
      "rotation": 4
    },
    {
      "x": -6,
      "y": 0,
      "z": 0,
      "name": "Soil_Clay"
    },
    {
      "x": -6,
      "y": 4,
      "z": 0,
      "name": "Wood_Ash_Trunk_Full",
      "rotation": 4
    },
    {
      "x": -6,
      "y": 0,
      "z": 1,
      "name": "Plant_Crop_Mushroom_Block_Brown"
    },
    {
      "x": -6,
      "y": 4,
      "z": 1,
      "name": "Wood_Ash_Trunk_Full",
      "rotation": 4
    },
    {
      "x": -6,
      "y": 0,
      "z": 2,
      "name": "Plant_Crop_Mushroom_Block_Brown"
    },
    {
      "x": -6,
      "y": 1,
      "z": 2,
      "name": "Wood_Ash_Trunk_Full"
    },
    {
      "x": -6,
      "y": 2,
      "z": 2,
      "name": "Wood_Ash_Trunk_Full"
    },
    {
      "x": -6,
      "y": 3,
      "z": 2,
      "name": "Wood_Ash_Trunk_Full"
    },
    {
      "x": -6,
      "y": 4,
      "z": 2,
      "name": "Wood_Ash_Trunk_Full"
    },
    {
      "x": -6,
      "y": 5,
      "z": 2,
      "name": "Wood_Ash_Trunk"
    },
    {
      "x": -6,
      "y": 6,
      "z": 2,
      "name": "Wood_Hardwood_Planks_Half"
    },
    {
      "x": -6,
      "y": 0,
      "z": 3,
      "name": "Plant_Crop_Mushroom_Block_Brown"
    },
    {
      "x": -6,
      "y": 4,
      "z": 3,
      "name": "Wood_Ash_Trunk_Full",
      "rotation": 4
    },
    {
      "x": -6,
      "y": 0,
      "z": 4,
      "name": "Soil_Clay"
    },
    {
      "x": -6,
      "y": 4,
      "z": 4,
      "name": "Wood_Ash_Trunk_Full",
      "rotation": 4
    },
    {
      "x": -6,
      "y": 0,
      "z": 5,
      "name": "Soil_Clay"
    },
    {
      "x": -6,
      "y": 4,
      "z": 5,
      "name": "Wood_Ash_Trunk_Full",
      "rotation": 4
    },
    {
      "x": -6,
      "y": 0,
      "z": 6,
      "name": "Soil_Clay"
    },
    {
      "x": -6,
      "y": 3,
      "z": 6,
      "name": "Wood_Hardwood_Planks_Half",
      "rotation": 8
    },
    {
      "x": -6,
      "y": 4,
      "z": 6,
      "name": "Wood_Ash_Trunk_Full",
      "rotation": 4
    },
    {
      "x": -6,
      "y": 5,
      "z": 6,
      "name": "Wood_Hardwood_Planks_Half"
    },
    {
      "x": -6,
      "y": 0,
      "z": 7,
      "name": "Wood_Hardwood_Planks"
    },
    {
      "x": -6,
      "y": 1,
      "z": 7,
      "name": "Wood_Hardwood_Planks"
    },
    {
      "x": -6,
      "y": 2,
      "z": 7,
      "name": "Wood_Hardwood_Planks"
    },
    {
      "x": -6,
      "y": 3,
      "z": 7,
      "name": "Wood_Hardwood_Planks"
    },
    {
      "x": -6,
      "y": 4,
      "z": 7,
      "name": "Wood_Ash_Trunk_Full",
      "rotation": 4
    },
    {
      "x": -6,
      "y": 0,
      "z": 8,
      "name": "Wood_Ash_Trunk_Full"
    },
    {
      "x": -6,
      "y": 1,
      "z": 8,
      "name": "Wood_Ash_Trunk_Full"
    },
    {
      "x": -6,
      "y": 2,
      "z": 8,
      "name": "Wood_Ash_Trunk_Full"
    },
    {
      "x": -6,
      "y": 3,
      "z": 8,
      "name": "Wood_Ash_Trunk_Full"
    },
    {
      "x": -6,
      "y": 4,
      "z": 8,
      "name": "Wood_Ash_Trunk_Full"
    },
    {
      "x": -6,
      "y": 5,
      "z": 8,
      "name": "Wood_Ash_Trunk"
    },
    {
      "x": -6,
      "y": 0,
      "z": 9,
      "name": "Wood_Softwood_Planks"
    },
    {
      "x": -6,
      "y": 0,
      "z": 10,
      "name": "Wood_Softwood_Planks"
    },
    {
      "x": -6,
      "y": 0,
      "z": 11,
      "name": "Wood_Softwood_Planks"
    },
    {
      "x": -6,
      "y": 0,
      "z": 12,
      "name": "Wood_Softwood_Planks"
    },
    {
      "x": -6,
      "y": 0,
      "z": 13,
      "name": "Wood_Softwood_Planks"
    },
    {
      "x": -6,
      "y": 0,
      "z": 14,
      "name": "Wood_Softwood_Planks"
    },
    {
      "x": -6,
      "y": 0,
      "z": 15,
      "name": "Wood_Softwood_Planks"
    },
    {
      "x": -6,
      "y": 0,
      "z": 16,
      "name": "Wood_Softwood_Planks"
    },
    {
      "x": -5,
      "y": 0,
      "z": -15,
      "name": "Soil_Gravel"
    },
    {
      "x": -5,
      "y": 0,
      "z": -14,
      "name": "Soil_Gravel"
    },
    {
      "x": -5,
      "y": 0,
      "z": -13,
      "name": "Soil_Gravel"
    },
    {
      "x": -5,
      "y": 0,
      "z": -12,
      "name": "Soil_Gravel"
    },
    {
      "x": -5,
      "y": 0,
      "z": -11,
      "name": "Soil_Gravel"
    },
    {
      "x": -5,
      "y": 0,
      "z": -10,
      "name": "Soil_Gravel"
    },
    {
      "x": -5,
      "y": 0,
      "z": -9,
      "name": "Wood_Softwood_Planks"
    },
    {
      "x": -5,
      "y": 0,
      "z": -8,
      "name": "Wood_Softwood_Planks"
    },
    {
      "x": -5,
      "y": 0,
      "z": -7,
      "name": "Wood_Softwood_Planks"
    },
    {
      "x": -5,
      "y": 0,
      "z": -6,
      "name": "Wood_Softwood_Planks"
    },
    {
      "x": -5,
      "y": 0,
      "z": -5,
      "name": "Wood_Softwood_Planks"
    },
    {
      "x": -5,
      "y": 0,
      "z": -4,
      "name": "Wood_Hardwood_Planks"
    },
    {
      "x": -5,
      "y": 1,
      "z": -4,
      "name": "Wood_Hardwood_Planks"
    },
    {
      "x": -5,
      "y": 2,
      "z": -4,
      "name": "Wood_Hardwood_Planks"
    },
    {
      "x": -5,
      "y": 3,
      "z": -4,
      "name": "Wood_Hardwood_Planks"
    },
    {
      "x": -5,
      "y": 4,
      "z": -4,
      "name": "Wood_Ash_Trunk_Full",
      "rotation": 5
    },
    {
      "x": -5,
      "y": 0,
      "z": -3,
      "name": "Soil_Clay"
    },
    {
      "x": -5,
      "y": 1,
      "z": -3,
      "name": "*Wood_Hardwood_Fence_State_Definitions_Corner",
      "rotation": 3
    },
    {
      "x": -5,
      "y": 2,
      "z": -3,
      "name": "Deco_Lantern"
    },
    {
      "x": -5,
      "y": 0,
      "z": -2,
      "name": "Soil_Clay"
    },
    {
      "x": -5,
      "y": 4,
      "z": -2,
      "name": "Wood_Hardwood_Planks_Half",
      "rotation": 5
    },
    {
      "x": -5,
      "y": 0,
      "z": -1,
      "name": "Soil_Clay"
    },
    {
      "x": -5,
      "y": 0,
      "z": 0,
      "name": "Soil_Clay"
    },
    {
      "x": -5,
      "y": 0,
      "z": 1,
      "name": "Plant_Crop_Mushroom_Block_Brown"
    },
    {
      "x": -5,
      "y": 0,
      "z": 2,
      "name": "Plant_Crop_Mushroom_Block_Brown"
    },
    {
      "x": -5,
      "y": 1,
      "z": 2,
      "name": "Wood_Hardwood_Fence",
      "rotation": 1
    },
    {
      "x": -5,
      "y": 3,
      "z": 2,
      "name": "Wood_Torch_Wall",
      "rotation": 1
    },
    {
      "x": -5,
      "y": 0,
      "z": 3,
      "name": "Plant_Crop_Mushroom_Block_Brown"
    },
    {
      "x": -5,
      "y": 0,
      "z": 4,
      "name": "Soil_Clay"
    },
    {
      "x": -5,
      "y": 0,
      "z": 5,
      "name": "Soil_Clay"
    },
    {
      "x": -5,
      "y": 0,
      "z": 6,
      "name": "Soil_Clay"
    },
    {
      "x": -5,
      "y": 4,
      "z": 6,
      "name": "Wood_Hardwood_Planks_Half",
      "rotation": 5
    },
    {
      "x": -5,
      "y": 0,
      "z": 7,
      "name": "Soil_Clay"
    },
    {
      "x": -5,
      "y": 1,
      "z": 7,
      "name": "*Wood_Hardwood_Fence_State_Definitions_Corner"
    },
    {
      "x": -5,
      "y": 2,
      "z": 7,
      "name": "Deco_Lantern"
    },
    {
      "x": -5,
      "y": 0,
      "z": 8,
      "name": "Wood_Hardwood_Planks"
    },
    {
      "x": -5,
      "y": 1,
      "z": 8,
      "name": "Wood_Hardwood_Planks"
    },
    {
      "x": -5,
      "y": 2,
      "z": 8,
      "name": "Wood_Hardwood_Planks"
    },
    {
      "x": -5,
      "y": 3,
      "z": 8,
      "name": "Wood_Hardwood_Planks"
    },
    {
      "x": -5,
      "y": 4,
      "z": 8,
      "name": "Wood_Ash_Trunk_Full",
      "rotation": 5
    },
    {
      "x": -5,
      "y": 0,
      "z": 9,
      "name": "Wood_Softwood_Planks"
    },
    {
      "x": -5,
      "y": 0,
      "z": 10,
      "name": "Wood_Softwood_Planks"
    },
    {
      "x": -5,
      "y": 0,
      "z": 11,
      "name": "Wood_Softwood_Planks"
    },
    {
      "x": -5,
      "y": 0,
      "z": 12,
      "name": "Wood_Softwood_Planks"
    },
    {
      "x": -5,
      "y": 0,
      "z": 13,
      "name": "Wood_Softwood_Planks"
    },
    {
      "x": -5,
      "y": 0,
      "z": 14,
      "name": "Wood_Softwood_Planks"
    },
    {
      "x": -5,
      "y": 0,
      "z": 15,
      "name": "Wood_Softwood_Planks"
    },
    {
      "x": -5,
      "y": 0,
      "z": 16,
      "name": "Wood_Softwood_Planks"
    },
    {
      "x": -4,
      "y": 0,
      "z": -15,
      "name": "Soil_Gravel"
    },
    {
      "x": -4,
      "y": 0,
      "z": -14,
      "name": "Soil_Gravel"
    },
    {
      "x": -4,
      "y": 0,
      "z": -13,
      "name": "Soil_Gravel"
    },
    {
      "x": -4,
      "y": 0,
      "z": -12,
      "name": "Soil_Gravel"
    },
    {
      "x": -4,
      "y": 0,
      "z": -11,
      "name": "Soil_Gravel"
    },
    {
      "x": -4,
      "y": 0,
      "z": -10,
      "name": "Soil_Gravel"
    },
    {
      "x": -4,
      "y": 0,
      "z": -9,
      "name": "Wood_Softwood_Planks"
    },
    {
      "x": -4,
      "y": 0,
      "z": -8,
      "name": "Soil_Clay"
    },
    {
      "x": -4,
      "y": 1,
      "z": -8,
      "name": "*Wood_Hardwood_Fence_State_Definitions_Corner",
      "rotation": 1
    },
    {
      "x": -4,
      "y": 2,
      "z": -8,
      "name": "*Wood_Hardwood_Fence_State_Definitions_Corner",
      "rotation": 1
    },
    {
      "x": -4,
      "y": 0,
      "z": -7,
      "name": "Soil_Clay"
    },
    {
      "x": -4,
      "y": 1,
      "z": -7,
      "name": "Wood_Hardwood_Fence",
      "rotation": 1
    },
    {
      "x": -4,
      "y": 2,
      "z": -7,
      "name": "Wood_Hardwood_Fence",
      "rotation": 1
    },
    {
      "x": -4,
      "y": 0,
      "z": -6,
      "name": "Soil_Clay"
    },
    {
      "x": -4,
      "y": 1,
      "z": -6,
      "name": "Wood_Hardwood_Fence",
      "rotation": 1
    },
    {
      "x": -4,
      "y": 2,
      "z": -6,
      "name": "Wood_Hardwood_Fence",
      "rotation": 1
    },
    {
      "x": -4,
      "y": 4,
      "z": -6,
      "name": "Wood_Ash_Trunk",
      "rotation": 4
    },
    {
      "x": -4,
      "y": 0,
      "z": -5,
      "name": "Wood_Ash_Trunk_Full"
    },
    {
      "x": -4,
      "y": 1,
      "z": -5,
      "name": "Wood_Ash_Trunk_Full"
    },
    {
      "x": -4,
      "y": 2,
      "z": -5,
      "name": "Wood_Ash_Trunk_Full"
    },
    {
      "x": -4,
      "y": 3,
      "z": -5,
      "name": "Wood_Ash_Trunk_Full"
    },
    {
      "x": -4,
      "y": 4,
      "z": -5,
      "name": "Wood_Ash_Trunk_Full",
      "rotation": 4
    },
    {
      "x": -4,
      "y": 0,
      "z": -4,
      "name": "Soil_Clay"
    },
    {
      "x": -4,
      "y": 3,
      "z": -4,
      "name": "Wood_Hardwood_Planks_Half",
      "rotation": 8
    },
    {
      "x": -4,
      "y": 4,
      "z": -4,
      "name": "Wood_Ash_Trunk_Full",
      "rotation": 5
    },
    {
      "x": -4,
      "y": 5,
      "z": -4,
      "name": "Wood_Hardwood_Planks_Half"
    },
    {
      "x": -4,
      "y": 0,
      "z": -3,
      "name": "Soil_Clay"
    },
    {
      "x": -4,
      "y": 4,
      "z": -3,
      "name": "Wood_Hardwood_Planks_Half",
      "rotation": 4
    },
    {
      "x": -4,
      "y": 0,
      "z": -2,
      "name": "Soil_Clay"
    },
    {
      "x": -4,
      "y": 0,
      "z": -1,
      "name": "Soil_Clay"
    },
    {
      "x": -4,
      "y": 0,
      "z": 0,
      "name": "Soil_Clay"
    },
    {
      "x": -4,
      "y": 0,
      "z": 1,
      "name": "Soil_Clay"
    },
    {
      "x": -4,
      "y": 0,
      "z": 2,
      "name": "Soil_Clay"
    },
    {
      "x": -4,
      "y": 0,
      "z": 3,
      "name": "Soil_Clay"
    },
    {
      "x": -4,
      "y": 0,
      "z": 4,
      "name": "Soil_Clay"
    },
    {
      "x": -4,
      "y": 0,
      "z": 5,
      "name": "Soil_Clay"
    },
    {
      "x": -4,
      "y": 0,
      "z": 6,
      "name": "Soil_Clay"
    },
    {
      "x": -4,
      "y": 0,
      "z": 7,
      "name": "Soil_Clay"
    },
    {
      "x": -4,
      "y": 4,
      "z": 7,
      "name": "Wood_Hardwood_Planks_Half",
      "rotation": 6
    },
    {
      "x": -4,
      "y": 0,
      "z": 8,
      "name": "Soil_Clay"
    },
    {
      "x": -4,
      "y": 3,
      "z": 8,
      "name": "Wood_Hardwood_Planks_Half",
      "rotation": 8
    },
    {
      "x": -4,
      "y": 4,
      "z": 8,
      "name": "Wood_Ash_Trunk_Full",
      "rotation": 5
    },
    {
      "x": -4,
      "y": 5,
      "z": 8,
      "name": "Wood_Hardwood_Planks_Half"
    },
    {
      "x": -4,
      "y": 0,
      "z": 9,
      "name": "Wood_Ash_Trunk_Full"
    },
    {
      "x": -4,
      "y": 1,
      "z": 9,
      "name": "Wood_Ash_Trunk_Full"
    },
    {
      "x": -4,
      "y": 2,
      "z": 9,
      "name": "Wood_Ash_Trunk_Full"
    },
    {
      "x": -4,
      "y": 3,
      "z": 9,
      "name": "Wood_Ash_Trunk_Full"
    },
    {
      "x": -4,
      "y": 4,
      "z": 9,
      "name": "Wood_Ash_Trunk_Full",
      "rotation": 4
    },
    {
      "x": -4,
      "y": 0,
      "z": 10,
      "name": "Soil_Clay"
    },
    {
      "x": -4,
      "y": 1,
      "z": 10,
      "name": "Wood_Hardwood_Fence",
      "rotation": 3
    },
    {
      "x": -4,
      "y": 2,
      "z": 10,
      "name": "Wood_Hardwood_Fence",
      "rotation": 1
    },
    {
      "x": -4,
      "y": 4,
      "z": 10,
      "name": "Wood_Ash_Trunk",
      "rotation": 4
    },
    {
      "x": -4,
      "y": 0,
      "z": 11,
      "name": "Soil_Clay"
    },
    {
      "x": -4,
      "y": 1,
      "z": 11,
      "name": "Wood_Hardwood_Fence",
      "rotation": 3
    },
    {
      "x": -4,
      "y": 2,
      "z": 11,
      "name": "Wood_Hardwood_Fence",
      "rotation": 1
    },
    {
      "x": -4,
      "y": 0,
      "z": 12,
      "name": "Soil_Clay"
    },
    {
      "x": -4,
      "y": 1,
      "z": 12,
      "name": "*Wood_Hardwood_Fence_State_Definitions_Corner",
      "rotation": 2
    },
    {
      "x": -4,
      "y": 2,
      "z": 12,
      "name": "*Wood_Hardwood_Fence_State_Definitions_Corner",
      "rotation": 2
    },
    {
      "x": -4,
      "y": 0,
      "z": 13,
      "name": "Wood_Softwood_Planks"
    },
    {
      "x": -4,
      "y": 0,
      "z": 14,
      "name": "Wood_Softwood_Planks"
    },
    {
      "x": -4,
      "y": 0,
      "z": 15,
      "name": "Wood_Softwood_Planks"
    },
    {
      "x": -4,
      "y": 0,
      "z": 16,
      "name": "Wood_Softwood_Planks"
    },
    {
      "x": -3,
      "y": 0,
      "z": -15,
      "name": "Soil_Gravel"
    },
    {
      "x": -3,
      "y": 0,
      "z": -14,
      "name": "Soil_Gravel"
    },
    {
      "x": -3,
      "y": 0,
      "z": -13,
      "name": "Soil_Gravel"
    },
    {
      "x": -3,
      "y": 0,
      "z": -12,
      "name": "Soil_Gravel"
    },
    {
      "x": -3,
      "y": 0,
      "z": -11,
      "name": "Soil_Gravel"
    },
    {
      "x": -3,
      "y": 0,
      "z": -10,
      "name": "Soil_Gravel"
    },
    {
      "x": -3,
      "y": 0,
      "z": -9,
      "name": "Wood_Softwood_Planks"
    },
    {
      "x": -3,
      "y": 0,
      "z": -8,
      "name": "Soil_Clay"
    },
    {
      "x": -3,
      "y": 1,
      "z": -8,
      "name": "Wood_Hardwood_Fence"
    },
    {
      "x": -3,
      "y": 2,
      "z": -8,
      "name": "Wood_Hardwood_Fence"
    },
    {
      "x": -3,
      "y": 0,
      "z": -7,
      "name": "Soil_Clay"
    },
    {
      "x": -3,
      "y": 0,
      "z": -6,
      "name": "Soil_Clay"
    },
    {
      "x": -3,
      "y": 0,
      "z": -5,
      "name": "Soil_Clay"
    },
    {
      "x": -3,
      "y": 0,
      "z": -4,
      "name": "Soil_Clay"
    },
    {
      "x": -3,
      "y": 4,
      "z": -4,
      "name": "Wood_Ash_Trunk_Full",
      "rotation": 5
    },
    {
      "x": -3,
      "y": 0,
      "z": -3,
      "name": "Soil_Clay"
    },
    {
      "x": -3,
      "y": 0,
      "z": -2,
      "name": "Soil_Clay"
    },
    {
      "x": -3,
      "y": 0,
      "z": -1,
      "name": "Soil_Clay"
    },
    {
      "x": -3,
      "y": 0,
      "z": 0,
      "name": "Soil_Clay"
    },
    {
      "x": -3,
      "y": 0,
      "z": 1,
      "name": "Soil_Clay"
    },
    {
      "x": -3,
      "y": 0,
      "z": 2,
      "name": "Soil_Clay"
    },
    {
      "x": -3,
      "y": 0,
      "z": 3,
      "name": "Soil_Clay"
    },
    {
      "x": -3,
      "y": 0,
      "z": 4,
      "name": "Soil_Clay"
    },
    {
      "x": -3,
      "y": 0,
      "z": 5,
      "name": "Soil_Clay"
    },
    {
      "x": -3,
      "y": 0,
      "z": 6,
      "name": "Soil_Clay"
    },
    {
      "x": -3,
      "y": 0,
      "z": 7,
      "name": "Soil_Clay"
    },
    {
      "x": -3,
      "y": 0,
      "z": 8,
      "name": "Soil_Clay"
    },
    {
      "x": -3,
      "y": 4,
      "z": 8,
      "name": "Wood_Ash_Trunk_Full",
      "rotation": 5
    },
    {
      "x": -3,
      "y": 0,
      "z": 9,
      "name": "Soil_Clay"
    },
    {
      "x": -3,
      "y": 0,
      "z": 10,
      "name": "Soil_Clay"
    },
    {
      "x": -3,
      "y": 0,
      "z": 11,
      "name": "K2_Slot_Portal_4"
    },
    {
      "x": -3,
      "y": 0,
      "z": 12,
      "name": "Soil_Clay"
    },
    {
      "x": -3,
      "y": 1,
      "z": 12,
      "name": "Wood_Hardwood_Fence",
      "rotation": 2
    },
    {
      "x": -3,
      "y": 2,
      "z": 12,
      "name": "Wood_Hardwood_Fence",
      "rotation": 2
    },
    {
      "x": -3,
      "y": 0,
      "z": 13,
      "name": "Wood_Softwood_Planks"
    },
    {
      "x": -3,
      "y": 0,
      "z": 14,
      "name": "Wood_Softwood_Planks"
    },
    {
      "x": -3,
      "y": 0,
      "z": 15,
      "name": "Wood_Softwood_Planks"
    },
    {
      "x": -3,
      "y": 0,
      "z": 16,
      "name": "Wood_Softwood_Planks"
    },
    {
      "x": -2,
      "y": 0,
      "z": -15,
      "name": "Soil_Gravel"
    },
    {
      "x": -2,
      "y": 0,
      "z": -14,
      "name": "Soil_Gravel"
    },
    {
      "x": -2,
      "y": 0,
      "z": -13,
      "name": "Soil_Gravel"
    },
    {
      "x": -2,
      "y": 0,
      "z": -12,
      "name": "Soil_Gravel"
    },
    {
      "x": -2,
      "y": 0,
      "z": -11,
      "name": "Soil_Gravel"
    },
    {
      "x": -2,
      "y": 0,
      "z": -10,
      "name": "Soil_Gravel"
    },
    {
      "x": -2,
      "y": 0,
      "z": -9,
      "name": "Wood_Softwood_Planks"
    },
    {
      "x": -2,
      "y": 0,
      "z": -8,
      "name": "Soil_Clay"
    },
    {
      "x": -2,
      "y": 1,
      "z": -8,
      "name": "Wood_Hardwood_Fence"
    },
    {
      "x": -2,
      "y": 2,
      "z": -8,
      "name": "Wood_Hardwood_Fence"
    },
    {
      "x": -2,
      "y": 0,
      "z": -7,
      "name": "Soil_Clay"
    },
    {
      "x": -2,
      "y": 0,
      "z": -6,
      "name": "Soil_Clay"
    },
    {
      "x": -2,
      "y": 0,
      "z": -5,
      "name": "Soil_Clay"
    },
    {
      "x": -2,
      "y": 0,
      "z": -4,
      "name": "Soil_Clay"
    },
    {
      "x": -2,
      "y": 4,
      "z": -4,
      "name": "Wood_Ash_Trunk_Full",
      "rotation": 5
    },
    {
      "x": -2,
      "y": 0,
      "z": -3,
      "name": "Soil_Clay"
    },
    {
      "x": -2,
      "y": 0,
      "z": -2,
      "name": "Soil_Clay"
    },
    {
      "x": -2,
      "y": 0,
      "z": -1,
      "name": "Soil_Clay"
    },
    {
      "x": -2,
      "y": 0,
      "z": 0,
      "name": "Soil_Clay"
    },
    {
      "x": -2,
      "y": 0,
      "z": 1,
      "name": "Soil_Clay"
    },
    {
      "x": -2,
      "y": 0,
      "z": 2,
      "name": "Soil_Clay"
    },
    {
      "x": -2,
      "y": 0,
      "z": 3,
      "name": "Soil_Clay"
    },
    {
      "x": -2,
      "y": 0,
      "z": 4,
      "name": "Soil_Clay"
    },
    {
      "x": -2,
      "y": 0,
      "z": 5,
      "name": "Soil_Clay"
    },
    {
      "x": -2,
      "y": 0,
      "z": 6,
      "name": "Soil_Clay"
    },
    {
      "x": -2,
      "y": 0,
      "z": 7,
      "name": "Soil_Clay"
    },
    {
      "x": -2,
      "y": 0,
      "z": 8,
      "name": "Soil_Clay"
    },
    {
      "x": -2,
      "y": 4,
      "z": 8,
      "name": "Wood_Ash_Trunk_Full",
      "rotation": 5
    },
    {
      "x": -2,
      "y": 0,
      "z": 9,
      "name": "Soil_Clay"
    },
    {
      "x": -2,
      "y": 0,
      "z": 10,
      "name": "Soil_Clay"
    },
    {
      "x": -2,
      "y": 0,
      "z": 11,
      "name": "Soil_Clay"
    },
    {
      "x": -2,
      "y": 0,
      "z": 12,
      "name": "Soil_Clay"
    },
    {
      "x": -2,
      "y": 1,
      "z": 12,
      "name": "Wood_Hardwood_Fence",
      "rotation": 2
    },
    {
      "x": -2,
      "y": 2,
      "z": 12,
      "name": "Wood_Hardwood_Fence",
      "rotation": 2
    },
    {
      "x": -2,
      "y": 0,
      "z": 13,
      "name": "Wood_Softwood_Planks"
    },
    {
      "x": -2,
      "y": 0,
      "z": 14,
      "name": "Wood_Softwood_Planks"
    },
    {
      "x": -2,
      "y": 0,
      "z": 15,
      "name": "Wood_Softwood_Planks"
    },
    {
      "x": -2,
      "y": 0,
      "z": 16,
      "name": "Wood_Softwood_Planks"
    },
    {
      "x": -1,
      "y": 0,
      "z": -15,
      "name": "Soil_Gravel"
    },
    {
      "x": -1,
      "y": 0,
      "z": -14,
      "name": "Soil_Gravel"
    },
    {
      "x": -1,
      "y": 0,
      "z": -13,
      "name": "Soil_Gravel"
    },
    {
      "x": -1,
      "y": 0,
      "z": -12,
      "name": "Soil_Gravel"
    },
    {
      "x": -1,
      "y": 0,
      "z": -11,
      "name": "Soil_Gravel"
    },
    {
      "x": -1,
      "y": 0,
      "z": -10,
      "name": "Soil_Gravel"
    },
    {
      "x": -1,
      "y": 0,
      "z": -9,
      "name": "Wood_Softwood_Planks"
    },
    {
      "x": -1,
      "y": 0,
      "z": -8,
      "name": "Soil_Clay"
    },
    {
      "x": -1,
      "y": 1,
      "z": -8,
      "name": "Wood_Hardwood_Fence"
    },
    {
      "x": -1,
      "y": 2,
      "z": -8,
      "name": "Wood_Hardwood_Fence"
    },
    {
      "x": -1,
      "y": 0,
      "z": -7,
      "name": "Soil_Clay"
    },
    {
      "x": -1,
      "y": 0,
      "z": -6,
      "name": "Soil_Clay"
    },
    {
      "x": -1,
      "y": 0,
      "z": -5,
      "name": "Plant_Crop_Mushroom_Block_Brown"
    },
    {
      "x": -1,
      "y": 0,
      "z": -4,
      "name": "Plant_Crop_Mushroom_Block_Brown"
    },
    {
      "x": -1,
      "y": 4,
      "z": -4,
      "name": "Wood_Ash_Trunk_Full",
      "rotation": 5
    },
    {
      "x": -1,
      "y": 0,
      "z": -3,
      "name": "Plant_Crop_Mushroom_Block_Brown"
    },
    {
      "x": -1,
      "y": 0,
      "z": -2,
      "name": "Soil_Clay"
    },
    {
      "x": -1,
      "y": 0,
      "z": -1,
      "name": "Soil_Clay"
    },
    {
      "x": -1,
      "y": 0,
      "z": 0,
      "name": "Soil_Clay"
    },
    {
      "x": -1,
      "y": 0,
      "z": 1,
      "name": "Soil_Clay"
    },
    {
      "x": -1,
      "y": 0,
      "z": 2,
      "name": "Soil_Clay"
    },
    {
      "x": -1,
      "y": 0,
      "z": 3,
      "name": "Soil_Clay"
    },
    {
      "x": -1,
      "y": 0,
      "z": 4,
      "name": "Soil_Clay"
    },
    {
      "x": -1,
      "y": 0,
      "z": 5,
      "name": "Soil_Clay"
    },
    {
      "x": -1,
      "y": 0,
      "z": 6,
      "name": "Soil_Clay"
    },
    {
      "x": -1,
      "y": 0,
      "z": 7,
      "name": "Plant_Crop_Mushroom_Block_Brown"
    },
    {
      "x": -1,
      "y": 0,
      "z": 8,
      "name": "Plant_Crop_Mushroom_Block_Brown"
    },
    {
      "x": -1,
      "y": 4,
      "z": 8,
      "name": "Wood_Ash_Trunk_Full",
      "rotation": 5
    },
    {
      "x": -1,
      "y": 0,
      "z": 9,
      "name": "Plant_Crop_Mushroom_Block_Brown"
    },
    {
      "x": -1,
      "y": 0,
      "z": 10,
      "name": "Soil_Clay"
    },
    {
      "x": -1,
      "y": 0,
      "z": 11,
      "name": "Soil_Clay"
    },
    {
      "x": -1,
      "y": 0,
      "z": 12,
      "name": "Soil_Clay"
    },
    {
      "x": -1,
      "y": 1,
      "z": 12,
      "name": "Wood_Hardwood_Fence",
      "rotation": 2
    },
    {
      "x": -1,
      "y": 2,
      "z": 12,
      "name": "Wood_Hardwood_Fence",
      "rotation": 2
    },
    {
      "x": -1,
      "y": 0,
      "z": 13,
      "name": "Wood_Softwood_Planks"
    },
    {
      "x": -1,
      "y": 0,
      "z": 14,
      "name": "Wood_Softwood_Planks"
    },
    {
      "x": -1,
      "y": 0,
      "z": 15,
      "name": "Wood_Softwood_Planks"
    },
    {
      "x": -1,
      "y": 0,
      "z": 16,
      "name": "Wood_Softwood_Planks"
    },
    {
      "x": 0,
      "y": 0,
      "z": -15,
      "name": "Soil_Gravel"
    },
    {
      "x": 0,
      "y": 0,
      "z": -14,
      "name": "Soil_Gravel"
    },
    {
      "x": 0,
      "y": 0,
      "z": -13,
      "name": "Soil_Gravel"
    },
    {
      "x": 0,
      "y": 0,
      "z": -12,
      "name": "Soil_Gravel"
    },
    {
      "x": 0,
      "y": 0,
      "z": -11,
      "name": "Soil_Gravel"
    },
    {
      "x": 0,
      "y": 0,
      "z": -10,
      "name": "Soil_Gravel"
    },
    {
      "x": 0,
      "y": 0,
      "z": -9,
      "name": "Wood_Softwood_Planks"
    },
    {
      "x": 0,
      "y": 0,
      "z": -8,
      "name": "Soil_Clay"
    },
    {
      "x": 0,
      "y": 1,
      "z": -8,
      "name": "Wood_Hardwood_Fence"
    },
    {
      "x": 0,
      "y": 2,
      "z": -8,
      "name": "Wood_Hardwood_Fence"
    },
    {
      "x": 0,
      "y": 0,
      "z": -7,
      "name": "Soil_Clay"
    },
    {
      "x": 0,
      "y": 0,
      "z": -6,
      "name": "Soil_Clay"
    },
    {
      "x": 0,
      "y": 0,
      "z": -5,
      "name": "Plant_Crop_Mushroom_Block_Brown"
    },
    {
      "x": 0,
      "y": 0,
      "z": -4,
      "name": "Plant_Crop_Mushroom_Block_Brown"
    },
    {
      "x": 0,
      "y": 1,
      "z": -4,
      "name": "Wood_Ash_Trunk_Full"
    },
    {
      "x": 0,
      "y": 2,
      "z": -4,
      "name": "Wood_Ash_Trunk_Full"
    },
    {
      "x": 0,
      "y": 3,
      "z": -4,
      "name": "Wood_Ash_Trunk_Full"
    },
    {
      "x": 0,
      "y": 4,
      "z": -4,
      "name": "Wood_Ash_Trunk_Full"
    },
    {
      "x": 0,
      "y": 5,
      "z": -4,
      "name": "Wood_Ash_Trunk"
    },
    {
      "x": 0,
      "y": 6,
      "z": -4,
      "name": "Wood_Hardwood_Planks_Half"
    },
    {
      "x": 0,
      "y": 0,
      "z": -3,
      "name": "Plant_Crop_Mushroom_Block_Brown"
    },
    {
      "x": 0,
      "y": 1,
      "z": -3,
      "name": "Wood_Hardwood_Fence"
    },
    {
      "x": 0,
      "y": 3,
      "z": -3,
      "name": "Wood_Torch_Wall"
    },
    {
      "x": 0,
      "y": 0,
      "z": -2,
      "name": "Soil_Clay"
    },
    {
      "x": 0,
      "y": 0,
      "z": -1,
      "name": "Soil_Clay"
    },
    {
      "x": 0,
      "y": 0,
      "z": 0,
      "name": "Soil_Clay"
    },
    {
      "x": 0,
      "y": 0,
      "z": 1,
      "name": "Soil_Clay"
    },
    {
      "x": 0,
      "y": 0,
      "z": 2,
      "name": "K2_Slot_Arrival"
    },
    {
      "x": 0,
      "y": 0,
      "z": 3,
      "name": "Soil_Clay"
    },
    {
      "x": 0,
      "y": 0,
      "z": 4,
      "name": "Soil_Clay"
    },
    {
      "x": 0,
      "y": 0,
      "z": 5,
      "name": "Soil_Clay"
    },
    {
      "x": 0,
      "y": 0,
      "z": 6,
      "name": "Soil_Clay"
    },
    {
      "x": 0,
      "y": 0,
      "z": 7,
      "name": "Plant_Crop_Mushroom_Block_Brown"
    },
    {
      "x": 0,
      "y": 1,
      "z": 7,
      "name": "Wood_Hardwood_Fence",
      "rotation": 2
    },
    {
      "x": 0,
      "y": 3,
      "z": 7,
      "name": "Wood_Torch_Wall",
      "rotation": 2
    },
    {
      "x": 0,
      "y": 0,
      "z": 8,
      "name": "Plant_Crop_Mushroom_Block_Brown"
    },
    {
      "x": 0,
      "y": 1,
      "z": 8,
      "name": "Wood_Ash_Trunk_Full"
    },
    {
      "x": 0,
      "y": 2,
      "z": 8,
      "name": "Wood_Ash_Trunk_Full"
    },
    {
      "x": 0,
      "y": 3,
      "z": 8,
      "name": "Wood_Ash_Trunk_Full"
    },
    {
      "x": 0,
      "y": 4,
      "z": 8,
      "name": "Wood_Ash_Trunk_Full"
    },
    {
      "x": 0,
      "y": 5,
      "z": 8,
      "name": "Wood_Ash_Trunk"
    },
    {
      "x": 0,
      "y": 6,
      "z": 8,
      "name": "Wood_Hardwood_Planks_Half"
    },
    {
      "x": 0,
      "y": 0,
      "z": 9,
      "name": "Plant_Crop_Mushroom_Block_Brown"
    },
    {
      "x": 0,
      "y": 0,
      "z": 10,
      "name": "Soil_Clay"
    },
    {
      "x": 0,
      "y": 0,
      "z": 11,
      "name": "Soil_Clay"
    },
    {
      "x": 0,
      "y": 0,
      "z": 12,
      "name": "Soil_Clay"
    },
    {
      "x": 0,
      "y": 1,
      "z": 12,
      "name": "Wood_Hardwood_Fence",
      "rotation": 2
    },
    {
      "x": 0,
      "y": 2,
      "z": 12,
      "name": "Wood_Hardwood_Fence",
      "rotation": 2
    },
    {
      "x": 0,
      "y": 0,
      "z": 13,
      "name": "Wood_Softwood_Planks"
    },
    {
      "x": 0,
      "y": 0,
      "z": 14,
      "name": "Wood_Softwood_Planks"
    },
    {
      "x": 0,
      "y": 0,
      "z": 15,
      "name": "Wood_Softwood_Planks"
    },
    {
      "x": 0,
      "y": 0,
      "z": 16,
      "name": "Wood_Softwood_Planks"
    },
    {
      "x": 1,
      "y": 0,
      "z": -15,
      "name": "Soil_Gravel"
    },
    {
      "x": 1,
      "y": 0,
      "z": -14,
      "name": "Soil_Gravel"
    },
    {
      "x": 1,
      "y": 0,
      "z": -13,
      "name": "Soil_Gravel"
    },
    {
      "x": 1,
      "y": 0,
      "z": -12,
      "name": "Soil_Gravel"
    },
    {
      "x": 1,
      "y": 0,
      "z": -11,
      "name": "Soil_Gravel"
    },
    {
      "x": 1,
      "y": 0,
      "z": -10,
      "name": "Soil_Gravel"
    },
    {
      "x": 1,
      "y": 0,
      "z": -9,
      "name": "Wood_Softwood_Planks"
    },
    {
      "x": 1,
      "y": 0,
      "z": -8,
      "name": "Soil_Clay"
    },
    {
      "x": 1,
      "y": 1,
      "z": -8,
      "name": "Wood_Hardwood_Fence"
    },
    {
      "x": 1,
      "y": 2,
      "z": -8,
      "name": "Wood_Hardwood_Fence"
    },
    {
      "x": 1,
      "y": 0,
      "z": -7,
      "name": "Soil_Clay"
    },
    {
      "x": 1,
      "y": 0,
      "z": -6,
      "name": "Soil_Clay"
    },
    {
      "x": 1,
      "y": 0,
      "z": -5,
      "name": "Plant_Crop_Mushroom_Block_Brown"
    },
    {
      "x": 1,
      "y": 0,
      "z": -4,
      "name": "Plant_Crop_Mushroom_Block_Brown"
    },
    {
      "x": 1,
      "y": 4,
      "z": -4,
      "name": "Wood_Ash_Trunk_Full",
      "rotation": 5
    },
    {
      "x": 1,
      "y": 0,
      "z": -3,
      "name": "Plant_Crop_Mushroom_Block_Brown"
    },
    {
      "x": 1,
      "y": 0,
      "z": -2,
      "name": "Soil_Clay"
    },
    {
      "x": 1,
      "y": 0,
      "z": -1,
      "name": "Soil_Clay"
    },
    {
      "x": 1,
      "y": 0,
      "z": 0,
      "name": "Soil_Clay"
    },
    {
      "x": 1,
      "y": 0,
      "z": 1,
      "name": "Soil_Clay"
    },
    {
      "x": 1,
      "y": 0,
      "z": 2,
      "name": "Soil_Clay"
    },
    {
      "x": 1,
      "y": 0,
      "z": 3,
      "name": "Soil_Clay"
    },
    {
      "x": 1,
      "y": 0,
      "z": 4,
      "name": "Soil_Clay"
    },
    {
      "x": 1,
      "y": 0,
      "z": 5,
      "name": "Soil_Clay"
    },
    {
      "x": 1,
      "y": 0,
      "z": 6,
      "name": "Soil_Clay"
    },
    {
      "x": 1,
      "y": 0,
      "z": 7,
      "name": "Plant_Crop_Mushroom_Block_Brown"
    },
    {
      "x": 1,
      "y": 0,
      "z": 8,
      "name": "Plant_Crop_Mushroom_Block_Brown"
    },
    {
      "x": 1,
      "y": 4,
      "z": 8,
      "name": "Wood_Ash_Trunk_Full",
      "rotation": 5
    },
    {
      "x": 1,
      "y": 0,
      "z": 9,
      "name": "Plant_Crop_Mushroom_Block_Brown"
    },
    {
      "x": 1,
      "y": 0,
      "z": 10,
      "name": "Soil_Clay"
    },
    {
      "x": 1,
      "y": 0,
      "z": 11,
      "name": "Soil_Clay"
    },
    {
      "x": 1,
      "y": 0,
      "z": 12,
      "name": "Soil_Clay"
    },
    {
      "x": 1,
      "y": 1,
      "z": 12,
      "name": "Wood_Hardwood_Fence",
      "rotation": 2
    },
    {
      "x": 1,
      "y": 2,
      "z": 12,
      "name": "Wood_Hardwood_Fence",
      "rotation": 2
    },
    {
      "x": 1,
      "y": 0,
      "z": 13,
      "name": "Wood_Softwood_Planks"
    },
    {
      "x": 1,
      "y": 0,
      "z": 14,
      "name": "Wood_Softwood_Planks"
    },
    {
      "x": 1,
      "y": 0,
      "z": 15,
      "name": "Wood_Softwood_Planks"
    },
    {
      "x": 1,
      "y": 0,
      "z": 16,
      "name": "Wood_Softwood_Planks"
    },
    {
      "x": 2,
      "y": 0,
      "z": -15,
      "name": "Soil_Gravel"
    },
    {
      "x": 2,
      "y": 0,
      "z": -14,
      "name": "Soil_Gravel"
    },
    {
      "x": 2,
      "y": 0,
      "z": -13,
      "name": "Soil_Gravel"
    },
    {
      "x": 2,
      "y": 0,
      "z": -12,
      "name": "Soil_Gravel"
    },
    {
      "x": 2,
      "y": 0,
      "z": -11,
      "name": "Soil_Gravel"
    },
    {
      "x": 2,
      "y": 0,
      "z": -10,
      "name": "Soil_Gravel"
    },
    {
      "x": 2,
      "y": 0,
      "z": -9,
      "name": "Wood_Softwood_Planks"
    },
    {
      "x": 2,
      "y": 0,
      "z": -8,
      "name": "Soil_Clay"
    },
    {
      "x": 2,
      "y": 1,
      "z": -8,
      "name": "Wood_Hardwood_Fence"
    },
    {
      "x": 2,
      "y": 2,
      "z": -8,
      "name": "Wood_Hardwood_Fence"
    },
    {
      "x": 2,
      "y": 0,
      "z": -7,
      "name": "Soil_Clay"
    },
    {
      "x": 2,
      "y": 0,
      "z": -6,
      "name": "Soil_Clay"
    },
    {
      "x": 2,
      "y": 0,
      "z": -5,
      "name": "Soil_Clay"
    },
    {
      "x": 2,
      "y": 0,
      "z": -4,
      "name": "Soil_Clay"
    },
    {
      "x": 2,
      "y": 4,
      "z": -4,
      "name": "Wood_Ash_Trunk_Full",
      "rotation": 5
    },
    {
      "x": 2,
      "y": 0,
      "z": -3,
      "name": "Soil_Clay"
    },
    {
      "x": 2,
      "y": 0,
      "z": -2,
      "name": "Soil_Clay"
    },
    {
      "x": 2,
      "y": 0,
      "z": -1,
      "name": "Soil_Clay"
    },
    {
      "x": 2,
      "y": 0,
      "z": 0,
      "name": "Soil_Clay"
    },
    {
      "x": 2,
      "y": 0,
      "z": 1,
      "name": "Soil_Clay"
    },
    {
      "x": 2,
      "y": 0,
      "z": 2,
      "name": "Soil_Clay"
    },
    {
      "x": 2,
      "y": 0,
      "z": 3,
      "name": "Soil_Clay"
    },
    {
      "x": 2,
      "y": 0,
      "z": 4,
      "name": "Soil_Clay"
    },
    {
      "x": 2,
      "y": 0,
      "z": 5,
      "name": "Soil_Clay"
    },
    {
      "x": 2,
      "y": 0,
      "z": 6,
      "name": "Soil_Clay"
    },
    {
      "x": 2,
      "y": 0,
      "z": 7,
      "name": "Soil_Clay"
    },
    {
      "x": 2,
      "y": 0,
      "z": 8,
      "name": "Soil_Clay"
    },
    {
      "x": 2,
      "y": 4,
      "z": 8,
      "name": "Wood_Ash_Trunk_Full",
      "rotation": 5
    },
    {
      "x": 2,
      "y": 0,
      "z": 9,
      "name": "Soil_Clay"
    },
    {
      "x": 2,
      "y": 0,
      "z": 10,
      "name": "Soil_Clay"
    },
    {
      "x": 2,
      "y": 0,
      "z": 11,
      "name": "K2_Slot_Portal_3"
    },
    {
      "x": 2,
      "y": 0,
      "z": 12,
      "name": "Soil_Clay"
    },
    {
      "x": 2,
      "y": 1,
      "z": 12,
      "name": "Wood_Hardwood_Fence",
      "rotation": 2
    },
    {
      "x": 2,
      "y": 2,
      "z": 12,
      "name": "Wood_Hardwood_Fence",
      "rotation": 2
    },
    {
      "x": 2,
      "y": 0,
      "z": 13,
      "name": "Wood_Softwood_Planks"
    },
    {
      "x": 2,
      "y": 0,
      "z": 14,
      "name": "Wood_Softwood_Planks"
    },
    {
      "x": 2,
      "y": 0,
      "z": 15,
      "name": "Wood_Softwood_Planks"
    },
    {
      "x": 2,
      "y": 0,
      "z": 16,
      "name": "Wood_Softwood_Planks"
    },
    {
      "x": 3,
      "y": 0,
      "z": -15,
      "name": "Soil_Gravel"
    },
    {
      "x": 3,
      "y": 0,
      "z": -14,
      "name": "Soil_Gravel"
    },
    {
      "x": 3,
      "y": 0,
      "z": -13,
      "name": "Soil_Gravel"
    },
    {
      "x": 3,
      "y": 0,
      "z": -12,
      "name": "Soil_Gravel"
    },
    {
      "x": 3,
      "y": 0,
      "z": -11,
      "name": "Soil_Gravel"
    },
    {
      "x": 3,
      "y": 0,
      "z": -10,
      "name": "Soil_Gravel"
    },
    {
      "x": 3,
      "y": 0,
      "z": -9,
      "name": "Wood_Softwood_Planks"
    },
    {
      "x": 3,
      "y": 0,
      "z": -8,
      "name": "Soil_Clay"
    },
    {
      "x": 3,
      "y": 1,
      "z": -8,
      "name": "Wood_Hardwood_Fence"
    },
    {
      "x": 3,
      "y": 2,
      "z": -8,
      "name": "Wood_Hardwood_Fence"
    },
    {
      "x": 3,
      "y": 0,
      "z": -7,
      "name": "Soil_Clay"
    },
    {
      "x": 3,
      "y": 0,
      "z": -6,
      "name": "Soil_Clay"
    },
    {
      "x": 3,
      "y": 0,
      "z": -5,
      "name": "Soil_Clay"
    },
    {
      "x": 3,
      "y": 0,
      "z": -4,
      "name": "Soil_Clay"
    },
    {
      "x": 3,
      "y": 4,
      "z": -4,
      "name": "Wood_Ash_Trunk_Full",
      "rotation": 5
    },
    {
      "x": 3,
      "y": 0,
      "z": -3,
      "name": "Soil_Clay"
    },
    {
      "x": 3,
      "y": 0,
      "z": -2,
      "name": "Soil_Clay"
    },
    {
      "x": 3,
      "y": 0,
      "z": -1,
      "name": "Soil_Clay"
    },
    {
      "x": 3,
      "y": 0,
      "z": 0,
      "name": "Soil_Clay"
    },
    {
      "x": 3,
      "y": 0,
      "z": 1,
      "name": "Soil_Clay"
    },
    {
      "x": 3,
      "y": 0,
      "z": 2,
      "name": "Soil_Clay"
    },
    {
      "x": 3,
      "y": 0,
      "z": 3,
      "name": "Soil_Clay"
    },
    {
      "x": 3,
      "y": 0,
      "z": 4,
      "name": "Soil_Clay"
    },
    {
      "x": 3,
      "y": 0,
      "z": 5,
      "name": "Soil_Clay"
    },
    {
      "x": 3,
      "y": 0,
      "z": 6,
      "name": "Soil_Clay"
    },
    {
      "x": 3,
      "y": 0,
      "z": 7,
      "name": "Soil_Clay"
    },
    {
      "x": 3,
      "y": 0,
      "z": 8,
      "name": "Soil_Clay"
    },
    {
      "x": 3,
      "y": 4,
      "z": 8,
      "name": "Wood_Ash_Trunk_Full",
      "rotation": 5
    },
    {
      "x": 3,
      "y": 0,
      "z": 9,
      "name": "Soil_Clay"
    },
    {
      "x": 3,
      "y": 0,
      "z": 10,
      "name": "Soil_Clay"
    },
    {
      "x": 3,
      "y": 0,
      "z": 11,
      "name": "Soil_Clay"
    },
    {
      "x": 3,
      "y": 0,
      "z": 12,
      "name": "Soil_Clay"
    },
    {
      "x": 3,
      "y": 1,
      "z": 12,
      "name": "Wood_Hardwood_Fence",
      "rotation": 2
    },
    {
      "x": 3,
      "y": 2,
      "z": 12,
      "name": "Wood_Hardwood_Fence",
      "rotation": 2
    },
    {
      "x": 3,
      "y": 0,
      "z": 13,
      "name": "Wood_Softwood_Planks"
    },
    {
      "x": 3,
      "y": 0,
      "z": 14,
      "name": "Wood_Softwood_Planks"
    },
    {
      "x": 3,
      "y": 0,
      "z": 15,
      "name": "Wood_Softwood_Planks"
    },
    {
      "x": 3,
      "y": 0,
      "z": 16,
      "name": "Wood_Softwood_Planks"
    },
    {
      "x": 4,
      "y": 0,
      "z": -15,
      "name": "Soil_Gravel"
    },
    {
      "x": 4,
      "y": 0,
      "z": -14,
      "name": "Soil_Gravel"
    },
    {
      "x": 4,
      "y": 0,
      "z": -13,
      "name": "Soil_Gravel"
    },
    {
      "x": 4,
      "y": 0,
      "z": -12,
      "name": "Soil_Gravel"
    },
    {
      "x": 4,
      "y": 0,
      "z": -11,
      "name": "Soil_Gravel"
    },
    {
      "x": 4,
      "y": 0,
      "z": -10,
      "name": "Soil_Gravel"
    },
    {
      "x": 4,
      "y": 0,
      "z": -9,
      "name": "Wood_Softwood_Planks"
    },
    {
      "x": 4,
      "y": 0,
      "z": -8,
      "name": "Soil_Clay"
    },
    {
      "x": 4,
      "y": 1,
      "z": -8,
      "name": "*Wood_Hardwood_Fence_State_Definitions_Corner"
    },
    {
      "x": 4,
      "y": 2,
      "z": -8,
      "name": "*Wood_Hardwood_Fence_State_Definitions_Corner"
    },
    {
      "x": 4,
      "y": 0,
      "z": -7,
      "name": "Soil_Clay"
    },
    {
      "x": 4,
      "y": 1,
      "z": -7,
      "name": "Wood_Hardwood_Fence",
      "rotation": 3
    },
    {
      "x": 4,
      "y": 2,
      "z": -7,
      "name": "Wood_Hardwood_Fence",
      "rotation": 3
    },
    {
      "x": 4,
      "y": 0,
      "z": -6,
      "name": "Soil_Clay"
    },
    {
      "x": 4,
      "y": 1,
      "z": -6,
      "name": "Wood_Hardwood_Fence",
      "rotation": 3
    },
    {
      "x": 4,
      "y": 2,
      "z": -6,
      "name": "Wood_Hardwood_Fence",
      "rotation": 3
    },
    {
      "x": 4,
      "y": 4,
      "z": -6,
      "name": "Wood_Ash_Trunk",
      "rotation": 4
    },
    {
      "x": 4,
      "y": 0,
      "z": -5,
      "name": "Wood_Ash_Trunk_Full"
    },
    {
      "x": 4,
      "y": 1,
      "z": -5,
      "name": "Wood_Ash_Trunk_Full"
    },
    {
      "x": 4,
      "y": 2,
      "z": -5,
      "name": "Wood_Ash_Trunk_Full"
    },
    {
      "x": 4,
      "y": 3,
      "z": -5,
      "name": "Wood_Ash_Trunk_Full"
    },
    {
      "x": 4,
      "y": 4,
      "z": -5,
      "name": "Wood_Ash_Trunk_Full",
      "rotation": 4
    },
    {
      "x": 4,
      "y": 0,
      "z": -4,
      "name": "Soil_Clay"
    },
    {
      "x": 4,
      "y": 3,
      "z": -4,
      "name": "Wood_Hardwood_Planks_Half",
      "rotation": 8
    },
    {
      "x": 4,
      "y": 4,
      "z": -4,
      "name": "Wood_Ash_Trunk_Full",
      "rotation": 5
    },
    {
      "x": 4,
      "y": 5,
      "z": -4,
      "name": "Wood_Hardwood_Planks_Half"
    },
    {
      "x": 4,
      "y": 0,
      "z": -3,
      "name": "Soil_Clay"
    },
    {
      "x": 4,
      "y": 4,
      "z": -3,
      "name": "Wood_Hardwood_Planks_Half",
      "rotation": 4
    },
    {
      "x": 4,
      "y": 0,
      "z": -2,
      "name": "Soil_Clay"
    },
    {
      "x": 4,
      "y": 0,
      "z": -1,
      "name": "Soil_Clay"
    },
    {
      "x": 4,
      "y": 0,
      "z": 0,
      "name": "Soil_Clay"
    },
    {
      "x": 4,
      "y": 0,
      "z": 1,
      "name": "Soil_Clay"
    },
    {
      "x": 4,
      "y": 0,
      "z": 2,
      "name": "Soil_Clay"
    },
    {
      "x": 4,
      "y": 0,
      "z": 3,
      "name": "Soil_Clay"
    },
    {
      "x": 4,
      "y": 0,
      "z": 4,
      "name": "Soil_Clay"
    },
    {
      "x": 4,
      "y": 0,
      "z": 5,
      "name": "Soil_Clay"
    },
    {
      "x": 4,
      "y": 0,
      "z": 6,
      "name": "Soil_Clay"
    },
    {
      "x": 4,
      "y": 0,
      "z": 7,
      "name": "Soil_Clay"
    },
    {
      "x": 4,
      "y": 4,
      "z": 7,
      "name": "Wood_Hardwood_Planks_Half",
      "rotation": 6
    },
    {
      "x": 4,
      "y": 0,
      "z": 8,
      "name": "Soil_Clay"
    },
    {
      "x": 4,
      "y": 3,
      "z": 8,
      "name": "Wood_Hardwood_Planks_Half",
      "rotation": 8
    },
    {
      "x": 4,
      "y": 4,
      "z": 8,
      "name": "Wood_Ash_Trunk_Full",
      "rotation": 5
    },
    {
      "x": 4,
      "y": 5,
      "z": 8,
      "name": "Wood_Hardwood_Planks_Half"
    },
    {
      "x": 4,
      "y": 0,
      "z": 9,
      "name": "Wood_Ash_Trunk_Full"
    },
    {
      "x": 4,
      "y": 1,
      "z": 9,
      "name": "Wood_Ash_Trunk_Full"
    },
    {
      "x": 4,
      "y": 2,
      "z": 9,
      "name": "Wood_Ash_Trunk_Full"
    },
    {
      "x": 4,
      "y": 3,
      "z": 9,
      "name": "Wood_Ash_Trunk_Full"
    },
    {
      "x": 4,
      "y": 4,
      "z": 9,
      "name": "Wood_Ash_Trunk_Full",
      "rotation": 4
    },
    {
      "x": 4,
      "y": 0,
      "z": 10,
      "name": "Soil_Clay"
    },
    {
      "x": 4,
      "y": 1,
      "z": 10,
      "name": "Wood_Hardwood_Fence",
      "rotation": 3
    },
    {
      "x": 4,
      "y": 2,
      "z": 10,
      "name": "Wood_Hardwood_Fence",
      "rotation": 3
    },
    {
      "x": 4,
      "y": 4,
      "z": 10,
      "name": "Wood_Ash_Trunk",
      "rotation": 4
    },
    {
      "x": 4,
      "y": 0,
      "z": 11,
      "name": "Soil_Clay"
    },
    {
      "x": 4,
      "y": 1,
      "z": 11,
      "name": "Wood_Hardwood_Fence",
      "rotation": 3
    },
    {
      "x": 4,
      "y": 2,
      "z": 11,
      "name": "Wood_Hardwood_Fence",
      "rotation": 3
    },
    {
      "x": 4,
      "y": 0,
      "z": 12,
      "name": "Soil_Clay"
    },
    {
      "x": 4,
      "y": 1,
      "z": 12,
      "name": "*Wood_Hardwood_Fence_State_Definitions_Corner",
      "rotation": 3
    },
    {
      "x": 4,
      "y": 2,
      "z": 12,
      "name": "*Wood_Hardwood_Fence_State_Definitions_Corner",
      "rotation": 3
    },
    {
      "x": 4,
      "y": 0,
      "z": 13,
      "name": "Wood_Softwood_Planks"
    },
    {
      "x": 4,
      "y": 0,
      "z": 14,
      "name": "Wood_Softwood_Planks"
    },
    {
      "x": 4,
      "y": 0,
      "z": 15,
      "name": "Wood_Softwood_Planks"
    },
    {
      "x": 4,
      "y": 0,
      "z": 16,
      "name": "Wood_Softwood_Planks"
    },
    {
      "x": 5,
      "y": 0,
      "z": -15,
      "name": "Soil_Gravel"
    },
    {
      "x": 5,
      "y": 0,
      "z": -14,
      "name": "Soil_Gravel"
    },
    {
      "x": 5,
      "y": 0,
      "z": -13,
      "name": "Soil_Gravel"
    },
    {
      "x": 5,
      "y": 0,
      "z": -12,
      "name": "Soil_Gravel"
    },
    {
      "x": 5,
      "y": 0,
      "z": -11,
      "name": "Soil_Gravel"
    },
    {
      "x": 5,
      "y": 0,
      "z": -10,
      "name": "Soil_Gravel"
    },
    {
      "x": 5,
      "y": 0,
      "z": -9,
      "name": "Wood_Softwood_Planks"
    },
    {
      "x": 5,
      "y": 0,
      "z": -8,
      "name": "Wood_Softwood_Planks"
    },
    {
      "x": 5,
      "y": 0,
      "z": -7,
      "name": "Wood_Softwood_Planks"
    },
    {
      "x": 5,
      "y": 0,
      "z": -6,
      "name": "Wood_Softwood_Planks"
    },
    {
      "x": 5,
      "y": 0,
      "z": -5,
      "name": "Wood_Softwood_Planks"
    },
    {
      "x": 5,
      "y": 0,
      "z": -4,
      "name": "Wood_Hardwood_Planks"
    },
    {
      "x": 5,
      "y": 1,
      "z": -4,
      "name": "Wood_Hardwood_Planks"
    },
    {
      "x": 5,
      "y": 2,
      "z": -4,
      "name": "Wood_Hardwood_Planks"
    },
    {
      "x": 5,
      "y": 3,
      "z": -4,
      "name": "Wood_Hardwood_Planks"
    },
    {
      "x": 5,
      "y": 4,
      "z": -4,
      "name": "Wood_Ash_Trunk_Full",
      "rotation": 5
    },
    {
      "x": 5,
      "y": 0,
      "z": -3,
      "name": "Soil_Clay"
    },
    {
      "x": 5,
      "y": 1,
      "z": -3,
      "name": "*Wood_Hardwood_Fence_State_Definitions_Corner",
      "rotation": 2
    },
    {
      "x": 5,
      "y": 2,
      "z": -3,
      "name": "Deco_Lantern"
    },
    {
      "x": 5,
      "y": 0,
      "z": -2,
      "name": "Soil_Clay"
    },
    {
      "x": 5,
      "y": 4,
      "z": -2,
      "name": "Wood_Hardwood_Planks_Half",
      "rotation": 7
    },
    {
      "x": 5,
      "y": 0,
      "z": -1,
      "name": "Soil_Clay"
    },
    {
      "x": 5,
      "y": 0,
      "z": 0,
      "name": "Soil_Clay"
    },
    {
      "x": 5,
      "y": 0,
      "z": 1,
      "name": "Plant_Crop_Mushroom_Block_Brown"
    },
    {
      "x": 5,
      "y": 0,
      "z": 2,
      "name": "Plant_Crop_Mushroom_Block_Brown"
    },
    {
      "x": 5,
      "y": 1,
      "z": 2,
      "name": "Wood_Hardwood_Fence",
      "rotation": 3
    },
    {
      "x": 5,
      "y": 3,
      "z": 2,
      "name": "Wood_Torch_Wall",
      "rotation": 3
    },
    {
      "x": 5,
      "y": 0,
      "z": 3,
      "name": "Plant_Crop_Mushroom_Block_Brown"
    },
    {
      "x": 5,
      "y": 0,
      "z": 4,
      "name": "Soil_Clay"
    },
    {
      "x": 5,
      "y": 0,
      "z": 5,
      "name": "Soil_Clay"
    },
    {
      "x": 5,
      "y": 0,
      "z": 6,
      "name": "Soil_Clay"
    },
    {
      "x": 5,
      "y": 4,
      "z": 6,
      "name": "Wood_Hardwood_Planks_Half",
      "rotation": 7
    },
    {
      "x": 5,
      "y": 0,
      "z": 7,
      "name": "Soil_Clay"
    },
    {
      "x": 5,
      "y": 1,
      "z": 7,
      "name": "*Wood_Hardwood_Fence_State_Definitions_Corner",
      "rotation": 1
    },
    {
      "x": 5,
      "y": 2,
      "z": 7,
      "name": "Deco_Lantern"
    },
    {
      "x": 5,
      "y": 0,
      "z": 8,
      "name": "Wood_Hardwood_Planks"
    },
    {
      "x": 5,
      "y": 1,
      "z": 8,
      "name": "Wood_Hardwood_Planks"
    },
    {
      "x": 5,
      "y": 2,
      "z": 8,
      "name": "Wood_Hardwood_Planks"
    },
    {
      "x": 5,
      "y": 3,
      "z": 8,
      "name": "Wood_Hardwood_Planks"
    },
    {
      "x": 5,
      "y": 4,
      "z": 8,
      "name": "Wood_Ash_Trunk_Full",
      "rotation": 5
    },
    {
      "x": 5,
      "y": 0,
      "z": 9,
      "name": "Wood_Softwood_Planks"
    },
    {
      "x": 5,
      "y": 0,
      "z": 10,
      "name": "Wood_Softwood_Planks"
    },
    {
      "x": 5,
      "y": 0,
      "z": 11,
      "name": "Wood_Softwood_Planks"
    },
    {
      "x": 5,
      "y": 0,
      "z": 12,
      "name": "Wood_Softwood_Planks"
    },
    {
      "x": 5,
      "y": 0,
      "z": 13,
      "name": "Wood_Softwood_Planks"
    },
    {
      "x": 5,
      "y": 0,
      "z": 14,
      "name": "Wood_Softwood_Planks"
    },
    {
      "x": 5,
      "y": 0,
      "z": 15,
      "name": "Wood_Softwood_Planks"
    },
    {
      "x": 5,
      "y": 0,
      "z": 16,
      "name": "Wood_Softwood_Planks"
    },
    {
      "x": 6,
      "y": 0,
      "z": -15,
      "name": "Soil_Gravel"
    },
    {
      "x": 6,
      "y": 0,
      "z": -14,
      "name": "Soil_Gravel"
    },
    {
      "x": 6,
      "y": 0,
      "z": -13,
      "name": "Soil_Gravel"
    },
    {
      "x": 6,
      "y": 0,
      "z": -12,
      "name": "Soil_Gravel"
    },
    {
      "x": 6,
      "y": 0,
      "z": -11,
      "name": "Soil_Gravel"
    },
    {
      "x": 6,
      "y": 0,
      "z": -10,
      "name": "Soil_Gravel"
    },
    {
      "x": 6,
      "y": 0,
      "z": -9,
      "name": "Wood_Softwood_Planks"
    },
    {
      "x": 6,
      "y": 0,
      "z": -8,
      "name": "Wood_Softwood_Planks"
    },
    {
      "x": 6,
      "y": 0,
      "z": -7,
      "name": "Wood_Softwood_Planks"
    },
    {
      "x": 6,
      "y": 0,
      "z": -6,
      "name": "Wood_Softwood_Planks"
    },
    {
      "x": 6,
      "y": 0,
      "z": -5,
      "name": "Wood_Softwood_Planks"
    },
    {
      "x": 6,
      "y": 0,
      "z": -4,
      "name": "Wood_Ash_Trunk_Full"
    },
    {
      "x": 6,
      "y": 1,
      "z": -4,
      "name": "Wood_Ash_Trunk_Full"
    },
    {
      "x": 6,
      "y": 2,
      "z": -4,
      "name": "Wood_Ash_Trunk_Full"
    },
    {
      "x": 6,
      "y": 3,
      "z": -4,
      "name": "Wood_Ash_Trunk_Full"
    },
    {
      "x": 6,
      "y": 4,
      "z": -4,
      "name": "Wood_Ash_Trunk_Full"
    },
    {
      "x": 6,
      "y": 5,
      "z": -4,
      "name": "Wood_Ash_Trunk"
    },
    {
      "x": 6,
      "y": 0,
      "z": -3,
      "name": "Wood_Hardwood_Planks"
    },
    {
      "x": 6,
      "y": 1,
      "z": -3,
      "name": "Wood_Hardwood_Planks"
    },
    {
      "x": 6,
      "y": 2,
      "z": -3,
      "name": "Wood_Hardwood_Planks"
    },
    {
      "x": 6,
      "y": 3,
      "z": -3,
      "name": "Wood_Hardwood_Planks"
    },
    {
      "x": 6,
      "y": 4,
      "z": -3,
      "name": "Wood_Ash_Trunk_Full",
      "rotation": 4
    },
    {
      "x": 6,
      "y": 0,
      "z": -2,
      "name": "Soil_Clay"
    },
    {
      "x": 6,
      "y": 3,
      "z": -2,
      "name": "Wood_Hardwood_Planks_Half",
      "rotation": 8
    },
    {
      "x": 6,
      "y": 4,
      "z": -2,
      "name": "Wood_Ash_Trunk_Full",
      "rotation": 4
    },
    {
      "x": 6,
      "y": 5,
      "z": -2,
      "name": "Wood_Hardwood_Planks_Half"
    },
    {
      "x": 6,
      "y": 0,
      "z": -1,
      "name": "Soil_Clay"
    },
    {
      "x": 6,
      "y": 4,
      "z": -1,
      "name": "Wood_Ash_Trunk_Full",
      "rotation": 4
    },
    {
      "x": 6,
      "y": 0,
      "z": 0,
      "name": "Soil_Clay"
    },
    {
      "x": 6,
      "y": 4,
      "z": 0,
      "name": "Wood_Ash_Trunk_Full",
      "rotation": 4
    },
    {
      "x": 6,
      "y": 0,
      "z": 1,
      "name": "Plant_Crop_Mushroom_Block_Brown"
    },
    {
      "x": 6,
      "y": 4,
      "z": 1,
      "name": "Wood_Ash_Trunk_Full",
      "rotation": 4
    },
    {
      "x": 6,
      "y": 0,
      "z": 2,
      "name": "Plant_Crop_Mushroom_Block_Brown"
    },
    {
      "x": 6,
      "y": 1,
      "z": 2,
      "name": "Wood_Ash_Trunk_Full"
    },
    {
      "x": 6,
      "y": 2,
      "z": 2,
      "name": "Wood_Ash_Trunk_Full"
    },
    {
      "x": 6,
      "y": 3,
      "z": 2,
      "name": "Wood_Ash_Trunk_Full"
    },
    {
      "x": 6,
      "y": 4,
      "z": 2,
      "name": "Wood_Ash_Trunk_Full"
    },
    {
      "x": 6,
      "y": 5,
      "z": 2,
      "name": "Wood_Ash_Trunk"
    },
    {
      "x": 6,
      "y": 6,
      "z": 2,
      "name": "Wood_Hardwood_Planks_Half"
    },
    {
      "x": 6,
      "y": 0,
      "z": 3,
      "name": "Plant_Crop_Mushroom_Block_Brown"
    },
    {
      "x": 6,
      "y": 4,
      "z": 3,
      "name": "Wood_Ash_Trunk_Full",
      "rotation": 4
    },
    {
      "x": 6,
      "y": 0,
      "z": 4,
      "name": "Soil_Clay"
    },
    {
      "x": 6,
      "y": 4,
      "z": 4,
      "name": "Wood_Ash_Trunk_Full",
      "rotation": 4
    },
    {
      "x": 6,
      "y": 0,
      "z": 5,
      "name": "Soil_Clay"
    },
    {
      "x": 6,
      "y": 4,
      "z": 5,
      "name": "Wood_Ash_Trunk_Full",
      "rotation": 4
    },
    {
      "x": 6,
      "y": 0,
      "z": 6,
      "name": "Soil_Clay"
    },
    {
      "x": 6,
      "y": 3,
      "z": 6,
      "name": "Wood_Hardwood_Planks_Half",
      "rotation": 8
    },
    {
      "x": 6,
      "y": 4,
      "z": 6,
      "name": "Wood_Ash_Trunk_Full",
      "rotation": 4
    },
    {
      "x": 6,
      "y": 5,
      "z": 6,
      "name": "Wood_Hardwood_Planks_Half"
    },
    {
      "x": 6,
      "y": 0,
      "z": 7,
      "name": "Wood_Hardwood_Planks"
    },
    {
      "x": 6,
      "y": 1,
      "z": 7,
      "name": "Wood_Hardwood_Planks"
    },
    {
      "x": 6,
      "y": 2,
      "z": 7,
      "name": "Wood_Hardwood_Planks"
    },
    {
      "x": 6,
      "y": 3,
      "z": 7,
      "name": "Wood_Hardwood_Planks"
    },
    {
      "x": 6,
      "y": 4,
      "z": 7,
      "name": "Wood_Ash_Trunk_Full",
      "rotation": 4
    },
    {
      "x": 6,
      "y": 0,
      "z": 8,
      "name": "Wood_Ash_Trunk_Full"
    },
    {
      "x": 6,
      "y": 1,
      "z": 8,
      "name": "Wood_Ash_Trunk_Full"
    },
    {
      "x": 6,
      "y": 2,
      "z": 8,
      "name": "Wood_Ash_Trunk_Full"
    },
    {
      "x": 6,
      "y": 3,
      "z": 8,
      "name": "Wood_Ash_Trunk_Full"
    },
    {
      "x": 6,
      "y": 4,
      "z": 8,
      "name": "Wood_Ash_Trunk_Full"
    },
    {
      "x": 6,
      "y": 5,
      "z": 8,
      "name": "Wood_Ash_Trunk"
    },
    {
      "x": 6,
      "y": 0,
      "z": 9,
      "name": "Wood_Softwood_Planks"
    },
    {
      "x": 6,
      "y": 0,
      "z": 10,
      "name": "Wood_Softwood_Planks"
    },
    {
      "x": 6,
      "y": 0,
      "z": 11,
      "name": "Wood_Softwood_Planks"
    },
    {
      "x": 6,
      "y": 0,
      "z": 12,
      "name": "Wood_Softwood_Planks"
    },
    {
      "x": 6,
      "y": 0,
      "z": 13,
      "name": "Wood_Softwood_Planks"
    },
    {
      "x": 6,
      "y": 0,
      "z": 14,
      "name": "Wood_Softwood_Planks"
    },
    {
      "x": 6,
      "y": 0,
      "z": 15,
      "name": "Wood_Softwood_Planks"
    },
    {
      "x": 6,
      "y": 0,
      "z": 16,
      "name": "Wood_Softwood_Planks"
    },
    {
      "x": 7,
      "y": 0,
      "z": -15,
      "name": "Soil_Gravel"
    },
    {
      "x": 7,
      "y": 0,
      "z": -14,
      "name": "Soil_Gravel"
    },
    {
      "x": 7,
      "y": 0,
      "z": -13,
      "name": "Soil_Gravel"
    },
    {
      "x": 7,
      "y": 0,
      "z": -12,
      "name": "Soil_Gravel"
    },
    {
      "x": 7,
      "y": 0,
      "z": -11,
      "name": "Soil_Gravel"
    },
    {
      "x": 7,
      "y": 0,
      "z": -10,
      "name": "Soil_Gravel"
    },
    {
      "x": 7,
      "y": 0,
      "z": -9,
      "name": "Wood_Softwood_Planks"
    },
    {
      "x": 7,
      "y": 0,
      "z": -8,
      "name": "Wood_Softwood_Planks"
    },
    {
      "x": 7,
      "y": 0,
      "z": -7,
      "name": "Wood_Softwood_Planks"
    },
    {
      "x": 7,
      "y": 0,
      "z": -6,
      "name": "Wood_Softwood_Planks"
    },
    {
      "x": 7,
      "y": 0,
      "z": -5,
      "name": "Wood_Softwood_Planks"
    },
    {
      "x": 7,
      "y": 0,
      "z": -4,
      "name": "Wood_Softwood_Planks"
    },
    {
      "x": 7,
      "y": 0,
      "z": -3,
      "name": "Wood_Softwood_Planks"
    },
    {
      "x": 7,
      "y": 0,
      "z": -2,
      "name": "Soil_Clay"
    },
    {
      "x": 7,
      "y": 1,
      "z": -2,
      "name": "Wood_Ash_Trunk_Full"
    },
    {
      "x": 7,
      "y": 2,
      "z": -2,
      "name": "Wood_Ash_Trunk_Full"
    },
    {
      "x": 7,
      "y": 3,
      "z": -2,
      "name": "Wood_Ash_Trunk_Full"
    },
    {
      "x": 7,
      "y": 4,
      "z": -2,
      "name": "Wood_Ash_Trunk_Full",
      "rotation": 5
    },
    {
      "x": 7,
      "y": 0,
      "z": -1,
      "name": "Soil_Clay"
    },
    {
      "x": 7,
      "y": 0,
      "z": 0,
      "name": "Soil_Clay"
    },
    {
      "x": 7,
      "y": 0,
      "z": 1,
      "name": "Plant_Crop_Mushroom_Block_Brown"
    },
    {
      "x": 7,
      "y": 0,
      "z": 2,
      "name": "Plant_Crop_Mushroom_Block_Brown"
    },
    {
      "x": 7,
      "y": 0,
      "z": 3,
      "name": "Plant_Crop_Mushroom_Block_Brown"
    },
    {
      "x": 7,
      "y": 0,
      "z": 4,
      "name": "Soil_Clay"
    },
    {
      "x": 7,
      "y": 0,
      "z": 5,
      "name": "Soil_Clay"
    },
    {
      "x": 7,
      "y": 0,
      "z": 6,
      "name": "Soil_Clay"
    },
    {
      "x": 7,
      "y": 1,
      "z": 6,
      "name": "Wood_Ash_Trunk_Full"
    },
    {
      "x": 7,
      "y": 2,
      "z": 6,
      "name": "Wood_Ash_Trunk_Full"
    },
    {
      "x": 7,
      "y": 3,
      "z": 6,
      "name": "Wood_Ash_Trunk_Full"
    },
    {
      "x": 7,
      "y": 4,
      "z": 6,
      "name": "Wood_Ash_Trunk_Full",
      "rotation": 5
    },
    {
      "x": 7,
      "y": 0,
      "z": 7,
      "name": "Wood_Softwood_Planks"
    },
    {
      "x": 7,
      "y": 0,
      "z": 8,
      "name": "Wood_Softwood_Planks"
    },
    {
      "x": 7,
      "y": 0,
      "z": 9,
      "name": "Wood_Softwood_Planks"
    },
    {
      "x": 7,
      "y": 0,
      "z": 10,
      "name": "Wood_Softwood_Planks"
    },
    {
      "x": 7,
      "y": 0,
      "z": 11,
      "name": "Wood_Softwood_Planks"
    },
    {
      "x": 7,
      "y": 0,
      "z": 12,
      "name": "Wood_Softwood_Planks"
    },
    {
      "x": 7,
      "y": 0,
      "z": 13,
      "name": "Wood_Softwood_Planks"
    },
    {
      "x": 7,
      "y": 0,
      "z": 14,
      "name": "Wood_Softwood_Planks"
    },
    {
      "x": 7,
      "y": 0,
      "z": 15,
      "name": "Wood_Softwood_Planks"
    },
    {
      "x": 7,
      "y": 0,
      "z": 16,
      "name": "Wood_Softwood_Planks"
    },
    {
      "x": 8,
      "y": 0,
      "z": -15,
      "name": "Soil_Gravel"
    },
    {
      "x": 8,
      "y": 0,
      "z": -14,
      "name": "Soil_Gravel"
    },
    {
      "x": 8,
      "y": 0,
      "z": -13,
      "name": "Soil_Gravel"
    },
    {
      "x": 8,
      "y": 0,
      "z": -12,
      "name": "Soil_Gravel"
    },
    {
      "x": 8,
      "y": 0,
      "z": -11,
      "name": "Soil_Gravel"
    },
    {
      "x": 8,
      "y": 0,
      "z": -10,
      "name": "Soil_Gravel"
    },
    {
      "x": 8,
      "y": 0,
      "z": -9,
      "name": "Wood_Softwood_Planks"
    },
    {
      "x": 8,
      "y": 0,
      "z": -8,
      "name": "Wood_Softwood_Planks"
    },
    {
      "x": 8,
      "y": 0,
      "z": -7,
      "name": "Wood_Softwood_Planks"
    },
    {
      "x": 8,
      "y": 0,
      "z": -6,
      "name": "Wood_Softwood_Planks"
    },
    {
      "x": 8,
      "y": 0,
      "z": -5,
      "name": "Wood_Softwood_Planks"
    },
    {
      "x": 8,
      "y": 0,
      "z": -4,
      "name": "Wood_Softwood_Planks"
    },
    {
      "x": 8,
      "y": 0,
      "z": -3,
      "name": "Wood_Softwood_Planks"
    },
    {
      "x": 8,
      "y": 0,
      "z": -2,
      "name": "Soil_Clay"
    },
    {
      "x": 8,
      "y": 1,
      "z": -2,
      "name": "Wood_Hardwood_Fence"
    },
    {
      "x": 8,
      "y": 2,
      "z": -2,
      "name": "Wood_Hardwood_Fence"
    },
    {
      "x": 8,
      "y": 4,
      "z": -2,
      "name": "Wood_Ash_Trunk",
      "rotation": 5
    },
    {
      "x": 8,
      "y": 0,
      "z": -1,
      "name": "Soil_Clay"
    },
    {
      "x": 8,
      "y": 0,
      "z": 0,
      "name": "K2_Slot_Portal_1"
    },
    {
      "x": 8,
      "y": 0,
      "z": 1,
      "name": "Soil_Clay"
    },
    {
      "x": 8,
      "y": 0,
      "z": 2,
      "name": "Soil_Clay"
    },
    {
      "x": 8,
      "y": 0,
      "z": 3,
      "name": "Soil_Clay"
    },
    {
      "x": 8,
      "y": 0,
      "z": 4,
      "name": "Soil_Clay"
    },
    {
      "x": 8,
      "y": 0,
      "z": 5,
      "name": "K2_Slot_Portal_2"
    },
    {
      "x": 8,
      "y": 0,
      "z": 6,
      "name": "Soil_Clay"
    },
    {
      "x": 8,
      "y": 1,
      "z": 6,
      "name": "Wood_Hardwood_Fence",
      "rotation": 2
    },
    {
      "x": 8,
      "y": 2,
      "z": 6,
      "name": "Wood_Hardwood_Fence",
      "rotation": 2
    },
    {
      "x": 8,
      "y": 4,
      "z": 6,
      "name": "Wood_Ash_Trunk",
      "rotation": 5
    },
    {
      "x": 8,
      "y": 0,
      "z": 7,
      "name": "Wood_Softwood_Planks"
    },
    {
      "x": 8,
      "y": 0,
      "z": 8,
      "name": "Wood_Softwood_Planks"
    },
    {
      "x": 8,
      "y": 0,
      "z": 9,
      "name": "Wood_Softwood_Planks"
    },
    {
      "x": 8,
      "y": 0,
      "z": 10,
      "name": "Wood_Softwood_Planks"
    },
    {
      "x": 8,
      "y": 0,
      "z": 11,
      "name": "Wood_Softwood_Planks"
    },
    {
      "x": 8,
      "y": 0,
      "z": 12,
      "name": "Wood_Softwood_Planks"
    },
    {
      "x": 8,
      "y": 0,
      "z": 13,
      "name": "Wood_Softwood_Planks"
    },
    {
      "x": 8,
      "y": 0,
      "z": 14,
      "name": "Wood_Softwood_Planks"
    },
    {
      "x": 8,
      "y": 0,
      "z": 15,
      "name": "Wood_Softwood_Planks"
    },
    {
      "x": 8,
      "y": 0,
      "z": 16,
      "name": "Wood_Softwood_Planks"
    },
    {
      "x": 9,
      "y": 0,
      "z": -15,
      "name": "Soil_Gravel"
    },
    {
      "x": 9,
      "y": 0,
      "z": -14,
      "name": "Soil_Gravel"
    },
    {
      "x": 9,
      "y": 0,
      "z": -13,
      "name": "Soil_Gravel"
    },
    {
      "x": 9,
      "y": 0,
      "z": -12,
      "name": "Soil_Gravel"
    },
    {
      "x": 9,
      "y": 0,
      "z": -11,
      "name": "Soil_Gravel"
    },
    {
      "x": 9,
      "y": 0,
      "z": -10,
      "name": "Soil_Gravel"
    },
    {
      "x": 9,
      "y": 0,
      "z": -9,
      "name": "Wood_Softwood_Planks"
    },
    {
      "x": 9,
      "y": 0,
      "z": -8,
      "name": "Wood_Softwood_Planks"
    },
    {
      "x": 9,
      "y": 0,
      "z": -7,
      "name": "Wood_Softwood_Planks"
    },
    {
      "x": 9,
      "y": 0,
      "z": -6,
      "name": "Wood_Softwood_Planks"
    },
    {
      "x": 9,
      "y": 0,
      "z": -5,
      "name": "Wood_Softwood_Planks"
    },
    {
      "x": 9,
      "y": 0,
      "z": -4,
      "name": "Wood_Softwood_Planks"
    },
    {
      "x": 9,
      "y": 0,
      "z": -3,
      "name": "Wood_Softwood_Planks"
    },
    {
      "x": 9,
      "y": 0,
      "z": -2,
      "name": "Soil_Clay"
    },
    {
      "x": 9,
      "y": 1,
      "z": -2,
      "name": "Wood_Hardwood_Fence"
    },
    {
      "x": 9,
      "y": 2,
      "z": -2,
      "name": "Wood_Hardwood_Fence"
    },
    {
      "x": 9,
      "y": 0,
      "z": -1,
      "name": "Soil_Clay"
    },
    {
      "x": 9,
      "y": 0,
      "z": 0,
      "name": "Soil_Clay"
    },
    {
      "x": 9,
      "y": 0,
      "z": 1,
      "name": "Soil_Clay"
    },
    {
      "x": 9,
      "y": 0,
      "z": 2,
      "name": "Soil_Clay"
    },
    {
      "x": 9,
      "y": 0,
      "z": 3,
      "name": "Soil_Clay"
    },
    {
      "x": 9,
      "y": 0,
      "z": 4,
      "name": "Soil_Clay"
    },
    {
      "x": 9,
      "y": 0,
      "z": 5,
      "name": "Soil_Clay"
    },
    {
      "x": 9,
      "y": 0,
      "z": 6,
      "name": "Soil_Clay"
    },
    {
      "x": 9,
      "y": 1,
      "z": 6,
      "name": "Wood_Hardwood_Fence",
      "rotation": 2
    },
    {
      "x": 9,
      "y": 2,
      "z": 6,
      "name": "Wood_Hardwood_Fence",
      "rotation": 2
    },
    {
      "x": 9,
      "y": 0,
      "z": 7,
      "name": "Wood_Softwood_Planks"
    },
    {
      "x": 9,
      "y": 0,
      "z": 8,
      "name": "Wood_Softwood_Planks"
    },
    {
      "x": 9,
      "y": 0,
      "z": 9,
      "name": "Wood_Softwood_Planks"
    },
    {
      "x": 9,
      "y": 0,
      "z": 10,
      "name": "Wood_Softwood_Planks"
    },
    {
      "x": 9,
      "y": 0,
      "z": 11,
      "name": "Wood_Softwood_Planks"
    },
    {
      "x": 9,
      "y": 0,
      "z": 12,
      "name": "Wood_Softwood_Planks"
    },
    {
      "x": 9,
      "y": 0,
      "z": 13,
      "name": "Wood_Softwood_Planks"
    },
    {
      "x": 9,
      "y": 0,
      "z": 14,
      "name": "Wood_Softwood_Planks"
    },
    {
      "x": 9,
      "y": 0,
      "z": 15,
      "name": "Wood_Softwood_Planks"
