{
  "version": 8,
  "blockIdVersion": 11,
  "anchorX": 0,
  "anchorY": 0,
  "anchorZ": 0,
  "blocks": [
    {
      "x": -15,
      "y": 0,
      "z": -15,
      "name": "Soil_Dirt"
    },
    {
      "x": -15,
      "y": 1,
      "z": -15,
      "name": "Soil_Dirt"
    },
    {
      "x": -15,
      "y": 2,
      "z": -15,
      "name": "Soil_Dirt"
    },
    {
      "x": -15,
      "y": 3,
      "z": -15,
      "name": "Soil_Grass"
    },
    {
      "x": -15,
      "y": 0,
      "z": -14,
      "name": "Soil_Dirt"
    },
    {
      "x": -15,
      "y": 1,
      "z": -14,
      "name": "Soil_Dirt"
    },
    {
      "x": -15,
      "y": 2,
      "z": -14,
      "name": "Soil_Dirt"
    },
    {
      "x": -15,
      "y": 3,
      "z": -14,
      "name": "Soil_Grass"
    },
    {
      "x": -15,
      "y": 0,
      "z": -13,
      "name": "Soil_Dirt"
    },
    {
      "x": -15,
      "y": 1,
      "z": -13,
      "name": "Soil_Dirt"
    },
    {
      "x": -15,
      "y": 2,
      "z": -13,
      "name": "Soil_Dirt"
    },
    {
      "x": -15,
      "y": 3,
      "z": -13,
      "name": "Soil_Grass"
    },
    {
      "x": -15,
      "y": 0,
      "z": -12,
      "name": "Soil_Dirt"
    },
    {
      "x": -15,
      "y": 1,
      "z": -12,
      "name": "Soil_Dirt"
    },
    {
      "x": -15,
      "y": 2,
      "z": -12,
      "name": "Soil_Dirt"
    },
    {
      "x": -15,
      "y": 3,
      "z": -12,
      "name": "Soil_Grass"
    },
    {
      "x": -15,
      "y": 0,
      "z": -11,
      "name": "Soil_Dirt"
    },
    {
      "x": -15,
      "y": 1,
      "z": -11,
      "name": "Soil_Dirt"
    },
    {
      "x": -15,
      "y": 2,
      "z": -11,
      "name": "Soil_Dirt"
    },
    {
      "x": -15,
      "y": 3,
      "z": -11,
      "name": "Soil_Grass"
    },
    {
      "x": -15,
      "y": 0,
      "z": -10,
      "name": "Soil_Dirt"
    },
    {
      "x": -15,
      "y": 1,
      "z": -10,
      "name": "Soil_Dirt"
    },
    {
      "x": -15,
      "y": 2,
      "z": -10,
      "name": "Soil_Dirt"
    },
    {
      "x": -15,
      "y": 3,
      "z": -10,
      "name": "Soil_Grass"
    },
    {
      "x": -15,
      "y": 0,
      "z": -9,
      "name": "Soil_Dirt"
    },
    {
      "x": -15,
      "y": 1,
      "z": -9,
      "name": "Soil_Dirt"
    },
    {
      "x": -15,
      "y": 2,
      "z": -9,
      "name": "Soil_Dirt"
    },
    {
      "x": -15,
      "y": 3,
      "z": -9,
      "name": "Soil_Grass"
    },
    {
      "x": -15,
      "y": 0,
      "z": -8,
      "name": "Soil_Dirt"
    },
    {
      "x": -15,
      "y": 1,
      "z": -8,
      "name": "Soil_Dirt"
    },
    {
      "x": -15,
      "y": 2,
      "z": -8,
      "name": "Soil_Dirt"
    },
    {
      "x": -15,
      "y": 3,
      "z": -8,
      "name": "Soil_Grass"
    },
    {
      "x": -15,
      "y": 0,
      "z": -7,
      "name": "Soil_Dirt"
    },
    {
      "x": -15,
      "y": 1,
      "z": -7,
      "name": "Soil_Dirt"
    },
    {
      "x": -15,
      "y": 2,
      "z": -7,
      "name": "Soil_Dirt"
    },
    {
      "x": -15,
      "y": 3,
      "z": -7,
      "name": "Soil_Grass"
    },
    {
      "x": -15,
      "y": 0,
      "z": -6,
      "name": "Soil_Dirt"
    },
    {
      "x": -15,
      "y": 1,
      "z": -6,
      "name": "Soil_Dirt"
    },
    {
      "x": -15,
      "y": 2,
      "z": -6,
      "name": "Soil_Dirt"
    },
    {
      "x": -15,
      "y": 3,
      "z": -6,
      "name": "Soil_Grass"
    },
    {
      "x": -15,
      "y": 0,
      "z": -5,
      "name": "Soil_Dirt"
    },
    {
      "x": -15,
      "y": 1,
      "z": -5,
      "name": "Soil_Dirt"
    },
    {
      "x": -15,
      "y": 2,
      "z": -5,
      "name": "Soil_Dirt"
    },
    {
      "x": -15,
      "y": 3,
      "z": -5,
      "name": "Soil_Grass"
    },
    {
      "x": -15,
      "y": 0,
      "z": -4,
      "name": "Soil_Dirt"
    },
    {
      "x": -15,
      "y": 1,
      "z": -4,
      "name": "Soil_Dirt"
    },
    {
      "x": -15,
      "y": 2,
      "z": -4,
      "name": "Soil_Dirt"
    },
    {
      "x": -15,
      "y": 3,
      "z": -4,
      "name": "Soil_Grass"
    },
    {
      "x": -15,
      "y": 0,
      "z": -3,
      "name": "Soil_Dirt"
    },
    {
      "x": -15,
      "y": 1,
      "z": -3,
      "name": "Soil_Dirt"
    },
    {
      "x": -15,
      "y": 2,
      "z": -3,
      "name": "Soil_Dirt"
    },
    {
      "x": -15,
      "y": 3,
      "z": -3,
      "name": "Soil_Grass"
    },
    {
      "x": -15,
      "y": 0,
      "z": -2,
      "name": "Soil_Dirt"
    },
    {
      "x": -15,
      "y": 1,
      "z": -2,
      "name": "Soil_Dirt"
    },
    {
      "x": -15,
      "y": 2,
      "z": -2,
      "name": "Soil_Dirt"
    },
    {
      "x": -15,
      "y": 3,
      "z": -2,
      "name": "Soil_Grass"
    },
    {
      "x": -15,
      "y": 0,
      "z": -1,
      "name": "Soil_Dirt"
    },
    {
      "x": -15,
      "y": 1,
      "z": -1,
      "name": "Soil_Dirt"
    },
    {
      "x": -15,
      "y": 2,
      "z": -1,
      "name": "Soil_Dirt"
    },
    {
      "x": -15,
      "y": 3,
      "z": -1,
      "name": "Soil_Grass"
    },
    {
      "x": -15,
      "y": 0,
      "z": 0,
      "name": "Soil_Dirt"
    },
    {
      "x": -15,
      "y": 1,
      "z": 0,
      "name": "Soil_Dirt"
    },
    {
      "x": -15,
      "y": 2,
      "z": 0,
      "name": "Soil_Dirt"
    },
    {
      "x": -15,
      "y": 3,
      "z": 0,
      "name": "Soil_Grass"
    },
    {
      "x": -15,
      "y": 0,
      "z": 1,
      "name": "Soil_Dirt"
    },
    {
      "x": -15,
      "y": 1,
      "z": 1,
      "name": "Soil_Dirt"
    },
    {
      "x": -15,
      "y": 2,
      "z": 1,
      "name": "Soil_Dirt"
    },
    {
      "x": -15,
      "y": 3,
      "z": 1,
      "name": "Soil_Grass"
    },
    {
      "x": -15,
      "y": 0,
      "z": 2,
      "name": "Soil_Dirt"
    },
    {
      "x": -15,
      "y": 1,
      "z": 2,
      "name": "Soil_Dirt"
    },
    {
      "x": -15,
      "y": 2,
      "z": 2,
      "name": "Soil_Dirt"
    },
    {
      "x": -15,
      "y": 3,
      "z": 2,
      "name": "Soil_Grass"
    },
    {
      "x": -15,
      "y": 0,
      "z": 3,
      "name": "Soil_Dirt"
    },
    {
      "x": -15,
      "y": 1,
      "z": 3,
      "name": "Soil_Dirt"
    },
    {
      "x": -15,
      "y": 2,
      "z": 3,
      "name": "Soil_Dirt"
    },
    {
      "x": -15,
      "y": 3,
      "z": 3,
      "name": "Soil_Grass"
    },
    {
      "x": -15,
      "y": 0,
      "z": 4,
      "name": "Soil_Dirt"
    },
    {
      "x": -15,
      "y": 1,
      "z": 4,
      "name": "Soil_Dirt"
    },
    {
      "x": -15,
      "y": 2,
      "z": 4,
      "name": "Soil_Dirt"
    },
    {
      "x": -15,
      "y": 3,
      "z": 4,
      "name": "Soil_Grass"
    },
    {
      "x": -15,
      "y": 0,
      "z": 5,
      "name": "Soil_Dirt"
    },
    {
      "x": -15,
      "y": 1,
      "z": 5,
      "name": "Soil_Dirt"
    },
    {
      "x": -15,
      "y": 2,
      "z": 5,
      "name": "Soil_Dirt"
    },
    {
      "x": -15,
      "y": 3,
      "z": 5,
      "name": "Soil_Grass"
    },
    {
      "x": -15,
      "y": 0,
      "z": 6,
      "name": "Soil_Dirt"
    },
    {
      "x": -15,
      "y": 1,
      "z": 6,
      "name": "Soil_Dirt"
    },
    {
      "x": -15,
      "y": 2,
      "z": 6,
      "name": "Soil_Dirt"
    },
    {
      "x": -15,
      "y": 3,
      "z": 6,
      "name": "Soil_Grass"
    },
    {
      "x": -15,
      "y": 0,
      "z": 7,
      "name": "Soil_Dirt"
    },
    {
      "x": -15,
      "y": 1,
      "z": 7,
      "name": "Soil_Dirt"
    },
    {
      "x": -15,
      "y": 2,
      "z": 7,
      "name": "Soil_Dirt"
    },
    {
      "x": -15,
      "y": 3,
      "z": 7,
      "name": "Soil_Grass"
    },
    {
      "x": -15,
      "y": 0,
      "z": 8,
      "name": "Soil_Dirt"
    },
    {
      "x": -15,
      "y": 1,
      "z": 8,
      "name": "Soil_Dirt"
    },
    {
      "x": -15,
      "y": 2,
      "z": 8,
      "name": "Soil_Dirt"
    },
    {
      "x": -15,
      "y": 3,
      "z": 8,
      "name": "Soil_Grass"
    },
    {
      "x": -15,
      "y": 0,
      "z": 9,
      "name": "Soil_Dirt"
    },
    {
      "x": -15,
      "y": 1,
      "z": 9,
      "name": "Soil_Dirt"
    },
    {
      "x": -15,
      "y": 2,
      "z": 9,
      "name": "Soil_Dirt"
    },
    {
      "x": -15,
      "y": 3,
      "z": 9,
      "name": "Soil_Grass"
    },
    {
      "x": -15,
      "y": 0,
      "z": 10,
      "name": "Soil_Dirt"
    },
    {
      "x": -15,
      "y": 1,
      "z": 10,
      "name": "Soil_Dirt"
    },
    {
      "x": -15,
      "y": 2,
      "z": 10,
      "name": "Soil_Dirt"
    },
    {
      "x": -15,
      "y": 3,
      "z": 10,
      "name": "Soil_Grass"
    },
    {
      "x": -15,
      "y": 0,
      "z": 11,
      "name": "Soil_Dirt"
    },
    {
      "x": -15,
      "y": 1,
      "z": 11,
      "name": "Soil_Dirt"
    },
    {
      "x": -15,
      "y": 2,
      "z": 11,
      "name": "Soil_Dirt"
    },
    {
      "x": -15,
      "y": 3,
      "z": 11,
      "name": "Soil_Grass"
    },
    {
      "x": -15,
      "y": 0,
      "z": 12,
      "name": "Soil_Dirt"
    },
    {
      "x": -15,
      "y": 1,
      "z": 12,
      "name": "Soil_Dirt"
    },
    {
      "x": -15,
      "y": 2,
      "z": 12,
      "name": "Soil_Dirt"
    },
    {
      "x": -15,
      "y": 3,
      "z": 12,
      "name": "Soil_Grass"
    },
    {
      "x": -15,
      "y": 0,
      "z": 13,
      "name": "Soil_Dirt"
    },
    {
      "x": -15,
      "y": 1,
      "z": 13,
      "name": "Soil_Dirt"
    },
    {
      "x": -15,
      "y": 2,
      "z": 13,
      "name": "Soil_Dirt"
    },
    {
      "x": -15,
      "y": 3,
      "z": 13,
      "name": "Soil_Grass"
    },
    {
      "x": -15,
      "y": 0,
      "z": 14,
      "name": "Soil_Dirt"
    },
    {
      "x": -15,
      "y": 1,
      "z": 14,
      "name": "Soil_Dirt"
    },
    {
      "x": -15,
      "y": 2,
      "z": 14,
      "name": "Soil_Dirt"
    },
    {
      "x": -15,
      "y": 3,
      "z": 14,
      "name": "Soil_Grass"
    },
    {
      "x": -15,
      "y": 0,
      "z": 15,
      "name": "Soil_Dirt"
    },
    {
      "x": -15,
      "y": 1,
      "z": 15,
      "name": "Soil_Dirt"
    },
    {
      "x": -15,
      "y": 2,
      "z": 15,
      "name": "Soil_Dirt"
    },
    {
      "x": -15,
      "y": 3,
      "z": 15,
      "name": "Soil_Grass"
    },
    {
      "x": -15,
      "y": 0,
      "z": 16,
      "name": "Soil_Dirt"
    },
    {
      "x": -15,
      "y": 1,
      "z": 16,
      "name": "Soil_Dirt"
    },
    {
      "x": -15,
      "y": 2,
      "z": 16,
      "name": "Soil_Dirt"
    },
    {
      "x": -15,
      "y": 3,
      "z": 16,
      "name": "Soil_Grass"
    },
    {
      "x": -14,
      "y": 0,
      "z": -15,
      "name": "Soil_Dirt"
    },
    {
      "x": -14,
      "y": 1,
      "z": -15,
      "name": "Soil_Dirt"
    },
    {
      "x": -14,
      "y": 2,
      "z": -15,
      "name": "Soil_Dirt"
    },
    {
      "x": -14,
      "y": 3,
      "z": -15,
      "name": "Soil_Grass"
    },
    {
      "x": -14,
      "y": 0,
      "z": -14,
      "name": "Soil_Dirt"
    },
    {
      "x": -14,
      "y": 1,
      "z": -14,
      "name": "Soil_Dirt"
    },
    {
      "x": -14,
      "y": 2,
      "z": -14,
      "name": "Soil_Dirt"
    },
    {
      "x": -14,
      "y": 3,
      "z": -14,
      "name": "Soil_Grass"
    },
    {
      "x": -14,
      "y": 0,
      "z": -13,
      "name": "Soil_Dirt"
    },
    {
      "x": -14,
      "y": 1,
      "z": -13,
      "name": "Soil_Dirt"
    },
    {
      "x": -14,
      "y": 2,
      "z": -13,
      "name": "Soil_Dirt"
    },
    {
      "x": -14,
      "y": 3,
      "z": -13,
      "name": "Soil_Grass"
    },
    {
      "x": -14,
      "y": 0,
      "z": -12,
      "name": "Soil_Dirt"
    },
    {
      "x": -14,
      "y": 1,
      "z": -12,
      "name": "Soil_Dirt"
    },
    {
      "x": -14,
      "y": 2,
      "z": -12,
      "name": "Soil_Dirt"
    },
    {
      "x": -14,
      "y": 3,
      "z": -12,
      "name": "Soil_Grass"
    },
    {
      "x": -14,
      "y": 0,
      "z": -11,
      "name": "Soil_Dirt"
    },
    {
      "x": -14,
      "y": 1,
      "z": -11,
      "name": "Soil_Dirt"
    },
    {
      "x": -14,
      "y": 2,
      "z": -11,
      "name": "Soil_Dirt"
    },
    {
      "x": -14,
      "y": 3,
      "z": -11,
      "name": "Soil_Grass"
    },
    {
      "x": -14,
      "y": 0,
      "z": -10,
      "name": "Soil_Dirt"
    },
    {
      "x": -14,
      "y": 1,
      "z": -10,
      "name": "Soil_Dirt"
    },
    {
      "x": -14,
      "y": 2,
      "z": -10,
      "name": "Soil_Dirt"
    },
    {
      "x": -14,
      "y": 3,
      "z": -10,
      "name": "Soil_Grass"
    },
    {
      "x": -14,
      "y": 0,
      "z": -9,
      "name": "Soil_Dirt"
    },
    {
      "x": -14,
      "y": 1,
      "z": -9,
      "name": "Soil_Dirt"
    },
    {
      "x": -14,
      "y": 2,
      "z": -9,
      "name": "Soil_Dirt"
    },
    {
      "x": -14,
      "y": 3,
      "z": -9,
      "name": "Soil_Grass"
    },
    {
      "x": -14,
      "y": 0,
      "z": -8,
      "name": "Soil_Dirt"
    },
    {
      "x": -14,
      "y": 1,
      "z": -8,
      "name": "Soil_Dirt"
    },
    {
      "x": -14,
      "y": 2,
      "z": -8,
      "name": "Soil_Dirt"
    },
    {
      "x": -14,
      "y": 3,
      "z": -8,
      "name": "Soil_Grass"
    },
    {
      "x": -14,
      "y": 0,
      "z": -7,
      "name": "Soil_Dirt"
    },
    {
      "x": -14,
      "y": 1,
      "z": -7,
      "name": "Soil_Dirt"
    },
    {
      "x": -14,
      "y": 2,
      "z": -7,
      "name": "Soil_Dirt"
    },
    {
      "x": -14,
      "y": 3,
      "z": -7,
      "name": "Soil_Grass"
    },
    {
      "x": -14,
      "y": 0,
      "z": -6,
      "name": "Soil_Dirt"
    },
    {
      "x": -14,
      "y": 1,
      "z": -6,
      "name": "Soil_Dirt"
    },
    {
      "x": -14,
      "y": 2,
      "z": -6,
      "name": "Soil_Dirt"
    },
    {
      "x": -14,
      "y": 3,
      "z": -6,
      "name": "Soil_Grass"
    },
    {
      "x": -14,
      "y": 0,
      "z": -5,
      "name": "Soil_Dirt"
    },
    {
      "x": -14,
      "y": 1,
      "z": -5,
      "name": "Soil_Dirt"
    },
    {
      "x": -14,
      "y": 2,
      "z": -5,
      "name": "Soil_Dirt"
    },
    {
      "x": -14,
      "y": 3,
      "z": -5,
      "name": "Soil_Grass"
    },
    {
      "x": -14,
      "y": 0,
      "z": -4,
      "name": "Soil_Dirt"
    },
    {
      "x": -14,
      "y": 1,
      "z": -4,
      "name": "Soil_Dirt"
    },
    {
      "x": -14,
      "y": 2,
      "z": -4,
      "name": "Soil_Dirt"
    },
    {
      "x": -14,
      "y": 3,
      "z": -4,
      "name": "Soil_Grass"
    },
    {
      "x": -14,
      "y": 0,
      "z": -3,
      "name": "Soil_Dirt"
    },
    {
      "x": -14,
      "y": 1,
      "z": -3,
      "name": "Soil_Dirt"
    },
    {
      "x": -14,
      "y": 2,
      "z": -3,
      "name": "Soil_Dirt"
    },
    {
      "x": -14,
      "y": 3,
      "z": -3,
      "name": "Soil_Grass"
    },
    {
      "x": -14,
      "y": 0,
      "z": -2,
      "name": "Soil_Dirt"
    },
    {
      "x": -14,
      "y": 1,
      "z": -2,
      "name": "Soil_Dirt"
    },
    {
      "x": -14,
      "y": 2,
      "z": -2,
      "name": "Soil_Dirt"
    },
    {
      "x": -14,
      "y": 3,
      "z": -2,
      "name": "Soil_Grass"
    },
    {
      "x": -14,
      "y": 0,
      "z": -1,
      "name": "Soil_Dirt"
    },
    {
      "x": -14,
      "y": 1,
      "z": -1,
      "name": "Soil_Dirt"
    },
    {
      "x": -14,
      "y": 2,
      "z": -1,
      "name": "Soil_Dirt"
    },
    {
      "x": -14,
      "y": 3,
      "z": -1,
      "name": "Soil_Grass"
    },
    {
      "x": -14,
      "y": 0,
      "z": 0,
      "name": "Soil_Dirt"
    },
    {
      "x": -14,
      "y": 1,
      "z": 0,
      "name": "Soil_Dirt"
    },
    {
      "x": -14,
      "y": 2,
      "z": 0,
      "name": "Soil_Dirt"
    },
    {
      "x": -14,
      "y": 3,
      "z": 0,
      "name": "Soil_Grass"
    },
    {
      "x": -14,
      "y": 0,
      "z": 1,
      "name": "Soil_Dirt"
    },
    {
      "x": -14,
      "y": 1,
      "z": 1,
      "name": "Soil_Dirt"
    },
    {
      "x": -14,
      "y": 2,
      "z": 1,
      "name": "Soil_Dirt"
    },
    {
      "x": -14,
      "y": 3,
      "z": 1,
      "name": "Soil_Grass"
    },
    {
      "x": -14,
      "y": 0,
      "z": 2,
      "name": "Soil_Dirt"
    },
    {
      "x": -14,
      "y": 1,
      "z": 2,
      "name": "Soil_Dirt"
    },
    {
      "x": -14,
      "y": 2,
      "z": 2,
      "name": "Soil_Dirt"
    },
    {
      "x": -14,
      "y": 3,
      "z": 2,
      "name": "Soil_Grass"
    },
    {
      "x": -14,
      "y": 0,
      "z": 3,
      "name": "Soil_Dirt"
    },
    {
      "x": -14,
      "y": 1,
      "z": 3,
      "name": "Soil_Dirt"
    },
    {
      "x": -14,
      "y": 2,
      "z": 3,
      "name": "Soil_Dirt"
    },
    {
      "x": -14,
      "y": 3,
      "z": 3,
      "name": "Soil_Grass"
    },
    {
      "x": -14,
      "y": 0,
      "z": 4,
      "name": "Soil_Dirt"
    },
    {
      "x": -14,
      "y": 1,
      "z": 4,
      "name": "Soil_Dirt"
    },
    {
      "x": -14,
      "y": 2,
      "z": 4,
      "name": "Soil_Dirt"
    },
    {
      "x": -14,
      "y": 3,
      "z": 4,
      "name": "Soil_Grass"
    },
    {
      "x": -14,
      "y": 0,
      "z": 5,
      "name": "Soil_Dirt"
    },
    {
      "x": -14,
      "y": 1,
      "z": 5,
      "name": "Soil_Dirt"
    },
    {
      "x": -14,
      "y": 2,
      "z": 5,
      "name": "Soil_Dirt"
    },
    {
      "x": -14,
      "y": 3,
      "z": 5,
      "name": "Soil_Grass"
    },
    {
      "x": -14,
      "y": 0,
      "z": 6,
      "name": "Soil_Dirt"
    },
    {
      "x": -14,
      "y": 1,
      "z": 6,
      "name": "Soil_Dirt"
    },
    {
      "x": -14,
      "y": 2,
      "z": 6,
      "name": "Soil_Dirt"
    },
    {
      "x": -14,
      "y": 3,
      "z": 6,
      "name": "Soil_Grass"
    },
    {
      "x": -14,
      "y": 0,
      "z": 7,
      "name": "Soil_Dirt"
    },
    {
      "x": -14,
      "y": 1,
      "z": 7,
      "name": "Soil_Dirt"
    },
    {
      "x": -14,
      "y": 2,
      "z": 7,
      "name": "Soil_Dirt"
    },
    {
      "x": -14,
      "y": 3,
      "z": 7,
      "name": "Soil_Grass"
    },
    {
      "x": -14,
      "y": 0,
      "z": 8,
      "name": "Soil_Dirt"
    },
    {
      "x": -14,
      "y": 1,
      "z": 8,
      "name": "Soil_Dirt"
    },
    {
      "x": -14,
      "y": 2,
      "z": 8,
      "name": "Soil_Dirt"
    },
    {
      "x": -14,
      "y": 3,
      "z": 8,
      "name": "Soil_Grass"
    },
    {
      "x": -14,
      "y": 0,
      "z": 9,
      "name": "Soil_Dirt"
    },
    {
      "x": -14,
      "y": 1,
      "z": 9,
      "name": "Soil_Dirt"
    },
    {
      "x": -14,
      "y": 2,
      "z": 9,
      "name": "Soil_Dirt"
    },
    {
      "x": -14,
      "y": 3,
      "z": 9,
      "name": "Soil_Grass"
    },
    {
      "x": -14,
      "y": 0,
      "z": 10,
      "name": "Soil_Dirt"
    },
    {
      "x": -14,
      "y": 1,
      "z": 10,
      "name": "Soil_Dirt"
    },
    {
      "x": -14,
      "y": 2,
      "z": 10,
      "name": "Soil_Dirt"
    },
    {
      "x": -14,
      "y": 3,
      "z": 10,
      "name": "Soil_Grass"
    },
    {
      "x": -14,
      "y": 0,
      "z": 11,
      "name": "Soil_Dirt"
    },
    {
      "x": -14,
      "y": 1,
      "z": 11,
      "name": "Soil_Dirt"
    },
    {
      "x": -14,
      "y": 2,
      "z": 11,
      "name": "Soil_Dirt"
    },
    {
      "x": -14,
      "y": 3,
      "z": 11,
      "name": "Soil_Grass"
    },
    {
      "x": -14,
      "y": 0,
      "z": 12,
      "name": "Soil_Dirt"
    },
    {
      "x": -14,
      "y": 1,
      "z": 12,
      "name": "Soil_Dirt"
    },
    {
      "x": -14,
      "y": 2,
      "z": 12,
      "name": "Soil_Dirt"
    },
    {
      "x": -14,
      "y": 3,
      "z": 12,
      "name": "Soil_Grass"
    },
    {
      "x": -14,
      "y": 0,
      "z": 13,
      "name": "Soil_Dirt"
    },
    {
      "x": -14,
      "y": 1,
      "z": 13,
      "name": "Soil_Dirt"
    },
    {
      "x": -14,
      "y": 2,
      "z": 13,
      "name": "Soil_Dirt"
    },
    {
      "x": -14,
      "y": 3,
      "z": 13,
      "name": "Soil_Grass"
    },
    {
      "x": -14,
      "y": 0,
      "z": 14,
      "name": "Soil_Dirt"
    },
    {
      "x": -14,
      "y": 1,
      "z": 14,
      "name": "Soil_Dirt"
    },
    {
      "x": -14,
      "y": 2,
      "z": 14,
      "name": "Soil_Dirt"
    },
    {
      "x": -14,
      "y": 3,
      "z": 14,
      "name": "Soil_Grass"
    },
    {
      "x": -14,
      "y": 0,
      "z": 15,
      "name": "Soil_Dirt"
    },
    {
      "x": -14,
      "y": 1,
      "z": 15,
      "name": "Soil_Dirt"
    },
    {
      "x": -14,
      "y": 2,
      "z": 15,
      "name": "Soil_Dirt"
    },
    {
      "x": -14,
      "y": 3,
      "z": 15,
      "name": "Soil_Grass"
    },
    {
      "x": -14,
      "y": 0,
      "z": 16,
      "name": "Soil_Dirt"
    },
    {
      "x": -14,
      "y": 1,
      "z": 16,
      "name": "Soil_Dirt"
    },
    {
      "x": -14,
      "y": 2,
      "z": 16,
      "name": "Soil_Dirt"
    },
    {
      "x": -14,
      "y": 3,
      "z": 16,
      "name": "Soil_Grass"
    },
    {
      "x": -13,
      "y": 0,
      "z": -15,
      "name": "Soil_Dirt"
    },
    {
      "x": -13,
      "y": 1,
      "z": -15,
      "name": "Soil_Dirt"
    },
    {
      "x": -13,
      "y": 2,
      "z": -15,
      "name": "Soil_Dirt"
    },
    {
      "x": -13,
      "y": 3,
      "z": -15,
      "name": "Soil_Grass"
    },
    {
      "x": -13,
      "y": 0,
      "z": -14,
      "name": "Soil_Dirt"
    },
    {
      "x": -13,
      "y": 1,
      "z": -14,
      "name": "Soil_Dirt"
    },
    {
      "x": -13,
      "y": 2,
      "z": -14,
      "name": "Soil_Dirt"
    },
    {
      "x": -13,
      "y": 3,
      "z": -14,
      "name": "Soil_Grass"
    },
    {
      "x": -13,
      "y": 0,
      "z": -13,
      "name": "Soil_Dirt"
    },
    {
      "x": -13,
      "y": 1,
      "z": -13,
      "name": "Soil_Dirt"
    },
    {
      "x": -13,
      "y": 2,
      "z": -13,
      "name": "Soil_Dirt"
    },
    {
      "x": -13,
      "y": 3,
      "z": -13,
      "name": "Soil_Grass"
    },
    {
      "x": -13,
      "y": 0,
      "z": -12,
      "name": "Soil_Dirt"
    },
    {
      "x": -13,
      "y": 1,
      "z": -12,
      "name": "Soil_Dirt"
    },
    {
      "x": -13,
      "y": 2,
      "z": -12,
      "name": "Soil_Dirt"
    },
    {
      "x": -13,
      "y": 3,
      "z": -12,
      "name": "Soil_Grass"
    },
    {
      "x": -13,
      "y": 0,
      "z": -11,
      "name": "Soil_Dirt"
    },
    {
      "x": -13,
      "y": 1,
      "z": -11,
      "name": "Soil_Dirt"
    },
    {
      "x": -13,
      "y": 2,
      "z": -11,
      "name": "Soil_Dirt"
    },
    {
      "x": -13,
      "y": 3,
      "z": -11,
      "name": "Soil_Grass"
    },
    {
      "x": -13,
      "y": 0,
      "z": -10,
      "name": "Soil_Dirt"
    },
    {
      "x": -13,
      "y": 1,
      "z": -10,
      "name": "Soil_Dirt"
    },
    {
      "x": -13,
      "y": 2,
      "z": -10,
      "name": "Soil_Dirt"
    },
    {
      "x": -13,
      "y": 3,
      "z": -10,
      "name": "Soil_Grass"
    },
    {
      "x": -13,
      "y": 0,
      "z": -9,
      "name": "Soil_Dirt"
    },
    {
      "x": -13,
      "y": 1,
      "z": -9,
      "name": "Soil_Dirt"
    },
    {
      "x": -13,
      "y": 2,
      "z": -9,
      "name": "Soil_Dirt"
    },
    {
      "x": -13,
      "y": 3,
      "z": -9,
      "name": "Soil_Grass"
    },
    {
      "x": -13,
      "y": 0,
      "z": -8,
      "name": "Soil_Dirt"
    },
    {
      "x": -13,
      "y": 1,
      "z": -8,
      "name": "Soil_Dirt"
    },
    {
      "x": -13,
      "y": 2,
      "z": -8,
      "name": "Soil_Dirt"
    },
    {
      "x": -13,
      "y": 3,
      "z": -8,
      "name": "Soil_Grass"
    },
    {
      "x": -13,
      "y": 0,
      "z": -7,
      "name": "Soil_Dirt"
    },
    {
      "x": -13,
      "y": 1,
      "z": -7,
      "name": "Soil_Dirt"
    },
    {
      "x": -13,
      "y": 2,
      "z": -7,
      "name": "Soil_Dirt"
    },
    {
      "x": -13,
      "y": 3,
      "z": -7,
      "name": "Soil_Grass"
    },
    {
      "x": -13,
      "y": 0,
      "z": -6,
      "name": "Soil_Dirt"
    },
    {
      "x": -13,
      "y": 1,
      "z": -6,
      "name": "Soil_Dirt"
    },
    {
      "x": -13,
      "y": 2,
      "z": -6,
      "name": "Soil_Dirt"
    },
    {
      "x": -13,
      "y": 3,
      "z": -6,
      "name": "Soil_Grass"
    },
    {
      "x": -13,
      "y": 0,
      "z": -5,
      "name": "Soil_Dirt"
    },
    {
      "x": -13,
      "y": 1,
      "z": -5,
      "name": "Soil_Dirt"
    },
    {
      "x": -13,
      "y": 2,
      "z": -5,
      "name": "Soil_Dirt"
    },
    {
      "x": -13,
      "y": 3,
      "z": -5,
      "name": "Soil_Grass"
    },
    {
      "x": -13,
      "y": 0,
      "z": -4,
      "name": "Soil_Dirt"
    },
    {
      "x": -13,
      "y": 1,
      "z": -4,
      "name": "Soil_Dirt"
    },
    {
      "x": -13,
      "y": 2,
      "z": -4,
      "name": "Soil_Dirt"
    },
    {
      "x": -13,
      "y": 3,
      "z": -4,
      "name": "Soil_Grass"
    },
    {
      "x": -13,
      "y": 0,
      "z": -3,
      "name": "Soil_Dirt"
    },
    {
      "x": -13,
      "y": 1,
      "z": -3,
      "name": "Soil_Dirt"
    },
    {
      "x": -13,
      "y": 2,
      "z": -3,
      "name": "Soil_Dirt"
    },
    {
      "x": -13,
      "y": 3,
      "z": -3,
      "name": "Soil_Grass"
    },
    {
      "x": -13,
      "y": 0,
      "z": -2,
      "name": "Soil_Dirt"
    },
    {
      "x": -13,
      "y": 1,
      "z": -2,
      "name": "Soil_Dirt"
    },
    {
      "x": -13,
      "y": 2,
      "z": -2,
      "name": "Soil_Dirt"
    },
    {
      "x": -13,
      "y": 3,
      "z": -2,
      "name": "Soil_Grass"
    },
    {
      "x": -13,
      "y": 0,
      "z": -1,
      "name": "Soil_Dirt"
    },
    {
      "x": -13,
      "y": 1,
      "z": -1,
      "name": "Soil_Dirt"
    },
    {
      "x": -13,
      "y": 2,
      "z": -1,
      "name": "Soil_Dirt"
    },
    {
      "x": -13,
      "y": 3,
      "z": -1,
      "name": "Soil_Grass"
    },
    {
      "x": -13,
      "y": 0,
      "z": 0,
      "name": "Soil_Dirt"
    },
    {
      "x": -13,
      "y": 1,
      "z": 0,
      "name": "Soil_Dirt"
    },
    {
      "x": -13,
      "y": 2,
      "z": 0,
      "name": "Soil_Dirt"
    },
    {
      "x": -13,
      "y": 3,
      "z": 0,
      "name": "Soil_Grass"
    },
    {
      "x": -13,
      "y": 0,
      "z": 1,
      "name": "Soil_Dirt"
    },
    {
      "x": -13,
      "y": 1,
      "z": 1,
      "name": "Soil_Dirt"
    },
    {
      "x": -13,
      "y": 2,
      "z": 1,
      "name": "Soil_Dirt"
    },
    {
      "x": -13,
      "y": 3,
      "z": 1,
      "name": "Soil_Grass"
    },
    {
      "x": -13,
      "y": 0,
      "z": 2,
      "name": "Soil_Dirt"
    },
    {
      "x": -13,
      "y": 1,
      "z": 2,
      "name": "Soil_Dirt"
    },
    {
      "x": -13,
      "y": 2,
      "z": 2,
      "name": "Soil_Dirt"
    },
    {
      "x": -13,
      "y": 3,
      "z": 2,
      "name": "Soil_Grass"
    },
    {
      "x": -13,
      "y": 0,
      "z": 3,
      "name": "Soil_Dirt"
    },
    {
      "x": -13,
      "y": 1,
      "z": 3,
      "name": "Soil_Dirt"
    },
    {
      "x": -13,
      "y": 2,
      "z": 3,
      "name": "Soil_Dirt"
    },
    {
      "x": -13,
      "y": 3,
      "z": 3,
      "name": "Soil_Grass"
    },
    {
      "x": -13,
      "y": 0,
      "z": 4,
      "name": "Soil_Dirt"
    },
    {
      "x": -13,
      "y": 1,
      "z": 4,
      "name": "Soil_Dirt"
    },
    {
      "x": -13,
      "y": 2,
      "z": 4,
      "name": "Soil_Dirt"
    },
    {
      "x": -13,
      "y": 3,
      "z": 4,
      "name": "Soil_Grass"
    },
    {
      "x": -13,
      "y": 0,
      "z": 5,
      "name": "Soil_Dirt"
    },
    {
      "x": -13,
      "y": 1,
      "z": 5,
      "name": "Soil_Dirt"
    },
    {
      "x": -13,
      "y": 2,
      "z": 5,
      "name": "Soil_Dirt"
    },
    {
      "x": -13,
      "y": 3,
      "z": 5,
      "name": "Soil_Grass"
    },
    {
      "x": -13,
      "y": 0,
      "z": 6,
      "name": "Soil_Dirt"
    },
    {
      "x": -13,
      "y": 1,
      "z": 6,
      "name": "Soil_Dirt"
    },
    {
      "x": -13,
      "y": 2,
      "z": 6,
      "name": "Soil_Dirt"
    },
    {
      "x": -13,
      "y": 3,
      "z": 6,
      "name": "Soil_Grass"
    },
    {
      "x": -13,
      "y": 0,
      "z": 7,
      "name": "Soil_Dirt"
    },
    {
      "x": -13,
      "y": 1,
      "z": 7,
      "name": "Soil_Dirt"
    },
    {
      "x": -13,
      "y": 2,
      "z": 7,
      "name": "Soil_Dirt"
    },
    {
      "x": -13,
      "y": 3,
      "z": 7,
      "name": "Soil_Grass"
    },
    {
      "x": -13,
      "y": 0,
      "z": 8,
      "name": "Soil_Dirt"
    },
    {
      "x": -13,
      "y": 1,
      "z": 8,
      "name": "Soil_Dirt"
    },
    {
      "x": -13,
      "y": 2,
      "z": 8,
      "name": "Soil_Dirt"
    },
    {
      "x": -13,
      "y": 3,
      "z": 8,
      "name": "Soil_Grass"
    },
    {
      "x": -13,
      "y": 0,
      "z": 9,
      "name": "Soil_Dirt"
    },
    {
      "x": -13,
      "y": 1,
      "z": 9,
      "name": "Soil_Dirt"
    },
    {
      "x": -13,
      "y": 2,
      "z": 9,
      "name": "Soil_Dirt"
    },
    {
      "x": -13,
      "y": 3,
      "z": 9,
      "name": "Soil_Grass"
    },
    {
      "x": -13,
      "y": 0,
      "z": 10,
      "name": "Soil_Dirt"
    },
    {
      "x": -13,
      "y": 1,
      "z": 10,
      "name": "Soil_Dirt"
    },
    {
      "x": -13,
      "y": 2,
      "z": 10,
      "name": "Soil_Dirt"
    },
    {
      "x": -13,
      "y": 3,
      "z": 10,
      "name": "Soil_Grass"
    },
    {
      "x": -13,
      "y": 0,
      "z": 11,
      "name": "Soil_Dirt"
    },
    {
      "x": -13,
      "y": 1,
      "z": 11,
      "name": "Soil_Dirt"
    },
    {
      "x": -13,
      "y": 2,
      "z": 11,
      "name": "Soil_Dirt"
    },
    {
      "x": -13,
      "y": 3,
      "z": 11,
      "name": "Soil_Grass"
    },
    {
      "x": -13,
      "y": 0,
      "z": 12,
      "name": "Soil_Dirt"
    },
    {
      "x": -13,
      "y": 1,
      "z": 12,
      "name": "Soil_Dirt"
    },
    {
      "x": -13,
      "y": 2,
      "z": 12,
      "name": "Soil_Dirt"
    },
    {
      "x": -13,
      "y": 3,
      "z": 12,
      "name": "Soil_Grass"
    },
    {
      "x": -13,
      "y": 0,
      "z": 13,
      "name": "Soil_Dirt"
    },
    {
      "x": -13,
      "y": 1,
      "z": 13,
      "name": "Soil_Dirt"
    },
    {
      "x": -13,
      "y": 2,
      "z": 13,
      "name": "Soil_Dirt"
    },
    {
      "x": -13,
      "y": 3,
      "z": 13,
      "name": "Soil_Grass"
    },
    {
      "x": -13,
      "y": 0,
      "z": 14,
      "name": "Soil_Dirt"
    },
    {
      "x": -13,
      "y": 1,
      "z": 14,
      "name": "Soil_Dirt"
    },
    {
      "x": -13,
      "y": 2,
      "z": 14,
      "name": "Soil_Dirt"
    },
    {
      "x": -13,
      "y": 3,
      "z": 14,
      "name": "Soil_Grass"
    },
    {
      "x": -13,
      "y": 0,
      "z": 15,
      "name": "Soil_Dirt"
    },
    {
      "x": -13,
      "y": 1,
      "z": 15,
      "name": "Soil_Dirt"
    },
    {
      "x": -13,
      "y": 2,
      "z": 15,
      "name": "Soil_Dirt"
    },
    {
      "x": -13,
      "y": 3,
      "z": 15,
      "name": "Soil_Grass"
    },
    {
      "x": -13,
      "y": 0,
      "z": 16,
      "name": "Soil_Dirt"
    },
    {
      "x": -13,
      "y": 1,
      "z": 16,
      "name": "Soil_Dirt"
    },
    {
      "x": -13,
      "y": 2,
      "z": 16,
      "name": "Soil_Dirt"
    },
    {
      "x": -13,
      "y": 3,
      "z": 16,
      "name": "Soil_Grass"
    },
    {
      "x": -12,
      "y": 0,
      "z": -15,
      "name": "Soil_Dirt"
    },
    {
      "x": -12,
      "y": 1,
      "z": -15,
      "name": "Soil_Dirt"
    },
    {
      "x": -12,
      "y": 2,
      "z": -15,
      "name": "Soil_Dirt"
    },
    {
      "x": -12,
      "y": 3,
      "z": -15,
      "name": "Soil_Grass"
    },
    {
      "x": -12,
      "y": 0,
      "z": -14,
      "name": "Soil_Dirt"
    },
    {
      "x": -12,
      "y": 1,
      "z": -14,
      "name": "Soil_Dirt"
    },
    {
      "x": -12,
      "y": 2,
      "z": -14,
      "name": "Soil_Dirt"
    },
    {
      "x": -12,
      "y": 3,
      "z": -14,
      "name": "Soil_Grass"
    },
    {
      "x": -12,
      "y": 0,
      "z": -13,
      "name": "Soil_Dirt"
    },
    {
      "x": -12,
      "y": 1,
      "z": -13,
      "name": "Soil_Dirt"
    },
    {
      "x": -12,
      "y": 2,
      "z": -13,
      "name": "Soil_Dirt"
    },
    {
      "x": -12,
      "y": 3,
      "z": -13,
      "name": "Soil_Grass"
    },
    {
      "x": -12,
      "y": 0,
      "z": -12,
      "name": "Soil_Dirt"
    },
    {
      "x": -12,
      "y": 1,
      "z": -12,
      "name": "Soil_Dirt"
    },
    {
      "x": -12,
      "y": 2,
      "z": -12,
      "name": "Soil_Dirt"
    },
    {
      "x": -12,
      "y": 3,
      "z": -12,
      "name": "Soil_Grass"
    },
    {
      "x": -12,
      "y": 0,
      "z": -11,
      "name": "Soil_Dirt"
    },
    {
      "x": -12,
      "y": 1,
      "z": -11,
      "name": "Soil_Dirt"
    },
    {
      "x": -12,
      "y": 2,
      "z": -11,
      "name": "Soil_Dirt"
    },
    {
      "x": -12,
      "y": 3,
      "z": -11,
      "name": "Soil_Grass"
    },
    {
      "x": -12,
      "y": 0,
      "z": -10,
      "name": "Soil_Dirt"
    },
    {
      "x": -12,
      "y": 1,
      "z": -10,
      "name": "Soil_Dirt"
    },
    {
      "x": -12,
      "y": 2,
      "z": -10,
      "name": "Soil_Dirt"
    },
    {
      "x": -12,
      "y": 3,
      "z": -10,
      "name": "Soil_Grass"
    },
    {
      "x": -12,
      "y": 0,
      "z": -9,
      "name": "Soil_Dirt"
    },
    {
      "x": -12,
      "y": 1,
      "z": -9,
      "name": "Soil_Dirt"
    },
    {
      "x": -12,
      "y": 2,
      "z": -9,
      "name": "Soil_Dirt"
    },
    {
      "x": -12,
      "y": 3,
      "z": -9,
      "name": "Soil_Grass"
    },
    {
      "x": -12,
      "y": 0,
      "z": -8,
      "name": "Soil_Dirt"
    },
    {
      "x": -12,
      "y": 1,
      "z": -8,
      "name": "Soil_Dirt"
    },
    {
      "x": -12,
      "y": 2,
      "z": -8,
      "name": "Soil_Dirt"
    },
    {
      "x": -12,
      "y": 3,
      "z": -8,
      "name": "Soil_Grass"
    },
    {
      "x": -12,
      "y": 0,
      "z": -7,
      "name": "Soil_Dirt"
    },
    {
      "x": -12,
      "y": 1,
      "z": -7,
      "name": "Soil_Dirt"
    },
    {
      "x": -12,
      "y": 2,
      "z": -7,
      "name": "Soil_Dirt"
    },
    {
      "x": -12,
      "y": 3,
      "z": -7,
      "name": "Soil_Grass"
    },
    {
      "x": -12,
      "y": 0,
      "z": -6,
      "name": "Soil_Dirt"
    },
    {
      "x": -12,
      "y": 1,
      "z": -6,
      "name": "Soil_Dirt"
    },
    {
      "x": -12,
      "y": 2,
      "z": -6,
      "name": "Soil_Dirt"
    },
    {
      "x": -12,
      "y": 3,
      "z": -6,
      "name": "Soil_Grass"
    },
    {
      "x": -12,
      "y": 0,
      "z": -5,
      "name": "Soil_Dirt"
    },
    {
      "x": -12,
      "y": 1,
      "z": -5,
      "name": "Soil_Dirt"
    },
    {
      "x": -12,
      "y": 2,
      "z": -5,
      "name": "Soil_Dirt"
    },
    {
      "x": -12,
      "y": 3,
      "z": -5,
      "name": "Soil_Grass"
    },
    {
      "x": -12,
      "y": 0,
      "z": -4,
      "name": "Soil_Dirt"
    },
    {
      "x": -12,
      "y": 1,
      "z": -4,
      "name": "Soil_Dirt"
    },
    {
      "x": -12,
      "y": 2,
      "z": -4,
      "name": "Soil_Dirt"
    },
    {
      "x": -12,
      "y": 3,
      "z": -4,
      "name": "Soil_Grass"
    },
    {
      "x": -12,
      "y": 0,
      "z": -3,
      "name": "Soil_Dirt"
    },
    {
      "x": -12,
      "y": 1,
      "z": -3,
      "name": "Soil_Dirt"
    },
    {
      "x": -12,
      "y": 2,
      "z": -3,
      "name": "Soil_Dirt"
    },
    {
      "x": -12,
      "y": 3,
      "z": -3,
      "name": "Soil_Grass"
    },
    {
      "x": -12,
      "y": 0,
      "z": -2,
      "name": "Soil_Dirt"
    },
    {
      "x": -12,
      "y": 1,
      "z": -2,
      "name": "Soil_Dirt"
    },
    {
      "x": -12,
      "y": 2,
      "z": -2,
      "name": "Soil_Dirt"
    },
    {
      "x": -12,
      "y": 3,
      "z": -2,
      "name": "Soil_Grass"
    },
    {
      "x": -12,
      "y": 0,
      "z": -1,
      "name": "Soil_Dirt"
    },
    {
      "x": -12,
      "y": 1,
      "z": -1,
      "name": "Soil_Dirt"
    },
    {
      "x": -12,
      "y": 2,
      "z": -1,
      "name": "Soil_Dirt"
    },
    {
      "x": -12,
      "y": 3,
      "z": -1,
      "name": "Soil_Grass"
    },
    {
      "x": -12,
      "y": 0,
      "z": 0,
      "name": "Soil_Dirt"
    },
    {
      "x": -12,
      "y": 1,
      "z": 0,
      "name": "Soil_Dirt"
    },
    {
      "x": -12,
      "y": 2,
      "z": 0,
      "name": "Soil_Dirt"
    },
    {
      "x": -12,
      "y": 3,
      "z": 0,
      "name": "Soil_Grass"
    },
    {
      "x": -12,
      "y": 0,
      "z": 1,
      "name": "Soil_Dirt"
    },
    {
      "x": -12,
      "y": 1,
      "z": 1,
      "name": "Soil_Dirt"
    },
    {
      "x": -12,
      "y": 2,
      "z": 1,
      "name": "Soil_Dirt"
    },
    {
      "x": -12,
      "y": 3,
      "z": 1,
      "name": "Soil_Grass"
    },
    {
      "x": -12,
      "y": 0,
      "z": 2,
      "name": "Soil_Dirt"
    },
    {
      "x": -12,
      "y": 1,
      "z": 2,
      "name": "Soil_Dirt"
    },
    {
      "x": -12,
      "y": 2,
      "z": 2,
      "name": "Soil_Dirt"
    },
    {
      "x": -12,
      "y": 3,
      "z": 2,
      "name": "Soil_Grass"
    },
    {
      "x": -12,
      "y": 0,
      "z": 3,
      "name": "Soil_Dirt"
    },
    {
      "x": -12,
      "y": 1,
      "z": 3,
      "name": "Soil_Dirt"
    },
    {
      "x": -12,
      "y": 2,
      "z": 3,
      "name": "Soil_Dirt"
    },
    {
      "x": -12,
      "y": 3,
      "z": 3,
      "name": "Soil_Grass"
    },
    {
      "x": -12,
      "y": 0,
      "z": 4,
      "name": "Soil_Dirt"
    },
    {
      "x": -12,
      "y": 1,
      "z": 4,
      "name": "Soil_Dirt"
    },
    {
      "x": -12,
      "y": 2,
      "z": 4,
      "name": "Soil_Dirt"
    },
    {
      "x": -12,
      "y": 3,
      "z": 4,
      "name": "Soil_Grass"
    },
    {
      "x": -12,
      "y": 0,
      "z": 5,
      "name": "Soil_Dirt"
    },
    {
      "x": -12,
      "y": 1,
      "z": 5,
      "name": "Soil_Dirt"
    },
    {
      "x": -12,
      "y": 2,
      "z": 5,
      "name": "Soil_Dirt"
    },
    {
      "x": -12,
      "y": 3,
      "z": 5,
      "name": "Soil_Grass"
    },
    {
      "x": -12,
      "y": 0,
      "z": 6,
      "name": "Soil_Dirt"
    },
    {
      "x": -12,
      "y": 1,
      "z": 6,
      "name": "Soil_Dirt"
    },
    {
      "x": -12,
      "y": 2,
      "z": 6,
      "name": "Soil_Dirt"
    },
    {
      "x": -12,
      "y": 3,
      "z": 6,
      "name": "Soil_Grass"
    },
    {
      "x": -12,
      "y": 0,
      "z": 7,
      "name": "Soil_Dirt"
    },
    {
      "x": -12,
      "y": 1,
      "z": 7,
      "name": "Soil_Dirt"
    },
    {
      "x": -12,
      "y": 2,
      "z": 7,
      "name": "Soil_Dirt"
    },
    {
      "x": -12,
      "y": 3,
      "z": 7,
      "name": "Soil_Grass"
    },
    {
      "x": -12,
      "y": 0,
      "z": 8,
      "name": "Soil_Dirt"
    },
    {
      "x": -12,
      "y": 1,
      "z": 8,
      "name": "Soil_Dirt"
    },
    {
      "x": -12,
      "y": 2,
      "z": 8,
      "name": "Soil_Dirt"
    },
    {
      "x": -12,
      "y": 3,
      "z": 8,
      "name": "Soil_Grass"
    },
    {
      "x": -12,
      "y": 0,
      "z": 9,
      "name": "Soil_Dirt"
    },
    {
      "x": -12,
      "y": 1,
      "z": 9,
      "name": "Soil_Dirt"
    },
    {
      "x": -12,
      "y": 2,
      "z": 9,
      "name": "Soil_Dirt"
    },
    {
      "x": -12,
      "y": 3,
      "z": 9,
      "name": "Soil_Grass"
    },
    {
      "x": -12,
      "y": 0,
      "z": 10,
      "name": "Soil_Dirt"
    },
    {
      "x": -12,
      "y": 1,
      "z": 10,
      "name": "Soil_Dirt"
    },
    {
      "x": -12,
      "y": 2,
      "z": 10,
      "name": "Soil_Dirt"
    },
    {
      "x": -12,
      "y": 3,
      "z": 10,
      "name": "Soil_Grass"
    },
    {
      "x": -12,
      "y": 0,
      "z": 11,
      "name": "Soil_Dirt"
    },
    {
      "x": -12,
      "y": 1,
      "z": 11,
      "name": "Soil_Dirt"
    },
    {
      "x": -12,
      "y": 2,
      "z": 11,
      "name": "Soil_Dirt"
    },
    {
      "x": -12,
      "y": 3,
      "z": 11,
      "name": "Soil_Grass"
    },
    {
      "x": -12,
      "y": 0,
      "z": 12,
      "name": "Soil_Dirt"
    },
    {
      "x": -12,
      "y": 1,
      "z": 12,
      "name": "Soil_Dirt"
    },
    {
      "x": -12,
      "y": 2,
      "z": 12,
      "name": "Soil_Dirt"
    },
    {
      "x": -12,
      "y": 3,
      "z": 12,
      "name": "Soil_Grass"
    },
    {
      "x": -12,
      "y": 0,
      "z": 13,
      "name": "Soil_Dirt"
    },
    {
      "x": -12,
      "y": 1,
      "z": 13,
      "name": "Soil_Dirt"
    },
    {
      "x": -12,
      "y": 2,
      "z": 13,
      "name": "Soil_Dirt"
    },
    {
      "x": -12,
      "y": 3,
      "z": 13,
      "name": "Soil_Grass"
    },
    {
      "x": -12,
      "y": 0,
      "z": 14,
      "name": "Soil_Dirt"
    },
    {
      "x": -12,
      "y": 1,
      "z": 14,
      "name": "Soil_Dirt"
    },
    {
      "x": -12,
      "y": 2,
      "z": 14,
      "name": "Soil_Dirt"
    },
    {
      "x": -12,
      "y": 3,
      "z": 14,
      "name": "Soil_Grass"
    },
    {
      "x": -12,
      "y": 0,
      "z": 15,
      "name": "Soil_Dirt"
    },
    {
      "x": -12,
      "y": 1,
      "z": 15,
      "name": "Soil_Dirt"
    },
    {
      "x": -12,
      "y": 2,
      "z": 15,
      "name": "Soil_Dirt"
    },
    {
      "x": -12,
      "y": 3,
      "z": 15,
      "name": "Soil_Grass"
    },
    {
      "x": -12,
      "y": 0,
      "z": 16,
      "name": "Soil_Dirt"
    },
    {
      "x": -12,
      "y": 1,
      "z": 16,
      "name": "Soil_Dirt"
    },
    {
      "x": -12,
      "y": 2,
      "z": 16,
      "name": "Soil_Dirt"
    },
    {
      "x": -12,
      "y": 3,
      "z": 16,
      "name": "Soil_Grass"
    },
    {
      "x": -11,
      "y": 0,
      "z": -15,
      "name": "Soil_Dirt"
    },
    {
      "x": -11,
      "y": 1,
      "z": -15,
      "name": "Soil_Dirt"
    },
    {
      "x": -11,
      "y": 2,
      "z": -15,
      "name": "Soil_Dirt"
    },
    {
      "x": -11,
      "y": 3,
      "z": -15,
      "name": "Soil_Grass"
    },
    {
      "x": -11,
      "y": 0,
      "z": -14,
      "name": "Soil_Dirt"
    },
    {
      "x": -11,
      "y": 1,
      "z": -14,
      "name": "Soil_Dirt"
    },
    {
      "x": -11,
      "y": 2,
      "z": -14,
      "name": "Soil_Dirt"
    },
    {
      "x": -11,
      "y": 3,
      "z": -14,
      "name": "Soil_Grass"
    },
    {
      "x": -11,
      "y": 0,
      "z": -13,
      "name": "Soil_Dirt"
    },
    {
      "x": -11,
      "y": 1,
      "z": -13,
      "name": "Soil_Dirt"
    },
    {
      "x": -11,
      "y": 2,
      "z": -13,
      "name": "Soil_Dirt"
    },
    {
      "x": -11,
      "y": 3,
      "z": -13,
      "name": "Soil_Grass"
    },
    {
      "x": -11,
      "y": 0,
      "z": -12,
      "name": "Soil_Dirt"
    },
    {
      "x": -11,
      "y": 1,
      "z": -12,
      "name": "Soil_Dirt"
    },
    {
      "x": -11,
      "y": 2,
      "z": -12,
      "name": "Soil_Dirt"
    },
    {
      "x": -11,
      "y": 3,
      "z": -12,
      "name": "Soil_Grass"
    },
    {
      "x": -11,
      "y": 0,
      "z": -11,
      "name": "Soil_Dirt"
    },
    {
      "x": -11,
      "y": 1,
      "z": -11,
      "name": "Soil_Dirt"
    },
    {
      "x": -11,
      "y": 2,
      "z": -11,
      "name": "Soil_Dirt"
    },
    {
      "x": -11,
      "y": 3,
      "z": -11,
      "name": "Soil_Grass"
    },
    {
      "x": -11,
      "y": 0,
      "z": -10,
      "name": "Soil_Dirt"
    },
    {
      "x": -11,
      "y": 1,
      "z": -10,
      "name": "Soil_Dirt"
    },
    {
      "x": -11,
      "y": 2,
      "z": -10,
      "name": "Soil_Dirt"
    },
    {
      "x": -11,
      "y": 3,
      "z": -10,
      "name": "Soil_Grass"
    },
    {
      "x": -11,
      "y": 0,
      "z": -9,
      "name": "Soil_Dirt"
    },
    {
      "x": -11,
      "y": 1,
      "z": -9,
      "name": "Soil_Dirt"
    },
    {
      "x": -11,
      "y": 2,
      "z": -9,
      "name": "Soil_Dirt"
    },
    {
      "x": -11,
      "y": 3,
      "z": -9,
      "name": "Soil_Grass"
    },
    {
      "x": -11,
      "y": 0,
      "z": -8,
      "name": "Soil_Dirt"
    },
    {
      "x": -11,
      "y": 1,
      "z": -8,
      "name": "Soil_Dirt"
    },
    {
      "x": -11,
      "y": 2,
      "z": -8,
      "name": "Soil_Dirt"
    },
    {
      "x": -11,
      "y": 3,
      "z": -8,
      "name": "Soil_Grass"
    },
    {
      "x": -11,
      "y": 0,
      "z": -7,
      "name": "Soil_Dirt"
    },
    {
      "x": -11,
      "y": 1,
      "z": -7,
      "name": "Soil_Dirt"
    },
    {
      "x": -11,
      "y": 2,
      "z": -7,
      "name": "Soil_Dirt"
    },
    {
      "x": -11,
      "y": 3,
      "z": -7,
      "name": "Soil_Grass"
    },
    {
      "x": -11,
      "y": 0,
      "z": -6,
      "name": "Soil_Dirt"
    },
    {
      "x": -11,
      "y": 1,
      "z": -6,
      "name": "Soil_Dirt"
    },
    {
      "x": -11,
      "y": 2,
      "z": -6,
      "name": "Soil_Dirt"
    },
    {
      "x": -11,
      "y": 3,
      "z": -6,
      "name": "Soil_Grass"
    },
    {
      "x": -11,
      "y": 0,
      "z": -5,
      "name": "Soil_Dirt"
    },
    {
      "x": -11,
      "y": 1,
      "z": -5,
      "name": "Soil_Dirt"
    },
    {
      "x": -11,
      "y": 2,
      "z": -5,
      "name": "Soil_Dirt"
    },
    {
      "x": -11,
      "y": 3,
      "z": -5,
      "name": "Soil_Grass"
    },
    {
      "x": -11,
      "y": 0,
      "z": -4,
      "name": "Soil_Dirt"
    },
    {
      "x": -11,
      "y": 1,
      "z": -4,
      "name": "Soil_Dirt"
    },
    {
      "x": -11,
      "y": 2,
      "z": -4,
      "name": "Soil_Dirt"
    },
    {
      "x": -11,
      "y": 3,
      "z": -4,
      "name": "Soil_Grass"
    },
    {
      "x": -11,
      "y": 0,
      "z": -3,
      "name": "Soil_Dirt"
    },
    {
      "x": -11,
      "y": 1,
      "z": -3,
      "name": "Soil_Dirt"
    },
    {
      "x": -11,
      "y": 2,
      "z": -3,
      "name": "Soil_Dirt"
    },
    {
      "x": -11,
      "y": 3,
      "z": -3,
      "name": "Soil_Grass"
    },
    {
      "x": -11,
      "y": 0,
      "z": -2,
      "name": "Soil_Dirt"
    },
    {
      "x": -11,
      "y": 1,
      "z": -2,
      "name": "Soil_Dirt"
    },
    {
      "x": -11,
      "y": 2,
      "z": -2,
      "name": "Soil_Dirt"
    },
    {
      "x": -11,
      "y": 3,
      "z": -2,
      "name": "Soil_Grass"
    },
    {
      "x": -11,
      "y": 0,
      "z": -1,
      "name": "Soil_Dirt"
    },
    {
      "x": -11,
      "y": 1,
      "z": -1,
      "name": "Soil_Dirt"
    },
    {
      "x": -11,
      "y": 2,
      "z": -1,
      "name": "Soil_Dirt"
    },
    {
      "x": -11,
      "y": 3,
      "z": -1,
      "name": "Soil_Grass"
    },
    {
      "x": -11,
      "y": 0,
      "z": 0,
      "name": "Soil_Dirt"
    },
    {
      "x": -11,
      "y": 1,
      "z": 0,
      "name": "Soil_Dirt"
    },
    {
      "x": -11,
      "y": 2,
      "z": 0,
      "name": "Soil_Dirt"
    },
    {
      "x": -11,
      "y": 3,
      "z": 0,
      "name": "Soil_Grass"
    },
    {
      "x": -11,
      "y": 0,
      "z": 1,
      "name": "Soil_Dirt"
    },
    {
      "x": -11,
      "y": 1,
      "z": 1,
      "name": "Soil_Dirt"
    },
    {
      "x": -11,
      "y": 2,
      "z": 1,
      "name": "Soil_Dirt"
    },
    {
      "x": -11,
      "y": 3,
      "z": 1,
      "name": "Soil_Grass"
    },
    {
      "x": -11,
      "y": 0,
      "z": 2,
      "name": "Soil_Dirt"
    },
    {
      "x": -11,
      "y": 1,
      "z": 2,
      "name": "Soil_Dirt"
    },
    {
      "x": -11,
      "y": 2,
      "z": 2,
      "name": "Soil_Dirt"
    },
    {
      "x": -11,
      "y": 3,
      "z": 2,
      "name": "Soil_Grass"
    },
    {
      "x": -11,
      "y": 0,
      "z": 3,
      "name": "Soil_Dirt"
    },
    {
      "x": -11,
      "y": 1,
      "z": 3,
      "name": "Soil_Dirt"
    },
    {
      "x": -11,
      "y": 2,
      "z": 3,
      "name": "Soil_Dirt"
    },
    {
      "x": -11,
      "y": 3,
      "z": 3,
      "name": "Soil_Grass"
    },
    {
      "x": -11,
      "y": 0,
      "z": 4,
      "name": "Soil_Dirt"
    },
    {
      "x": -11,
      "y": 1,
      "z": 4,
      "name": "Soil_Dirt"
    },
    {
      "x": -11,
      "y": 2,
      "z": 4,
      "name": "Soil_Dirt"
    },
    {
      "x": -11,
      "y": 3,
      "z": 4,
      "name": "Soil_Grass"
    },
    {
      "x": -11,
      "y": 0,
      "z": 5,
      "name": "Soil_Dirt"
    },
    {
      "x": -11,
      "y": 1,
      "z": 5,
      "name": "Soil_Dirt"
    },
    {
      "x": -11,
      "y": 2,
      "z": 5,
      "name": "Soil_Dirt"
    },
    {
      "x": -11,
      "y": 3,
      "z": 5,
      "name": "Soil_Grass"
    },
    {
      "x": -11,
      "y": 0,
      "z": 6,
      "name": "Soil_Dirt"
    },
    {
      "x": -11,
      "y": 1,
      "z": 6,
      "name": "Soil_Dirt"
    },
    {
      "x": -11,
      "y": 2,
      "z": 6,
      "name": "Soil_Dirt"
    },
    {
      "x": -11,
      "y": 3,
      "z": 6,
      "name": "Soil_Grass"
    },
    {
      "x": -11,
      "y": 0,
      "z": 7,
      "name": "Soil_Dirt"
    },
    {
      "x": -11,
      "y": 1,
      "z": 7,
      "name": "Soil_Dirt"
    },
    {
      "x": -11,
      "y": 2,
      "z": 7,
      "name": "Soil_Dirt"
    },
    {
      "x": -11,
      "y": 3,
      "z": 7,
      "name": "Soil_Grass"
    },
    {
      "x": -11,
      "y": 0,
      "z": 8,
      "name": "Soil_Dirt"
    },
    {
      "x": -11,
      "y": 1,
      "z": 8,
      "name": "Soil_Dirt"
    },
    {
      "x": -11,
      "y": 2,
      "z": 8,
      "name": "Soil_Dirt"
    },
    {
      "x": -11,
      "y": 3,
      "z": 8,
      "name": "Soil_Grass"
    },
    {
      "x": -11,
      "y": 0,
      "z": 9,
      "name": "Soil_Dirt"
    },
    {
      "x": -11,
      "y": 1,
      "z": 9,
      "name": "Soil_Dirt"
    },
    {
      "x": -11,
      "y": 2,
      "z": 9,
      "name": "Soil_Dirt"
    },
    {
      "x": -11,
      "y": 3,
      "z": 9,
      "name": "Soil_Grass"
    },
    {
      "x": -11,
      "y": 0,
      "z": 10,
      "name": "Soil_Dirt"
    },
    {
      "x": -11,
      "y": 1,
      "z": 10,
      "name": "Soil_Dirt"
    },
    {
      "x": -11,
      "y": 2,
      "z": 10,
      "name": "Soil_Dirt"
    },
    {
      "x": -11,
      "y": 3,
      "z": 10,
      "name": "Soil_Grass"
    },
    {
      "x": -11,
      "y": 0,
      "z": 11,
      "name": "Soil_Dirt"
    },
    {
      "x": -11,
      "y": 1,
      "z": 11,
      "name": "Soil_Dirt"
    },
    {
      "x": -11,
      "y": 2,
      "z": 11,
      "name": "Soil_Dirt"
    },
    {
      "x": -11,
      "y": 3,
      "z": 11,
      "name": "Soil_Grass"
    },
    {
      "x": -11,
      "y": 0,
      "z": 12,
      "name": "Soil_Dirt"
    },
    {
      "x": -11,
      "y": 1,
      "z": 12,
      "name": "Soil_Dirt"
    },
    {
      "x": -11,
      "y": 2,
      "z": 12,
      "name": "Soil_Dirt"
    },
    {
      "x": -11,
      "y": 3,
      "z": 12,
      "name": "Soil_Grass"
    },
    {
      "x": -11,
      "y": 0,
      "z": 13,
      "name": "Soil_Dirt"
    },
    {
      "x": -11,
      "y": 1,
      "z": 13,
      "name": "Soil_Dirt"
    },
    {
      "x": -11,
      "y": 2,
      "z": 13,
      "name": "Soil_Dirt"
    },
    {
      "x": -11,
      "y": 3,
      "z": 13,
      "name": "Soil_Grass"
    },
    {
      "x": -11,
      "y": 0,
      "z": 14,
      "name": "Soil_Dirt"
    },
    {
      "x": -11,
      "y": 1,
      "z": 14,
      "name": "Soil_Dirt"
    },
    {
      "x": -11,
      "y": 2,
      "z": 14,
      "name": "Soil_Dirt"
    },
    {
      "x": -11,
      "y": 3,
      "z": 14,
      "name": "Soil_Grass"
    },
    {
      "x": -11,
      "y": 0,
      "z": 15,
      "name": "Soil_Dirt"
    },
    {
      "x": -11,
      "y": 1,
      "z": 15,
      "name": "Soil_Dirt"
    },
    {
      "x": -11,
      "y": 2,
      "z": 15,
      "name": "Soil_Dirt"
    },
    {
      "x": -11,
      "y": 3,
      "z": 15,
      "name": "Soil_Grass"
    },
    {
      "x": -11,
      "y": 0,
      "z": 16,
      "name": "Soil_Dirt"
    },
    {
      "x": -11,
      "y": 1,
      "z": 16,
      "name": "Soil_Dirt"
    },
    {
      "x": -11,
      "y": 2,
      "z": 16,
      "name": "Soil_Dirt"
    },
    {
      "x": -11,
      "y": 3,
      "z": 16,
      "name": "Soil_Grass"
    },
    {
      "x": -10,
      "y": 0,
      "z": -15,
      "name": "Soil_Dirt"
    },
    {
      "x": -10,
      "y": 1,
      "z": -15,
      "name": "Soil_Dirt"
    },
    {
      "x": -10,
      "y": 2,
      "z": -15,
      "name": "Soil_Dirt"
    },
    {
      "x": -10,
      "y": 3,
      "z": -15,
      "name": "Soil_Grass"
    },
    {
      "x": -10,
      "y": 0,
      "z": -14,
      "name": "Soil_Dirt"
    },
    {
      "x": -10,
      "y": 1,
      "z": -14,
      "name": "Soil_Dirt"
    },
    {
      "x": -10,
      "y": 2,
      "z": -14,
      "name": "Soil_Dirt"
    },
    {
      "x": -10,
      "y": 3,
      "z": -14,
      "name": "Soil_Grass"
    },
    {
      "x": -10,
      "y": 0,
      "z": -13,
      "name": "Soil_Dirt"
    },
    {
      "x": -10,
      "y": 1,
      "z": -13,
      "name": "Soil_Dirt"
    },
    {
      "x": -10,
      "y": 2,
      "z": -13,
      "name": "Soil_Dirt"
    },
    {
      "x": -10,
      "y": 3,
      "z": -13,
      "name": "Soil_Grass"
    },
    {
      "x": -10,
      "y": 0,
      "z": -12,
      "name": "Soil_Dirt"
    },
    {
      "x": -10,
      "y": 1,
      "z": -12,
      "name": "Soil_Dirt"
    },
    {
      "x": -10,
      "y": 2,
      "z": -12,
      "name": "Soil_Dirt"
    },
    {
      "x": -10,
      "y": 3,
      "z": -12,
      "name": "Soil_Grass"
    },
    {
      "x": -10,
      "y": 0,
      "z": -11,
      "name": "Soil_Dirt"
    },
    {
      "x": -10,
      "y": 1,
      "z": -11,
      "name": "Soil_Dirt"
    },
    {
      "x": -10,
      "y": 2,
      "z": -11,
      "name": "Soil_Dirt"
    },
    {
      "x": -10,
      "y": 3,
      "z": -11,
      "name": "Soil_Grass"
    },
    {
      "x": -10,
      "y": 0,
      "z": -10,
      "name": "Soil_Dirt"
    },
    {
      "x": -10,
      "y": 1,
      "z": -10,
      "name": "Soil_Dirt"
    },
    {
      "x": -10,
      "y": 2,
      "z": -10,
      "name": "Soil_Dirt"
    },
    {
      "x": -10,
      "y": 3,
      "z": -10,
      "name": "Soil_Grass"
    },
    {
      "x": -10,
      "y": 0,
      "z": -9,
      "name": "Soil_Dirt"
    },
    {
      "x": -10,
      "y": 1,
      "z": -9,
      "name": "Soil_Dirt"
    },
    {
      "x": -10,
      "y": 2,
      "z": -9,
      "name": "Soil_Dirt"
    },
    {
      "x": -10,
      "y": 3,
      "z": -9,
      "name": "Soil_Grass"
    },
    {
      "x": -10,
      "y": 0,
      "z": -8,
      "name": "Soil_Dirt"
    },
    {
      "x": -10,
      "y": 1,
      "z": -8,
      "name": "Soil_Dirt"
    },
    {
      "x": -10,
      "y": 2,
      "z": -8,
      "name": "Soil_Dirt"
    },
    {
      "x": -10,
      "y": 3,
      "z": -8,
      "name": "Soil_Grass"
    },
    {
      "x": -10,
      "y": 0,
      "z": -7,
      "name": "Soil_Dirt"
    },
    {
      "x": -10,
      "y": 1,
      "z": -7,
      "name": "Soil_Dirt"
    },
    {
      "x": -10,
      "y": 2,
      "z": -7,
      "name": "Soil_Dirt"
    },
    {
      "x": -10,
      "y": 3,
      "z": -7,
      "name": "Soil_Grass"
    },
    {
      "x": -10,
      "y": 0,
      "z": -6,
      "name": "Soil_Dirt"
    },
    {
      "x": -10,
      "y": 1,
      "z": -6,
      "name": "Soil_Dirt"
    },
    {
      "x": -10,
      "y": 2,
      "z": -6,
      "name": "Soil_Dirt"
    },
    {
      "x": -10,
      "y": 3,
      "z": -6,
      "name": "Soil_Grass"
    },
    {
      "x": -10,
      "y": 0,
      "z": -5,
      "name": "Soil_Dirt"
    },
    {
      "x": -10,
      "y": 1,
      "z": -5,
      "name": "Soil_Dirt"
    },
    {
      "x": -10,
      "y": 2,
      "z": -5,
      "name": "Soil_Dirt"
    },
    {
      "x": -10,
      "y": 3,
      "z": -5,
      "name": "Soil_Grass"
    },
    {
      "x": -10,
      "y": 0,
      "z": -4,
      "name": "Soil_Dirt"
    },
    {
      "x": -10,
      "y": 1,
      "z": -4,
      "name": "Soil_Dirt"
    },
    {
      "x": -10,
      "y": 2,
      "z": -4,
      "name": "Soil_Dirt"
    },
    {
      "x": -10,
      "y": 3,
      "z": -4,
      "name": "Soil_Grass"
    },
    {
      "x": -10,
      "y": 0,
      "z": -3,
      "name": "Soil_Dirt"
    },
    {
      "x": -10,
      "y": 1,
      "z": -3,
      "name": "Soil_Dirt"
    },
    {
      "x": -10,
      "y": 2,
      "z": -3,
      "name": "Soil_Dirt"
    },
    {
      "x": -10,
      "y": 3,
      "z": -3,
      "name": "Soil_Grass"
    },
    {
      "x": -10,
      "y": 0,
      "z": -2,
      "name": "Soil_Dirt"
    },
    {
      "x": -10,
      "y": 1,
      "z": -2,
      "name": "Soil_Dirt"
    },
    {
      "x": -10,
      "y": 2,
      "z": -2,
      "name": "Soil_Dirt"
    },
    {
      "x": -10,
      "y": 3,
      "z": -2,
      "name": "Soil_Clay"
    },
    {
      "x": -10,
      "y": 4,
      "z": -2,
      "name": "*Wood_Hardwood_Fence_State_Definitions_Corner",
      "rotation": 1
    },
    {
      "x": -10,
      "y": 5,
      "z": -2,
      "name": "*Wood_Hardwood_Fence_State_Definitions_Corner",
      "rotation": 1
    },
    {
      "x": -10,
      "y": 0,
      "z": -1,
      "name": "Soil_Dirt"
    },
    {
      "x": -10,
      "y": 1,
      "z": -1,
      "name": "Soil_Dirt"
    },
    {
      "x": -10,
      "y": 2,
      "z": -1,
      "name": "Soil_Dirt"
    },
    {
      "x": -10,
      "y": 3,
      "z": -1,
      "name": "Soil_Clay"
    },
    {
      "x": -10,
      "y": 4,
      "z": -1,
      "name": "Wood_Hardwood_Fence",
      "rotation": 1
    },
    {
      "x": -10,
      "y": 5,
      "z": -1,
      "name": "Wood_Hardwood_Fence",
      "rotation": 1
    },
    {
      "x": -10,
      "y": 0,
      "z": 0,
      "name": "Soil_Dirt"
    },
    {
      "x": -10,
      "y": 1,
      "z": 0,
      "name": "Soil_Dirt"
    },
    {
      "x": -10,
      "y": 2,
      "z": 0,
      "name": "Soil_Dirt"
    },
    {
      "x": -10,
      "y": 3,
      "z": 0,
      "name": "Soil_Clay"
    },
    {
      "x": -10,
      "y": 4,
      "z": 0,
      "name": "Wood_Hardwood_Fence",
      "rotation": 1
    },
    {
      "x": -10,
      "y": 5,
      "z": 0,
      "name": "Wood_Hardwood_Fence",
      "rotation": 1
    },
    {
      "x": -10,
      "y": 0,
      "z": 1,
      "name": "Soil_Dirt"
    },
    {
      "x": -10,
      "y": 1,
      "z": 1,
      "name": "Soil_Dirt"
    },
    {
      "x": -10,
      "y": 2,
      "z": 1,
      "name": "Soil_Dirt"
    },
    {
      "x": -10,
      "y": 3,
      "z": 1,
      "name": "Soil_Clay"
    },
    {
      "x": -10,
      "y": 4,
      "z": 1,
      "name": "Wood_Hardwood_Fence",
      "rotation": 1
    },
    {
      "x": -10,
      "y": 5,
      "z": 1,
      "name": "Wood_Hardwood_Fence",
      "rotation": 1
    },
    {
      "x": -10,
      "y": 0,
      "z": 2,
      "name": "Soil_Dirt"
    },
    {
      "x": -10,
      "y": 1,
      "z": 2,
      "name": "Soil_Dirt"
    },
    {
      "x": -10,
      "y": 2,
      "z": 2,
      "name": "Soil_Dirt"
    },
    {
      "x": -10,
      "y": 3,
      "z": 2,
      "name": "Soil_Clay"
    },
    {
      "x": -10,
      "y": 4,
      "z": 2,
      "name": "Wood_Hardwood_Fence",
      "rotation": 1
    },
    {
      "x": -10,
      "y": 5,
      "z": 2,
      "name": "Wood_Hardwood_Fence",
      "rotation": 1
    },
    {
      "x": -10,
      "y": 0,
      "z": 3,
      "name": "Soil_Dirt"
    },
    {
      "x": -10,
      "y": 1,
      "z": 3,
      "name": "Soil_Dirt"
    },
    {
      "x": -10,
      "y": 2,
      "z": 3,
      "name": "Soil_Dirt"
    },
    {
      "x": -10,
      "y": 3,
      "z": 3,
      "name": "Soil_Clay"
    },
    {
      "x": -10,
      "y": 4,
      "z": 3,
      "name": "Wood_Hardwood_Fence",
      "rotation": 1
    },
    {
      "x": -10,
      "y": 5,
      "z": 3,
      "name": "Wood_Hardwood_Fence",
      "rotation": 1
    },
    {
      "x": -10,
      "y": 0,
      "z": 4,
      "name": "Soil_Dirt"
    },
    {
      "x": -10,
      "y": 1,
      "z": 4,
      "name": "Soil_Dirt"
    },
    {
      "x": -10,
      "y": 2,
      "z": 4,
      "name": "Soil_Dirt"
    },
    {
      "x": -10,
      "y": 3,
      "z": 4,
      "name": "Soil_Clay"
    },
    {
      "x": -10,
      "y": 4,
      "z": 4,
      "name": "Wood_Hardwood_Fence",
      "rotation": 1
    },
    {
      "x": -10,
      "y": 5,
      "z": 4,
      "name": "Wood_Hardwood_Fence",
      "rotation": 1
    },
    {
      "x": -10,
      "y": 0,
      "z": 5,
      "name": "Soil_Dirt"
    },
    {
      "x": -10,
      "y": 1,
      "z": 5,
      "name": "Soil_Dirt"
    },
    {
      "x": -10,
      "y": 2,
      "z": 5,
      "name": "Soil_Dirt"
    },
    {
      "x": -10,
      "y": 3,
      "z": 5,
      "name": "Soil_Clay"
    },
    {
      "x": -10,
      "y": 4,
      "z": 5,
      "name": "Wood_Hardwood_Fence",
      "rotation": 1
    },
    {
      "x": -10,
      "y": 5,
      "z": 5,
      "name": "Wood_Hardwood_Fence",
      "rotation": 1
    },
    {
      "x": -10,
      "y": 0,
      "z": 6,
      "name": "Soil_Dirt"
    },
    {
      "x": -10,
      "y": 1,
      "z": 6,
      "name": "Soil_Dirt"
    },
    {
      "x": -10,
      "y": 2,
      "z": 6,
      "name": "Soil_Dirt"
    },
    {
      "x": -10,
      "y": 3,
      "z": 6,
      "name": "Soil_Clay"
    },
    {
      "x": -10,
      "y": 4,
      "z": 6,
      "name": "*Wood_Hardwood_Fence_State_Definitions_Corner",
      "rotation": 2
    },
    {
      "x": -10,
      "y": 5,
      "z": 6,
      "name": "*Wood_Hardwood_Fence_State_Definitions_Corner",
      "rotation": 2
    },
    {
      "x": -10,
      "y": 0,
      "z": 7,
      "name": "Soil_Dirt"
    },
    {
      "x": -10,
      "y": 1,
      "z": 7,
      "name": "Soil_Dirt"
    },
    {
      "x": -10,
      "y": 2,
      "z": 7,
      "name": "Soil_Dirt"
    },
    {
      "x": -10,
      "y": 3,
      "z": 7,
      "name": "Soil_Grass"
    },
    {
      "x": -10,
      "y": 0,
      "z": 8,
      "name": "Soil_Dirt"
    },
    {
      "x": -10,
      "y": 1,
      "z": 8,
      "name": "Soil_Dirt"
    },
    {
      "x": -10,
      "y": 2,
      "z": 8,
      "name": "Soil_Dirt"
    },
    {
      "x": -10,
      "y": 3,
      "z": 8,
      "name": "Soil_Grass"
    },
    {
      "x": -10,
      "y": 0,
      "z": 9,
      "name": "Soil_Dirt"
    },
    {
      "x": -10,
      "y": 1,
      "z": 9,
      "name": "Soil_Dirt"
    },
    {
      "x": -10,
      "y": 2,
      "z": 9,
      "name": "Soil_Dirt"
    },
    {
      "x": -10,
      "y": 3,
      "z": 9,
      "name": "Soil_Grass"
    },
    {
      "x": -10,
      "y": 0,
      "z": 10,
      "name": "Soil_Dirt"
    },
    {
      "x": -10,
      "y": 1,
      "z": 10,
      "name": "Soil_Dirt"
    },
    {
      "x": -10,
      "y": 2,
      "z": 10,
      "name": "Soil_Dirt"
    },
    {
      "x": -10,
      "y": 3,
      "z": 10,
      "name": "Soil_Grass"
    },
    {
      "x": -10,
      "y": 0,
      "z": 11,
      "name": "Soil_Dirt"
    },
    {
      "x": -10,
      "y": 1,
      "z": 11,
      "name": "Soil_Dirt"
    },
    {
      "x": -10,
      "y": 2,
      "z": 11,
      "name": "Soil_Dirt"
    },
    {
      "x": -10,
      "y": 3,
      "z": 11,
      "name": "Soil_Grass"
    },
    {
      "x": -10,
      "y": 0,
      "z": 12,
      "name": "Soil_Dirt"
    },
    {
      "x": -10,
      "y": 1,
      "z": 12,
      "name": "Soil_Dirt"
    },
    {
      "x": -10,
      "y": 2,
      "z": 12,
      "name": "Soil_Dirt"
    },
    {
      "x": -10,
      "y": 3,
      "z": 12,
      "name": "Soil_Grass"
    },
    {
      "x": -10,
      "y": 0,
      "z": 13,
      "name": "Soil_Dirt"
    },
    {
      "x": -10,
      "y": 1,
      "z": 13,
      "name": "Soil_Dirt"
    },
    {
      "x": -10,
      "y": 2,
      "z": 13,
      "name": "Soil_Dirt"
    },
    {
      "x": -10,
      "y": 3,
      "z": 13,
      "name": "Soil_Grass"
    },
    {
      "x": -10,
      "y": 0,
      "z": 14,
      "name": "Soil_Dirt"
    },
    {
      "x": -10,
      "y": 1,
      "z": 14,
      "name": "Soil_Dirt"
    },
    {
      "x": -10,
      "y": 2,
      "z": 14,
      "name": "Soil_Dirt"
    },
    {
      "x": -10,
      "y": 3,
      "z": 14,
      "name": "Soil_Grass"
    },
    {
      "x": -10,
      "y": 0,
      "z": 15,
      "name": "Soil_Dirt"
    },
    {
      "x": -10,
      "y": 1,
      "z": 15,
      "name": "Soil_Dirt"
    },
    {
      "x": -10,
      "y": 2,
      "z": 15,
      "name": "Soil_Dirt"
    },
    {
      "x": -10,
      "y": 3,
      "z": 15,
      "name": "Soil_Grass"
    },
    {
      "x": -10,
      "y": 0,
      "z": 16,
      "name": "Soil_Dirt"
    },
    {
      "x": -10,
      "y": 1,
      "z": 16,
      "name": "Soil_Dirt"
    },
    {
      "x": -10,
      "y": 2,
      "z": 16,
      "name": "Soil_Dirt"
    },
    {
      "x": -10,
      "y": 3,
      "z": 16,
      "name": "Soil_Grass"
    },
    {
      "x": -9,
      "y": 0,
      "z": -15,
      "name": "Soil_Dirt"
    },
    {
      "x": -9,
      "y": 1,
      "z": -15,
      "name": "Soil_Dirt"
    },
    {
      "x": -9,
      "y": 2,
      "z": -15,
      "name": "Soil_Dirt"
    },
    {
      "x": -9,
      "y": 3,
      "z": -15,
      "name": "Soil_Grass"
    },
    {
      "x": -9,
      "y": 0,
      "z": -14,
      "name": "Soil_Dirt"
    },
    {
      "x": -9,
      "y": 1,
      "z": -14,
      "name": "Soil_Dirt"
    },
    {
      "x": -9,
      "y": 2,
      "z": -14,
      "name": "Soil_Dirt"
    },
    {
      "x": -9,
      "y": 3,
      "z": -14,
      "name": "Soil_Grass"
    },
    {
      "x": -9,
      "y": 0,
      "z": -13,
      "name": "Soil_Dirt"
    },
    {
      "x": -9,
      "y": 1,
      "z": -13,
      "name": "Soil_Dirt"
    },
    {
      "x": -9,
      "y": 2,
      "z": -13,
      "name": "Soil_Dirt"
    },
    {
      "x": -9,
      "y": 3,
      "z": -13,
      "name": "Soil_Grass"
    },
    {
      "x": -9,
      "y": 0,
      "z": -12,
      "name": "Soil_Dirt"
    },
    {
      "x": -9,
      "y": 1,
      "z": -12,
      "name": "Soil_Dirt"
    },
    {
      "x": -9,
      "y": 2,
      "z": -12,
      "name": "Soil_Dirt"
    },
    {
      "x": -9,
      "y": 3,
      "z": -12,
      "name": "Soil_Grass"
    },
    {
      "x": -9,
      "y": 0,
      "z": -11,
      "name": "Soil_Dirt"
    },
    {
      "x": -9,
      "y": 1,
      "z": -11,
      "name": "Soil_Dirt"
    },
    {
      "x": -9,
      "y": 2,
      "z": -11,
      "name": "Soil_Dirt"
    },
    {
      "x": -9,
      "y": 3,
      "z": -11,
      "name": "Soil_Grass"
    },
    {
      "x": -9,
      "y": 0,
      "z": -10,
      "name": "Soil_Dirt"
    },
    {
      "x": -9,
      "y": 1,
      "z": -10,
      "name": "Soil_Dirt"
    },
    {
      "x": -9,
      "y": 2,
      "z": -10,
      "name": "Soil_Dirt"
    },
    {
      "x": -9,
      "y": 3,
      "z": -10,
      "name": "Soil_Grass"
    },
    {
      "x": -9,
      "y": 0,
      "z": -9,
      "name": "Soil_Dirt"
    },
    {
      "x": -9,
      "y": 1,
      "z": -9,
      "name": "Soil_Dirt"
    },
    {
      "x": -9,
      "y": 2,
      "z": -9,
      "name": "Soil_Dirt"
    },
    {
      "x": -9,
      "y": 3,
      "z": -9,
      "name": "Soil_Grass"
    },
    {
      "x": -9,
      "y": 0,
      "z": -8,
      "name": "Soil_Dirt"
    },
    {
      "x": -9,
      "y": 1,
      "z": -8,
      "name": "Soil_Dirt"
    },
    {
      "x": -9,
      "y": 2,
      "z": -8,
      "name": "Soil_Dirt"
    },
    {
      "x": -9,
      "y": 3,
      "z": -8,
      "name": "Soil_Grass"
    },
    {
      "x": -9,
      "y": 0,
      "z": -7,
      "name": "Soil_Dirt"
    },
    {
      "x": -9,
      "y": 1,
      "z": -7,
      "name": "Soil_Dirt"
    },
    {
      "x": -9,
      "y": 2,
      "z": -7,
      "name": "Soil_Dirt"
    },
    {
      "x": -9,
      "y": 3,
      "z": -7,
      "name": "Soil_Grass"
    },
    {
      "x": -9,
      "y": 0,
      "z": -6,
      "name": "Soil_Dirt"
    },
    {
      "x": -9,
      "y": 1,
      "z": -6,
      "name": "Soil_Dirt"
    },
    {
      "x": -9,
      "y": 2,
      "z": -6,
      "name": "Soil_Dirt"
    },
    {
      "x": -9,
      "y": 3,
      "z": -6,
      "name": "Soil_Grass"
    },
    {
      "x": -9,
      "y": 0,
      "z": -5,
      "name": "Soil_Dirt"
    },
    {
      "x": -9,
      "y": 1,
      "z": -5,
      "name": "Soil_Dirt"
    },
    {
      "x": -9,
      "y": 2,
      "z": -5,
      "name": "Soil_Dirt"
    },
    {
      "x": -9,
      "y": 3,
      "z": -5,
      "name": "Soil_Grass"
    },
    {
      "x": -9,
      "y": 0,
      "z": -4,
      "name": "Soil_Dirt"
    },
    {
      "x": -9,
      "y": 1,
      "z": -4,
      "name": "Soil_Dirt"
    },
    {
      "x": -9,
      "y": 2,
      "z": -4,
      "name": "Soil_Dirt"
    },
    {
      "x": -9,
      "y": 3,
      "z": -4,
      "name": "Soil_Grass"
    },
    {
      "x": -9,
      "y": 0,
      "z": -3,
      "name": "Soil_Dirt"
    },
    {
      "x": -9,
      "y": 1,
      "z": -3,
      "name": "Soil_Dirt"
    },
    {
      "x": -9,
      "y": 2,
      "z": -3,
      "name": "Soil_Dirt"
    },
    {
      "x": -9,
      "y": 3,
      "z": -3,
      "name": "Soil_Grass"
    },
    {
      "x": -9,
      "y": 0,
      "z": -2,
      "name": "Soil_Dirt"
    },
    {
      "x": -9,
      "y": 1,
      "z": -2,
      "name": "Soil_Dirt"
    },
    {
      "x": -9,
      "y": 2,
      "z": -2,
      "name": "Soil_Dirt"
    },
    {
      "x": -9,
      "y": 3,
      "z": -2,
      "name": "Soil_Clay"
    },
    {
      "x": -9,
      "y": 4,
      "z": -2,
      "name": "Wood_Hardwood_Fence"
    },
    {
      "x": -9,
      "y": 5,
      "z": -2,
      "name": "Wood_Hardwood_Fence"
    },
    {
      "x": -9,
      "y": 0,
      "z": -1,
      "name": "Soil_Dirt"
    },
    {
      "x": -9,
      "y": 1,
      "z": -1,
      "name": "Soil_Dirt"
    },
    {
      "x": -9,
      "y": 2,
      "z": -1,
      "name": "Soil_Dirt"
    },
    {
      "x": -9,
      "y": 3,
      "z": -1,
      "name": "Soil_Clay"
    },
    {
      "x": -9,
      "y": 0,
      "z": 0,
      "name": "Soil_Dirt"
    },
    {
      "x": -9,
      "y": 1,
      "z": 0,
      "name": "Soil_Dirt"
    },
    {
      "x": -9,
      "y": 2,
      "z": 0,
      "name": "Soil_Dirt"
    },
    {
      "x": -9,
      "y": 3,
      "z": 0,
      "name": "Soil_Clay"
    },
    {
      "x": -9,
      "y": 0,
      "z": 1,
      "name": "Soil_Dirt"
    },
    {
      "x": -9,
      "y": 1,
      "z": 1,
      "name": "Soil_Dirt"
    },
    {
      "x": -9,
      "y": 2,
      "z": 1,
      "name": "Soil_Dirt"
    },
    {
      "x": -9,
      "y": 3,
      "z": 1,
      "name": "Soil_Clay"
    },
    {
      "x": -9,
      "y": 0,
      "z": 2,
      "name": "Soil_Dirt"
    },
    {
      "x": -9,
      "y": 1,
      "z": 2,
      "name": "Soil_Dirt"
    },
    {
      "x": -9,
      "y": 2,
      "z": 2,
      "name": "Soil_Dirt"
    },
    {
      "x": -9,
      "y": 3,
      "z": 2,
      "name": "Soil_Clay"
    },
    {
      "x": -9,
      "y": 0,
      "z": 3,
      "name": "Soil_Dirt"
    },
    {
      "x": -9,
      "y": 1,
      "z": 3,
      "name": "Soil_Dirt"
    },
    {
      "x": -9,
      "y": 2,
      "z": 3,
      "name": "Soil_Dirt"
    },
    {
      "x": -9,
      "y": 3,
      "z": 3,
      "name": "Soil_Clay"
    },
    {
      "x": -9,
      "y": 0,
      "z": 4,
      "name": "Soil_Dirt"
    },
    {
      "x": -9,
      "y": 1,
      "z": 4,
      "name": "Soil_Dirt"
    },
    {
      "x": -9,
      "y": 2,
      "z": 4,
      "name": "Soil_Dirt"
    },
    {
      "x": -9,
      "y": 3,
      "z": 4,
      "name": "Soil_Clay"
    },
    {
      "x": -9,
      "y": 0,
      "z": 5,
      "name": "Soil_Dirt"
    },
    {
      "x": -9,
      "y": 1,
      "z": 5,
      "name": "Soil_Dirt"
    },
    {
      "x": -9,
      "y": 2,
      "z": 5,
      "name": "Soil_Dirt"
    },
    {
      "x": -9,
      "y": 3,
      "z": 5,
      "name": "Soil_Clay"
    },
    {
      "x": -9,
      "y": 0,
      "z": 6,
      "name": "Soil_Dirt"
    },
    {
      "x": -9,
      "y": 1,
      "z": 6,
      "name": "Soil_Dirt"
    },
    {
      "x": -9,
      "y": 2,
      "z": 6,
      "name": "Soil_Dirt"
    },
    {
      "x": -9,
      "y": 3,
      "z": 6,
      "name": "Soil_Clay"
    },
    {
      "x": -9,
      "y": 4,
      "z": 6,
      "name": "Wood_Hardwood_Fence",
      "rotation": 2
    },
    {
      "x": -9,
      "y": 5,
      "z": 6,
      "name": "Wood_Hardwood_Fence",
      "rotation": 2
    },
    {
      "x": -9,
      "y": 0,
      "z": 7,
      "name": "Soil_Dirt"
    },
    {
      "x": -9,
      "y": 1,
      "z": 7,
      "name": "Soil_Dirt"
    },
    {
      "x": -9,
      "y": 2,
      "z": 7,
      "name": "Soil_Dirt"
    },
    {
      "x": -9,
      "y": 3,
      "z": 7,
      "name": "Soil_Grass"
    },
    {
      "x": -9,
      "y": 0,
      "z": 8,
      "name": "Soil_Dirt"
    },
    {
      "x": -9,
      "y": 1,
      "z": 8,
      "name": "Soil_Dirt"
    },
    {
      "x": -9,
      "y": 2,
      "z": 8,
      "name": "Soil_Dirt"
    },
    {
      "x": -9,
      "y": 3,
      "z": 8,
      "name": "Soil_Grass"
    },
    {
      "x": -9,
      "y": 0,
      "z": 9,
      "name": "Soil_Dirt"
    },
    {
      "x": -9,
      "y": 1,
      "z": 9,
      "name": "Soil_Dirt"
    },
    {
      "x": -9,
      "y": 2,
      "z": 9,
      "name": "Soil_Dirt"
    },
    {
      "x": -9,
      "y": 3,
      "z": 9,
      "name": "Soil_Grass"
    },
    {
      "x": -9,
      "y": 0,
      "z": 10,
      "name": "Soil_Dirt"
    },
    {
      "x": -9,
      "y": 1,
      "z": 10,
      "name": "Soil_Dirt"
    },
    {
      "x": -9,
      "y": 2,
      "z": 10,
      "name": "Soil_Dirt"
    },
    {
      "x": -9,
      "y": 3,
      "z": 10,
      "name": "Soil_Grass"
    },
    {
      "x": -9,
      "y": 0,
      "z": 11,
      "name": "Soil_Dirt"
    },
    {
      "x": -9,
      "y": 1,
      "z": 11,
      "name": "Soil_Dirt"
    },
    {
      "x": -9,
      "y": 2,
      "z": 11,
      "name": "Soil_Dirt"
    },
    {
      "x": -9,
      "y": 3,
      "z": 11,
      "name": "Soil_Grass"
    },
    {
      "x": -9,
      "y": 0,
      "z": 12,
      "name": "Soil_Dirt"
    },
    {
      "x": -9,
      "y": 1,
      "z": 12,
      "name": "Soil_Dirt"
    },
    {
      "x": -9,
      "y": 2,
      "z": 12,
      "name": "Soil_Dirt"
    },
    {
      "x": -9,
      "y": 3,
      "z": 12,
      "name": "Soil_Grass"
    },
    {
      "x": -9,
      "y": 0,
      "z": 13,
      "name": "Soil_Dirt"
    },
    {
      "x": -9,
      "y": 1,
      "z": 13,
      "name": "Soil_Dirt"
    },
    {
      "x": -9,
      "y": 2,
      "z": 13,
      "name": "Soil_Dirt"
    },
    {
      "x": -9,
      "y": 3,
      "z": 13,
      "name": "Soil_Grass"
    },
    {
      "x": -9,
      "y": 0,
      "z": 14,
      "name": "Soil_Dirt"
    },
    {
      "x": -9,
      "y": 1,
      "z": 14,
      "name": "Soil_Dirt"
    },
    {
      "x": -9,
      "y": 2,
      "z": 14,
      "name": "Soil_Dirt"
    },
    {
      "x": -9,
      "y": 3,
      "z": 14,
      "name": "Soil_Grass"
    },
    {
      "x": -9,
      "y": 0,
      "z": 15,
      "name": "Soil_Dirt"
    },
    {
      "x": -9,
      "y": 1,
      "z": 15,
      "name": "Soil_Dirt"
    },
    {
      "x": -9,
      "y": 2,
      "z": 15,
      "name": "Soil_Dirt"
    },
    {
      "x": -9,
      "y": 3,
      "z": 15,
      "name": "Soil_Grass"
    },
    {
      "x": -9,
      "y": 0,
      "z": 16,
      "name": "Soil_Dirt"
    },
    {
      "x": -9,
      "y": 1,
      "z": 16,
      "name": "Soil_Dirt"
    },
    {
      "x": -9,
      "y": 2,
      "z": 16,
      "name": "Soil_Dirt"
    },
    {
      "x": -9,
      "y": 3,
      "z": 16,
      "name": "Soil_Grass"
    },
    {
      "x": -8,
      "y": 0,
      "z": -15,
      "name": "Soil_Dirt"
    },
    {
      "x": -8,
      "y": 1,
      "z": -15,
      "name": "Soil_Dirt"
    },
    {
      "x": -8,
      "y": 2,
      "z": -15,
      "name": "Soil_Dirt"
    },
    {
      "x": -8,
      "y": 3,
      "z": -15,
      "name": "Soil_Grass"
    },
    {
      "x": -8,
      "y": 0,
      "z": -14,
      "name": "Soil_Dirt"
    },
    {
      "x": -8,
      "y": 1,
      "z": -14,
      "name": "Soil_Dirt"
    },
    {
      "x": -8,
      "y": 2,
      "z": -14,
      "name": "Soil_Dirt"
    },
    {
      "x": -8,
      "y": 3,
      "z": -14,
      "name": "Soil_Grass"
    },
    {
      "x": -8,
      "y": 0,
      "z": -13,
      "name": "Soil_Dirt"
    },
    {
      "x": -8,
      "y": 1,
      "z": -13,
      "name": "Soil_Dirt"
    },
    {
      "x": -8,
      "y": 2,
      "z": -13,
      "name": "Soil_Dirt"
    },
    {
      "x": -8,
      "y": 3,
      "z": -13,
      "name": "Soil_Grass"
    },
    {
      "x": -8,
      "y": 0,
      "z": -12,
      "name": "Soil_Dirt"
    },
    {
      "x": -8,
      "y": 1,
      "z": -12,
      "name": "Soil_Dirt"
    },
    {
      "x": -8,
      "y": 2,
      "z": -12,
      "name": "Soil_Dirt"
    },
    {
      "x": -8,
      "y": 3,
      "z": -12,
      "name": "Soil_Grass"
    },
    {
      "x": -8,
      "y": 0,
      "z": -11,
      "name": "Soil_Dirt"
    },
    {
      "x": -8,
      "y": 1,
      "z": -11,
      "name": "Soil_Dirt"
    },
    {
      "x": -8,
      "y": 2,
      "z": -11,
      "name": "Soil_Dirt"
    },
    {
      "x": -8,
      "y": 3,
      "z": -11,
      "name": "Soil_Grass"
    },
    {
      "x": -8,
      "y": 0,
      "z": -10,
      "name": "Soil_Dirt"
    },
    {
      "x": -8,
      "y": 1,
      "z": -10,
      "name": "Soil_Dirt"
    },
    {
      "x": -8,
      "y": 2,
      "z": -10,
      "name": "Soil_Dirt"
    },
    {
      "x": -8,
      "y": 3,
      "z": -10,
      "name": "Soil_Grass"
    },
    {
      "x": -8,
      "y": 0,
      "z": -9,
      "name": "Soil_Dirt"
    },
    {
      "x": -8,
      "y": 1,
      "z": -9,
      "name": "Soil_Dirt"
    },
    {
      "x": -8,
      "y": 2,
      "z": -9,
      "name": "Soil_Dirt"
    },
    {
      "x": -8,
      "y": 3,
      "z": -9,
      "name": "Soil_Grass"
    },
    {
      "x": -8,
      "y": 0,
      "z": -8,
      "name": "Soil_Dirt"
    },
    {
      "x": -8,
      "y": 1,
      "z": -8,
      "name": "Soil_Dirt"
    },
    {
      "x": -8,
      "y": 2,
      "z": -8,
      "name": "Soil_Dirt"
    },
    {
      "x": -8,
      "y": 3,
      "z": -8,
      "name": "Soil_Grass"
    },
    {
      "x": -8,
      "y": 0,
      "z": -7,
      "name": "Soil_Dirt"
    },
    {
      "x": -8,
      "y": 1,
      "z": -7,
      "name": "Soil_Dirt"
    },
    {
      "x": -8,
      "y": 2,
      "z": -7,
      "name": "Soil_Dirt"
    },
    {
      "x": -8,
      "y": 3,
      "z": -7,
      "name": "Soil_Grass"
    },
    {
      "x": -8,
      "y": 0,
      "z": -6,
      "name": "Soil_Dirt"
    },
    {
      "x": -8,
      "y": 1,
      "z": -6,
      "name": "Soil_Dirt"
    },
    {
      "x": -8,
      "y": 2,
      "z": -6,
      "name": "Soil_Dirt"
    },
    {
      "x": -8,
      "y": 3,
      "z": -6,
      "name": "Soil_Grass"
    },
    {
      "x": -8,
      "y": 0,
      "z": -5,
      "name": "Soil_Dirt"
    },
    {
      "x": -8,
      "y": 1,
      "z": -5,
      "name": "Soil_Dirt"
    },
    {
      "x": -8,
      "y": 2,
      "z": -5,
      "name": "Soil_Dirt"
    },
    {
      "x": -8,
      "y": 3,
      "z": -5,
      "name": "Soil_Grass"
    },
    {
      "x": -8,
      "y": 0,
      "z": -4,
      "name": "Soil_Dirt"
    },
    {
      "x": -8,
      "y": 1,
      "z": -4,
      "name": "Soil_Dirt"
    },
    {
      "x": -8,
      "y": 2,
      "z": -4,
      "name": "Soil_Dirt"
    },
    {
      "x": -8,
      "y": 3,
      "z": -4,
      "name": "Soil_Grass"
    },
    {
      "x": -8,
      "y": 0,
      "z": -3,
      "name": "Soil_Dirt"
    },
    {
      "x": -8,
      "y": 1,
      "z": -3,
      "name": "Soil_Dirt"
    },
    {
      "x": -8,
      "y": 2,
      "z": -3,
      "name": "Soil_Dirt"
    },
    {
      "x": -8,
      "y": 3,
      "z": -3,
      "name": "Soil_Grass"
    },
    {
      "x": -8,
      "y": 0,
      "z": -2,
      "name": "Soil_Dirt"
    },
    {
      "x": -8,
      "y": 1,
      "z": -2,
      "name": "Soil_Dirt"
    },
    {
      "x": -8,
      "y": 2,
      "z": -2,
      "name": "Soil_Dirt"
    },
    {
      "x": -8,
      "y": 3,
      "z": -2,
      "name": "Soil_Clay"
    },
    {
      "x": -8,
      "y": 4,
      "z": -2,
      "name": "Wood_Hardwood_Fence"
    },
    {
      "x": -8,
      "y": 5,
      "z": -2,
      "name": "Wood_Hardwood_Fence"
    },
    {
      "x": -8,
      "y": 7,
      "z": -2,
      "name": "Wood_Ash_Trunk",
      "rotation": 5
    },
    {
      "x": -8,
      "y": 0,
      "z": -1,
      "name": "Soil_Dirt"
    },
    {
      "x": -8,
      "y": 1,
      "z": -1,
      "name": "Soil_Dirt"
    },
    {
      "x": -8,
      "y": 2,
      "z": -1,
      "name": "Soil_Dirt"
    },
    {
      "x": -8,
      "y": 3,
      "z": -1,
      "name": "Soil_Clay"
    },
    {
      "x": -8,
      "y": 0,
      "z": 0,
      "name": "Soil_Dirt"
    },
    {
      "x": -8,
      "y": 1,
      "z": 0,
      "name": "Soil_Dirt"
    },
    {
      "x": -8,
      "y": 2,
      "z": 0,
      "name": "Soil_Dirt"
    },
    {
      "x": -8,
      "y": 3,
      "z": 0,
      "name": "K2_Slot_Portal_6"
    },
    {
      "x": -8,
      "y": 0,
      "z": 1,
      "name": "Soil_Dirt"
    },
    {
      "x": -8,
      "y": 1,
      "z": 1,
      "name": "Soil_Dirt"
    },
    {
      "x": -8,
      "y": 2,
      "z": 1,
      "name": "Soil_Dirt"
    },
    {
      "x": -8,
      "y": 3,
      "z": 1,
      "name": "Soil_Clay"
    },
    {
      "x": -8,
      "y": 0,
      "z": 2,
      "name": "Soil_Dirt"
    },
    {
      "x": -8,
      "y": 1,
      "z": 2,
      "name": "Soil_Dirt"
    },
    {
      "x": -8,
      "y": 2,
      "z": 2,
      "name": "Soil_Dirt"
    },
    {
      "x": -8,
      "y": 3,
      "z": 2,
      "name": "Soil_Clay"
    },
    {
      "x": -8,
      "y": 0,
      "z": 3,
      "name": "Soil_Dirt"
    },
    {
      "x": -8,
      "y": 1,
      "z": 3,
      "name": "Soil_Dirt"
    },
    {
      "x": -8,
      "y": 2,
      "z": 3,
      "name": "Soil_Dirt"
    },
    {
      "x": -8,
      "y": 3,
      "z": 3,
      "name": "Soil_Clay"
    },
    {
      "x": -8,
      "y": 0,
      "z": 4,
      "name": "Soil_Dirt"
    },
    {
      "x": -8,
      "y": 1,
      "z": 4,
      "name": "Soil_Dirt"
    },
    {
      "x": -8,
      "y": 2,
      "z": 4,
      "name": "Soil_Dirt"
    },
    {
      "x": -8,
      "y": 3,
      "z": 4,
      "name": "K2_Slot_Portal_5"
    },
    {
      "x": -8,
      "y": 0,
      "z": 5,
      "name": "Soil_Dirt"
    },
    {
      "x": -8,
      "y": 1,
      "z": 5,
      "name": "Soil_Dirt"
    },
    {
      "x": -8,
      "y": 2,
      "z": 5,
      "name": "Soil_Dirt"
    },
    {
      "x": -8,
      "y": 3,
      "z": 5,
      "name": "Soil_Clay"
    },
    {
      "x": -8,
      "y": 0,
      "z": 6,
      "name": "Soil_Dirt"
    },
    {
      "x": -8,
      "y": 1,
      "z": 6,
      "name": "Soil_Dirt"
    },
    {
      "x": -8,
      "y": 2,
      "z": 6,
      "name": "Soil_Dirt"
    },
    {
      "x": -8,
      "y": 3,
      "z": 6,
      "name": "Soil_Clay"
    },
    {
      "x": -8,
      "y": 4,
      "z": 6,
      "name": "Wood_Hardwood_Fence",
      "rotation": 2
    },
    {
      "x": -8,
      "y": 5,
      "z": 6,
      "name": "Wood_Hardwood_Fence",
      "rotation": 2
    },
    {
      "x": -8,
      "y": 7,
      "z": 6,
      "name": "Wood_Ash_Trunk",
      "rotation": 5
    },
    {
      "x": -8,
      "y": 0,
      "z": 7,
      "name": "Soil_Dirt"
    },
    {
      "x": -8,
      "y": 1,
      "z": 7,
      "name": "Soil_Dirt"
    },
    {
      "x": -8,
      "y": 2,
      "z": 7,
      "name": "Soil_Dirt"
    },
    {
      "x": -8,
      "y": 3,
      "z": 7,
      "name": "Soil_Grass"
    },
    {
      "x": -8,
      "y": 0,
      "z": 8,
      "name": "Soil_Dirt"
    },
    {
      "x": -8,
      "y": 1,
      "z": 8,
      "name": "Soil_Dirt"
    },
    {
      "x": -8,
      "y": 2,
      "z": 8,
      "name": "Soil_Dirt"
    },
    {
      "x": -8,
      "y": 3,
      "z": 8,
      "name": "Soil_Grass"
    },
    {
      "x": -8,
      "y": 0,
      "z": 9,
      "name": "Soil_Dirt"
    },
    {
      "x": -8,
      "y": 1,
      "z": 9,
      "name": "Soil_Dirt"
    },
    {
      "x": -8,
      "y": 2,
      "z": 9,
      "name": "Soil_Dirt"
    },
    {
      "x": -8,
      "y": 3,
      "z": 9,
      "name": "Soil_Grass"
    },
    {
      "x": -8,
      "y": 0,
      "z": 10,
      "name": "Soil_Dirt"
    },
    {
      "x": -8,
      "y": 1,
      "z": 10,
      "name": "Soil_Dirt"
    },
    {
      "x": -8,
      "y": 2,
      "z": 10,
      "name": "Soil_Dirt"
    },
    {
      "x": -8,
      "y": 3,
      "z": 10,
      "name": "Soil_Grass"
    },
    {
      "x": -8,
      "y": 0,
      "z": 11,
      "name": "Soil_Dirt"
    },
    {
      "x": -8,
      "y": 1,
      "z": 11,
      "name": "Soil_Dirt"
    },
    {
      "x": -8,
      "y": 2,
      "z": 11,
      "name": "Soil_Dirt"
    },
    {
      "x": -8,
      "y": 3,
      "z": 11,
      "name": "Soil_Grass"
    },
    {
      "x": -8,
      "y": 0,
      "z": 12,
      "name": "Soil_Dirt"
    },
    {
      "x": -8,
      "y": 1,
      "z": 12,
      "name": "Soil_Dirt"
    },
    {
      "x": -8,
      "y": 2,
      "z": 12,
      "name": "Soil_Dirt"
    },
    {
      "x": -8,
      "y": 3,
      "z": 12,
      "name": "Soil_Grass"
    },
    {
      "x": -8,
      "y": 0,
      "z": 13,
      "name": "Soil_Dirt"
    },
    {
      "x": -8,
      "y": 1,
      "z": 13,
      "name": "Soil_Dirt"
    },
    {
      "x": -8,
      "y": 2,
      "z": 13,
      "name": "Soil_Dirt"
    },
    {
      "x": -8,
      "y": 3,
      "z": 13,
      "name": "Soil_Grass"
    },
    {
      "x": -8,
      "y": 0,
      "z": 14,
      "name": "Soil_Dirt"
    },
    {
      "x": -8,
      "y": 1,
      "z": 14,
      "name": "Soil_Dirt"
    },
    {
      "x": -8,
      "y": 2,
      "z": 14,
      "name": "Soil_Dirt"
    },
    {
      "x": -8,
      "y": 3,
      "z": 14,
      "name": "Soil_Grass"
    },
    {
      "x": -8,
      "y": 0,
      "z": 15,
      "name": "Soil_Dirt"
    },
    {
      "x": -8,
      "y": 1,
      "z": 15,
      "name": "Soil_Dirt"
    },
    {
      "x": -8,
      "y": 2,
      "z": 15,
      "name": "Soil_Dirt"
    },
    {
      "x": -8,
      "y": 3,
      "z": 15,
      "name": "Soil_Grass"
    },
    {
      "x": -8,
      "y": 0,
      "z": 16,
      "name": "Soil_Dirt"
    },
    {
      "x": -8,
      "y": 1,
      "z": 16,
      "name": "Soil_Dirt"
    },
    {
      "x": -8,
      "y": 2,
      "z": 16,
      "name": "Soil_Dirt"
    },
    {
      "x": -8,
      "y": 3,
      "z": 16,
      "name": "Soil_Grass"
    },
    {
      "x": -7,
      "y": 0,
      "z": -15,
      "name": "Soil_Dirt"
    },
    {
      "x": -7,
      "y": 1,
      "z": -15,
      "name": "Soil_Dirt"
    },
    {
      "x": -7,
      "y": 2,
      "z": -15,
      "name": "Soil_Dirt"
    },
    {
      "x": -7,
      "y": 3,
      "z": -15,
      "name": "Soil_Grass"
    },
    {
      "x": -7,
      "y": 0,
      "z": -14,
      "name": "Soil_Dirt"
    },
    {
      "x": -7,
      "y": 1,
      "z": -14,
      "name": "Soil_Dirt"
    },
    {
      "x": -7,
      "y": 2,
      "z": -14,
      "name": "Soil_Dirt"
    },
    {
      "x": -7,
      "y": 3,
      "z": -14,
      "name": "Soil_Grass"
    },
    {
      "x": -7,
      "y": 0,
      "z": -13,
      "name": "Soil_Dirt"
    },
    {
      "x": -7,
      "y": 1,
      "z": -13,
      "name": "Soil_Dirt"
    },
    {
      "x": -7,
      "y": 2,
      "z": -13,
      "name": "Soil_Dirt"
    },
    {
      "x": -7,
      "y": 3,
      "z": -13,
      "name": "Soil_Grass"
    },
    {
      "x": -7,
      "y": 0,
      "z": -12,
      "name": "Soil_Dirt"
    },
    {
      "x": -7,
      "y": 1,
      "z": -12,
      "name": "Soil_Dirt"
    },
    {
      "x": -7,
      "y": 2,
      "z": -12,
      "name": "Soil_Dirt"
    },
    {
      "x": -7,
      "y": 3,
      "z": -12,
      "name": "Soil_Grass"
    },
    {
      "x": -7,
      "y": 0,
      "z": -11,
      "name": "Soil_Dirt"
    },
    {
      "x": -7,
      "y": 1,
      "z": -11,
      "name": "Soil_Dirt"
    },
    {
      "x": -7,
      "y": 2,
      "z": -11,
      "name": "Soil_Dirt"
    },
    {
      "x": -7,
      "y": 3,
      "z": -11,
      "name": "Soil_Grass"
    },
    {
      "x": -7,
      "y": 0,
      "z": -10,
      "name": "Soil_Dirt"
    },
    {
      "x": -7,
      "y": 1,
      "z": -10,
      "name": "Soil_Dirt"
    },
    {
      "x": -7,
      "y": 2,
      "z": -10,
      "name": "Soil_Dirt"
    },
    {
      "x": -7,
      "y": 3,
      "z": -10,
      "name": "Soil_Grass"
    },
    {
      "x": -7,
      "y": 0,
      "z": -9,
      "name": "Soil_Dirt"
    },
    {
      "x": -7,
      "y": 1,
      "z": -9,
      "name": "Soil_Dirt"
    },
    {
      "x": -7,
      "y": 2,
      "z": -9,
      "name": "Soil_Dirt"
    },
    {
      "x": -7,
      "y": 3,
      "z": -9,
      "name": "Soil_Grass"
    },
    {
      "x": -7,
      "y": 0,
      "z": -8,
      "name": "Soil_Dirt"
    },
    {
      "x": -7,
      "y": 1,
      "z": -8,
      "name": "Soil_Dirt"
    },
    {
      "x": -7,
      "y": 2,
      "z": -8,
      "name": "Soil_Dirt"
    },
    {
      "x": -7,
      "y": 3,
      "z": -8,
      "name": "Soil_Grass"
    },
    {
      "x": -7,
      "y": 0,
      "z": -7,
      "name": "Soil_Dirt"
    },
    {
      "x": -7,
      "y": 1,
      "z": -7,
      "name": "Soil_Dirt"
    },
    {
      "x": -7,
      "y": 2,
      "z": -7,
      "name": "Soil_Dirt"
    },
    {
      "x": -7,
      "y": 3,
      "z": -7,
      "name": "Soil_Grass"
    },
    {
      "x": -7,
      "y": 0,
      "z": -6,
      "name": "Soil_Dirt"
    },
    {
      "x": -7,
      "y": 1,
      "z": -6,
      "name": "Soil_Dirt"
    },
    {
      "x": -7,
      "y": 2,
      "z": -6,
      "name": "Soil_Dirt"
    },
    {
      "x": -7,
      "y": 3,
      "z": -6,
      "name": "Soil_Grass"
    },
    {
      "x": -7,
      "y": 0,
      "z": -5,
      "name": "Soil_Dirt"
    },
    {
      "x": -7,
      "y": 1,
      "z": -5,
      "name": "Soil_Dirt"
    },
    {
      "x": -7,
      "y": 2,
      "z": -5,
      "name": "Soil_Dirt"
    },
    {
      "x": -7,
      "y": 3,
      "z": -5,
      "name": "Soil_Grass"
    },
    {
      "x": -7,
      "y": 0,
      "z": -4,
      "name": "Soil_Dirt"
    },
    {
      "x": -7,
      "y": 1,
      "z": -4,
      "name": "Soil_Dirt"
    },
    {
      "x": -7,
      "y": 2,
      "z": -4,
      "name": "Soil_Dirt"
    },
    {
      "x": -7,
      "y": 3,
      "z": -4,
      "name": "Soil_Grass"
    },
    {
      "x": -7,
      "y": 0,
      "z": -3,
      "name": "Soil_Dirt"
    },
    {
      "x": -7,
      "y": 1,
      "z": -3,
      "name": "Soil_Dirt"
    },
    {
      "x": -7,
      "y": 2,
      "z": -3,
      "name": "Soil_Dirt"
    },
    {
      "x": -7,
      "y": 3,
      "z": -3,
      "name": "Soil_Grass"
    },
    {
      "x": -7,
      "y": 0,
      "z": -2,
      "name": "Soil_Dirt"
    },
    {
      "x": -7,
      "y": 1,
      "z": -2,
      "name": "Soil_Dirt"
    },
    {
      "x": -7,
      "y": 2,
      "z": -2,
      "name": "Soil_Dirt"
    },
    {
      "x": -7,
      "y": 3,
      "z": -2,
      "name": "Soil_Clay"
    },
    {
      "x": -7,
      "y": 4,
      "z": -2,
      "name": "Wood_Ash_Trunk_Full"
    },
    {
      "x": -7,
      "y": 5,
      "z": -2,
      "name": "Wood_Ash_Trunk_Full"
    },
    {
      "x": -7,
      "y": 6,
      "z": -2,
      "name": "Wood_Ash_Trunk_Full"
    },
    {
      "x": -7,
      "y": 7,
      "z": -2,
      "name": "Wood_Ash_Trunk_Full",
      "rotation": 5
    },
    {
      "x": -7,
      "y": 0,
      "z": -1,
      "name": "Soil_Dirt"
    },
    {
      "x": -7,
      "y": 1,
      "z": -1,
      "name": "Soil_Dirt"
    },
    {
      "x": -7,
      "y": 2,
      "z": -1,
      "name": "Soil_Dirt"
    },
    {
      "x": -7,
      "y": 3,
      "z": -1,
      "name": "Soil_Clay"
    },
    {
      "x": -7,
      "y": 0,
      "z": 0,
      "name": "Soil_Dirt"
    },
    {
      "x": -7,
      "y": 1,
      "z": 0,
      "name": "Soil_Dirt"
    },
    {
      "x": -7,
      "y": 2,
      "z": 0,
      "name": "Soil_Dirt"
    },
    {
      "x": -7,
      "y": 3,
      "z": 0,
      "name": "Soil_Clay"
    },
    {
      "x": -7,
      "y": 0,
      "z": 1,
      "name": "Soil_Dirt"
    },
    {
      "x": -7,
      "y": 1,
      "z": 1,
      "name": "Soil_Dirt"
    },
    {
      "x": -7,
      "y": 2,
      "z": 1,
      "name": "Soil_Dirt"
    },
    {
      "x": -7,
      "y": 3,
      "z": 1,
      "name": "Plant_Crop_Mushroom_Block_Brown"
    },
    {
      "x": -7,
      "y": 0,
      "z": 2,
      "name": "Soil_Dirt"
    },
    {
      "x": -7,
      "y": 1,
      "z": 2,
      "name": "Soil_Dirt"
    },
    {
      "x": -7,
      "y": 2,
      "z": 2,
      "name": "Soil_Dirt"
    },
    {
      "x": -7,
      "y": 3,
      "z": 2,
      "name": "Plant_Crop_Mushroom_Block_Brown"
    },
    {
      "x": -7,
      "y": 0,
      "z": 3,
      "name": "Soil_Dirt"
    },
    {
      "x": -7,
      "y": 1,
      "z": 3,
      "name": "Soil_Dirt"
    },
    {
      "x": -7,
      "y": 2,
      "z": 3,
      "name": "Soil_Dirt"
    },
    {
      "x": -7,
      "y": 3,
      "z": 3,
      "name": "Plant_Crop_Mushroom_Block_Brown"
    },
    {
      "x": -7,
      "y": 0,
      "z": 4,
      "name": "Soil_Dirt"
    },
    {
      "x": -7,
      "y": 1,
      "z": 4,
      "name": "Soil_Dirt"
    },
    {
      "x": -7,
      "y": 2,
      "z": 4,
      "name": "Soil_Dirt"
    },
    {
      "x": -7,
      "y": 3,
      "z": 4,
      "name": "Soil_Clay"
    },
    {
      "x": -7,
      "y": 0,
      "z": 5,
      "name": "Soil_Dirt"
    },
    {
      "x": -7,
      "y": 1,
      "z": 5,
      "name": "Soil_Dirt"
    },
    {
      "x": -7,
      "y": 2,
      "z": 5,
      "name": "Soil_Dirt"
    },
    {
      "x": -7,
      "y": 3,
      "z": 5,
      "name": "Soil_Clay"
    },
    {
      "x": -7,
      "y": 0,
      "z": 6,
      "name": "Soil_Dirt"
    },
    {
      "x": -7,
      "y": 1,
      "z": 6,
      "name": "Soil_Dirt"
    },
    {
      "x": -7,
      "y": 2,
      "z": 6,
      "name": "Soil_Dirt"
    },
    {
      "x": -7,
      "y": 3,
      "z": 6,
      "name": "Soil_Clay"
    },
    {
      "x": -7,
      "y": 4,
      "z": 6,
      "name": "Wood_Ash_Trunk_Full"
    },
    {
      "x": -7,
      "y": 5,
      "z": 6,
      "name": "Wood_Ash_Trunk_Full"
    },
    {
      "x": -7,
      "y": 6,
      "z": 6,
      "name": "Wood_Ash_Trunk_Full"
    },
    {
      "x": -7,
      "y": 7,
      "z": 6,
      "name": "Wood_Ash_Trunk_Full",
      "rotation": 5
    },
    {
      "x": -7,
      "y": 0,
      "z": 7,
      "name": "Soil_Dirt"
    },
    {
      "x": -7,
      "y": 1,
      "z": 7,
      "name": "Soil_Dirt"
    },
    {
      "x": -7,
      "y": 2,
      "z": 7,
      "name": "Soil_Dirt"
    },
    {
      "x": -7,
      "y": 3,
      "z": 7,
      "name": "Soil_Grass"
    },
    {
      "x": -7,
      "y": 0,
      "z": 8,
      "name": "Soil_Dirt"
    },
    {
      "x": -7,
      "y": 1,
      "z": 8,
      "name": "Soil_Dirt"
    },
    {
      "x": -7,
      "y": 2,
      "z": 8,
      "name": "Soil_Dirt"
    },
    {
      "x": -7,
      "y": 3,
      "z": 8,
      "name": "Soil_Grass"
    },
    {
      "x": -7,
      "y": 0,
      "z": 9,
      "name": "Soil_Dirt"
    },
    {
      "x": -7,
      "y": 1,
      "z": 9,
      "name": "Soil_Dirt"
    },
    {
      "x": -7,
      "y": 2,
      "z": 9,
      "name": "Soil_Dirt"
    },
    {
      "x": -7,
      "y": 3,
      "z": 9,
      "name": "Soil_Grass"
    },
    {
      "x": -7,
      "y": 0,
      "z": 10,
      "name": "Soil_Dirt"
    },
    {
      "x": -7,
      "y": 1,
      "z": 10,
      "name": "Soil_Dirt"
    },
    {
      "x": -7,
      "y": 2,
      "z": 10,
      "name": "Soil_Dirt"
    },
    {
      "x": -7,
      "y": 3,
      "z": 10,
      "name": "Soil_Grass"
    },
    {
      "x": -7,
      "y": 0,
      "z": 11,
      "name": "Soil_Dirt"
    },
    {
      "x": -7,
      "y": 1,
      "z": 11,
      "name": "Soil_Dirt"
    },
    {
      "x": -7,
      "y": 2,
      "z": 11,
      "name": "Soil_Dirt"
    },
    {
      "x": -7,
      "y": 3,
      "z": 11,
      "name": "Soil_Grass"
    },
    {
      "x": -7,
      "y": 0,
      "z": 12,
      "name": "Soil_Dirt"
    },
    {
      "x": -7,
      "y": 1,
      "z": 12,
      "name": "Soil_Dirt"
    },
    {
      "x": -7,
      "y": 2,
      "z": 12,
      "name": "Soil_Dirt"
    },
    {
      "x": -7,
      "y": 3,
      "z": 12,
      "name": "Soil_Grass"
    },
    {
      "x": -7,
      "y": 0,
      "z": 13,
      "name": "Soil_Dirt"
    },
    {
      "x": -7,
      "y": 1,
      "z": 13,
      "name": "Soil_Dirt"
    },
    {
      "x": -7,
      "y": 2,
      "z": 13,
      "name": "Soil_Dirt"
    },
    {
      "x": -7,
      "y": 3,
      "z": 13,
      "name": "Soil_Grass"
    },
    {
      "x": -7,
      "y": 0,
      "z": 14,
      "name": "Soil_Dirt"
    },
    {
      "x": -7,
      "y": 1,
      "z": 14,
      "name": "Soil_Dirt"
    },
    {
      "x": -7,
      "y": 2,
      "z": 14,
      "name": "Soil_Dirt"
    },
    {
      "x": -7,
      "y": 3,
      "z": 14,
      "name": "Soil_Grass"
    },
    {
