{
  "version": 8,
  "blockIdVersion": 11,
  "anchorX": 0,
  "anchorY": 0,
  "anchorZ": 0,
  "blocks": [
    {
      "x": -31,
      "y": 0,
      "z": -31,
      "name": "Soil_Grass"
    },
    {
      "x": -31,
      "y": 0,
      "z": -30,
      "name": "Soil_Grass"
    },
    {
      "x": -31,
      "y": 0,
      "z": -29,
      "name": "Soil_Grass"
    },
    {
      "x": -31,
      "y": 0,
      "z": -28,
      "name": "Soil_Grass"
    },
    {
      "x": -31,
      "y": 0,
      "z": -27,
      "name": "Soil_Grass"
    },
    {
      "x": -31,
      "y": 0,
      "z": -26,
      "name": "Soil_Grass"
    },
    {
      "x": -31,
      "y": 0,
      "z": -25,
      "name": "Soil_Grass"
    },
    {
      "x": -31,
      "y": 0,
      "z": -24,
      "name": "Soil_Grass"
    },
    {
      "x": -31,
      "y": 0,
      "z": -23,
      "name": "Soil_Grass"
    },
    {
      "x": -31,
      "y": 0,
      "z": -22,
      "name": "Soil_Grass"
    },
    {
      "x": -31,
      "y": 0,
      "z": -21,
      "name": "Soil_Grass"
    },
    {
      "x": -31,
      "y": 0,
      "z": -20,
      "name": "Soil_Grass"
    },
    {
      "x": -31,
      "y": 0,
      "z": -19,
      "name": "Soil_Grass"
    },
    {
      "x": -31,
      "y": 7,
      "z": -19,
      "name": "Plant_Leaves_Beech"
    },
    {
      "x": -31,
      "y": 8,
      "z": -19,
      "name": "Plant_Leaves_Beech"
    },
    {
      "x": -31,
      "y": 0,
      "z": -18,
      "name": "Soil_Grass"
    },
    {
      "x": -31,
      "y": 7,
      "z": -18,
      "name": "Plant_Leaves_Beech"
    },
    {
      "x": -31,
      "y": 8,
      "z": -18,
      "name": "Plant_Leaves_Beech"
    },
    {
      "x": -31,
      "y": 11,
      "z": -18,
      "name": "Plant_Leaves_Beech"
    },
    {
      "x": -31,
      "y": 0,
      "z": -17,
      "name": "Soil_Grass"
    },
    {
      "x": -31,
      "y": 7,
      "z": -17,
      "name": "Plant_Leaves_Beech"
    },
    {
      "x": -31,
      "y": 8,
      "z": -17,
      "name": "Plant_Leaves_Beech"
    },
    {
      "x": -31,
      "y": 9,
      "z": -17,
      "name": "Plant_Leaves_Beech"
    },
    {
      "x": -31,
      "y": 11,
      "z": -17,
      "name": "Plant_Leaves_Beech"
    },
    {
      "x": -31,
      "y": 12,
      "z": -17,
      "name": "Plant_Leaves_Beech"
    },
    {
      "x": -31,
      "y": 0,
      "z": -16,
      "name": "Soil_Grass"
    },
    {
      "x": -31,
      "y": 7,
      "z": -16,
      "name": "Wood_Beech_Branch_Corner",
      "rotation": 3
    },
    {
      "x": -31,
      "y": 8,
      "z": -16,
      "name": "Plant_Leaves_Beech"
    },
    {
      "x": -31,
      "y": 9,
      "z": -16,
      "name": "Plant_Leaves_Beech"
    },
    {
      "x": -31,
      "y": 10,
      "z": -16,
      "name": "Plant_Leaves_Beech"
    },
    {
      "x": -31,
      "y": 12,
      "z": -16,
      "name": "Plant_Leaves_Beech"
    },
    {
      "x": -31,
      "y": 0,
      "z": -15,
      "name": "Soil_Grass"
    },
    {
      "x": -31,
      "y": 7,
      "z": -15,
      "name": "Plant_Leaves_Beech"
    },
    {
      "x": -31,
      "y": 8,
      "z": -15,
      "name": "Plant_Leaves_Beech"
    },
    {
      "x": -31,
      "y": 9,
      "z": -15,
      "name": "Plant_Leaves_Beech"
    },
    {
      "x": -31,
      "y": 0,
      "z": -14,
      "name": "Soil_Grass"
    },
    {
      "x": -31,
      "y": 8,
      "z": -14,
      "name": "Plant_Leaves_Beech"
    },
    {
      "x": -31,
      "y": 10,
      "z": -14,
      "name": "Plant_Leaves_Beech"
    },
    {
      "x": -31,
      "y": 0,
      "z": -13,
      "name": "Soil_Grass"
    },
    {
      "x": -31,
      "y": 0,
      "z": -12,
      "name": "Soil_Grass"
    },
    {
      "x": -31,
      "y": 0,
      "z": -11,
      "name": "Soil_Grass"
    },
    {
      "x": -31,
      "y": 0,
      "z": -10,
      "name": "Soil_Grass"
    },
    {
      "x": -31,
      "y": 0,
      "z": -9,
      "name": "Soil_Grass"
    },
    {
      "x": -31,
      "y": 0,
      "z": -8,
      "name": "Soil_Grass"
    },
    {
      "x": -31,
      "y": 0,
      "z": -7,
      "name": "Soil_Grass"
    },
    {
      "x": -31,
      "y": 7,
      "z": -7,
      "name": "Plant_Leaves_Beech"
    },
    {
      "x": -31,
      "y": 8,
      "z": -7,
      "name": "Plant_Leaves_Beech"
    },
    {
      "x": -31,
      "y": 0,
      "z": -6,
      "name": "Soil_Grass"
    },
    {
      "x": -31,
      "y": 7,
      "z": -6,
      "name": "Plant_Leaves_Beech"
    },
    {
      "x": -31,
      "y": 8,
      "z": -6,
      "name": "Plant_Leaves_Beech"
    },
    {
      "x": -31,
      "y": 11,
      "z": -6,
      "name": "Plant_Leaves_Beech"
    },
    {
      "x": -31,
      "y": 0,
      "z": -5,
      "name": "Soil_Grass"
    },
    {
      "x": -31,
      "y": 7,
      "z": -5,
      "name": "Plant_Leaves_Beech"
    },
    {
      "x": -31,
      "y": 8,
      "z": -5,
      "name": "Plant_Leaves_Beech"
    },
    {
      "x": -31,
      "y": 9,
      "z": -5,
      "name": "Plant_Leaves_Beech"
    },
    {
      "x": -31,
      "y": 11,
      "z": -5,
      "name": "Plant_Leaves_Beech"
    },
    {
      "x": -31,
      "y": 12,
      "z": -5,
      "name": "Plant_Leaves_Beech"
    },
    {
      "x": -31,
      "y": 0,
      "z": -4,
      "name": "Soil_Grass"
    },
    {
      "x": -31,
      "y": 7,
      "z": -4,
      "name": "Wood_Beech_Branch_Corner",
      "rotation": 3
    },
    {
      "x": -31,
      "y": 8,
      "z": -4,
      "name": "Plant_Leaves_Beech"
    },
    {
      "x": -31,
      "y": 9,
      "z": -4,
      "name": "Plant_Leaves_Beech"
    },
    {
      "x": -31,
      "y": 10,
      "z": -4,
      "name": "Plant_Leaves_Beech"
    },
    {
      "x": -31,
      "y": 12,
      "z": -4,
      "name": "Plant_Leaves_Beech"
    },
    {
      "x": -31,
      "y": 0,
      "z": -3,
      "name": "Soil_Grass"
    },
    {
      "x": -31,
      "y": 7,
      "z": -3,
      "name": "Plant_Leaves_Beech"
    },
    {
      "x": -31,
      "y": 8,
      "z": -3,
      "name": "Plant_Leaves_Beech"
    },
    {
      "x": -31,
      "y": 9,
      "z": -3,
      "name": "Plant_Leaves_Beech"
    },
    {
      "x": -31,
      "y": 0,
      "z": -2,
      "name": "Soil_Grass"
    },
    {
      "x": -31,
      "y": 8,
      "z": -2,
      "name": "Plant_Leaves_Beech"
    },
    {
      "x": -31,
      "y": 10,
      "z": -2,
      "name": "Plant_Leaves_Beech"
    },
    {
      "x": -31,
      "y": 0,
      "z": -1,
      "name": "Soil_Grass"
    },
    {
      "x": -31,
      "y": 0,
      "z": 0,
      "name": "Soil_Grass"
    },
    {
      "x": -31,
      "y": 0,
      "z": 1,
      "name": "Soil_Grass"
    },
    {
      "x": -31,
      "y": 0,
      "z": 2,
      "name": "Soil_Grass"
    },
    {
      "x": -31,
      "y": 0,
      "z": 3,
      "name": "Soil_Grass"
    },
    {
      "x": -31,
      "y": 0,
      "z": 4,
      "name": "Soil_Grass"
    },
    {
      "x": -31,
      "y": 0,
      "z": 5,
      "name": "Soil_Grass"
    },
    {
      "x": -31,
      "y": 0,
      "z": 6,
      "name": "Soil_Grass"
    },
    {
      "x": -31,
      "y": 7,
      "z": 6,
      "name": "Plant_Leaves_Beech"
    },
    {
      "x": -31,
      "y": 8,
      "z": 6,
      "name": "Plant_Leaves_Beech"
    },
    {
      "x": -31,
      "y": 0,
      "z": 7,
      "name": "Soil_Grass"
    },
    {
      "x": -31,
      "y": 7,
      "z": 7,
      "name": "Plant_Leaves_Beech"
    },
    {
      "x": -31,
      "y": 8,
      "z": 7,
      "name": "Plant_Leaves_Beech"
    },
    {
      "x": -31,
      "y": 11,
      "z": 7,
      "name": "Plant_Leaves_Beech"
    },
    {
      "x": -31,
      "y": 0,
      "z": 8,
      "name": "Soil_Grass"
    },
    {
      "x": -31,
      "y": 7,
      "z": 8,
      "name": "Plant_Leaves_Beech"
    },
    {
      "x": -31,
      "y": 8,
      "z": 8,
      "name": "Plant_Leaves_Beech"
    },
    {
      "x": -31,
      "y": 9,
      "z": 8,
      "name": "Plant_Leaves_Beech"
    },
    {
      "x": -31,
      "y": 11,
      "z": 8,
      "name": "Plant_Leaves_Beech"
    },
    {
      "x": -31,
      "y": 12,
      "z": 8,
      "name": "Plant_Leaves_Beech"
    },
    {
      "x": -31,
      "y": 0,
      "z": 9,
      "name": "Soil_Grass"
    },
    {
      "x": -31,
      "y": 7,
      "z": 9,
      "name": "Wood_Beech_Branch_Corner",
      "rotation": 3
    },
    {
      "x": -31,
      "y": 8,
      "z": 9,
      "name": "Plant_Leaves_Beech"
    },
    {
      "x": -31,
      "y": 9,
      "z": 9,
      "name": "Plant_Leaves_Beech"
    },
    {
      "x": -31,
      "y": 10,
      "z": 9,
      "name": "Plant_Leaves_Beech"
    },
    {
      "x": -31,
      "y": 12,
      "z": 9,
      "name": "Plant_Leaves_Beech"
    },
    {
      "x": -31,
      "y": 0,
      "z": 10,
      "name": "Soil_Grass"
    },
    {
      "x": -31,
      "y": 7,
      "z": 10,
      "name": "Plant_Leaves_Beech"
    },
    {
      "x": -31,
      "y": 8,
      "z": 10,
      "name": "Plant_Leaves_Beech"
    },
    {
      "x": -31,
      "y": 9,
      "z": 10,
      "name": "Plant_Leaves_Beech"
    },
    {
      "x": -31,
      "y": 0,
      "z": 11,
      "name": "Soil_Grass"
    },
    {
      "x": -31,
      "y": 8,
      "z": 11,
      "name": "Plant_Leaves_Beech"
    },
    {
      "x": -31,
      "y": 10,
      "z": 11,
      "name": "Plant_Leaves_Beech"
    },
    {
      "x": -31,
      "y": 0,
      "z": 12,
      "name": "Soil_Grass"
    },
    {
      "x": -31,
      "y": 0,
      "z": 13,
      "name": "Soil_Grass"
    },
    {
      "x": -31,
      "y": 0,
      "z": 14,
      "name": "Soil_Grass"
    },
    {
      "x": -31,
      "y": 0,
      "z": 15,
      "name": "Soil_Grass"
    },
    {
      "x": -31,
      "y": 0,
      "z": 16,
      "name": "Soil_Grass"
    },
    {
      "x": -31,
      "y": 0,
      "z": 17,
      "name": "Soil_Grass"
    },
    {
      "x": -31,
      "y": 0,
      "z": 18,
      "name": "Soil_Grass"
    },
    {
      "x": -31,
      "y": 0,
      "z": 19,
      "name": "Soil_Grass"
    },
    {
      "x": -31,
      "y": 0,
      "z": 20,
      "name": "Soil_Grass"
    },
    {
      "x": -31,
      "y": 0,
      "z": 21,
      "name": "Soil_Grass"
    },
    {
      "x": -31,
      "y": 0,
      "z": 22,
      "name": "Soil_Grass"
    },
    {
      "x": -31,
      "y": 0,
      "z": 23,
      "name": "Soil_Grass"
    },
    {
      "x": -31,
      "y": 0,
      "z": 24,
      "name": "Soil_Grass"
    },
    {
      "x": -31,
      "y": 0,
      "z": 25,
      "name": "Soil_Grass"
    },
    {
      "x": -31,
      "y": 0,
      "z": 26,
      "name": "Soil_Grass"
    },
    {
      "x": -31,
      "y": 0,
      "z": 27,
      "name": "Soil_Grass"
    },
    {
      "x": -31,
      "y": 0,
      "z": 28,
      "name": "Soil_Grass"
    },
    {
      "x": -31,
      "y": 0,
      "z": 29,
      "name": "Soil_Grass"
    },
    {
      "x": -31,
      "y": 0,
      "z": 30,
      "name": "Soil_Grass"
    },
    {
      "x": -31,
      "y": 0,
      "z": 31,
      "name": "Soil_Grass"
    },
    {
      "x": -31,
      "y": 0,
      "z": 32,
      "name": "Soil_Grass"
    },
    {
      "x": -30,
      "y": 0,
      "z": -31,
      "name": "Soil_Grass"
    },
    {
      "x": -30,
      "y": 0,
      "z": -30,
      "name": "Soil_Grass"
    },
    {
      "x": -30,
      "y": 0,
      "z": -29,
      "name": "Soil_Grass"
    },
    {
      "x": -30,
      "y": 0,
      "z": -28,
      "name": "Soil_Grass"
    },
    {
      "x": -30,
      "y": 0,
      "z": -27,
      "name": "Soil_Grass"
    },
    {
      "x": -30,
      "y": 0,
      "z": -26,
      "name": "Soil_Grass"
    },
    {
      "x": -30,
      "y": 0,
      "z": -25,
      "name": "Soil_Grass"
    },
    {
      "x": -30,
      "y": 0,
      "z": -24,
      "name": "Soil_Grass"
    },
    {
      "x": -30,
      "y": 0,
      "z": -23,
      "name": "Soil_Grass"
    },
    {
      "x": -30,
      "y": 0,
      "z": -22,
      "name": "Soil_Grass"
    },
    {
      "x": -30,
      "y": 0,
      "z": -21,
      "name": "Soil_Grass"
    },
    {
      "x": -30,
      "y": 0,
      "z": -20,
      "name": "Soil_Grass"
    },
    {
      "x": -30,
      "y": 7,
      "z": -20,
      "name": "Plant_Leaves_Beech"
    },
    {
      "x": -30,
      "y": 0,
      "z": -19,
      "name": "Soil_Grass"
    },
    {
      "x": -30,
      "y": 7,
      "z": -19,
      "name": "Plant_Leaves_Beech"
    },
    {
      "x": -30,
      "y": 8,
      "z": -19,
      "name": "Plant_Leaves_Beech"
    },
    {
      "x": -30,
      "y": 0,
      "z": -18,
      "name": "Soil_Grass"
    },
    {
      "x": -30,
      "y": 7,
      "z": -18,
      "name": "Plant_Leaves_Beech"
    },
    {
      "x": -30,
      "y": 11,
      "z": -18,
      "name": "Plant_Leaves_Beech"
    },
    {
      "x": -30,
      "y": 0,
      "z": -17,
      "name": "Soil_Grass"
    },
    {
      "x": -30,
      "y": 7,
      "z": -17,
      "name": "Plant_Leaves_Beech"
    },
    {
      "x": -30,
      "y": 11,
      "z": -17,
      "name": "Plant_Leaves_Beech"
    },
    {
      "x": -30,
      "y": 12,
      "z": -17,
      "name": "Plant_Leaves_Beech"
    },
    {
      "x": -30,
      "y": 13,
      "z": -17,
      "name": "Plant_Leaves_Beech"
    },
    {
      "x": -30,
      "y": 15,
      "z": -17,
      "name": "Plant_Leaves_Beech"
    },
    {
      "x": -30,
      "y": 16,
      "z": -17,
      "name": "Plant_Leaves_Beech"
    },
    {
      "x": -30,
      "y": 0,
      "z": -16,
      "name": "Soil_Grass"
    },
    {
      "x": -30,
      "y": 7,
      "z": -16,
      "name": "Wood_Beech_Branch_Long",
      "rotation": 5
    },
    {
      "x": -30,
      "y": 11,
      "z": -16,
      "name": "Plant_Leaves_Beech"
    },
    {
      "x": -30,
      "y": 12,
      "z": -16,
      "name": "Plant_Leaves_Beech"
    },
    {
      "x": -30,
      "y": 13,
      "z": -16,
      "name": "Plant_Leaves_Beech"
    },
    {
      "x": -30,
      "y": 15,
      "z": -16,
      "name": "Plant_Leaves_Beech"
    },
    {
      "x": -30,
      "y": 16,
      "z": -16,
      "name": "Plant_Leaves_Beech"
    },
    {
      "x": -30,
      "y": 0,
      "z": -15,
      "name": "Soil_Grass"
    },
    {
      "x": -30,
      "y": 10,
      "z": -15,
      "name": "Plant_Leaves_Beech"
    },
    {
      "x": -30,
      "y": 12,
      "z": -15,
      "name": "Plant_Leaves_Beech"
    },
    {
      "x": -30,
      "y": 13,
      "z": -15,
      "name": "Plant_Leaves_Beech"
    },
    {
      "x": -30,
      "y": 15,
      "z": -15,
      "name": "Plant_Leaves_Beech"
    },
    {
      "x": -30,
      "y": 16,
      "z": -15,
      "name": "Plant_Leaves_Beech"
    },
    {
      "x": -30,
      "y": 0,
      "z": -14,
      "name": "Soil_Grass"
    },
    {
      "x": -30,
      "y": 10,
      "z": -14,
      "name": "Plant_Leaves_Beech"
    },
    {
      "x": -30,
      "y": 11,
      "z": -14,
      "name": "Plant_Leaves_Beech"
    },
    {
      "x": -30,
      "y": 15,
      "z": -14,
      "name": "Plant_Leaves_Beech"
    },
    {
      "x": -30,
      "y": 0,
      "z": -13,
      "name": "Soil_Grass"
    },
    {
      "x": -30,
      "y": 7,
      "z": -13,
      "name": "Plant_Leaves_Beech"
    },
    {
      "x": -30,
      "y": 8,
      "z": -13,
      "name": "Plant_Leaves_Beech"
    },
    {
      "x": -30,
      "y": 10,
      "z": -13,
      "name": "Plant_Leaves_Beech"
    },
    {
      "x": -30,
      "y": 11,
      "z": -13,
      "name": "Plant_Leaves_Beech"
    },
    {
      "x": -30,
      "y": 0,
      "z": -12,
      "name": "Soil_Grass"
    },
    {
      "x": -30,
      "y": 0,
      "z": -11,
      "name": "Soil_Grass"
    },
    {
      "x": -30,
      "y": 0,
      "z": -10,
      "name": "Soil_Grass"
    },
    {
      "x": -30,
      "y": 0,
      "z": -9,
      "name": "Soil_Grass"
    },
    {
      "x": -30,
      "y": 0,
      "z": -8,
      "name": "Soil_Grass"
    },
    {
      "x": -30,
      "y": 7,
      "z": -8,
      "name": "Plant_Leaves_Beech"
    },
    {
      "x": -30,
      "y": 0,
      "z": -7,
      "name": "Soil_Grass"
    },
    {
      "x": -30,
      "y": 7,
      "z": -7,
      "name": "Plant_Leaves_Beech"
    },
    {
      "x": -30,
      "y": 8,
      "z": -7,
      "name": "Plant_Leaves_Beech"
    },
    {
      "x": -30,
      "y": 0,
      "z": -6,
      "name": "Soil_Grass"
    },
    {
      "x": -30,
      "y": 7,
      "z": -6,
      "name": "Plant_Leaves_Beech"
    },
    {
      "x": -30,
      "y": 11,
      "z": -6,
      "name": "Plant_Leaves_Beech"
    },
    {
      "x": -30,
      "y": 0,
      "z": -5,
      "name": "Soil_Grass"
    },
    {
      "x": -30,
      "y": 7,
      "z": -5,
      "name": "Plant_Leaves_Beech"
    },
    {
      "x": -30,
      "y": 11,
      "z": -5,
      "name": "Plant_Leaves_Beech"
    },
    {
      "x": -30,
      "y": 12,
      "z": -5,
      "name": "Plant_Leaves_Beech"
    },
    {
      "x": -30,
      "y": 13,
      "z": -5,
      "name": "Plant_Leaves_Beech"
    },
    {
      "x": -30,
      "y": 15,
      "z": -5,
      "name": "Plant_Leaves_Beech"
    },
    {
      "x": -30,
      "y": 16,
      "z": -5,
      "name": "Plant_Leaves_Beech"
    },
    {
      "x": -30,
      "y": 0,
      "z": -4,
      "name": "Soil_Grass"
    },
    {
      "x": -30,
      "y": 7,
      "z": -4,
      "name": "Wood_Beech_Branch_Long",
      "rotation": 5
    },
    {
      "x": -30,
      "y": 11,
      "z": -4,
      "name": "Plant_Leaves_Beech"
    },
    {
      "x": -30,
      "y": 12,
      "z": -4,
      "name": "Plant_Leaves_Beech"
    },
    {
      "x": -30,
      "y": 13,
      "z": -4,
      "name": "Plant_Leaves_Beech"
    },
    {
      "x": -30,
      "y": 15,
      "z": -4,
      "name": "Plant_Leaves_Beech"
    },
    {
      "x": -30,
      "y": 16,
      "z": -4,
      "name": "Plant_Leaves_Beech"
    },
    {
      "x": -30,
      "y": 0,
      "z": -3,
      "name": "Soil_Grass"
    },
    {
      "x": -30,
      "y": 10,
      "z": -3,
      "name": "Plant_Leaves_Beech"
    },
    {
      "x": -30,
      "y": 12,
      "z": -3,
      "name": "Plant_Leaves_Beech"
    },
    {
      "x": -30,
      "y": 13,
      "z": -3,
      "name": "Plant_Leaves_Beech"
    },
    {
      "x": -30,
      "y": 15,
      "z": -3,
      "name": "Plant_Leaves_Beech"
    },
    {
      "x": -30,
      "y": 16,
      "z": -3,
      "name": "Plant_Leaves_Beech"
    },
    {
      "x": -30,
      "y": 0,
      "z": -2,
      "name": "Soil_Grass"
    },
    {
      "x": -30,
      "y": 10,
      "z": -2,
      "name": "Plant_Leaves_Beech"
    },
    {
      "x": -30,
      "y": 11,
      "z": -2,
      "name": "Plant_Leaves_Beech"
    },
    {
      "x": -30,
      "y": 15,
      "z": -2,
      "name": "Plant_Leaves_Beech"
    },
    {
      "x": -30,
      "y": 0,
      "z": -1,
      "name": "Soil_Grass"
    },
    {
      "x": -30,
      "y": 7,
      "z": -1,
      "name": "Plant_Leaves_Beech"
    },
    {
      "x": -30,
      "y": 8,
      "z": -1,
      "name": "Plant_Leaves_Beech"
    },
    {
      "x": -30,
      "y": 10,
      "z": -1,
      "name": "Plant_Leaves_Beech"
    },
    {
      "x": -30,
      "y": 11,
      "z": -1,
      "name": "Plant_Leaves_Beech"
    },
    {
      "x": -30,
      "y": 0,
      "z": 0,
      "name": "Soil_Grass"
    },
    {
      "x": -30,
      "y": 0,
      "z": 1,
      "name": "Soil_Grass"
    },
    {
      "x": -30,
      "y": 0,
      "z": 2,
      "name": "Soil_Grass"
    },
    {
      "x": -30,
      "y": 0,
      "z": 3,
      "name": "Soil_Grass"
    },
    {
      "x": -30,
      "y": 0,
      "z": 4,
      "name": "Soil_Grass"
    },
    {
      "x": -30,
      "y": 0,
      "z": 5,
      "name": "Soil_Grass"
    },
    {
      "x": -30,
      "y": 7,
      "z": 5,
      "name": "Plant_Leaves_Beech"
    },
    {
      "x": -30,
      "y": 0,
      "z": 6,
      "name": "Soil_Grass"
    },
    {
      "x": -30,
      "y": 7,
      "z": 6,
      "name": "Plant_Leaves_Beech"
    },
    {
      "x": -30,
      "y": 8,
      "z": 6,
      "name": "Plant_Leaves_Beech"
    },
    {
      "x": -30,
      "y": 0,
      "z": 7,
      "name": "Soil_Grass"
    },
    {
      "x": -30,
      "y": 7,
      "z": 7,
      "name": "Plant_Leaves_Beech"
    },
    {
      "x": -30,
      "y": 11,
      "z": 7,
      "name": "Plant_Leaves_Beech"
    },
    {
      "x": -30,
      "y": 0,
      "z": 8,
      "name": "Soil_Grass"
    },
    {
      "x": -30,
      "y": 7,
      "z": 8,
      "name": "Plant_Leaves_Beech"
    },
    {
      "x": -30,
      "y": 11,
      "z": 8,
      "name": "Plant_Leaves_Beech"
    },
    {
      "x": -30,
      "y": 12,
      "z": 8,
      "name": "Plant_Leaves_Beech"
    },
    {
      "x": -30,
      "y": 13,
      "z": 8,
      "name": "Plant_Leaves_Beech"
    },
    {
      "x": -30,
      "y": 15,
      "z": 8,
      "name": "Plant_Leaves_Beech"
    },
    {
      "x": -30,
      "y": 16,
      "z": 8,
      "name": "Plant_Leaves_Beech"
    },
    {
      "x": -30,
      "y": 0,
      "z": 9,
      "name": "Soil_Grass"
    },
    {
      "x": -30,
      "y": 7,
      "z": 9,
      "name": "Wood_Beech_Branch_Long",
      "rotation": 5
    },
    {
      "x": -30,
      "y": 11,
      "z": 9,
      "name": "Plant_Leaves_Beech"
    },
    {
      "x": -30,
      "y": 12,
      "z": 9,
      "name": "Plant_Leaves_Beech"
    },
    {
      "x": -30,
      "y": 13,
      "z": 9,
      "name": "Plant_Leaves_Beech"
    },
    {
      "x": -30,
      "y": 15,
      "z": 9,
      "name": "Plant_Leaves_Beech"
    },
    {
      "x": -30,
      "y": 16,
      "z": 9,
      "name": "Plant_Leaves_Beech"
    },
    {
      "x": -30,
      "y": 0,
      "z": 10,
      "name": "Soil_Grass"
    },
    {
      "x": -30,
      "y": 10,
      "z": 10,
      "name": "Plant_Leaves_Beech"
    },
    {
      "x": -30,
      "y": 12,
      "z": 10,
      "name": "Plant_Leaves_Beech"
    },
    {
      "x": -30,
      "y": 13,
      "z": 10,
      "name": "Plant_Leaves_Beech"
    },
    {
      "x": -30,
      "y": 15,
      "z": 10,
      "name": "Plant_Leaves_Beech"
    },
    {
      "x": -30,
      "y": 16,
      "z": 10,
      "name": "Plant_Leaves_Beech"
    },
    {
      "x": -30,
      "y": 0,
      "z": 11,
      "name": "Soil_Grass"
    },
    {
      "x": -30,
      "y": 10,
      "z": 11,
      "name": "Plant_Leaves_Beech"
    },
    {
      "x": -30,
      "y": 11,
      "z": 11,
      "name": "Plant_Leaves_Beech"
    },
    {
      "x": -30,
      "y": 15,
      "z": 11,
      "name": "Plant_Leaves_Beech"
    },
    {
      "x": -30,
      "y": 0,
      "z": 12,
      "name": "Soil_Grass"
    },
    {
      "x": -30,
      "y": 7,
      "z": 12,
      "name": "Plant_Leaves_Beech"
    },
    {
      "x": -30,
      "y": 8,
      "z": 12,
      "name": "Plant_Leaves_Beech"
    },
    {
      "x": -30,
      "y": 10,
      "z": 12,
      "name": "Plant_Leaves_Beech"
    },
    {
      "x": -30,
      "y": 11,
      "z": 12,
      "name": "Plant_Leaves_Beech"
    },
    {
      "x": -30,
      "y": 0,
      "z": 13,
      "name": "Soil_Grass"
    },
    {
      "x": -30,
      "y": 0,
      "z": 14,
      "name": "Soil_Grass"
    },
    {
      "x": -30,
      "y": 0,
      "z": 15,
      "name": "Soil_Grass"
    },
    {
      "x": -30,
      "y": 0,
      "z": 16,
      "name": "Soil_Grass"
    },
    {
      "x": -30,
      "y": 0,
      "z": 17,
      "name": "Soil_Grass"
    },
    {
      "x": -30,
      "y": 0,
      "z": 18,
      "name": "Soil_Grass"
    },
    {
      "x": -30,
      "y": 0,
      "z": 19,
      "name": "Soil_Grass"
    },
    {
      "x": -30,
      "y": 0,
      "z": 20,
      "name": "Soil_Grass"
    },
    {
      "x": -30,
      "y": 0,
      "z": 21,
      "name": "Soil_Grass"
    },
    {
      "x": -30,
      "y": 7,
      "z": 21,
      "name": "Plant_Leaves_Beech"
    },
    {
      "x": -30,
      "y": 0,
      "z": 22,
      "name": "Soil_Grass"
    },
    {
      "x": -30,
      "y": 7,
      "z": 22,
      "name": "Plant_Leaves_Beech"
    },
    {
      "x": -30,
      "y": 8,
      "z": 22,
      "name": "Plant_Leaves_Beech"
    },
    {
      "x": -30,
      "y": 0,
      "z": 23,
      "name": "Soil_Grass"
    },
    {
      "x": -30,
      "y": 7,
      "z": 23,
      "name": "Plant_Leaves_Beech"
    },
    {
      "x": -30,
      "y": 8,
      "z": 23,
      "name": "Plant_Leaves_Beech"
    },
    {
      "x": -30,
      "y": 9,
      "z": 23,
      "name": "Plant_Leaves_Beech"
    },
    {
      "x": -30,
      "y": 0,
      "z": 24,
      "name": "Soil_Grass"
    },
    {
      "x": -30,
      "y": 7,
      "z": 24,
      "name": "Plant_Leaves_Beech"
    },
    {
      "x": -30,
      "y": 8,
      "z": 24,
      "name": "Plant_Leaves_Beech"
    },
    {
      "x": -30,
      "y": 0,
      "z": 25,
      "name": "Soil_Grass"
    },
    {
      "x": -30,
      "y": 0,
      "z": 26,
      "name": "Soil_Grass"
    },
    {
      "x": -30,
      "y": 0,
      "z": 27,
      "name": "Soil_Grass"
    },
    {
      "x": -30,
      "y": 0,
      "z": 28,
      "name": "Soil_Grass"
    },
    {
      "x": -30,
      "y": 0,
      "z": 29,
      "name": "Soil_Grass"
    },
    {
      "x": -30,
      "y": 0,
      "z": 30,
      "name": "Soil_Grass"
    },
    {
      "x": -30,
      "y": 0,
      "z": 31,
      "name": "Soil_Grass"
    },
    {
      "x": -30,
      "y": 0,
      "z": 32,
      "name": "Soil_Grass"
    },
    {
      "x": -29,
      "y": 0,
      "z": -31,
      "name": "Soil_Grass"
    },
    {
      "x": -29,
      "y": 0,
      "z": -30,
      "name": "Soil_Grass"
    },
    {
      "x": -29,
      "y": 0,
      "z": -29,
      "name": "Soil_Grass"
    },
    {
      "x": -29,
      "y": 7,
      "z": -29,
      "name": "Plant_Leaves_Beech"
    },
    {
      "x": -29,
      "y": 0,
      "z": -28,
      "name": "Soil_Grass"
    },
    {
      "x": -29,
      "y": 7,
      "z": -28,
      "name": "Plant_Leaves_Beech"
    },
    {
      "x": -29,
      "y": 8,
      "z": -28,
      "name": "Plant_Leaves_Beech"
    },
    {
      "x": -29,
      "y": 0,
      "z": -27,
      "name": "Soil_Grass"
    },
    {
      "x": -29,
      "y": 7,
      "z": -27,
      "name": "Plant_Leaves_Beech"
    },
    {
      "x": -29,
      "y": 8,
      "z": -27,
      "name": "Plant_Leaves_Beech"
    },
    {
      "x": -29,
      "y": 9,
      "z": -27,
      "name": "Plant_Leaves_Beech"
    },
    {
      "x": -29,
      "y": 0,
      "z": -26,
      "name": "Soil_Grass"
    },
    {
      "x": -29,
      "y": 7,
      "z": -26,
      "name": "Plant_Leaves_Beech"
    },
    {
      "x": -29,
      "y": 8,
      "z": -26,
      "name": "Plant_Leaves_Beech"
    },
    {
      "x": -29,
      "y": 0,
      "z": -25,
      "name": "Soil_Grass"
    },
    {
      "x": -29,
      "y": 0,
      "z": -24,
      "name": "Soil_Grass"
    },
    {
      "x": -29,
      "y": 0,
      "z": -23,
      "name": "Soil_Grass"
    },
    {
      "x": -29,
      "y": 0,
      "z": -22,
      "name": "Soil_Grass"
    },
    {
      "x": -29,
      "y": 0,
      "z": -21,
      "name": "Soil_Grass"
    },
    {
      "x": -29,
      "y": 0,
      "z": -20,
      "name": "Soil_Grass"
    },
    {
      "x": -29,
      "y": 11,
      "z": -20,
      "name": "Plant_Leaves_Beech"
    },
    {
      "x": -29,
      "y": 0,
      "z": -19,
      "name": "Soil_Grass"
    },
    {
      "x": -29,
      "y": 10,
      "z": -19,
      "name": "Plant_Leaves_Beech"
    },
    {
      "x": -29,
      "y": 11,
      "z": -19,
      "name": "Plant_Leaves_Beech"
    },
    {
      "x": -29,
      "y": 12,
      "z": -19,
      "name": "Plant_Leaves_Beech"
    },
    {
      "x": -29,
      "y": 0,
      "z": -18,
      "name": "Soil_Grass"
    },
    {
      "x": -29,
      "y": 10,
      "z": -18,
      "name": "Plant_Leaves_Beech"
    },
    {
      "x": -29,
      "y": 15,
      "z": -18,
      "name": "Plant_Leaves_Beech"
    },
    {
      "x": -29,
      "y": 16,
      "z": -18,
      "name": "Plant_Leaves_Beech"
    },
    {
      "x": -29,
      "y": 0,
      "z": -17,
      "name": "Soil_Grass"
    },
    {
      "x": -29,
      "y": 12,
      "z": -17,
      "name": "Plant_Leaves_Beech"
    },
    {
      "x": -29,
      "y": 13,
      "z": -17,
      "name": "Plant_Leaves_Beech"
    },
    {
      "x": -29,
      "y": 15,
      "z": -17,
      "name": "Plant_Leaves_Beech"
    },
    {
      "x": -29,
      "y": 16,
      "z": -17,
      "name": "Plant_Leaves_Beech"
    },
    {
      "x": -29,
      "y": 17,
      "z": -17,
      "name": "Plant_Leaves_Beech"
    },
    {
      "x": -29,
      "y": 0,
      "z": -16,
      "name": "Soil_Grass"
    },
    {
      "x": -29,
      "y": 7,
      "z": -16,
      "name": "Wood_Beech_Branch_Long",
      "rotation": 5
    },
    {
      "x": -29,
      "y": 12,
      "z": -16,
      "name": "Wood_Beech_Branch_Long",
      "rotation": 5
    },
    {
      "x": -29,
      "y": 13,
      "z": -16,
      "name": "Plant_Leaves_Beech"
    },
    {
      "x": -29,
      "y": 15,
      "z": -16,
      "name": "Wood_Beech_Branch_Corner",
      "rotation": 3
    },
    {
      "x": -29,
      "y": 16,
      "z": -16,
      "name": "Plant_Leaves_Beech"
    },
    {
      "x": -29,
      "y": 17,
      "z": -16,
      "name": "Plant_Leaves_Beech"
    },
    {
      "x": -29,
      "y": 0,
      "z": -15,
      "name": "Soil_Grass"
    },
    {
      "x": -29,
      "y": 12,
      "z": -15,
      "name": "Plant_Leaves_Beech"
    },
    {
      "x": -29,
      "y": 13,
      "z": -15,
      "name": "Plant_Leaves_Beech"
    },
    {
      "x": -29,
      "y": 15,
      "z": -15,
      "name": "Plant_Leaves_Beech"
    },
    {
      "x": -29,
      "y": 16,
      "z": -15,
      "name": "Plant_Leaves_Beech"
    },
    {
      "x": -29,
      "y": 17,
      "z": -15,
      "name": "Plant_Leaves_Beech"
    },
    {
      "x": -29,
      "y": 0,
      "z": -14,
      "name": "Soil_Grass"
    },
    {
      "x": -29,
      "y": 10,
      "z": -14,
      "name": "Wood_Beech_Branch_Corner",
      "rotation": 3
    },
    {
      "x": -29,
      "y": 11,
      "z": -14,
      "name": "Plant_Leaves_Beech"
    },
    {
      "x": -29,
      "y": 15,
      "z": -14,
      "name": "Plant_Leaves_Beech"
    },
    {
      "x": -29,
      "y": 16,
      "z": -14,
      "name": "Plant_Leaves_Beech"
    },
    {
      "x": -29,
      "y": 0,
      "z": -13,
      "name": "Soil_Grass"
    },
    {
      "x": -29,
      "y": 8,
      "z": -13,
      "name": "Plant_Leaves_Beech"
    },
    {
      "x": -29,
      "y": 10,
      "z": -13,
      "name": "Plant_Leaves_Beech"
    },
    {
      "x": -29,
      "y": 11,
      "z": -13,
      "name": "Plant_Leaves_Beech"
    },
    {
      "x": -29,
      "y": 16,
      "z": -13,
      "name": "Plant_Leaves_Beech"
    },
    {
      "x": -29,
      "y": 0,
      "z": -12,
      "name": "Soil_Grass"
    },
    {
      "x": -29,
      "y": 7,
      "z": -12,
      "name": "Plant_Leaves_Beech"
    },
    {
      "x": -29,
      "y": 8,
      "z": -12,
      "name": "Plant_Leaves_Beech"
    },
    {
      "x": -29,
      "y": 0,
      "z": -11,
      "name": "Soil_Grass"
    },
    {
      "x": -29,
      "y": 0,
      "z": -10,
      "name": "Soil_Grass"
    },
    {
      "x": -29,
      "y": 0,
      "z": -9,
      "name": "Soil_Grass"
    },
    {
      "x": -29,
      "y": 0,
      "z": -8,
      "name": "Soil_Grass"
    },
    {
      "x": -29,
      "y": 11,
      "z": -8,
      "name": "Plant_Leaves_Beech"
    },
    {
      "x": -29,
      "y": 0,
      "z": -7,
      "name": "Soil_Grass"
    },
    {
      "x": -29,
      "y": 10,
      "z": -7,
      "name": "Plant_Leaves_Beech"
    },
    {
      "x": -29,
      "y": 11,
      "z": -7,
      "name": "Plant_Leaves_Beech"
    },
    {
      "x": -29,
      "y": 12,
      "z": -7,
      "name": "Plant_Leaves_Beech"
    },
    {
      "x": -29,
      "y": 0,
      "z": -6,
      "name": "Soil_Grass"
    },
    {
      "x": -29,
      "y": 10,
      "z": -6,
      "name": "Plant_Leaves_Beech"
    },
    {
      "x": -29,
      "y": 15,
      "z": -6,
      "name": "Plant_Leaves_Beech"
    },
    {
      "x": -29,
      "y": 16,
      "z": -6,
      "name": "Plant_Leaves_Beech"
    },
    {
      "x": -29,
      "y": 0,
      "z": -5,
      "name": "Soil_Grass"
    },
    {
      "x": -29,
      "y": 12,
      "z": -5,
      "name": "Plant_Leaves_Beech"
    },
    {
      "x": -29,
      "y": 13,
      "z": -5,
      "name": "Plant_Leaves_Beech"
    },
    {
      "x": -29,
      "y": 15,
      "z": -5,
      "name": "Plant_Leaves_Beech"
    },
    {
      "x": -29,
      "y": 16,
      "z": -5,
      "name": "Plant_Leaves_Beech"
    },
    {
      "x": -29,
      "y": 17,
      "z": -5,
      "name": "Plant_Leaves_Beech"
    },
    {
      "x": -29,
      "y": 0,
      "z": -4,
      "name": "Soil_Grass"
    },
    {
      "x": -29,
      "y": 7,
      "z": -4,
      "name": "Wood_Beech_Branch_Long",
      "rotation": 5
    },
    {
      "x": -29,
      "y": 12,
      "z": -4,
      "name": "Wood_Beech_Branch_Long",
      "rotation": 5
    },
    {
      "x": -29,
      "y": 13,
      "z": -4,
      "name": "Plant_Leaves_Beech"
    },
    {
      "x": -29,
      "y": 15,
      "z": -4,
      "name": "Wood_Beech_Branch_Corner",
      "rotation": 3
    },
    {
      "x": -29,
      "y": 16,
      "z": -4,
      "name": "Plant_Leaves_Beech"
    },
    {
      "x": -29,
      "y": 17,
      "z": -4,
      "name": "Plant_Leaves_Beech"
    },
    {
      "x": -29,
      "y": 0,
      "z": -3,
      "name": "Soil_Grass"
    },
    {
      "x": -29,
      "y": 12,
      "z": -3,
      "name": "Plant_Leaves_Beech"
    },
    {
      "x": -29,
      "y": 13,
      "z": -3,
      "name": "Plant_Leaves_Beech"
    },
    {
      "x": -29,
      "y": 15,
      "z": -3,
      "name": "Plant_Leaves_Beech"
    },
    {
      "x": -29,
      "y": 16,
      "z": -3,
      "name": "Plant_Leaves_Beech"
    },
    {
      "x": -29,
      "y": 17,
      "z": -3,
      "name": "Plant_Leaves_Beech"
    },
    {
      "x": -29,
      "y": 0,
      "z": -2,
      "name": "Soil_Grass"
    },
    {
      "x": -29,
      "y": 10,
      "z": -2,
      "name": "Wood_Beech_Branch_Corner",
      "rotation": 3
    },
    {
      "x": -29,
      "y": 11,
      "z": -2,
      "name": "Plant_Leaves_Beech"
    },
    {
      "x": -29,
      "y": 15,
      "z": -2,
      "name": "Plant_Leaves_Beech"
    },
    {
      "x": -29,
      "y": 16,
      "z": -2,
      "name": "Plant_Leaves_Beech"
    },
    {
      "x": -29,
      "y": 0,
      "z": -1,
      "name": "Soil_Grass"
    },
    {
      "x": -29,
      "y": 8,
      "z": -1,
      "name": "Plant_Leaves_Beech"
    },
    {
      "x": -29,
      "y": 10,
      "z": -1,
      "name": "Plant_Leaves_Beech"
    },
    {
      "x": -29,
      "y": 11,
      "z": -1,
      "name": "Plant_Leaves_Beech"
    },
    {
      "x": -29,
      "y": 16,
      "z": -1,
      "name": "Plant_Leaves_Beech"
    },
    {
      "x": -29,
      "y": 0,
      "z": 0,
      "name": "Soil_Grass"
    },
    {
      "x": -29,
      "y": 7,
      "z": 0,
      "name": "Plant_Leaves_Beech"
    },
    {
      "x": -29,
      "y": 8,
      "z": 0,
      "name": "Plant_Leaves_Beech"
    },
    {
      "x": -29,
      "y": 0,
      "z": 1,
      "name": "Soil_Grass"
    },
    {
      "x": -29,
      "y": 0,
      "z": 2,
      "name": "Soil_Grass"
    },
    {
      "x": -29,
      "y": 0,
      "z": 3,
      "name": "Soil_Grass"
    },
    {
      "x": -29,
      "y": 0,
      "z": 4,
      "name": "Soil_Grass"
    },
    {
      "x": -29,
      "y": 0,
      "z": 5,
      "name": "Soil_Grass"
    },
    {
      "x": -29,
      "y": 11,
      "z": 5,
      "name": "Plant_Leaves_Beech"
    },
    {
      "x": -29,
      "y": 0,
      "z": 6,
      "name": "Soil_Grass"
    },
    {
      "x": -29,
      "y": 10,
      "z": 6,
      "name": "Plant_Leaves_Beech"
    },
    {
      "x": -29,
      "y": 11,
      "z": 6,
      "name": "Plant_Leaves_Beech"
    },
    {
      "x": -29,
      "y": 12,
      "z": 6,
      "name": "Plant_Leaves_Beech"
    },
    {
      "x": -29,
      "y": 0,
      "z": 7,
      "name": "Soil_Grass"
    },
    {
      "x": -29,
      "y": 10,
      "z": 7,
      "name": "Plant_Leaves_Beech"
    },
    {
      "x": -29,
      "y": 15,
      "z": 7,
      "name": "Plant_Leaves_Beech"
    },
    {
      "x": -29,
      "y": 16,
      "z": 7,
      "name": "Plant_Leaves_Beech"
    },
    {
      "x": -29,
      "y": 0,
      "z": 8,
      "name": "Soil_Grass"
    },
    {
      "x": -29,
      "y": 12,
      "z": 8,
      "name": "Plant_Leaves_Beech"
    },
    {
      "x": -29,
      "y": 13,
      "z": 8,
      "name": "Plant_Leaves_Beech"
    },
    {
      "x": -29,
      "y": 15,
      "z": 8,
      "name": "Plant_Leaves_Beech"
    },
    {
      "x": -29,
      "y": 16,
      "z": 8,
      "name": "Plant_Leaves_Beech"
    },
    {
      "x": -29,
      "y": 17,
      "z": 8,
      "name": "Plant_Leaves_Beech"
    },
    {
      "x": -29,
      "y": 0,
      "z": 9,
      "name": "Soil_Grass"
    },
    {
      "x": -29,
      "y": 7,
      "z": 9,
      "name": "Wood_Beech_Branch_Long",
      "rotation": 5
    },
    {
      "x": -29,
      "y": 12,
      "z": 9,
      "name": "Wood_Beech_Branch_Long",
      "rotation": 5
    },
    {
      "x": -29,
      "y": 13,
      "z": 9,
      "name": "Plant_Leaves_Beech"
    },
    {
      "x": -29,
      "y": 15,
      "z": 9,
      "name": "Wood_Beech_Branch_Corner",
      "rotation": 3
    },
    {
      "x": -29,
      "y": 16,
      "z": 9,
      "name": "Plant_Leaves_Beech"
    },
    {
      "x": -29,
      "y": 17,
      "z": 9,
      "name": "Plant_Leaves_Beech"
    },
    {
      "x": -29,
      "y": 0,
      "z": 10,
      "name": "Soil_Grass"
    },
    {
      "x": -29,
      "y": 12,
      "z": 10,
      "name": "Plant_Leaves_Beech"
    },
    {
      "x": -29,
      "y": 13,
      "z": 10,
      "name": "Plant_Leaves_Beech"
    },
    {
      "x": -29,
      "y": 15,
      "z": 10,
      "name": "Plant_Leaves_Beech"
    },
    {
      "x": -29,
      "y": 16,
      "z": 10,
      "name": "Plant_Leaves_Beech"
    },
    {
      "x": -29,
      "y": 17,
      "z": 10,
      "name": "Plant_Leaves_Beech"
    },
    {
      "x": -29,
      "y": 0,
      "z": 11,
      "name": "Soil_Grass"
    },
    {
      "x": -29,
      "y": 10,
      "z": 11,
      "name": "Wood_Beech_Branch_Corner",
      "rotation": 3
    },
    {
      "x": -29,
      "y": 11,
      "z": 11,
      "name": "Plant_Leaves_Beech"
    },
    {
      "x": -29,
      "y": 15,
      "z": 11,
      "name": "Plant_Leaves_Beech"
    },
    {
      "x": -29,
      "y": 16,
      "z": 11,
      "name": "Plant_Leaves_Beech"
    },
    {
      "x": -29,
      "y": 0,
      "z": 12,
      "name": "Soil_Grass"
    },
    {
      "x": -29,
      "y": 8,
      "z": 12,
      "name": "Plant_Leaves_Beech"
    },
    {
      "x": -29,
      "y": 10,
      "z": 12,
      "name": "Plant_Leaves_Beech"
    },
    {
      "x": -29,
      "y": 11,
      "z": 12,
      "name": "Plant_Leaves_Beech"
    },
    {
      "x": -29,
      "y": 16,
      "z": 12,
      "name": "Plant_Leaves_Beech"
    },
    {
      "x": -29,
      "y": 0,
      "z": 13,
      "name": "Soil_Grass"
    },
    {
      "x": -29,
      "y": 7,
      "z": 13,
      "name": "Plant_Leaves_Beech"
    },
    {
      "x": -29,
      "y": 8,
      "z": 13,
      "name": "Plant_Leaves_Beech"
    },
    {
      "x": -29,
      "y": 0,
      "z": 14,
      "name": "Soil_Grass"
    },
    {
      "x": -29,
      "y": 0,
      "z": 15,
      "name": "Soil_Grass"
    },
    {
      "x": -29,
      "y": 0,
      "z": 16,
      "name": "Soil_Grass"
    },
    {
      "x": -29,
      "y": 0,
      "z": 17,
      "name": "Soil_Grass"
    },
    {
      "x": -29,
      "y": 0,
      "z": 18,
      "name": "Soil_Grass"
    },
    {
      "x": -29,
      "y": 0,
      "z": 19,
      "name": "Soil_Grass"
    },
    {
      "x": -29,
      "y": 0,
      "z": 20,
      "name": "Soil_Grass"
    },
    {
      "x": -29,
      "y": 7,
      "z": 20,
      "name": "Plant_Leaves_Beech"
    },
    {
      "x": -29,
      "y": 8,
      "z": 20,
      "name": "Plant_Leaves_Beech"
    },
    {
      "x": -29,
      "y": 0,
      "z": 21,
      "name": "Soil_Grass"
    },
    {
      "x": -29,
      "y": 7,
      "z": 21,
      "name": "Plant_Leaves_Beech"
    },
    {
      "x": -29,
      "y": 8,
      "z": 21,
      "name": "Plant_Leaves_Beech"
    },
    {
      "x": -29,
      "y": 11,
      "z": 21,
      "name": "Plant_Leaves_Beech"
    },
    {
      "x": -29,
      "y": 0,
      "z": 22,
      "name": "Soil_Grass"
    },
    {
      "x": -29,
      "y": 7,
      "z": 22,
      "name": "Plant_Leaves_Beech"
    },
    {
      "x": -29,
      "y": 8,
      "z": 22,
      "name": "Plant_Leaves_Beech"
    },
    {
      "x": -29,
      "y": 9,
      "z": 22,
      "name": "Plant_Leaves_Beech"
    },
    {
      "x": -29,
      "y": 11,
      "z": 22,
      "name": "Plant_Leaves_Beech"
    },
    {
      "x": -29,
      "y": 12,
      "z": 22,
      "name": "Plant_Leaves_Beech"
    },
    {
      "x": -29,
      "y": 0,
      "z": 23,
      "name": "Soil_Grass"
    },
    {
      "x": -29,
      "y": 7,
      "z": 23,
      "name": "Wood_Beech_Branch_Corner",
      "rotation": 3
    },
    {
      "x": -29,
      "y": 8,
      "z": 23,
      "name": "Plant_Leaves_Beech"
    },
    {
      "x": -29,
      "y": 9,
      "z": 23,
      "name": "Plant_Leaves_Beech"
    },
    {
      "x": -29,
      "y": 10,
      "z": 23,
      "name": "Plant_Leaves_Beech"
    },
    {
      "x": -29,
      "y": 12,
      "z": 23,
      "name": "Plant_Leaves_Beech"
    },
    {
      "x": -29,
      "y": 0,
      "z": 24,
      "name": "Soil_Grass"
    },
    {
      "x": -29,
      "y": 7,
      "z": 24,
      "name": "Plant_Leaves_Beech"
    },
    {
      "x": -29,
      "y": 8,
      "z": 24,
      "name": "Plant_Leaves_Beech"
    },
    {
      "x": -29,
      "y": 9,
      "z": 24,
      "name": "Plant_Leaves_Beech"
    },
    {
      "x": -29,
      "y": 0,
      "z": 25,
      "name": "Soil_Grass"
    },
    {
      "x": -29,
      "y": 8,
      "z": 25,
      "name": "Plant_Leaves_Beech"
    },
    {
      "x": -29,
      "y": 10,
      "z": 25,
      "name": "Plant_Leaves_Beech"
    },
    {
      "x": -29,
      "y": 0,
      "z": 26,
      "name": "Soil_Grass"
    },
    {
      "x": -29,
      "y": 0,
      "z": 27,
      "name": "Soil_Grass"
    },
    {
      "x": -29,
      "y": 0,
      "z": 28,
      "name": "Soil_Grass"
    },
    {
      "x": -29,
      "y": 0,
      "z": 29,
      "name": "Soil_Grass"
    },
    {
      "x": -29,
      "y": 0,
      "z": 30,
      "name": "Soil_Grass"
    },
    {
      "x": -29,
      "y": 0,
      "z": 31,
      "name": "Soil_Grass"
    },
    {
      "x": -29,
      "y": 0,
      "z": 32,
      "name": "Soil_Grass"
    },
    {
      "x": -28,
      "y": 0,
      "z": -31,
      "name": "Soil_Grass"
    },
    {
      "x": -28,
      "y": 0,
      "z": -30,
      "name": "Soil_Grass"
    },
    {
      "x": -28,
      "y": 7,
      "z": -30,
      "name": "Plant_Leaves_Beech"
    },
    {
      "x": -28,
      "y": 8,
      "z": -30,
      "name": "Plant_Leaves_Beech"
    },
    {
      "x": -28,
      "y": 0,
      "z": -29,
      "name": "Soil_Grass"
    },
    {
      "x": -28,
      "y": 7,
      "z": -29,
      "name": "Plant_Leaves_Beech"
    },
    {
      "x": -28,
      "y": 8,
      "z": -29,
      "name": "Plant_Leaves_Beech"
    },
    {
      "x": -28,
      "y": 11,
      "z": -29,
      "name": "Plant_Leaves_Beech"
    },
    {
      "x": -28,
      "y": 0,
      "z": -28,
      "name": "Soil_Grass"
    },
    {
      "x": -28,
      "y": 7,
      "z": -28,
      "name": "Plant_Leaves_Beech"
    },
    {
      "x": -28,
      "y": 8,
      "z": -28,
      "name": "Plant_Leaves_Beech"
    },
    {
      "x": -28,
      "y": 9,
      "z": -28,
      "name": "Plant_Leaves_Beech"
    },
    {
      "x": -28,
      "y": 11,
      "z": -28,
      "name": "Plant_Leaves_Beech"
    },
    {
      "x": -28,
      "y": 12,
      "z": -28,
      "name": "Plant_Leaves_Beech"
    },
    {
      "x": -28,
      "y": 0,
      "z": -27,
      "name": "Soil_Grass"
    },
    {
      "x": -28,
      "y": 7,
      "z": -27,
      "name": "Wood_Beech_Branch_Corner",
      "rotation": 3
    },
    {
      "x": -28,
      "y": 8,
      "z": -27,
      "name": "Plant_Leaves_Beech"
    },
    {
      "x": -28,
      "y": 9,
      "z": -27,
      "name": "Plant_Leaves_Beech"
    },
    {
      "x": -28,
      "y": 10,
      "z": -27,
      "name": "Plant_Leaves_Beech"
    },
    {
      "x": -28,
      "y": 12,
      "z": -27,
      "name": "Plant_Leaves_Beech"
    },
    {
      "x": -28,
      "y": 0,
      "z": -26,
      "name": "Soil_Grass"
    },
    {
      "x": -28,
      "y": 7,
      "z": -26,
      "name": "Plant_Leaves_Beech"
    },
    {
      "x": -28,
      "y": 8,
      "z": -26,
      "name": "Plant_Leaves_Beech"
    },
    {
      "x": -28,
      "y": 9,
      "z": -26,
      "name": "Plant_Leaves_Beech"
    },
    {
      "x": -28,
      "y": 0,
      "z": -25,
      "name": "Soil_Grass"
    },
    {
      "x": -28,
      "y": 8,
      "z": -25,
      "name": "Plant_Leaves_Beech"
    },
    {
      "x": -28,
      "y": 10,
      "z": -25,
      "name": "Plant_Leaves_Beech"
    },
    {
      "x": -28,
      "y": 0,
      "z": -24,
      "name": "Soil_Grass"
    },
    {
      "x": -28,
      "y": 0,
      "z": -23,
      "name": "Soil_Grass"
    },
    {
      "x": -28,
      "y": 0,
      "z": -22,
      "name": "Soil_Grass"
    },
    {
      "x": -28,
      "y": 7,
      "z": -22,
      "name": "Plant_Leaves_Beech"
    },
    {
      "x": -28,
      "y": 8,
      "z": -22,
      "name": "Plant_Leaves_Beech"
    },
    {
      "x": -28,
      "y": 0,
      "z": -21,
      "name": "Soil_Grass"
    },
    {
      "x": -28,
      "y": 7,
      "z": -21,
      "name": "Plant_Leaves_Beech"
    },
    {
      "x": -28,
      "y": 8,
      "z": -21,
      "name": "Plant_Leaves_Beech"
    },
    {
      "x": -28,
      "y": 9,
      "z": -21,
      "name": "Plant_Leaves_Beech"
    },
    {
      "x": -28,
      "y": 0,
      "z": -20,
      "name": "Soil_Grass"
    },
    {
      "x": -28,
      "y": 11,
      "z": -20,
      "name": "Plant_Leaves_Beech"
    },
    {
      "x": -28,
      "y": 12,
      "z": -20,
      "name": "Plant_Leaves_Beech"
    },
    {
      "x": -28,
      "y": 16,
      "z": -20,
      "name": "Plant_Leaves_Beech"
    },
    {
      "x": -28,
      "y": 0,
      "z": -19,
      "name": "Soil_Grass"
    },
    {
      "x": -28,
      "y": 10,
      "z": -19,
      "name": "Plant_Leaves_Beech"
    },
    {
      "x": -28,
      "y": 11,
      "z": -19,
      "name": "Plant_Leaves_Beech"
    },
    {
      "x": -28,
      "y": 12,
      "z": -19,
      "name": "Plant_Leaves_Beech"
    },
    {
      "x": -28,
      "y": 15,
      "z": -19,
      "name": "Plant_Leaves_Beech"
    },
    {
      "x": -28,
      "y": 16,
      "z": -19,
      "name": "Plant_Leaves_Beech"
    },
    {
      "x": -28,
      "y": 17,
      "z": -19,
      "name": "Plant_Leaves_Beech"
    },
    {
      "x": -28,
      "y": 0,
      "z": -18,
      "name": "Soil_Grass"
    },
    {
      "x": -28,
      "y": 7,
      "z": -18,
      "name": "Wood_Beech_Branch_Corner",
      "rotation": 3
    },
    {
      "x": -28,
      "y": 8,
      "z": -18,
      "name": "Wood_Beech_Branch_Long"
    },
    {
      "x": -28,
      "y": 9,
      "z": -18,
      "name": "Wood_Beech_Branch_Long"
    },
    {
      "x": -28,
      "y": 10,
      "z": -18,
      "name": "Wood_Beech_Branch_Long"
    },
    {
      "x": -28,
      "y": 11,
      "z": -18,
      "name": "Plant_Leaves_Beech"
    },
    {
      "x": -28,
      "y": 15,
      "z": -18,
      "name": "Plant_Leaves_Beech"
    },
    {
      "x": -28,
      "y": 0,
      "z": -17,
      "name": "Soil_Grass"
    },
    {
      "x": -28,
      "y": 15,
      "z": -17,
      "name": "Wood_Beech_Branch_Long",
      "rotation": 4
    },
    {
      "x": -28,
      "y": 17,
      "z": -17,
      "name": "Plant_Leaves_Beech"
    },
    {
      "x": -28,
      "y": 19,
      "z": -17,
      "name": "Plant_Leaves_Beech"
    },
    {
      "x": -28,
      "y": 20,
      "z": -17,
      "name": "Plant_Leaves_Beech"
    },
    {
      "x": -28,
      "y": 0,
      "z": -16,
      "name": "Soil_Grass"
    },
    {
      "x": -28,
      "y": 7,
      "z": -16,
      "name": "Wood_Beech_Trunk_Full"
    },
    {
      "x": -28,
      "y": 12,
      "z": -16,
      "name": "Wood_Beech_Branch_Long",
      "rotation": 5
    },
    {
      "x": -28,
      "y": 15,
      "z": -16,
      "name": "Wood_Beech_Trunk_Full"
    },
    {
      "x": -28,
      "y": 17,
      "z": -16,
      "name": "Plant_Leaves_Beech"
    },
    {
      "x": -28,
      "y": 18,
      "z": -16,
      "name": "Plant_Leaves_Beech"
    },
    {
      "x": -28,
      "y": 20,
      "z": -16,
      "name": "Plant_Leaves_Beech"
    },
    {
      "x": -28,
      "y": 0,
      "z": -15,
      "name": "Soil_Grass"
    },
    {
      "x": -28,
      "y": 7,
      "z": -15,
      "name": "Wood_Beech_Branch_Long",
      "rotation": 4
    },
    {
      "x": -28,
      "y": 15,
      "z": -15,
      "name": "Wood_Beech_Branch_Corner"
    },
    {
      "x": -28,
      "y": 16,
      "z": -15,
      "name": "Wood_Beech_Branch_Long"
    },
    {
      "x": -28,
      "y": 17,
      "z": -15,
      "name": "Wood_Beech_Branch_Long"
    },
    {
      "x": -28,
      "y": 18,
      "z": -15,
      "name": "Plant_Leaves_Beech"
    },
    {
      "x": -28,
      "y": 20,
      "z": -15,
      "name": "Plant_Leaves_Beech"
    },
    {
      "x": -28,
      "y": 0,
      "z": -14,
      "name": "Soil_Grass"
    },
    {
      "x": -28,
      "y": 7,
      "z": -14,
      "name": "Wood_Beech_Branch_Long",
      "rotation": 4
    },
    {
      "x": -28,
      "y": 10,
      "z": -14,
      "name": "Wood_Beech_Branch_Long",
      "rotation": 5
    },
    {
      "x": -28,
      "y": 17,
      "z": -14,
      "name": "Plant_Leaves_Beech"
    },
    {
      "x": -28,
      "y": 0,
      "z": -13,
      "name": "Soil_Grass"
    },
    {
      "x": -28,
      "y": 7,
      "z": -13,
      "name": "Wood_Beech_Branch_Long",
      "rotation": 4
    },
    {
      "x": -28,
      "y": 9,
      "z": -13,
      "name": "Plant_Leaves_Beech"
    },
    {
      "x": -28,
      "y": 14,
      "z": -13,
      "name": "Plant_Leaves_Beech"
    },
    {
      "x": -28,
      "y": 15,
      "z": -13,
      "name": "Plant_Leaves_Beech"
    },
    {
      "x": -28,
      "y": 16,
      "z": -13,
      "name": "Plant_Leaves_Beech"
    },
    {
      "x": -28,
      "y": 17,
      "z": -13,
      "name": "Plant_Leaves_Beech"
    },
    {
      "x": -28,
      "y": 0,
      "z": -12,
      "name": "Soil_Grass"
    },
    {
      "x": -28,
      "y": 7,
      "z": -12,
      "name": "Wood_Beech_Branch_Corner"
    },
    {
      "x": -28,
      "y": 8,
      "z": -12,
      "name": "Plant_Leaves_Beech"
    },
    {
      "x": -28,
      "y": 9,
      "z": -12,
      "name": "Plant_Leaves_Beech"
    },
    {
      "x": -28,
      "y": 0,
      "z": -11,
      "name": "Soil_Grass"
    },
    {
      "x": -28,
      "y": 7,
      "z": -11,
      "name": "Plant_Leaves_Beech"
    },
    {
      "x": -28,
      "y": 8,
      "z": -11,
      "name": "Plant_Leaves_Beech"
    },
    {
      "x": -28,
      "y": 10,
      "z": -11,
      "name": "Plant_Leaves_Beech"
    },
    {
      "x": -28,
      "y": 11,
      "z": -11,
      "name": "Plant_Leaves_Beech"
    },
    {
      "x": -28,
      "y": 0,
      "z": -10,
      "name": "Soil_Grass"
    },
    {
      "x": -28,
      "y": 7,
      "z": -10,
      "name": "Plant_Leaves_Beech"
    },
    {
      "x": -28,
      "y": 8,
      "z": -10,
      "name": "Plant_Leaves_Beech"
    },
    {
      "x": -28,
      "y": 0,
      "z": -9,
      "name": "Soil_Grass"
    },
    {
      "x": -28,
      "y": 7,
      "z": -9,
      "name": "Plant_Leaves_Beech"
    },
    {
      "x": -28,
      "y": 8,
      "z": -9,
      "name": "Plant_Leaves_Beech"
    },
    {
      "x": -28,
      "y": 9,
      "z": -9,
      "name": "Plant_Leaves_Beech"
    },
    {
      "x": -28,
      "y": 0,
      "z": -8,
      "name": "Soil_Grass"
    },
    {
      "x": -28,
      "y": 11,
      "z": -8,
      "name": "Plant_Leaves_Beech"
    },
    {
      "x": -28,
      "y": 12,
      "z": -8,
      "name": "Plant_Leaves_Beech"
    },
    {
      "x": -28,
      "y": 16,
      "z": -8,
      "name": "Plant_Leaves_Beech"
    },
    {
      "x": -28,
      "y": 0,
      "z": -7,
      "name": "Soil_Grass"
    },
    {
      "x": -28,
      "y": 10,
      "z": -7,
      "name": "Plant_Leaves_Beech"
    },
    {
      "x": -28,
      "y": 11,
      "z": -7,
      "name": "Plant_Leaves_Beech"
    },
    {
      "x": -28,
      "y": 12,
      "z": -7,
      "name": "Plant_Leaves_Beech"
    },
    {
      "x": -28,
      "y": 15,
      "z": -7,
      "name": "Plant_Leaves_Beech"
    },
    {
      "x": -28,
      "y": 16,
      "z": -7,
      "name": "Plant_Leaves_Beech"
    },
    {
      "x": -28,
      "y": 17,
      "z": -7,
      "name": "Plant_Leaves_Beech"
    },
    {
      "x": -28,
      "y": 0,
      "z": -6,
      "name": "Soil_Grass"
    },
    {
      "x": -28,
      "y": 7,
      "z": -6,
      "name": "Wood_Beech_Branch_Corner",
      "rotation": 3
    },
    {
      "x": -28,
      "y": 8,
      "z": -6,
      "name": "Wood_Beech_Branch_Long"
    },
    {
      "x": -28,
      "y": 9,
      "z": -6,
      "name": "Wood_Beech_Branch_Long"
    },
    {
      "x": -28,
      "y": 10,
      "z": -6,
      "name": "Wood_Beech_Branch_Long"
    },
    {
      "x": -28,
      "y": 11,
      "z": -6,
      "name": "Plant_Leaves_Beech"
    },
    {
      "x": -28,
      "y": 15,
      "z": -6,
      "name": "Plant_Leaves_Beech"
    },
    {
      "x": -28,
      "y": 0,
      "z": -5,
      "name": "Soil_Grass"
    },
    {
      "x": -28,
      "y": 15,
      "z": -5,
      "name": "Wood_Beech_Branch_Long",
      "rotation": 4
    },
    {
      "x": -28,
      "y": 17,
      "z": -5,
      "name": "Plant_Leaves_Beech"
    },
    {
      "x": -28,
      "y": 19,
      "z": -5,
      "name": "Plant_Leaves_Beech"
    },
    {
      "x": -28,
      "y": 20,
      "z": -5,
      "name": "Plant_Leaves_Beech"
    },
    {
      "x": -28,
      "y": 0,
      "z": -4,
      "name": "Soil_Grass"
    },
    {
      "x": -28,
      "y": 7,
      "z": -4,
      "name": "Wood_Beech_Trunk_Full"
    },
    {
      "x": -28,
      "y": 12,
      "z": -4,
      "name": "Wood_Beech_Branch_Long",
      "rotation": 5
    },
    {
      "x": -28,
      "y": 15,
      "z": -4,
      "name": "Wood_Beech_Trunk_Full"
    },
    {
      "x": -28,
      "y": 17,
      "z": -4,
      "name": "Plant_Leaves_Beech"
    },
    {
      "x": -28,
      "y": 18,
      "z": -4,
      "name": "Plant_Leaves_Beech"
    },
    {
      "x": -28,
      "y": 20,
      "z": -4,
      "name": "Plant_Leaves_Beech"
    },
    {
      "x": -28,
      "y": 0,
      "z": -3,
      "name": "Soil_Grass"
    },
    {
      "x": -28,
      "y": 7,
      "z": -3,
      "name": "Wood_Beech_Branch_Long",
      "rotation": 4
    },
    {
      "x": -28,
      "y": 15,
      "z": -3,
      "name": "Wood_Beech_Branch_Corner"
    },
    {
      "x": -28,
      "y": 16,
      "z": -3,
      "name": "Wood_Beech_Branch_Long"
    },
    {
      "x": -28,
      "y": 17,
      "z": -3,
      "name": "Wood_Beech_Branch_Long"
    },
    {
      "x": -28,
      "y": 18,
      "z": -3,
      "name": "Plant_Leaves_Beech"
    },
    {
      "x": -28,
      "y": 20,
      "z": -3,
      "name": "Plant_Leaves_Beech"
    },
    {
      "x": -28,
      "y": 0,
      "z": -2,
      "name": "Soil_Grass"
    },
    {
      "x": -28,
      "y": 7,
      "z": -2,
      "name": "Wood_Beech_Branch_Long",
      "rotation": 4
    },
    {
      "x": -28,
      "y": 10,
      "z": -2,
      "name": "Wood_Beech_Branch_Long",
      "rotation": 5
    },
    {
      "x": -28,
      "y": 17,
      "z": -2,
      "name": "Plant_Leaves_Beech"
    },
    {
      "x": -28,
      "y": 0,
      "z": -1,
      "name": "Soil_Grass"
    },
    {
      "x": -28,
      "y": 7,
      "z": -1,
      "name": "Wood_Beech_Branch_Long",
      "rotation": 4
    },
    {
      "x": -28,
      "y": 9,
      "z": -1,
      "name": "Plant_Leaves_Beech"
    },
    {
      "x": -28,
      "y": 14,
      "z": -1,
      "name": "Plant_Leaves_Beech"
    },
    {
      "x": -28,
      "y": 15,
      "z": -1,
      "name": "Plant_Leaves_Beech"
    },
    {
      "x": -28,
      "y": 16,
      "z": -1,
      "name": "Plant_Leaves_Beech"
    },
    {
      "x": -28,
      "y": 17,
      "z": -1,
      "name": "Plant_Leaves_Beech"
    },
    {
      "x": -28,
      "y": 0,
      "z": 0,
      "name": "Soil_Grass"
    },
    {
      "x": -28,
      "y": 7,
      "z": 0,
      "name": "Wood_Beech_Branch_Corner"
    },
    {
      "x": -28,
      "y": 8,
      "z": 0,
      "name": "Plant_Leaves_Beech"
    },
    {
      "x": -28,
      "y": 9,
      "z": 0,
      "name": "Plant_Leaves_Beech"
    },
    {
      "x": -28,
      "y": 0,
      "z": 1,
      "name": "Soil_Grass"
    },
    {
      "x": -28,
      "y": 7,
      "z": 1,
      "name": "Plant_Leaves_Beech"
    },
    {
      "x": -28,
      "y": 8,
      "z": 1,
      "name": "Plant_Leaves_Beech"
    },
    {
      "x": -28,
      "y": 10,
      "z": 1,
      "name": "Plant_Leaves_Beech"
    },
    {
      "x": -28,
      "y": 11,
      "z": 1,
      "name": "Plant_Leaves_Beech"
    },
    {
      "x": -28,
      "y": 0,
      "z": 2,
      "name": "Soil_Grass"
    },
    {
      "x": -28,
      "y": 0,
      "z": 3,
      "name": "Soil_Grass"
    },
    {
      "x": -28,
      "y": 7,
      "z": 3,
      "name": "Plant_Leaves_Beech"
    },
    {
      "x": -28,
      "y": 8,
      "z": 3,
      "name": "Plant_Leaves_Beech"
    },
    {
      "x": -28,
      "y": 0,
      "z": 4,
      "name": "Soil_Grass"
    },
    {
      "x": -28,
      "y": 7,
      "z": 4,
      "name": "Plant_Leaves_Beech"
    },
    {
      "x": -28,
      "y": 8,
      "z": 4,
      "name": "Plant_Leaves_Beech"
    },
    {
      "x": -28,
      "y": 9,
      "z": 4,
      "name": "Plant_Leaves_Beech"
    },
    {
      "x": -28,
      "y": 0,
      "z": 5,
      "name": "Soil_Grass"
    },
    {
      "x": -28,
      "y": 11,
      "z": 5,
      "name": "Plant_Leaves_Beech"
    },
    {
      "x": -28,
      "y": 12,
      "z": 5,
      "name": "Plant_Leaves_Beech"
    },
    {
      "x": -28,
      "y": 16,
      "z": 5,
      "name": "Plant_Leaves_Beech"
    },
    {
      "x": -28,
      "y": 0,
      "z": 6,
      "name": "Soil_Grass"
    },
    {
      "x": -28,
      "y": 10,
      "z": 6,
      "name": "Plant_Leaves_Beech"
    },
    {
      "x": -28,
      "y": 11,
      "z": 6,
      "name": "Plant_Leaves_Beech"
    },
    {
      "x": -28,
      "y": 12,
      "z": 6,
      "name": "Plant_Leaves_Beech"
    },
    {
      "x": -28,
      "y": 15,
      "z": 6,
      "name": "Plant_Leaves_Beech"
    },
    {
      "x": -28,
      "y": 16,
      "z": 6,
      "name": "Plant_Leaves_Beech"
    },
    {
      "x": -28,
      "y": 17,
      "z": 6,
      "name": "Plant_Leaves_Beech"
    },
    {
      "x": -28,
      "y": 0,
      "z": 7,
      "name": "Soil_Grass"
    },
    {
      "x": -28,
      "y": 7,
      "z": 7,
      "name": "Wood_Beech_Branch_Corner",
      "rotation": 3
    },
    {
      "x": -28,
      "y": 8,
      "z": 7,
      "name": "Wood_Beech_Branch_Long"
    },
    {
      "x": -28,
      "y": 9,
      "z": 7,
      "name": "Wood_Beech_Branch_Long"
    },
    {
      "x": -28,
      "y": 10,
      "z": 7,
      "name": "Wood_Beech_Branch_Long"
    },
    {
      "x": -28,
      "y": 11,
      "z": 7,
      "name": "Plant_Leaves_Beech"
    },
    {
      "x": -28,
      "y": 15,
      "z": 7,
      "name": "Plant_Leaves_Beech"
    },
    {
      "x": -28,
      "y": 0,
      "z": 8,
      "name": "Soil_Grass"
    },
    {
      "x": -28,
      "y": 15,
      "z": 8,
      "name": "Wood_Beech_Branch_Long",
      "rotation": 4
    },
    {
      "x": -28,
      "y": 17,
      "z": 8,
      "name": "Plant_Leaves_Beech"
    },
    {
      "x": -28,
      "y": 19,
      "z": 8,
      "name": "Plant_Leaves_Beech"
    },
    {
      "x": -28,
      "y": 20,
      "z": 8,
      "name": "Plant_Leaves_Beech"
    },
    {
      "x": -28,
      "y": 0,
      "z": 9,
      "name": "Soil_Grass"
    },
    {
      "x": -28,
      "y": 7,
      "z": 9,
      "name": "Wood_Beech_Trunk_Full"
    },
    {
      "x": -28,
      "y": 12,
      "z": 9,
      "name": "Wood_Beech_Branch_Long",
      "rotation": 5
    },
    {
      "x": -28,
      "y": 15,
      "z": 9,
      "name": "Wood_Beech_Trunk_Full"
    },
    {
      "x": -28,
      "y": 17,
      "z": 9,
      "name": "Plant_Leaves_Beech"
    },
    {
      "x": -28,
      "y": 18,
      "z": 9,
      "name": "Plant_Leaves_Beech"
    },
    {
      "x": -28,
      "y": 20,
      "z": 9,
      "name": "Plant_Leaves_Beech"
    },
    {
      "x": -28,
      "y": 0,
      "z": 10,
      "name": "Soil_Grass"
    },
    {
      "x": -28,
      "y": 7,
      "z": 10,
      "name": "Wood_Beech_Branch_Long",
      "rotation": 4
    },
    {
      "x": -28,
      "y": 15,
      "z": 10,
      "name": "Wood_Beech_Branch_Corner"
    },
    {
      "x": -28,
      "y": 16,
      "z": 10,
      "name": "Wood_Beech_Branch_Long"
    },
    {
      "x": -28,
      "y": 17,
      "z": 10,
      "name": "Wood_Beech_Branch_Long"
    },
    {
      "x": -28,
      "y": 18,
      "z": 10,
      "name": "Plant_Leaves_Beech"
    },
    {
      "x": -28,
      "y": 20,
      "z": 10,
      "name": "Plant_Leaves_Beech"
    },
    {
      "x": -28,
      "y": 0,
      "z": 11,
      "name": "Soil_Grass"
    },
    {
      "x": -28,
      "y": 7,
      "z": 11,
      "name": "Wood_Beech_Branch_Long",
      "rotation": 4
    },
    {
      "x": -28,
      "y": 10,
      "z": 11,
      "name": "Wood_Beech_Branch_Long",
      "rotation": 5
    },
    {
      "x": -28,
      "y": 17,
      "z": 11,
      "name": "Plant_Leaves_Beech"
    },
    {
      "x": -28,
      "y": 0,
      "z": 12,
      "name": "Soil_Grass"
    },
    {
      "x": -28,
      "y": 7,
      "z": 12,
      "name": "Wood_Beech_Branch_Long",
      "rotation": 4
    },
    {
      "x": -28,
      "y": 9,
      "z": 12,
      "name": "Plant_Leaves_Beech"
    },
    {
      "x": -28,
      "y": 14,
      "z": 12,
      "name": "Plant_Leaves_Beech"
    },
    {
      "x": -28,
      "y": 15,
      "z": 12,
      "name": "Plant_Leaves_Beech"
    },
    {
      "x": -28,
      "y": 16,
      "z": 12,
      "name": "Plant_Leaves_Beech"
    },
    {
      "x": -28,
      "y": 17,
      "z": 12,
      "name": "Plant_Leaves_Beech"
    },
    {
      "x": -28,
      "y": 0,
      "z": 13,
      "name": "Soil_Grass"
    },
    {
      "x": -28,
      "y": 7,
      "z": 13,
      "name": "Wood_Beech_Branch_Corner"
    },
    {
      "x": -28,
      "y": 8,
      "z": 13,
      "name": "Plant_Leaves_Beech"
    },
    {
      "x": -28,
      "y": 9,
      "z": 13,
      "name": "Plant_Leaves_Beech"
    },
    {
      "x": -28,
      "y": 0,
      "z": 14,
      "name": "Soil_Grass"
    },
    {
      "x": -28,
      "y": 7,
      "z": 14,
      "name": "Plant_Leaves_Beech"
    },
    {
      "x": -28,
      "y": 8,
      "z": 14,
      "name": "Plant_Leaves_Beech"
    },
    {
      "x": -28,
      "y": 10,
      "z": 14,
      "name": "Plant_Leaves_Beech"
    },
    {
      "x": -28,
      "y": 11,
      "z": 14,
      "name": "Plant_Leaves_Beech"
    },
    {
      "x": -28,
      "y": 0,
      "z": 15,
      "name": "Soil_Grass"
    },
    {
      "x": -28,
      "y": 0,
      "z": 16,
      "name": "Soil_Grass"
    },
    {
      "x": -28,
      "y": 0,
      "z": 17,
      "name": "Soil_Grass"
    },
    {
      "x": -28,
      "y": 0,
      "z": 18,
      "name": "Soil_Grass"
    },
    {
      "x": -28,
      "y": 0,
      "z": 19,
      "name": "Soil_Grass"
    },
    {
      "x": -28,
      "y": 7,
      "z": 19,
      "name": "Plant_Leaves_Beech"
    },
    {
      "x": -28,
      "y": 0,
      "z": 20,
      "name": "Soil_Grass"
    },
    {
      "x": -28,
      "y": 7,
      "z": 20,
      "name": "Plant_Leaves_Beech"
    },
    {
      "x": -28,
      "y": 8,
      "z": 20,
      "name": "Plant_Leaves_Beech"
    },
    {
      "x": -28,
      "y": 0,
      "z": 21,
      "name": "Soil_Grass"
    },
    {
      "x": -28,
      "y": 7,
      "z": 21,
      "name": "Plant_Leaves_Beech"
    },
    {
      "x": -28,
      "y": 11,
      "z": 21,
      "name": "Plant_Leaves_Beech"
    },
    {
      "x": -28,
      "y": 0,
      "z": 22,
      "name": "Soil_Grass"
    },
    {
      "x": -28,
      "y": 7,
      "z": 22,
      "name": "Plant_Leaves_Beech"
    },
    {
      "x": -28,
      "y": 11,
      "z": 22,
      "name": "Plant_Leaves_Beech"
    },
    {
      "x": -28,
      "y": 12,
      "z": 22,
      "name": "Plant_Leaves_Beech"
    },
    {
      "x": -28,
      "y": 13,
      "z": 22,
      "name": "Plant_Leaves_Beech"
    },
    {
      "x": -28,
      "y": 15,
      "z": 22,
      "name": "Plant_Leaves_Beech"
    },
    {
      "x": -28,
      "y": 16,
      "z": 22,
      "name": "Plant_Leaves_Beech"
    },
    {
      "x": -28,
      "y": 0,
      "z": 23,
      "name": "Soil_Grass"
    },
    {
      "x": -28,
      "y": 7,
      "z": 23,
      "name": "Wood_Beech_Branch_Long",
      "rotation": 5
    },
    {
      "x": -28,
      "y": 11,
      "z": 23,
      "name": "Plant_Leaves_Beech"
    },
    {
      "x": -28,
      "y": 12,
      "z": 23,
      "name": "Plant_Leaves_Beech"
    },
    {
      "x": -28,
      "y": 13,
      "z": 23,
      "name": "Plant_Leaves_Beech"
    },
    {
      "x": -28,
      "y": 15,
      "z": 23,
      "name": "Plant_Leaves_Beech"
    },
    {
      "x": -28,
      "y": 16,
      "z": 23,
      "name": "Plant_Leaves_Beech"
    },
    {
      "x": -28,
      "y": 0,
      "z": 24,
      "name": "Soil_Grass"
    },
    {
      "x": -28,
      "y": 10,
      "z": 24,
      "name": "Plant_Leaves_Beech"
    },
    {
      "x": -28,
      "y": 12,
      "z": 24,
      "name": "Plant_Leaves_Beech"
    },
    {
      "x": -28,
      "y": 13,
      "z": 24,
      "name": "Plant_Leaves_Beech"
    },
    {
      "x": -28,
      "y": 15,
      "z": 24,
      "name": "Plant_Leaves_Beech"
    },
    {
      "x": -28,
      "y": 16,
      "z": 24,
      "name": "Plant_Leaves_Beech"
    },
    {
      "x": -28,
      "y": 0,
      "z": 25,
      "name": "Soil_Grass"
    },
    {
      "x": -28,
      "y": 10,
      "z": 25,
      "name": "Plant_Leaves_Beech"
    },
    {
      "x": -28,
      "y": 11,
      "z": 25,
      "name": "Plant_Leaves_Beech"
    },
    {
      "x": -28,
      "y": 15,
      "z": 25,
      "name": "Plant_Leaves_Beech"
    },
    {
      "x": -28,
      "y": 0,
      "z": 26,
      "name": "Soil_Grass"
    },
    {
      "x": -28,
      "y": 7,
      "z": 26,
      "name": "Plant_Leaves_Beech"
    },
    {
      "x": -28,
      "y": 8,
      "z": 26,
      "name": "Plant_Leaves_Beech"
    },
    {
      "x": -28,
      "y": 10,
      "z": 26,
      "name": "Plant_Leaves_Beech"
    },
    {
      "x": -28,
      "y": 11,
      "z": 26,
      "name": "Plant_Leaves_Beech"
    },
    {
      "x": -28,
      "y": 0,
      "z": 27,
      "name": "Soil_Grass"
    },
    {
      "x": -28,
      "y": 0,
      "z": 28,
      "name": "Soil_Grass"
    },
    {
      "x": -28,
      "y": 0,
      "z": 29,
      "name": "Soil_Grass"
    },
    {
      "x": -28,
      "y": 0,
      "z": 30,
      "name": "Soil_Grass"
    },
    {
      "x": -28,
      "y": 0,
      "z": 31,
      "name": "Soil_Grass"
    },
    {
      "x": -28,
      "y": 0,
      "z": 32,
      "name": "Soil_Grass"
    },
    {
      "x": -27,
      "y": 0,
      "z": -31,
      "name": "Soil_Grass"
    },
    {
      "x": -27,
      "y": 7,
      "z": -31,
      "name": "Plant_Leaves_Beech"
    },
    {
      "x": -27,
      "y": 0,
      "z": -30,
      "name": "Soil_Grass"
    },
    {
      "x": -27,
      "y": 7,
      "z": -30,
      "name": "Plant_Leaves_Beech"
    },
    {
      "x": -27,
      "y": 8,
      "z": -30,
      "name": "Plant_Leaves_Beech"
    },
    {
      "x": -27,
      "y": 0,
      "z": -29,
      "name": "Soil_Grass"
    },
    {
      "x": -27,
      "y": 7,
      "z": -29,
      "name": "Plant_Leaves_Beech"
    },
    {
      "x": -27,
      "y": 11,
      "z": -29,
      "name": "Plant_Leaves_Beech"
    },
    {
      "x": -27,
      "y": 0,
      "z": -28,
      "name": "Soil_Grass"
    },
    {
      "x": -27,
      "y": 7,
      "z": -28,
      "name": "Plant_Leaves_Beech"
    },
    {
      "x": -27,
      "y": 11,
      "z": -28,
      "name": "Plant_Leaves_Beech"
    },
    {
      "x": -27,
      "y": 12,
      "z": -28,
      "name": "Plant_Leaves_Beech"
    },
    {
      "x": -27,
      "y": 13,
      "z": -28,
      "name": "Plant_Leaves_Beech"
    },
    {
      "x": -27,
      "y": 15,
      "z": -28,
      "name": "Plant_Leaves_Beech"
    },
    {
      "x": -27,
      "y": 16,
      "z": -28,
      "name": "Plant_Leaves_Beech"
    },
    {
      "x": -27,
      "y": 0,
      "z": -27,
      "name": "Soil_Grass"
    },
    {
      "x": -27,
      "y": 7,
      "z": -27,
      "name": "Wood_Beech_Branch_Long",
      "rotation": 5
    },
    {
      "x": -27,
      "y": 11,
      "z": -27,
      "name": "Plant_Leaves_Beech"
    },
    {
      "x": -27,
      "y": 12,
      "z": -27,
      "name": "Plant_Leaves_Beech"
    },
    {
      "x": -27,
      "y": 13,
      "z": -27,
      "name": "Plant_Leaves_Beech"
    },
    {
      "x": -27,
      "y": 15,
      "z": -27,
      "name": "Plant_Leaves_Beech"
    },
    {
      "x": -27,
      "y": 16,
      "z": -27,
      "name": "Plant_Leaves_Beech"
    },
    {
      "x": -27,
      "y": 0,
      "z": -26,
      "name": "Soil_Grass"
    },
    {
      "x": -27,
      "y": 10,
      "z": -26,
      "name": "Plant_Leaves_Beech"
    },
    {
      "x": -27,
      "y": 12,
      "z": -26,
      "name": "Plant_Leaves_Beech"
    },
    {
      "x": -27,
      "y": 13,
      "z": -26,
      "name": "Plant_Leaves_Beech"
    },
    {
      "x": -27,
      "y": 15,
      "z": -26,
      "name": "Plant_Leaves_Beech"
    },
    {
      "x": -27,
      "y": 16,
      "z": -26,
      "name": "Plant_Leaves_Beech"
    },
    {
      "x": -27,
      "y": 0,
      "z": -25,
      "name": "Soil_Grass"
    },
    {
      "x": -27,
      "y": 10,
      "z": -25,
      "name": "Plant_Leaves_Beech"
    },
    {
      "x": -27,
      "y": 11,
      "z": -25,
      "name": "Plant_Leaves_Beech"
    },
    {
      "x": -27,
      "y": 15,
      "z": -25,
      "name": "Plant_Leaves_Beech"
    },
    {
      "x": -27,
      "y": 0,
      "z": -24,
      "name": "Soil_Grass"
    },
    {
      "x": -27,
      "y": 7,
      "z": -24,
      "name": "Plant_Leaves_Beech"
    },
    {
      "x": -27,
      "y": 8,
      "z": -24,
      "name": "Plant_Leaves_Beech"
    },
    {
      "x": -27,
      "y": 10,
      "z": -24,
      "name": "Plant_Leaves_Beech"
    },
    {
      "x": -27,
      "y": 11,
      "z": -24,
      "name": "Plant_Leaves_Beech"
    },
    {
      "x": -27,
      "y": 0,
      "z": -23,
      "name": "Soil_Grass"
    },
    {
      "x": -27,
      "y": 0,
      "z": -22,
      "name": "Soil_Grass"
    },
    {
      "x": -27,
      "y": 7,
      "z": -22,
      "name": "Plant_Leaves_Beech"
    },
    {
      "x": -27,
      "y": 9,
      "z": -22,
      "name": "Plant_Leaves_Beech"
    },
    {
      "x": -27,
      "y": 0,
      "z": -21,
      "name": "Soil_Grass"
    },
    {
      "x": -27,
      "y": 7,
      "z": -21,
      "name": "Plant_Leaves_Beech"
    },
    {
      "x": -27,
      "y": 8,
      "z": -21,
      "name": "Plant_Leaves_Beech"
    },
    {
      "x": -27,
      "y": 9,
      "z": -21,
      "name": "Plant_Leaves_Beech"
    },
    {
      "x": -27,
      "y": 0,
      "z": -20,
      "name": "Soil_Grass"
    },
    {
      "x": -27,
      "y": 12,
      "z": -20,
      "name": "Plant_Leaves_Beech"
    },
    {
      "x": -27,
      "y": 13,
      "z": -20,
      "name": "Plant_Leaves_Beech"
    },
    {
      "x": -27,
      "y": 16,
      "z": -20,
      "name": "Plant_Leaves_Beech"
    },
    {
      "x": -27,
      "y": 17,
      "z": -20,
      "name": "Plant_Leaves_Beech"
    },
    {
      "x": -27,
      "y": 0,
      "z": -19,
      "name": "Soil_Grass"
    },
    {
      "x": -27,
      "y": 12,
      "z": -19,
      "name": "Plant_Leaves_Beech"
    },
    {
      "x": -27,
      "y": 13,
      "z": -19,
      "name": "Plant_Leaves_Beech"
    },
    {
      "x": -27,
      "y": 16,
      "z": -19,
      "name": "Plant_Leaves_Beech"
    },
    {
      "x": -27,
      "y": 17,
      "z": -19,
      "name": "Plant_Leaves_Beech"
    },
    {
      "x": -27,
      "y": 0,
      "z": -18,
      "name": "Soil_Grass"
    },
    {
      "x": -27,
      "y": 7,
      "z": -18,
      "name": "Wood_Beech_Trunk_Full"
    },
    {
      "x": -27,
      "y": 0,
      "z": -17,
      "name": "Soil_Grass"
    },
    {
      "x": -27,
      "y": 19,
      "z": -17,
      "name": "Plant_Leaves_Beech"
    },
    {
      "x": -27,
      "y": 20,
      "z": -17,
      "name": "Plant_Leaves_Beech"
    },
    {
      "x": -27,
      "y": 0,
      "z": -16,
      "name": "Soil_Grass"
    },
    {
      "x": -27,
      "y": 7,
      "z": -16,
      "name": "Wood_Beech_Trunk_Full"
    },
    {
      "x": -27,
      "y": 12,
      "z": -16,
      "name": "Wood_Beech_Branch_Long",
      "rotation": 5
    },
    {
      "x": -27,
      "y": 15,
      "z": -16,
      "name": "Wood_Beech_Trunk_Full"
    },
    {
      "x": -27,
      "y": 17,
      "z": -16,
      "name": "Wood_Beech_Branch_Corner",
      "rotation": 3
    },
    {
      "x": -27,
      "y": 18,
      "z": -16,
      "name": "Wood_Beech_Branch_Long"
    },
    {
      "x": -27,
      "y": 19,
      "z": -16,
      "name": "Wood_Beech_Branch_Long"
    },
    {
      "x": -27,
      "y": 20,
      "z": -16,
      "name": "Wood_Beech_Branch_Long"
    },
    {
      "x": -27,
      "y": 21,
      "z": -16,
      "name": "Plant_Leaves_Beech"
    },
    {
      "x": -27,
      "y": 0,
      "z": -15,
      "name": "Soil_Grass"
    },
    {
      "x": -27,
      "y": 20,
      "z": -15,
      "name": "Plant_Leaves_Beech"
    },
    {
      "x": -27,
      "y": 21,
      "z": -15,
      "name": "Plant_Leaves_Beech"
    },
    {
      "x": -27,
      "y": 0,
      "z": -14,
      "name": "Soil_Grass"
    },
    {
      "x": -27,
      "y": 10,
      "z": -14,
      "name": "Wood_Beech_Branch_Long",
      "rotation": 5
    },
    {
      "x": -27,
      "y": 19,
      "z": -14,
      "name": "Plant_Leaves_Beech"
    },
    {
      "x": -27,
      "y": 20,
      "z": -14,
      "name": "Plant_Leaves_Beech"
    },
    {
      "x": -27,
      "y": 0,
      "z": -13,
      "name": "Soil_Grass"
    },
    {
      "x": -27,
      "y": 14,
      "z": -13,
      "name": "Plant_Leaves_Beech"
    },
    {
      "x": -27,
      "y": 15,
      "z": -13,
      "name": "Plant_Leaves_Beech"
    },
    {
      "x": -27,
      "y": 16,
      "z": -13,
      "name": "Plant_Leaves_Beech"
    },
    {
      "x": -27,
      "y": 19,
      "z": -13,
      "name": "Plant_Leaves_Beech"
    },
    {
      "x": -27,
      "y": 0,
      "z": -12,
      "name": "Soil_Grass"
    },
    {
      "x": -27,
      "y": 5,
      "z": -12,
      "name": "Plant_Leaves_Beech"
    },
    {
      "x": -27,
      "y": 6,
      "z": -12,
      "name": "Plant_Leaves_Beech"
    },
    {
      "x": -27,
      "y": 8,
      "z": -12,
      "name": "Plant_Leaves_Beech"
    },
    {
      "x": -27,
      "y": 9,
      "z": -12,
      "name": "Plant_Leaves_Beech"
    },
    {
      "x": -27,
      "y": 14,
      "z": -12,
      "name": "Plant_Leaves_Beech"
    },
    {
      "x": -27,
      "y": 15,
      "z": -12,
      "name": "Plant_Leaves_Beech"
    },
    {
      "x": -27,
      "y": 0,
      "z": -11,
      "name": "Soil_Grass"
    },
    {
      "x": -27,
      "y": 5,
      "z": -11,
      "name": "Plant_Leaves_Beech"
    },
    {
      "x": -27,
      "y": 6,
      "z": -11,
      "name": "Plant_Leaves_Beech"
    },
    {
      "x": -27,
      "y": 7,
      "z": -11,
      "name": "Plant_Leaves_Beech"
    },
    {
      "x": -27,
      "y": 8,
      "z": -11,
      "name": "Plant_Leaves_Beech"
    },
    {
      "x": -27,
      "y": 10,
      "z": -11,
      "name": "Plant_Leaves_Beech"
    },
    {
      "x": -27,
      "y": 11,
      "z": -11,
      "name": "Plant_Leaves_Beech"
    },
    {
      "x": -27,
      "y": 0,
      "z": -10,
      "name": "Soil_Grass"
    },
    {
      "x": -27,
      "y": 7,
      "z": -10,
      "name": "Plant_Leaves_Beech"
    },
    {
      "x": -27,
      "y": 9,
      "z": -10,
      "name": "Plant_Leaves_Beech"
    },
    {
      "x": -27,
      "y": 10,
      "z": -10,
      "name": "Plant_Leaves_Beech"
    },
    {
      "x": -27,
      "y": 11,
      "z": -10,
      "name": "Plant_Leaves_Beech"
    },
    {
      "x": -27,
      "y": 0,
      "z": -9,
      "name": "Soil_Grass"
    },
    {
      "x": -27,
      "y": 7,
      "z": -9,
      "name": "Plant_Leaves_Beech"
    },
    {
      "x": -27,
      "y": 8,
      "z": -9,
      "name": "Plant_Leaves_Beech"
    },
    {
      "x": -27,
      "y": 9,
      "z": -9,
      "name": "Plant_Leaves_Beech"
    },
    {
      "x": -27,
      "y": 0,
      "z": -8,
      "name": "Soil_Grass"
    },
    {
      "x": -27,
      "y": 12,
      "z": -8,
      "name": "Plant_Leaves_Beech"
    },
    {
      "x": -27,
      "y": 13,
      "z": -8,
      "name": "Plant_Leaves_Beech"
    },
    {
      "x": -27,
      "y": 16,
      "z": -8,
      "name": "Plant_Leaves_Beech"
    },
    {
      "x": -27,
      "y": 17,
      "z": -8,
      "name": "Plant_Leaves_Beech"
    },
    {
      "x": -27,
      "y": 0,
      "z": -7,
      "name": "Soil_Grass"
    },
    {
      "x": -27,
      "y": 12,
      "z": -7,
      "name": "Plant_Leaves_Beech"
    },
    {
      "x": -27,
      "y": 13,
      "z": -7,
      "name": "Plant_Leaves_Beech"
    },
    {
      "x": -27,
      "y": 16,
      "z": -7,
      "name": "Plant_Leaves_Beech"
    },
    {
      "x": -27,
      "y": 17,
      "z": -7,
      "name": "Plant_Leaves_Beech"
    },
    {
      "x": -27,
      "y": 0,
      "z": -6,
      "name": "Soil_Grass"
    },
    {
      "x": -27,
      "y": 7,
      "z": -6,
      "name": "Wood_Beech_Trunk_Full"
    },
    {
      "x": -27,
      "y": 0,
      "z": -5,
      "name": "Soil_Grass"
    },
    {
      "x": -27,
      "y": 19,
      "z": -5,
      "name": "Plant_Leaves_Beech"
    },
    {
      "x": -27,
      "y": 20,
      "z": -5,
      "name": "Plant_Leaves_Beech"
    },
    {
      "x": -27,
      "y": 0,
      "z": -4,
      "name": "Soil_Grass"
    },
    {
      "x": -27,
      "y": 7,
      "z": -4,
      "name": "Wood_Beech_Trunk_Full"
    },
    {
      "x": -27,
      "y": 12,
      "z": -4,
      "name": "Wood_Beech_Branch_Long",
      "rotation": 5
    },
    {
      "x": -27,
      "y": 15,
      "z": -4,
      "name": "Wood_Beech_Trunk_Full"
    },
    {
      "x": -27,
      "y": 17,
      "z": -4,
      "name": "Wood_Beech_Branch_Corner",
      "rotation": 3
    },
    {
      "x": -27,
      "y": 18,
      "z": -4,
      "name": "Wood_Beech_Branch_Long"
    },
    {
      "x": -27,
      "y": 19,
      "z": -4,
      "name": "Wood_Beech_Branch_Long"
    },
    {
      "x": -27,
      "y": 20,
      "z": -4,
      "name": "Wood_Beech_Branch_Long"
    },
    {
      "x": -27,
      "y": 21,
      "z": -4,
      "name": "Plant_Leaves_Beech"
    },
    {
      "x": -27,
      "y": 0,
      "z": -3,
      "name": "Soil_Grass"
    },
    {
      "x": -27,
      "y": 20,
      "z": -3,
      "name": "Plant_Leaves_Beech"
    },
    {
      "x": -27,
      "y": 21,
      "z": -3,
      "name": "Plant_Leaves_Beech"
    },
    {
      "x": -27,
      "y": 0,
      "z": -2,
      "name": "Soil_Grass"
    },
    {
      "x": -27,
      "y": 10,
      "z": -2,
      "name": "Wood_Beech_Branch_Long",
      "rotation": 5
    },
    {
      "x": -27,
      "y": 19,
      "z": -2,
      "name": "Plant_Leaves_Beech"
    },
    {
      "x": -27,
      "y": 20,
      "z": -2,
      "name": "Plant_Leaves_Beech"
    },
    {
      "x": -27,
      "y": 0,
      "z": -1,
      "name": "Soil_Grass"
    },
    {
      "x": -27,
      "y": 14,
      "z": -1,
      "name": "Plant_Leaves_Beech"
    },
    {
      "x": -27,
      "y": 15,
      "z": -1,
      "name": "Plant_Leaves_Beech"
    },
    {
      "x": -27,
      "y": 16,
      "z": -1,
      "name": "Plant_Leaves_Beech"
    },
    {
      "x": -27,
      "y": 19,
      "z": -1,
      "name": "Plant_Leaves_Beech"
    },
    {
      "x": -27,
      "y": 0,
      "z": 0,
      "name": "Soil_Grass"
    },
    {
      "x": -27,
      "y": 5,
      "z": 0,
      "name": "Plant_Leaves_Beech"
    },
    {
      "x": -27,
      "y": 6,
      "z": 0,
      "name": "Plant_Leaves_Beech"
    },
    {
      "x": -27,
      "y": 8,
      "z": 0,
      "name": "Plant_Leaves_Beech"
    },
    {
      "x": -27,
      "y": 9,
      "z": 0,
      "name": "Plant_Leaves_Beech"
    },
    {
      "x": -27,
      "y": 14,
      "z": 0,
      "name": "Plant_Leaves_Beech"
    },
    {
      "x": -27,
      "y": 15,
      "z": 0,
      "name": "Plant_Leaves_Beech"
    },
    {
      "x": -27,
      "y": 0,
      "z": 1,
      "name": "Soil_Grass"
    },
    {
      "x": -27,
      "y": 5,
      "z": 1,
      "name": "Plant_Leaves_Beech"
    },
    {
      "x": -27,
      "y": 6,
      "z": 1,
      "name": "Plant_Leaves_Beech"
    },
    {
      "x": -27,
      "y": 7,
      "z": 1,
      "name": "Plant_Leaves_Beech"
    },
    {
      "x": -27,
      "y": 8,
      "z": 1,
      "name": "Plant_Leaves_Beech"
    },
    {
      "x": -27,
      "y": 10,
      "z": 1,
      "name": "Plant_Leaves_Beech"
    },
    {
      "x": -27,
      "y": 11,
      "z": 1,
      "name": "Plant_Leaves_Beech"
    },
    {
      "x": -27,
      "y": 0,
      "z": 2,
      "name": "Soil_Grass"
    },
    {
      "x": -27,
      "y": 10,
      "z": 2,
      "name": "Plant_Leaves_Beech"
    },
    {
      "x": -27,
      "y": 11,
      "z": 2,
      "name": "Plant_Leaves_Beech"
    },
    {
      "x": -27,
      "y": 0,
      "z": 3,
      "name": "Soil_Grass"
    },
    {
      "x": -27,
      "y": 7,
      "z": 3,
      "name": "Plant_Leaves_Beech"
    },
    {
      "x": -27,
      "y": 9,
      "z": 3,
      "name": "Plant_Leaves_Beech"
    },
    {
      "x": -27,
      "y": 0,
      "z": 4,
      "name": "Soil_Grass"
    },
    {
      "x": -27,
      "y": 7,
      "z": 4,
      "name": "Plant_Leaves_Beech"
    },
    {
      "x": -27,
      "y": 8,
      "z": 4,
      "name": "Plant_Leaves_Beech"
    },
    {
      "x": -27,
      "y": 9,
      "z": 4,
      "name": "Plant_Leaves_Beech"
    },
    {
      "x": -27,
      "y": 0,
      "z": 5,
      "name": "Soil_Grass"
    },
    {
      "x": -27,
      "y": 12,
      "z": 5,
      "name": "Plant_Leaves_Beech"
    },
    {
      "x": -27,
      "y": 13,
      "z": 5,
      "name": "Plant_Leaves_Beech"
    },
    {
      "x": -27,
      "y": 16,
      "z": 5,
      "name": "Plant_Leaves_Beech"
    },
    {
      "x": -27,
      "y": 17,
      "z": 5,
      "name": "Plant_Leaves_Beech"
    },
    {
      "x": -27,
      "y": 0,
      "z": 6,
      "name": "Soil_Grass"
    },
    {
      "x": -27,
      "y": 12,
      "z": 6,
      "name": "Plant_Leaves_Beech"
    },
    {
      "x": -27,
      "y": 13,
      "z": 6,
      "name": "Plant_Leaves_Beech"
    },
    {
      "x": -27,
      "y": 16,
      "z": 6,
      "name": "Plant_Leaves_Beech"
    },
    {
      "x": -27,
      "y": 17,
      "z": 6,
      "name": "Plant_Leaves_Beech"
    },
    {
      "x": -27,
      "y": 0,
      "z": 7,
      "name": "Soil_Grass"
    },
    {
      "x": -27,
      "y": 7,
      "z": 7,
      "name": "Wood_Beech_Trunk_Full"
    },
    {
      "x": -27,
      "y": 0,
      "z": 8,
      "name": "Soil_Grass"
    },
    {
      "x": -27,
      "y": 19,
      "z": 8,
      "name": "Plant_Leaves_Beech"
    },
    {
      "x": -27,
      "y": 20,
      "z": 8,
      "name": "Plant_Leaves_Beech"
    },
    {
      "x": -27,
      "y": 0,
      "z": 9,
      "name": "Soil_Grass"
    },
    {
      "x": -27,
      "y": 7,
      "z": 9,
      "name": "Wood_Beech_Trunk_Full"
    },
    {
      "x": -27,
      "y": 12,
      "z": 9,
      "name": "Wood_Beech_Branch_Long",
      "rotation": 5
    },
    {
      "x": -27,
      "y": 15,
      "z": 9,
      "name": "Wood_Beech_Trunk_Full"
    },
    {
      "x": -27,
      "y": 17,
      "z": 9,
      "name": "Wood_Beech_Branch_Corner",
      "rotation": 3
    },
    {
      "x": -27,
      "y": 18,
      "z": 9,
      "name": "Wood_Beech_Branch_Long"
    },
    {
      "x": -27,
      "y": 19,
      "z": 9,
      "name": "Wood_Beech_Branch_Long"
    },
    {
      "x": -27,
      "y": 20,
      "z": 9,
      "name": "Wood_Beech_Branch_Long"
    },
    {
      "x": -27,
      "y": 21,
      "z": 9,
      "name": "Plant_Leaves_Beech"
    },
    {
      "x": -27,
      "y": 0,
      "z": 10,
      "name": "Soil_Grass"
    },
    {
      "x": -27,
      "y": 20,
      "z": 10,
      "name": "Plant_Leaves_Beech"
    },
    {
      "x": -27,
      "y": 21,
      "z": 10,
      "name": "Plant_Leaves_Beech"
    },
    {
      "x": -27,
      "y": 0,
      "z": 11,
      "name": "Soil_Grass"
    },
    {
      "x": -27,
      "y": 10,
      "z": 11,
      "name": "Wood_Beech_Branch_Long",
      "rotation": 5
    },
    {
      "x": -27,
      "y": 19,
      "z": 11,
      "name": "Plant_Leaves_Beech"
    },
    {
      "x": -27,
      "y": 20,
      "z": 11,
      "name": "Plant_Leaves_Beech"
    },
    {
      "x": -27,
      "y": 0,
      "z": 12,
      "name": "Soil_Grass"
    },
    {
      "x": -27,
      "y": 14,
      "z": 12,
      "name": "Plant_Leaves_Beech"
    },
    {
      "x": -27,
      "y": 15,
      "z": 12,
      "name": "Plant_Leaves_Beech"
    },
    {
      "x": -27,
      "y": 16,
      "z": 12,
      "name": "Plant_Leaves_Beech"
    },
    {
      "x": -27,
      "y": 19,
      "z": 12,
      "name": "Plant_Leaves_Beech"
    },
    {
      "x": -27,
      "y": 0,
      "z": 13,
      "name": "Soil_Grass"
    },
    {
      "x": -27,
      "y": 5,
      "z": 13,
      "name": "Plant_Leaves_Beech"
    },
    {
      "x": -27,
      "y": 6,
      "z": 13,
      "name": "Plant_Leaves_Beech"
    },
    {
      "x": -27,
      "y": 8,
      "z": 13,
      "name": "Plant_Leaves_Beech"
    },
    {
      "x": -27,
      "y": 9,
      "z": 13,
      "name": "Plant_Leaves_Beech"
    },
    {
      "x": -27,
      "y": 14,
      "z": 13,
      "name": "Plant_Leaves_Beech"
    },
    {
      "x": -27,
      "y": 15,
      "z": 13,
      "name": "Plant_Leaves_Beech"
    },
    {
      "x": -27,
      "y": 0,
      "z": 14,
      "name": "Soil_Grass"
    },
    {
      "x": -27,
      "y": 5,
      "z": 14,
      "name": "Plant_Leaves_Beech"
    },
    {
      "x": -27,
      "y": 6,
      "z": 14,
      "name": "Plant_Leaves_Beech"
    },
    {
      "x": -27,
      "y": 7,
      "z": 14,
      "name": "Plant_Leaves_Beech"
    },
    {
      "x": -27,
      "y": 8,
      "z": 14,
      "name": "Plant_Leaves_Beech"
    },
    {
      "x": -27,
      "y": 10,
      "z": 14,
      "name": "Plant_Leaves_Beech"
    },
    {
      "x": -27,
      "y": 11,
      "z": 14,
      "name": "Plant_Leaves_Beech"
    },
    {
      "x": -27,
      "y": 0,
      "z": 15,
      "name": "Soil_Grass"
    },
    {
      "x": -27,
      "y": 10,
      "z": 15,
      "name": "Plant_Leaves_Beech"
    },
    {
      "x": -27,
      "y": 11,
      "z": 15,
      "name": "Plant_Leaves_Beech"
    },
    {
      "x": -27,
      "y": 0,
      "z": 16,
      "name": "Soil_Grass"
    },
    {
      "x": -27,
      "y": 0,
      "z": 17,
      "name": "Soil_Grass"
    },
    {
      "x": -27,
      "y": 0,
      "z": 18,
      "name": "Soil_Grass"
    },
    {
      "x": -27,
      "y": 0,
      "z": 19,
      "name": "Soil_Grass"
    },
    {
      "x": -27,
      "y": 11,
      "z": 19,
      "name": "Plant_Leaves_Beech"
    },
    {
      "x": -27,
      "y": 0,
      "z": 20,
      "name": "Soil_Grass"
    },
    {
      "x": -27,
      "y": 10,
      "z": 20,
      "name": "Plant_Leaves_Beech"
    },
    {
      "x": -27,
      "y": 11,
      "z": 20,
      "name": "Plant_Leaves_Beech"
    },
    {
      "x": -27,
      "y": 12,
      "z": 20,
      "name": "Plant_Leaves_Beech"
    },
    {
      "x": -27,
      "y": 0,
      "z": 21,
      "name": "Soil_Grass"
    },
    {
      "x": -27,
      "y": 10,
      "z": 21,
      "name": "Plant_Leaves_Beech"
    },
    {
      "x": -27,
      "y": 15,
      "z": 21,
      "name": "Plant_Leaves_Beech"
    },
    {
      "x": -27,
      "y": 16,
      "z": 21,
      "name": "Plant_Leaves_Beech"
    },
    {
      "x": -27,
      "y": 0,
      "z": 22,
      "name": "Soil_Grass"
    },
    {
      "x": -27,
      "y": 12,
      "z": 22,
      "name": "Plant_Leaves_Beech"
    },
    {
      "x": -27,
      "y": 13,
      "z": 22,
      "name": "Plant_Leaves_Beech"
    },
    {
      "x": -27,
      "y": 15,
      "z": 22,
      "name": "Plant_Leaves_Beech"
    },
    {
      "x": -27,
      "y": 16,
      "z": 22,
      "name": "Plant_Leaves_Beech"
    },
    {
      "x": -27,
      "y": 17,
      "z": 22,
      "name": "Plant_Leaves_Beech"
    },
    {
      "x": -27,
      "y": 0,
      "z": 23,
      "name": "Soil_Grass"
    },
    {
      "x": -27,
      "y": 7,
      "z": 23,
      "name": "Wood_Beech_Branch_Long",
      "rotation": 5
    },
    {
      "x": -27,
      "y": 12,
      "z": 23,
      "name": "Wood_Beech_Branch_Long",
      "rotation": 5
    },
    {
      "x": -27,
      "y": 13,
      "z": 23,
      "name": "Plant_Leaves_Beech"
    },
    {
      "x": -27,
      "y": 15,
      "z": 23,
      "name": "Wood_Beech_Branch_Corner",
      "rotation": 3
    },
    {
      "x": -27,
      "y": 16,
      "z": 23,
      "name": "Plant_Leaves_Beech"
    },
    {
      "x": -27,
      "y": 17,
      "z": 23,
      "name": "Plant_Leaves_Beech"
    },
    {
      "x": -27,
      "y": 0,
      "z": 24,
      "name": "Soil_Grass"
    },
    {
      "x": -27,
      "y": 12,
      "z": 24,
      "name": "Plant_Leaves_Beech"
    },
    {
      "x": -27,
      "y": 13,
      "z": 24,
      "name": "Plant_Leaves_Beech"
    },
    {
      "x": -27,
      "y": 15,
      "z": 24,
      "name": "Plant_Leaves_Beech"
    },
    {
      "x": -27,
      "y": 16,
      "z": 24,
      "name": "Plant_Leaves_Beech"
    },
    {
      "x": -27,
      "y": 17,
      "z": 24,
      "name": "Plant_Leaves_Beech"
    },
    {
      "x": -27,
      "y": 0,
      "z": 25,
      "name": "Soil_Grass"
    },
    {
      "x": -27,
      "y": 10,
      "z": 25,
      "name": "Wood_Beech_Branch_Corner",
      "rotation": 3
    },
    {
      "x": -27,
      "y": 11,
      "z": 25,
      "name": "Plant_Leaves_Beech"
    },
    {
      "x": -27,
      "y": 15,
      "z": 25,
      "name": "Plant_Leaves_Beech"
    },
    {
      "x": -27,
      "y": 16,
      "z": 25,
      "name": "Plant_Leaves_Beech"
    },
    {
      "x": -27,
      "y": 0,
      "z": 26,
      "name": "Soil_Grass"
    },
    {
      "x": -27,
      "y": 8,
      "z": 26,
      "name": "Plant_Leaves_Beech"
    },
    {
      "x": -27,
      "y": 10,
      "z": 26,
      "name": "Plant_Leaves_Beech"
    },
    {
      "x": -27,
      "y": 11,
      "z": 26,
      "name": "Plant_Leaves_Beech"
    },
    {
      "x": -27,
      "y": 16,
      "z": 26,
      "name": "Plant_Leaves_Beech"
    },
    {
      "x": -27,
      "y": 0,
      "z": 27,
      "name": "Soil_Grass"
    },
    {
      "x": -27,
      "y": 7,
      "z": 27,
      "name": "Plant_Leaves_Beech"
    },
    {
      "x": -27,
      "y": 8,
      "z": 27,
      "name": "Plant_Leaves_Beech"
    },
    {
      "x": -27,
      "y": 0,
      "z": 28,
      "name": "Soil_Grass"
    },
    {
      "x": -27,
      "y": 0,
      "z": 29,
      "name": "Soil_Grass"
    },
    {
      "x": -27,
      "y": 0,
      "z": 30,
      "name": "Soil_Grass"
    },
    {
      "x": -27,
      "y": 0,
      "z": 31,
      "name": "Soil_Grass"
    },
    {
      "x": -27,
      "y": 0,
      "z": 32,
      "name": "Soil_Grass"
    },
    {
      "x": -26,
      "y": 0,
      "z": -31,
      "name": "Soil_Grass"
    },
    {
      "x": -26,
      "y": 11,
      "z": -31,
      "name": "Plant_Leaves_Beech"
    },
    {
      "x": -26,
      "y": 0,
      "z": -30,
      "name": "Soil_Grass"
    },
    {
      "x": -26,
      "y": 10,
      "z": -30,
      "name": "Plant_Leaves_Beech"
    },
    {
      "x": -26,
      "y": 11,
      "z": -30,
      "name": "Plant_Leaves_Beech"
    },
    {
      "x": -26,
      "y": 12,
      "z": -30,
      "name": "Plant_Leaves_Beech"
    },
    {
      "x": -26,
      "y": 0,
      "z": -29,
      "name": "Soil_Grass"
    },
    {
      "x": -26,
      "y": 10,
      "z": -29,
      "name": "Plant_Leaves_Beech"
    },
    {
      "x": -26,
      "y": 15,
      "z": -29,
      "name": "Plant_Leaves_Beech"
    },
    {
      "x": -26,
      "y": 16,
      "z": -29,
      "name": "Plant_Leaves_Beech"
    },
    {
      "x": -26,
      "y": 0,
      "z": -28,
      "name": "Soil_Grass"
    },
    {
      "x": -26,
      "y": 12,
      "z": -28,
      "name": "Plant_Leaves_Beech"
    },
    {
      "x": -26,
      "y": 13,
      "z": -28,
      "name": "Plant_Leaves_Beech"
    },
    {
      "x": -26,
      "y": 15,
      "z": -28,
      "name": "Plant_Leaves_Beech"
    },
    {
      "x": -26,
      "y": 16,
      "z": -28,
      "name": "Plant_Leaves_Beech"
    },
    {
      "x": -26,
      "y": 17,
      "z": -28,
      "name": "Plant_Leaves_Beech"
    },
    {
      "x": -26,
      "y": 0,
      "z": -27,
      "name": "Soil_Grass"
    },
    {
      "x": -26,
      "y": 7,
      "z": -27,
      "name": "Wood_Beech_Branch_Long",
      "rotation": 5
    },
    {
      "x": -26,
      "y": 12,
      "z": -27,
      "name": "Wood_Beech_Branch_Long",
      "rotation": 5
    },
    {
      "x": -26,
      "y": 13,
      "z": -27,
      "name": "Plant_Leaves_Beech"
    },
    {
      "x": -26,
      "y": 15,
      "z": -27,
      "name": "Wood_Beech_Branch_Corner",
      "rotation": 3
    },
    {
      "x": -26,
      "y": 16,
      "z": -27,
      "name": "Plant_Leaves_Beech"
    },
    {
      "x": -26,
      "y": 17,
      "z": -27,
      "name": "Plant_Leaves_Beech"
    },
    {
      "x": -26,
      "y": 0,
      "z": -26,
      "name": "Soil_Grass"
    },
    {
      "x": -26,
      "y": 12,
      "z": -26,
      "name": "Plant_Leaves_Beech"
    },
    {
      "x": -26,
      "y": 13,
      "z": -26,
      "name": "Plant_Leaves_Beech"
    },
    {
      "x": -26,
      "y": 15,
      "z": -26,
      "name": "Plant_Leaves_Beech"
    },
    {
      "x": -26,
      "y": 16,
      "z": -26,
      "name": "Plant_Leaves_Beech"
    },
    {
      "x": -26,
      "y": 17,
      "z": -26,
      "name": "Plant_Leaves_Beech"
    },
    {
      "x": -26,
      "y": 0,
      "z": -25,
      "name": "Soil_Grass"
    },
    {
      "x": -26,
      "y": 10,
      "z": -25,
      "name": "Wood_Beech_Branch_Corner",
      "rotation": 3
    },
    {
      "x": -26,
      "y": 11,
      "z": -25,
      "name": "Plant_Leaves_Beech"
    },
    {
      "x": -26,
      "y": 15,
      "z": -25,
      "name": "Plant_Leaves_Beech"
    },
    {
      "x": -26,
      "y": 16,
      "z": -25,
      "name": "Plant_Leaves_Beech"
    },
    {
      "x": -26,
      "y": 0,
      "z": -24,
      "name": "Soil_Grass"
    },
    {
      "x": -26,
      "y": 8,
      "z": -24,
      "name": "Plant_Leaves_Beech"
    },
    {
      "x": -26,
      "y": 10,
      "z": -24,
      "name": "Plant_Leaves_Beech"
    },
    {
      "x": -26,
      "y": 11,
      "z": -24,
      "name": "Plant_Leaves_Beech"
    },
    {
      "x": -26,
      "y": 16,
      "z": -24,
      "name": "Plant_Leaves_Beech"
    },
    {
      "x": -26,
      "y": 0,
      "z": -23,
      "name": "Soil_Grass"
    },
    {
      "x": -26,
      "y": 7,
      "z": -23,
      "name": "Plant_Leaves_Beech"
    },
    {
      "x": -26,
      "y": 8,
      "z": -23,
      "name": "Plant_Leaves_Beech"
    },
    {
      "x": -26,
      "y": 0,
      "z": -22,
      "name": "Soil_Grass"
    },
    {
      "x": -26,
      "y": 7,
      "z": -22,
      "name": "Plant_Leaves_Beech"
    },
    {
      "x": -26,
      "y": 8,
      "z": -22,
      "name": "Plant_Leaves_Beech"
    },
    {
      "x": -26,
      "y": 9,
      "z": -22,
      "name": "Plant_Leaves_Beech"
    },
    {
      "x": -26,
      "y": 0,
      "z": -21,
      "name": "Soil_Grass"
    },
    {
      "x": -26,
      "y": 7,
      "z": -21,
      "name": "Wood_Beech_Branch_Long",
      "rotation": 4
    },
    {
      "x": -26,
      "y": 8,
      "z": -21,
      "name": "Plant_Leaves_Beech"
    },
    {
      "x": -26,
      "y": 9,
      "z": -21,
      "name": "Plant_Leaves_Beech"
    },
    {
      "x": -26,
      "y": 10,
      "z": -21,
      "name": "Plant_Leaves_Beech"
    },
    {
      "x": -26,
      "y": 12,
      "z": -21,
      "name": "Plant_Leaves_Beech"
    },
    {
      "x": -26,
      "y": 13,
      "z": -21,
      "name": "Plant_Leaves_Beech"
    },
    {
      "x": -26,
      "y": 0,
      "z": -20,
      "name": "Soil_Grass"
    },
    {
      "x": -26,
      "y": 7,
      "z": -20,
      "name": "Wood_Beech_Branch_Long",
      "rotation": 4
    },
    {
      "x": -26,
      "y": 12,
      "z": -20,
      "name": "Plant_Leaves_Beech"
    },
    {
      "x": -26,
      "y": 13,
      "z": -20,
      "name": "Plant_Leaves_Beech"
    },
    {
      "x": -26,
      "y": 16,
      "z": -20,
      "name": "Plant_Leaves_Beech"
    },
    {
      "x": -26,
      "y": 17,
      "z": -20,
      "name": "Plant_Leaves_Beech"
    },
    {
      "x": -26,
      "y": 0,
      "z": -19,
      "name": "Soil_Grass"
    },
    {
      "x": -26,
      "y": 7,
      "z": -19,
      "name": "Wood_Beech_Branch_Long",
      "rotation": 4
    },
    {
      "x": -26,
      "y": 12,
      "z": -19,
      "name": "Wood_Beech_Branch_Long",
      "rotation": 4
    },
    {
      "x": -26,
      "y": 13,
      "z": -19,
      "name": "Plant_Leaves_Beech"
    },
    {
      "x": -26,
      "y": 15,
      "z": -19,
      "name": "Wood_Beech_Branch_Corner",
      "rotation": 2
    },
    {
      "x": -26,
      "y": 16,
      "z": -19,
      "name": "Wood_Beech_Branch_Long"
    },
    {
