{
  "version": 8,
  "blockIdVersion": 11,
  "anchorX": 0,
  "anchorY": 0,
  "anchorZ": 0,
  "blocks": [
    {
      "x": -15,
      "y": 0,
      "z": -15,
      "name": "Soil_Grass"
    },
    {
      "x": -15,
      "y": 0,
      "z": -14,
      "name": "Soil_Grass"
    },
    {
      "x": -15,
      "y": 0,
      "z": -13,
      "name": "Soil_Grass"
    },
    {
      "x": -15,
      "y": 0,
      "z": -12,
      "name": "Soil_Grass"
    },
    {
      "x": -15,
      "y": 0,
      "z": -11,
      "name": "Soil_Grass"
    },
    {
      "x": -15,
      "y": 0,
      "z": -10,
      "name": "Soil_Grass"
    },
    {
      "x": -15,
      "y": 0,
      "z": -9,
      "name": "Soil_Grass"
    },
    {
      "x": -15,
      "y": 0,
      "z": -8,
      "name": "Soil_Grass"
    },
    {
      "x": -15,
      "y": 0,
      "z": -7,
      "name": "Soil_Grass"
    },
    {
      "x": -15,
      "y": 0,
      "z": -6,
      "name": "Soil_Grass"
    },
    {
      "x": -15,
      "y": 0,
      "z": -5,
      "name": "Soil_Grass"
    },
    {
      "x": -15,
      "y": 0,
      "z": -4,
      "name": "Soil_Grass"
    },
    {
      "x": -15,
      "y": 0,
      "z": -3,
      "name": "Soil_Grass"
    },
    {
      "x": -15,
      "y": 0,
      "z": -2,
      "name": "Soil_Grass"
    },
    {
      "x": -15,
      "y": 0,
      "z": -1,
      "name": "Soil_Grass"
    },
    {
      "x": -15,
      "y": 0,
      "z": 0,
      "name": "Soil_Grass"
    },
    {
      "x": -15,
      "y": 0,
      "z": 1,
      "name": "Soil_Grass"
    },
    {
      "x": -15,
      "y": 0,
      "z": 2,
      "name": "Soil_Grass"
    },
    {
      "x": -15,
      "y": 0,
      "z": 3,
      "name": "Soil_Grass"
    },
    {
      "x": -15,
      "y": 0,
      "z": 4,
      "name": "Soil_Grass"
    },
    {
      "x": -15,
      "y": 0,
      "z": 5,
      "name": "Soil_Grass"
    },
    {
      "x": -15,
      "y": 0,
      "z": 6,
      "name": "Soil_Grass"
    },
    {
      "x": -15,
      "y": 0,
      "z": 7,
      "name": "Soil_Grass"
    },
    {
      "x": -15,
      "y": 0,
      "z": 8,
      "name": "Soil_Grass"
    },
    {
      "x": -15,
      "y": 0,
      "z": 9,
      "name": "Soil_Grass"
    },
    {
      "x": -15,
      "y": 0,
      "z": 10,
      "name": "Soil_Grass"
    },
    {
      "x": -15,
      "y": 0,
      "z": 11,
      "name": "Soil_Grass"
    },
    {
      "x": -15,
      "y": 0,
      "z": 12,
      "name": "Soil_Grass"
    },
    {
      "x": -15,
      "y": 0,
      "z": 13,
      "name": "Soil_Grass"
    },
    {
      "x": -15,
      "y": 0,
      "z": 14,
      "name": "Soil_Grass"
    },
    {
      "x": -15,
      "y": 0,
      "z": 15,
      "name": "Soil_Grass"
    },
    {
      "x": -15,
      "y": 0,
      "z": 16,
      "name": "Soil_Grass"
    },
    {
      "x": -14,
      "y": 0,
      "z": -15,
      "name": "Soil_Grass"
    },
    {
      "x": -14,
      "y": 0,
      "z": -14,
      "name": "Soil_Grass"
    },
    {
      "x": -14,
      "y": 0,
      "z": -13,
      "name": "Soil_Grass"
    },
    {
      "x": -14,
      "y": 0,
      "z": -12,
      "name": "Soil_Grass"
    },
    {
      "x": -14,
      "y": 0,
      "z": -11,
      "name": "Soil_Grass"
    },
    {
      "x": -14,
      "y": 0,
      "z": -10,
      "name": "Soil_Grass"
    },
    {
      "x": -14,
      "y": 0,
      "z": -9,
      "name": "Soil_Grass"
    },
    {
      "x": -14,
      "y": 0,
      "z": -8,
      "name": "Soil_Grass"
    },
    {
      "x": -14,
      "y": 0,
      "z": -7,
      "name": "Soil_Grass"
    },
    {
      "x": -14,
      "y": 0,
      "z": -6,
      "name": "Soil_Grass"
    },
    {
      "x": -14,
      "y": 0,
      "z": -5,
      "name": "Soil_Grass"
    },
    {
      "x": -14,
      "y": 0,
      "z": -4,
      "name": "Soil_Grass"
    },
    {
      "x": -14,
      "y": 0,
      "z": -3,
      "name": "Soil_Grass"
    },
    {
      "x": -14,
      "y": 0,
      "z": -2,
      "name": "Soil_Grass"
    },
    {
      "x": -14,
      "y": 0,
      "z": -1,
      "name": "Soil_Grass"
    },
    {
      "x": -14,
      "y": 0,
      "z": 0,
      "name": "Soil_Grass"
    },
    {
      "x": -14,
      "y": 0,
      "z": 1,
      "name": "Soil_Grass"
    },
    {
      "x": -14,
      "y": 0,
      "z": 2,
      "name": "Soil_Grass"
    },
    {
      "x": -14,
      "y": 0,
      "z": 3,
      "name": "Soil_Grass"
    },
    {
      "x": -14,
      "y": 0,
      "z": 4,
      "name": "Soil_Grass"
    },
    {
      "x": -14,
      "y": 0,
      "z": 5,
      "name": "Soil_Grass"
    },
    {
      "x": -14,
      "y": 0,
      "z": 6,
      "name": "Soil_Grass"
    },
    {
      "x": -14,
      "y": 0,
      "z": 7,
      "name": "Soil_Grass"
    },
    {
      "x": -14,
      "y": 0,
      "z": 8,
      "name": "Soil_Grass"
    },
    {
      "x": -14,
      "y": 0,
      "z": 9,
      "name": "Soil_Grass"
    },
    {
      "x": -14,
      "y": 0,
      "z": 10,
      "name": "Soil_Grass"
    },
    {
      "x": -14,
      "y": 0,
      "z": 11,
      "name": "Soil_Grass"
    },
    {
      "x": -14,
      "y": 0,
      "z": 12,
      "name": "Soil_Grass"
    },
    {
      "x": -14,
      "y": 0,
      "z": 13,
      "name": "Soil_Grass"
    },
    {
      "x": -14,
      "y": 0,
      "z": 14,
      "name": "Soil_Grass"
    },
    {
      "x": -14,
      "y": 0,
      "z": 15,
      "name": "Soil_Grass"
    },
    {
      "x": -14,
      "y": 0,
      "z": 16,
      "name": "Soil_Grass"
    },
    {
      "x": -13,
      "y": 0,
      "z": -15,
      "name": "Soil_Grass"
    },
    {
      "x": -13,
      "y": 0,
      "z": -14,
      "name": "Soil_Grass"
    },
    {
      "x": -13,
      "y": 0,
      "z": -13,
      "name": "Soil_Grass"
    },
    {
      "x": -13,
      "y": 0,
      "z": -12,
      "name": "Soil_Grass"
    },
    {
      "x": -13,
      "y": 0,
      "z": -11,
      "name": "Soil_Grass"
    },
    {
      "x": -13,
      "y": 0,
      "z": -10,
      "name": "Soil_Grass"
    },
    {
      "x": -13,
      "y": 0,
      "z": -9,
      "name": "Soil_Grass"
    },
    {
      "x": -13,
      "y": 0,
      "z": -8,
      "name": "Soil_Grass"
    },
    {
      "x": -13,
      "y": 0,
      "z": -7,
      "name": "Soil_Grass"
    },
    {
      "x": -13,
      "y": 0,
      "z": -6,
      "name": "Soil_Grass"
    },
    {
      "x": -13,
      "y": 0,
      "z": -5,
      "name": "Soil_Grass"
    },
    {
      "x": -13,
      "y": 0,
      "z": -4,
      "name": "Soil_Grass"
    },
    {
      "x": -13,
      "y": 0,
      "z": -3,
      "name": "Soil_Grass"
    },
    {
      "x": -13,
      "y": 0,
      "z": -2,
      "name": "Soil_Grass"
    },
    {
      "x": -13,
      "y": 0,
      "z": -1,
      "name": "Soil_Grass"
    },
    {
      "x": -13,
      "y": 0,
      "z": 0,
      "name": "Soil_Grass"
    },
    {
      "x": -13,
      "y": 0,
      "z": 1,
      "name": "Soil_Grass"
    },
    {
      "x": -13,
      "y": 0,
      "z": 2,
      "name": "Soil_Grass"
    },
    {
      "x": -13,
      "y": 0,
      "z": 3,
      "name": "Soil_Grass"
    },
    {
      "x": -13,
      "y": 0,
      "z": 4,
      "name": "Soil_Grass"
    },
    {
      "x": -13,
      "y": 0,
      "z": 5,
      "name": "Soil_Grass"
    },
    {
      "x": -13,
      "y": 0,
      "z": 6,
      "name": "Soil_Grass"
    },
    {
      "x": -13,
      "y": 0,
      "z": 7,
      "name": "Soil_Grass"
    },
    {
      "x": -13,
      "y": 0,
      "z": 8,
      "name": "Soil_Grass"
    },
    {
      "x": -13,
      "y": 0,
      "z": 9,
      "name": "Soil_Grass"
    },
    {
      "x": -13,
      "y": 0,
      "z": 10,
      "name": "Soil_Grass"
    },
    {
      "x": -13,
      "y": 0,
      "z": 11,
      "name": "Soil_Grass"
    },
    {
      "x": -13,
      "y": 0,
      "z": 12,
      "name": "Soil_Grass"
    },
    {
      "x": -13,
      "y": 0,
      "z": 13,
      "name": "Soil_Grass"
    },
    {
      "x": -13,
      "y": 0,
      "z": 14,
      "name": "Soil_Grass"
    },
    {
      "x": -13,
      "y": 0,
      "z": 15,
      "name": "Soil_Grass"
    },
    {
      "x": -13,
      "y": 0,
      "z": 16,
      "name": "Soil_Grass"
    },
    {
      "x": -12,
      "y": 0,
      "z": -15,
      "name": "Soil_Grass"
    },
    {
      "x": -12,
      "y": 0,
      "z": -14,
      "name": "Soil_Grass"
    },
    {
      "x": -12,
      "y": 0,
      "z": -13,
      "name": "Soil_Grass"
    },
    {
      "x": -12,
      "y": 0,
      "z": -12,
      "name": "Soil_Grass"
    },
    {
      "x": -12,
      "y": 0,
      "z": -11,
      "name": "Soil_Grass"
    },
    {
      "x": -12,
      "y": 0,
      "z": -10,
      "name": "Soil_Grass"
    },
    {
      "x": -12,
      "y": 0,
      "z": -9,
      "name": "Soil_Grass"
    },
    {
      "x": -12,
      "y": 0,
      "z": -8,
      "name": "Soil_Grass"
    },
    {
      "x": -12,
      "y": 0,
      "z": -7,
      "name": "Soil_Grass"
    },
    {
      "x": -12,
      "y": 0,
      "z": -6,
      "name": "Soil_Grass"
    },
    {
      "x": -12,
      "y": 0,
      "z": -5,
      "name": "Soil_Grass"
    },
    {
      "x": -12,
      "y": 0,
      "z": -4,
      "name": "Soil_Grass"
    },
    {
      "x": -12,
      "y": 0,
      "z": -3,
      "name": "Soil_Grass"
    },
    {
      "x": -12,
      "y": 0,
      "z": -2,
      "name": "Soil_Grass"
    },
    {
      "x": -12,
      "y": 0,
      "z": -1,
      "name": "Soil_Grass"
    },
    {
      "x": -12,
      "y": 0,
      "z": 0,
      "name": "Soil_Grass"
    },
    {
      "x": -12,
      "y": 0,
      "z": 1,
      "name": "Soil_Grass"
    },
    {
      "x": -12,
      "y": 0,
      "z": 2,
      "name": "Soil_Grass"
    },
    {
      "x": -12,
      "y": 0,
      "z": 3,
      "name": "Soil_Grass"
    },
    {
      "x": -12,
      "y": 0,
      "z": 4,
      "name": "Soil_Grass"
    },
    {
      "x": -12,
      "y": 0,
      "z": 5,
      "name": "Soil_Grass"
    },
    {
      "x": -12,
      "y": 0,
      "z": 6,
      "name": "Soil_Grass"
    },
    {
      "x": -12,
      "y": 0,
      "z": 7,
      "name": "Soil_Grass"
    },
    {
      "x": -12,
      "y": 0,
      "z": 8,
      "name": "Soil_Grass"
    },
    {
      "x": -12,
      "y": 0,
      "z": 9,
      "name": "Soil_Grass"
    },
    {
      "x": -12,
      "y": 0,
      "z": 10,
      "name": "Soil_Grass"
    },
    {
      "x": -12,
      "y": 0,
      "z": 11,
      "name": "Soil_Grass"
    },
    {
      "x": -12,
      "y": 0,
      "z": 12,
      "name": "Soil_Grass"
    },
    {
      "x": -12,
      "y": 0,
      "z": 13,
      "name": "Soil_Grass"
    },
    {
      "x": -12,
      "y": 0,
      "z": 14,
      "name": "Soil_Grass"
    },
    {
      "x": -12,
      "y": 0,
      "z": 15,
      "name": "Soil_Grass"
    },
    {
      "x": -12,
      "y": 0,
      "z": 16,
      "name": "Soil_Grass"
    },
    {
      "x": -11,
      "y": 0,
      "z": -15,
      "name": "Soil_Grass"
    },
    {
      "x": -11,
      "y": 0,
      "z": -14,
      "name": "Soil_Grass"
    },
    {
      "x": -11,
      "y": 0,
      "z": -13,
      "name": "Soil_Grass"
    },
    {
      "x": -11,
      "y": 0,
      "z": -12,
      "name": "Soil_Grass"
    },
    {
      "x": -11,
      "y": 0,
      "z": -11,
      "name": "Soil_Grass"
    },
    {
      "x": -11,
      "y": 0,
      "z": -10,
      "name": "Soil_Grass"
    },
    {
      "x": -11,
      "y": 0,
      "z": -9,
      "name": "Soil_Grass"
    },
    {
      "x": -11,
      "y": 0,
      "z": -8,
      "name": "Soil_Grass"
    },
    {
      "x": -11,
      "y": 0,
      "z": -7,
      "name": "Soil_Grass"
    },
    {
      "x": -11,
      "y": 0,
      "z": -6,
      "name": "Soil_Grass"
    },
    {
      "x": -11,
      "y": 0,
      "z": -5,
      "name": "Soil_Grass"
    },
    {
      "x": -11,
      "y": 0,
      "z": -4,
      "name": "Soil_Grass"
    },
    {
      "x": -11,
      "y": 0,
      "z": -3,
      "name": "Soil_Grass"
    },
    {
      "x": -11,
      "y": 0,
      "z": -2,
      "name": "Soil_Grass"
    },
    {
      "x": -11,
      "y": 0,
      "z": -1,
      "name": "Soil_Grass"
    },
    {
      "x": -11,
      "y": 0,
      "z": 0,
      "name": "Soil_Grass"
    },
    {
      "x": -11,
      "y": 0,
      "z": 1,
      "name": "Soil_Grass"
    },
    {
      "x": -11,
      "y": 0,
      "z": 2,
      "name": "Soil_Grass"
    },
    {
      "x": -11,
      "y": 0,
      "z": 3,
      "name": "Soil_Grass"
    },
    {
      "x": -11,
      "y": 0,
      "z": 4,
      "name": "Soil_Grass"
    },
    {
      "x": -11,
      "y": 0,
      "z": 5,
      "name": "Soil_Grass"
    },
    {
      "x": -11,
      "y": 0,
      "z": 6,
      "name": "Soil_Grass"
    },
    {
      "x": -11,
      "y": 0,
      "z": 7,
      "name": "Soil_Grass"
    },
    {
      "x": -11,
      "y": 0,
      "z": 8,
      "name": "Soil_Grass"
    },
    {
      "x": -11,
      "y": 0,
      "z": 9,
      "name": "Soil_Grass"
    },
    {
      "x": -11,
      "y": 0,
      "z": 10,
      "name": "Soil_Grass"
    },
    {
      "x": -11,
      "y": 0,
      "z": 11,
      "name": "Soil_Grass"
    },
    {
      "x": -11,
      "y": 0,
      "z": 12,
      "name": "Soil_Grass"
    },
    {
      "x": -11,
      "y": 0,
      "z": 13,
      "name": "Soil_Grass"
    },
    {
      "x": -11,
      "y": 0,
      "z": 14,
      "name": "Soil_Grass"
    },
    {
      "x": -11,
      "y": 0,
      "z": 15,
      "name": "Soil_Grass"
    },
    {
      "x": -11,
      "y": 0,
      "z": 16,
      "name": "Soil_Grass"
    },
    {
      "x": -10,
      "y": 0,
      "z": -15,
      "name": "Soil_Grass"
    },
    {
      "x": -10,
      "y": 0,
      "z": -14,
      "name": "Soil_Grass"
    },
    {
      "x": -10,
      "y": 0,
      "z": -13,
      "name": "Soil_Grass"
    },
    {
      "x": -10,
      "y": 0,
      "z": -12,
      "name": "Soil_Grass"
    },
    {
      "x": -10,
      "y": 0,
      "z": -11,
      "name": "Soil_Grass"
    },
    {
      "x": -10,
      "y": 0,
      "z": -10,
      "name": "Soil_Grass"
    },
    {
      "x": -10,
      "y": 0,
      "z": -9,
      "name": "Soil_Grass"
    },
    {
      "x": -10,
      "y": 0,
      "z": -8,
      "name": "Soil_Grass"
    },
    {
      "x": -10,
      "y": 0,
      "z": -7,
      "name": "Soil_Grass"
    },
    {
      "x": -10,
      "y": 0,
      "z": -6,
      "name": "Soil_Grass"
    },
    {
      "x": -10,
      "y": 0,
      "z": -5,
      "name": "Soil_Grass"
    },
    {
      "x": -10,
      "y": 0,
      "z": -4,
      "name": "Soil_Grass"
    },
    {
      "x": -10,
      "y": 0,
      "z": -3,
      "name": "Soil_Grass"
    },
    {
      "x": -10,
      "y": 0,
      "z": -2,
      "name": "Soil_Grass"
    },
    {
      "x": -10,
      "y": 0,
      "z": -1,
      "name": "Soil_Grass"
    },
    {
      "x": -10,
      "y": 0,
      "z": 0,
      "name": "Soil_Grass"
    },
    {
      "x": -10,
      "y": 0,
      "z": 1,
      "name": "Soil_Grass"
    },
    {
      "x": -10,
      "y": 0,
      "z": 2,
      "name": "Soil_Grass"
    },
    {
      "x": -10,
      "y": 0,
      "z": 3,
      "name": "Soil_Grass"
    },
    {
      "x": -10,
      "y": 0,
      "z": 4,
      "name": "Soil_Grass"
    },
    {
      "x": -10,
      "y": 0,
      "z": 5,
      "name": "Soil_Grass"
    },
    {
      "x": -10,
      "y": 0,
      "z": 6,
      "name": "Soil_Grass"
    },
    {
      "x": -10,
      "y": 0,
      "z": 7,
      "name": "Soil_Grass"
    },
    {
      "x": -10,
      "y": 0,
      "z": 8,
      "name": "Soil_Grass"
    },
    {
      "x": -10,
      "y": 0,
      "z": 9,
      "name": "Soil_Grass"
    },
    {
      "x": -10,
      "y": 0,
      "z": 10,
      "name": "Soil_Grass"
    },
    {
      "x": -10,
      "y": 0,
      "z": 11,
      "name": "Soil_Grass"
    },
    {
      "x": -10,
      "y": 0,
      "z": 12,
      "name": "Soil_Grass"
    },
    {
      "x": -10,
      "y": 0,
      "z": 13,
      "name": "Soil_Grass"
    },
    {
      "x": -10,
      "y": 0,
      "z": 14,
      "name": "Soil_Grass"
    },
    {
      "x": -10,
      "y": 0,
      "z": 15,
      "name": "Soil_Grass"
    },
    {
      "x": -10,
      "y": 0,
      "z": 16,
      "name": "Soil_Grass"
    },
    {
      "x": -9,
      "y": 0,
      "z": -15,
      "name": "Soil_Grass"
    },
    {
      "x": -9,
      "y": 0,
      "z": -14,
      "name": "Soil_Grass"
    },
    {
      "x": -9,
      "y": 0,
      "z": -13,
      "name": "Soil_Grass"
    },
    {
      "x": -9,
      "y": 0,
      "z": -12,
      "name": "Soil_Grass"
    },
    {
      "x": -9,
      "y": 0,
      "z": -11,
      "name": "Soil_Grass"
    },
    {
      "x": -9,
      "y": 0,
      "z": -10,
      "name": "Soil_Grass"
    },
    {
      "x": -9,
      "y": 0,
      "z": -9,
      "name": "Soil_Grass"
    },
    {
      "x": -9,
      "y": 0,
      "z": -8,
      "name": "Soil_Grass"
    },
    {
      "x": -9,
      "y": 0,
      "z": -7,
      "name": "Soil_Grass"
    },
    {
      "x": -9,
      "y": 0,
      "z": -6,
      "name": "Soil_Grass"
    },
    {
      "x": -9,
      "y": 0,
      "z": -5,
      "name": "Soil_Grass"
    },
    {
      "x": -9,
      "y": 0,
      "z": -4,
      "name": "Soil_Grass"
    },
    {
      "x": -9,
      "y": 0,
      "z": -3,
      "name": "Soil_Grass"
    },
    {
      "x": -9,
      "y": 0,
      "z": -2,
      "name": "Soil_Grass"
    },
    {
      "x": -9,
      "y": 0,
      "z": -1,
      "name": "Soil_Grass"
    },
    {
      "x": -9,
      "y": 0,
      "z": 0,
      "name": "Soil_Grass"
    },
    {
      "x": -9,
      "y": 0,
      "z": 1,
      "name": "Soil_Grass"
    },
    {
      "x": -9,
      "y": 0,
      "z": 2,
      "name": "Soil_Grass"
    },
    {
      "x": -9,
      "y": 0,
      "z": 3,
      "name": "Soil_Grass"
    },
    {
      "x": -9,
      "y": 0,
      "z": 4,
      "name": "Soil_Grass"
    },
    {
      "x": -9,
      "y": 0,
      "z": 5,
      "name": "Soil_Grass"
    },
    {
      "x": -9,
      "y": 0,
      "z": 6,
      "name": "Soil_Grass"
    },
    {
      "x": -9,
      "y": 0,
      "z": 7,
      "name": "Soil_Grass"
    },
    {
      "x": -9,
      "y": 0,
      "z": 8,
      "name": "Soil_Grass"
    },
    {
      "x": -9,
      "y": 0,
      "z": 9,
      "name": "Soil_Grass"
    },
    {
      "x": -9,
      "y": 0,
      "z": 10,
      "name": "Soil_Grass"
    },
    {
      "x": -9,
      "y": 0,
      "z": 11,
      "name": "Soil_Grass"
    },
    {
      "x": -9,
      "y": 0,
      "z": 12,
      "name": "Soil_Grass"
    },
    {
      "x": -9,
      "y": 0,
      "z": 13,
      "name": "Soil_Grass"
    },
    {
      "x": -9,
      "y": 0,
      "z": 14,
      "name": "Soil_Grass"
    },
    {
      "x": -9,
      "y": 0,
      "z": 15,
      "name": "Soil_Grass"
    },
    {
      "x": -9,
      "y": 0,
      "z": 16,
      "name": "Soil_Grass"
    },
    {
      "x": -8,
      "y": 0,
      "z": -15,
      "name": "Soil_Grass"
    },
    {
      "x": -8,
      "y": 0,
      "z": -14,
      "name": "Soil_Grass"
    },
    {
      "x": -8,
      "y": 0,
      "z": -13,
      "name": "Soil_Grass"
    },
    {
      "x": -8,
      "y": 0,
      "z": -12,
      "name": "Soil_Grass"
    },
    {
      "x": -8,
      "y": 0,
      "z": -11,
      "name": "Soil_Grass"
    },
    {
      "x": -8,
      "y": 0,
      "z": -10,
      "name": "Soil_Grass"
    },
    {
      "x": -8,
      "y": 0,
      "z": -9,
      "name": "Soil_Grass"
    },
    {
      "x": -8,
      "y": 0,
      "z": -8,
      "name": "Soil_Grass"
    },
    {
      "x": -8,
      "y": 0,
      "z": -7,
      "name": "Soil_Grass"
    },
    {
      "x": -8,
      "y": 0,
      "z": -6,
      "name": "Soil_Grass"
    },
    {
      "x": -8,
      "y": 0,
      "z": -5,
      "name": "Soil_Grass"
    },
    {
      "x": -8,
      "y": 0,
      "z": -4,
      "name": "Soil_Grass"
    },
    {
      "x": -8,
      "y": 0,
      "z": -3,
      "name": "Soil_Grass"
    },
    {
      "x": -8,
      "y": 0,
      "z": -2,
      "name": "Soil_Grass"
    },
    {
      "x": -8,
      "y": 0,
      "z": -1,
      "name": "Soil_Grass"
    },
    {
      "x": -8,
      "y": 0,
      "z": 0,
      "name": "Soil_Grass"
    },
    {
      "x": -8,
      "y": 0,
      "z": 1,
      "name": "Soil_Grass"
    },
    {
      "x": -8,
      "y": 0,
      "z": 2,
      "name": "Soil_Grass"
    },
    {
      "x": -8,
      "y": 0,
      "z": 3,
      "name": "Soil_Grass"
    },
    {
      "x": -8,
      "y": 0,
      "z": 4,
      "name": "Soil_Grass"
    },
    {
      "x": -8,
      "y": 0,
      "z": 5,
      "name": "Soil_Grass"
    },
    {
      "x": -8,
      "y": 0,
      "z": 6,
      "name": "Soil_Grass"
    },
    {
      "x": -8,
      "y": 0,
      "z": 7,
      "name": "Soil_Grass"
    },
    {
      "x": -8,
      "y": 0,
      "z": 8,
      "name": "Soil_Grass"
    },
    {
      "x": -8,
      "y": 0,
      "z": 9,
      "name": "Soil_Grass"
    },
    {
      "x": -8,
      "y": 0,
      "z": 10,
      "name": "Soil_Grass"
    },
    {
      "x": -8,
      "y": 0,
      "z": 11,
      "name": "Soil_Grass"
    },
    {
      "x": -8,
      "y": 0,
      "z": 12,
      "name": "Soil_Grass"
    },
    {
      "x": -8,
      "y": 0,
      "z": 13,
      "name": "Soil_Grass"
    },
    {
      "x": -8,
      "y": 0,
      "z": 14,
      "name": "Soil_Grass"
    },
    {
      "x": -8,
      "y": 0,
      "z": 15,
      "name": "Soil_Grass"
    },
    {
      "x": -8,
      "y": 0,
      "z": 16,
      "name": "Soil_Grass"
    },
    {
      "x": -7,
      "y": 0,
      "z": -15,
      "name": "Soil_Grass"
    },
    {
      "x": -7,
      "y": 0,
      "z": -14,
      "name": "Soil_Grass"
    },
    {
      "x": -7,
      "y": 0,
      "z": -13,
      "name": "Soil_Grass"
    },
    {
      "x": -7,
      "y": 0,
      "z": -12,
      "name": "Soil_Grass"
    },
    {
      "x": -7,
      "y": 0,
      "z": -11,
      "name": "Soil_Grass"
    },
    {
      "x": -7,
      "y": 0,
      "z": -10,
      "name": "Soil_Grass"
    },
    {
      "x": -7,
      "y": 0,
      "z": -9,
      "name": "Soil_Grass"
    },
    {
      "x": -7,
      "y": 0,
      "z": -8,
      "name": "Soil_Grass"
    },
    {
      "x": -7,
      "y": 0,
      "z": -7,
      "name": "Soil_Grass"
    },
    {
      "x": -7,
      "y": 0,
      "z": -6,
      "name": "Soil_Grass"
    },
    {
      "x": -7,
      "y": 0,
      "z": -5,
      "name": "Soil_Grass"
    },
    {
      "x": -7,
      "y": 0,
      "z": -4,
      "name": "Soil_Grass"
    },
    {
      "x": -7,
      "y": 0,
      "z": -3,
      "name": "Soil_Grass"
    },
    {
      "x": -7,
      "y": 0,
      "z": -2,
      "name": "Soil_Grass"
    },
    {
      "x": -7,
      "y": 0,
      "z": -1,
      "name": "Soil_Grass"
    },
    {
      "x": -7,
      "y": 0,
      "z": 0,
      "name": "Soil_Grass"
    },
    {
      "x": -7,
      "y": 0,
      "z": 1,
      "name": "Soil_Grass"
    },
    {
      "x": -7,
      "y": 0,
      "z": 2,
      "name": "Soil_Grass"
    },
    {
      "x": -7,
      "y": 0,
      "z": 3,
      "name": "Soil_Grass"
    },
    {
      "x": -7,
      "y": 0,
      "z": 4,
      "name": "Soil_Grass"
    },
    {
      "x": -7,
      "y": 0,
      "z": 5,
      "name": "Soil_Grass"
    },
    {
      "x": -7,
      "y": 0,
      "z": 6,
      "name": "Soil_Grass"
    },
    {
      "x": -7,
      "y": 0,
      "z": 7,
      "name": "Soil_Grass"
    },
    {
      "x": -7,
      "y": 0,
      "z": 8,
      "name": "Soil_Grass"
    },
    {
      "x": -7,
      "y": 0,
      "z": 9,
      "name": "Soil_Grass"
    },
    {
      "x": -7,
      "y": 0,
      "z": 10,
      "name": "Soil_Grass"
    },
    {
      "x": -7,
      "y": 0,
      "z": 11,
      "name": "Soil_Grass"
    },
    {
      "x": -7,
      "y": 0,
      "z": 12,
      "name": "Soil_Grass"
    },
    {
      "x": -7,
      "y": 0,
      "z": 13,
      "name": "Soil_Grass"
    },
    {
      "x": -7,
      "y": 0,
      "z": 14,
      "name": "Soil_Grass"
    },
    {
      "x": -7,
      "y": 0,
      "z": 15,
      "name": "Soil_Grass"
    },
    {
      "x": -7,
      "y": 0,
      "z": 16,
      "name": "Soil_Grass"
    },
    {
      "x": -6,
      "y": 0,
      "z": -15,
      "name": "Soil_Grass"
    },
    {
      "x": -6,
      "y": 0,
      "z": -14,
      "name": "Soil_Grass"
    },
    {
      "x": -6,
      "y": 0,
      "z": -13,
      "name": "Soil_Grass"
    },
    {
      "x": -6,
      "y": 0,
      "z": -12,
      "name": "Soil_Grass"
    },
    {
      "x": -6,
      "y": 0,
      "z": -11,
      "name": "Soil_Grass"
    },
    {
      "x": -6,
      "y": 0,
      "z": -10,
      "name": "Soil_Grass"
    },
    {
      "x": -6,
      "y": 0,
      "z": -9,
      "name": "Soil_Grass"
    },
    {
      "x": -6,
      "y": 0,
      "z": -8,
      "name": "Soil_Grass"
    },
    {
      "x": -6,
      "y": 0,
      "z": -7,
      "name": "Soil_Grass"
    },
    {
      "x": -6,
      "y": 0,
      "z": -6,
      "name": "Soil_Grass"
    },
    {
      "x": -6,
      "y": 0,
      "z": -5,
      "name": "Soil_Grass"
    },
    {
      "x": -6,
      "y": 0,
      "z": -4,
      "name": "Soil_Grass"
    },
    {
      "x": -6,
      "y": 0,
      "z": -3,
      "name": "Soil_Grass"
    },
    {
      "x": -6,
      "y": 0,
      "z": -2,
      "name": "Soil_Grass"
    },
    {
      "x": -6,
      "y": 0,
      "z": -1,
      "name": "Soil_Grass"
    },
    {
      "x": -6,
      "y": 0,
      "z": 0,
      "name": "Soil_Grass"
    },
    {
      "x": -6,
      "y": 0,
      "z": 1,
      "name": "Soil_Grass"
    },
    {
      "x": -6,
      "y": 0,
      "z": 2,
      "name": "Soil_Grass"
    },
    {
      "x": -6,
      "y": 0,
      "z": 3,
      "name": "Soil_Grass"
    },
    {
      "x": -6,
      "y": 0,
      "z": 4,
      "name": "Soil_Grass"
    },
    {
      "x": -6,
      "y": 0,
      "z": 5,
      "name": "Soil_Grass"
    },
    {
      "x": -6,
      "y": 0,
      "z": 6,
      "name": "Soil_Grass"
    },
    {
      "x": -6,
      "y": 0,
      "z": 7,
      "name": "Soil_Grass"
    },
    {
      "x": -6,
      "y": 0,
      "z": 8,
      "name": "Soil_Grass"
    },
    {
      "x": -6,
      "y": 0,
      "z": 9,
      "name": "Soil_Grass"
    },
    {
      "x": -6,
      "y": 0,
      "z": 10,
      "name": "Soil_Grass"
    },
    {
      "x": -6,
      "y": 0,
      "z": 11,
      "name": "Soil_Grass"
    },
    {
      "x": -6,
      "y": 0,
      "z": 12,
      "name": "Soil_Grass"
    },
    {
      "x": -6,
      "y": 0,
      "z": 13,
      "name": "Soil_Grass"
    },
    {
      "x": -6,
      "y": 0,
      "z": 14,
      "name": "Soil_Grass"
    },
    {
      "x": -6,
      "y": 0,
      "z": 15,
      "name": "Soil_Grass"
    },
    {
      "x": -6,
      "y": 0,
      "z": 16,
      "name": "Soil_Grass"
    },
    {
      "x": -5,
      "y": 0,
      "z": -15,
      "name": "Soil_Grass"
    },
    {
      "x": -5,
      "y": 0,
      "z": -14,
      "name": "Soil_Grass"
    },
    {
      "x": -5,
      "y": 0,
      "z": -13,
      "name": "Soil_Grass"
    },
    {
      "x": -5,
      "y": 0,
      "z": -12,
      "name": "Soil_Grass"
    },
    {
      "x": -5,
      "y": 0,
      "z": -11,
      "name": "Soil_Grass"
    },
    {
      "x": -5,
      "y": 0,
      "z": -10,
      "name": "Soil_Grass"
    },
    {
      "x": -5,
      "y": 0,
      "z": -9,
      "name": "Soil_Grass"
    },
    {
      "x": -5,
      "y": 0,
      "z": -8,
      "name": "Soil_Grass"
    },
    {
      "x": -5,
      "y": 0,
      "z": -7,
      "name": "Soil_Grass"
    },
    {
      "x": -5,
      "y": 0,
      "z": -6,
      "name": "Soil_Grass"
    },
    {
      "x": -5,
      "y": 0,
      "z": -5,
      "name": "Soil_Grass"
    },
    {
      "x": -5,
      "y": 0,
      "z": -4,
      "name": "Soil_Grass"
    },
    {
      "x": -5,
      "y": 0,
      "z": -3,
      "name": "Soil_Grass"
    },
    {
      "x": -5,
      "y": 0,
      "z": -2,
      "name": "Soil_Grass"
    },
    {
      "x": -5,
      "y": 0,
      "z": -1,
      "name": "Soil_Grass"
    },
    {
      "x": -5,
      "y": 0,
      "z": 0,
      "name": "Soil_Grass"
    },
    {
      "x": -5,
      "y": 0,
      "z": 1,
      "name": "Soil_Grass"
    },
    {
      "x": -5,
      "y": 0,
      "z": 2,
      "name": "Soil_Grass"
    },
    {
      "x": -5,
      "y": 0,
      "z": 3,
      "name": "Soil_Grass"
    },
    {
      "x": -5,
      "y": 0,
      "z": 4,
      "name": "Soil_Grass"
    },
    {
      "x": -5,
      "y": 0,
      "z": 5,
      "name": "Soil_Grass"
    },
    {
      "x": -5,
      "y": 0,
      "z": 6,
      "name": "Soil_Grass"
    },
    {
      "x": -5,
      "y": 0,
      "z": 7,
      "name": "Soil_Grass"
    },
    {
      "x": -5,
      "y": 0,
      "z": 8,
      "name": "Soil_Grass"
    },
    {
      "x": -5,
      "y": 0,
      "z": 9,
      "name": "Soil_Grass"
    },
    {
      "x": -5,
      "y": 0,
      "z": 10,
      "name": "Soil_Grass"
    },
    {
      "x": -5,
      "y": 0,
      "z": 11,
      "name": "Soil_Grass"
    },
    {
      "x": -5,
      "y": 0,
      "z": 12,
      "name": "Soil_Grass"
    },
    {
      "x": -5,
      "y": 0,
      "z": 13,
      "name": "Soil_Grass"
    },
    {
      "x": -5,
      "y": 0,
      "z": 14,
      "name": "Soil_Grass"
    },
    {
      "x": -5,
      "y": 0,
      "z": 15,
      "name": "Soil_Grass"
    },
    {
      "x": -5,
      "y": 0,
      "z": 16,
      "name": "Soil_Grass"
    },
    {
      "x": -4,
      "y": 0,
      "z": -15,
      "name": "Soil_Grass"
    },
    {
      "x": -4,
      "y": 0,
      "z": -14,
      "name": "Soil_Grass"
    },
    {
      "x": -4,
      "y": 0,
      "z": -13,
      "name": "Soil_Grass"
    },
    {
      "x": -4,
      "y": 0,
      "z": -12,
      "name": "Soil_Grass"
    },
    {
      "x": -4,
      "y": 0,
      "z": -11,
      "name": "Soil_Grass"
    },
    {
      "x": -4,
      "y": 0,
      "z": -10,
      "name": "Soil_Grass"
    },
    {
      "x": -4,
      "y": 0,
      "z": -9,
      "name": "K2_Slot_Pad_4"
    },
    {
      "x": -4,
      "y": 0,
      "z": -8,
      "name": "K2_Slot_Pad_3"
    },
    {
      "x": -4,
      "y": 0,
      "z": -7,
      "name": "K2_Slot_Pad_2"
    },
    {
      "x": -4,
      "y": 0,
      "z": -6,
      "name": "K2_Slot_Pad_1"
    },
    {
      "x": -4,
      "y": 0,
      "z": -5,
      "name": "Soil_Grass"
    },
    {
      "x": -4,
      "y": 0,
      "z": -4,
      "name": "Soil_Grass"
    },
    {
      "x": -4,
      "y": 0,
      "z": -3,
      "name": "Soil_Grass"
    },
    {
      "x": -4,
      "y": 0,
      "z": -2,
      "name": "Soil_Grass"
    },
    {
      "x": -4,
      "y": 0,
      "z": -1,
      "name": "Soil_Grass"
    },
    {
      "x": -4,
      "y": 0,
      "z": 0,
      "name": "Soil_Grass"
    },
    {
      "x": -4,
      "y": 0,
      "z": 1,
      "name": "Soil_Grass"
    },
    {
      "x": -4,
      "y": 0,
      "z": 2,
      "name": "Soil_Grass"
    },
    {
      "x": -4,
      "y": 0,
      "z": 3,
      "name": "Soil_Grass"
    },
    {
      "x": -4,
      "y": 0,
      "z": 4,
      "name": "Wood_Softwood_Planks"
    },
    {
      "x": -4,
      "y": 1,
      "z": 4,
      "name": "Rock_Stone_Brick_Smooth"
    },
    {
      "x": -4,
      "y": 2,
      "z": 4,
      "name": "Rock_Stone_Brick_Smooth"
    },
    {
      "x": -4,
      "y": 3,
      "z": 4,
      "name": "Rock_Stone_Brick_Smooth"
    },
    {
      "x": -4,
      "y": 4,
      "z": 4,
      "name": "Rock_Stone_Brick_Smooth"
    },
    {
      "x": -4,
      "y": 0,
      "z": 5,
      "name": "Wood_Softwood_Planks"
    },
    {
      "x": -4,
      "y": 1,
      "z": 5,
      "name": "Rock_Stone_Brick_Smooth"
    },
    {
      "x": -4,
      "y": 2,
      "z": 5,
      "name": "Rock_Stone_Brick_Smooth"
    },
    {
      "x": -4,
      "y": 3,
      "z": 5,
      "name": "Rock_Stone_Brick_Smooth"
    },
    {
      "x": -4,
      "y": 4,
      "z": 5,
      "name": "Rock_Stone_Brick_Smooth"
    },
    {
      "x": -4,
      "y": 0,
      "z": 6,
      "name": "Wood_Softwood_Planks"
    },
    {
      "x": -4,
      "y": 1,
      "z": 6,
      "name": "Rock_Stone_Brick_Smooth"
    },
    {
      "x": -4,
      "y": 2,
      "z": 6,
      "name": "K2_Slot_Sign"
    },
    {
      "x": -4,
      "y": 3,
      "z": 6,
      "name": "Rock_Stone_Brick_Smooth"
    },
    {
      "x": -4,
      "y": 4,
      "z": 6,
      "name": "Rock_Stone_Brick_Smooth"
    },
    {
      "x": -4,
      "y": 0,
      "z": 7,
      "name": "Wood_Softwood_Planks"
    },
    {
      "x": -4,
      "y": 1,
      "z": 7,
      "name": "Rock_Stone_Brick_Smooth"
    },
    {
      "x": -4,
      "y": 2,
      "z": 7,
      "name": "Rock_Stone_Brick_Smooth"
    },
    {
      "x": -4,
      "y": 3,
      "z": 7,
      "name": "Rock_Stone_Brick_Smooth"
    },
    {
      "x": -4,
      "y": 4,
      "z": 7,
      "name": "Rock_Stone_Brick_Smooth"
    },
    {
      "x": -4,
      "y": 0,
      "z": 8,
      "name": "Wood_Softwood_Planks"
    },
    {
      "x": -4,
      "y": 1,
      "z": 8,
      "name": "Rock_Stone_Brick_Smooth"
    },
    {
      "x": -4,
      "y": 2,
      "z": 8,
      "name": "Rock_Stone_Brick_Smooth"
    },
    {
      "x": -4,
      "y": 3,
      "z": 8,
      "name": "Rock_Stone_Brick_Smooth"
    },
    {
      "x": -4,
      "y": 4,
      "z": 8,
      "name": "Rock_Stone_Brick_Smooth"
    },
    {
      "x": -4,
      "y": 0,
      "z": 9,
      "name": "Wood_Softwood_Planks"
    },
    {
      "x": -4,
      "y": 1,
      "z": 9,
      "name": "Rock_Stone_Brick_Smooth"
    },
    {
      "x": -4,
      "y": 2,
      "z": 9,
      "name": "Rock_Stone_Brick_Smooth"
    },
    {
      "x": -4,
      "y": 3,
      "z": 9,
      "name": "Rock_Stone_Brick_Smooth"
    },
    {
      "x": -4,
      "y": 4,
      "z": 9,
      "name": "Rock_Stone_Brick_Smooth"
    },
    {
      "x": -4,
      "y": 0,
      "z": 10,
      "name": "Wood_Softwood_Planks"
    },
    {
      "x": -4,
      "y": 1,
      "z": 10,
      "name": "Rock_Stone_Brick_Smooth"
    },
    {
      "x": -4,
      "y": 2,
      "z": 10,
      "name": "Rock_Stone_Brick_Smooth"
    },
    {
      "x": -4,
      "y": 3,
      "z": 10,
      "name": "Rock_Stone_Brick_Smooth"
    },
    {
      "x": -4,
      "y": 4,
      "z": 10,
      "name": "Rock_Stone_Brick_Smooth"
    },
    {
      "x": -4,
      "y": 0,
      "z": 11,
      "name": "Wood_Softwood_Planks"
    },
    {
      "x": -4,
      "y": 1,
      "z": 11,
      "name": "Rock_Stone_Brick_Smooth"
    },
    {
      "x": -4,
      "y": 2,
      "z": 11,
      "name": "Rock_Stone_Brick_Smooth"
    },
    {
      "x": -4,
      "y": 3,
      "z": 11,
      "name": "Rock_Stone_Brick_Smooth"
    },
    {
      "x": -4,
      "y": 4,
      "z": 11,
      "name": "Rock_Stone_Brick_Smooth"
    },
    {
      "x": -4,
      "y": 0,
      "z": 12,
      "name": "Soil_Grass"
    },
    {
      "x": -4,
      "y": 0,
      "z": 13,
      "name": "Soil_Grass"
    },
    {
      "x": -4,
      "y": 0,
      "z": 14,
      "name": "Soil_Grass"
    },
    {
      "x": -4,
      "y": 0,
      "z": 15,
      "name": "Soil_Grass"
    },
    {
      "x": -4,
      "y": 0,
      "z": 16,
      "name": "Soil_Grass"
    },
    {
      "x": -3,
      "y": 0,
      "z": -15,
      "name": "Soil_Grass"
    },
    {
      "x": -3,
      "y": 0,
      "z": -14,
      "name": "Soil_Grass"
    },
    {
      "x": -3,
      "y": 0,
      "z": -13,
      "name": "Soil_Grass"
    },
    {
      "x": -3,
      "y": 0,
      "z": -12,
      "name": "Soil_Grass"
    },
    {
      "x": -3,
      "y": 0,
      "z": -11,
      "name": "Soil_Grass"
    },
    {
      "x": -3,
      "y": 0,
      "z": -10,
      "name": "Soil_Grass"
    },
    {
      "x": -3,
      "y": 0,
      "z": -9,
      "name": "Soil_Grass"
    },
    {
      "x": -3,
      "y": 0,
      "z": -8,
      "name": "Soil_Grass"
    },
    {
      "x": -3,
      "y": 0,
      "z": -7,
      "name": "Soil_Grass"
    },
    {
      "x": -3,
      "y": 0,
      "z": -6,
      "name": "Soil_Grass"
    },
    {
      "x": -3,
      "y": 0,
      "z": -5,
      "name": "Soil_Grass"
    },
    {
      "x": -3,
      "y": 0,
      "z": -4,
      "name": "Wood_Softwood_Planks"
    },
    {
      "x": -3,
      "y": 1,
      "z": -4,
      "name": "Rock_Stone_Brick_Decorative"
    },
    {
      "x": -3,
      "y": 2,
      "z": -4,
      "name": "Rock_Stone_Brick_Smooth"
    },
    {
      "x": -3,
      "y": 3,
      "z": -4,
      "name": "Rock_Stone_Brick_Smooth"
    },
    {
      "x": -3,
      "y": 4,
      "z": -4,
      "name": "Rock_Stone_Brick_Smooth"
    },
    {
      "x": -3,
      "y": 0,
      "z": -3,
      "name": "Wood_Softwood_Planks"
    },
    {
      "x": -3,
      "y": 1,
      "z": -3,
      "name": "Rock_Stone_Brick_Smooth"
    },
    {
      "x": -3,
      "y": 2,
      "z": -3,
      "name": "Rock_Stone_Brick_Smooth"
    },
    {
      "x": -3,
      "y": 3,
      "z": -3,
      "name": "Rock_Stone_Brick_Smooth"
    },
    {
      "x": -3,
      "y": 4,
      "z": -3,
      "name": "Rock_Stone_Brick_Smooth"
    },
    {
      "x": -3,
      "y": 0,
      "z": -2,
      "name": "Wood_Softwood_Planks"
    },
    {
      "x": -3,
      "y": 1,
      "z": -2,
      "name": "Rock_Stone_Brick_Smooth"
    },
    {
      "x": -3,
      "y": 2,
      "z": -2,
      "name": "Rock_Stone_Brick_Smooth"
    },
    {
      "x": -3,
      "y": 3,
      "z": -2,
      "name": "Rock_Stone_Brick_Smooth"
    },
    {
      "x": -3,
      "y": 4,
      "z": -2,
      "name": "Rock_Stone_Brick_Smooth"
    },
    {
      "x": -3,
      "y": 0,
      "z": -1,
      "name": "Wood_Softwood_Planks"
    },
    {
      "x": -3,
      "y": 1,
      "z": -1,
      "name": "Rock_Stone_Brick_Smooth"
    },
    {
      "x": -3,
      "y": 2,
      "z": -1,
      "name": "Rock_Stone_Brick_Smooth"
    },
    {
      "x": -3,
      "y": 3,
      "z": -1,
      "name": "Rock_Stone_Brick_Smooth"
    },
    {
      "x": -3,
      "y": 4,
      "z": -1,
      "name": "Rock_Stone_Brick_Smooth"
    },
    {
      "x": -3,
      "y": 0,
      "z": 0,
      "name": "Wood_Softwood_Planks"
    },
    {
      "x": -3,
      "y": 1,
      "z": 0,
      "name": "Rock_Stone_Brick_Decorative"
    },
    {
      "x": -3,
      "y": 2,
      "z": 0,
      "name": "Rock_Stone_Brick_Smooth"
    },
    {
      "x": -3,
      "y": 3,
      "z": 0,
      "name": "Rock_Stone_Brick_Smooth"
    },
    {
      "x": -3,
      "y": 4,
      "z": 0,
      "name": "Rock_Stone_Brick_Smooth"
    },
    {
      "x": -3,
      "y": 0,
      "z": 1,
      "name": "Wood_Softwood_Planks"
    },
    {
      "x": -3,
      "y": 1,
      "z": 1,
      "name": "Rock_Stone_Brick_Smooth"
    },
    {
      "x": -3,
      "y": 2,
      "z": 1,
      "name": "Rock_Stone_Brick_Smooth"
    },
    {
      "x": -3,
      "y": 3,
      "z": 1,
      "name": "Rock_Stone_Brick_Smooth"
    },
    {
      "x": -3,
      "y": 4,
      "z": 1,
      "name": "Rock_Stone_Brick_Smooth"
    },
    {
      "x": -3,
      "y": 0,
      "z": 2,
      "name": "Wood_Softwood_Planks"
    },
    {
      "x": -3,
      "y": 1,
      "z": 2,
      "name": "Rock_Stone_Brick_Smooth"
    },
    {
      "x": -3,
      "y": 2,
      "z": 2,
      "name": "Rock_Stone_Brick_Smooth"
    },
    {
      "x": -3,
      "y": 3,
      "z": 2,
      "name": "Rock_Stone_Brick_Smooth"
    },
    {
      "x": -3,
      "y": 4,
      "z": 2,
      "name": "Rock_Stone_Brick_Smooth"
    },
    {
      "x": -3,
      "y": 0,
      "z": 3,
      "name": "Wood_Softwood_Planks"
    },
    {
      "x": -3,
      "y": 1,
      "z": 3,
      "name": "Rock_Stone_Brick_Smooth"
    },
    {
      "x": -3,
      "y": 2,
      "z": 3,
      "name": "Rock_Stone_Brick_Smooth"
    },
    {
      "x": -3,
      "y": 3,
      "z": 3,
      "name": "Rock_Stone_Brick_Smooth"
    },
    {
      "x": -3,
      "y": 4,
      "z": 3,
      "name": "Rock_Stone_Brick_Smooth"
    },
    {
      "x": -3,
      "y": 0,
      "z": 4,
      "name": "Wood_Softwood_Planks"
    },
    {
      "x": -3,
      "y": 1,
      "z": 4,
      "name": "Rock_Stone_Brick_Decorative"
    },
    {
      "x": -3,
      "y": 2,
      "z": 4,
      "name": "Rock_Stone_Brick_Smooth"
    },
    {
      "x": -3,
      "y": 3,
      "z": 4,
      "name": "Rock_Stone_Brick_Smooth"
    },
    {
      "x": -3,
      "y": 4,
      "z": 4,
      "name": "Rock_Stone_Brick_Smooth"
    },
    {
      "x": -3,
      "y": 0,
      "z": 5,
      "name": "Wood_Softwood_Planks"
    },
    {
      "x": -3,
      "y": 4,
      "z": 5,
      "name": "Wood_Hardwood_Planks_Half",
      "rotation": 8
    },
    {
      "x": -3,
      "y": 0,
      "z": 6,
      "name": "Wood_Softwood_Planks"
    },
    {
      "x": -3,
      "y": 4,
      "z": 6,
      "name": "Wood_Hardwood_Planks_Half",
      "rotation": 8
    },
    {
      "x": -3,
      "y": 0,
      "z": 7,
      "name": "Wood_Softwood_Planks"
    },
    {
      "x": -3,
      "y": 4,
      "z": 7,
      "name": "Wood_Hardwood_Planks_Half",
      "rotation": 8
    },
    {
      "x": -3,
      "y": 0,
      "z": 8,
      "name": "Wood_Softwood_Planks"
    },
    {
      "x": -3,
      "y": 3,
      "z": 8,
      "name": "Wood_Torch_Wall",
      "rotation": 1
    },
    {
      "x": -3,
      "y": 4,
      "z": 8,
      "name": "Wood_Hardwood_Planks_Half",
      "rotation": 8
    },
    {
      "x": -3,
      "y": 0,
      "z": 9,
      "name": "Wood_Softwood_Planks"
    },
    {
      "x": -3,
      "y": 4,
      "z": 9,
      "name": "Wood_Hardwood_Planks_Half",
      "rotation": 8
    },
    {
      "x": -3,
      "y": 0,
      "z": 10,
      "name": "Wood_Softwood_Planks"
    },
    {
      "x": -3,
      "y": 4,
      "z": 10,
      "name": "Wood_Hardwood_Planks_Half",
      "rotation": 8
    },
    {
      "x": -3,
      "y": 0,
      "z": 11,
      "name": "Rock_Stone_Brick_Smooth"
    },
    {
      "x": -3,
      "y": 1,
      "z": 11,
      "name": "Rock_Stone_Brick_Smooth"
    },
    {
      "x": -3,
      "y": 2,
      "z": 11,
      "name": "Rock_Stone_Brick_Smooth"
    },
    {
      "x": -3,
      "y": 3,
      "z": 11,
      "name": "Rock_Stone_Brick_Smooth"
    },
    {
      "x": -3,
      "y": 4,
      "z": 11,
      "name": "Rock_Stone_Brick_Smooth"
    },
    {
      "x": -3,
      "y": 0,
      "z": 12,
      "name": "Soil_Grass"
    },
    {
      "x": -3,
      "y": 0,
      "z": 13,
      "name": "Soil_Grass"
    },
    {
      "x": -3,
      "y": 0,
      "z": 14,
      "name": "Soil_Grass"
    },
    {
      "x": -3,
      "y": 0,
      "z": 15,
      "name": "Soil_Grass"
    },
    {
      "x": -3,
      "y": 0,
      "z": 16,
      "name": "Soil_Grass"
    },
    {
      "x": -2,
      "y": 0,
      "z": -15,
      "name": "Soil_Grass"
    },
    {
      "x": -2,
      "y": 0,
      "z": -14,
      "name": "Soil_Grass"
    },
    {
      "x": -2,
      "y": 0,
      "z": -13,
      "name": "Soil_Grass"
    },
    {
      "x": -2,
      "y": 0,
      "z": -12,
      "name": "Soil_Grass"
    },
    {
      "x": -2,
      "y": 0,
      "z": -11,
      "name": "Soil_Grass"
    },
    {
      "x": -2,
      "y": 0,
      "z": -10,
      "name": "Soil_Grass"
    },
    {
      "x": -2,
      "y": 0,
      "z": -9,
      "name": "Soil_Grass"
    },
    {
      "x": -2,
      "y": 0,
      "z": -8,
      "name": "Soil_Grass"
    },
    {
      "x": -2,
      "y": 0,
      "z": -7,
      "name": "K2_Slot_Arrival"
    },
    {
      "x": -2,
      "y": 0,
      "z": -6,
      "name": "Soil_Grass"
    },
    {
      "x": -2,
      "y": 0,
      "z": -5,
      "name": "Soil_Grass"
    },
    {
      "x": -2,
      "y": 0,
      "z": -4,
      "name": "Wood_Softwood_Planks"
    },
    {
      "x": -2,
      "y": 3,
      "z": -4,
      "name": "Rock_Stone_Brick_Smooth"
    },
    {
      "x": -2,
      "y": 4,
      "z": -4,
      "name": "Rock_Stone_Brick_Smooth"
    },
    {
      "x": -2,
      "y": 0,
      "z": -3,
      "name": "Wood_Softwood_Planks"
    },
    {
      "x": -2,
      "y": 4,
      "z": -3,
      "name": "Wood_Hardwood_Planks_Half",
      "rotation": 8
    },
    {
      "x": -2,
      "y": 0,
      "z": -2,
      "name": "Wood_Softwood_Planks"
    },
    {
      "x": -2,
      "y": 4,
      "z": -2,
      "name": "Wood_Hardwood_Planks_Half",
      "rotation": 8
    },
    {
      "x": -2,
      "y": 0,
      "z": -1,
      "name": "Wood_Softwood_Planks"
    },
    {
      "x": -2,
      "y": 4,
      "z": -1,
      "name": "Wood_Hardwood_Planks_Half",
      "rotation": 8
    },
    {
      "x": -2,
      "y": 0,
      "z": 0,
      "name": "Wood_Softwood_Planks"
    },
    {
      "x": -2,
      "y": 4,
      "z": 0,
      "name": "Wood_Hardwood_Planks_Half",
      "rotation": 8
    },
    {
      "x": -2,
      "y": 0,
      "z": 1,
      "name": "Wood_Softwood_Planks"
    },
    {
      "x": -2,
      "y": 4,
      "z": 1,
      "name": "Wood_Hardwood_Planks_Half",
      "rotation": 8
    },
    {
      "x": -2,
      "y": 0,
      "z": 2,
      "name": "Wood_Softwood_Planks"
    },
    {
      "x": -2,
      "y": 4,
      "z": 2,
      "name": "Wood_Hardwood_Planks_Half",
      "rotation": 8
    },
    {
      "x": -2,
      "y": 0,
      "z": 3,
      "name": "Wood_Softwood_Planks"
    },
    {
      "x": -2,
      "y": 4,
      "z": 3,
      "name": "Wood_Hardwood_Planks_Half",
      "rotation": 8
    },
    {
      "x": -2,
      "y": 0,
      "z": 4,
      "name": "Wood_Softwood_Planks"
    },
    {
      "x": -2,
      "y": 1,
      "z": 4,
      "name": "K2_Slot_Station_Combine"
    },
    {
      "x": -2,
      "y": 3,
      "z": 4,
      "name": "Rock_Stone_Brick_Smooth"
    },
    {
      "x": -2,
      "y": 4,
      "z": 4,
      "name": "Rock_Stone_Brick_Smooth"
    },
    {
      "x": -2,
      "y": 0,
      "z": 5,
      "name": "Wood_Softwood_Planks"
    },
    {
      "x": -2,
      "y": 4,
      "z": 5,
      "name": "Wood_Hardwood_Planks_Half",
      "rotation": 8
    },
    {
      "x": -2,
      "y": 0,
      "z": 6,
      "name": "Wood_Softwood_Planks"
    },
    {
      "x": -2,
      "y": 4,
      "z": 6,
      "name": "Wood_Hardwood_Planks_Half",
      "rotation": 8
    },
    {
      "x": -2,
      "y": 0,
      "z": 7,
      "name": "Wood_Softwood_Planks"
    },
    {
      "x": -2,
      "y": 4,
      "z": 7,
      "name": "Wood_Hardwood_Planks_Half",
      "rotation": 8
    },
    {
      "x": -2,
      "y": 0,
      "z": 8,
      "name": "Wood_Softwood_Planks"
    },
    {
      "x": -2,
      "y": 4,
      "z": 8,
      "name": "Wood_Hardwood_Planks_Half",
      "rotation": 8
    },
    {
      "x": -2,
      "y": 0,
      "z": 9,
      "name": "Wood_Softwood_Planks"
    },
    {
      "x": -2,
      "y": 4,
      "z": 9,
      "name": "Wood_Hardwood_Planks_Half",
      "rotation": 8
    },
    {
      "x": -2,
      "y": 0,
      "z": 10,
      "name": "Wood_Softwood_Planks"
    },
    {
      "x": -2,
      "y": 1,
      "z": 10,
      "name": "K2_Slot_Station_Rack"
    },
    {
      "x": -2,
      "y": 4,
      "z": 10,
      "name": "Wood_Hardwood_Planks_Half",
      "rotation": 8
    },
    {
      "x": -2,
      "y": 0,
      "z": 11,
      "name": "Wood_Softwood_Planks"
    },
    {
      "x": -2,
      "y": 1,
      "z": 11,
      "name": "Rock_Stone_Brick_Smooth"
    },
    {
      "x": -2,
      "y": 2,
      "z": 11,
      "name": "Rock_Stone_Brick_Smooth"
    },
    {
      "x": -2,
      "y": 3,
      "z": 11,
      "name": "Rock_Stone_Brick_Smooth"
    },
    {
      "x": -2,
      "y": 4,
      "z": 11,
      "name": "Rock_Stone_Brick_Smooth"
    },
    {
      "x": -2,
      "y": 0,
      "z": 12,
      "name": "Soil_Grass"
    },
    {
      "x": -2,
      "y": 0,
      "z": 13,
      "name": "Soil_Grass"
    },
    {
      "x": -2,
      "y": 0,
      "z": 14,
      "name": "Soil_Grass"
    },
    {
      "x": -2,
      "y": 0,
      "z": 15,
      "name": "Soil_Grass"
    },
    {
      "x": -2,
      "y": 0,
      "z": 16,
      "name": "Soil_Grass"
    },
    {
      "x": -1,
      "y": 0,
      "z": -15,
      "name": "Soil_Grass"
    },
    {
      "x": -1,
      "y": 0,
      "z": -14,
      "name": "Soil_Grass"
    },
    {
      "x": -1,
      "y": 0,
      "z": -13,
      "name": "Soil_Grass"
    },
    {
      "x": -1,
      "y": 0,
      "z": -12,
      "name": "Soil_Grass"
    },
    {
      "x": -1,
      "y": 0,
      "z": -11,
      "name": "Soil_Grass"
    },
    {
      "x": -1,
      "y": 0,
      "z": -10,
      "name": "Soil_Grass"
    },
    {
      "x": -1,
      "y": 0,
      "z": -9,
      "name": "Soil_Grass"
    },
    {
      "x": -1,
      "y": 0,
      "z": -8,
      "name": "Soil_Grass"
    },
    {
      "x": -1,
      "y": 0,
      "z": -7,
      "name": "Soil_Grass"
    },
    {
      "x": -1,
      "y": 0,
      "z": -6,
      "name": "Soil_Grass"
    },
    {
      "x": -1,
      "y": 0,
      "z": -5,
      "name": "Soil_Grass"
    },
    {
      "x": -1,
      "y": 0,
      "z": -4,
      "name": "Wood_Softwood_Planks"
    },
    {
      "x": -1,
      "y": 1,
      "z": -4,
      "name": "Rock_Stone_Brick_Decorative"
    },
    {
      "x": -1,
      "y": 2,
      "z": -4,
      "name": "Rock_Stone_Brick_Smooth"
    },
    {
      "x": -1,
      "y": 3,
      "z": -4,
      "name": "Rock_Stone_Brick_Smooth"
    },
    {
      "x": -1,
      "y": 4,
      "z": -4,
      "name": "Rock_Stone_Brick_Smooth"
    },
    {
      "x": -1,
      "y": 0,
      "z": -3,
      "name": "Wood_Softwood_Planks"
    },
    {
      "x": -1,
      "y": 3,
      "z": -3,
      "name": "Wood_Torch_Wall"
    },
    {
      "x": -1,
      "y": 4,
      "z": -3,
      "name": "Wood_Hardwood_Planks_Half",
      "rotation": 8
    },
    {
      "x": -1,
      "y": 0,
      "z": -2,
      "name": "Wood_Softwood_Planks"
    },
    {
      "x": -1,
      "y": 4,
      "z": -2,
      "name": "Wood_Hardwood_Planks_Half",
      "rotation": 8
    },
    {
      "x": -1,
      "y": 0,
      "z": -1,
      "name": "Wood_Softwood_Planks"
    },
    {
      "x": -1,
      "y": 4,
      "z": -1,
      "name": "Wood_Hardwood_Planks_Half",
      "rotation": 8
    },
    {
      "x": -1,
      "y": 0,
      "z": 0,
      "name": "Wood_Softwood_Planks"
    },
    {
      "x": -1,
      "y": 4,
      "z": 0,
      "name": "Wood_Hardwood_Planks_Half",
      "rotation": 8
    },
    {
      "x": -1,
      "y": 0,
      "z": 1,
      "name": "Wood_Softwood_Planks"
    },
    {
      "x": -1,
      "y": 4,
      "z": 1,
      "name": "Wood_Hardwood_Planks_Half",
      "rotation": 8
    },
    {
      "x": -1,
      "y": 0,
      "z": 2,
      "name": "Wood_Softwood_Planks"
    },
    {
      "x": -1,
      "y": 4,
      "z": 2,
      "name": "Wood_Hardwood_Planks_Half",
      "rotation": 8
    },
    {
      "x": -1,
      "y": 0,
      "z": 3,
      "name": "Wood_Softwood_Planks"
    },
    {
      "x": -1,
      "y": 4,
      "z": 3,
      "name": "Wood_Hardwood_Planks_Half",
      "rotation": 8
    },
    {
      "x": -1,
      "y": 0,
      "z": 4,
      "name": "Wood_Softwood_Planks"
    },
    {
      "x": -1,
      "y": 1,
      "z": 4,
      "name": "K2_Slot_Station_Combine"
    },
    {
      "x": -1,
      "y": 3,
      "z": 4,
      "name": "Rock_Stone_Brick_Smooth"
    },
    {
      "x": -1,
      "y": 4,
      "z": 4,
      "name": "Rock_Stone_Brick_Smooth"
    },
    {
      "x": -1,
      "y": 0,
      "z": 5,
      "name": "Wood_Softwood_Planks"
    },
    {
      "x": -1,
      "y": 4,
      "z": 5,
      "name": "Wood_Hardwood_Planks_Half",
      "rotation": 8
    },
    {
      "x": -1,
      "y": 0,
      "z": 6,
      "name": "Wood_Softwood_Planks"
    },
    {
      "x": -1,
      "y": 4,
      "z": 6,
      "name": "Wood_Hardwood_Planks_Half",
      "rotation": 8
    },
    {
      "x": -1,
      "y": 0,
      "z": 7,
      "name": "Wood_Softwood_Planks"
    },
    {
      "x": -1,
      "y": 4,
      "z": 7,
      "name": "Wood_Hardwood_Planks_Half",
      "rotation": 8
    },
    {
      "x": -1,
      "y": 0,
      "z": 8,
      "name": "Wood_Softwood_Planks"
    },
    {
      "x": -1,
      "y": 4,
      "z": 8,
      "name": "Wood_Hardwood_Planks_Half",
      "rotation": 8
    },
    {
      "x": -1,
      "y": 0,
      "z": 9,
      "name": "Wood_Softwood_Planks"
    },
    {
      "x": -1,
      "y": 4,
      "z": 9,
      "name": "Wood_Hardwood_Planks_Half",
      "rotation": 8
    },
    {
      "x": -1,
      "y": 0,
      "z": 10,
      "name": "Wood_Softwood_Planks"
    },
    {
      "x": -1,
      "y": 1,
      "z": 10,
      "name": "K2_Slot_Station_Bin"
    },
    {
      "x": -1,
      "y": 4,
      "z": 10,
      "name": "Wood_Hardwood_Planks_Half",
      "rotation": 8
    },
    {
      "x": -1,
      "y": 0,
      "z": 11,
      "name": "Wood_Softwood_Planks"
    },
    {
      "x": -1,
      "y": 1,
      "z": 11,
      "name": "Rock_Stone_Brick_Smooth"
    },
    {
      "x": -1,
      "y": 2,
      "z": 11,
      "name": "Rock_Stone_Brick_Smooth"
    },
    {
      "x": -1,
      "y": 3,
      "z": 11,
      "name": "Rock_Stone_Brick_Smooth"
    },
    {
      "x": -1,
      "y": 4,
      "z": 11,
      "name": "Rock_Stone_Brick_Smooth"
    },
    {
      "x": -1,
      "y": 0,
      "z": 12,
      "name": "Soil_Grass"
    },
    {
      "x": -1,
      "y": 0,
      "z": 13,
      "name": "Soil_Grass"
    },
    {
      "x": -1,
      "y": 0,
      "z": 14,
      "name": "Soil_Grass"
    },
    {
      "x": -1,
      "y": 0,
      "z": 15,
      "name": "Soil_Grass"
    },
    {
      "x": -1,
      "y": 0,
      "z": 16,
      "name": "Soil_Grass"
    },
    {
      "x": 0,
      "y": 0,
      "z": -15,
      "name": "Soil_Grass"
    },
    {
      "x": 0,
      "y": 0,
      "z": -14,
      "name": "Soil_Grass"
    },
    {
      "x": 0,
      "y": 0,
      "z": -13,
      "name": "Soil_Grass"
    },
    {
      "x": 0,
      "y": 0,
      "z": -12,
      "name": "Soil_Grass"
    },
    {
      "x": 0,
      "y": 0,
      "z": -11,
      "name": "Soil_Grass"
    },
    {
      "x": 0,
      "y": 0,
      "z": -10,
      "name": "Soil_Grass"
    },
    {
      "x": 0,
      "y": 0,
      "z": -9,
      "name": "Soil_Grass"
    },
    {
      "x": 0,
      "y": 0,
      "z": -8,
      "name": "Soil_Grass"
    },
    {
      "x": 0,
      "y": 0,
      "z": -7,
      "name": "Soil_Grass"
    },
    {
      "x": 0,
      "y": 0,
      "z": -6,
      "name": "K2_Slot_Queue_1"
    },
    {
      "x": 0,
      "y": 0,
      "z": -5,
      "name": "Soil_Grass"
    },
    {
      "x": 0,
      "y": 0,
      "z": -4,
      "name": "Wood_Softwood_Planks"
    },
    {
      "x": 0,
      "y": 1,
      "z": -4,
      "name": "Rock_Stone_Brick_Smooth"
    },
    {
      "x": 0,
      "y": 3,
      "z": -4,
      "name": "Rock_Stone_Brick_Smooth"
    },
    {
      "x": 0,
      "y": 4,
      "z": -4,
      "name": "Rock_Stone_Brick_Smooth"
    },
    {
      "x": 0,
      "y": 0,
      "z": -3,
      "name": "Wood_Softwood_Planks"
    },
    {
      "x": 0,
      "y": 4,
      "z": -3,
      "name": "Wood_Hardwood_Planks_Half",
      "rotation": 8
    },
    {
      "x": 0,
      "y": 0,
      "z": -2,
      "name": "Wood_Softwood_Planks"
    },
    {
      "x": 0,
      "y": 4,
      "z": -2,
      "name": "Wood_Hardwood_Planks_Half",
      "rotation": 8
    },
    {
      "x": 0,
      "y": 0,
      "z": -1,
      "name": "Wood_Softwood_Planks"
    },
    {
      "x": 0,
      "y": 4,
      "z": -1,
      "name": "Wood_Hardwood_Planks_Half",
      "rotation": 8
    },
    {
      "x": 0,
      "y": 0,
      "z": 0,
      "name": "Wood_Softwood_Planks"
    },
    {
      "x": 0,
      "y": 4,
      "z": 0,
      "name": "Wood_Hardwood_Planks_Half",
      "rotation": 8
    },
    {
      "x": 0,
      "y": 0,
      "z": 1,
      "name": "Wood_Softwood_Planks"
    },
    {
      "x": 0,
      "y": 4,
      "z": 1,
      "name": "Wood_Hardwood_Planks_Half",
      "rotation": 8
    },
    {
      "x": 0,
      "y": 0,
      "z": 2,
      "name": "Wood_Softwood_Planks"
    },
    {
      "x": 0,
      "y": 4,
      "z": 2,
      "name": "Wood_Hardwood_Planks_Half",
      "rotation": 8
    },
    {
      "x": 0,
      "y": 0,
      "z": 3,
      "name": "Wood_Softwood_Planks"
    },
    {
      "x": 0,
      "y": 4,
      "z": 3,
      "name": "Wood_Hardwood_Planks_Half",
      "rotation": 8
    },
    {
      "x": 0,
      "y": 0,
      "z": 4,
      "name": "Wood_Softwood_Planks"
    },
    {
      "x": 0,
      "y": 1,
      "z": 4,
      "name": "K2_Slot_Station_Combine"
    },
    {
      "x": 0,
      "y": 3,
      "z": 4,
      "name": "Rock_Stone_Brick_Smooth"
    },
    {
      "x": 0,
      "y": 4,
      "z": 4,
      "name": "Rock_Stone_Brick_Smooth"
    },
    {
      "x": 0,
      "y": 0,
      "z": 5,
      "name": "Wood_Softwood_Planks"
    },
    {
      "x": 0,
      "y": 4,
      "z": 5,
      "name": "Wood_Hardwood_Planks_Half",
      "rotation": 8
    },
    {
      "x": 0,
      "y": 0,
      "z": 6,
      "name": "Wood_Softwood_Planks"
    },
    {
      "x": 0,
      "y": 4,
      "z": 6,
      "name": "Wood_Hardwood_Planks_Half",
      "rotation": 8
    },
    {
      "x": 0,
      "y": 0,
      "z": 7,
      "name": "Wood_Softwood_Planks"
    },
    {
      "x": 0,
      "y": 4,
      "z": 7,
      "name": "Wood_Hardwood_Planks_Half",
      "rotation": 8
    },
    {
      "x": 0,
      "y": 0,
      "z": 8,
      "name": "Wood_Softwood_Planks"
    },
    {
      "x": 0,
      "y": 4,
      "z": 8,
      "name": "Wood_Hardwood_Planks_Half",
      "rotation": 8
    },
    {
      "x": 0,
      "y": 0,
      "z": 9,
      "name": "Wood_Softwood_Planks"
    },
    {
      "x": 0,
      "y": 4,
      "z": 9,
      "name": "Wood_Hardwood_Planks_Half",
      "rotation": 8
    },
    {
      "x": 0,
      "y": 0,
      "z": 10,
      "name": "Wood_Softwood_Planks"
    },
    {
      "x": 0,
      "y": 4,
      "z": 10,
      "name": "Wood_Hardwood_Planks_Half",
      "rotation": 8
    },
    {
      "x": 0,
      "y": 0,
      "z": 11,
      "name": "Wood_Softwood_Planks"
    },
    {
      "x": 0,
      "y": 1,
      "z": 11,
      "name": "Rock_Stone_Brick_Smooth"
    },
    {
      "x": 0,
      "y": 2,
      "z": 11,
      "name": "Rock_Stone_Brick_Smooth"
    },
    {
      "x": 0,
      "y": 3,
      "z": 11,
      "name": "Rock_Stone_Brick_Smooth"
    },
    {
      "x": 0,
      "y": 4,
      "z": 11,
      "name": "Rock_Stone_Brick_Smooth"
    },
    {
      "x": 0,
      "y": 0,
      "z": 12,
      "name": "Soil_Grass"
    },
    {
      "x": 0,
      "y": 0,
      "z": 13,
      "name": "Soil_Grass"
    },
    {
      "x": 0,
      "y": 0,
      "z": 14,
      "name": "Soil_Grass"
    },
    {
      "x": 0,
      "y": 0,
      "z": 15,
      "name": "Soil_Grass"
    },
    {
      "x": 0,
      "y": 0,
      "z": 16,
      "name": "Soil_Grass"
    },
    {
      "x": 1,
      "y": 0,
      "z": -15,
      "name": "Soil_Grass"
    },
    {
      "x": 1,
      "y": 0,
      "z": -14,
      "name": "Soil_Grass"
    },
    {
      "x": 1,
      "y": 0,
      "z": -13,
      "name": "Soil_Grass"
    },
    {
      "x": 1,
      "y": 0,
      "z": -12,
      "name": "Soil_Grass"
    },
    {
      "x": 1,
      "y": 0,
      "z": -11,
      "name": "Soil_Grass"
    },
    {
      "x": 1,
      "y": 0,
      "z": -10,
      "name": "Soil_Grass"
    },
    {
      "x": 1,
      "y": 0,
      "z": -9,
      "name": "Soil_Grass"
    },
    {
      "x": 1,
      "y": 0,
      "z": -8,
      "name": "Soil_Grass"
    },
    {
      "x": 1,
      "y": 0,
      "z": -7,
      "name": "Soil_Grass"
    },
    {
      "x": 1,
      "y": 0,
      "z": -5,
      "name": "Soil_Grass"
    },
    {
      "x": 1,
      "y": 0,
      "z": -4,
      "name": "Wood_Softwood_Planks"
    },
    {
      "x": 1,
      "y": 1,
      "z": -4,
      "name": "Rock_Stone_Brick_Smooth"
    },
    {
      "x": 1,
      "y": 3,
      "z": -4,
      "name": "Rock_Stone_Brick_Smooth"
    },
    {
      "x": 1,
      "y": 4,
      "z": -4,
      "name": "Rock_Stone_Brick_Smooth"
    },
    {
      "x": 1,
      "y": 0,
      "z": -3,
      "name": "Wood_Softwood_Planks"
    },
    {
      "x": 1,
      "y": 4,
      "z": -3,
      "name": "Wood_Hardwood_Planks_Half",
      "rotation": 8
    },
    {
      "x": 1,
      "y": 0,
      "z": -2,
      "name": "Wood_Softwood_Planks"
    },
    {
      "x": 1,
      "y": 4,
      "z": -2,
      "name": "Wood_Hardwood_Planks_Half",
      "rotation": 8
    },
    {
      "x": 1,
      "y": 0,
      "z": -1,
      "name": "Wood_Softwood_Planks"
    },
    {
      "x": 1,
      "y": 4,
      "z": -1,
      "name": "Wood_Hardwood_Planks_Half",
      "rotation": 8
    },
    {
      "x": 1,
      "y": 0,
      "z": 0,
      "name": "Wood_Softwood_Planks"
    },
    {
      "x": 1,
      "y": 4,
      "z": 0,
      "name": "Wood_Hardwood_Planks_Half",
      "rotation": 8
    },
    {
      "x": 1,
      "y": 0,
      "z": 1,
      "name": "Wood_Softwood_Planks"
    },
    {
      "x": 1,
      "y": 4,
      "z": 1,
      "name": "Wood_Hardwood_Planks_Half",
      "rotation": 8
    },
    {
      "x": 1,
      "y": 0,
      "z": 2,
      "name": "Wood_Softwood_Planks"
    },
    {
      "x": 1,
      "y": 4,
      "z": 2,
      "name": "Wood_Hardwood_Planks_Half",
      "rotation": 8
    },
    {
      "x": 1,
      "y": 0,
      "z": 3,
      "name": "Wood_Softwood_Planks"
    },
    {
      "x": 1,
      "y": 3,
      "z": 3,
      "name": "Wood_Torch_Wall",
      "rotation": 2
    },
    {
      "x": 1,
      "y": 4,
      "z": 3,
      "name": "Wood_Hardwood_Planks_Half",
      "rotation": 8
    },
    {
      "x": 1,
      "y": 0,
      "z": 4,
      "name": "Wood_Softwood_Planks"
    },
    {
      "x": 1,
      "y": 1,
      "z": 4,
      "name": "Rock_Stone_Brick_Decorative"
    },
    {
      "x": 1,
      "y": 2,
      "z": 4,
      "name": "Rock_Stone_Brick_Smooth"
    },
    {
      "x": 1,
      "y": 3,
      "z": 4,
      "name": "Rock_Stone_Brick_Smooth"
    },
    {
      "x": 1,
      "y": 4,
      "z": 4,
      "name": "Rock_Stone_Brick_Smooth"
    },
    {
      "x": 1,
      "y": 0,
      "z": 5,
      "name": "Wood_Softwood_Planks"
    },
    {
      "x": 1,
      "y": 4,
      "z": 5,
      "name": "Wood_Hardwood_Planks_Half",
      "rotation": 8
    },
    {
      "x": 1,
      "y": 0,
      "z": 6,
      "name": "Wood_Softwood_Planks"
    },
    {
      "x": 1,
      "y": 1,
      "z": 6,
      "name": "K2_Slot_Station_Press"
    },
    {
      "x": 1,
      "y": 4,
      "z": 6,
      "name": "Wood_Hardwood_Planks_Half",
      "rotation": 8
    },
    {
      "x": 1,
      "y": 0,
      "z": 7,
      "name": "Wood_Softwood_Planks"
    },
    {
      "x": 1,
      "y": 1,
      "z": 7,
      "name": "K2_Slot_Station_Heat"
    },
    {
      "x": 1,
      "y": 4,
      "z": 7,
      "name": "Wood_Hardwood_Planks_Half",
      "rotation": 8
    },
    {
      "x": 1,
      "y": 0,
      "z": 8,
      "name": "Wood_Softwood_Planks"
    },
    {
      "x": 1,
      "y": 4,
      "z": 8,
      "name": "Wood_Hardwood_Planks_Half",
      "rotation": 8
    },
    {
      "x": 1,
      "y": 0,
      "z": 9,
      "name": "Wood_Softwood_Planks"
    },
    {
      "x": 1,
      "y": 1,
      "z": 9,
      "name": "K2_Slot_Station_Wash"
    },
    {
      "x": 1,
      "y": 4,
      "z": 9,
      "name": "Wood_Hardwood_Planks_Half",
      "rotation": 8
    },
    {
      "x": 1,
      "y": 0,
      "z": 10,
      "name": "Wood_Softwood_Planks"
    },
    {
      "x": 1,
      "y": 4,
      "z": 10,
      "name": "Wood_Hardwood_Planks_Half",
      "rotation": 8
    },
    {
      "x": 1,
      "y": 0,
      "z": 11,
      "name": "Wood_Softwood_Planks"
    },
    {
      "x": 1,
      "y": 1,
      "z": 11,
      "name": "Rock_Stone_Brick_Smooth"
    },
    {
      "x": 1,
      "y": 2,
      "z": 11,
      "name": "Rock_Stone_Brick_Smooth"
    },
    {
      "x": 1,
      "y": 3,
      "z": 11,
      "name": "Rock_Stone_Brick_Smooth"
    },
    {
      "x": 1,
      "y": 4,
      "z": 11,
      "name": "Rock_Stone_Brick_Smooth"
    },
    {
      "x": 1,
      "y": 0,
      "z": 12,
      "name": "Soil_Grass"
    },
    {
      "x": 1,
      "y": 0,
      "z": 13,
      "name": "Soil_Grass"
    },
    {
      "x": 1,
      "y": 0,
      "z": 14,
      "name": "Soil_Grass"
    },
    {
      "x": 1,
      "y": 0,
      "z": 15,
      "name": "Soil_Grass"
    },
    {
      "x": 1,
      "y": 0,
      "z": 16,
      "name": "Soil_Grass"
    },
    {
      "x": 2,
      "y": 0,
      "z": -15,
      "name": "Soil_Grass"
    },
    {
      "x": 2,
      "y": 0,
      "z": -14,
      "name": "Soil_Grass"
    },
    {
      "x": 2,
      "y": 0,
      "z": -13,
      "name": "Soil_Grass"
    },
    {
      "x": 2,
      "y": 0,
      "z": -12,
      "name": "Soil_Grass"
    },
    {
      "x": 2,
      "y": 0,
      "z": -11,
      "name": "Soil_Grass"
    },
    {
      "x": 2,
      "y": 0,
      "z": -10,
      "name": "Soil_Grass"
    },
    {
      "x": 2,
      "y": 0,
      "z": -9,
      "name": "Soil_Grass"
    },
    {
      "x": 2,
      "y": 0,
      "z": -8,
      "name": "Soil_Grass"
    },
    {
      "x": 2,
      "y": 0,
      "z": -7,
      "name": "Soil_Grass"
    },
    {
      "x": 2,
      "y": 0,
      "z": -6,
      "name": "K2_Slot_Queue_2"
    },
    {
      "x": 2,
      "y": 0,
      "z": -5,
      "name": "Soil_Grass"
    },
    {
      "x": 2,
      "y": 0,
      "z": -4,
      "name": "Wood_Softwood_Planks"
    },
    {
      "x": 2,
      "y": 1,
      "z": -4,
      "name": "Rock_Stone_Brick_Smooth"
    },
    {
      "x": 2,
      "y": 3,
      "z": -4,
      "name": "Rock_Stone_Brick_Smooth"
    },
    {
      "x": 2,
      "y": 4,
      "z": -4,
      "name": "Rock_Stone_Brick_Smooth"
    },
    {
      "x": 2,
      "y": 0,
      "z": -3,
      "name": "Wood_Softwood_Planks"
    },
    {
      "x": 2,
      "y": 4,
      "z": -3,
      "name": "Wood_Hardwood_Planks_Half",
      "rotation": 8
    },
    {
      "x": 2,
      "y": 0,
      "z": -2,
      "name": "Wood_Softwood_Planks"
    },
    {
      "x": 2,
      "y": 4,
      "z": -2,
      "name": "Wood_Hardwood_Planks_Half",
      "rotation": 8
    },
    {
      "x": 2,
      "y": 0,
      "z": -1,
      "name": "Wood_Softwood_Planks"
    },
    {
      "x": 2,
      "y": 4,
      "z": -1,
      "name": "Wood_Hardwood_Planks_Half",
      "rotation": 8
    },
    {
      "x": 2,
      "y": 0,
      "z": 0,
      "name": "Wood_Softwood_Planks"
    },
    {
      "x": 2,
      "y": 4,
      "z": 0,
      "name": "Wood_Hardwood_Planks_Half",
      "rotation": 8
    },
    {
      "x": 2,
      "y": 0,
      "z": 1,
      "name": "Wood_Softwood_Planks"
    },
    {
      "x": 2,
      "y": 4,
      "z": 1,
      "name": "Wood_Hardwood_Planks_Half",
      "rotation": 8
    },
    {
      "x": 2,
      "y": 0,
      "z": 2,
      "name": "Wood_Softwood_Planks"
    },
    {
      "x": 2,
      "y": 4,
      "z": 2,
      "name": "Wood_Hardwood_Planks_Half",
      "rotation": 8
    },
    {
      "x": 2,
      "y": 0,
      "z": 3,
      "name": "Wood_Softwood_Planks"
    },
    {
      "x": 2,
      "y": 4,
      "z": 3,
      "name": "Wood_Hardwood_Planks_Half",
      "rotation": 8
    },
    {
      "x": 2,
      "y": 0,
      "z": 4,
      "name": "Wood_Softwood_Planks"
    },
    {
      "x": 2,
      "y": 3,
      "z": 4,
      "name": "Rock_Stone_Brick_Smooth"
    },
    {
      "x": 2,
      "y": 4,
      "z": 4,
      "name": "Rock_Stone_Brick_Smooth"
    },
    {
      "x": 2,
      "y": 0,
      "z": 5,
      "name": "Wood_Softwood_Planks"
    },
    {
      "x": 2,
      "y": 4,
      "z": 5,
      "name": "Wood_Hardwood_Planks_Half",
      "rotation": 8
    },
    {
      "x": 2,
      "y": 0,
      "z": 6,
      "name": "Wood_Softwood_Planks"
    },
    {
      "x": 2,
      "y": 4,
      "z": 6,
      "name": "Wood_Hardwood_Planks_Half",
      "rotation": 8
    },
    {
      "x": 2,
      "y": 0,
      "z": 7,
      "name": "Wood_Softwood_Planks"
    },
    {
      "x": 2,
      "y": 3,
      "z": 7,
      "name": "Wood_Torch_Wall",
      "rotation": 3
    },
    {
      "x": 2,
      "y": 4,
      "z": 7,
      "name": "Wood_Hardwood_Planks_Half",
      "rotation": 8
    },
    {
      "x": 2,
      "y": 0,
      "z": 8,
      "name": "Wood_Softwood_Planks"
    },
    {
      "x": 2,
      "y": 4,
      "z": 8,
      "name": "Wood_Hardwood_Planks_Half",
      "rotation": 8
    },
    {
      "x": 2,
      "y": 0,
      "z": 9,
      "name": "Wood_Softwood_Planks"
    },
    {
      "x": 2,
      "y": 4,
      "z": 9,
      "name": "Wood_Hardwood_Planks_Half",
      "rotation": 8
    },
    {
      "x": 2,
      "y": 0,
      "z": 10,
      "name": "Wood_Softwood_Planks"
    },
    {
      "x": 2,
      "y": 4,
      "z": 10,
      "name": "Wood_Hardwood_Planks_Half",
      "rotation": 8
    },
    {
      "x": 2,
      "y": 0,
      "z": 11,
      "name": "Wood_Softwood_Planks"
    },
    {
      "x": 2,
      "y": 1,
      "z": 11,
      "name": "Rock_Stone_Brick_Smooth"
    },
    {
      "x": 2,
      "y": 2,
      "z": 11,
      "name": "Rock_Stone_Brick_Smooth"
    },
    {
      "x": 2,
      "y": 3,
      "z": 11,
      "name": "Rock_Stone_Brick_Smooth"
    },
    {
      "x": 2,
      "y": 4,
      "z": 11,
      "name": "Rock_Stone_Brick_Smooth"
    },
    {
      "x": 2,
      "y": 0,
      "z": 12,
      "name": "Soil_Grass"
    },
    {
      "x": 2,
      "y": 0,
      "z": 13,
      "name": "Soil_Grass"
    },
    {
      "x": 2,
      "y": 0,
      "z": 14,
      "name": "Soil_Grass"
    },
    {
      "x": 2,
      "y": 0,
      "z": 15,
      "name": "Soil_Grass"
    },
    {
      "x": 2,
      "y": 0,
      "z": 16,
      "name": "Soil_Grass"
    },
    {
      "x": 3,
      "y": 0,
      "z": -15,
      "name": "Soil_Grass"
    },
    {
      "x": 3,
      "y": 0,
      "z": -14,
      "name": "Soil_Grass"
    },
    {
      "x": 3,
      "y": 0,
      "z": -13,
      "name": "Soil_Grass"
    },
    {
      "x": 3,
      "y": 0,
      "z": -12,
      "name": "Soil_Grass"
    },
    {
      "x": 3,
      "y": 0,
      "z": -11,
      "name": "Soil_Grass"
    },
    {
      "x": 3,
      "y": 0,
      "z": -10,
      "name": "Soil_Grass"
    },
    {
      "x": 3,
      "y": 0,
      "z": -9,
      "name": "Soil_Grass"
    },
    {
      "x": 3,
      "y": 0,
      "z": -8,
      "name": "Soil_Grass"
    },
    {
      "x": 3,
      "y": 0,
      "z": -7,
      "name": "Soil_Grass"
    },
    {
      "x": 3,
      "y": 0,
      "z": -6,
      "name": "Soil_Grass"
    },
    {
      "x": 3,
      "y": 0,
      "z": -5,
      "name": "Soil_Grass"
    },
    {
      "x": 3,
      "y": 0,
      "z": -4,
      "name": "Wood_Softwood_Planks"
    },
    {
      "x": 3,
      "y": 1,
      "z": -4,
      "name": "Rock_Stone_Brick_Decorative"
    },
    {
      "x": 3,
      "y": 2,
      "z": -4,
      "name": "Rock_Stone_Brick_Smooth"
    },
    {
      "x": 3,
      "y": 3,
      "z": -4,
      "name": "Rock_Stone_Brick_Smooth"
    },
    {
      "x": 3,
      "y": 4,
      "z": -4,
      "name": "Rock_Stone_Brick_Smooth"
    },
    {
      "x": 3,
      "y": 0,
      "z": -3,
      "name": "Wood_Softwood_Planks"
    },
    {
      "x": 3,
      "y": 3,
      "z": -3,
      "name": "Wood_Torch_Wall"
    },
    {
      "x": 3,
      "y": 4,
      "z": -3,
      "name": "Wood_Hardwood_Planks_Half",
      "rotation": 8
    },
    {
      "x": 3,
      "y": 0,
      "z": -2,
      "name": "Wood_Softwood_Planks"
    },
    {
      "x": 3,
      "y": 4,
      "z": -2,
      "name": "Wood_Hardwood_Planks_Half",
      "rotation": 8
    },
    {
      "x": 3,
      "y": 0,
      "z": -1,
      "name": "Wood_Softwood_Planks"
    },
    {
      "x": 3,
      "y": 4,
      "z": -1,
      "name": "Wood_Hardwood_Planks_Half",
      "rotation": 8
    },
    {
      "x": 3,
      "y": 0,
      "z": 0,
      "name": "Wood_Softwood_Planks"
    },
    {
      "x": 3,
      "y": 4,
      "z": 0,
      "name": "Wood_Hardwood_Planks_Half",
      "rotation": 8
    },
    {
      "x": 3,
      "y": 0,
      "z": 1,
      "name": "Wood_Softwood_Planks"
    },
    {
      "x": 3,
      "y": 1,
      "z": 1,
      "name": "K2_Slot_Chair",
      "rotation": 1
    },
    {
      "x": 3,
      "y": 4,
      "z": 1,
      "name": "Wood_Hardwood_Planks_Half",
      "rotation": 8
    },
    {
      "x": 3,
      "y": 0,
      "z": 2,
      "name": "Wood_Softwood_Planks"
    },
    {
      "x": 3,
      "y": 4,
      "z": 2,
      "name": "Wood_Hardwood_Planks_Half",
      "rotation": 8
    },
    {
      "x": 3,
      "y": 0,
      "z": 3,
      "name": "Wood_Softwood_Planks"
    },
    {
      "x": 3,
      "y": 3,
      "z": 3,
      "name": "Wood_Torch_Wall",
      "rotation": 2
    },
    {
      "x": 3,
      "y": 4,
      "z": 3,
      "name": "Wood_Hardwood_Planks_Half",
      "rotation": 8
    },
    {
      "x": 3,
      "y": 0,
      "z": 4,
      "name": "Wood_Softwood_Planks"
    },
    {
      "x": 3,
      "y": 1,
      "z": 4,
      "name": "Rock_Stone_Brick_Decorative"
    },
    {
      "x": 3,
      "y": 2,
      "z": 4,
      "name": "Rock_Stone_Brick_Smooth"
    },
    {
      "x": 3,
      "y": 3,
      "z": 4,
      "name": "Rock_Stone_Brick_Smooth"
    },
    {
      "x": 3,
      "y": 4,
      "z": 4,
      "name": "Rock_Stone_Brick_Smooth"
    },
    {
      "x": 3,
      "y": 0,
      "z": 5,
      "name": "Wood_Softwood_Planks"
    },
    {
      "x": 3,
      "y": 1,
      "z": 5,
      "name": "Rock_Stone_Brick_Smooth"
    },
    {
      "x": 3,
      "y": 2,
      "z": 5,
      "name": "Rock_Stone_Brick_Smooth"
    },
    {
      "x": 3,
      "y": 3,
      "z": 5,
      "name": "Rock_Stone_Brick_Smooth"
    },
    {
      "x": 3,
      "y": 4,
      "z": 5,
      "name": "Rock_Stone_Brick_Smooth"
    },
    {
      "x": 3,
      "y": 0,
      "z": 6,
      "name": "Wood_Softwood_Planks"
    },
    {
      "x": 3,
      "y": 1,
      "z": 6,
      "name": "Rock_Stone_Brick_Smooth"
    },
    {
      "x": 3,
      "y": 2,
      "z": 6,
      "name": "Rock_Stone_Brick_Smooth"
    },
    {
      "x": 3,
      "y": 3,
      "z": 6,
      "name": "Rock_Stone_Brick_Smooth"
    },
    {
      "x": 3,
      "y": 4,
      "z": 6,
      "name": "Rock_Stone_Brick_Smooth"
    },
    {
      "x": 3,
      "y": 0,
      "z": 7,
      "name": "Wood_Softwood_Planks"
    },
    {
      "x": 3,
      "y": 1,
      "z": 7,
      "name": "Rock_Stone_Brick_Smooth"
    },
    {
      "x": 3,
      "y": 2,
      "z": 7,
      "name": "Rock_Stone_Brick_Smooth"
    },
    {
      "x": 3,
      "y": 3,
      "z": 7,
      "name": "Rock_Stone_Brick_Smooth"
    },
    {
      "x": 3,
      "y": 4,
      "z": 7,
      "name": "Rock_Stone_Brick_Smooth"
    },
    {
      "x": 3,
      "y": 0,
      "z": 8,
      "name": "Wood_Softwood_Planks"
    },
    {
      "x": 3,
      "y": 1,
      "z": 8,
      "name": "Rock_Stone_Brick_Smooth"
    },
    {
      "x": 3,
      "y": 2,
      "z": 8,
      "name": "Rock_Stone_Brick_Smooth"
    },
    {
      "x": 3,
      "y": 3,
      "z": 8,
      "name": "Rock_Stone_Brick_Smooth"
    },
    {
      "x": 3,
      "y": 4,
      "z": 8,
      "name": "Rock_Stone_Brick_Smooth"
    },
    {
      "x": 3,
      "y": 0,
      "z": 9,
      "name": "Wood_Softwood_Planks"
    },
    {
      "x": 3,
      "y": 1,
      "z": 9,
      "name": "Rock_Stone_Brick_Smooth"
    },
    {
      "x": 3,
      "y": 2,
      "z": 9,
      "name": "Rock_Stone_Brick_Smooth"
    },
    {
      "x": 3,
      "y": 3,
      "z": 9,
      "name": "Rock_Stone_Brick_Smooth"
    },
    {
      "x": 3,
      "y": 4,
      "z": 9,
      "name": "Rock_Stone_Brick_Smooth"
    },
    {
      "x": 3,
      "y": 0,
      "z": 10,
      "name": "Rock_Stone_Brick_Smooth"
    },
    {
      "x": 3,
      "y": 1,
      "z": 10,
      "name": "Rock_Stone_Brick_Smooth"
    },
    {
      "x": 3,
      "y": 2,
      "z": 10,
      "name": "Rock_Stone_Brick_Smooth"
    },
    {
      "x": 3,
      "y": 3,
      "z": 10,
      "name": "Rock_Stone_Brick_Smooth"
    },
    {
      "x": 3,
      "y": 4,
      "z": 10,
      "name": "Rock_Stone_Brick_Smooth"
    },
    {
      "x": 3,
      "y": 0,
      "z": 11,
      "name": "Wood_Softwood_Planks"
    },
    {
      "x": 3,
      "y": 1,
      "z": 11,
      "name": "Rock_Stone_Brick_Smooth"
    },
    {
      "x": 3,
      "y": 2,
      "z": 11,
      "name": "Rock_Stone_Brick_Smooth"
    },
    {
      "x": 3,
      "y": 3,
      "z": 11,
      "name": "Rock_Stone_Brick_Smooth"
    },
    {
      "x": 3,
      "y": 4,
      "z": 11,
      "name": "Rock_Stone_Brick_Smooth"
    },
    {
      "x": 3,
      "y": 0,
      "z": 12,
      "name": "Soil_Grass"
    },
    {
      "x": 3,
      "y": 0,
      "z": 13,
      "name": "Soil_Grass"
    },
    {
      "x": 3,
      "y": 0,
      "z": 14,
      "name": "Soil_Grass"
    },
    {
      "x": 3,
      "y": 0,
      "z": 15,
      "name": "Soil_Grass"
    },
    {
      "x": 3,
      "y": 0,
      "z": 16,
      "name": "Soil_Grass"
    },
    {
      "x": 4,
      "y": 0,
      "z": -15,
      "name": "Soil_Grass"
    },
    {
      "x": 4,
      "y": 0,
      "z": -14,
      "name": "Soil_Grass"
    },
    {
      "x": 4,
      "y": 0,
      "z": -13,
      "name": "Soil_Grass"
    },
    {
      "x": 4,
      "y": 0,
      "z": -12,
      "name": "Soil_Grass"
    },
    {
      "x": 4,
      "y": 0,
      "z": -11,
      "name": "Soil_Grass"
    },
    {
      "x": 4,
      "y": 0,
      "z": -10,
      "name": "Soil_Grass"
    },
    {
      "x": 4,
      "y": 0,
      "z": -9,
      "name": "Soil_Grass"
    },
    {
      "x": 4,
      "y": 0,
      "z": -8,
      "name": "Soil_Grass"
    },
    {
      "x": 4,
      "y": 0,
      "z": -7,
      "name": "Soil_Grass"
    },
    {
      "x": 4,
      "y": 0,
      "z": -6,
      "name": "K2_Slot_Queue_3"
    },
    {
      "x": 4,
      "y": 0,
      "z": -5,
      "name": "Soil_Grass"
    },
    {
      "x": 4,
      "y": 0,
      "z": -4,
      "name": "Wood_Softwood_Planks"
    },
    {
      "x": 4,
      "y": 1,
      "z": -4,
      "name": "Rock_Stone_Brick_Smooth"
    },
    {
      "x": 4,
      "y": 3,
      "z": -4,
      "name": "Rock_Stone_Brick_Smooth"
    },
    {
      "x": 4,
      "y": 4,
      "z": -4,
      "name": "Rock_Stone_Brick_Smooth"
    },
    {
      "x": 4,
      "y": 0,
      "z": -3,
      "name": "Wood_Softwood_Planks"
    },
    {
      "x": 4,
      "y": 4,
      "z": -3,
      "name": "Wood_Hardwood_Planks_Half",
      "rotation": 8
    },
    {
      "x": 4,
      "y": 0,
      "z": -2,
      "name": "Wood_Softwood_Planks"
    },
    {
      "x": 4,
      "y": 4,
      "z": -2,
      "name": "Wood_Hardwood_Planks_Half",
      "rotation": 8
    },
    {
      "x": 4,
      "y": 0,
      "z": -1,
      "name": "Wood_Softwood_Planks"
    },
    {
      "x": 4,
      "y": 1,
      "z": -1,
      "name": "K2_Slot_Chair"
    },
    {
      "x": 4,
      "y": 4,
      "z": -1,
      "name": "Wood_Hardwood_Planks_Half",
      "rotation": 8
    },
    {
      "x": 4,
      "y": 0,
      "z": 0,
      "name": "Wood_Softwood_Planks"
    },
    {
      "x": 4,
      "y": 4,
      "z": 0,
      "name": "Wood_Hardwood_Planks_Half",
      "rotation": 8
    },
    {
      "x": 4,
      "y": 0,
      "z": 1,
      "name": "Wood_Softwood_Planks"
    },
    {
      "x": 4,
      "y": 4,
      "z": 1,
      "name": "Wood_Hardwood_Planks_Half",
      "rotation": 8
    },
    {
      "x": 4,
      "y": 0,
      "z": 2,
      "name": "Wood_Softwood_Planks"
    },
    {
      "x": 4,
      "y": 4,
      "z": 2,
      "name": "Wood_Hardwood_Planks_Half",
      "rotation": 8
    },
    {
      "x": 4,
      "y": 0,
      "z": 3,
      "name": "Wood_Softwood_Planks"
    },
    {
      "x": 4,
      "y": 4,
      "z": 3,
      "name": "Wood_Hardwood_Planks_Half",
      "rotation": 8
    },
    {
      "x": 4,
      "y": 0,
      "z": 4,
      "name": "Wood_Softwood_Planks"
    },
    {
      "x": 4,
      "y": 1,
      "z": 4,
      "name": "Rock_Stone_Brick_Smooth"
    },
    {
      "x": 4,
      "y": 2,
      "z": 4,
      "name": "Rock_Stone_Brick_Smooth"
    },
    {
      "x": 4,
      "y": 3,
      "z": 4,
      "name": "Rock_Stone_Brick_Smooth"
    },
    {
      "x": 4,
      "y": 4,
      "z": 4,
      "name": "Rock_Stone_Brick_Smooth"
    },
    {
      "x": 4,
      "y": 0,
      "z": 5,
      "name": "Soil_Grass"
    },
    {
      "x": 4,
      "y": 0,
      "z": 6,
      "name": "Soil_Grass"
    },
    {
      "x": 4,
      "y": 0,
      "z": 7,
      "name": "Soil_Grass"
    },
    {
      "x": 4,
      "y": 0,
      "z": 8,
      "name": "Soil_Grass"
    },
    {
      "x": 4,
      "y": 0,
      "z": 9,
      "name": "Soil_Grass"
    },
    {
      "x": 4,
      "y": 0,
      "z": 10,
      "name": "Soil_Grass"
    },
    {
      "x": 4,
      "y": 0,
      "z": 11,
      "name": "Soil_Grass"
    },
    {
      "x": 4,
      "y": 0,
      "z": 12,
      "name": "Soil_Grass"
    },
    {
      "x": 4,
      "y": 0,
      "z": 13,
      "name": "Soil_Grass"
    },
    {
      "x": 4,
      "y": 0,
      "z": 14,
      "name": "Soil_Grass"
    },
    {
      "x": 4,
      "y": 0,
      "z": 15,
      "name": "Soil_Grass"
    },
    {
      "x": 4,
      "y": 0,
      "z": 16,
      "name": "Soil_Grass"
    },
    {
      "x": 5,
      "y": 0,
      "z": -15,
      "name": "Soil_Grass"
    },
    {
      "x": 5,
      "y": 0,
      "z": -14,
      "name": "Soil_Grass"
    },
    {
      "x": 5,
      "y": 0,
      "z": -13,
      "name": "Soil_Grass"
    },
    {
      "x": 5,
      "y": 0,
      "z": -12,
      "name": "Soil_Grass"
    },
    {
      "x": 5,
      "y": 0,
      "z": -11,
      "name": "Soil_Grass"
    },
    {
      "x": 5,
      "y": 0,
      "z": -10,
      "name": "Soil_Grass"
    },
    {
      "x": 5,
      "y": 0,
      "z": -9,
      "name": "Soil_Grass"
    },
    {
      "x": 5,
      "y": 0,
      "z": -8,
      "name": "Soil_Grass"
    },
    {
      "x": 5,
      "y": 0,
      "z": -7,
      "name": "Soil_Grass"
    },
    {
      "x": 5,
      "y": 0,
      "z": -6,
      "name": "Soil_Grass"
    },
    {
      "x": 5,
      "y": 0,
      "z": -5,
      "name": "Soil_Grass"
    },
    {
      "x": 5,
      "y": 0,
      "z": -4,
      "name": "Wood_Softwood_Planks"
    },
    {
      "x": 5,
      "y": 1,
      "z": -4,
      "name": "Rock_Stone_Brick_Smooth"
    },
    {
      "x": 5,
      "y": 3,
      "z": -4,
      "name": "Rock_Stone_Brick_Smooth"
    },
    {
      "x": 5,
      "y": 4,
      "z": -4,
      "name": "Rock_Stone_Brick_Smooth"
    },
    {
      "x": 5,
      "y": 0,
      "z": -3,
      "name": "Wood_Softwood_Planks"
    },
    {
      "x": 5,
      "y": 4,
      "z": -3,
      "name": "Wood_Hardwood_Planks_Half",
      "rotation": 8
    },
    {
      "x": 5,
      "y": 0,
      "z": -2,
      "name": "Wood_Softwood_Planks"
    },
    {
      "x": 5,
      "y": 4,
      "z": -2,
      "name": "Wood_Hardwood_Planks_Half",
      "rotation": 8
    },
    {
      "x": 5,
      "y": 0,
      "z": -1,
      "name": "Wood_Softwood_Planks"
    },
    {
      "x": 5,
      "y": 4,
      "z": -1,
      "name": "Wood_Hardwood_Planks_Half",
      "rotation": 8
    },
    {
      "x": 5,
      "y": 0,
      "z": 0,
      "name": "Wood_Softwood_Planks"
    },
    {
      "x": 5,
      "y": 4,
      "z": 0,
      "name": "Wood_Hardwood_Planks_Half",
      "rotation": 8
    },
    {
      "x": 5,
      "y": 0,
      "z": 1,
      "name": "Wood_Softwood_Planks"
    },
    {
      "x": 5,
      "y": 4,
      "z": 1,
      "name": "Wood_Hardwood_Planks_Half",
      "rotation": 8
    },
    {
      "x": 5,
      "y": 0,
      "z": 2,
      "name": "Wood_Softwood_Planks"
    },
    {
      "x": 5,
      "y": 1,
      "z": 2,
      "name": "K2_Slot_Chair",
      "rotation": 2
    },
    {
      "x": 5,
      "y": 4,
      "z": 2,
      "name": "Wood_Hardwood_Planks_Half",
      "rotation": 8
    },
    {
      "x": 5,
      "y": 0,
      "z": 3,
      "name": "Wood_Softwood_Planks"
    },
    {
      "x": 5,
      "y": 4,
      "z": 3,
      "name": "Wood_Hardwood_Planks_Half",
      "rotation": 8
    },
    {
      "x": 5,
      "y": 0,
      "z": 4,
      "name": "Wood_Softwood_Planks"
    },
    {
      "x": 5,
      "y": 1,
      "z": 4,
      "name": "Rock_Stone_Brick_Smooth"
    },
    {
      "x": 5,
      "y": 2,
      "z": 4,
      "name": "Rock_Stone_Brick_Smooth"
    },
    {
      "x": 5,
      "y": 3,
      "z": 4,
      "name": "Rock_Stone_Brick_Smooth"
    },
    {
      "x": 5,
      "y": 4,
      "z": 4,
      "name": "Rock_Stone_Brick_Smooth"
    },
    {
      "x": 5,
      "y": 0,
      "z": 5,
      "name": "Soil_Grass"
    },
    {
      "x": 5,
      "y": 0,
      "z": 6,
      "name": "Soil_Grass"
    },
    {
      "x": 5,
      "y": 0,
      "z": 7,
      "name": "Soil_Grass"
    },
    {
      "x": 5,
      "y": 0,
      "z": 8,
      "name": "Soil_Grass"
    },
    {
      "x": 5,
      "y": 0,
      "z": 9,
      "name": "Soil_Grass"
    },
    {
      "x": 5,
      "y": 0,
      "z": 10,
      "name": "Soil_Grass"
    },
    {
      "x": 5,
      "y": 0,
      "z": 11,
      "name": "Soil_Grass"
    },
    {
      "x": 5,
      "y": 0,
      "z": 12,
      "name": "Soil_Grass"
    },
    {
      "x": 5,
      "y": 0,
      "z": 13,
      "name": "Soil_Grass"
    },
    {
      "x": 5,
      "y": 0,
      "z": 14,
      "name": "Soil_Grass"
    },
    {
      "x": 5,
      "y": 0,
      "z": 15,
      "name": "Soil_Grass"
    },
    {
      "x": 5,
      "y": 0,
      "z": 16,
      "name": "Soil_Grass"
    },
    {
      "x": 6,
      "y": 0,
      "z": -15,
      "name": "Soil_Grass"
    },
    {
      "x": 6,
      "y": 0,
      "z": -14,
      "name": "Soil_Grass"
    },
    {
      "x": 6,
      "y": 0,
      "z": -13,
      "name": "Soil_Grass"
    },
    {
      "x": 6,
      "y": 0,
      "z": -12,
      "name": "Soil_Grass"
    },
    {
      "x": 6,
      "y": 0,
      "z": -11,
      "name": "Soil_Grass"
    },
    {
      "x": 6,
      "y": 0,
      "z": -10,
      "name": "Soil_Grass"
    },
    {
      "x": 6,
      "y": 0,
      "z": -9,
      "name": "Soil_Grass"
    },
    {
      "x": 6,
      "y": 0,
      "z": -8,
      "name": "Soil_Grass"
    },
    {
      "x": 6,
      "y": 0,
      "z": -7,
      "name": "Soil_Grass"
    },
    {
      "x": 6,
      "y": 0,
      "z": -6,
      "name": "K2_Slot_Queue_4"
    },
    {
      "x": 6,
      "y": 0,
      "z": -5,
      "name": "Soil_Grass"
    },
    {
      "x": 6,
      "y": 0,
      "z": -4,
      "name": "Wood_Softwood_Planks"
    },
    {
      "x": 6,
      "y": 1,
      "z": -4,
      "name": "Rock_Stone_Brick_Smooth"
    },
    {
      "x": 6,
      "y": 3,
      "z": -4,
      "name": "Rock_Stone_Brick_Smooth"
    },
    {
      "x": 6,
      "y": 4,
      "z": -4,
      "name": "Rock_Stone_Brick_Smooth"
    },
    {
      "x": 6,
      "y": 0,
      "z": -3,
      "name": "Wood_Softwood_Planks"
    },
    {
      "x": 6,
      "y": 4,
      "z": -3,
      "name": "Wood_Hardwood_Planks_Half",
      "rotation": 8
    },
    {
      "x": 6,
      "y": 0,
      "z": -2,
      "name": "Wood_Softwood_Planks"
    },
    {
      "x": 6,
      "y": 4,
      "z": -2,
      "name": "Wood_Hardwood_Planks_Half",
      "rotation": 8
    },
    {
      "x": 6,
      "y": 0,
      "z": -1,
      "name": "Wood_Softwood_Planks"
    },
    {
      "x": 6,
      "y": 4,
      "z": -1,
      "name": "Wood_Hardwood_Planks_Half",
      "rotation": 8
    },
    {
      "x": 6,
      "y": 0,
      "z": 0,
      "name": "Wood_Softwood_Planks"
    },
    {
      "x": 6,
      "y": 1,
      "z": 0,
      "name": "K2_Slot_Chair",
      "rotation": 3
    },
    {
      "x": 6,
      "y": 4,
      "z": 0,
      "name": "Wood_Hardwood_Planks_Half",
      "rotation": 8
    },
    {
      "x": 6,
      "y": 0,
      "z": 1,
      "name": "Wood_Softwood_Planks"
    },
    {
      "x": 6,
      "y": 4,
      "z": 1,
      "name": "Wood_Hardwood_Planks_Half",
      "rotation": 8
    },
    {
      "x": 6,
      "y": 0,
      "z": 2,
      "name": "Wood_Softwood_Planks"
    },
    {
      "x": 6,
      "y": 4,
      "z": 2,
      "name": "Wood_Hardwood_Planks_Half",
      "rotation": 8
    },
    {
      "x": 6,
      "y": 0,
      "z": 3,
      "name": "Wood_Softwood_Planks"
    },
    {
      "x": 6,
      "y": 4,
      "z": 3,
      "name": "Wood_Hardwood_Planks_Half",
      "rotation": 8
    },
    {
      "x": 6,
      "y": 0,
      "z": 4,
      "name": "Wood_Softwood_Planks"
    },
    {
      "x": 6,
      "y": 1,
      "z": 4,
      "name": "Rock_Stone_Brick_Smooth"
    },
    {
      "x": 6,
      "y": 2,
      "z": 4,
      "name": "Rock_Stone_Brick_Smooth"
    },
    {
      "x": 6,
      "y": 3,
      "z": 4,
      "name": "Rock_Stone_Brick_Smooth"
    },
    {
      "x": 6,
      "y": 4,
      "z": 4,
      "name": "Rock_Stone_Brick_Smooth"
    },
    {
      "x": 6,
      "y": 0,
      "z": 5,
      "name": "Soil_Grass"
    },
    {
      "x": 6,
      "y": 0,
      "z": 6,
      "name": "Soil_Grass"
    },
    {
      "x": 6,
      "y": 0,
      "z": 7,
      "name": "Soil_Grass"
    },
    {
      "x": 6,
      "y": 0,
      "z": 8,
      "name": "Soil_Grass"
    },
    {
      "x": 6,
      "y": 0,
      "z": 9,
      "name": "Soil_Grass"
    },
    {
      "x": 6,
      "y": 0,
      "z": 10,
      "name": "Soil_Grass"
    },
    {
      "x": 6,
      "y": 0,
      "z": 11,
      "name": "Soil_Grass"
    },
    {
      "x": 6,
      "y": 0,
      "z": 12,
      "name": "Soil_Grass"
    },
    {
      "x": 6,
      "y": 0,
      "z": 13,
      "name": "Soil_Grass"
    },
    {
      "x": 6,
      "y": 0,
      "z": 14,
      "name": "Soil_Grass"
    },
    {
      "x": 6,
      "y": 0,
      "z": 15,
      "name": "Soil_Grass"
    },
    {
      "x": 6,
      "y": 0,
      "z": 16,
      "name": "Soil_Grass"
    },
    {
      "x": 7,
      "y": 0,
      "z": -15,
      "name": "Soil_Grass"
    },
    {
      "x": 7,
      "y": 0,
      "z": -14,
      "name": "Soil_Grass"
    },
    {
      "x": 7,
      "y": 0,
      "z": -13,
      "name": "Soil_Grass"
    },
    {
      "x": 7,
      "y": 0,
      "z": -12,
      "name": "Soil_Grass"
    },
    {
      "x": 7,
      "y": 0,
      "z": -11,
      "name": "Soil_Grass"
    },
    {
      "x": 7,
      "y": 0,
      "z": -10,
      "name": "Soil_Grass"
    },
    {
      "x": 7,
      "y": 0,
      "z": -9,
      "name": "Soil_Grass"
    },
    {
      "x": 7,
      "y": 0,
      "z": -8,
      "name": "Soil_Grass"
    },
    {
      "x": 7,
      "y": 0,
      "z": -7,
      "name": "Soil_Grass"
    },
    {
      "x": 7,
      "y": 0,
      "z": -6,
      "name": "Soil_Grass"
    },
    {
      "x": 7,
      "y": 0,
      "z": -5,
      "name": "Soil_Grass"
    },
    {
      "x": 7,
      "y": 0,
      "z": -4,
      "name": "Wood_Softwood_Planks"
    },
    {
      "x": 7,
      "y": 1,
      "z": -4,
      "name": "Rock_Stone_Brick_Decorative"
    },
    {
      "x": 7,
      "y": 2,
      "z": -4,
      "name": "Rock_Stone_Brick_Smooth"
    },
    {
      "x": 7,
      "y": 3,
      "z": -4,
      "name": "Rock_Stone_Brick_Smooth"
    },
    {
      "x": 7,
      "y": 4,
      "z": -4,
      "name": "Rock_Stone_Brick_Smooth"
    },
    {
      "x": 7,
      "y": 0,
      "z": -3,
      "name": "Wood_Softwood_Planks"
    },
    {
      "x": 7,
      "y": 1,
      "z": -3,
      "name": "Rock_Stone_Brick_Smooth"
    },
    {
      "x": 7,
      "y": 2,
      "z": -3,
      "name": "Rock_Stone_Brick_Smooth"
    },
    {
      "x": 7,
      "y": 3,
      "z": -3,
      "name": "Rock_Stone_Brick_Smooth"
    },
    {
      "x": 7,
      "y": 4,
      "z": -3,
      "name": "Rock_Stone_Brick_Smooth"
    },
    {
      "x": 7,
      "y": 0,
      "z": -2,
      "name": "Wood_Softwood_Planks"
    },
    {
      "x": 7,
      "y": 1,
      "z": -2,
      "name": "Rock_Stone_Brick_Smooth"
    },
    {
      "x": 7,
      "y": 2,
      "z": -2,
      "name": "Rock_Stone_Brick_Smooth"
    },
    {
      "x": 7,
      "y": 3,
      "z": -2,
      "name": "Rock_Stone_Brick_Smooth"
    },
    {
      "x": 7,
      "y": 4,
      "z": -2,
      "name": "Rock_Stone_Brick_Smooth"
    },
    {
      "x": 7,
      "y": 0,
      "z": -1,
      "name": "Wood_Softwood_Planks"
    },
    {
      "x": 7,
      "y": 1,
      "z": -1,
      "name": "Rock_Stone_Brick_Smooth"
    },
    {
      "x": 7,
      "y": 2,
      "z": -1,
      "name": "Rock_Stone_Brick_Smooth"
    },
    {
      "x": 7,
      "y": 3,
      "z": -1,
      "name": "Rock_Stone_Brick_Smooth"
    },
    {
      "x": 7,
      "y": 4,
      "z": -1,
      "name": "Rock_Stone_Brick_Smooth"
    },
    {
      "x": 7,
      "y": 0,
      "z": 0,
      "name": "Wood_Softwood_Planks"
    },
    {
      "x": 7,
      "y": 1,
      "z": 0,
      "name": "Rock_Stone_Brick_Decorative"
    },
    {
      "x": 7,
      "y": 2,
      "z": 0,
      "name": "Rock_Stone_Brick_Smooth"
    },
    {
      "x": 7,
      "y": 3,
      "z": 0,
      "name": "Rock_Stone_Brick_Smooth"
    },
    {
      "x": 7,
      "y": 4,
      "z": 0,
      "name": "Rock_Stone_Brick_Smooth"
    },
    {
      "x": 7,
      "y": 0,
      "z": 1,
      "name": "Wood_Softwood_Planks"
    },
    {
      "x": 7,
      "y": 1,
      "z": 1,
      "name": "Rock_Stone_Brick_Smooth"
    },
    {
      "x": 7,
      "y": 2,
      "z": 1,
      "name": "Rock_Stone_Brick_Smooth"
    },
    {
      "x": 7,
      "y": 3,
      "z": 1,
      "name": "Rock_Stone_Brick_Smooth"
    },
    {
      "x": 7,
      "y": 4,
      "z": 1,
      "name": "Rock_Stone_Brick_Smooth"
    },
    {
      "x": 7,
      "y": 0,
      "z": 2,
      "name": "Wood_Softwood_Planks"
    },
    {
      "x": 7,
      "y": 1,
      "z": 2,
      "name": "Rock_Stone_Brick_Smooth"
    },
    {
      "x": 7,
      "y": 2,
      "z": 2,
      "name": "Rock_Stone_Brick_Smooth"
    },
    {
      "x": 7,
      "y": 3,
      "z": 2,
      "name": "Rock_Stone_Brick_Smooth"
    },
    {
      "x": 7,
      "y": 4,
      "z": 2,
      "name": "Rock_Stone_Brick_Smooth"
    },
    {
      "x": 7,
      "y": 0,
      "z": 3,
      "name": "Wood_Softwood_Planks"
    },
    {
      "x": 7,
      "y": 1,
      "z": 3,
      "name": "Rock_Stone_Brick_Smooth"
    },
    {
      "x": 7,
      "y": 2,
      "z": 3,
      "name": "Rock_Stone_Brick_Smooth"
    },
    {
      "x": 7,
      "y": 3,
      "z": 3,
      "name": "Rock_Stone_Brick_Smooth"
    },
    {
      "x": 7,
      "y": 4,
      "z": 3,
      "name": "Rock_Stone_Brick_Smooth"
    },
    {
      "x": 7,
      "y": 0,
      "z": 4,
      "name": "Wood_Softwood_Planks"
    },
    {
      "x": 7,
      "y": 1,
      "z": 4,
      "name": "Rock_Stone_Brick_Decorative"
    },
    {
      "x": 7,
      "y": 2,
      "z": 4,
      "name": "Rock_Stone_Brick_Smooth"
    },
    {
      "x": 7,
      "y": 3,
      "z": 4,
      "name": "Rock_Stone_Brick_Smooth"
    },
    {
      "x": 7,
      "y": 4,
      "z": 4,
      "name": "Rock_Stone_Brick_Smooth"
    },
    {
      "x": 7,
      "y": 0,
      "z": 5,
      "name": "Soil_Grass"
    },
    {
      "x": 7,
      "y": 0,
      "z": 6,
      "name": "Soil_Grass"
    },
    {
      "x": 7,
      "y": 0,
      "z": 7,
      "name": "Soil_Grass"
    },
    {
      "x": 7,
      "y": 0,
      "z": 8,
      "name": "Soil_Grass"
    },
    {
      "x": 7,
      "y": 0,
      "z": 9,
      "name": "Soil_Grass"
    },
    {
      "x": 7,
      "y": 0,
      "z": 10,
      "name": "Soil_Grass"
    },
    {
      "x": 7,
      "y": 0,
      "z": 11,
      "name": "Soil_Grass"
    },
    {
      "x": 7,
      "y": 0,
      "z": 12,
      "name": "Soil_Grass"
    },
    {
      "x": 7,
      "y": 0,
      "z": 13,
      "name": "Soil_Grass"
    },
    {
      "x": 7,
      "y": 0,
      "z": 14,
      "name": "Soil_Grass"
    },
    {
      "x": 7,
      "y": 0,
      "z": 15,
      "name": "Soil_Grass"
    },
    {
      "x": 7,
      "y": 0,
      "z": 16,
      "name": "Soil_Grass"
    },
    {
      "x": 8,
      "y": 0,
      "z": -15,
      "name": "Soil_Grass"
    },
    {
      "x": 8,
      "y": 0,
      "z": -14,
      "name": "Soil_Grass"
    },
    {
      "x": 8,
      "y": 0,
      "z": -13,
      "name": "Soil_Grass"
    },
    {
      "x": 8,
      "y": 0,
      "z": -12,
      "name": "Soil_Grass"
    },
    {
      "x": 8,
      "y": 0,
      "z": -11,
      "name": "Soil_Grass"
    },
    {
      "x": 8,
      "y": 0,
      "z": -10,
      "name": "Soil_Grass"
    },
    {
      "x": 8,
      "y": 0,
      "z": -9,
      "name": "Soil_Grass"
    },
    {
      "x": 8,
      "y": 0,
      "z": -8,
      "name": "Soil_Grass"
    },
    {
      "x": 8,
      "y": 0,
      "z": -7,
      "name": "Soil_Grass"
    },
    {
      "x": 8,
      "y": 0,
      "z": -6,
      "name": "Soil_Grass"
    },
    {
      "x": 8,
      "y": 0,
      "z": -5,
      "name": "Soil_Grass"
    },
    {
      "x": 8,
      "y": 0,
      "z": -4,
      "name": "Soil_Grass"
    },
    {
      "x": 8,
      "y": 0,
      "z": -3,
      "name": "Soil_Grass"
    },
    {
      "x": 8,
      "y": 0,
      "z": -2,
      "name": "Soil_Grass"
    },
    {
      "x": 8,
      "y": 0,
      "z": -1,
      "name": "Soil_Grass"
    },
    {
      "x": 8,
      "y": 0,
      "z": 0,
      "name": "Soil_Grass"
    },
    {
      "x": 8,
      "y": 0,
      "z": 1,
      "name": "Soil_Grass"
    },
    {
      "x": 8,
      "y": 0,
      "z": 2,
      "name": "Soil_Grass"
    },
    {
      "x": 8,
      "y": 0,
      "z": 3,
      "name": "Soil_Grass"
    },
    {
      "x": 8,
      "y": 0,
      "z": 4,
      "name": "Soil_Grass"
    },
    {
      "x": 8,
      "y": 0,
      "z": 5,
      "name": "Soil_Grass"
    },
    {
      "x": 8,
      "y": 0,
      "z": 6,
      "name": "Soil_Grass"
    },
    {
      "x": 8,
      "y": 0,
      "z": 7,
      "name": "Soil_Grass"
    },
    {
      "x": 8,
      "y": 0,
      "z": 8,
      "name": "Soil_Grass"
    },
    {
      "x": 8,
      "y": 0,
      "z": 9,
      "name": "Soil_Grass"
    },
    {
      "x": 8,
      "y": 0,
      "z": 10,
      "name": "Soil_Grass"
    },
    {
      "x": 8,
      "y": 0,
      "z": 11,
      "name": "Soil_Grass"
    },
    {
      "x": 8,
      "y": 0,
      "z": 12,
      "name": "Soil_Grass"
    },
    {
      "x": 8,
      "y": 0,
      "z": 13,
      "name": "Soil_Grass"
    },
    {
      "x": 8,
      "y": 0,
      "z": 14,
      "name": "Soil_Grass"
    },
    {
      "x": 8,
      "y": 0,
      "z": 15,
      "name": "Soil_Grass"
    },
    {
      "x": 8,
      "y": 0,
      "z": 16,
      "name": "Soil_Grass"
    },
    {
      "x": 9,
      "y": 0,
      "z": -15,
      "name": "Soil_Grass"
    },
    {
      "x": 9,
      "y": 0,
      "z": -14,
      "name": "Soil_Grass"
    },
    {
