{
  "version": 8,
  "blockIdVersion": 11,
  "anchorX": 0,
  "anchorY": 0,
  "anchorZ": 0,
  "blocks": [
    {
      "x": -15,
      "y": 0,
      "z": -15,
      "name": "Soil_Dirt"
    },
    {
      "x": -15,
      "y": 1,
      "z": -15,
      "name": "Soil_Dirt"
    },
    {
      "x": -15,
      "y": 2,
      "z": -15,
      "name": "Soil_Dirt"
    },
    {
      "x": -15,
      "y": 3,
      "z": -15,
      "name": "Soil_Grass"
    },
    {
      "x": -15,
      "y": 4,
      "z": -15,
      "name": "K2_Slot_Size_Small"
    },
    {
      "x": -15,
      "y": 0,
      "z": -14,
      "name": "Soil_Dirt"
    },
    {
      "x": -15,
      "y": 1,
      "z": -14,
      "name": "Soil_Dirt"
    },
    {
      "x": -15,
      "y": 2,
      "z": -14,
      "name": "Soil_Dirt"
    },
    {
      "x": -15,
      "y": 3,
      "z": -14,
      "name": "Soil_Grass"
    },
    {
      "x": -15,
      "y": 0,
      "z": -13,
      "name": "Soil_Dirt"
    },
    {
      "x": -15,
      "y": 1,
      "z": -13,
      "name": "Soil_Dirt"
    },
    {
      "x": -15,
      "y": 2,
      "z": -13,
      "name": "Soil_Dirt"
    },
    {
      "x": -15,
      "y": 3,
      "z": -13,
      "name": "Soil_Grass"
    },
    {
      "x": -15,
      "y": 0,
      "z": -12,
      "name": "Soil_Dirt"
    },
    {
      "x": -15,
      "y": 1,
      "z": -12,
      "name": "Soil_Dirt"
    },
    {
      "x": -15,
      "y": 2,
      "z": -12,
      "name": "Soil_Dirt"
    },
    {
      "x": -15,
      "y": 3,
      "z": -12,
      "name": "Soil_Grass"
    },
    {
      "x": -15,
      "y": 0,
      "z": -11,
      "name": "Soil_Dirt"
    },
    {
      "x": -15,
      "y": 1,
      "z": -11,
      "name": "Soil_Dirt"
    },
    {
      "x": -15,
      "y": 2,
      "z": -11,
      "name": "Soil_Dirt"
    },
    {
      "x": -15,
      "y": 3,
      "z": -11,
      "name": "Soil_Grass"
    },
    {
      "x": -15,
      "y": 0,
      "z": -10,
      "name": "Soil_Dirt"
    },
    {
      "x": -15,
      "y": 1,
      "z": -10,
      "name": "Soil_Dirt"
    },
    {
      "x": -15,
      "y": 2,
      "z": -10,
      "name": "Soil_Dirt"
    },
    {
      "x": -15,
      "y": 3,
      "z": -10,
      "name": "Soil_Grass"
    },
    {
      "x": -15,
      "y": 0,
      "z": -9,
      "name": "Soil_Dirt"
    },
    {
      "x": -15,
      "y": 1,
      "z": -9,
      "name": "Soil_Dirt"
    },
    {
      "x": -15,
      "y": 2,
      "z": -9,
      "name": "Soil_Dirt"
    },
    {
      "x": -15,
      "y": 3,
      "z": -9,
      "name": "Soil_Grass"
    },
    {
      "x": -15,
      "y": 0,
      "z": -8,
      "name": "Soil_Dirt"
    },
    {
      "x": -15,
      "y": 1,
      "z": -8,
      "name": "Soil_Dirt"
    },
    {
      "x": -15,
      "y": 2,
      "z": -8,
      "name": "Soil_Dirt"
    },
    {
      "x": -15,
      "y": 3,
      "z": -8,
      "name": "Soil_Grass"
    },
    {
      "x": -15,
      "y": 0,
      "z": -7,
      "name": "Soil_Dirt"
    },
    {
      "x": -15,
      "y": 1,
      "z": -7,
      "name": "Soil_Dirt"
    },
    {
      "x": -15,
      "y": 2,
      "z": -7,
      "name": "Soil_Dirt"
    },
    {
      "x": -15,
      "y": 3,
      "z": -7,
      "name": "Soil_Grass"
    },
    {
      "x": -15,
      "y": 0,
      "z": -6,
      "name": "Soil_Dirt"
    },
    {
      "x": -15,
      "y": 1,
      "z": -6,
      "name": "Soil_Dirt"
    },
    {
      "x": -15,
      "y": 2,
      "z": -6,
      "name": "Soil_Dirt"
    },
    {
      "x": -15,
      "y": 3,
      "z": -6,
      "name": "Soil_Grass"
    },
    {
      "x": -15,
      "y": 0,
      "z": -5,
      "name": "Soil_Dirt"
    },
    {
      "x": -15,
      "y": 1,
      "z": -5,
      "name": "Soil_Dirt"
    },
    {
      "x": -15,
      "y": 2,
      "z": -5,
      "name": "Soil_Dirt"
    },
    {
      "x": -15,
      "y": 3,
      "z": -5,
      "name": "Soil_Grass"
    },
    {
      "x": -15,
      "y": 0,
      "z": -4,
      "name": "Soil_Dirt"
    },
    {
      "x": -15,
      "y": 1,
      "z": -4,
      "name": "Soil_Dirt"
    },
    {
      "x": -15,
      "y": 2,
      "z": -4,
      "name": "Soil_Dirt"
    },
    {
      "x": -15,
      "y": 3,
      "z": -4,
      "name": "Soil_Grass"
    },
    {
      "x": -15,
      "y": 0,
      "z": -3,
      "name": "Soil_Dirt"
    },
    {
      "x": -15,
      "y": 1,
      "z": -3,
      "name": "Soil_Dirt"
    },
    {
      "x": -15,
      "y": 2,
      "z": -3,
      "name": "Soil_Dirt"
    },
    {
      "x": -15,
      "y": 3,
      "z": -3,
      "name": "Soil_Grass"
    },
    {
      "x": -15,
      "y": 0,
      "z": -2,
      "name": "Soil_Dirt"
    },
    {
      "x": -15,
      "y": 1,
      "z": -2,
      "name": "Soil_Dirt"
    },
    {
      "x": -15,
      "y": 2,
      "z": -2,
      "name": "Soil_Dirt"
    },
    {
      "x": -15,
      "y": 3,
      "z": -2,
      "name": "Soil_Grass"
    },
    {
      "x": -15,
      "y": 0,
      "z": -1,
      "name": "Soil_Dirt"
    },
    {
      "x": -15,
      "y": 1,
      "z": -1,
      "name": "Soil_Dirt"
    },
    {
      "x": -15,
      "y": 2,
      "z": -1,
      "name": "Soil_Dirt"
    },
    {
      "x": -15,
      "y": 3,
      "z": -1,
      "name": "Soil_Grass"
    },
    {
      "x": -15,
      "y": 0,
      "z": 0,
      "name": "Soil_Dirt"
    },
    {
      "x": -15,
      "y": 1,
      "z": 0,
      "name": "Soil_Dirt"
    },
    {
      "x": -15,
      "y": 2,
      "z": 0,
      "name": "Soil_Dirt"
    },
    {
      "x": -15,
      "y": 3,
      "z": 0,
      "name": "Soil_Grass"
    },
    {
      "x": -15,
      "y": 0,
      "z": 1,
      "name": "Soil_Dirt"
    },
    {
      "x": -15,
      "y": 1,
      "z": 1,
      "name": "Soil_Dirt"
    },
    {
      "x": -15,
      "y": 2,
      "z": 1,
      "name": "Soil_Dirt"
    },
    {
      "x": -15,
      "y": 3,
      "z": 1,
      "name": "Soil_Grass"
    },
    {
      "x": -15,
      "y": 0,
      "z": 2,
      "name": "Soil_Dirt"
    },
    {
      "x": -15,
      "y": 1,
      "z": 2,
      "name": "Soil_Dirt"
    },
    {
      "x": -15,
      "y": 2,
      "z": 2,
      "name": "Soil_Dirt"
    },
    {
      "x": -15,
      "y": 3,
      "z": 2,
      "name": "Soil_Grass"
    },
    {
      "x": -15,
      "y": 0,
      "z": 3,
      "name": "Soil_Dirt"
    },
    {
      "x": -15,
      "y": 1,
      "z": 3,
      "name": "Soil_Dirt"
    },
    {
      "x": -15,
      "y": 2,
      "z": 3,
      "name": "Soil_Dirt"
    },
    {
      "x": -15,
      "y": 3,
      "z": 3,
      "name": "Soil_Grass"
    },
    {
      "x": -15,
      "y": 0,
      "z": 4,
      "name": "Soil_Dirt"
    },
    {
      "x": -15,
      "y": 1,
      "z": 4,
      "name": "Soil_Dirt"
    },
    {
      "x": -15,
      "y": 2,
      "z": 4,
      "name": "Soil_Dirt"
    },
    {
      "x": -15,
      "y": 3,
      "z": 4,
      "name": "Soil_Grass"
    },
    {
      "x": -15,
      "y": 0,
      "z": 5,
      "name": "Soil_Dirt"
    },
    {
      "x": -15,
      "y": 1,
      "z": 5,
      "name": "Soil_Dirt"
    },
    {
      "x": -15,
      "y": 2,
      "z": 5,
      "name": "Soil_Dirt"
    },
    {
      "x": -15,
      "y": 3,
      "z": 5,
      "name": "Soil_Grass"
    },
    {
      "x": -15,
      "y": 0,
      "z": 6,
      "name": "Soil_Dirt"
    },
    {
      "x": -15,
      "y": 1,
      "z": 6,
      "name": "Soil_Dirt"
    },
    {
      "x": -15,
      "y": 2,
      "z": 6,
      "name": "Soil_Dirt"
    },
    {
      "x": -15,
      "y": 3,
      "z": 6,
      "name": "Soil_Grass"
    },
    {
      "x": -15,
      "y": 0,
      "z": 7,
      "name": "Soil_Dirt"
    },
    {
      "x": -15,
      "y": 1,
      "z": 7,
      "name": "Soil_Dirt"
    },
    {
      "x": -15,
      "y": 2,
      "z": 7,
      "name": "Soil_Dirt"
    },
    {
      "x": -15,
      "y": 3,
      "z": 7,
      "name": "Soil_Grass"
    },
    {
      "x": -15,
      "y": 0,
      "z": 8,
      "name": "Soil_Dirt"
    },
    {
      "x": -15,
      "y": 1,
      "z": 8,
      "name": "Soil_Dirt"
    },
    {
      "x": -15,
      "y": 2,
      "z": 8,
      "name": "Soil_Dirt"
    },
    {
      "x": -15,
      "y": 3,
      "z": 8,
      "name": "Soil_Grass"
    },
    {
      "x": -15,
      "y": 0,
      "z": 9,
      "name": "Soil_Dirt"
    },
    {
      "x": -15,
      "y": 1,
      "z": 9,
      "name": "Soil_Dirt"
    },
    {
      "x": -15,
      "y": 2,
      "z": 9,
      "name": "Soil_Dirt"
    },
    {
      "x": -15,
      "y": 3,
      "z": 9,
      "name": "Soil_Grass"
    },
    {
      "x": -15,
      "y": 0,
      "z": 10,
      "name": "Soil_Dirt"
    },
    {
      "x": -15,
      "y": 1,
      "z": 10,
      "name": "Soil_Dirt"
    },
    {
      "x": -15,
      "y": 2,
      "z": 10,
      "name": "Soil_Dirt"
    },
    {
      "x": -15,
      "y": 3,
      "z": 10,
      "name": "Soil_Grass"
    },
    {
      "x": -15,
      "y": 0,
      "z": 11,
      "name": "Soil_Dirt"
    },
    {
      "x": -15,
      "y": 1,
      "z": 11,
      "name": "Soil_Dirt"
    },
    {
      "x": -15,
      "y": 2,
      "z": 11,
      "name": "Soil_Dirt"
    },
    {
      "x": -15,
      "y": 3,
      "z": 11,
      "name": "Soil_Grass"
    },
    {
      "x": -15,
      "y": 0,
      "z": 12,
      "name": "Soil_Dirt"
    },
    {
      "x": -15,
      "y": 1,
      "z": 12,
      "name": "Soil_Dirt"
    },
    {
      "x": -15,
      "y": 2,
      "z": 12,
      "name": "Soil_Dirt"
    },
    {
      "x": -15,
      "y": 3,
      "z": 12,
      "name": "Soil_Grass"
    },
    {
      "x": -15,
      "y": 0,
      "z": 13,
      "name": "Soil_Dirt"
    },
    {
      "x": -15,
      "y": 1,
      "z": 13,
      "name": "Soil_Dirt"
    },
    {
      "x": -15,
      "y": 2,
      "z": 13,
      "name": "Soil_Dirt"
    },
    {
      "x": -15,
      "y": 3,
      "z": 13,
      "name": "Soil_Grass"
    },
    {
      "x": -15,
      "y": 0,
      "z": 14,
      "name": "Soil_Dirt"
    },
    {
      "x": -15,
      "y": 1,
      "z": 14,
      "name": "Soil_Dirt"
    },
    {
      "x": -15,
      "y": 2,
      "z": 14,
      "name": "Soil_Dirt"
    },
    {
      "x": -15,
      "y": 3,
      "z": 14,
      "name": "Soil_Grass"
    },
    {
      "x": -15,
      "y": 0,
      "z": 15,
      "name": "Soil_Dirt"
    },
    {
      "x": -15,
      "y": 1,
      "z": 15,
      "name": "Soil_Dirt"
    },
    {
      "x": -15,
      "y": 2,
      "z": 15,
      "name": "Soil_Dirt"
    },
    {
      "x": -15,
      "y": 3,
      "z": 15,
      "name": "Soil_Grass"
    },
    {
      "x": -15,
      "y": 0,
      "z": 16,
      "name": "Soil_Dirt"
    },
    {
      "x": -15,
      "y": 1,
      "z": 16,
      "name": "Soil_Dirt"
    },
    {
      "x": -15,
      "y": 2,
      "z": 16,
      "name": "Soil_Dirt"
    },
    {
      "x": -15,
      "y": 3,
      "z": 16,
      "name": "Soil_Grass"
    },
    {
      "x": -14,
      "y": 0,
      "z": -15,
      "name": "Soil_Dirt"
    },
    {
      "x": -14,
      "y": 1,
      "z": -15,
      "name": "Soil_Dirt"
    },
    {
      "x": -14,
      "y": 2,
      "z": -15,
      "name": "Soil_Dirt"
    },
    {
      "x": -14,
      "y": 3,
      "z": -15,
      "name": "Soil_Grass"
    },
    {
      "x": -14,
      "y": 0,
      "z": -14,
      "name": "Soil_Dirt"
    },
    {
      "x": -14,
      "y": 1,
      "z": -14,
      "name": "Soil_Dirt"
    },
    {
      "x": -14,
      "y": 2,
      "z": -14,
      "name": "Soil_Dirt"
    },
    {
      "x": -14,
      "y": 3,
      "z": -14,
      "name": "Soil_Grass"
    },
    {
      "x": -14,
      "y": 0,
      "z": -13,
      "name": "Soil_Dirt"
    },
    {
      "x": -14,
      "y": 1,
      "z": -13,
      "name": "Soil_Dirt"
    },
    {
      "x": -14,
      "y": 2,
      "z": -13,
      "name": "Soil_Dirt"
    },
    {
      "x": -14,
      "y": 3,
      "z": -13,
      "name": "Soil_Grass"
    },
    {
      "x": -14,
      "y": 0,
      "z": -12,
      "name": "Soil_Dirt"
    },
    {
      "x": -14,
      "y": 1,
      "z": -12,
      "name": "Soil_Dirt"
    },
    {
      "x": -14,
      "y": 2,
      "z": -12,
      "name": "Soil_Dirt"
    },
    {
      "x": -14,
      "y": 3,
      "z": -12,
      "name": "Soil_Grass"
    },
    {
      "x": -14,
      "y": 0,
      "z": -11,
      "name": "Soil_Dirt"
    },
    {
      "x": -14,
      "y": 1,
      "z": -11,
      "name": "Soil_Dirt"
    },
    {
      "x": -14,
      "y": 2,
      "z": -11,
      "name": "Soil_Dirt"
    },
    {
      "x": -14,
      "y": 3,
      "z": -11,
      "name": "Soil_Grass"
    },
    {
      "x": -14,
      "y": 0,
      "z": -10,
      "name": "Soil_Dirt"
    },
    {
      "x": -14,
      "y": 1,
      "z": -10,
      "name": "Soil_Dirt"
    },
    {
      "x": -14,
      "y": 2,
      "z": -10,
      "name": "Soil_Dirt"
    },
    {
      "x": -14,
      "y": 3,
      "z": -10,
      "name": "Soil_Grass"
    },
    {
      "x": -14,
      "y": 0,
      "z": -9,
      "name": "Soil_Dirt"
    },
    {
      "x": -14,
      "y": 1,
      "z": -9,
      "name": "Soil_Dirt"
    },
    {
      "x": -14,
      "y": 2,
      "z": -9,
      "name": "Soil_Dirt"
    },
    {
      "x": -14,
      "y": 3,
      "z": -9,
      "name": "Soil_Grass"
    },
    {
      "x": -14,
      "y": 0,
      "z": -8,
      "name": "Soil_Dirt"
    },
    {
      "x": -14,
      "y": 1,
      "z": -8,
      "name": "Soil_Dirt"
    },
    {
      "x": -14,
      "y": 2,
      "z": -8,
      "name": "Soil_Dirt"
    },
    {
      "x": -14,
      "y": 3,
      "z": -8,
      "name": "Soil_Grass"
    },
    {
      "x": -14,
      "y": 0,
      "z": -7,
      "name": "Soil_Dirt"
    },
    {
      "x": -14,
      "y": 1,
      "z": -7,
      "name": "Soil_Dirt"
    },
    {
      "x": -14,
      "y": 2,
      "z": -7,
      "name": "Soil_Dirt"
    },
    {
      "x": -14,
      "y": 3,
      "z": -7,
      "name": "Soil_Grass"
    },
    {
      "x": -14,
      "y": 0,
      "z": -6,
      "name": "Soil_Dirt"
    },
    {
      "x": -14,
      "y": 1,
      "z": -6,
      "name": "Soil_Dirt"
    },
    {
      "x": -14,
      "y": 2,
      "z": -6,
      "name": "Soil_Dirt"
    },
    {
      "x": -14,
      "y": 3,
      "z": -6,
      "name": "Soil_Grass"
    },
    {
      "x": -14,
      "y": 0,
      "z": -5,
      "name": "Soil_Dirt"
    },
    {
      "x": -14,
      "y": 1,
      "z": -5,
      "name": "Soil_Dirt"
    },
    {
      "x": -14,
      "y": 2,
      "z": -5,
      "name": "Soil_Dirt"
    },
    {
      "x": -14,
      "y": 3,
      "z": -5,
      "name": "Soil_Grass"
    },
    {
      "x": -14,
      "y": 0,
      "z": -4,
      "name": "Soil_Dirt"
    },
    {
      "x": -14,
      "y": 1,
      "z": -4,
      "name": "Soil_Dirt"
    },
    {
      "x": -14,
      "y": 2,
      "z": -4,
      "name": "Soil_Dirt"
    },
    {
      "x": -14,
      "y": 3,
      "z": -4,
      "name": "Soil_Grass"
    },
    {
      "x": -14,
      "y": 0,
      "z": -3,
      "name": "Soil_Dirt"
    },
    {
      "x": -14,
      "y": 1,
      "z": -3,
      "name": "Soil_Dirt"
    },
    {
      "x": -14,
      "y": 2,
      "z": -3,
      "name": "Soil_Dirt"
    },
    {
      "x": -14,
      "y": 3,
      "z": -3,
      "name": "Soil_Grass"
    },
    {
      "x": -14,
      "y": 0,
      "z": -2,
      "name": "Soil_Dirt"
    },
    {
      "x": -14,
      "y": 1,
      "z": -2,
      "name": "Soil_Dirt"
    },
    {
      "x": -14,
      "y": 2,
      "z": -2,
      "name": "Soil_Dirt"
    },
    {
      "x": -14,
      "y": 3,
      "z": -2,
      "name": "Soil_Grass"
    },
    {
      "x": -14,
      "y": 0,
      "z": -1,
      "name": "Soil_Dirt"
    },
    {
      "x": -14,
      "y": 1,
      "z": -1,
      "name": "Soil_Dirt"
    },
    {
      "x": -14,
      "y": 2,
      "z": -1,
      "name": "Soil_Dirt"
    },
    {
      "x": -14,
      "y": 3,
      "z": -1,
      "name": "Soil_Grass"
    },
    {
      "x": -14,
      "y": 0,
      "z": 0,
      "name": "Soil_Dirt"
    },
    {
      "x": -14,
      "y": 1,
      "z": 0,
      "name": "Soil_Dirt"
    },
    {
      "x": -14,
      "y": 2,
      "z": 0,
      "name": "Soil_Dirt"
    },
    {
      "x": -14,
      "y": 3,
      "z": 0,
      "name": "Soil_Grass"
    },
    {
      "x": -14,
      "y": 0,
      "z": 1,
      "name": "Soil_Dirt"
    },
    {
      "x": -14,
      "y": 1,
      "z": 1,
      "name": "Soil_Dirt"
    },
    {
      "x": -14,
      "y": 2,
      "z": 1,
      "name": "Soil_Dirt"
    },
    {
      "x": -14,
      "y": 3,
      "z": 1,
      "name": "Soil_Grass"
    },
    {
      "x": -14,
      "y": 0,
      "z": 2,
      "name": "Soil_Dirt"
    },
    {
      "x": -14,
      "y": 1,
      "z": 2,
      "name": "Soil_Dirt"
    },
    {
      "x": -14,
      "y": 2,
      "z": 2,
      "name": "Soil_Dirt"
    },
    {
      "x": -14,
      "y": 3,
      "z": 2,
      "name": "Soil_Grass"
    },
    {
      "x": -14,
      "y": 0,
      "z": 3,
      "name": "Soil_Dirt"
    },
    {
      "x": -14,
      "y": 1,
      "z": 3,
      "name": "Soil_Dirt"
    },
    {
      "x": -14,
      "y": 2,
      "z": 3,
      "name": "Soil_Dirt"
    },
    {
      "x": -14,
      "y": 3,
      "z": 3,
      "name": "Soil_Grass"
    },
    {
      "x": -14,
      "y": 0,
      "z": 4,
      "name": "Soil_Dirt"
    },
    {
      "x": -14,
      "y": 1,
      "z": 4,
      "name": "Soil_Dirt"
    },
    {
      "x": -14,
      "y": 2,
      "z": 4,
      "name": "Soil_Dirt"
    },
    {
      "x": -14,
      "y": 3,
      "z": 4,
      "name": "Soil_Grass"
    },
    {
      "x": -14,
      "y": 0,
      "z": 5,
      "name": "Soil_Dirt"
    },
    {
      "x": -14,
      "y": 1,
      "z": 5,
      "name": "Soil_Dirt"
    },
    {
      "x": -14,
      "y": 2,
      "z": 5,
      "name": "Soil_Dirt"
    },
    {
      "x": -14,
      "y": 3,
      "z": 5,
      "name": "Soil_Grass"
    },
    {
      "x": -14,
      "y": 0,
      "z": 6,
      "name": "Soil_Dirt"
    },
    {
      "x": -14,
      "y": 1,
      "z": 6,
      "name": "Soil_Dirt"
    },
    {
      "x": -14,
      "y": 2,
      "z": 6,
      "name": "Soil_Dirt"
    },
    {
      "x": -14,
      "y": 3,
      "z": 6,
      "name": "Soil_Grass"
    },
    {
      "x": -14,
      "y": 0,
      "z": 7,
      "name": "Soil_Dirt"
    },
    {
      "x": -14,
      "y": 1,
      "z": 7,
      "name": "Soil_Dirt"
    },
    {
      "x": -14,
      "y": 2,
      "z": 7,
      "name": "Soil_Dirt"
    },
    {
      "x": -14,
      "y": 3,
      "z": 7,
      "name": "Soil_Grass"
    },
    {
      "x": -14,
      "y": 0,
      "z": 8,
      "name": "Soil_Dirt"
    },
    {
      "x": -14,
      "y": 1,
      "z": 8,
      "name": "Soil_Dirt"
    },
    {
      "x": -14,
      "y": 2,
      "z": 8,
      "name": "Soil_Dirt"
    },
    {
      "x": -14,
      "y": 3,
      "z": 8,
      "name": "Soil_Grass"
    },
    {
      "x": -14,
      "y": 0,
      "z": 9,
      "name": "Soil_Dirt"
    },
    {
      "x": -14,
      "y": 1,
      "z": 9,
      "name": "Soil_Dirt"
    },
    {
      "x": -14,
      "y": 2,
      "z": 9,
      "name": "Soil_Dirt"
    },
    {
      "x": -14,
      "y": 3,
      "z": 9,
      "name": "Soil_Grass"
    },
    {
      "x": -14,
      "y": 0,
      "z": 10,
      "name": "Soil_Dirt"
    },
    {
      "x": -14,
      "y": 1,
      "z": 10,
      "name": "Soil_Dirt"
    },
    {
      "x": -14,
      "y": 2,
      "z": 10,
      "name": "Soil_Dirt"
    },
    {
      "x": -14,
      "y": 3,
      "z": 10,
      "name": "Soil_Grass"
    },
    {
      "x": -14,
      "y": 0,
      "z": 11,
      "name": "Soil_Dirt"
    },
    {
      "x": -14,
      "y": 1,
      "z": 11,
      "name": "Soil_Dirt"
    },
    {
      "x": -14,
      "y": 2,
      "z": 11,
      "name": "Soil_Dirt"
    },
    {
      "x": -14,
      "y": 3,
      "z": 11,
      "name": "Soil_Grass"
    },
    {
      "x": -14,
      "y": 0,
      "z": 12,
      "name": "Soil_Dirt"
    },
    {
      "x": -14,
      "y": 1,
      "z": 12,
      "name": "Soil_Dirt"
    },
    {
      "x": -14,
      "y": 2,
      "z": 12,
      "name": "Soil_Dirt"
    },
    {
      "x": -14,
      "y": 3,
      "z": 12,
      "name": "Soil_Grass"
    },
    {
      "x": -14,
      "y": 0,
      "z": 13,
      "name": "Soil_Dirt"
    },
    {
      "x": -14,
      "y": 1,
      "z": 13,
      "name": "Soil_Dirt"
    },
    {
      "x": -14,
      "y": 2,
      "z": 13,
      "name": "Soil_Dirt"
    },
    {
      "x": -14,
      "y": 3,
      "z": 13,
      "name": "Soil_Grass"
    },
    {
      "x": -14,
      "y": 0,
      "z": 14,
      "name": "Soil_Dirt"
    },
    {
      "x": -14,
      "y": 1,
      "z": 14,
      "name": "Soil_Dirt"
    },
    {
      "x": -14,
      "y": 2,
      "z": 14,
      "name": "Soil_Dirt"
    },
    {
      "x": -14,
      "y": 3,
      "z": 14,
      "name": "Soil_Grass"
    },
    {
      "x": -14,
      "y": 0,
      "z": 15,
      "name": "Soil_Dirt"
    },
    {
      "x": -14,
      "y": 1,
      "z": 15,
      "name": "Soil_Dirt"
    },
    {
      "x": -14,
      "y": 2,
      "z": 15,
      "name": "Soil_Dirt"
    },
    {
      "x": -14,
      "y": 3,
      "z": 15,
      "name": "Soil_Grass"
    },
    {
      "x": -14,
      "y": 0,
      "z": 16,
      "name": "Soil_Dirt"
    },
    {
      "x": -14,
      "y": 1,
      "z": 16,
      "name": "Soil_Dirt"
    },
    {
      "x": -14,
      "y": 2,
      "z": 16,
      "name": "Soil_Dirt"
    },
    {
      "x": -14,
      "y": 3,
      "z": 16,
      "name": "Soil_Grass"
    },
    {
      "x": -13,
      "y": 0,
      "z": -15,
      "name": "Soil_Dirt"
    },
    {
      "x": -13,
      "y": 1,
      "z": -15,
      "name": "Soil_Dirt"
    },
    {
      "x": -13,
      "y": 2,
      "z": -15,
      "name": "Soil_Dirt"
    },
    {
      "x": -13,
      "y": 3,
      "z": -15,
      "name": "Soil_Grass"
    },
    {
      "x": -13,
      "y": 0,
      "z": -14,
      "name": "Soil_Dirt"
    },
    {
      "x": -13,
      "y": 1,
      "z": -14,
      "name": "Soil_Dirt"
    },
    {
      "x": -13,
      "y": 2,
      "z": -14,
      "name": "Soil_Dirt"
    },
    {
      "x": -13,
      "y": 3,
      "z": -14,
      "name": "Soil_Grass"
    },
    {
      "x": -13,
      "y": 0,
      "z": -13,
      "name": "Soil_Dirt"
    },
    {
      "x": -13,
      "y": 1,
      "z": -13,
      "name": "Soil_Dirt"
    },
    {
      "x": -13,
      "y": 2,
      "z": -13,
      "name": "Soil_Dirt"
    },
    {
      "x": -13,
      "y": 3,
      "z": -13,
      "name": "K2_Slot_Arrival"
    },
    {
      "x": -13,
      "y": 0,
      "z": -12,
      "name": "Soil_Dirt"
    },
    {
      "x": -13,
      "y": 1,
      "z": -12,
      "name": "Soil_Dirt"
    },
    {
      "x": -13,
      "y": 2,
      "z": -12,
      "name": "Soil_Dirt"
    },
    {
      "x": -13,
      "y": 3,
      "z": -12,
      "name": "Soil_Grass"
    },
    {
      "x": -13,
      "y": 0,
      "z": -11,
      "name": "Soil_Dirt"
    },
    {
      "x": -13,
      "y": 1,
      "z": -11,
      "name": "Soil_Dirt"
    },
    {
      "x": -13,
      "y": 2,
      "z": -11,
      "name": "Soil_Dirt"
    },
    {
      "x": -13,
      "y": 3,
      "z": -11,
      "name": "Soil_Grass"
    },
    {
      "x": -13,
      "y": 0,
      "z": -10,
      "name": "Soil_Dirt"
    },
    {
      "x": -13,
      "y": 1,
      "z": -10,
      "name": "Soil_Dirt"
    },
    {
      "x": -13,
      "y": 2,
      "z": -10,
      "name": "Soil_Dirt"
    },
    {
      "x": -13,
      "y": 3,
      "z": -10,
      "name": "Soil_Grass"
    },
    {
      "x": -13,
      "y": 0,
      "z": -9,
      "name": "Soil_Dirt"
    },
    {
      "x": -13,
      "y": 1,
      "z": -9,
      "name": "Soil_Dirt"
    },
    {
      "x": -13,
      "y": 2,
      "z": -9,
      "name": "Soil_Dirt"
    },
    {
      "x": -13,
      "y": 3,
      "z": -9,
      "name": "Soil_Grass"
    },
    {
      "x": -13,
      "y": 0,
      "z": -8,
      "name": "Soil_Dirt"
    },
    {
      "x": -13,
      "y": 1,
      "z": -8,
      "name": "Soil_Dirt"
    },
    {
      "x": -13,
      "y": 2,
      "z": -8,
      "name": "Soil_Dirt"
    },
    {
      "x": -13,
      "y": 3,
      "z": -8,
      "name": "Soil_Grass"
    },
    {
      "x": -13,
      "y": 0,
      "z": -7,
      "name": "Soil_Dirt"
    },
    {
      "x": -13,
      "y": 1,
      "z": -7,
      "name": "Soil_Dirt"
    },
    {
      "x": -13,
      "y": 2,
      "z": -7,
      "name": "Soil_Dirt"
    },
    {
      "x": -13,
      "y": 3,
      "z": -7,
      "name": "Soil_Grass"
    },
    {
      "x": -13,
      "y": 0,
      "z": -6,
      "name": "Soil_Dirt"
    },
    {
      "x": -13,
      "y": 1,
      "z": -6,
      "name": "Soil_Dirt"
    },
    {
      "x": -13,
      "y": 2,
      "z": -6,
      "name": "Soil_Dirt"
    },
    {
      "x": -13,
      "y": 3,
      "z": -6,
      "name": "Soil_Grass"
    },
    {
      "x": -13,
      "y": 0,
      "z": -5,
      "name": "Soil_Dirt"
    },
    {
      "x": -13,
      "y": 1,
      "z": -5,
      "name": "Soil_Dirt"
    },
    {
      "x": -13,
      "y": 2,
      "z": -5,
      "name": "Soil_Dirt"
    },
    {
      "x": -13,
      "y": 3,
      "z": -5,
      "name": "Soil_Grass"
    },
    {
      "x": -13,
      "y": 0,
      "z": -4,
      "name": "Soil_Dirt"
    },
    {
      "x": -13,
      "y": 1,
      "z": -4,
      "name": "Soil_Dirt"
    },
    {
      "x": -13,
      "y": 2,
      "z": -4,
      "name": "Soil_Dirt"
    },
    {
      "x": -13,
      "y": 3,
      "z": -4,
      "name": "Soil_Grass"
    },
    {
      "x": -13,
      "y": 0,
      "z": -3,
      "name": "Soil_Dirt"
    },
    {
      "x": -13,
      "y": 1,
      "z": -3,
      "name": "Soil_Dirt"
    },
    {
      "x": -13,
      "y": 2,
      "z": -3,
      "name": "Soil_Dirt"
    },
    {
      "x": -13,
      "y": 3,
      "z": -3,
      "name": "Soil_Grass"
    },
    {
      "x": -13,
      "y": 0,
      "z": -2,
      "name": "Soil_Dirt"
    },
    {
      "x": -13,
      "y": 1,
      "z": -2,
      "name": "Soil_Dirt"
    },
    {
      "x": -13,
      "y": 2,
      "z": -2,
      "name": "Soil_Dirt"
    },
    {
      "x": -13,
      "y": 3,
      "z": -2,
      "name": "Soil_Grass"
    },
    {
      "x": -13,
      "y": 0,
      "z": -1,
      "name": "Soil_Dirt"
    },
    {
      "x": -13,
      "y": 1,
      "z": -1,
      "name": "Soil_Dirt"
    },
    {
      "x": -13,
      "y": 2,
      "z": -1,
      "name": "Soil_Dirt"
    },
    {
      "x": -13,
      "y": 3,
      "z": -1,
      "name": "Soil_Grass"
    },
    {
      "x": -13,
      "y": 0,
      "z": 0,
      "name": "Soil_Dirt"
    },
    {
      "x": -13,
      "y": 1,
      "z": 0,
      "name": "Soil_Dirt"
    },
    {
      "x": -13,
      "y": 2,
      "z": 0,
      "name": "Soil_Dirt"
    },
    {
      "x": -13,
      "y": 3,
      "z": 0,
      "name": "Soil_Grass"
    },
    {
      "x": -13,
      "y": 0,
      "z": 1,
      "name": "Soil_Dirt"
    },
    {
      "x": -13,
      "y": 1,
      "z": 1,
      "name": "Soil_Dirt"
    },
    {
      "x": -13,
      "y": 2,
      "z": 1,
      "name": "Soil_Dirt"
    },
    {
      "x": -13,
      "y": 3,
      "z": 1,
      "name": "Soil_Grass"
    },
    {
      "x": -13,
      "y": 0,
      "z": 2,
      "name": "Soil_Dirt"
    },
    {
      "x": -13,
      "y": 1,
      "z": 2,
      "name": "Soil_Dirt"
    },
    {
      "x": -13,
      "y": 2,
      "z": 2,
      "name": "Soil_Dirt"
    },
    {
      "x": -13,
      "y": 3,
      "z": 2,
      "name": "Soil_Grass"
    },
    {
      "x": -13,
      "y": 0,
      "z": 3,
      "name": "Soil_Dirt"
    },
    {
      "x": -13,
      "y": 1,
      "z": 3,
      "name": "Soil_Dirt"
    },
    {
      "x": -13,
      "y": 2,
      "z": 3,
      "name": "Soil_Dirt"
    },
    {
      "x": -13,
      "y": 3,
      "z": 3,
      "name": "Soil_Grass"
    },
    {
      "x": -13,
      "y": 0,
      "z": 4,
      "name": "Soil_Dirt"
    },
    {
      "x": -13,
      "y": 1,
      "z": 4,
      "name": "Soil_Dirt"
    },
    {
      "x": -13,
      "y": 2,
      "z": 4,
      "name": "Soil_Dirt"
    },
    {
      "x": -13,
      "y": 3,
      "z": 4,
      "name": "Soil_Grass"
    },
    {
      "x": -13,
      "y": 0,
      "z": 5,
      "name": "Soil_Dirt"
    },
    {
      "x": -13,
      "y": 1,
      "z": 5,
      "name": "Soil_Dirt"
    },
    {
      "x": -13,
      "y": 2,
      "z": 5,
      "name": "Soil_Dirt"
    },
    {
      "x": -13,
      "y": 3,
      "z": 5,
      "name": "Soil_Grass"
    },
    {
      "x": -13,
      "y": 0,
      "z": 6,
      "name": "Soil_Dirt"
    },
    {
      "x": -13,
      "y": 1,
      "z": 6,
      "name": "Soil_Dirt"
    },
    {
      "x": -13,
      "y": 2,
      "z": 6,
      "name": "Soil_Dirt"
    },
    {
      "x": -13,
      "y": 3,
      "z": 6,
      "name": "Soil_Grass"
    },
    {
      "x": -13,
      "y": 0,
      "z": 7,
      "name": "Soil_Dirt"
    },
    {
      "x": -13,
      "y": 1,
      "z": 7,
      "name": "Soil_Dirt"
    },
    {
      "x": -13,
      "y": 2,
      "z": 7,
      "name": "Soil_Dirt"
    },
    {
      "x": -13,
      "y": 3,
      "z": 7,
      "name": "Soil_Grass"
    },
    {
      "x": -13,
      "y": 0,
      "z": 8,
      "name": "Soil_Dirt"
    },
    {
      "x": -13,
      "y": 1,
      "z": 8,
      "name": "Soil_Dirt"
    },
    {
      "x": -13,
      "y": 2,
      "z": 8,
      "name": "Soil_Dirt"
    },
    {
      "x": -13,
      "y": 3,
      "z": 8,
      "name": "Soil_Grass"
    },
    {
      "x": -13,
      "y": 0,
      "z": 9,
      "name": "Soil_Dirt"
    },
    {
      "x": -13,
      "y": 1,
      "z": 9,
      "name": "Soil_Dirt"
    },
    {
      "x": -13,
      "y": 2,
      "z": 9,
      "name": "Soil_Dirt"
    },
    {
      "x": -13,
      "y": 3,
      "z": 9,
      "name": "Soil_Grass"
    },
    {
      "x": -13,
      "y": 0,
      "z": 10,
      "name": "Soil_Dirt"
    },
    {
      "x": -13,
      "y": 1,
      "z": 10,
      "name": "Soil_Dirt"
    },
    {
      "x": -13,
      "y": 2,
      "z": 10,
      "name": "Soil_Dirt"
    },
    {
      "x": -13,
      "y": 3,
      "z": 10,
      "name": "Soil_Grass"
    },
    {
      "x": -13,
      "y": 0,
      "z": 11,
      "name": "Soil_Dirt"
    },
    {
      "x": -13,
      "y": 1,
      "z": 11,
      "name": "Soil_Dirt"
    },
    {
      "x": -13,
      "y": 2,
      "z": 11,
      "name": "Soil_Dirt"
    },
    {
      "x": -13,
      "y": 3,
      "z": 11,
      "name": "Soil_Grass"
    },
    {
      "x": -13,
      "y": 0,
      "z": 12,
      "name": "Soil_Dirt"
    },
    {
      "x": -13,
      "y": 1,
      "z": 12,
      "name": "Soil_Dirt"
    },
    {
      "x": -13,
      "y": 2,
      "z": 12,
      "name": "Soil_Dirt"
    },
    {
      "x": -13,
      "y": 3,
      "z": 12,
      "name": "Soil_Grass"
    },
    {
      "x": -13,
      "y": 0,
      "z": 13,
      "name": "Soil_Dirt"
    },
    {
      "x": -13,
      "y": 1,
      "z": 13,
      "name": "Soil_Dirt"
    },
    {
      "x": -13,
      "y": 2,
      "z": 13,
      "name": "Soil_Dirt"
    },
    {
      "x": -13,
      "y": 3,
      "z": 13,
      "name": "Soil_Grass"
    },
    {
      "x": -13,
      "y": 0,
      "z": 14,
      "name": "Soil_Dirt"
    },
    {
      "x": -13,
      "y": 1,
      "z": 14,
      "name": "Soil_Dirt"
    },
    {
      "x": -13,
      "y": 2,
      "z": 14,
      "name": "Soil_Dirt"
    },
    {
      "x": -13,
      "y": 3,
      "z": 14,
      "name": "Soil_Grass"
    },
    {
      "x": -13,
      "y": 0,
      "z": 15,
      "name": "Soil_Dirt"
    },
    {
      "x": -13,
      "y": 1,
      "z": 15,
      "name": "Soil_Dirt"
    },
    {
      "x": -13,
      "y": 2,
      "z": 15,
      "name": "Soil_Dirt"
    },
    {
      "x": -13,
      "y": 3,
      "z": 15,
      "name": "Soil_Grass"
    },
    {
      "x": -13,
      "y": 0,
      "z": 16,
      "name": "Soil_Dirt"
    },
    {
      "x": -13,
      "y": 1,
      "z": 16,
      "name": "Soil_Dirt"
    },
    {
      "x": -13,
      "y": 2,
      "z": 16,
      "name": "Soil_Dirt"
    },
    {
      "x": -13,
      "y": 3,
      "z": 16,
      "name": "Soil_Grass"
    },
    {
      "x": -12,
      "y": 0,
      "z": -15,
      "name": "Soil_Dirt"
    },
    {
      "x": -12,
      "y": 1,
      "z": -15,
      "name": "Soil_Dirt"
    },
    {
      "x": -12,
      "y": 2,
      "z": -15,
      "name": "Soil_Dirt"
    },
    {
      "x": -12,
      "y": 3,
      "z": -15,
      "name": "Soil_Grass"
    },
    {
      "x": -12,
      "y": 0,
      "z": -14,
      "name": "Soil_Dirt"
    },
    {
      "x": -12,
      "y": 1,
      "z": -14,
      "name": "Soil_Dirt"
    },
    {
      "x": -12,
      "y": 2,
      "z": -14,
      "name": "Soil_Dirt"
    },
    {
      "x": -12,
      "y": 3,
      "z": -14,
      "name": "Soil_Grass"
    },
    {
      "x": -12,
      "y": 0,
      "z": -13,
      "name": "Soil_Dirt"
    },
    {
      "x": -12,
      "y": 1,
      "z": -13,
      "name": "Soil_Dirt"
    },
    {
      "x": -12,
      "y": 2,
      "z": -13,
      "name": "Soil_Dirt"
    },
    {
      "x": -12,
      "y": 3,
      "z": -13,
      "name": "Soil_Grass"
    },
    {
      "x": -12,
      "y": 0,
      "z": -12,
      "name": "Soil_Dirt"
    },
    {
      "x": -12,
      "y": 1,
      "z": -12,
      "name": "Soil_Dirt"
    },
    {
      "x": -12,
      "y": 2,
      "z": -12,
      "name": "Soil_Dirt"
    },
    {
      "x": -12,
      "y": 3,
      "z": -12,
      "name": "Soil_Grass"
    },
    {
      "x": -12,
      "y": 0,
      "z": -11,
      "name": "Soil_Dirt"
    },
    {
      "x": -12,
      "y": 1,
      "z": -11,
      "name": "Soil_Dirt"
    },
    {
      "x": -12,
      "y": 2,
      "z": -11,
      "name": "Soil_Dirt"
    },
    {
      "x": -12,
      "y": 3,
      "z": -11,
      "name": "Soil_Grass"
    },
    {
      "x": -12,
      "y": 0,
      "z": -10,
      "name": "Soil_Dirt"
    },
    {
      "x": -12,
      "y": 1,
      "z": -10,
      "name": "Soil_Dirt"
    },
    {
      "x": -12,
      "y": 2,
      "z": -10,
      "name": "Soil_Dirt"
    },
    {
      "x": -12,
      "y": 3,
      "z": -10,
      "name": "Soil_Grass"
    },
    {
      "x": -12,
      "y": 0,
      "z": -9,
      "name": "Soil_Dirt"
    },
    {
      "x": -12,
      "y": 1,
      "z": -9,
      "name": "Soil_Dirt"
    },
    {
      "x": -12,
      "y": 2,
      "z": -9,
      "name": "Soil_Dirt"
    },
    {
      "x": -12,
      "y": 3,
      "z": -9,
      "name": "Soil_Grass"
    },
    {
      "x": -12,
      "y": 0,
      "z": -8,
      "name": "Soil_Dirt"
    },
    {
      "x": -12,
      "y": 1,
      "z": -8,
      "name": "Soil_Dirt"
    },
    {
      "x": -12,
      "y": 2,
      "z": -8,
      "name": "Soil_Dirt"
    },
    {
      "x": -12,
      "y": 3,
      "z": -8,
      "name": "Soil_Grass"
    },
    {
      "x": -12,
      "y": 0,
      "z": -7,
      "name": "Soil_Dirt"
    },
    {
      "x": -12,
      "y": 1,
      "z": -7,
      "name": "Soil_Dirt"
    },
    {
      "x": -12,
      "y": 2,
      "z": -7,
      "name": "Soil_Dirt"
    },
    {
      "x": -12,
      "y": 3,
      "z": -7,
      "name": "Soil_Grass"
    },
    {
      "x": -12,
      "y": 0,
      "z": -6,
      "name": "Soil_Dirt"
    },
    {
      "x": -12,
      "y": 1,
      "z": -6,
      "name": "Soil_Dirt"
    },
    {
      "x": -12,
      "y": 2,
      "z": -6,
      "name": "Soil_Dirt"
    },
    {
      "x": -12,
      "y": 3,
      "z": -6,
      "name": "Soil_Grass"
    },
    {
      "x": -12,
      "y": 0,
      "z": -5,
      "name": "Soil_Dirt"
    },
    {
      "x": -12,
      "y": 1,
      "z": -5,
      "name": "Soil_Dirt"
    },
    {
      "x": -12,
      "y": 2,
      "z": -5,
      "name": "Soil_Dirt"
    },
    {
      "x": -12,
      "y": 3,
      "z": -5,
      "name": "Soil_Grass"
    },
    {
      "x": -12,
      "y": 0,
      "z": -4,
      "name": "Soil_Dirt"
    },
    {
      "x": -12,
      "y": 1,
      "z": -4,
      "name": "Soil_Dirt"
    },
    {
      "x": -12,
      "y": 2,
      "z": -4,
      "name": "Soil_Dirt"
    },
    {
      "x": -12,
      "y": 3,
      "z": -4,
      "name": "Soil_Grass"
    },
    {
      "x": -12,
      "y": 0,
      "z": -3,
      "name": "Soil_Dirt"
    },
    {
      "x": -12,
      "y": 1,
      "z": -3,
      "name": "Soil_Dirt"
    },
    {
      "x": -12,
      "y": 2,
      "z": -3,
      "name": "Soil_Dirt"
    },
    {
      "x": -12,
      "y": 3,
      "z": -3,
      "name": "Soil_Grass"
    },
    {
      "x": -12,
      "y": 0,
      "z": -2,
      "name": "Soil_Dirt"
    },
    {
      "x": -12,
      "y": 1,
      "z": -2,
      "name": "Soil_Dirt"
    },
    {
      "x": -12,
      "y": 2,
      "z": -2,
      "name": "Soil_Dirt"
    },
    {
      "x": -12,
      "y": 3,
      "z": -2,
      "name": "Soil_Grass"
    },
    {
      "x": -12,
      "y": 0,
      "z": -1,
      "name": "Soil_Dirt"
    },
    {
      "x": -12,
      "y": 1,
      "z": -1,
      "name": "Soil_Dirt"
    },
    {
      "x": -12,
      "y": 2,
      "z": -1,
      "name": "Soil_Dirt"
    },
    {
      "x": -12,
      "y": 3,
      "z": -1,
      "name": "Soil_Grass"
    },
    {
      "x": -12,
      "y": 0,
      "z": 0,
      "name": "Soil_Dirt"
    },
    {
      "x": -12,
      "y": 1,
      "z": 0,
      "name": "Soil_Dirt"
    },
    {
      "x": -12,
      "y": 2,
      "z": 0,
      "name": "Soil_Dirt"
    },
    {
      "x": -12,
      "y": 3,
      "z": 0,
      "name": "Soil_Grass"
    },
    {
      "x": -12,
      "y": 0,
      "z": 1,
      "name": "Soil_Dirt"
    },
    {
      "x": -12,
      "y": 1,
      "z": 1,
      "name": "Soil_Dirt"
    },
    {
      "x": -12,
      "y": 2,
      "z": 1,
      "name": "Soil_Dirt"
    },
    {
      "x": -12,
      "y": 3,
      "z": 1,
      "name": "Soil_Grass"
    },
    {
      "x": -12,
      "y": 0,
      "z": 2,
      "name": "Soil_Dirt"
    },
    {
      "x": -12,
      "y": 1,
      "z": 2,
      "name": "Soil_Dirt"
    },
    {
      "x": -12,
      "y": 2,
      "z": 2,
      "name": "Soil_Dirt"
    },
    {
      "x": -12,
      "y": 3,
      "z": 2,
      "name": "Soil_Grass"
    },
    {
      "x": -12,
      "y": 0,
      "z": 3,
      "name": "Soil_Dirt"
    },
    {
      "x": -12,
      "y": 1,
      "z": 3,
      "name": "Soil_Dirt"
    },
    {
      "x": -12,
      "y": 2,
      "z": 3,
      "name": "Soil_Dirt"
    },
    {
      "x": -12,
      "y": 3,
      "z": 3,
      "name": "Soil_Grass"
    },
    {
      "x": -12,
      "y": 0,
      "z": 4,
      "name": "Soil_Dirt"
    },
    {
      "x": -12,
      "y": 1,
      "z": 4,
      "name": "Soil_Dirt"
    },
    {
      "x": -12,
      "y": 2,
      "z": 4,
      "name": "Soil_Dirt"
    },
    {
      "x": -12,
      "y": 3,
      "z": 4,
      "name": "Soil_Grass"
    },
    {
      "x": -12,
      "y": 0,
      "z": 5,
      "name": "Soil_Dirt"
    },
    {
      "x": -12,
      "y": 1,
      "z": 5,
      "name": "Soil_Dirt"
    },
    {
      "x": -12,
      "y": 2,
      "z": 5,
      "name": "Soil_Dirt"
    },
    {
      "x": -12,
      "y": 3,
      "z": 5,
      "name": "Soil_Grass"
    },
    {
      "x": -12,
      "y": 0,
      "z": 6,
      "name": "Soil_Dirt"
    },
    {
      "x": -12,
      "y": 1,
      "z": 6,
      "name": "Soil_Dirt"
    },
    {
      "x": -12,
      "y": 2,
      "z": 6,
      "name": "Soil_Dirt"
    },
    {
      "x": -12,
      "y": 3,
      "z": 6,
      "name": "Soil_Grass"
    },
    {
      "x": -12,
      "y": 0,
      "z": 7,
      "name": "Soil_Dirt"
    },
    {
      "x": -12,
      "y": 1,
      "z": 7,
      "name": "Soil_Dirt"
    },
    {
      "x": -12,
      "y": 2,
      "z": 7,
      "name": "Soil_Dirt"
    },
    {
      "x": -12,
      "y": 3,
      "z": 7,
      "name": "Soil_Grass"
    },
    {
      "x": -12,
      "y": 0,
      "z": 8,
      "name": "Soil_Dirt"
    },
    {
      "x": -12,
      "y": 1,
      "z": 8,
      "name": "Soil_Dirt"
    },
    {
      "x": -12,
      "y": 2,
      "z": 8,
      "name": "Soil_Dirt"
    },
    {
      "x": -12,
      "y": 3,
      "z": 8,
      "name": "Soil_Grass"
    },
    {
      "x": -12,
      "y": 0,
      "z": 9,
      "name": "Soil_Dirt"
    },
    {
      "x": -12,
      "y": 1,
      "z": 9,
      "name": "Soil_Dirt"
    },
    {
      "x": -12,
      "y": 2,
      "z": 9,
      "name": "Soil_Dirt"
    },
    {
      "x": -12,
      "y": 3,
      "z": 9,
      "name": "Soil_Grass"
    },
    {
      "x": -12,
      "y": 0,
      "z": 10,
      "name": "Soil_Dirt"
    },
    {
      "x": -12,
      "y": 1,
      "z": 10,
      "name": "Soil_Dirt"
    },
    {
      "x": -12,
      "y": 2,
      "z": 10,
      "name": "Soil_Dirt"
    },
    {
      "x": -12,
      "y": 3,
      "z": 10,
      "name": "Soil_Grass"
    },
    {
      "x": -12,
      "y": 0,
      "z": 11,
      "name": "Soil_Dirt"
    },
    {
      "x": -12,
      "y": 1,
      "z": 11,
      "name": "Soil_Dirt"
    },
    {
      "x": -12,
      "y": 2,
      "z": 11,
      "name": "Soil_Dirt"
    },
    {
      "x": -12,
      "y": 3,
      "z": 11,
      "name": "Soil_Grass"
    },
    {
      "x": -12,
      "y": 0,
      "z": 12,
      "name": "Soil_Dirt"
    },
    {
      "x": -12,
      "y": 1,
      "z": 12,
      "name": "Soil_Dirt"
    },
    {
      "x": -12,
      "y": 2,
      "z": 12,
      "name": "Soil_Dirt"
    },
    {
      "x": -12,
      "y": 3,
      "z": 12,
      "name": "Soil_Grass"
    },
    {
      "x": -12,
      "y": 0,
      "z": 13,
      "name": "Soil_Dirt"
    },
    {
      "x": -12,
      "y": 1,
      "z": 13,
      "name": "Soil_Dirt"
    },
    {
      "x": -12,
      "y": 2,
      "z": 13,
      "name": "Soil_Dirt"
    },
    {
      "x": -12,
      "y": 3,
      "z": 13,
      "name": "Soil_Grass"
    },
    {
      "x": -12,
      "y": 0,
      "z": 14,
      "name": "Soil_Dirt"
    },
    {
      "x": -12,
      "y": 1,
      "z": 14,
      "name": "Soil_Dirt"
    },
    {
      "x": -12,
      "y": 2,
      "z": 14,
      "name": "Soil_Dirt"
    },
    {
      "x": -12,
      "y": 3,
      "z": 14,
      "name": "Soil_Grass"
    },
    {
      "x": -12,
      "y": 0,
      "z": 15,
      "name": "Soil_Dirt"
    },
    {
      "x": -12,
      "y": 1,
      "z": 15,
      "name": "Soil_Dirt"
    },
    {
      "x": -12,
      "y": 2,
      "z": 15,
      "name": "Soil_Dirt"
    },
    {
      "x": -12,
      "y": 3,
      "z": 15,
      "name": "Soil_Grass"
    },
    {
      "x": -12,
      "y": 0,
      "z": 16,
      "name": "Soil_Dirt"
    },
    {
      "x": -12,
      "y": 1,
      "z": 16,
      "name": "Soil_Dirt"
    },
    {
      "x": -12,
      "y": 2,
      "z": 16,
      "name": "Soil_Dirt"
    },
    {
      "x": -12,
      "y": 3,
      "z": 16,
      "name": "Soil_Grass"
    },
    {
      "x": -11,
      "y": 0,
      "z": -15,
      "name": "Soil_Dirt"
    },
    {
      "x": -11,
      "y": 1,
      "z": -15,
      "name": "Soil_Dirt"
    },
    {
      "x": -11,
      "y": 2,
      "z": -15,
      "name": "Soil_Dirt"
    },
    {
      "x": -11,
      "y": 3,
      "z": -15,
      "name": "Soil_Grass"
    },
    {
      "x": -11,
      "y": 0,
      "z": -14,
      "name": "Soil_Dirt"
    },
    {
      "x": -11,
      "y": 1,
      "z": -14,
      "name": "Soil_Dirt"
    },
    {
      "x": -11,
      "y": 2,
      "z": -14,
      "name": "Soil_Dirt"
    },
    {
      "x": -11,
      "y": 3,
      "z": -14,
      "name": "Soil_Grass"
    },
    {
      "x": -11,
      "y": 0,
      "z": -13,
      "name": "Soil_Dirt"
    },
    {
      "x": -11,
      "y": 1,
      "z": -13,
      "name": "Soil_Dirt"
    },
    {
      "x": -11,
      "y": 2,
      "z": -13,
      "name": "Soil_Dirt"
    },
    {
      "x": -11,
      "y": 3,
      "z": -13,
      "name": "Soil_Grass"
    },
    {
      "x": -11,
      "y": 0,
      "z": -12,
      "name": "Soil_Dirt"
    },
    {
      "x": -11,
      "y": 1,
      "z": -12,
      "name": "Soil_Dirt"
    },
    {
      "x": -11,
      "y": 2,
      "z": -12,
      "name": "Soil_Dirt"
    },
    {
      "x": -11,
      "y": 3,
      "z": -12,
      "name": "Soil_Grass"
    },
    {
      "x": -11,
      "y": 0,
      "z": -11,
      "name": "Soil_Dirt"
    },
    {
      "x": -11,
      "y": 1,
      "z": -11,
      "name": "Soil_Dirt"
    },
    {
      "x": -11,
      "y": 2,
      "z": -11,
      "name": "Soil_Dirt"
    },
    {
      "x": -11,
      "y": 3,
      "z": -11,
      "name": "Soil_Grass"
    },
    {
      "x": -11,
      "y": 0,
      "z": -10,
      "name": "Soil_Dirt"
    },
    {
      "x": -11,
      "y": 1,
      "z": -10,
      "name": "Soil_Dirt"
    },
    {
      "x": -11,
      "y": 2,
      "z": -10,
      "name": "Soil_Dirt"
    },
    {
      "x": -11,
      "y": 3,
      "z": -10,
      "name": "Soil_Grass"
    },
    {
      "x": -11,
      "y": 0,
      "z": -9,
      "name": "Soil_Dirt"
    },
    {
      "x": -11,
      "y": 1,
      "z": -9,
      "name": "Soil_Dirt"
    },
    {
      "x": -11,
      "y": 2,
      "z": -9,
      "name": "Soil_Dirt"
    },
    {
      "x": -11,
      "y": 3,
      "z": -9,
      "name": "Soil_Grass"
    },
    {
      "x": -11,
      "y": 0,
      "z": -8,
      "name": "Soil_Dirt"
    },
    {
      "x": -11,
      "y": 1,
      "z": -8,
      "name": "Soil_Dirt"
    },
    {
      "x": -11,
      "y": 2,
      "z": -8,
      "name": "Soil_Dirt"
    },
    {
      "x": -11,
      "y": 3,
      "z": -8,
      "name": "Soil_Grass"
    },
    {
      "x": -11,
      "y": 0,
      "z": -7,
      "name": "Soil_Dirt"
    },
    {
      "x": -11,
      "y": 1,
      "z": -7,
      "name": "Soil_Dirt"
    },
    {
      "x": -11,
      "y": 2,
      "z": -7,
      "name": "Soil_Dirt"
    },
    {
      "x": -11,
      "y": 3,
      "z": -7,
      "name": "Soil_Grass"
    },
    {
      "x": -11,
      "y": 0,
      "z": -6,
      "name": "Soil_Dirt"
    },
    {
      "x": -11,
      "y": 1,
      "z": -6,
      "name": "Soil_Dirt"
    },
    {
      "x": -11,
      "y": 2,
      "z": -6,
      "name": "Soil_Dirt"
    },
    {
      "x": -11,
      "y": 3,
      "z": -6,
      "name": "Soil_Grass"
    },
    {
      "x": -11,
      "y": 0,
      "z": -5,
      "name": "Soil_Dirt"
    },
    {
      "x": -11,
      "y": 1,
      "z": -5,
      "name": "Soil_Dirt"
    },
    {
      "x": -11,
      "y": 2,
      "z": -5,
      "name": "Soil_Dirt"
    },
    {
      "x": -11,
      "y": 3,
      "z": -5,
      "name": "Soil_Grass"
    },
    {
      "x": -11,
      "y": 0,
      "z": -4,
      "name": "Soil_Dirt"
    },
    {
      "x": -11,
      "y": 1,
      "z": -4,
      "name": "Soil_Dirt"
    },
    {
      "x": -11,
      "y": 2,
      "z": -4,
      "name": "Soil_Dirt"
    },
    {
      "x": -11,
      "y": 3,
      "z": -4,
      "name": "Soil_Grass"
    },
    {
      "x": -11,
      "y": 0,
      "z": -3,
      "name": "Soil_Dirt"
    },
    {
      "x": -11,
      "y": 1,
      "z": -3,
      "name": "Soil_Dirt"
    },
    {
      "x": -11,
      "y": 2,
      "z": -3,
      "name": "Soil_Dirt"
    },
    {
      "x": -11,
      "y": 3,
      "z": -3,
      "name": "Soil_Grass"
    },
    {
      "x": -11,
      "y": 0,
      "z": -2,
      "name": "Soil_Dirt"
    },
    {
      "x": -11,
      "y": 1,
      "z": -2,
      "name": "Soil_Dirt"
    },
    {
      "x": -11,
      "y": 2,
      "z": -2,
      "name": "Soil_Dirt"
    },
    {
      "x": -11,
      "y": 3,
      "z": -2,
      "name": "Soil_Grass"
    },
    {
      "x": -11,
      "y": 0,
      "z": -1,
      "name": "Soil_Dirt"
    },
    {
      "x": -11,
      "y": 1,
      "z": -1,
      "name": "Soil_Dirt"
    },
    {
      "x": -11,
      "y": 2,
      "z": -1,
      "name": "Soil_Dirt"
    },
    {
      "x": -11,
      "y": 3,
      "z": -1,
      "name": "Soil_Grass"
    },
    {
      "x": -11,
      "y": 0,
      "z": 0,
      "name": "Soil_Dirt"
    },
    {
      "x": -11,
      "y": 1,
      "z": 0,
      "name": "Soil_Dirt"
    },
    {
      "x": -11,
      "y": 2,
      "z": 0,
      "name": "Soil_Dirt"
    },
    {
      "x": -11,
      "y": 3,
      "z": 0,
      "name": "Soil_Grass"
    },
    {
      "x": -11,
      "y": 0,
      "z": 1,
      "name": "Soil_Dirt"
    },
    {
      "x": -11,
      "y": 1,
      "z": 1,
      "name": "Soil_Dirt"
    },
    {
      "x": -11,
      "y": 2,
      "z": 1,
      "name": "Soil_Dirt"
    },
    {
      "x": -11,
      "y": 3,
      "z": 1,
      "name": "Soil_Grass"
    },
    {
      "x": -11,
      "y": 0,
      "z": 2,
      "name": "Soil_Dirt"
    },
    {
      "x": -11,
      "y": 1,
      "z": 2,
      "name": "Soil_Dirt"
    },
    {
      "x": -11,
      "y": 2,
      "z": 2,
      "name": "Soil_Dirt"
    },
    {
      "x": -11,
      "y": 3,
      "z": 2,
      "name": "Soil_Grass"
    },
    {
      "x": -11,
      "y": 0,
      "z": 3,
      "name": "Soil_Dirt"
    },
    {
      "x": -11,
      "y": 1,
      "z": 3,
      "name": "Soil_Dirt"
    },
    {
      "x": -11,
      "y": 2,
      "z": 3,
      "name": "Soil_Dirt"
    },
    {
      "x": -11,
      "y": 3,
      "z": 3,
      "name": "Soil_Grass"
    },
    {
      "x": -11,
      "y": 0,
      "z": 4,
      "name": "Soil_Dirt"
    },
    {
      "x": -11,
      "y": 1,
      "z": 4,
      "name": "Soil_Dirt"
    },
    {
      "x": -11,
      "y": 2,
      "z": 4,
      "name": "Soil_Dirt"
    },
    {
      "x": -11,
      "y": 3,
      "z": 4,
      "name": "Soil_Grass"
    },
    {
      "x": -11,
      "y": 0,
      "z": 5,
      "name": "Soil_Dirt"
    },
    {
      "x": -11,
      "y": 1,
      "z": 5,
      "name": "Soil_Dirt"
    },
    {
      "x": -11,
      "y": 2,
      "z": 5,
      "name": "Soil_Dirt"
    },
    {
      "x": -11,
      "y": 3,
      "z": 5,
      "name": "Soil_Grass"
    },
    {
      "x": -11,
      "y": 0,
      "z": 6,
      "name": "Soil_Dirt"
    },
    {
      "x": -11,
      "y": 1,
      "z": 6,
      "name": "Soil_Dirt"
    },
    {
      "x": -11,
      "y": 2,
      "z": 6,
      "name": "Soil_Dirt"
    },
    {
      "x": -11,
      "y": 3,
      "z": 6,
      "name": "Soil_Grass"
    },
    {
      "x": -11,
      "y": 0,
      "z": 7,
      "name": "Soil_Dirt"
    },
    {
      "x": -11,
      "y": 1,
      "z": 7,
      "name": "Soil_Dirt"
    },
    {
      "x": -11,
      "y": 2,
      "z": 7,
      "name": "Soil_Dirt"
    },
    {
      "x": -11,
      "y": 3,
      "z": 7,
      "name": "Soil_Grass"
    },
    {
      "x": -11,
      "y": 0,
      "z": 8,
      "name": "Soil_Dirt"
    },
    {
      "x": -11,
      "y": 1,
      "z": 8,
      "name": "Soil_Dirt"
    },
    {
      "x": -11,
      "y": 2,
      "z": 8,
      "name": "Soil_Dirt"
    },
    {
      "x": -11,
      "y": 3,
      "z": 8,
      "name": "Soil_Grass"
    },
    {
      "x": -11,
      "y": 0,
      "z": 9,
      "name": "Soil_Dirt"
    },
    {
      "x": -11,
      "y": 1,
      "z": 9,
      "name": "Soil_Dirt"
    },
    {
      "x": -11,
      "y": 2,
      "z": 9,
      "name": "Soil_Dirt"
    },
    {
      "x": -11,
      "y": 3,
      "z": 9,
      "name": "Soil_Grass"
    },
    {
      "x": -11,
      "y": 0,
      "z": 10,
      "name": "Soil_Dirt"
    },
    {
      "x": -11,
      "y": 1,
      "z": 10,
      "name": "Soil_Dirt"
    },
    {
      "x": -11,
      "y": 2,
      "z": 10,
      "name": "Soil_Dirt"
    },
    {
      "x": -11,
      "y": 3,
      "z": 10,
      "name": "Soil_Grass"
    },
    {
      "x": -11,
      "y": 0,
      "z": 11,
      "name": "Soil_Dirt"
    },
    {
      "x": -11,
      "y": 1,
      "z": 11,
      "name": "Soil_Dirt"
    },
    {
      "x": -11,
      "y": 2,
      "z": 11,
      "name": "Soil_Dirt"
    },
    {
      "x": -11,
      "y": 3,
      "z": 11,
      "name": "Soil_Grass"
    },
    {
      "x": -11,
      "y": 0,
      "z": 12,
      "name": "Soil_Dirt"
    },
    {
      "x": -11,
      "y": 1,
      "z": 12,
      "name": "Soil_Dirt"
    },
    {
      "x": -11,
      "y": 2,
      "z": 12,
      "name": "Soil_Dirt"
    },
    {
      "x": -11,
      "y": 3,
      "z": 12,
      "name": "Soil_Grass"
    },
    {
      "x": -11,
      "y": 0,
      "z": 13,
      "name": "Soil_Dirt"
    },
    {
      "x": -11,
      "y": 1,
      "z": 13,
      "name": "Soil_Dirt"
    },
    {
      "x": -11,
      "y": 2,
      "z": 13,
      "name": "Soil_Dirt"
    },
    {
      "x": -11,
      "y": 3,
      "z": 13,
      "name": "Soil_Grass"
    },
    {
      "x": -11,
      "y": 0,
      "z": 14,
      "name": "Soil_Dirt"
    },
    {
      "x": -11,
      "y": 1,
      "z": 14,
      "name": "Soil_Dirt"
    },
    {
      "x": -11,
      "y": 2,
      "z": 14,
      "name": "Soil_Dirt"
    },
    {
      "x": -11,
      "y": 3,
      "z": 14,
      "name": "Soil_Grass"
    },
    {
      "x": -11,
      "y": 0,
      "z": 15,
      "name": "Soil_Dirt"
    },
    {
      "x": -11,
      "y": 1,
      "z": 15,
      "name": "Soil_Dirt"
    },
    {
      "x": -11,
      "y": 2,
      "z": 15,
      "name": "Soil_Dirt"
    },
    {
      "x": -11,
      "y": 3,
      "z": 15,
      "name": "Soil_Grass"
    },
    {
      "x": -11,
      "y": 0,
      "z": 16,
      "name": "Soil_Dirt"
    },
    {
      "x": -11,
      "y": 1,
      "z": 16,
      "name": "Soil_Dirt"
    },
    {
      "x": -11,
      "y": 2,
      "z": 16,
      "name": "Soil_Dirt"
    },
    {
      "x": -11,
      "y": 3,
      "z": 16,
      "name": "Soil_Grass"
    },
    {
      "x": -10,
      "y": 0,
      "z": -15,
      "name": "Soil_Dirt"
    },
    {
      "x": -10,
      "y": 1,
      "z": -15,
      "name": "Soil_Dirt"
    },
    {
      "x": -10,
      "y": 2,
      "z": -15,
      "name": "Soil_Dirt"
    },
    {
      "x": -10,
      "y": 3,
      "z": -15,
      "name": "Soil_Grass"
    },
    {
      "x": -10,
      "y": 0,
      "z": -14,
      "name": "Soil_Dirt"
    },
    {
      "x": -10,
      "y": 1,
      "z": -14,
      "name": "Soil_Dirt"
    },
    {
      "x": -10,
      "y": 2,
      "z": -14,
      "name": "Soil_Dirt"
    },
    {
      "x": -10,
      "y": 3,
      "z": -14,
      "name": "Soil_Grass"
    },
    {
      "x": -10,
      "y": 0,
      "z": -13,
      "name": "Soil_Dirt"
    },
    {
      "x": -10,
      "y": 1,
      "z": -13,
      "name": "Soil_Dirt"
    },
    {
      "x": -10,
      "y": 2,
      "z": -13,
      "name": "Soil_Dirt"
    },
    {
      "x": -10,
      "y": 3,
      "z": -13,
      "name": "Soil_Grass"
    },
    {
      "x": -10,
      "y": 0,
      "z": -12,
      "name": "Soil_Dirt"
    },
    {
      "x": -10,
      "y": 1,
      "z": -12,
      "name": "Soil_Dirt"
    },
    {
      "x": -10,
      "y": 2,
      "z": -12,
      "name": "Soil_Dirt"
    },
    {
      "x": -10,
      "y": 3,
      "z": -12,
      "name": "Soil_Grass"
    },
    {
      "x": -10,
      "y": 0,
      "z": -11,
      "name": "Soil_Dirt"
    },
    {
      "x": -10,
      "y": 1,
      "z": -11,
      "name": "Soil_Dirt"
    },
    {
      "x": -10,
      "y": 2,
      "z": -11,
      "name": "Soil_Dirt"
    },
    {
      "x": -10,
      "y": 3,
      "z": -11,
      "name": "Soil_Grass"
    },
    {
      "x": -10,
      "y": 0,
      "z": -10,
      "name": "Soil_Dirt"
    },
    {
      "x": -10,
      "y": 1,
      "z": -10,
      "name": "Soil_Dirt"
    },
    {
      "x": -10,
      "y": 2,
      "z": -10,
      "name": "Soil_Dirt"
    },
    {
      "x": -10,
      "y": 3,
      "z": -10,
      "name": "Soil_Grass"
    },
    {
      "x": -10,
      "y": 0,
      "z": -9,
      "name": "Soil_Dirt"
    },
    {
      "x": -10,
      "y": 1,
      "z": -9,
      "name": "Soil_Dirt"
    },
    {
      "x": -10,
      "y": 2,
      "z": -9,
      "name": "Soil_Dirt"
    },
    {
      "x": -10,
      "y": 3,
      "z": -9,
      "name": "Soil_Dirt"
    },
    {
      "x": -10,
      "y": 4,
      "z": -9,
      "name": "Rock_Calcite_Brick_Decorative"
    },
    {
      "x": -10,
      "y": 5,
      "z": -9,
      "name": "Rock_Lime_Brick_Smooth"
    },
    {
      "x": -10,
      "y": 6,
      "z": -9,
      "name": "Rock_Lime_Brick_Smooth"
    },
    {
      "x": -10,
      "y": 7,
      "z": -9,
      "name": "Rock_Lime_Brick_Smooth"
    },
    {
      "x": -10,
      "y": 8,
      "z": -9,
      "name": "Rock_Calcite_Brick_Smooth_Half"
    },
    {
      "x": -10,
      "y": 0,
      "z": -8,
      "name": "Soil_Dirt"
    },
    {
      "x": -10,
      "y": 1,
      "z": -8,
      "name": "Soil_Dirt"
    },
    {
      "x": -10,
      "y": 2,
      "z": -8,
      "name": "Soil_Dirt"
    },
    {
      "x": -10,
      "y": 3,
      "z": -8,
      "name": "Soil_Dirt"
    },
    {
      "x": -10,
      "y": 4,
      "z": -8,
      "name": "Rock_Calcite_Brick_Decorative"
    },
    {
      "x": -10,
      "y": 5,
      "z": -8,
      "name": "Rock_Lime_Brick_Smooth"
    },
    {
      "x": -10,
      "y": 6,
      "z": -8,
      "name": "Rock_Lime_Brick_Smooth"
    },
    {
      "x": -10,
      "y": 7,
      "z": -8,
      "name": "Rock_Lime_Brick_Smooth"
    },
    {
      "x": -10,
      "y": 8,
      "z": -8,
      "name": "Rock_Calcite_Brick_Smooth_Half"
    },
    {
      "x": -10,
      "y": 0,
      "z": -7,
      "name": "Soil_Dirt"
    },
    {
      "x": -10,
      "y": 1,
      "z": -7,
      "name": "Soil_Dirt"
    },
    {
      "x": -10,
      "y": 2,
      "z": -7,
      "name": "Soil_Dirt"
    },
    {
      "x": -10,
      "y": 3,
      "z": -7,
      "name": "Soil_Dirt"
    },
    {
      "x": -10,
      "y": 4,
      "z": -7,
      "name": "Rock_Calcite_Brick_Decorative"
    },
    {
      "x": -10,
      "y": 5,
      "z": -7,
      "name": "Furniture_Temple_Dark_Window",
      "rotation": 1
    },
    {
      "x": -10,
      "y": 6,
      "z": -7,
      "name": "Furniture_Temple_Dark_Window",
      "rotation": 1
    },
    {
      "x": -10,
      "y": 7,
      "z": -7,
      "name": "Rock_Lime_Brick_Smooth"
    },
    {
      "x": -10,
      "y": 8,
      "z": -7,
      "name": "Rock_Calcite_Brick_Smooth_Half"
    },
    {
      "x": -10,
      "y": 0,
      "z": -6,
      "name": "Soil_Dirt"
    },
    {
      "x": -10,
      "y": 1,
      "z": -6,
      "name": "Soil_Dirt"
    },
    {
      "x": -10,
      "y": 2,
      "z": -6,
      "name": "Soil_Dirt"
    },
    {
      "x": -10,
      "y": 3,
      "z": -6,
      "name": "Soil_Dirt"
    },
    {
      "x": -10,
      "y": 4,
      "z": -6,
      "name": "Rock_Calcite_Brick_Decorative"
    },
    {
      "x": -10,
      "y": 5,
      "z": -6,
      "name": "Rock_Lime_Brick_Smooth"
    },
    {
      "x": -10,
      "y": 6,
      "z": -6,
      "name": "Rock_Lime_Brick_Smooth"
    },
    {
      "x": -10,
      "y": 7,
      "z": -6,
      "name": "Rock_Lime_Brick_Smooth"
    },
    {
      "x": -10,
      "y": 8,
      "z": -6,
      "name": "Rock_Calcite_Brick_Smooth_Half"
    },
    {
      "x": -10,
      "y": 0,
      "z": -5,
      "name": "Soil_Dirt"
    },
    {
      "x": -10,
      "y": 1,
      "z": -5,
      "name": "Soil_Dirt"
    },
    {
      "x": -10,
      "y": 2,
      "z": -5,
      "name": "Soil_Dirt"
    },
    {
      "x": -10,
      "y": 3,
      "z": -5,
      "name": "Soil_Dirt"
    },
    {
      "x": -10,
      "y": 4,
      "z": -5,
      "name": "Rock_Calcite_Brick_Decorative"
    },
    {
      "x": -10,
      "y": 5,
      "z": -5,
      "name": "Furniture_Temple_Dark_Window",
      "rotation": 1
    },
    {
      "x": -10,
      "y": 6,
      "z": -5,
      "name": "Furniture_Temple_Dark_Window",
      "rotation": 1
    },
    {
      "x": -10,
      "y": 7,
      "z": -5,
      "name": "Rock_Lime_Brick_Smooth"
    },
    {
      "x": -10,
      "y": 8,
      "z": -5,
      "name": "Rock_Calcite_Brick_Smooth_Half"
    },
    {
      "x": -10,
      "y": 0,
      "z": -4,
      "name": "Soil_Dirt"
    },
    {
      "x": -10,
      "y": 1,
      "z": -4,
      "name": "Soil_Dirt"
    },
    {
      "x": -10,
      "y": 2,
      "z": -4,
      "name": "Soil_Dirt"
    },
    {
      "x": -10,
      "y": 3,
      "z": -4,
      "name": "Soil_Dirt"
    },
    {
      "x": -10,
      "y": 4,
      "z": -4,
      "name": "Rock_Calcite_Brick_Decorative"
    },
    {
      "x": -10,
      "y": 5,
      "z": -4,
      "name": "Rock_Lime_Brick_Smooth"
    },
    {
      "x": -10,
      "y": 6,
      "z": -4,
      "name": "Rock_Lime_Brick_Smooth"
    },
    {
      "x": -10,
      "y": 7,
      "z": -4,
      "name": "Rock_Lime_Brick_Smooth"
    },
    {
      "x": -10,
      "y": 8,
      "z": -4,
      "name": "Rock_Calcite_Brick_Smooth_Half"
    },
    {
      "x": -10,
      "y": 0,
      "z": -3,
      "name": "Soil_Dirt"
    },
    {
      "x": -10,
      "y": 1,
      "z": -3,
      "name": "Soil_Dirt"
    },
    {
      "x": -10,
      "y": 2,
      "z": -3,
      "name": "Soil_Dirt"
    },
    {
      "x": -10,
      "y": 3,
      "z": -3,
      "name": "Soil_Dirt"
    },
    {
      "x": -10,
      "y": 4,
      "z": -3,
      "name": "Rock_Calcite_Brick_Decorative"
    },
    {
      "x": -10,
      "y": 5,
      "z": -3,
      "name": "Furniture_Temple_Dark_Window",
      "rotation": 1
    },
    {
      "x": -10,
      "y": 6,
      "z": -3,
      "name": "Furniture_Temple_Dark_Window",
      "rotation": 1
    },
    {
      "x": -10,
      "y": 7,
      "z": -3,
      "name": "Rock_Lime_Brick_Smooth"
    },
    {
      "x": -10,
      "y": 8,
      "z": -3,
      "name": "Rock_Calcite_Brick_Smooth_Half"
    },
    {
      "x": -10,
      "y": 0,
      "z": -2,
      "name": "Soil_Dirt"
    },
    {
      "x": -10,
      "y": 1,
      "z": -2,
      "name": "Soil_Dirt"
    },
    {
      "x": -10,
      "y": 2,
      "z": -2,
      "name": "Soil_Dirt"
    },
    {
      "x": -10,
      "y": 3,
      "z": -2,
      "name": "Soil_Dirt"
    },
    {
      "x": -10,
      "y": 4,
      "z": -2,
      "name": "Rock_Calcite_Brick_Decorative"
    },
    {
      "x": -10,
      "y": 5,
      "z": -2,
      "name": "Rock_Lime_Brick_Smooth"
    },
    {
      "x": -10,
      "y": 6,
      "z": -2,
      "name": "Rock_Lime_Brick_Smooth"
    },
    {
      "x": -10,
      "y": 7,
      "z": -2,
      "name": "Rock_Lime_Brick_Smooth"
    },
    {
      "x": -10,
      "y": 8,
      "z": -2,
      "name": "Rock_Calcite_Brick_Smooth_Half"
    },
    {
      "x": -10,
      "y": 0,
      "z": -1,
      "name": "Soil_Dirt"
    },
    {
      "x": -10,
      "y": 1,
      "z": -1,
      "name": "Soil_Dirt"
    },
    {
      "x": -10,
      "y": 2,
      "z": -1,
      "name": "Soil_Dirt"
    },
    {
      "x": -10,
      "y": 3,
      "z": -1,
      "name": "Soil_Dirt"
    },
    {
      "x": -10,
      "y": 4,
      "z": -1,
      "name": "Rock_Calcite_Brick_Decorative"
    },
    {
      "x": -10,
      "y": 5,
      "z": -1,
      "name": "Rock_Lime_Brick_Smooth"
    },
    {
      "x": -10,
      "y": 6,
      "z": -1,
      "name": "Rock_Lime_Brick_Smooth"
    },
    {
      "x": -10,
      "y": 7,
      "z": -1,
      "name": "Rock_Lime_Brick_Smooth"
    },
    {
      "x": -10,
      "y": 8,
      "z": -1,
      "name": "Rock_Calcite_Brick_Smooth_Half"
    },
    {
      "x": -10,
      "y": 0,
      "z": 0,
      "name": "Soil_Dirt"
    },
    {
      "x": -10,
      "y": 1,
      "z": 0,
      "name": "Soil_Dirt"
    },
    {
      "x": -10,
      "y": 2,
      "z": 0,
      "name": "Soil_Dirt"
    },
    {
      "x": -10,
      "y": 3,
      "z": 0,
      "name": "Soil_Grass"
    },
    {
      "x": -10,
      "y": 0,
      "z": 1,
      "name": "Soil_Dirt"
    },
    {
      "x": -10,
      "y": 1,
      "z": 1,
      "name": "Soil_Dirt"
    },
    {
      "x": -10,
      "y": 2,
      "z": 1,
      "name": "Soil_Dirt"
    },
    {
      "x": -10,
      "y": 3,
      "z": 1,
      "name": "Soil_Grass"
    },
    {
      "x": -10,
      "y": 0,
      "z": 2,
      "name": "Soil_Dirt"
    },
    {
      "x": -10,
      "y": 1,
      "z": 2,
      "name": "Soil_Dirt"
    },
    {
      "x": -10,
      "y": 2,
      "z": 2,
      "name": "Soil_Dirt"
    },
    {
      "x": -10,
      "y": 3,
      "z": 2,
      "name": "Soil_Grass"
    },
    {
      "x": -10,
      "y": 0,
      "z": 3,
      "name": "Soil_Dirt"
    },
    {
      "x": -10,
      "y": 1,
      "z": 3,
      "name": "Soil_Dirt"
    },
    {
      "x": -10,
      "y": 2,
      "z": 3,
      "name": "Soil_Dirt"
    },
    {
      "x": -10,
      "y": 3,
      "z": 3,
      "name": "Soil_Grass"
    },
    {
      "x": -10,
      "y": 0,
      "z": 4,
      "name": "Soil_Dirt"
    },
    {
      "x": -10,
      "y": 1,
      "z": 4,
      "name": "Soil_Dirt"
    },
    {
      "x": -10,
      "y": 2,
      "z": 4,
      "name": "Soil_Dirt"
    },
    {
      "x": -10,
      "y": 3,
      "z": 4,
      "name": "Soil_Grass"
    },
    {
      "x": -10,
      "y": 0,
      "z": 5,
      "name": "Soil_Dirt"
    },
    {
      "x": -10,
      "y": 1,
      "z": 5,
      "name": "Soil_Dirt"
    },
    {
      "x": -10,
      "y": 2,
      "z": 5,
      "name": "Soil_Dirt"
    },
    {
      "x": -10,
      "y": 3,
      "z": 5,
      "name": "Soil_Grass"
    },
    {
      "x": -10,
      "y": 0,
      "z": 6,
      "name": "Soil_Dirt"
    },
    {
      "x": -10,
      "y": 1,
      "z": 6,
      "name": "Soil_Dirt"
    },
    {
      "x": -10,
      "y": 2,
      "z": 6,
      "name": "Soil_Dirt"
    },
    {
      "x": -10,
      "y": 3,
      "z": 6,
      "name": "Soil_Grass"
    },
    {
      "x": -10,
      "y": 0,
      "z": 7,
      "name": "Soil_Dirt"
    },
    {
      "x": -10,
      "y": 1,
      "z": 7,
      "name": "Soil_Dirt"
    },
    {
      "x": -10,
      "y": 2,
      "z": 7,
      "name": "Soil_Dirt"
    },
    {
      "x": -10,
      "y": 3,
      "z": 7,
      "name": "Soil_Grass"
    },
    {
      "x": -10,
      "y": 0,
      "z": 8,
      "name": "Soil_Dirt"
    },
    {
      "x": -10,
      "y": 1,
      "z": 8,
      "name": "Soil_Dirt"
    },
    {
      "x": -10,
      "y": 2,
      "z": 8,
      "name": "Soil_Dirt"
    },
    {
      "x": -10,
      "y": 3,
      "z": 8,
      "name": "Soil_Grass"
    },
    {
      "x": -10,
      "y": 0,
      "z": 9,
      "name": "Soil_Dirt"
    },
    {
      "x": -10,
      "y": 1,
      "z": 9,
      "name": "Soil_Dirt"
    },
    {
      "x": -10,
      "y": 2,
      "z": 9,
      "name": "Soil_Dirt"
    },
    {
      "x": -10,
      "y": 3,
      "z": 9,
      "name": "Soil_Grass"
    },
    {
      "x": -10,
      "y": 0,
      "z": 10,
      "name": "Soil_Dirt"
    },
    {
      "x": -10,
      "y": 1,
      "z": 10,
      "name": "Soil_Dirt"
    },
    {
      "x": -10,
      "y": 2,
      "z": 10,
      "name": "Soil_Dirt"
    },
    {
      "x": -10,
      "y": 3,
      "z": 10,
      "name": "Soil_Grass"
    },
    {
      "x": -10,
      "y": 0,
      "z": 11,
      "name": "Soil_Dirt"
    },
    {
      "x": -10,
      "y": 1,
      "z": 11,
      "name": "Soil_Dirt"
    },
    {
      "x": -10,
      "y": 2,
      "z": 11,
      "name": "Soil_Dirt"
    },
    {
      "x": -10,
      "y": 3,
      "z": 11,
      "name": "Soil_Grass"
    },
    {
      "x": -10,
      "y": 0,
      "z": 12,
      "name": "Soil_Dirt"
    },
    {
      "x": -10,
      "y": 1,
      "z": 12,
      "name": "Soil_Dirt"
    },
    {
      "x": -10,
      "y": 2,
      "z": 12,
      "name": "Soil_Dirt"
    },
    {
      "x": -10,
      "y": 3,
      "z": 12,
      "name": "Soil_Grass"
    },
    {
      "x": -10,
      "y": 0,
      "z": 13,
      "name": "Soil_Dirt"
    },
    {
      "x": -10,
      "y": 1,
      "z": 13,
      "name": "Soil_Dirt"
    },
    {
      "x": -10,
      "y": 2,
      "z": 13,
      "name": "Soil_Dirt"
    },
    {
      "x": -10,
      "y": 3,
      "z": 13,
      "name": "Soil_Grass"
    },
    {
      "x": -10,
      "y": 0,
      "z": 14,
      "name": "Soil_Dirt"
    },
    {
      "x": -10,
      "y": 1,
      "z": 14,
      "name": "Soil_Dirt"
    },
    {
      "x": -10,
      "y": 2,
      "z": 14,
      "name": "Soil_Dirt"
    },
    {
      "x": -10,
      "y": 3,
      "z": 14,
      "name": "Soil_Grass"
    },
    {
      "x": -10,
      "y": 0,
      "z": 15,
      "name": "Soil_Dirt"
    },
    {
      "x": -10,
      "y": 1,
      "z": 15,
      "name": "Soil_Dirt"
    },
    {
      "x": -10,
      "y": 2,
      "z": 15,
      "name": "Soil_Dirt"
    },
    {
      "x": -10,
      "y": 3,
      "z": 15,
      "name": "Soil_Grass"
    },
    {
      "x": -10,
      "y": 0,
      "z": 16,
      "name": "Soil_Dirt"
    },
    {
      "x": -10,
      "y": 1,
      "z": 16,
      "name": "Soil_Dirt"
    },
    {
      "x": -10,
      "y": 2,
      "z": 16,
      "name": "Soil_Dirt"
    },
    {
      "x": -10,
      "y": 3,
      "z": 16,
      "name": "Soil_Grass"
    },
    {
      "x": -9,
      "y": 0,
      "z": -15,
      "name": "Soil_Dirt"
    },
    {
      "x": -9,
      "y": 1,
      "z": -15,
      "name": "Soil_Dirt"
    },
    {
      "x": -9,
      "y": 2,
      "z": -15,
      "name": "Soil_Dirt"
    },
    {
      "x": -9,
      "y": 3,
      "z": -15,
      "name": "Soil_Grass"
    },
    {
      "x": -9,
      "y": 0,
      "z": -14,
      "name": "Soil_Dirt"
    },
    {
      "x": -9,
      "y": 1,
      "z": -14,
      "name": "Soil_Dirt"
    },
    {
      "x": -9,
      "y": 2,
      "z": -14,
      "name": "Soil_Dirt"
    },
    {
      "x": -9,
      "y": 3,
      "z": -14,
      "name": "Soil_Grass"
    },
    {
      "x": -9,
      "y": 0,
      "z": -13,
      "name": "Soil_Dirt"
    },
    {
      "x": -9,
      "y": 1,
      "z": -13,
      "name": "Soil_Dirt"
    },
    {
      "x": -9,
      "y": 2,
      "z": -13,
      "name": "Soil_Dirt"
    },
    {
      "x": -9,
      "y": 3,
      "z": -13,
      "name": "Soil_Grass"
    },
    {
      "x": -9,
      "y": 0,
      "z": -12,
      "name": "Soil_Dirt"
    },
    {
      "x": -9,
      "y": 1,
      "z": -12,
      "name": "Soil_Dirt"
    },
    {
      "x": -9,
      "y": 2,
      "z": -12,
      "name": "Soil_Dirt"
    },
    {
      "x": -9,
      "y": 3,
      "z": -12,
      "name": "Soil_Grass"
    },
    {
      "x": -9,
      "y": 0,
      "z": -11,
      "name": "Soil_Dirt"
    },
    {
      "x": -9,
      "y": 1,
      "z": -11,
      "name": "Soil_Dirt"
    },
    {
      "x": -9,
      "y": 2,
      "z": -11,
      "name": "Soil_Dirt"
    },
    {
      "x": -9,
      "y": 3,
      "z": -11,
      "name": "Soil_Grass"
    },
    {
      "x": -9,
      "y": 0,
      "z": -10,
      "name": "Soil_Dirt"
    },
    {
      "x": -9,
      "y": 1,
      "z": -10,
      "name": "Soil_Dirt"
    },
    {
      "x": -9,
      "y": 2,
      "z": -10,
      "name": "Soil_Dirt"
    },
    {
      "x": -9,
      "y": 3,
      "z": -10,
      "name": "K2_Slot_Pad_4"
    },
    {
      "x": -9,
      "y": 0,
      "z": -9,
      "name": "Soil_Dirt"
    },
    {
      "x": -9,
      "y": 1,
      "z": -9,
      "name": "Soil_Dirt"
    },
    {
      "x": -9,
      "y": 2,
      "z": -9,
      "name": "Soil_Dirt"
    },
    {
      "x": -9,
      "y": 3,
      "z": -9,
      "name": "Soil_Dirt"
    },
    {
      "x": -9,
      "y": 4,
      "z": -9,
      "name": "Rock_Calcite_Brick_Decorative"
    },
    {
      "x": -9,
      "y": 5,
      "z": -9,
      "name": "Rock_Lime_Brick_Smooth"
    },
    {
      "x": -9,
      "y": 6,
      "z": -9,
      "name": "Rock_Lime_Brick_Smooth"
    },
    {
      "x": -9,
      "y": 7,
      "z": -9,
      "name": "Rock_Lime_Brick_Smooth"
    },
    {
      "x": -9,
      "y": 8,
      "z": -9,
      "name": "Rock_Calcite_Brick_Smooth_Half"
    },
    {
      "x": -9,
      "y": 0,
      "z": -8,
      "name": "Soil_Dirt"
    },
    {
      "x": -9,
      "y": 1,
      "z": -8,
      "name": "Soil_Dirt"
    },
    {
      "x": -9,
      "y": 2,
      "z": -8,
      "name": "Soil_Dirt"
    },
    {
      "x": -9,
      "y": 3,
      "z": -8,
      "name": "Rock_Slate_Brick_Smooth"
    },
    {
      "x": -9,
      "y": 4,
      "z": -8,
      "name": "K2_Slot_Station_Wash"
    },
    {
      "x": -9,
      "y": 6,
      "z": -8,
      "name": "Build_Lightsource_White",
      "rotation": 4
    },
    {
      "x": -9,
      "y": 7,
      "z": -8,
      "name": "Rock_Calcite_Brick_Smooth_Half",
      "rotation": 8
    },
    {
      "x": -9,
      "y": 0,
      "z": -7,
      "name": "Soil_Dirt"
    },
    {
      "x": -9,
      "y": 1,
      "z": -7,
      "name": "Soil_Dirt"
    },
    {
      "x": -9,
      "y": 2,
      "z": -7,
      "name": "Soil_Dirt"
    },
    {
      "x": -9,
      "y": 3,
      "z": -7,
      "name": "Rock_Chalk_Brick_Smooth"
    },
    {
      "x": -9,
      "y": 4,
      "z": -7,
      "name": "K2_Slot_Station_Rack"
    },
    {
      "x": -9,
      "y": 7,
      "z": -7,
      "name": "Rock_Calcite_Brick_Smooth_Half",
      "rotation": 8
    },
    {
      "x": -9,
      "y": 0,
      "z": -6,
      "name": "Soil_Dirt"
    },
    {
      "x": -9,
      "y": 1,
      "z": -6,
      "name": "Soil_Dirt"
    },
    {
      "x": -9,
      "y": 2,
      "z": -6,
      "name": "Soil_Dirt"
    },
    {
      "x": -9,
      "y": 3,
      "z": -6,
      "name": "Rock_Slate_Brick_Smooth"
    },
    {
      "x": -9,
      "y": 4,
      "z": -6,
      "name": "K2_Slot_Station_Press"
    },
    {
      "x": -9,
      "y": 7,
      "z": -6,
      "name": "Rock_Calcite_Brick_Smooth_Half",
      "rotation": 8
    },
    {
      "x": -9,
      "y": 0,
      "z": -5,
      "name": "Soil_Dirt"
    },
    {
      "x": -9,
      "y": 1,
      "z": -5,
      "name": "Soil_Dirt"
    },
    {
      "x": -9,
      "y": 2,
      "z": -5,
      "name": "Soil_Dirt"
    },
    {
      "x": -9,
      "y": 3,
      "z": -5,
      "name": "Rock_Chalk_Brick_Smooth"
    },
    {
      "x": -9,
      "y": 4,
      "z": -5,
      "name": "K2_Slot_Station_Heat"
    },
    {
      "x": -9,
      "y": 7,
      "z": -5,
      "name": "Rock_Calcite_Brick_Smooth_Half",
      "rotation": 8
    },
    {
      "x": -9,
      "y": 0,
      "z": -4,
      "name": "Soil_Dirt"
    },
    {
      "x": -9,
      "y": 1,
      "z": -4,
      "name": "Soil_Dirt"
    },
    {
      "x": -9,
      "y": 2,
      "z": -4,
      "name": "Soil_Dirt"
    },
    {
      "x": -9,
      "y": 3,
      "z": -4,
      "name": "Rock_Slate_Brick_Smooth"
    },
    {
      "x": -9,
      "y": 7,
      "z": -4,
      "name": "Rock_Calcite_Brick_Smooth_Half",
      "rotation": 8
    },
    {
      "x": -9,
      "y": 0,
      "z": -3,
      "name": "Soil_Dirt"
    },
    {
      "x": -9,
      "y": 1,
      "z": -3,
      "name": "Soil_Dirt"
    },
    {
      "x": -9,
      "y": 2,
      "z": -3,
      "name": "Soil_Dirt"
    },
    {
      "x": -9,
      "y": 3,
      "z": -3,
      "name": "Rock_Chalk_Brick_Smooth"
    },
    {
      "x": -9,
      "y": 7,
      "z": -3,
      "name": "Rock_Calcite_Brick_Smooth_Half",
      "rotation": 8
    },
    {
      "x": -9,
      "y": 0,
      "z": -2,
      "name": "Soil_Dirt"
    },
    {
      "x": -9,
      "y": 1,
      "z": -2,
      "name": "Soil_Dirt"
    },
    {
      "x": -9,
      "y": 2,
      "z": -2,
      "name": "Soil_Dirt"
    },
    {
      "x": -9,
      "y": 3,
      "z": -2,
      "name": "Rock_Slate_Brick_Smooth"
    },
    {
      "x": -9,
      "y": 4,
      "z": -2,
      "name": "K2_Slot_Station_Bin"
    },
    {
      "x": -9,
      "y": 6,
      "z": -2,
      "name": "Build_Lightsource_White",
      "rotation": 4
    },
    {
      "x": -9,
      "y": 7,
      "z": -2,
      "name": "Rock_Calcite_Brick_Smooth_Half",
      "rotation": 8
    },
    {
      "x": -9,
      "y": 0,
      "z": -1,
      "name": "Soil_Dirt"
    },
    {
      "x": -9,
      "y": 1,
      "z": -1,
      "name": "Soil_Dirt"
    },
    {
      "x": -9,
      "y": 2,
      "z": -1,
      "name": "Soil_Dirt"
    },
    {
      "x": -9,
      "y": 3,
      "z": -1,
      "name": "Soil_Dirt"
    },
    {
      "x": -9,
      "y": 4,
      "z": -1,
      "name": "Rock_Calcite_Brick_Decorative"
    },
    {
      "x": -9,
      "y": 5,
      "z": -1,
      "name": "Rock_Lime_Brick_Smooth"
    },
    {
      "x": -9,
      "y": 6,
      "z": -1,
      "name": "Rock_Lime_Brick_Smooth"
    },
    {
      "x": -9,
      "y": 7,
      "z": -1,
      "name": "Rock_Lime_Brick_Smooth"
    },
    {
      "x": -9,
      "y": 8,
      "z": -1,
      "name": "Rock_Calcite_Brick_Smooth_Half"
    },
    {
      "x": -9,
      "y": 0,
      "z": 0,
      "name": "Soil_Dirt"
    },
    {
      "x": -9,
      "y": 1,
      "z": 0,
      "name": "Soil_Dirt"
    },
    {
      "x": -9,
      "y": 2,
      "z": 0,
      "name": "Soil_Dirt"
    },
    {
      "x": -9,
      "y": 3,
      "z": 0,
      "name": "Soil_Grass"
    },
    {
      "x": -9,
      "y": 0,
      "z": 1,
      "name": "Soil_Dirt"
    },
    {
      "x": -9,
      "y": 1,
      "z": 1,
      "name": "Soil_Dirt"
    },
    {
      "x": -9,
      "y": 2,
      "z": 1,
      "name": "Soil_Dirt"
    },
    {
      "x": -9,
      "y": 3,
      "z": 1,
      "name": "Soil_Grass"
    },
    {
      "x": -9,
      "y": 0,
      "z": 2,
      "name": "Soil_Dirt"
    },
    {
      "x": -9,
      "y": 1,
      "z": 2,
      "name": "Soil_Dirt"
    },
    {
      "x": -9,
      "y": 2,
      "z": 2,
      "name": "Soil_Dirt"
    },
    {
      "x": -9,
      "y": 3,
      "z": 2,
      "name": "Soil_Grass"
    },
    {
      "x": -9,
      "y": 0,
      "z": 3,
      "name": "Soil_Dirt"
    },
    {
      "x": -9,
      "y": 1,
      "z": 3,
      "name": "Soil_Dirt"
    },
    {
      "x": -9,
      "y": 2,
      "z": 3,
      "name": "Soil_Dirt"
    },
    {
      "x": -9,
      "y": 3,
      "z": 3,
      "name": "Soil_Grass"
    },
    {
      "x": -9,
      "y": 0,
      "z": 4,
      "name": "Soil_Dirt"
    },
    {
      "x": -9,
      "y": 1,
      "z": 4,
      "name": "Soil_Dirt"
    },
    {
      "x": -9,
      "y": 2,
      "z": 4,
      "name": "Soil_Dirt"
    },
    {
      "x": -9,
      "y": 3,
      "z": 4,
      "name": "Soil_Grass"
    },
    {
      "x": -9,
      "y": 0,
      "z": 5,
      "name": "Soil_Dirt"
    },
    {
      "x": -9,
      "y": 1,
      "z": 5,
      "name": "Soil_Dirt"
    },
    {
      "x": -9,
      "y": 2,
      "z": 5,
      "name": "Soil_Dirt"
    },
    {
      "x": -9,
      "y": 3,
      "z": 5,
      "name": "Soil_Grass"
    },
    {
      "x": -9,
      "y": 0,
      "z": 6,
      "name": "Soil_Dirt"
    },
    {
      "x": -9,
      "y": 1,
      "z": 6,
      "name": "Soil_Dirt"
    },
    {
      "x": -9,
      "y": 2,
      "z": 6,
      "name": "Soil_Dirt"
    },
    {
      "x": -9,
      "y": 3,
      "z": 6,
      "name": "Soil_Grass"
    },
    {
      "x": -9,
      "y": 0,
      "z": 7,
      "name": "Soil_Dirt"
    },
    {
      "x": -9,
      "y": 1,
      "z": 7,
      "name": "Soil_Dirt"
    },
    {
      "x": -9,
      "y": 2,
      "z": 7,
      "name": "Soil_Dirt"
    },
    {
      "x": -9,
      "y": 3,
      "z": 7,
      "name": "Soil_Grass"
    },
    {
      "x": -9,
      "y": 0,
      "z": 8,
      "name": "Soil_Dirt"
    },
    {
      "x": -9,
      "y": 1,
      "z": 8,
      "name": "Soil_Dirt"
    },
    {
      "x": -9,
      "y": 2,
      "z": 8,
      "name": "Soil_Dirt"
    },
    {
      "x": -9,
      "y": 3,
      "z": 8,
      "name": "Soil_Grass"
    },
    {
      "x": -9,
      "y": 0,
      "z": 9,
      "name": "Soil_Dirt"
    },
    {
      "x": -9,
      "y": 1,
      "z": 9,
      "name": "Soil_Dirt"
    },
    {
      "x": -9,
      "y": 2,
      "z": 9,
      "name": "Soil_Dirt"
    },
    {
      "x": -9,
      "y": 3,
      "z": 9,
      "name": "Soil_Grass"
    },
    {
      "x": -9,
      "y": 0,
      "z": 10,
      "name": "Soil_Dirt"
    },
    {
      "x": -9,
      "y": 1,
      "z": 10,
      "name": "Soil_Dirt"
    },
    {
      "x": -9,
      "y": 2,
      "z": 10,
      "name": "Soil_Dirt"
    },
    {
      "x": -9,
      "y": 3,
      "z": 10,
      "name": "Soil_Grass"
    },
    {
      "x": -9,
      "y": 0,
      "z": 11,
      "name": "Soil_Dirt"
    },
    {
      "x": -9,
      "y": 1,
      "z": 11,
      "name": "Soil_Dirt"
    },
    {
      "x": -9,
      "y": 2,
      "z": 11,
      "name": "Soil_Dirt"
    },
    {
      "x": -9,
      "y": 3,
      "z": 11,
      "name": "Soil_Grass"
    },
    {
      "x": -9,
      "y": 0,
      "z": 12,
      "name": "Soil_Dirt"
    },
    {
      "x": -9,
      "y": 1,
      "z": 12,
      "name": "Soil_Dirt"
    },
    {
      "x": -9,
      "y": 2,
      "z": 12,
      "name": "Soil_Dirt"
    },
    {
      "x": -9,
      "y": 3,
      "z": 12,
      "name": "Soil_Grass"
    },
    {
      "x": -9,
      "y": 0,
      "z": 13,
      "name": "Soil_Dirt"
    },
    {
      "x": -9,
      "y": 1,
      "z": 13,
      "name": "Soil_Dirt"
    },
    {
      "x": -9,
      "y": 2,
      "z": 13,
      "name": "Soil_Dirt"
    },
    {
      "x": -9,
      "y": 3,
      "z": 13,
      "name": "Soil_Grass"
    },
    {
      "x": -9,
      "y": 0,
      "z": 14,
      "name": "Soil_Dirt"
    },
    {
      "x": -9,
      "y": 1,
      "z": 14,
      "name": "Soil_Dirt"
    },
    {
      "x": -9,
      "y": 2,
      "z": 14,
      "name": "Soil_Dirt"
    },
    {
      "x": -9,
      "y": 3,
      "z": 14,
      "name": "Soil_Grass"
    },
    {
      "x": -9,
      "y": 0,
      "z": 15,
      "name": "Soil_Dirt"
    },
    {
      "x": -9,
      "y": 1,
      "z": 15,
      "name": "Soil_Dirt"
    },
    {
      "x": -9,
      "y": 2,
      "z": 15,
      "name": "Soil_Dirt"
    },
    {
      "x": -9,
      "y": 3,
      "z": 15,
      "name": "Soil_Grass"
    },
    {
      "x": -9,
      "y": 0,
      "z": 16,
      "name": "Soil_Dirt"
    },
    {
      "x": -9,
      "y": 1,
      "z": 16,
      "name": "Soil_Dirt"
    },
    {
      "x": -9,
      "y": 2,
      "z": 16,
      "name": "Soil_Dirt"
    },
    {
      "x": -9,
      "y": 3,
      "z": 16,
      "name": "Soil_Grass"
    },
    {
      "x": -8,
      "y": 0,
      "z": -15,
      "name": "Soil_Dirt"
    },
    {
      "x": -8,
      "y": 1,
      "z": -15,
      "name": "Soil_Dirt"
    },
    {
      "x": -8,
      "y": 2,
      "z": -15,
      "name": "Soil_Dirt"
    },
    {
      "x": -8,
      "y": 3,
      "z": -15,
      "name": "Soil_Grass"
    },
    {
      "x": -8,
      "y": 0,
      "z": -14,
      "name": "Soil_Dirt"
    },
    {
      "x": -8,
      "y": 1,
      "z": -14,
      "name": "Soil_Dirt"
    },
    {
      "x": -8,
      "y": 2,
      "z": -14,
      "name": "Soil_Dirt"
    },
    {
      "x": -8,
      "y": 3,
      "z": -14,
      "name": "Soil_Grass"
    },
    {
      "x": -8,
      "y": 0,
      "z": -13,
      "name": "Soil_Dirt"
    },
    {
      "x": -8,
      "y": 1,
      "z": -13,
      "name": "Soil_Dirt"
    },
    {
      "x": -8,
      "y": 2,
      "z": -13,
      "name": "Soil_Dirt"
    },
    {
      "x": -8,
      "y": 3,
      "z": -13,
      "name": "Soil_Grass"
    },
    {
      "x": -8,
      "y": 0,
      "z": -12,
      "name": "Soil_Dirt"
    },
    {
      "x": -8,
      "y": 1,
      "z": -12,
      "name": "Soil_Dirt"
    },
    {
      "x": -8,
      "y": 2,
      "z": -12,
      "name": "Soil_Dirt"
    },
    {
      "x": -8,
      "y": 3,
      "z": -12,
      "name": "Soil_Grass"
    },
    {
      "x": -8,
      "y": 0,
      "z": -11,
      "name": "Soil_Dirt"
    },
    {
      "x": -8,
      "y": 1,
      "z": -11,
      "name": "Soil_Dirt"
    },
    {
      "x": -8,
      "y": 2,
      "z": -11,
      "name": "Soil_Dirt"
    },
    {
      "x": -8,
      "y": 3,
      "z": -11,
      "name": "Soil_Grass"
    },
    {
      "x": -8,
      "y": 0,
      "z": -10,
      "name": "Soil_Dirt"
    },
    {
      "x": -8,
      "y": 1,
      "z": -10,
      "name": "Soil_Dirt"
    },
    {
      "x": -8,
      "y": 2,
      "z": -10,
      "name": "Soil_Dirt"
    },
    {
      "x": -8,
      "y": 3,
      "z": -10,
      "name": "K2_Slot_Pad_3"
    },
    {
      "x": -8,
      "y": 0,
      "z": -9,
      "name": "Soil_Dirt"
    },
    {
      "x": -8,
      "y": 1,
      "z": -9,
      "name": "Soil_Dirt"
    },
    {
      "x": -8,
      "y": 2,
      "z": -9,
      "name": "Soil_Dirt"
    },
    {
      "x": -8,
      "y": 3,
      "z": -9,
      "name": "Soil_Dirt"
    },
    {
      "x": -8,
      "y": 4,
      "z": -9,
      "name": "Rock_Calcite_Brick_Decorative"
    },
    {
      "x": -8,
      "y": 5,
      "z": -9,
      "name": "Rock_Lime_Brick_Smooth"
    },
    {
      "x": -8,
      "y": 6,
      "z": -9,
      "name": "Rock_Lime_Brick_Smooth"
    },
    {
      "x": -8,
      "y": 7,
      "z": -9,
      "name": "Rock_Lime_Brick_Smooth"
    },
    {
      "x": -8,
      "y": 8,
      "z": -9,
      "name": "Rock_Calcite_Brick_Smooth_Half"
    },
    {
      "x": -8,
      "y": 0,
      "z": -8,
      "name": "Soil_Dirt"
    },
    {
      "x": -8,
      "y": 1,
      "z": -8,
      "name": "Soil_Dirt"
    },
    {
      "x": -8,
      "y": 2,
      "z": -8,
      "name": "Soil_Dirt"
    },
    {
      "x": -8,
      "y": 3,
      "z": -8,
      "name": "Rock_Chalk_Brick_Smooth"
    },
    {
      "x": -8,
      "y": 7,
      "z": -8,
      "name": "Rock_Calcite_Brick_Smooth_Half",
      "rotation": 8
    },
    {
      "x": -8,
      "y": 0,
      "z": -7,
      "name": "Soil_Dirt"
    },
    {
      "x": -8,
      "y": 1,
      "z": -7,
      "name": "Soil_Dirt"
    },
    {
      "x": -8,
      "y": 2,
      "z": -7,
      "name": "Soil_Dirt"
    },
    {
      "x": -8,
      "y": 3,
      "z": -7,
      "name": "Rock_Slate_Brick_Smooth"
    },
    {
      "x": -8,
      "y": 7,
      "z": -7,
      "name": "Rock_Calcite_Brick_Smooth_Half",
      "rotation": 8
    },
    {
      "x": -8,
      "y": 0,
      "z": -6,
      "name": "Soil_Dirt"
    },
    {
      "x": -8,
      "y": 1,
      "z": -6,
      "name": "Soil_Dirt"
    },
    {
      "x": -8,
      "y": 2,
      "z": -6,
      "name": "Soil_Dirt"
    },
    {
      "x": -8,
      "y": 3,
      "z": -6,
      "name": "Rock_Chalk_Brick_Smooth"
    },
    {
      "x": -8,
      "y": 7,
      "z": -6,
      "name": "Rock_Calcite_Brick_Smooth_Half",
      "rotation": 8
    },
    {
      "x": -8,
      "y": 0,
      "z": -5,
      "name": "Soil_Dirt"
    },
    {
      "x": -8,
      "y": 1,
      "z": -5,
      "name": "Soil_Dirt"
    },
    {
      "x": -8,
      "y": 2,
      "z": -5,
      "name": "Soil_Dirt"
    },
    {
      "x": -8,
      "y": 3,
      "z": -5,
      "name": "Rock_Slate_Brick_Smooth"
    },
    {
      "x": -8,
      "y": 7,
      "z": -5,
      "name": "Rock_Calcite_Brick_Smooth_Half",
      "rotation": 8
    },
    {
      "x": -8,
      "y": 0,
      "z": -4,
      "name": "Soil_Dirt"
    },
    {
      "x": -8,
      "y": 1,
      "z": -4,
      "name": "Soil_Dirt"
    },
    {
      "x": -8,
      "y": 2,
      "z": -4,
      "name": "Soil_Dirt"
    },
    {
      "x": -8,
      "y": 3,
      "z": -4,
      "name": "Rock_Chalk_Brick_Smooth"
    },
    {
      "x": -8,
      "y": 7,
      "z": -4,
      "name": "Rock_Calcite_Brick_Smooth_Half",
      "rotation": 8
    },
    {
      "x": -8,
      "y": 0,
      "z": -3,
      "name": "Soil_Dirt"
    },
    {
      "x": -8,
      "y": 1,
      "z": -3,
      "name": "Soil_Dirt"
    },
    {
      "x": -8,
      "y": 2,
      "z": -3,
      "name": "Soil_Dirt"
    },
    {
      "x": -8,
      "y": 3,
      "z": -3,
      "name": "Rock_Slate_Brick_Smooth"
    },
    {
      "x": -8,
      "y": 7,
      "z": -3,
      "name": "Rock_Calcite_Brick_Smooth_Half",
      "rotation": 8
    },
    {
      "x": -8,
      "y": 0,
      "z": -2,
      "name": "Soil_Dirt"
    },
    {
      "x": -8,
      "y": 1,
      "z": -2,
      "name": "Soil_Dirt"
    },
    {
      "x": -8,
      "y": 2,
      "z": -2,
      "name": "Soil_Dirt"
    },
    {
      "x": -8,
      "y": 3,
      "z": -2,
      "name": "Rock_Chalk_Brick_Smooth"
    },
    {
      "x": -8,
      "y": 7,
      "z": -2,
      "name": "Rock_Calcite_Brick_Smooth_Half",
      "rotation": 8
    },
    {
      "x": -8,
      "y": 0,
      "z": -1,
      "name": "Soil_Dirt"
    },
    {
      "x": -8,
      "y": 1,
      "z": -1,
      "name": "Soil_Dirt"
    },
    {
      "x": -8,
      "y": 2,
      "z": -1,
      "name": "Soil_Dirt"
    },
    {
      "x": -8,
      "y": 3,
      "z": -1,
      "name": "Soil_Dirt"
    },
    {
      "x": -8,
      "y": 4,
      "z": -1,
      "name": "Rock_Calcite_Brick_Decorative"
    },
    {
      "x": -8,
      "y": 5,
      "z": -1,
      "name": "Furniture_Temple_Dark_Window"
    },
    {
      "x": -8,
      "y": 6,
      "z": -1,
      "name": "Furniture_Temple_Dark_Window"
    },
    {
      "x": -8,
      "y": 7,
      "z": -1,
      "name": "Rock_Lime_Brick_Smooth"
    },
    {
      "x": -8,
      "y": 8,
      "z": -1,
      "name": "Rock_Calcite_Brick_Smooth_Half"
    },
    {
      "x": -8,
      "y": 0,
      "z": 0,
      "name": "Soil_Dirt"
    },
    {
      "x": -8,
      "y": 1,
      "z": 0,
      "name": "Soil_Dirt"
    },
    {
      "x": -8,
      "y": 2,
      "z": 0,
      "name": "Soil_Dirt"
    },
    {
      "x": -8,
      "y": 3,
      "z": 0,
      "name": "Soil_Grass"
    },
    {
      "x": -8,
      "y": 0,
      "z": 1,
      "name": "Soil_Dirt"
    },
    {
      "x": -8,
      "y": 1,
      "z": 1,
      "name": "Soil_Dirt"
    },
    {
      "x": -8,
      "y": 2,
      "z": 1,
      "name": "Soil_Dirt"
    },
    {
      "x": -8,
      "y": 3,
      "z": 1,
      "name": "Soil_Grass"
    },
    {
      "x": -8,
      "y": 0,
      "z": 2,
      "name": "Soil_Dirt"
    },
    {
      "x": -8,
      "y": 1,
      "z": 2,
      "name": "Soil_Dirt"
    },
    {
      "x": -8,
      "y": 2,
      "z": 2,
      "name": "Soil_Dirt"
    },
    {
      "x": -8,
      "y": 3,
      "z": 2,
      "name": "Soil_Grass"
    },
    {
      "x": -8,
      "y": 0,
      "z": 3,
      "name": "Soil_Dirt"
    },
    {
      "x": -8,
      "y": 1,
      "z": 3,
      "name": "Soil_Dirt"
    },
    {
      "x": -8,
      "y": 2,
      "z": 3,
      "name": "Soil_Dirt"
    },
    {
      "x": -8,
      "y": 3,
      "z": 3,
      "name": "Soil_Grass"
    },
    {
      "x": -8,
      "y": 0,
      "z": 4,
      "name": "Soil_Dirt"
    },
    {
      "x": -8,
      "y": 1,
      "z": 4,
      "name": "Soil_Dirt"
    },
    {
      "x": -8,
      "y": 2,
      "z": 4,
      "name": "Soil_Dirt"
    },
    {
      "x": -8,
      "y": 3,
      "z": 4,
      "name": "Soil_Grass"
    },
    {
      "x": -8,
      "y": 0,
      "z": 5,
      "name": "Soil_Dirt"
    },
    {
      "x": -8,
      "y": 1,
      "z": 5,
      "name": "Soil_Dirt"
    },
    {
      "x": -8,
      "y": 2,
      "z": 5,
      "name": "Soil_Dirt"
    },
    {
      "x": -8,
      "y": 3,
      "z": 5,
      "name": "Soil_Grass"
    },
    {
      "x": -8,
      "y": 0,
      "z": 6,
      "name": "Soil_Dirt"
    },
    {
      "x": -8,
      "y": 1,
      "z": 6,
      "name": "Soil_Dirt"
    },
    {
      "x": -8,
      "y": 2,
      "z": 6,
      "name": "Soil_Dirt"
    },
    {
      "x": -8,
      "y": 3,
      "z": 6,
      "name": "Soil_Grass"
    },
    {
      "x": -8,
      "y": 0,
      "z": 7,
      "name": "Soil_Dirt"
    },
    {
      "x": -8,
      "y": 1,
      "z": 7,
      "name": "Soil_Dirt"
    },
    {
      "x": -8,
      "y": 2,
      "z": 7,
      "name": "Soil_Dirt"
    },
    {
      "x": -8,
      "y": 3,
      "z": 7,
      "name": "Soil_Grass"
    },
    {
      "x": -8,
      "y": 0,
      "z": 8,
      "name": "Soil_Dirt"
    },
    {
      "x": -8,
      "y": 1,
      "z": 8,
      "name": "Soil_Dirt"
    },
    {
      "x": -8,
      "y": 2,
      "z": 8,
      "name": "Soil_Dirt"
    },
    {
      "x": -8,
      "y": 3,
      "z": 8,
      "name": "Soil_Grass"
    },
    {
      "x": -8,
      "y": 0,
      "z": 9,
      "name": "Soil_Dirt"
    },
    {
      "x": -8,
      "y": 1,
      "z": 9,
      "name": "Soil_Dirt"
    },
    {
      "x": -8,
      "y": 2,
      "z": 9,
      "name": "Soil_Dirt"
    },
    {
      "x": -8,
      "y": 3,
      "z": 9,
      "name": "Soil_Grass"
    },
    {
      "x": -8,
      "y": 0,
      "z": 10,
      "name": "Soil_Dirt"
    },
    {
      "x": -8,
      "y": 1,
      "z": 10,
      "name": "Soil_Dirt"
    },
    {
      "x": -8,
      "y": 2,
      "z": 10,
      "name": "Soil_Dirt"
    },
    {
      "x": -8,
      "y": 3,
      "z": 10,
      "name": "Soil_Grass"
    },
    {
      "x": -8,
      "y": 0,
      "z": 11,
      "name": "Soil_Dirt"
    },
    {
      "x": -8,
      "y": 1,
      "z": 11,
      "name": "Soil_Dirt"
    },
    {
      "x": -8,
      "y": 2,
      "z": 11,
      "name": "Soil_Dirt"
    },
    {
      "x": -8,
      "y": 3,
      "z": 11,
      "name": "Soil_Grass"
    },
    {
      "x": -8,
      "y": 0,
      "z": 12,
      "name": "Soil_Dirt"
    },
    {
      "x": -8,
      "y": 1,
      "z": 12,
      "name": "Soil_Dirt"
    },
    {
      "x": -8,
      "y": 2,
      "z": 12,
      "name": "Soil_Dirt"
    },
    {
      "x": -8,
      "y": 3,
      "z": 12,
      "name": "Soil_Grass"
    },
    {
      "x": -8,
      "y": 0,
      "z": 13,
      "name": "Soil_Dirt"
    },
    {
      "x": -8,
      "y": 1,
      "z": 13,
      "name": "Soil_Dirt"
    },
    {
      "x": -8,
      "y": 2,
      "z": 13,
      "name": "Soil_Dirt"
    },
    {
      "x": -8,
      "y": 3,
      "z": 13,
      "name": "Soil_Grass"
    },
    {
      "x": -8,
      "y": 0,
      "z": 14,
      "name": "Soil_Dirt"
    },
    {
      "x": -8,
      "y": 1,
      "z": 14,
      "name": "Soil_Dirt"
    },
    {
      "x": -8,
      "y": 2,
      "z": 14,
      "name": "Soil_Dirt"
    },
    {
      "x": -8,
      "y": 3,
      "z": 14,
      "name": "Soil_Grass"
    },
    {
      "x": -8,
      "y": 0,
      "z": 15,
      "name": "Soil_Dirt"
    },
    {
      "x": -8,
      "y": 1,
      "z": 15,
      "name": "Soil_Dirt"
    },
    {
      "x": -8,
      "y": 2,
      "z": 15,
      "name": "Soil_Dirt"
    },
    {
      "x": -8,
      "y": 3,
      "z": 15,
      "name": "Soil_Grass"
    },
    {
      "x": -8,
      "y": 0,
      "z": 16,
      "name": "Soil_Dirt"
    },
    {
      "x": -8,
      "y": 1,
      "z": 16,
      "name": "Soil_Dirt"
    },
    {
      "x": -8,
      "y": 2,
      "z": 16,
      "name": "Soil_Dirt"
    },
    {
      "x": -8,
      "y": 3,
      "z": 16,
      "name": "Soil_Grass"
    },
    {
      "x": -7,
      "y": 0,
      "z": -15,
      "name": "Soil_Dirt"
    },
    {
      "x": -7,
      "y": 1,
      "z": -15,
      "name": "Soil_Dirt"
    },
    {
      "x": -7,
      "y": 2,
      "z": -15,
      "name": "Soil_Dirt"
    },
    {
      "x": -7,
      "y": 3,
      "z": -15,
      "name": "Soil_Grass"
    },
    {
      "x": -7,
      "y": 0,
      "z": -14,
      "name": "Soil_Dirt"
    },
    {
      "x": -7,
      "y": 1,
      "z": -14,
      "name": "Soil_Dirt"
    },
    {
      "x": -7,
      "y": 2,
      "z": -14,
      "name": "Soil_Dirt"
    },
    {
      "x": -7,
      "y": 3,
      "z": -14,
      "name": "Soil_Grass"
    },
    {
      "x": -7,
      "y": 0,
      "z": -13,
      "name": "Soil_Dirt"
    },
    {
      "x": -7,
      "y": 1,
      "z": -13,
      "name": "Soil_Dirt"
    },
    {
      "x": -7,
      "y": 2,
      "z": -13,
      "name": "Soil_Dirt"
    },
    {
      "x": -7,
      "y": 3,
      "z": -13,
      "name": "Soil_Grass"
    },
    {
      "x": -7,
      "y": 0,
      "z": -12,
      "name": "Soil_Dirt"
    },
    {
      "x": -7,
      "y": 1,
      "z": -12,
      "name": "Soil_Dirt"
    },
    {
      "x": -7,
      "y": 2,
      "z": -12,
      "name": "Soil_Dirt"
    },
    {
      "x": -7,
      "y": 3,
      "z": -12,
      "name": "Soil_Grass"
    },
    {
      "x": -7,
      "y": 0,
      "z": -11,
      "name": "Soil_Dirt"
    },
    {
      "x": -7,
      "y": 1,
      "z": -11,
      "name": "Soil_Dirt"
    },
    {
      "x": -7,
      "y": 2,
      "z": -11,
      "name": "Soil_Dirt"
    },
    {
      "x": -7,
      "y": 3,
      "z": -11,
      "name": "Soil_Grass"
    },
    {
      "x": -7,
      "y": 0,
      "z": -10,
      "name": "Soil_Dirt"
    },
    {
      "x": -7,
      "y": 1,
      "z": -10,
      "name": "Soil_Dirt"
    },
    {
      "x": -7,
      "y": 2,
      "z": -10,
      "name": "Soil_Dirt"
    },
    {
      "x": -7,
      "y": 3,
      "z": -10,
      "name": "K2_Slot_Pad_2"
    },
    {
      "x": -7,
      "y": 0,
      "z": -9,
      "name": "Soil_Dirt"
    },
    {
      "x": -7,
      "y": 1,
      "z": -9,
      "name": "Soil_Dirt"
    },
    {
      "x": -7,
      "y": 2,
      "z": -9,
      "name": "Soil_Dirt"
    },
    {
      "x": -7,
      "y": 3,
      "z": -9,
      "name": "Soil_Dirt"
    },
    {
      "x": -7,
      "y": 4,
      "z": -9,
      "name": "Rock_Calcite_Brick_Decorative"
    },
    {
      "x": -7,
      "y": 5,
      "z": -9,
      "name": "Rock_Lime_Brick_Smooth"
    },
    {
      "x": -7,
      "y": 6,
      "z": -9,
      "name": "Rock_Lime_Brick_Smooth"
    },
    {
      "x": -7,
      "y": 7,
      "z": -9,
      "name": "Rock_Lime_Brick_Smooth"
    },
    {
      "x": -7,
      "y": 8,
      "z": -9,
      "name": "Rock_Calcite_Brick_Smooth_Half"
    },
    {
      "x": -7,
      "y": 0,
      "z": -8,
      "name": "Soil_Dirt"
    },
    {
      "x": -7,
      "y": 1,
      "z": -8,
      "name": "Soil_Dirt"
    },
    {
      "x": -7,
      "y": 2,
      "z": -8,
      "name": "Soil_Dirt"
    },
    {
      "x": -7,
      "y": 3,
      "z": -8,
      "name": "Rock_Slate_Brick_Smooth"
    },
    {
      "x": -7,
      "y": 7,
      "z": -8,
      "name": "Rock_Calcite_Brick_Smooth_Half",
      "rotation": 8
    },
    {
      "x": -7,
      "y": 0,
      "z": -7,
      "name": "Soil_Dirt"
    },
    {
      "x": -7,
      "y": 1,
      "z": -7,
      "name": "Soil_Dirt"
    },
    {
      "x": -7,
      "y": 2,
      "z": -7,
      "name": "Soil_Dirt"
    },
    {
      "x": -7,
      "y": 3,
      "z": -7,
      "name": "Rock_Chalk_Brick_Smooth"
    },
    {
      "x": -7,
      "y": 7,
      "z": -7,
      "name": "Rock_Calcite_Brick_Smooth_Half",
      "rotation": 8
    },
    {
      "x": -7,
      "y": 0,
      "z": -6,
      "name": "Soil_Dirt"
    },
    {
      "x": -7,
      "y": 1,
      "z": -6,
      "name": "Soil_Dirt"
    },
    {
      "x": -7,
      "y": 2,
      "z": -6,
      "name": "Soil_Dirt"
    },
    {
      "x": -7,
      "y": 3,
      "z": -6,
      "name": "Rock_Slate_Brick_Smooth"
    },
    {
      "x": -7,
      "y": 7,
      "z": -6,
      "name": "Rock_Calcite_Brick_Smooth_Half",
      "rotation": 8
    },
    {
      "x": -7,
      "y": 0,
      "z": -5,
      "name": "Soil_Dirt"
    },
    {
      "x": -7,
      "y": 1,
      "z": -5,
      "name": "Soil_Dirt"
    },
    {
      "x": -7,
      "y": 2,
      "z": -5,
      "name": "Soil_Dirt"
    },
    {
      "x": -7,
      "y": 3,
      "z": -5,
      "name": "Rock_Chalk_Brick_Smooth"
    },
    {
