{
  "version": 8,
  "blockIdVersion": 11,
  "anchorX": 0,
  "anchorY": 0,
  "anchorZ": 0,
  "blocks": [
    {
      "x": -15,
      "y": 0,
      "z": -15,
      "name": "Soil_Dirt"
    },
    {
      "x": -15,
      "y": 1,
      "z": -15,
      "name": "Soil_Dirt"
    },
    {
      "x": -15,
      "y": 2,
      "z": -15,
      "name": "Soil_Dirt"
    },
    {
      "x": -15,
      "y": 3,
      "z": -15,
      "name": "Soil_Grass"
    },
    {
      "x": -15,
      "y": 0,
      "z": -14,
      "name": "Soil_Dirt"
    },
    {
      "x": -15,
      "y": 1,
      "z": -14,
      "name": "Soil_Dirt"
    },
    {
      "x": -15,
      "y": 2,
      "z": -14,
      "name": "Soil_Dirt"
    },
    {
      "x": -15,
      "y": 3,
      "z": -14,
      "name": "Soil_Grass"
    },
    {
      "x": -15,
      "y": 0,
      "z": -13,
      "name": "Wood_Ash_Trunk_Full"
    },
    {
      "x": -15,
      "y": 1,
      "z": -13,
      "name": "Soil_Dirt"
    },
    {
      "x": -15,
      "y": 2,
      "z": -13,
      "name": "Soil_Dirt"
    },
    {
      "x": -15,
      "y": 3,
      "z": -13,
      "name": "Soil_Grass"
    },
    {
      "x": -15,
      "y": 0,
      "z": -12,
      "name": "Soil_Dirt"
    },
    {
      "x": -15,
      "y": 1,
      "z": -12,
      "name": "Wood_Ash_Trunk_Full"
    },
    {
      "x": -15,
      "y": 2,
      "z": -12,
      "name": "Wood_Ash_Trunk",
      "support": 15
    },
    {
      "x": -15,
      "y": 3,
      "z": -12,
      "name": "Wood_Ash_Trunk_Full"
    },
    {
      "x": -15,
      "y": 0,
      "z": -11,
      "name": "Soil_Dirt"
    },
    {
      "x": -15,
      "y": 1,
      "z": -11,
      "name": "Wood_Ash_Trunk_Full"
    },
    {
      "x": -15,
      "y": 2,
      "z": -11,
      "name": "Wood_Ash_Trunk",
      "support": 15
    },
    {
      "x": -15,
      "y": 3,
      "z": -11,
      "name": "Wood_Ash_Trunk",
      "support": 15
    },
    {
      "x": -15,
      "y": 4,
      "z": -11,
      "name": "Wood_Ash_Trunk_Full"
    },
    {
      "x": -15,
      "y": 0,
      "z": -10,
      "name": "Soil_Dirt"
    },
    {
      "x": -15,
      "y": 1,
      "z": -10,
      "name": "Soil_Dirt"
    },
    {
      "x": -15,
      "y": 2,
      "z": -10,
      "name": "Wood_Ash_Trunk_Full"
    },
    {
      "x": -15,
      "y": 3,
      "z": -10,
      "name": "Wood_Ash_Trunk",
      "support": 15
    },
    {
      "x": -15,
      "y": 4,
      "z": -10,
      "name": "Wood_Ash_Trunk_Full"
    },
    {
      "x": -15,
      "y": 0,
      "z": -9,
      "name": "Soil_Dirt"
    },
    {
      "x": -15,
      "y": 1,
      "z": -9,
      "name": "Soil_Dirt"
    },
    {
      "x": -15,
      "y": 2,
      "z": -9,
      "name": "Wood_Ash_Trunk_Full"
    },
    {
      "x": -15,
      "y": 3,
      "z": -9,
      "name": "Wood_Ash_Trunk",
      "support": 15
    },
    {
      "x": -15,
      "y": 4,
      "z": -9,
      "name": "Wood_Ash_Trunk_Full"
    },
    {
      "x": -15,
      "y": 0,
      "z": -8,
      "name": "Soil_Dirt"
    },
    {
      "x": -15,
      "y": 1,
      "z": -8,
      "name": "Soil_Dirt"
    },
    {
      "x": -15,
      "y": 2,
      "z": -8,
      "name": "Soil_Dirt"
    },
    {
      "x": -15,
      "y": 3,
      "z": -8,
      "name": "Soil_Grass"
    },
    {
      "x": -15,
      "y": 0,
      "z": -7,
      "name": "Soil_Dirt"
    },
    {
      "x": -15,
      "y": 1,
      "z": -7,
      "name": "Soil_Dirt"
    },
    {
      "x": -15,
      "y": 2,
      "z": -7,
      "name": "Soil_Dirt"
    },
    {
      "x": -15,
      "y": 3,
      "z": -7,
      "name": "Soil_Grass"
    },
    {
      "x": -15,
      "y": 0,
      "z": -6,
      "name": "Soil_Dirt"
    },
    {
      "x": -15,
      "y": 1,
      "z": -6,
      "name": "Soil_Dirt"
    },
    {
      "x": -15,
      "y": 2,
      "z": -6,
      "name": "Soil_Dirt"
    },
    {
      "x": -15,
      "y": 3,
      "z": -6,
      "name": "Soil_Grass"
    },
    {
      "x": -15,
      "y": 0,
      "z": -5,
      "name": "Soil_Dirt"
    },
    {
      "x": -15,
      "y": 1,
      "z": -5,
      "name": "Wood_Ash_Trunk_Full"
    },
    {
      "x": -15,
      "y": 2,
      "z": -5,
      "name": "Wood_Ash_Trunk",
      "support": 15
    },
    {
      "x": -15,
      "y": 3,
      "z": -5,
      "name": "Wood_Ash_Trunk",
      "support": 15
    },
    {
      "x": -15,
      "y": 4,
      "z": -5,
      "name": "Wood_Ash_Trunk_Full"
    },
    {
      "x": -15,
      "y": 0,
      "z": -4,
      "name": "Wood_Ash_Trunk_Full"
    },
    {
      "x": -15,
      "y": 1,
      "z": -4,
      "name": "Wood_Ash_Trunk",
      "support": 15
    },
    {
      "x": -15,
      "y": 2,
      "z": -4,
      "name": "Wood_Ash_Trunk_Full"
    },
    {
      "x": -15,
      "y": 3,
      "z": -4,
      "name": "Soil_Grass"
    },
    {
      "x": -15,
      "y": 0,
      "z": -3,
      "name": "Soil_Dirt"
    },
    {
      "x": -15,
      "y": 1,
      "z": -3,
      "name": "Soil_Dirt"
    },
    {
      "x": -15,
      "y": 2,
      "z": -3,
      "name": "Soil_Dirt"
    },
    {
      "x": -15,
      "y": 3,
      "z": -3,
      "name": "Soil_Grass"
    },
    {
      "x": -15,
      "y": 0,
      "z": -2,
      "name": "Soil_Dirt"
    },
    {
      "x": -15,
      "y": 1,
      "z": -2,
      "name": "Soil_Dirt"
    },
    {
      "x": -15,
      "y": 2,
      "z": -2,
      "name": "Soil_Dirt"
    },
    {
      "x": -15,
      "y": 3,
      "z": -2,
      "name": "Soil_Grass"
    },
    {
      "x": -15,
      "y": 0,
      "z": -1,
      "name": "Soil_Dirt"
    },
    {
      "x": -15,
      "y": 1,
      "z": -1,
      "name": "Soil_Dirt"
    },
    {
      "x": -15,
      "y": 2,
      "z": -1,
      "name": "Soil_Dirt"
    },
    {
      "x": -15,
      "y": 3,
      "z": -1,
      "name": "Soil_Grass"
    },
    {
      "x": -15,
      "y": 15,
      "z": -1,
      "name": "Wood_Ash_Trunk_Full"
    },
    {
      "x": -15,
      "y": 16,
      "z": -1,
      "name": "Wood_Ash_Trunk_Full"
    },
    {
      "x": -15,
      "y": 0,
      "z": 0,
      "name": "Soil_Dirt"
    },
    {
      "x": -15,
      "y": 1,
      "z": 0,
      "name": "Soil_Dirt"
    },
    {
      "x": -15,
      "y": 2,
      "z": 0,
      "name": "Soil_Dirt"
    },
    {
      "x": -15,
      "y": 3,
      "z": 0,
      "name": "Soil_Grass"
    },
    {
      "x": -15,
      "y": 14,
      "z": 0,
      "name": "Wood_Ash_Trunk_Full"
    },
    {
      "x": -15,
      "y": 15,
      "z": 0,
      "name": "Wood_Ash_Trunk",
      "support": 15
    },
    {
      "x": -15,
      "y": 16,
      "z": 0,
      "name": "Wood_Ash_Trunk",
      "support": 15
    },
    {
      "x": -15,
      "y": 17,
      "z": 0,
      "name": "Wood_Ash_Trunk_Full"
    },
    {
      "x": -15,
      "y": 0,
      "z": 1,
      "name": "Soil_Dirt"
    },
    {
      "x": -15,
      "y": 1,
      "z": 1,
      "name": "Soil_Dirt"
    },
    {
      "x": -15,
      "y": 2,
      "z": 1,
      "name": "Soil_Dirt"
    },
    {
      "x": -15,
      "y": 3,
      "z": 1,
      "name": "Soil_Grass"
    },
    {
      "x": -15,
      "y": 13,
      "z": 1,
      "name": "Wood_Ash_Trunk_Full"
    },
    {
      "x": -15,
      "y": 14,
      "z": 1,
      "name": "Wood_Ash_Trunk",
      "support": 15
    },
    {
      "x": -15,
      "y": 15,
      "z": 1,
      "name": "Wood_Ash_Trunk",
      "support": 15
    },
    {
      "x": -15,
      "y": 16,
      "z": 1,
      "name": "Wood_Ash_Trunk",
      "support": 15
    },
    {
      "x": -15,
      "y": 17,
      "z": 1,
      "name": "Wood_Ash_Trunk_Full"
    },
    {
      "x": -15,
      "y": 18,
      "z": 1,
      "name": "Furniture_Kweebec_Table"
    },
    {
      "x": -15,
      "y": 0,
      "z": 2,
      "name": "Soil_Dirt"
    },
    {
      "x": -15,
      "y": 1,
      "z": 2,
      "name": "Soil_Dirt"
    },
    {
      "x": -15,
      "y": 2,
      "z": 2,
      "name": "Soil_Dirt"
    },
    {
      "x": -15,
      "y": 3,
      "z": 2,
      "name": "Soil_Grass"
    },
    {
      "x": -15,
      "y": 13,
      "z": 2,
      "name": "Wood_Ash_Trunk_Full"
    },
    {
      "x": -15,
      "y": 14,
      "z": 2,
      "name": "Wood_Ash_Trunk",
      "support": 15
    },
    {
      "x": -15,
      "y": 15,
      "z": 2,
      "name": "Wood_Ash_Trunk",
      "support": 15
    },
    {
      "x": -15,
      "y": 16,
      "z": 2,
      "name": "Wood_Ash_Trunk",
      "support": 15
    },
    {
      "x": -15,
      "y": 17,
      "z": 2,
      "name": "Wood_Ash_Trunk_Full"
    },
    {
      "x": -15,
      "y": 18,
      "z": 2,
      "name": "Furniture_Kweebec_Table",
      "filler": 32
    },
    {
      "x": -15,
      "y": 0,
      "z": 3,
      "name": "Soil_Dirt"
    },
    {
      "x": -15,
      "y": 1,
      "z": 3,
      "name": "Soil_Dirt"
    },
    {
      "x": -15,
      "y": 2,
      "z": 3,
      "name": "Soil_Dirt"
    },
    {
      "x": -15,
      "y": 3,
      "z": 3,
      "name": "Soil_Grass"
    },
    {
      "x": -15,
      "y": 13,
      "z": 3,
      "name": "Wood_Ash_Trunk_Full"
    },
    {
      "x": -15,
      "y": 14,
      "z": 3,
      "name": "Wood_Ash_Trunk",
      "support": 15
    },
    {
      "x": -15,
      "y": 15,
      "z": 3,
      "name": "Wood_Ash_Trunk",
      "support": 15
    },
    {
      "x": -15,
      "y": 16,
      "z": 3,
      "name": "Wood_Ash_Trunk",
      "support": 15
    },
    {
      "x": -15,
      "y": 17,
      "z": 3,
      "name": "Wood_Ash_Trunk_Full"
    },
    {
      "x": -15,
      "y": 18,
      "z": 3,
      "name": "Furniture_Kweebec_Stool"
    },
    {
      "x": -15,
      "y": 0,
      "z": 4,
      "name": "Soil_Dirt"
    },
    {
      "x": -15,
      "y": 1,
      "z": 4,
      "name": "Soil_Dirt"
    },
    {
      "x": -15,
      "y": 2,
      "z": 4,
      "name": "Soil_Dirt"
    },
    {
      "x": -15,
      "y": 3,
      "z": 4,
      "name": "Soil_Grass"
    },
    {
      "x": -15,
      "y": 13,
      "z": 4,
      "name": "Wood_Ash_Trunk_Full"
    },
    {
      "x": -15,
      "y": 14,
      "z": 4,
      "name": "Wood_Ash_Trunk",
      "support": 15
    },
    {
      "x": -15,
      "y": 15,
      "z": 4,
      "name": "Wood_Ash_Trunk",
      "support": 15
    },
    {
      "x": -15,
      "y": 16,
      "z": 4,
      "name": "Wood_Ash_Trunk",
      "support": 15
    },
    {
      "x": -15,
      "y": 17,
      "z": 4,
      "name": "Wood_Ash_Trunk_Full"
    },
    {
      "x": -15,
      "y": 0,
      "z": 5,
      "name": "Soil_Dirt"
    },
    {
      "x": -15,
      "y": 1,
      "z": 5,
      "name": "Soil_Dirt"
    },
    {
      "x": -15,
      "y": 2,
      "z": 5,
      "name": "Soil_Dirt"
    },
    {
      "x": -15,
      "y": 3,
      "z": 5,
      "name": "Soil_Grass"
    },
    {
      "x": -15,
      "y": 13,
      "z": 5,
      "name": "Wood_Ash_Trunk_Full"
    },
    {
      "x": -15,
      "y": 17,
      "z": 5,
      "name": "Furniture_Kweebec_Platform",
      "rotation": 1
    },
    {
      "x": -15,
      "y": 0,
      "z": 6,
      "name": "Soil_Dirt"
    },
    {
      "x": -15,
      "y": 1,
      "z": 6,
      "name": "Soil_Dirt"
    },
    {
      "x": -15,
      "y": 2,
      "z": 6,
      "name": "Soil_Dirt"
    },
    {
      "x": -15,
      "y": 3,
      "z": 6,
      "name": "Soil_Grass"
    },
    {
      "x": -15,
      "y": 0,
      "z": 7,
      "name": "Soil_Dirt"
    },
    {
      "x": -15,
      "y": 1,
      "z": 7,
      "name": "Soil_Dirt"
    },
    {
      "x": -15,
      "y": 2,
      "z": 7,
      "name": "Soil_Dirt"
    },
    {
      "x": -15,
      "y": 3,
      "z": 7,
      "name": "Soil_Grass"
    },
    {
      "x": -15,
      "y": 0,
      "z": 8,
      "name": "Wood_Ash_Trunk",
      "support": 15
    },
    {
      "x": -15,
      "y": 1,
      "z": 8,
      "name": "Wood_Ash_Trunk_Full"
    },
    {
      "x": -15,
      "y": 2,
      "z": 8,
      "name": "Soil_Dirt"
    },
    {
      "x": -15,
      "y": 3,
      "z": 8,
      "name": "Soil_Grass"
    },
    {
      "x": -15,
      "y": 0,
      "z": 9,
      "name": "Wood_Ash_Trunk_Full"
    },
    {
      "x": -15,
      "y": 1,
      "z": 9,
      "name": "Wood_Ash_Trunk",
      "support": 15
    },
    {
      "x": -15,
      "y": 2,
      "z": 9,
      "name": "Wood_Ash_Trunk",
      "support": 15
    },
    {
      "x": -15,
      "y": 3,
      "z": 9,
      "name": "Wood_Ash_Trunk_Full"
    },
    {
      "x": -15,
      "y": 0,
      "z": 10,
      "name": "Soil_Dirt"
    },
    {
      "x": -15,
      "y": 1,
      "z": 10,
      "name": "Wood_Ash_Trunk_Full"
    },
    {
      "x": -15,
      "y": 2,
      "z": 10,
      "name": "Wood_Ash_Trunk",
      "support": 15
    },
    {
      "x": -15,
      "y": 3,
      "z": 10,
      "name": "Wood_Ash_Trunk_Full"
    },
    {
      "x": -15,
      "y": 0,
      "z": 11,
      "name": "Soil_Dirt"
    },
    {
      "x": -15,
      "y": 1,
      "z": 11,
      "name": "Wood_Ash_Trunk_Full"
    },
    {
      "x": -15,
      "y": 2,
      "z": 11,
      "name": "Wood_Ash_Trunk",
      "support": 15
    },
    {
      "x": -15,
      "y": 3,
      "z": 11,
      "name": "Wood_Ash_Trunk",
      "support": 15
    },
    {
      "x": -15,
      "y": 4,
      "z": 11,
      "name": "Wood_Ash_Trunk_Full"
    },
    {
      "x": -15,
      "y": 0,
      "z": 12,
      "name": "Soil_Dirt"
    },
    {
      "x": -15,
      "y": 1,
      "z": 12,
      "name": "Soil_Dirt"
    },
    {
      "x": -15,
      "y": 2,
      "z": 12,
      "name": "Wood_Ash_Trunk_Full"
    },
    {
      "x": -15,
      "y": 3,
      "z": 12,
      "name": "Wood_Ash_Trunk",
      "support": 15
    },
    {
      "x": -15,
      "y": 4,
      "z": 12,
      "name": "Wood_Ash_Trunk_Full"
    },
    {
      "x": -15,
      "y": 0,
      "z": 13,
      "name": "Soil_Dirt"
    },
    {
      "x": -15,
      "y": 1,
      "z": 13,
      "name": "Soil_Dirt"
    },
    {
      "x": -15,
      "y": 2,
      "z": 13,
      "name": "Soil_Dirt"
    },
    {
      "x": -15,
      "y": 3,
      "z": 13,
      "name": "Soil_Grass"
    },
    {
      "x": -15,
      "y": 0,
      "z": 14,
      "name": "Soil_Dirt"
    },
    {
      "x": -15,
      "y": 1,
      "z": 14,
      "name": "Soil_Dirt"
    },
    {
      "x": -15,
      "y": 2,
      "z": 14,
      "name": "Soil_Dirt"
    },
    {
      "x": -15,
      "y": 3,
      "z": 14,
      "name": "Soil_Grass"
    },
    {
      "x": -15,
      "y": 0,
      "z": 15,
      "name": "Soil_Dirt"
    },
    {
      "x": -15,
      "y": 1,
      "z": 15,
      "name": "Soil_Dirt"
    },
    {
      "x": -15,
      "y": 2,
      "z": 15,
      "name": "Soil_Dirt"
    },
    {
      "x": -15,
      "y": 3,
      "z": 15,
      "name": "Soil_Grass"
    },
    {
      "x": -15,
      "y": 0,
      "z": 16,
      "name": "Soil_Dirt"
    },
    {
      "x": -15,
      "y": 1,
      "z": 16,
      "name": "Soil_Dirt"
    },
    {
      "x": -15,
      "y": 2,
      "z": 16,
      "name": "Soil_Dirt"
    },
    {
      "x": -15,
      "y": 3,
      "z": 16,
      "name": "Soil_Grass"
    },
    {
      "x": -14,
      "y": 0,
      "z": -15,
      "name": "Soil_Dirt"
    },
    {
      "x": -14,
      "y": 1,
      "z": -15,
      "name": "Soil_Dirt"
    },
    {
      "x": -14,
      "y": 2,
      "z": -15,
      "name": "Soil_Dirt"
    },
    {
      "x": -14,
      "y": 3,
      "z": -15,
      "name": "Soil_Grass"
    },
    {
      "x": -14,
      "y": 0,
      "z": -14,
      "name": "Soil_Dirt"
    },
    {
      "x": -14,
      "y": 1,
      "z": -14,
      "name": "Soil_Dirt"
    },
    {
      "x": -14,
      "y": 2,
      "z": -14,
      "name": "Soil_Dirt"
    },
    {
      "x": -14,
      "y": 3,
      "z": -14,
      "name": "Soil_Grass"
    },
    {
      "x": -14,
      "y": 0,
      "z": -13,
      "name": "Soil_Dirt"
    },
    {
      "x": -14,
      "y": 1,
      "z": -13,
      "name": "Soil_Dirt"
    },
    {
      "x": -14,
      "y": 2,
      "z": -13,
      "name": "Soil_Dirt"
    },
    {
      "x": -14,
      "y": 3,
      "z": -13,
      "name": "Soil_Grass"
    },
    {
      "x": -14,
      "y": 0,
      "z": -12,
      "name": "Soil_Dirt"
    },
    {
      "x": -14,
      "y": 1,
      "z": -12,
      "name": "Soil_Dirt"
    },
    {
      "x": -14,
      "y": 2,
      "z": -12,
      "name": "Soil_Dirt"
    },
    {
      "x": -14,
      "y": 3,
      "z": -12,
      "name": "Soil_Grass"
    },
    {
      "x": -14,
      "y": 0,
      "z": -11,
      "name": "Soil_Dirt"
    },
    {
      "x": -14,
      "y": 1,
      "z": -11,
      "name": "Soil_Dirt"
    },
    {
      "x": -14,
      "y": 2,
      "z": -11,
      "name": "Wood_Ash_Trunk_Full"
    },
    {
      "x": -14,
      "y": 3,
      "z": -11,
      "name": "Wood_Ash_Trunk_Full"
    },
    {
      "x": -14,
      "y": 0,
      "z": -10,
      "name": "Soil_Dirt"
    },
    {
      "x": -14,
      "y": 1,
      "z": -10,
      "name": "Soil_Dirt"
    },
    {
      "x": -14,
      "y": 2,
      "z": -10,
      "name": "Wood_Ash_Trunk_Full"
    },
    {
      "x": -14,
      "y": 3,
      "z": -10,
      "name": "Wood_Ash_Trunk",
      "support": 15
    },
    {
      "x": -14,
      "y": 4,
      "z": -10,
      "name": "Wood_Ash_Trunk_Full"
    },
    {
      "x": -14,
      "y": 0,
      "z": -9,
      "name": "Soil_Dirt"
    },
    {
      "x": -14,
      "y": 1,
      "z": -9,
      "name": "Soil_Dirt"
    },
    {
      "x": -14,
      "y": 2,
      "z": -9,
      "name": "Wood_Ash_Trunk_Full"
    },
    {
      "x": -14,
      "y": 3,
      "z": -9,
      "name": "Wood_Ash_Trunk",
      "support": 15
    },
    {
      "x": -14,
      "y": 4,
      "z": -9,
      "name": "Wood_Ash_Trunk_Full"
    },
    {
      "x": -14,
      "y": 0,
      "z": -8,
      "name": "Soil_Dirt"
    },
    {
      "x": -14,
      "y": 1,
      "z": -8,
      "name": "Soil_Dirt"
    },
    {
      "x": -14,
      "y": 2,
      "z": -8,
      "name": "Wood_Ash_Trunk_Full"
    },
    {
      "x": -14,
      "y": 3,
      "z": -8,
      "name": "Wood_Ash_Trunk",
      "support": 15
    },
    {
      "x": -14,
      "y": 4,
      "z": -8,
      "name": "Wood_Ash_Trunk",
      "support": 15
    },
    {
      "x": -14,
      "y": 5,
      "z": -8,
      "name": "Wood_Ash_Trunk_Full"
    },
    {
      "x": -14,
      "y": 0,
      "z": -7,
      "name": "Soil_Dirt"
    },
    {
      "x": -14,
      "y": 1,
      "z": -7,
      "name": "Soil_Dirt"
    },
    {
      "x": -14,
      "y": 2,
      "z": -7,
      "name": "Soil_Dirt"
    },
    {
      "x": -14,
      "y": 3,
      "z": -7,
      "name": "Wood_Ash_Trunk_Full"
    },
    {
      "x": -14,
      "y": 4,
      "z": -7,
      "name": "Wood_Ash_Trunk",
      "support": 15
    },
    {
      "x": -14,
      "y": 5,
      "z": -7,
      "name": "Wood_Ash_Trunk",
      "support": 15
    },
    {
      "x": -14,
      "y": 6,
      "z": -7,
      "name": "Wood_Ash_Trunk_Full"
    },
    {
      "x": -14,
      "y": 0,
      "z": -6,
      "name": "Soil_Dirt"
    },
    {
      "x": -14,
      "y": 1,
      "z": -6,
      "name": "Soil_Dirt"
    },
    {
      "x": -14,
      "y": 2,
      "z": -6,
      "name": "Soil_Dirt"
    },
    {
      "x": -14,
      "y": 3,
      "z": -6,
      "name": "Wood_Ash_Trunk_Full"
    },
    {
      "x": -14,
      "y": 4,
      "z": -6,
      "name": "Wood_Ash_Trunk",
      "support": 15
    },
    {
      "x": -14,
      "y": 5,
      "z": -6,
      "name": "Wood_Ash_Trunk",
      "support": 15
    },
    {
      "x": -14,
      "y": 6,
      "z": -6,
      "name": "Wood_Ash_Trunk_Full"
    },
    {
      "x": -14,
      "y": 0,
      "z": -5,
      "name": "Soil_Dirt"
    },
    {
      "x": -14,
      "y": 1,
      "z": -5,
      "name": "Soil_Dirt"
    },
    {
      "x": -14,
      "y": 2,
      "z": -5,
      "name": "Wood_Ash_Trunk_Full"
    },
    {
      "x": -14,
      "y": 3,
      "z": -5,
      "name": "Wood_Ash_Trunk",
      "support": 15
    },
    {
      "x": -14,
      "y": 4,
      "z": -5,
      "name": "Wood_Ash_Trunk",
      "support": 15
    },
    {
      "x": -14,
      "y": 5,
      "z": -5,
      "name": "Wood_Ash_Trunk",
      "support": 15
    },
    {
      "x": -14,
      "y": 6,
      "z": -5,
      "name": "Wood_Ash_Trunk_Full"
    },
    {
      "x": -14,
      "y": 0,
      "z": -4,
      "name": "Soil_Dirt"
    },
    {
      "x": -14,
      "y": 1,
      "z": -4,
      "name": "Wood_Ash_Roots"
    },
    {
      "x": -14,
      "y": 2,
      "z": -4,
      "name": "Wood_Ash_Trunk_Full"
    },
    {
      "x": -14,
      "y": 3,
      "z": -4,
      "name": "Wood_Ash_Trunk",
      "support": 15
    },
    {
      "x": -14,
      "y": 4,
      "z": -4,
      "name": "Wood_Ash_Trunk",
      "support": 15
    },
    {
      "x": -14,
      "y": 5,
      "z": -4,
      "name": "Wood_Ash_Trunk_Full"
    },
    {
      "x": -14,
      "y": 0,
      "z": -3,
      "name": "Soil_Dirt"
    },
    {
      "x": -14,
      "y": 1,
      "z": -3,
      "name": "Soil_Dirt"
    },
    {
      "x": -14,
      "y": 2,
      "z": -3,
      "name": "Soil_Dirt"
    },
    {
      "x": -14,
      "y": 3,
      "z": -3,
      "name": "Soil_Grass"
    },
    {
      "x": -14,
      "y": 0,
      "z": -2,
      "name": "Soil_Dirt"
    },
    {
      "x": -14,
      "y": 1,
      "z": -2,
      "name": "Soil_Dirt"
    },
    {
      "x": -14,
      "y": 2,
      "z": -2,
      "name": "Soil_Dirt"
    },
    {
      "x": -14,
      "y": 3,
      "z": -2,
      "name": "Soil_Grass"
    },
    {
      "x": -14,
      "y": 0,
      "z": -1,
      "name": "Soil_Dirt"
    },
    {
      "x": -14,
      "y": 1,
      "z": -1,
      "name": "Soil_Dirt"
    },
    {
      "x": -14,
      "y": 2,
      "z": -1,
      "name": "Soil_Dirt"
    },
    {
      "x": -14,
      "y": 3,
      "z": -1,
      "name": "Soil_Grass"
    },
    {
      "x": -14,
      "y": 0,
      "z": 0,
      "name": "Soil_Dirt"
    },
    {
      "x": -14,
      "y": 1,
      "z": 0,
      "name": "Soil_Dirt"
    },
    {
      "x": -14,
      "y": 2,
      "z": 0,
      "name": "Soil_Dirt"
    },
    {
      "x": -14,
      "y": 3,
      "z": 0,
      "name": "Soil_Grass"
    },
    {
      "x": -14,
      "y": 14,
      "z": 0,
      "name": "Wood_Ash_Roots"
    },
    {
      "x": -14,
      "y": 15,
      "z": 0,
      "name": "Wood_Ash_Trunk",
      "support": 15
    },
    {
      "x": -14,
      "y": 16,
      "z": 0,
      "name": "Wood_Ash_Trunk",
      "support": 15
    },
    {
      "x": -14,
      "y": 17,
      "z": 0,
      "name": "Wood_Ash_Trunk_Full"
    },
    {
      "x": -14,
      "y": 18,
      "z": 0,
      "name": "Furniture_Kweebec_Stool"
    },
    {
      "x": -14,
      "y": 0,
      "z": 1,
      "name": "Soil_Dirt"
    },
    {
      "x": -14,
      "y": 1,
      "z": 1,
      "name": "Soil_Dirt"
    },
    {
      "x": -14,
      "y": 2,
      "z": 1,
      "name": "Soil_Dirt"
    },
    {
      "x": -14,
      "y": 3,
      "z": 1,
      "name": "Soil_Grass"
    },
    {
      "x": -14,
      "y": 13,
      "z": 1,
      "name": "Wood_Ash_Trunk_Full"
    },
    {
      "x": -14,
      "y": 14,
      "z": 1,
      "name": "Wood_Ash_Trunk",
      "support": 15
    },
    {
      "x": -14,
      "y": 15,
      "z": 1,
      "name": "Wood_Ash_Trunk",
      "support": 15
    },
    {
      "x": -14,
      "y": 16,
      "z": 1,
      "name": "Wood_Ash_Trunk",
      "support": 15
    },
    {
      "x": -14,
      "y": 17,
      "z": 1,
      "name": "Wood_Ash_Trunk_Full"
    },
    {
      "x": -14,
      "y": 18,
      "z": 1,
      "name": "Furniture_Kweebec_Table",
      "filler": 1
    },
    {
      "x": -14,
      "y": 0,
      "z": 2,
      "name": "Soil_Dirt"
    },
    {
      "x": -14,
      "y": 1,
      "z": 2,
      "name": "Soil_Dirt"
    },
    {
      "x": -14,
      "y": 2,
      "z": 2,
      "name": "Soil_Dirt"
    },
    {
      "x": -14,
      "y": 3,
      "z": 2,
      "name": "Soil_Grass"
    },
    {
      "x": -14,
      "y": 13,
      "z": 2,
      "name": "Wood_Ash_Trunk_Full"
    },
    {
      "x": -14,
      "y": 14,
      "z": 2,
      "name": "Wood_Ash_Trunk",
      "support": 15
    },
    {
      "x": -14,
      "y": 15,
      "z": 2,
      "name": "Wood_Ash_Trunk",
      "support": 15
    },
    {
      "x": -14,
      "y": 16,
      "z": 2,
      "name": "Wood_Ash_Trunk",
      "support": 15
    },
    {
      "x": -14,
      "y": 17,
      "z": 2,
      "name": "Wood_Ash_Trunk_Full"
    },
    {
      "x": -14,
      "y": 18,
      "z": 2,
      "name": "Furniture_Kweebec_Table",
      "filler": 33
    },
    {
      "x": -14,
      "y": 0,
      "z": 3,
      "name": "Soil_Dirt"
    },
    {
      "x": -14,
      "y": 1,
      "z": 3,
      "name": "Soil_Dirt"
    },
    {
      "x": -14,
      "y": 2,
      "z": 3,
      "name": "Soil_Dirt"
    },
    {
      "x": -14,
      "y": 3,
      "z": 3,
      "name": "Soil_Grass"
    },
    {
      "x": -14,
      "y": 12,
      "z": 3,
      "name": "Wood_Ash_Roots"
    },
    {
      "x": -14,
      "y": 13,
      "z": 3,
      "name": "Wood_Ash_Trunk",
      "support": 15
    },
    {
      "x": -14,
      "y": 14,
      "z": 3,
      "name": "Wood_Ash_Trunk",
      "support": 15
    },
    {
      "x": -14,
      "y": 15,
      "z": 3,
      "name": "Wood_Ash_Trunk",
      "support": 15
    },
    {
      "x": -14,
      "y": 16,
      "z": 3,
      "name": "Wood_Ash_Trunk",
      "support": 15
    },
    {
      "x": -14,
      "y": 17,
      "z": 3,
      "name": "Wood_Ash_Trunk_Full"
    },
    {
      "x": -14,
      "y": 0,
      "z": 4,
      "name": "Soil_Dirt"
    },
    {
      "x": -14,
      "y": 1,
      "z": 4,
      "name": "Soil_Dirt"
    },
    {
      "x": -14,
      "y": 2,
      "z": 4,
      "name": "Soil_Dirt"
    },
    {
      "x": -14,
      "y": 3,
      "z": 4,
      "name": "Soil_Grass"
    },
    {
      "x": -14,
      "y": 14,
      "z": 4,
      "name": "Wood_Ash_Trunk_Full"
    },
    {
      "x": -14,
      "y": 15,
      "z": 4,
      "name": "Wood_Ash_Trunk",
      "support": 15
    },
    {
      "x": -14,
      "y": 16,
      "z": 4,
      "name": "Wood_Ash_Trunk_Full"
    },
    {
      "x": -14,
      "y": 17,
      "z": 4,
      "name": "Furniture_Kweebec_Platform",
      "rotation": 1
    },
    {
      "x": -14,
      "y": 0,
      "z": 5,
      "name": "Soil_Dirt"
    },
    {
      "x": -14,
      "y": 1,
      "z": 5,
      "name": "Soil_Dirt"
    },
    {
      "x": -14,
      "y": 2,
      "z": 5,
      "name": "Soil_Dirt"
    },
    {
      "x": -14,
      "y": 3,
      "z": 5,
      "name": "Soil_Grass"
    },
    {
      "x": -14,
      "y": 17,
      "z": 5,
      "name": "Furniture_Kweebec_Platform",
      "rotation": 1
    },
    {
      "x": -14,
      "y": 0,
      "z": 6,
      "name": "Soil_Dirt"
    },
    {
      "x": -14,
      "y": 1,
      "z": 6,
      "name": "Soil_Dirt"
    },
    {
      "x": -14,
      "y": 2,
      "z": 6,
      "name": "Soil_Dirt"
    },
    {
      "x": -14,
      "y": 3,
      "z": 6,
      "name": "Soil_Grass"
    },
    {
      "x": -14,
      "y": 0,
      "z": 7,
      "name": "Soil_Dirt"
    },
    {
      "x": -14,
      "y": 1,
      "z": 7,
      "name": "Soil_Dirt"
    },
    {
      "x": -14,
      "y": 2,
      "z": 7,
      "name": "Soil_Dirt"
    },
    {
      "x": -14,
      "y": 3,
      "z": 7,
      "name": "Soil_Grass"
    },
    {
      "x": -14,
      "y": 10,
      "z": 7,
      "name": "Rock_Stone"
    },
    {
      "x": -14,
      "y": 11,
      "z": 7,
      "name": "Rock_Stone_Mossy"
    },
    {
      "x": -14,
      "y": 12,
      "z": 7,
      "name": "Rock_Stone_Mossy"
    },
    {
      "x": -14,
      "y": 0,
      "z": 8,
      "name": "Wood_Ash_Trunk_Full"
    },
    {
      "x": -14,
      "y": 1,
      "z": 8,
      "name": "Wood_Ash_Trunk",
      "support": 15
    },
    {
      "x": -14,
      "y": 2,
      "z": 8,
      "name": "Wood_Ash_Trunk_Full"
    },
    {
      "x": -14,
      "y": 3,
      "z": 8,
      "name": "Soil_Grass"
    },
    {
      "x": -14,
      "y": 9,
      "z": 8,
      "name": "Rock_Stone"
    },
    {
      "x": -14,
      "y": 10,
      "z": 8,
      "name": "Rock_Stone_Mossy"
    },
    {
      "x": -14,
      "y": 11,
      "z": 8,
      "name": "Rock_Stone"
    },
    {
      "x": -14,
      "y": 12,
      "z": 8,
      "name": "Rock_Stone_Mossy"
    },
    {
      "x": -14,
      "y": 13,
      "z": 8,
      "name": "Rock_Stone"
    },
    {
      "x": -14,
      "y": 14,
      "z": 8,
      "name": "Rock_Stone"
    },
    {
      "x": -14,
      "y": 15,
      "z": 8,
      "name": "Rock_Stone"
    },
    {
      "x": -14,
      "y": 0,
      "z": 9,
      "name": "Wood_Ash_Trunk_Full"
    },
    {
      "x": -14,
      "y": 1,
      "z": 9,
      "name": "Wood_Ash_Trunk",
      "support": 15
    },
    {
      "x": -14,
      "y": 2,
      "z": 9,
      "name": "Wood_Ash_Trunk",
      "support": 15
    },
    {
      "x": -14,
      "y": 3,
      "z": 9,
      "name": "Wood_Ash_Trunk_Full"
    },
    {
      "x": -14,
      "y": 10,
      "z": 9,
      "name": "Rock_Stone_Mossy"
    },
    {
      "x": -14,
      "y": 11,
      "z": 9,
      "name": "Rock_Stone_Mossy"
    },
    {
      "x": -14,
      "y": 12,
      "z": 9,
      "name": "Rock_Stone"
    },
    {
      "x": -14,
      "y": 13,
      "z": 9,
      "name": "Rock_Stone"
    },
    {
      "x": -14,
      "y": 14,
      "z": 9,
      "name": "Rock_Stone"
    },
    {
      "x": -14,
      "y": 15,
      "z": 9,
      "name": "Rock_Stone"
    },
    {
      "x": -14,
      "y": 16,
      "z": 9,
      "name": "Rock_Stone"
    },
    {
      "x": -14,
      "y": 0,
      "z": 10,
      "name": "Soil_Dirt"
    },
    {
      "x": -14,
      "y": 1,
      "z": 10,
      "name": "Wood_Ash_Trunk_Full"
    },
    {
      "x": -14,
      "y": 2,
      "z": 10,
      "name": "Wood_Ash_Trunk",
      "support": 15
    },
    {
      "x": -14,
      "y": 3,
      "z": 10,
      "name": "Wood_Ash_Trunk",
      "support": 15
    },
    {
      "x": -14,
      "y": 4,
      "z": 10,
      "name": "Wood_Ash_Trunk_Full"
    },
    {
      "x": -14,
      "y": 13,
      "z": 10,
      "name": "Rock_Stone"
    },
    {
      "x": -14,
      "y": 14,
      "z": 10,
      "name": "Rock_Stone"
    },
    {
      "x": -14,
      "y": 15,
      "z": 10,
      "name": "Rock_Stone"
    },
    {
      "x": -14,
      "y": 16,
      "z": 10,
      "name": "Rock_Stone"
    },
    {
      "x": -14,
      "y": 0,
      "z": 11,
      "name": "Soil_Dirt"
    },
    {
      "x": -14,
      "y": 1,
      "z": 11,
      "name": "Soil_Dirt"
    },
    {
      "x": -14,
      "y": 2,
      "z": 11,
      "name": "Wood_Ash_Trunk_Full"
    },
    {
      "x": -14,
      "y": 3,
      "z": 11,
      "name": "Wood_Ash_Trunk",
      "support": 15
    },
    {
      "x": -14,
      "y": 4,
      "z": 11,
      "name": "Wood_Ash_Trunk_Full"
    },
    {
      "x": -14,
      "y": 0,
      "z": 12,
      "name": "Soil_Dirt"
    },
    {
      "x": -14,
      "y": 1,
      "z": 12,
      "name": "Soil_Dirt"
    },
    {
      "x": -14,
      "y": 2,
      "z": 12,
      "name": "Soil_Dirt"
    },
    {
      "x": -14,
      "y": 3,
      "z": 12,
      "name": "Wood_Ash_Trunk_Full"
    },
    {
      "x": -14,
      "y": 4,
      "z": 12,
      "name": "Wood_Ash_Trunk",
      "support": 15
    },
    {
      "x": -14,
      "y": 5,
      "z": 12,
      "name": "Wood_Ash_Trunk_Full"
    },
    {
      "x": -14,
      "y": 0,
      "z": 13,
      "name": "Soil_Dirt"
    },
    {
      "x": -14,
      "y": 1,
      "z": 13,
      "name": "Soil_Dirt"
    },
    {
      "x": -14,
      "y": 2,
      "z": 13,
      "name": "Soil_Dirt"
    },
    {
      "x": -14,
      "y": 3,
      "z": 13,
      "name": "Soil_Grass"
    },
    {
      "x": -14,
      "y": 4,
      "z": 13,
      "name": "Wood_Ash_Trunk_Full"
    },
    {
      "x": -14,
      "y": 0,
      "z": 14,
      "name": "Soil_Dirt"
    },
    {
      "x": -14,
      "y": 1,
      "z": 14,
      "name": "Soil_Dirt"
    },
    {
      "x": -14,
      "y": 2,
      "z": 14,
      "name": "Soil_Dirt"
    },
    {
      "x": -14,
      "y": 3,
      "z": 14,
      "name": "Soil_Grass"
    },
    {
      "x": -14,
      "y": 0,
      "z": 15,
      "name": "Soil_Dirt"
    },
    {
      "x": -14,
      "y": 1,
      "z": 15,
      "name": "Soil_Dirt"
    },
    {
      "x": -14,
      "y": 2,
      "z": 15,
      "name": "Soil_Dirt"
    },
    {
      "x": -14,
      "y": 3,
      "z": 15,
      "name": "Soil_Grass"
    },
    {
      "x": -14,
      "y": 0,
      "z": 16,
      "name": "Soil_Dirt"
    },
    {
      "x": -14,
      "y": 1,
      "z": 16,
      "name": "Soil_Dirt"
    },
    {
      "x": -14,
      "y": 2,
      "z": 16,
      "name": "Soil_Dirt"
    },
    {
      "x": -14,
      "y": 3,
      "z": 16,
      "name": "Soil_Grass"
    },
    {
      "x": -13,
      "y": 0,
      "z": -15,
      "name": "Soil_Dirt"
    },
    {
      "x": -13,
      "y": 1,
      "z": -15,
      "name": "Soil_Dirt"
    },
    {
      "x": -13,
      "y": 2,
      "z": -15,
      "name": "Soil_Dirt"
    },
    {
      "x": -13,
      "y": 3,
      "z": -15,
      "name": "Soil_Grass"
    },
    {
      "x": -13,
      "y": 0,
      "z": -14,
      "name": "Soil_Dirt"
    },
    {
      "x": -13,
      "y": 1,
      "z": -14,
      "name": "Soil_Dirt"
    },
    {
      "x": -13,
      "y": 2,
      "z": -14,
      "name": "Soil_Dirt"
    },
    {
      "x": -13,
      "y": 3,
      "z": -14,
      "name": "Soil_Grass"
    },
    {
      "x": -13,
      "y": 0,
      "z": -13,
      "name": "Soil_Dirt"
    },
    {
      "x": -13,
      "y": 1,
      "z": -13,
      "name": "Soil_Dirt"
    },
    {
      "x": -13,
      "y": 2,
      "z": -13,
      "name": "Soil_Dirt"
    },
    {
      "x": -13,
      "y": 3,
      "z": -13,
      "name": "Soil_Grass"
    },
    {
      "x": -13,
      "y": 0,
      "z": -12,
      "name": "Soil_Dirt"
    },
    {
      "x": -13,
      "y": 1,
      "z": -12,
      "name": "Soil_Dirt"
    },
    {
      "x": -13,
      "y": 2,
      "z": -12,
      "name": "Soil_Dirt"
    },
    {
      "x": -13,
      "y": 3,
      "z": -12,
      "name": "Soil_Grass"
    },
    {
      "x": -13,
      "y": 0,
      "z": -11,
      "name": "Soil_Dirt"
    },
    {
      "x": -13,
      "y": 1,
      "z": -11,
      "name": "Soil_Dirt"
    },
    {
      "x": -13,
      "y": 2,
      "z": -11,
      "name": "Soil_Dirt"
    },
    {
      "x": -13,
      "y": 3,
      "z": -11,
      "name": "Soil_Grass"
    },
    {
      "x": -13,
      "y": 0,
      "z": -10,
      "name": "Soil_Dirt"
    },
    {
      "x": -13,
      "y": 1,
      "z": -10,
      "name": "Soil_Dirt"
    },
    {
      "x": -13,
      "y": 2,
      "z": -10,
      "name": "Wood_Ash_Trunk_Full"
    },
    {
      "x": -13,
      "y": 3,
      "z": -10,
      "name": "Wood_Ash_Trunk_Full"
    },
    {
      "x": -13,
      "y": 4,
      "z": -10,
      "name": "Wood_Ash_Trunk_Full"
    },
    {
      "x": -13,
      "y": 0,
      "z": -9,
      "name": "Soil_Dirt"
    },
    {
      "x": -13,
      "y": 1,
      "z": -9,
      "name": "Soil_Dirt"
    },
    {
      "x": -13,
      "y": 2,
      "z": -9,
      "name": "Wood_Ash_Trunk_Full"
    },
    {
      "x": -13,
      "y": 3,
      "z": -9,
      "name": "Wood_Ash_Trunk",
      "support": 15
    },
    {
      "x": -13,
      "y": 4,
      "z": -9,
      "name": "Wood_Ash_Trunk",
      "support": 15
    },
    {
      "x": -13,
      "y": 5,
      "z": -9,
      "name": "Wood_Ash_Trunk_Full"
    },
    {
      "x": -13,
      "y": 0,
      "z": -8,
      "name": "Soil_Dirt"
    },
    {
      "x": -13,
      "y": 1,
      "z": -8,
      "name": "Soil_Dirt"
    },
    {
      "x": -13,
      "y": 2,
      "z": -8,
      "name": "Wood_Ash_Trunk_Full"
    },
    {
      "x": -13,
      "y": 3,
      "z": -8,
      "name": "Wood_Ash_Trunk",
      "support": 15
    },
    {
      "x": -13,
      "y": 4,
      "z": -8,
      "name": "Wood_Ash_Trunk",
      "support": 15
    },
    {
      "x": -13,
      "y": 5,
      "z": -8,
      "name": "Wood_Ash_Trunk",
      "support": 15
    },
    {
      "x": -13,
      "y": 6,
      "z": -8,
      "name": "Wood_Ash_Trunk_Full"
    },
    {
      "x": -13,
      "y": 0,
      "z": -7,
      "name": "Soil_Dirt"
    },
    {
      "x": -13,
      "y": 1,
      "z": -7,
      "name": "Soil_Dirt"
    },
    {
      "x": -13,
      "y": 2,
      "z": -7,
      "name": "Wood_Ash_Trunk_Full"
    },
    {
      "x": -13,
      "y": 3,
      "z": -7,
      "name": "Wood_Ash_Trunk",
      "support": 15
    },
    {
      "x": -13,
      "y": 4,
      "z": -7,
      "name": "Wood_Ash_Trunk",
      "support": 15
    },
    {
      "x": -13,
      "y": 5,
      "z": -7,
      "name": "Wood_Ash_Trunk",
      "support": 15
    },
    {
      "x": -13,
      "y": 6,
      "z": -7,
      "name": "Wood_Ash_Trunk",
      "support": 15
    },
    {
      "x": -13,
      "y": 7,
      "z": -7,
      "name": "Wood_Ash_Trunk_Full"
    },
    {
      "x": -13,
      "y": 0,
      "z": -6,
      "name": "Soil_Dirt"
    },
    {
      "x": -13,
      "y": 1,
      "z": -6,
      "name": "Soil_Dirt"
    },
    {
      "x": -13,
      "y": 2,
      "z": -6,
      "name": "Wood_Ash_Trunk_Full"
    },
    {
      "x": -13,
      "y": 3,
      "z": -6,
      "name": "Wood_Ash_Trunk",
      "support": 15
    },
    {
      "x": -13,
      "y": 4,
      "z": -6,
      "name": "Wood_Ash_Trunk",
      "support": 15
    },
    {
      "x": -13,
      "y": 5,
      "z": -6,
      "name": "Wood_Ash_Trunk",
      "support": 15
    },
    {
      "x": -13,
      "y": 6,
      "z": -6,
      "name": "Wood_Ash_Trunk",
      "support": 15
    },
    {
      "x": -13,
      "y": 7,
      "z": -6,
      "name": "Wood_Ash_Trunk",
      "support": 15
    },
    {
      "x": -13,
      "y": 8,
      "z": -6,
      "name": "Wood_Ash_Trunk_Full"
    },
    {
      "x": -13,
      "y": 0,
      "z": -5,
      "name": "Soil_Dirt"
    },
    {
      "x": -13,
      "y": 1,
      "z": -5,
      "name": "Soil_Dirt"
    },
    {
      "x": -13,
      "y": 2,
      "z": -5,
      "name": "Wood_Ash_Roots"
    },
    {
      "x": -13,
      "y": 3,
      "z": -5,
      "name": "Wood_Ash_Trunk_Full"
    },
    {
      "x": -13,
      "y": 4,
      "z": -5,
      "name": "Wood_Ash_Trunk",
      "support": 15
    },
    {
      "x": -13,
      "y": 5,
      "z": -5,
      "name": "Wood_Ash_Trunk",
      "support": 15
    },
    {
      "x": -13,
      "y": 6,
      "z": -5,
      "name": "Wood_Ash_Trunk",
      "support": 15
    },
    {
      "x": -13,
      "y": 7,
      "z": -5,
      "name": "Wood_Ash_Trunk",
      "support": 15
    },
    {
      "x": -13,
      "y": 8,
      "z": -5,
      "name": "Wood_Ash_Trunk_Full"
    },
    {
      "x": -13,
      "y": 0,
      "z": -4,
      "name": "Soil_Dirt"
    },
    {
      "x": -13,
      "y": 1,
      "z": -4,
      "name": "Soil_Dirt"
    },
    {
      "x": -13,
      "y": 2,
      "z": -4,
      "name": "Soil_Dirt"
    },
    {
      "x": -13,
      "y": 3,
      "z": -4,
      "name": "Soil_Grass"
    },
    {
      "x": -13,
      "y": 4,
      "z": -4,
      "name": "Wood_Ash_Trunk_Full"
    },
    {
      "x": -13,
      "y": 5,
      "z": -4,
      "name": "Wood_Ash_Trunk",
      "support": 15
    },
    {
      "x": -13,
      "y": 6,
      "z": -4,
      "name": "Wood_Ash_Trunk",
      "support": 15
    },
    {
      "x": -13,
      "y": 7,
      "z": -4,
      "name": "Wood_Ash_Trunk",
      "support": 15
    },
    {
      "x": -13,
      "y": 8,
      "z": -4,
      "name": "Wood_Ash_Trunk",
      "support": 15
    },
    {
      "x": -13,
      "y": 9,
      "z": -4,
      "name": "Wood_Ash_Trunk_Full"
    },
    {
      "x": -13,
      "y": 0,
      "z": -3,
      "name": "Soil_Dirt"
    },
    {
      "x": -13,
      "y": 1,
      "z": -3,
      "name": "Soil_Dirt"
    },
    {
      "x": -13,
      "y": 2,
      "z": -3,
      "name": "Soil_Dirt"
    },
    {
      "x": -13,
      "y": 3,
      "z": -3,
      "name": "Soil_Grass"
    },
    {
      "x": -13,
      "y": 7,
      "z": -3,
      "name": "Wood_Ash_Trunk_Full"
    },
    {
      "x": -13,
      "y": 8,
      "z": -3,
      "name": "Wood_Ash_Trunk",
      "support": 15
    },
    {
      "x": -13,
      "y": 9,
      "z": -3,
      "name": "Wood_Ash_Trunk_Full"
    },
    {
      "x": -13,
      "y": 0,
      "z": -2,
      "name": "Soil_Dirt"
    },
    {
      "x": -13,
      "y": 1,
      "z": -2,
      "name": "Soil_Dirt"
    },
    {
      "x": -13,
      "y": 2,
      "z": -2,
      "name": "Soil_Dirt"
    },
    {
      "x": -13,
      "y": 3,
      "z": -2,
      "name": "Soil_Grass"
    },
    {
      "x": -13,
      "y": 0,
      "z": -1,
      "name": "Soil_Dirt"
    },
    {
      "x": -13,
      "y": 1,
      "z": -1,
      "name": "Soil_Dirt"
    },
    {
      "x": -13,
      "y": 2,
      "z": -1,
      "name": "Soil_Dirt"
    },
    {
      "x": -13,
      "y": 3,
      "z": -1,
      "name": "Soil_Grass"
    },
    {
      "x": -13,
      "y": 0,
      "z": 0,
      "name": "Soil_Dirt"
    },
    {
      "x": -13,
      "y": 1,
      "z": 0,
      "name": "Soil_Dirt"
    },
    {
      "x": -13,
      "y": 2,
      "z": 0,
      "name": "Soil_Dirt"
    },
    {
      "x": -13,
      "y": 3,
      "z": 0,
      "name": "Soil_Grass"
    },
    {
      "x": -13,
      "y": 15,
      "z": 0,
      "name": "Wood_Ash_Trunk_Full"
    },
    {
      "x": -13,
      "y": 16,
      "z": 0,
      "name": "Wood_Ash_Trunk_Full"
    },
    {
      "x": -13,
      "y": 0,
      "z": 1,
      "name": "Soil_Dirt"
    },
    {
      "x": -13,
      "y": 1,
      "z": 1,
      "name": "Soil_Dirt"
    },
    {
      "x": -13,
      "y": 2,
      "z": 1,
      "name": "Soil_Dirt"
    },
    {
      "x": -13,
      "y": 3,
      "z": 1,
      "name": "Soil_Grass"
    },
    {
      "x": -13,
      "y": 13,
      "z": 1,
      "name": "Wood_Ash_Roots"
    },
    {
      "x": -13,
      "y": 14,
      "z": 1,
      "name": "Wood_Ash_Trunk",
      "support": 15
    },
    {
      "x": -13,
      "y": 15,
      "z": 1,
      "name": "Wood_Ash_Trunk",
      "support": 15
    },
    {
      "x": -13,
      "y": 16,
      "z": 1,
      "name": "Wood_Ash_Trunk",
      "support": 15
    },
    {
      "x": -13,
      "y": 17,
      "z": 1,
      "name": "Wood_Ash_Trunk_Full"
    },
    {
      "x": -13,
      "y": 18,
      "z": 1,
      "name": "Container_Bucket"
    },
    {
      "x": -13,
      "y": 0,
      "z": 2,
      "name": "Soil_Dirt"
    },
    {
      "x": -13,
      "y": 1,
      "z": 2,
      "name": "Soil_Dirt"
    },
    {
      "x": -13,
      "y": 2,
      "z": 2,
      "name": "Soil_Dirt"
    },
    {
      "x": -13,
      "y": 3,
      "z": 2,
      "name": "Soil_Grass"
    },
    {
      "x": -13,
      "y": 13,
      "z": 2,
      "name": "Wood_Ash_Trunk_Full"
    },
    {
      "x": -13,
      "y": 14,
      "z": 2,
      "name": "Wood_Ash_Trunk",
      "support": 15
    },
    {
      "x": -13,
      "y": 15,
      "z": 2,
      "name": "Wood_Ash_Trunk",
      "support": 15
    },
    {
      "x": -13,
      "y": 16,
      "z": 2,
      "name": "Wood_Ash_Trunk",
      "support": 15
    },
    {
      "x": -13,
      "y": 17,
      "z": 2,
      "name": "Wood_Ash_Trunk_Full"
    },
    {
      "x": -13,
      "y": 18,
      "z": 2,
      "name": "Wood_Ash_Branch_Long"
    },
    {
      "x": -13,
      "y": 0,
      "z": 3,
      "name": "Soil_Dirt"
    },
    {
      "x": -13,
      "y": 1,
      "z": 3,
      "name": "Soil_Dirt"
    },
    {
      "x": -13,
      "y": 2,
      "z": 3,
      "name": "Soil_Dirt"
    },
    {
      "x": -13,
      "y": 3,
      "z": 3,
      "name": "Soil_Grass"
    },
    {
      "x": -13,
      "y": 13,
      "z": 3,
      "name": "Wood_Ash_Trunk_Full"
    },
    {
      "x": -13,
      "y": 14,
      "z": 3,
      "name": "Wood_Ash_Trunk",
      "support": 15
    },
    {
      "x": -13,
      "y": 15,
      "z": 3,
      "name": "Wood_Ash_Trunk",
      "support": 15
    },
    {
      "x": -13,
      "y": 16,
      "z": 3,
      "name": "Wood_Ash_Trunk",
      "support": 15
    },
    {
      "x": -13,
      "y": 17,
      "z": 3,
      "name": "Wood_Ash_Trunk_Full"
    },
    {
      "x": -13,
      "y": 0,
      "z": 4,
      "name": "Soil_Dirt"
    },
    {
      "x": -13,
      "y": 1,
      "z": 4,
      "name": "Soil_Dirt"
    },
    {
      "x": -13,
      "y": 2,
      "z": 4,
      "name": "Soil_Dirt"
    },
    {
      "x": -13,
      "y": 3,
      "z": 4,
      "name": "Soil_Grass"
    },
    {
      "x": -13,
      "y": 15,
      "z": 4,
      "name": "Wood_Ash_Trunk_Full"
    },
    {
      "x": -13,
      "y": 16,
      "z": 4,
      "name": "Wood_Ash_Trunk",
      "support": 15
    },
    {
      "x": -13,
      "y": 17,
      "z": 4,
      "name": "Wood_Ash_Trunk_Full"
    },
    {
      "x": -13,
      "y": 0,
      "z": 5,
      "name": "Soil_Dirt"
    },
    {
      "x": -13,
      "y": 1,
      "z": 5,
      "name": "Soil_Dirt"
    },
    {
      "x": -13,
      "y": 2,
      "z": 5,
      "name": "Soil_Dirt"
    },
    {
      "x": -13,
      "y": 3,
      "z": 5,
      "name": "Soil_Grass"
    },
    {
      "x": -13,
      "y": 10,
      "z": 5,
      "name": "Rock_Stone_Mossy"
    },
    {
      "x": -13,
      "y": 11,
      "z": 5,
      "name": "Rock_Stone_Mossy"
    },
    {
      "x": -13,
      "y": 12,
      "z": 5,
      "name": "Rock_Stone_Mossy"
    },
    {
      "x": -13,
      "y": 15,
      "z": 5,
      "name": "Wood_Ash_Branch_Long",
      "rotation": 4
    },
    {
      "x": -13,
      "y": 17,
      "z": 5,
      "name": "Furniture_Kweebec_Platform",
      "rotation": 1
    },
    {
      "x": -13,
      "y": 0,
      "z": 6,
      "name": "Soil_Dirt"
    },
    {
      "x": -13,
      "y": 1,
      "z": 6,
      "name": "Soil_Dirt"
    },
    {
      "x": -13,
      "y": 2,
      "z": 6,
      "name": "Soil_Dirt"
    },
    {
      "x": -13,
      "y": 3,
      "z": 6,
      "name": "Soil_Grass"
    },
    {
      "x": -13,
      "y": 8,
      "z": 6,
      "name": "Rock_Stone"
    },
    {
      "x": -13,
      "y": 9,
      "z": 6,
      "name": "Rock_Stone_Mossy"
    },
    {
      "x": -13,
      "y": 10,
      "z": 6,
      "name": "Rock_Stone_Mossy"
    },
    {
      "x": -13,
      "y": 11,
      "z": 6,
      "name": "Rock_Stone_Mossy"
    },
    {
      "x": -13,
      "y": 12,
      "z": 6,
      "name": "Rock_Stone_Mossy"
    },
    {
      "x": -13,
      "y": 13,
      "z": 6,
      "name": "Rock_Stone"
    },
    {
      "x": -13,
      "y": 14,
      "z": 6,
      "name": "Rock_Stone"
    },
    {
      "x": -13,
      "y": 15,
      "z": 6,
      "name": "Wood_Ash_Branch_Corner"
    },
    {
      "x": -13,
      "y": 16,
      "z": 6,
      "name": "Wood_Ash_Branch_Long"
    },
    {
      "x": -13,
      "y": 17,
      "z": 6,
      "name": "Wood_Ash_Branch_Long"
    },
    {
      "x": -13,
      "y": 18,
      "z": 6,
      "name": "Wood_Ash_Branch_Long"
    },
    {
      "x": -13,
      "y": 0,
      "z": 7,
      "name": "Soil_Dirt"
    },
    {
      "x": -13,
      "y": 1,
      "z": 7,
      "name": "Soil_Dirt"
    },
    {
      "x": -13,
      "y": 2,
      "z": 7,
      "name": "Soil_Dirt"
    },
    {
      "x": -13,
      "y": 3,
      "z": 7,
      "name": "Soil_Grass"
    },
    {
      "x": -13,
      "y": 5,
      "z": 7,
      "name": "Rock_Stone"
    },
    {
      "x": -13,
      "y": 6,
      "z": 7,
      "name": "Rock_Stone_Mossy"
    },
    {
      "x": -13,
      "y": 7,
      "z": 7,
      "name": "Rock_Stone_Mossy"
    },
    {
      "x": -13,
      "y": 8,
      "z": 7,
      "name": "Rock_Stone_Mossy"
    },
    {
      "x": -13,
      "y": 9,
      "z": 7,
      "name": "Rock_Stone"
    },
    {
      "x": -13,
      "y": 10,
      "z": 7,
      "name": "Rock_Stone_Mossy"
    },
    {
      "x": -13,
      "y": 11,
      "z": 7,
      "name": "Rock_Stone"
    },
    {
      "x": -13,
      "y": 12,
      "z": 7,
      "name": "Rock_Stone_Mossy"
    },
    {
      "x": -13,
      "y": 13,
      "z": 7,
      "name": "Rock_Stone"
    },
    {
      "x": -13,
      "y": 14,
      "z": 7,
      "name": "Rock_Stone"
    },
    {
      "x": -13,
      "y": 0,
      "z": 8,
      "name": "Soil_Dirt"
    },
    {
      "x": -13,
      "y": 1,
      "z": 8,
      "name": "Wood_Ash_Trunk_Full"
    },
    {
      "x": -13,
      "y": 2,
      "z": 8,
      "name": "Wood_Ash_Trunk",
      "support": 15
    },
    {
      "x": -13,
      "y": 3,
      "z": 8,
      "name": "Wood_Ash_Trunk",
      "support": 15
    },
    {
      "x": -13,
      "y": 4,
      "z": 8,
      "name": "Rock_Stone"
    },
    {
      "x": -13,
      "y": 5,
      "z": 8,
      "name": "Rock_Stone"
    },
    {
      "x": -13,
      "y": 6,
      "z": 8,
      "name": "Rock_Stone_Mossy"
    },
    {
      "x": -13,
      "y": 7,
      "z": 8,
      "name": "Rock_Stone_Mossy"
    },
    {
      "x": -13,
      "y": 8,
      "z": 8,
      "name": "Rock_Stone"
    },
    {
      "x": -13,
      "y": 9,
      "z": 8,
      "name": "Rock_Stone"
    },
    {
      "x": -13,
      "y": 10,
      "z": 8,
      "name": "Rock_Stone"
    },
    {
      "x": -13,
      "y": 11,
      "z": 8,
      "name": "Rock_Stone"
    },
    {
      "x": -13,
      "y": 12,
      "z": 8,
      "name": "Rock_Stone"
    },
    {
      "x": -13,
      "y": 13,
      "z": 8,
      "name": "Rock_Stone"
    },
    {
      "x": -13,
      "y": 14,
      "z": 8,
      "name": "Rock_Stone"
    },
    {
      "x": -13,
      "y": 15,
      "z": 8,
      "name": "Rock_Stone"
    },
    {
      "x": -13,
      "y": 16,
      "z": 8,
      "name": "Rock_Stone_Mossy"
    },
    {
      "x": -13,
      "y": 17,
      "z": 8,
      "name": "Rock_Stone_Mossy"
    },
    {
      "x": -13,
      "y": 18,
      "z": 8,
      "name": "Rock_Stone_Mossy"
    },
    {
      "x": -13,
      "y": 0,
      "z": 9,
      "name": "Soil_Dirt"
    },
    {
      "x": -13,
      "y": 1,
      "z": 9,
      "name": "Wood_Ash_Trunk_Full"
    },
    {
      "x": -13,
      "y": 2,
      "z": 9,
      "name": "Wood_Ash_Trunk",
      "support": 15
    },
    {
      "x": -13,
      "y": 3,
      "z": 9,
      "name": "Wood_Ash_Trunk",
      "support": 15
    },
    {
      "x": -13,
      "y": 4,
      "z": 9,
      "name": "Wood_Ash_Trunk",
      "support": 15
    },
    {
      "x": -13,
      "y": 5,
      "z": 9,
      "name": "Rock_Stone_Mossy"
    },
    {
      "x": -13,
      "y": 6,
      "z": 9,
      "name": "Rock_Stone_Mossy"
    },
    {
      "x": -13,
      "y": 7,
      "z": 9,
      "name": "Rock_Stone_Mossy"
    },
    {
      "x": -13,
      "y": 8,
      "z": 9,
      "name": "Rock_Stone"
    },
    {
      "x": -13,
      "y": 9,
      "z": 9,
      "name": "Rock_Stone"
    },
    {
      "x": -13,
      "y": 10,
      "z": 9,
      "name": "Rock_Stone_Mossy"
    },
    {
      "x": -13,
      "y": 11,
      "z": 9,
      "name": "Rock_Stone"
    },
    {
      "x": -13,
      "y": 12,
      "z": 9,
      "name": "Rock_Stone"
    },
    {
      "x": -13,
      "y": 13,
      "z": 9,
      "name": "Rock_Stone"
    },
    {
      "x": -13,
      "y": 14,
      "z": 9,
      "name": "Rock_Stone"
    },
    {
      "x": -13,
      "y": 15,
      "z": 9,
      "name": "Rock_Stone"
    },
    {
      "x": -13,
      "y": 16,
      "z": 9,
      "name": "Rock_Stone"
    },
    {
      "x": -13,
      "y": 17,
      "z": 9,
      "name": "Rock_Stone_Mossy"
    },
    {
      "x": -13,
      "y": 18,
      "z": 9,
      "name": "Rock_Stone_Mossy"
    },
    {
      "x": -13,
      "y": 0,
      "z": 10,
      "name": "Soil_Dirt"
    },
    {
      "x": -13,
      "y": 1,
      "z": 10,
      "name": "Soil_Dirt"
    },
    {
      "x": -13,
      "y": 2,
      "z": 10,
      "name": "Wood_Ash_Trunk_Full"
    },
    {
      "x": -13,
      "y": 3,
      "z": 10,
      "name": "Wood_Ash_Trunk",
      "support": 15
    },
    {
      "x": -13,
      "y": 4,
      "z": 10,
      "name": "Wood_Ash_Trunk_Full"
    },
    {
      "x": -13,
      "y": 8,
      "z": 10,
      "name": "Rock_Stone"
    },
    {
      "x": -13,
      "y": 9,
      "z": 10,
      "name": "Rock_Stone"
    },
    {
      "x": -13,
      "y": 10,
      "z": 10,
      "name": "Rock_Stone"
    },
    {
      "x": -13,
      "y": 11,
      "z": 10,
      "name": "Rock_Stone"
    },
    {
      "x": -13,
      "y": 12,
      "z": 10,
      "name": "Rock_Stone"
    },
    {
      "x": -13,
      "y": 13,
      "z": 10,
      "name": "Rock_Stone"
    },
    {
      "x": -13,
      "y": 14,
      "z": 10,
      "name": "Rock_Stone"
    },
    {
      "x": -13,
      "y": 15,
      "z": 10,
      "name": "Rock_Stone"
    },
    {
      "x": -13,
      "y": 16,
      "z": 10,
      "name": "Rock_Stone_Mossy"
    },
    {
      "x": -13,
      "y": 17,
      "z": 10,
      "name": "Rock_Stone"
    },
    {
      "x": -13,
      "y": 18,
      "z": 10,
      "name": "Rock_Stone_Mossy"
    },
    {
      "x": -13,
      "y": 0,
      "z": 11,
      "name": "Soil_Dirt"
    },
    {
      "x": -13,
      "y": 1,
      "z": 11,
      "name": "Soil_Dirt"
    },
    {
      "x": -13,
      "y": 2,
      "z": 11,
      "name": "Soil_Dirt"
    },
    {
      "x": -13,
      "y": 3,
      "z": 11,
      "name": "Wood_Ash_Trunk_Full"
    },
    {
      "x": -13,
      "y": 4,
      "z": 11,
      "name": "Wood_Ash_Trunk",
      "support": 15
    },
    {
      "x": -13,
      "y": 5,
      "z": 11,
      "name": "Wood_Ash_Trunk_Full"
    },
    {
      "x": -13,
      "y": 10,
      "z": 11,
      "name": "Rock_Stone"
    },
    {
      "x": -13,
      "y": 11,
      "z": 11,
      "name": "Rock_Stone"
    },
    {
      "x": -13,
      "y": 12,
      "z": 11,
      "name": "Rock_Stone_Mossy"
    },
    {
      "x": -13,
      "y": 13,
      "z": 11,
      "name": "Rock_Stone"
    },
    {
      "x": -13,
      "y": 14,
      "z": 11,
      "name": "Rock_Stone"
    },
    {
      "x": -13,
      "y": 15,
      "z": 11,
      "name": "Rock_Stone_Mossy"
    },
    {
      "x": -13,
      "y": 16,
      "z": 11,
      "name": "Rock_Stone_Mossy"
    },
    {
      "x": -13,
      "y": 17,
      "z": 11,
      "name": "Rock_Stone_Mossy"
    },
    {
      "x": -13,
      "y": 0,
      "z": 12,
      "name": "Soil_Dirt"
    },
    {
      "x": -13,
      "y": 1,
      "z": 12,
      "name": "Soil_Dirt"
    },
    {
      "x": -13,
      "y": 2,
      "z": 12,
      "name": "Soil_Dirt"
    },
    {
      "x": -13,
      "y": 3,
      "z": 12,
      "name": "Wood_Ash_Trunk_Full"
    },
    {
      "x": -13,
      "y": 4,
      "z": 12,
      "name": "Wood_Ash_Trunk",
      "support": 15
    },
    {
      "x": -13,
      "y": 5,
      "z": 12,
      "name": "Wood_Ash_Trunk_Full"
    },
    {
      "x": -13,
      "y": 12,
      "z": 12,
      "name": "Rock_Stone_Mossy"
    },
    {
      "x": -13,
      "y": 13,
      "z": 12,
      "name": "Rock_Stone_Mossy"
    },
    {
      "x": -13,
      "y": 14,
      "z": 12,
      "name": "Rock_Stone"
    },
    {
      "x": -13,
      "y": 0,
      "z": 13,
      "name": "Wood_Ash_Trunk_Full"
    },
    {
      "x": -13,
      "y": 1,
      "z": 13,
      "name": "Wood_Ash_Trunk",
      "support": 15
    },
    {
      "x": -13,
      "y": 2,
      "z": 13,
      "name": "Wood_Ash_Trunk",
      "support": 15
    },
    {
      "x": -13,
      "y": 3,
      "z": 13,
      "name": "Wood_Ash_Trunk",
      "support": 15
    },
    {
      "x": -13,
      "y": 4,
      "z": 13,
      "name": "Wood_Ash_Trunk",
      "support": 15
    },
    {
      "x": -13,
      "y": 5,
      "z": 13,
      "name": "Wood_Ash_Trunk_Full"
    },
    {
      "x": -13,
      "y": 0,
      "z": 14,
      "name": "Wood_Ash_Trunk",
      "support": 15
    },
    {
      "x": -13,
      "y": 1,
      "z": 14,
      "name": "Wood_Ash_Trunk",
      "support": 15
    },
    {
      "x": -13,
      "y": 2,
      "z": 14,
      "name": "Wood_Ash_Trunk_Full"
    },
    {
      "x": -13,
      "y": 3,
      "z": 14,
      "name": "Soil_Grass"
    },
    {
      "x": -13,
      "y": 0,
      "z": 15,
      "name": "Soil_Dirt"
    },
    {
      "x": -13,
      "y": 1,
      "z": 15,
      "name": "Soil_Dirt"
    },
    {
      "x": -13,
      "y": 2,
      "z": 15,
      "name": "Soil_Dirt"
    },
    {
      "x": -13,
      "y": 3,
      "z": 15,
      "name": "Soil_Grass"
    },
    {
      "x": -13,
      "y": 0,
      "z": 16,
      "name": "Soil_Dirt"
    },
    {
      "x": -13,
      "y": 1,
      "z": 16,
      "name": "Soil_Dirt"
    },
    {
      "x": -13,
      "y": 2,
      "z": 16,
      "name": "Soil_Dirt"
    },
    {
      "x": -13,
      "y": 3,
      "z": 16,
      "name": "Soil_Grass"
    },
    {
      "x": -12,
      "y": 0,
      "z": -15,
      "name": "Soil_Dirt"
    },
    {
      "x": -12,
      "y": 1,
      "z": -15,
      "name": "Soil_Dirt"
    },
    {
      "x": -12,
      "y": 2,
      "z": -15,
      "name": "Soil_Dirt"
    },
    {
      "x": -12,
      "y": 3,
      "z": -15,
      "name": "Soil_Grass"
    },
    {
      "x": -12,
      "y": 0,
      "z": -14,
      "name": "Soil_Dirt"
    },
    {
      "x": -12,
      "y": 1,
      "z": -14,
      "name": "Soil_Dirt"
    },
    {
      "x": -12,
      "y": 2,
      "z": -14,
      "name": "Soil_Dirt"
    },
    {
      "x": -12,
      "y": 3,
      "z": -14,
      "name": "Soil_Grass"
    },
    {
      "x": -12,
      "y": 0,
      "z": -13,
      "name": "Soil_Dirt"
    },
    {
      "x": -12,
      "y": 1,
      "z": -13,
      "name": "Soil_Dirt"
    },
    {
      "x": -12,
      "y": 2,
      "z": -13,
      "name": "Soil_Dirt"
    },
    {
      "x": -12,
      "y": 3,
      "z": -13,
      "name": "Soil_Grass"
    },
    {
      "x": -12,
      "y": 0,
      "z": -12,
      "name": "Soil_Dirt"
    },
    {
      "x": -12,
      "y": 1,
      "z": -12,
      "name": "Soil_Dirt"
    },
    {
      "x": -12,
      "y": 2,
      "z": -12,
      "name": "Soil_Dirt"
    },
    {
      "x": -12,
      "y": 3,
      "z": -12,
      "name": "Soil_Grass"
    },
    {
      "x": -12,
      "y": 0,
      "z": -11,
      "name": "Soil_Dirt"
    },
    {
      "x": -12,
      "y": 1,
      "z": -11,
      "name": "Soil_Dirt"
    },
    {
      "x": -12,
      "y": 2,
      "z": -11,
      "name": "Soil_Dirt"
    },
    {
      "x": -12,
      "y": 3,
      "z": -11,
      "name": "Soil_Grass"
    },
    {
      "x": -12,
      "y": 0,
      "z": -10,
      "name": "Soil_Dirt"
    },
    {
      "x": -12,
      "y": 1,
      "z": -10,
      "name": "Soil_Dirt"
    },
    {
      "x": -12,
      "y": 2,
      "z": -10,
      "name": "Soil_Dirt"
    },
    {
      "x": -12,
      "y": 3,
      "z": -10,
      "name": "Wood_Ash_Trunk_Full"
    },
    {
      "x": -12,
      "y": 4,
      "z": -10,
      "name": "Wood_Ash_Trunk_Full"
    },
    {
      "x": -12,
      "y": 0,
      "z": -9,
      "name": "Soil_Dirt"
    },
    {
      "x": -12,
      "y": 1,
      "z": -9,
      "name": "Wood_Ash_Trunk_Full"
    },
    {
      "x": -12,
      "y": 2,
      "z": -9,
      "name": "Wood_Ash_Trunk",
      "support": 15
    },
    {
      "x": -12,
      "y": 3,
      "z": -9,
      "name": "Wood_Ash_Trunk",
      "support": 15
    },
    {
      "x": -12,
      "y": 4,
      "z": -9,
      "name": "Wood_Ash_Trunk",
      "support": 15
    },
    {
      "x": -12,
      "y": 5,
      "z": -9,
      "name": "Wood_Ash_Trunk_Full"
    },
    {
      "x": -12,
      "y": 0,
      "z": -8,
      "name": "Soil_Dirt"
    },
    {
      "x": -12,
      "y": 1,
      "z": -8,
      "name": "Soil_Dirt"
    },
    {
      "x": -12,
      "y": 2,
      "z": -8,
      "name": "Wood_Ash_Trunk_Full"
    },
    {
      "x": -12,
      "y": 3,
      "z": -8,
      "name": "Wood_Ash_Trunk",
      "support": 15
    },
    {
      "x": -12,
      "y": 4,
      "z": -8,
      "name": "Wood_Ash_Trunk",
      "support": 15
    },
    {
      "x": -12,
      "y": 5,
      "z": -8,
      "name": "Wood_Ash_Trunk_Full"
    },
    {
      "x": -12,
      "y": 0,
      "z": -7,
      "name": "Soil_Dirt"
    },
    {
      "x": -12,
      "y": 1,
      "z": -7,
      "name": "Soil_Dirt"
    },
    {
      "x": -12,
      "y": 2,
      "z": -7,
      "name": "Wood_Ash_Trunk_Full"
    },
    {
      "x": -12,
      "y": 3,
      "z": -7,
      "name": "Wood_Ash_Trunk",
      "support": 15
    },
    {
      "x": -12,
      "y": 4,
      "z": -7,
      "name": "Wood_Ash_Trunk",
      "support": 15
    },
    {
      "x": -12,
      "y": 5,
      "z": -7,
      "name": "Wood_Ash_Trunk",
      "support": 15
    },
    {
      "x": -12,
      "y": 6,
      "z": -7,
      "name": "Wood_Ash_Trunk",
      "support": 15
    },
    {
      "x": -12,
      "y": 7,
      "z": -7,
      "name": "Wood_Ash_Trunk_Full"
    },
    {
      "x": -12,
      "y": 0,
      "z": -6,
      "name": "Soil_Dirt"
    },
    {
      "x": -12,
      "y": 1,
      "z": -6,
      "name": "Soil_Dirt"
    },
    {
      "x": -12,
      "y": 2,
      "z": -6,
      "name": "Wood_Ash_Trunk_Full"
    },
    {
      "x": -12,
      "y": 3,
      "z": -6,
      "name": "Wood_Ash_Trunk",
      "support": 15
    },
    {
      "x": -12,
      "y": 4,
      "z": -6,
      "name": "Wood_Ash_Trunk",
      "support": 15
    },
    {
      "x": -12,
      "y": 5,
      "z": -6,
      "name": "Wood_Ash_Trunk",
      "support": 15
    },
    {
      "x": -12,
      "y": 6,
      "z": -6,
      "name": "Wood_Ash_Trunk",
      "support": 15
    },
    {
      "x": -12,
      "y": 7,
      "z": -6,
      "name": "Wood_Ash_Trunk",
      "support": 15
    },
    {
      "x": -12,
      "y": 8,
      "z": -6,
      "name": "Wood_Ash_Trunk",
      "support": 15
    },
    {
      "x": -12,
      "y": 9,
      "z": -6,
      "name": "Wood_Ash_Trunk_Full",
      "rotation": 5
    },
    {
      "x": -12,
      "y": 0,
      "z": -5,
      "name": "Soil_Dirt"
    },
    {
      "x": -12,
      "y": 1,
      "z": -5,
      "name": "Soil_Dirt"
    },
    {
      "x": -12,
      "y": 2,
      "z": -5,
      "name": "Wood_Ash_Trunk_Full"
    },
    {
      "x": -12,
      "y": 3,
      "z": -5,
      "name": "Wood_Ash_Trunk",
      "support": 15
    },
    {
      "x": -12,
      "y": 4,
      "z": -5,
      "name": "Wood_Ash_Trunk",
      "support": 15
    },
    {
      "x": -12,
      "y": 5,
      "z": -5,
      "name": "Wood_Ash_Trunk",
      "support": 15
    },
    {
      "x": -12,
      "y": 6,
      "z": -5,
      "name": "Wood_Ash_Trunk",
      "support": 15
    },
    {
      "x": -12,
      "y": 7,
      "z": -5,
      "name": "Wood_Ash_Trunk",
      "support": 15
    },
    {
      "x": -12,
      "y": 8,
      "z": -5,
      "name": "Wood_Ash_Trunk",
      "support": 15
    },
    {
      "x": -12,
      "y": 9,
      "z": -5,
      "name": "Wood_Ash_Trunk_Full"
    },
    {
      "x": -12,
      "y": 0,
      "z": -4,
      "name": "Soil_Dirt"
    },
    {
      "x": -12,
      "y": 1,
      "z": -4,
      "name": "Soil_Dirt"
    },
    {
      "x": -12,
      "y": 2,
      "z": -4,
      "name": "Soil_Grass"
    },
    {
      "x": -12,
      "y": 3,
      "z": -4,
      "name": "Wood_Ash_Roots"
    },
    {
      "x": -12,
      "y": 4,
      "z": -4,
      "name": "Wood_Ash_Trunk_Full"
    },
    {
      "x": -12,
      "y": 5,
      "z": -4,
      "name": "Wood_Ash_Trunk",
      "support": 15
    },
    {
      "x": -12,
      "y": 6,
      "z": -4,
      "name": "Wood_Ash_Trunk",
      "support": 15
    },
    {
      "x": -12,
      "y": 7,
      "z": -4,
      "name": "Wood_Ash_Trunk",
      "support": 15
    },
    {
      "x": -12,
      "y": 8,
      "z": -4,
      "name": "Wood_Ash_Trunk",
      "support": 15
    },
    {
      "x": -12,
      "y": 9,
      "z": -4,
      "name": "Wood_Ash_Trunk",
      "support": 15
    },
    {
      "x": -12,
      "y": 10,
      "z": -4,
      "name": "Wood_Ash_Trunk_Full"
    },
    {
      "x": -12,
      "y": 0,
      "z": -3,
      "name": "Soil_Dirt"
    },
    {
      "x": -12,
      "y": 1,
      "z": -3,
      "name": "Soil_Dirt"
    },
    {
      "x": -12,
      "y": 2,
      "z": -3,
      "name": "Soil_Dirt"
    },
    {
      "x": -12,
      "y": 3,
      "z": -3,
      "name": "Soil_Grass"
    },
    {
      "x": -12,
      "y": 6,
      "z": -3,
      "name": "Wood_Ash_Trunk_Full"
    },
    {
      "x": -12,
      "y": 7,
      "z": -3,
      "name": "Wood_Ash_Trunk",
      "support": 15
    },
    {
      "x": -12,
      "y": 8,
      "z": -3,
      "name": "Wood_Ash_Trunk",
      "support": 15
    },
    {
      "x": -12,
      "y": 9,
      "z": -3,
      "name": "Wood_Ash_Trunk",
      "support": 15
    },
    {
      "x": -12,
      "y": 10,
      "z": -3,
      "name": "Wood_Ash_Trunk_Full"
    },
    {
      "x": -12,
      "y": 0,
      "z": -2,
      "name": "Soil_Dirt"
    },
    {
      "x": -12,
      "y": 1,
      "z": -2,
      "name": "Soil_Dirt"
    },
    {
      "x": -12,
      "y": 2,
      "z": -2,
      "name": "Soil_Dirt"
    },
    {
      "x": -12,
      "y": 3,
      "z": -2,
      "name": "Soil_Grass"
    },
    {
      "x": -12,
      "y": 8,
      "z": -2,
      "name": "Wood_Ash_Trunk_Full"
    },
    {
      "x": -12,
      "y": 9,
      "z": -2,
      "name": "Wood_Ash_Trunk_Full"
    },
    {
      "x": -12,
      "y": 0,
      "z": -1,
      "name": "Soil_Dirt"
    },
    {
      "x": -12,
      "y": 1,
      "z": -1,
      "name": "Soil_Dirt"
    },
    {
      "x": -12,
      "y": 2,
      "z": -1,
      "name": "Soil_Dirt"
    },
    {
      "x": -12,
      "y": 3,
      "z": -1,
      "name": "Soil_Grass"
    },
    {
      "x": -12,
      "y": 0,
      "z": 0,
      "name": "Soil_Dirt"
    },
    {
      "x": -12,
      "y": 1,
      "z": 0,
      "name": "Soil_Dirt"
    },
    {
      "x": -12,
      "y": 2,
      "z": 0,
      "name": "Soil_Dirt"
    },
    {
      "x": -12,
      "y": 3,
      "z": 0,
      "name": "Soil_Grass"
    },
    {
      "x": -12,
      "y": 0,
      "z": 1,
      "name": "Soil_Dirt"
    },
    {
      "x": -12,
      "y": 1,
      "z": 1,
      "name": "Soil_Dirt"
    },
    {
      "x": -12,
      "y": 2,
      "z": 1,
      "name": "Soil_Dirt"
    },
    {
      "x": -12,
      "y": 3,
      "z": 1,
      "name": "Soil_Grass"
    },
    {
      "x": -12,
      "y": 13,
      "z": 1,
      "name": "Wood_Ash_Roots"
    },
    {
      "x": -12,
      "y": 14,
      "z": 1,
      "name": "Wood_Ash_Trunk",
      "support": 15
    },
    {
      "x": -12,
      "y": 15,
      "z": 1,
      "name": "Wood_Ash_Trunk",
      "support": 15
    },
    {
      "x": -12,
      "y": 16,
      "z": 1,
      "name": "Wood_Ash_Trunk_Full"
    },
    {
      "x": -12,
      "y": 0,
      "z": 2,
      "name": "Soil_Dirt"
    },
    {
      "x": -12,
      "y": 1,
      "z": 2,
      "name": "Soil_Dirt"
    },
    {
      "x": -12,
      "y": 2,
      "z": 2,
      "name": "Soil_Dirt"
    },
    {
      "x": -12,
      "y": 3,
      "z": 2,
      "name": "Soil_Grass"
    },
    {
      "x": -12,
      "y": 12,
      "z": 2,
      "name": "Wood_Ash_Roots"
    },
    {
      "x": -12,
      "y": 13,
      "z": 2,
      "name": "Wood_Ash_Trunk",
      "support": 15
    },
    {
      "x": -12,
      "y": 14,
      "z": 2,
      "name": "Wood_Ash_Trunk",
      "support": 15
    },
    {
      "x": -12,
      "y": 15,
      "z": 2,
      "name": "Wood_Ash_Trunk",
      "support": 15
    },
    {
      "x": -12,
      "y": 16,
      "z": 2,
      "name": "Wood_Ash_Trunk",
      "support": 15
    },
    {
      "x": -12,
      "y": 17,
      "z": 2,
      "name": "Wood_Ash_Trunk_Full"
    },
    {
      "x": -12,
      "y": 0,
      "z": 3,
      "name": "Soil_Dirt"
    },
    {
      "x": -12,
      "y": 1,
      "z": 3,
      "name": "Soil_Dirt"
    },
    {
      "x": -12,
      "y": 2,
      "z": 3,
      "name": "Soil_Dirt"
    },
    {
      "x": -12,
      "y": 3,
      "z": 3,
      "name": "Soil_Grass"
    },
    {
      "x": -12,
      "y": 12,
      "z": 3,
      "name": "Wood_Ash_Roots"
    },
    {
      "x": -12,
      "y": 13,
      "z": 3,
      "name": "Wood_Ash_Trunk",
      "support": 15
    },
    {
      "x": -12,
      "y": 14,
      "z": 3,
      "name": "Wood_Ash_Trunk",
      "support": 15
    },
    {
      "x": -12,
      "y": 15,
      "z": 3,
      "name": "Wood_Ash_Trunk",
      "support": 15
    },
    {
      "x": -12,
      "y": 16,
      "z": 3,
      "name": "Wood_Ash_Trunk",
      "support": 15
    },
    {
      "x": -12,
      "y": 17,
      "z": 3,
      "name": "Wood_Ash_Trunk_Full"
    },
    {
      "x": -12,
      "y": 0,
      "z": 4,
      "name": "Soil_Dirt"
    },
    {
      "x": -12,
      "y": 1,
      "z": 4,
      "name": "Soil_Dirt"
    },
    {
      "x": -12,
      "y": 2,
      "z": 4,
      "name": "Soil_Dirt"
    },
    {
      "x": -12,
      "y": 3,
      "z": 4,
      "name": "Soil_Grass"
    },
    {
      "x": -12,
      "y": 14,
      "z": 4,
      "name": "Wood_Ash_Trunk_Full"
    },
    {
      "x": -12,
      "y": 15,
      "z": 4,
      "name": "Wood_Ash_Trunk",
      "support": 15
    },
    {
      "x": -12,
      "y": 16,
      "z": 4,
      "name": "Wood_Ash_Trunk",
      "support": 15
    },
    {
      "x": -12,
      "y": 17,
      "z": 4,
      "name": "Wood_Ash_Trunk_Full"
    },
    {
      "x": -12,
      "y": 0,
      "z": 5,
      "name": "Soil_Dirt"
    },
    {
      "x": -12,
      "y": 1,
      "z": 5,
      "name": "Soil_Dirt"
    },
    {
      "x": -12,
      "y": 2,
      "z": 5,
      "name": "Soil_Dirt"
    },
    {
      "x": -12,
      "y": 3,
      "z": 5,
      "name": "Soil_Grass"
    },
    {
      "x": -12,
      "y": 5,
      "z": 5,
      "name": "Rock_Stone"
    },
    {
      "x": -12,
      "y": 6,
      "z": 5,
      "name": "Rock_Stone"
    },
    {
      "x": -12,
      "y": 7,
      "z": 5,
      "name": "Rock_Stone"
    },
    {
      "x": -12,
      "y": 8,
      "z": 5,
      "name": "Rock_Stone"
    },
    {
      "x": -12,
      "y": 9,
      "z": 5,
      "name": "Rock_Stone"
    },
    {
      "x": -12,
      "y": 10,
      "z": 5,
      "name": "Rock_Stone"
    },
    {
      "x": -12,
      "y": 11,
      "z": 5,
      "name": "Rock_Stone"
    },
    {
      "x": -12,
      "y": 12,
      "z": 5,
      "name": "Rock_Stone_Mossy"
    },
    {
      "x": -12,
      "y": 13,
      "z": 5,
      "name": "Rock_Stone"
    },
    {
      "x": -12,
      "y": 14,
      "z": 5,
      "name": "Rock_Stone"
    },
    {
      "x": -12,
      "y": 15,
      "z": 5,
      "name": "Wood_Ash_Trunk",
      "support": 15
    },
    {
      "x": -12,
      "y": 16,
      "z": 5,
      "name": "Wood_Ash_Trunk_Full"
    },
    {
      "x": -12,
      "y": 17,
      "z": 5,
      "name": "Furniture_Kweebec_Platform",
      "rotation": 1
    },
    {
      "x": -12,
      "y": 0,
      "z": 6,
      "name": "Soil_Dirt"
    },
    {
      "x": -12,
      "y": 1,
      "z": 6,
      "name": "Soil_Dirt"
    },
    {
      "x": -12,
      "y": 2,
      "z": 6,
      "name": "Soil_Dirt"
    },
    {
      "x": -12,
      "y": 3,
      "z": 6,
      "name": "Rock_Stone"
    },
    {
      "x": -12,
      "y": 4,
      "z": 6,
      "name": "Rock_Stone"
    },
    {
      "x": -12,
      "y": 5,
      "z": 6,
      "name": "Rock_Stone"
    },
    {
      "x": -12,
      "y": 6,
      "z": 6,
      "name": "Rock_Stone"
    },
    {
      "x": -12,
      "y": 7,
      "z": 6,
      "name": "Rock_Stone"
    },
    {
      "x": -12,
      "y": 8,
      "z": 6,
      "name": "Rock_Stone"
    },
    {
      "x": -12,
      "y": 9,
      "z": 6,
      "name": "Rock_Stone"
    },
    {
      "x": -12,
      "y": 10,
      "z": 6,
      "name": "Rock_Stone_Mossy"
    },
    {
      "x": -12,
      "y": 11,
      "z": 6,
      "name": "Rock_Stone"
    },
    {
      "x": -12,
      "y": 12,
      "z": 6,
      "name": "Rock_Stone"
    },
    {
      "x": -12,
      "y": 13,
      "z": 6,
      "name": "Rock_Stone"
    },
    {
      "x": -12,
      "y": 14,
      "z": 6,
      "name": "Rock_Stone"
    },
    {
      "x": -12,
      "y": 15,
      "z": 6,
      "name": "Rock_Stone"
    },
    {
      "x": -12,
      "y": 0,
      "z": 7,
      "name": "Soil_Dirt"
    },
    {
      "x": -12,
      "y": 1,
      "z": 7,
      "name": "Soil_Dirt"
    },
    {
      "x": -12,
      "y": 2,
      "z": 7,
      "name": "Soil_Dirt"
    },
    {
      "x": -12,
      "y": 3,
      "z": 7,
      "name": "Rock_Stone"
    },
    {
      "x": -12,
      "y": 4,
      "z": 7,
      "name": "Rock_Stone"
    },
    {
      "x": -12,
      "y": 5,
      "z": 7,
      "name": "Rock_Stone"
    },
    {
      "x": -12,
      "y": 6,
      "z": 7,
      "name": "Rock_Stone"
    },
    {
      "x": -12,
      "y": 7,
      "z": 7,
      "name": "Rock_Stone_Mossy"
    },
    {
      "x": -12,
      "y": 8,
      "z": 7,
      "name": "Rock_Stone"
    },
    {
      "x": -12,
      "y": 9,
      "z": 7,
      "name": "Rock_Stone"
    },
    {
      "x": -12,
      "y": 10,
      "z": 7,
      "name": "Rock_Stone"
    },
    {
      "x": -12,
      "y": 11,
      "z": 7,
      "name": "Rock_Stone"
    },
    {
      "x": -12,
      "y": 12,
      "z": 7,
      "name": "Rock_Stone"
    },
    {
      "x": -12,
      "y": 13,
      "z": 7,
      "name": "Rock_Stone"
    },
    {
      "x": -12,
      "y": 14,
      "z": 7,
      "name": "Rock_Stone"
    },
    {
      "x": -12,
      "y": 15,
      "z": 7,
      "name": "Rock_Stone"
    },
    {
      "x": -12,
      "y": 16,
      "z": 7,
      "name": "Rock_Stone"
    },
    {
      "x": -12,
      "y": 17,
      "z": 7,
      "name": "Rock_Stone_Mossy"
    },
    {
      "x": -12,
      "y": 0,
      "z": 8,
      "name": "Soil_Dirt"
    },
    {
      "x": -12,
      "y": 1,
      "z": 8,
      "name": "Soil_Dirt"
    },
    {
      "x": -12,
      "y": 2,
      "z": 8,
      "name": "Wood_Ash_Trunk_Full"
    },
    {
      "x": -12,
      "y": 3,
      "z": 8,
      "name": "Rock_Stone"
    },
    {
      "x": -12,
      "y": 4,
      "z": 8,
      "name": "Rock_Stone"
    },
    {
      "x": -12,
      "y": 5,
      "z": 8,
      "name": "Rock_Stone"
    },
    {
      "x": -12,
      "y": 6,
      "z": 8,
      "name": "Rock_Stone"
    },
    {
      "x": -12,
      "y": 7,
      "z": 8,
      "name": "Rock_Stone"
    },
    {
      "x": -12,
      "y": 8,
      "z": 8,
      "name": "Rock_Stone"
    },
    {
      "x": -12,
      "y": 9,
      "z": 8,
      "name": "Rock_Stone"
    },
    {
      "x": -12,
      "y": 10,
      "z": 8,
      "name": "Rock_Stone"
    },
    {
      "x": -12,
      "y": 11,
      "z": 8,
      "name": "Rock_Stone"
    },
    {
      "x": -12,
      "y": 12,
      "z": 8,
      "name": "Rock_Stone"
    },
    {
      "x": -12,
      "y": 13,
      "z": 8,
      "name": "Rock_Stone"
    },
    {
      "x": -12,
      "y": 14,
      "z": 8,
      "name": "Rock_Stone"
    },
    {
      "x": -12,
      "y": 15,
      "z": 8,
      "name": "Rock_Stone"
    },
    {
      "x": -12,
      "y": 16,
      "z": 8,
      "name": "Rock_Stone"
    },
    {
      "x": -12,
      "y": 17,
      "z": 8,
      "name": "Rock_Stone_Mossy"
    },
    {
      "x": -12,
      "y": 18,
      "z": 8,
      "name": "Rock_Stone_Mossy"
    },
    {
      "x": -12,
      "y": 0,
      "z": 9,
      "name": "Soil_Dirt"
    },
    {
      "x": -12,
      "y": 1,
      "z": 9,
      "name": "Wood_Ash_Trunk_Full"
    },
    {
      "x": -12,
      "y": 2,
      "z": 9,
      "name": "Wood_Ash_Trunk",
      "support": 15
    },
    {
      "x": -12,
      "y": 3,
      "z": 9,
      "name": "Rock_Stone"
    },
    {
      "x": -12,
      "y": 4,
      "z": 9,
      "name": "Rock_Stone"
    },
    {
      "x": -12,
      "y": 5,
      "z": 9,
      "name": "Rock_Stone"
    },
    {
      "x": -12,
      "y": 6,
      "z": 9,
      "name": "Rock_Stone_Mossy"
    },
    {
      "x": -12,
      "y": 7,
      "z": 9,
      "name": "Rock_Stone"
    },
    {
      "x": -12,
      "y": 8,
      "z": 9,
      "name": "Rock_Stone"
    },
    {
      "x": -12,
      "y": 9,
      "z": 9,
      "name": "Rock_Stone"
    },
    {
      "x": -12,
      "y": 10,
      "z": 9,
      "name": "Rock_Stone"
    },
    {
      "x": -12,
      "y": 11,
      "z": 9,
      "name": "Rock_Stone"
    },
    {
      "x": -12,
      "y": 12,
      "z": 9,
      "name": "Rock_Stone"
    },
    {
      "x": -12,
      "y": 13,
      "z": 9,
      "name": "Rock_Stone"
    },
    {
      "x": -12,
      "y": 14,
      "z": 9,
      "name": "Rock_Stone"
    },
    {
      "x": -12,
      "y": 15,
      "z": 9,
      "name": "Rock_Stone"
    },
    {
      "x": -12,
      "y": 16,
      "z": 9,
      "name": "Rock_Stone"
    },
    {
      "x": -12,
      "y": 17,
      "z": 9,
      "name": "Rock_Stone"
    },
    {
      "x": -12,
      "y": 18,
      "z": 9,
      "name": "Rock_Stone_Mossy"
    },
    {
      "x": -12,
      "y": 0,
      "z": 10,
      "name": "Soil_Dirt"
    },
    {
      "x": -12,
      "y": 1,
      "z": 10,
      "name": "Wood_Ash_Trunk_Full"
    },
    {
      "x": -12,
      "y": 2,
      "z": 10,
      "name": "Wood_Ash_Trunk",
      "support": 15
    },
    {
      "x": -12,
      "y": 3,
      "z": 10,
      "name": "Rock_Stone"
    },
    {
      "x": -12,
      "y": 4,
      "z": 10,
      "name": "Rock_Stone"
    },
    {
      "x": -12,
      "y": 5,
      "z": 10,
      "name": "Rock_Stone"
    },
    {
      "x": -12,
      "y": 6,
      "z": 10,
      "name": "Rock_Stone"
    },
    {
      "x": -12,
      "y": 7,
      "z": 10,
      "name": "Rock_Stone"
    },
    {
      "x": -12,
      "y": 8,
      "z": 10,
      "name": "Rock_Stone"
    },
    {
      "x": -12,
      "y": 9,
      "z": 10,
      "name": "Rock_Stone"
    },
    {
      "x": -12,
      "y": 10,
      "z": 10,
      "name": "Rock_Stone"
    },
    {
      "x": -12,
      "y": 11,
      "z": 10,
      "name": "Rock_Stone"
    },
    {
      "x": -12,
      "y": 12,
      "z": 10,
      "name": "Rock_Stone"
    },
    {
      "x": -12,
      "y": 13,
      "z": 10,
      "name": "Rock_Stone"
    },
    {
      "x": -12,
      "y": 14,
      "z": 10,
      "name": "Rock_Stone"
    },
    {
      "x": -12,
      "y": 15,
      "z": 10,
      "name": "Rock_Stone"
    },
    {
      "x": -12,
      "y": 16,
      "z": 10,
      "name": "Rock_Stone"
    },
    {
      "x": -12,
      "y": 17,
      "z": 10,
      "name": "Rock_Stone"
    },
    {
      "x": -12,
      "y": 18,
      "z": 10,
      "name": "Plant_Moss_Block_Green_Dark"
    },
    {
      "x": -12,
      "y": 0,
      "z": 11,
      "name": "Soil_Dirt"
    },
    {
      "x": -12,
      "y": 1,
      "z": 11,
      "name": "Soil_Dirt"
    },
    {
      "x": -12,
      "y": 2,
      "z": 11,
      "name": "Wood_Ash_Trunk_Full"
    },
    {
      "x": -12,
      "y": 3,
      "z": 11,
      "name": "Wood_Ash_Trunk",
      "support": 15
    },
    {
      "x": -12,
      "y": 4,
      "z": 11,
      "name": "Wood_Ash_Trunk",
      "support": 15
    },
    {
      "x": -12,
      "y": 5,
      "z": 11,
      "name": "Rock_Stone"
    },
    {
      "x": -12,
      "y": 6,
      "z": 11,
      "name": "Rock_Stone"
    },
    {
      "x": -12,
      "y": 7,
      "z": 11,
      "name": "Rock_Stone"
    },
    {
      "x": -12,
      "y": 8,
      "z": 11,
      "name": "Rock_Stone"
    },
    {
      "x": -12,
      "y": 9,
      "z": 11,
      "name": "Rock_Stone"
    },
    {
      "x": -12,
      "y": 10,
      "z": 11,
      "name": "Rock_Stone"
    },
    {
      "x": -12,
      "y": 11,
      "z": 11,
      "name": "Rock_Stone"
    },
    {
      "x": -12,
      "y": 12,
      "z": 11,
      "name": "Rock_Stone"
    },
    {
      "x": -12,
      "y": 13,
      "z": 11,
      "name": "Rock_Stone"
    },
    {
      "x": -12,
      "y": 14,
      "z": 11,
      "name": "Rock_Stone"
    },
    {
      "x": -12,
      "y": 15,
      "z": 11,
      "name": "Rock_Stone"
    },
    {
      "x": -12,
      "y": 16,
      "z": 11,
      "name": "Rock_Stone_Mossy"
    },
    {
      "x": -12,
      "y": 17,
      "z": 11,
      "name": "Rock_Stone"
    },
    {
      "x": -12,
      "y": 18,
      "z": 11,
      "name": "Plant_Moss_Block_Green_Dark"
    },
    {
      "x": -12,
      "y": 0,
      "z": 12,
      "name": "Wood_Ash_Trunk",
      "support": 15
    },
    {
      "x": -12,
      "y": 1,
      "z": 12,
      "name": "Wood_Ash_Trunk",
      "support": 15
    },
    {
      "x": -12,
      "y": 2,
      "z": 12,
      "name": "Wood_Ash_Trunk",
      "support": 15
    },
    {
      "x": -12,
      "y": 3,
      "z": 12,
      "name": "Wood_Ash_Trunk",
      "support": 15
    },
    {
      "x": -12,
      "y": 4,
      "z": 12,
      "name": "Wood_Ash_Trunk",
      "support": 15
    },
    {
      "x": -12,
      "y": 5,
      "z": 12,
      "name": "Wood_Ash_Trunk_Full"
    },
    {
      "x": -12,
      "y": 11,
      "z": 12,
      "name": "Rock_Stone"
    },
    {
      "x": -12,
      "y": 12,
      "z": 12,
      "name": "Rock_Stone_Mossy"
    },
    {
      "x": -12,
      "y": 13,
      "z": 12,
      "name": "Rock_Stone_Mossy"
    },
    {
      "x": -12,
      "y": 14,
      "z": 12,
      "name": "Rock_Stone"
    },
    {
      "x": -12,
      "y": 15,
      "z": 12,
      "name": "Rock_Stone"
    },
    {
      "x": -12,
      "y": 16,
      "z": 12,
      "name": "Rock_Stone"
    },
    {
      "x": -12,
      "y": 17,
      "z": 12,
      "name": "Rock_Stone"
    },
    {
      "x": -12,
      "y": 18,
      "z": 12,
      "name": "Rock_Stone"
    },
    {
      "x": -12,
      "y": 0,
      "z": 13,
      "name": "Wood_Ash_Trunk",
      "support": 15
    },
    {
      "x": -12,
      "y": 1,
      "z": 13,
      "name": "Wood_Ash_Trunk",
      "support": 15
    },
    {
      "x": -12,
      "y": 2,
      "z": 13,
      "name": "Wood_Ash_Trunk",
      "support": 15
    },
    {
      "x": -12,
      "y": 3,
      "z": 13,
      "name": "Wood_Ash_Trunk",
      "support": 15
    },
    {
      "x": -12,
      "y": 4,
      "z": 13,
      "name": "Wood_Ash_Trunk",
      "support": 15
    },
    {
      "x": -12,
      "y": 5,
      "z": 13,
      "name": "Wood_Ash_Trunk",
      "support": 15
    },
    {
      "x": -12,
      "y": 6,
      "z": 13,
      "name": "Wood_Ash_Trunk_Full"
    },
    {
      "x": -12,
      "y": 12,
      "z": 13,
      "name": "Rock_Stone_Mossy"
    },
    {
      "x": -12,
      "y": 13,
      "z": 13,
      "name": "Rock_Stone_Mossy"
    },
    {
      "x": -12,
      "y": 14,
      "z": 13,
      "name": "Rock_Stone_Mossy"
    },
    {
      "x": -12,
      "y": 15,
      "z": 13,
      "name": "Rock_Stone"
    },
    {
      "x": -12,
      "y": 16,
      "z": 13,
      "name": "Rock_Stone"
    },
    {
      "x": -12,
      "y": 17,
      "z": 13,
      "name": "Rock_Stone"
    },
    {
      "x": -12,
      "y": 18,
      "z": 13,
      "name": "Rock_Stone"
    },
    {
      "x": -12,
      "y": 0,
      "z": 14,
      "name": "Wood_Ash_Trunk",
      "support": 15
    },
    {
      "x": -12,
      "y": 1,
      "z": 14,
      "name": "Wood_Ash_Trunk",
      "support": 15
    },
    {
      "x": -12,
      "y": 2,
      "z": 14,
      "name": "Wood_Ash_Trunk",
      "support": 15
    },
    {
      "x": -12,
      "y": 3,
      "z": 14,
      "name": "Wood_Ash_Trunk",
      "support": 15
    },
    {
      "x": -12,
      "y": 4,
      "z": 14,
      "name": "Wood_Ash_Trunk_Full"
    },
    {
      "x": -12,
      "y": 0,
      "z": 15,
      "name": "Wood_Ash_Trunk_Full"
    },
    {
      "x": -12,
      "y": 1,
      "z": 15,
      "name": "Soil_Dirt"
    },
    {
      "x": -12,
      "y": 2,
      "z": 15,
      "name": "Soil_Dirt"
    },
    {
      "x": -12,
      "y": 3,
      "z": 15,
      "name": "Soil_Grass"
    },
    {
      "x": -12,
      "y": 0,
      "z": 16,
      "name": "Soil_Dirt"
    },
    {
      "x": -12,
      "y": 1,
      "z": 16,
      "name": "Soil_Dirt"
    },
    {
      "x": -12,
      "y": 2,
      "z": 16,
      "name": "Soil_Dirt"
    },
    {
      "x": -12,
      "y": 3,
      "z": 16,
      "name": "Soil_Grass"
    },
    {
      "x": -11,
      "y": 0,
      "z": -15,
      "name": "Soil_Dirt"
    },
    {
      "x": -11,
      "y": 1,
      "z": -15,
      "name": "Soil_Dirt"
    },
    {
      "x": -11,
      "y": 2,
      "z": -15,
      "name": "Soil_Dirt"
    },
    {
      "x": -11,
      "y": 3,
      "z": -15,
      "name": "Soil_Grass"
    },
    {
      "x": -11,
      "y": 0,
      "z": -14,
      "name": "Soil_Dirt"
    },
    {
      "x": -11,
      "y": 1,
      "z": -14,
      "name": "Soil_Dirt"
    },
    {
      "x": -11,
      "y": 2,
      "z": -14,
      "name": "Soil_Dirt"
    },
    {
      "x": -11,
      "y": 3,
      "z": -14,
      "name": "Soil_Grass"
    },
    {
      "x": -11,
      "y": 0,
      "z": -13,
      "name": "Soil_Dirt"
    },
    {
      "x": -11,
      "y": 1,
      "z": -13,
      "name": "Soil_Dirt"
    },
    {
      "x": -11,
      "y": 2,
      "z": -13,
      "name": "Soil_Dirt"
    },
    {
      "x": -11,
      "y": 3,
      "z": -13,
      "name": "Soil_Grass"
    },
    {
      "x": -11,
      "y": 0,
      "z": -12,
      "name": "Soil_Dirt"
    },
    {
      "x": -11,
      "y": 1,
      "z": -12,
      "name": "Soil_Dirt"
    },
    {
      "x": -11,
      "y": 2,
      "z": -12,
      "name": "Soil_Dirt"
    },
    {
      "x": -11,
      "y": 3,
      "z": -12,
      "name": "Soil_Grass"
    },
    {
      "x": -11,
      "y": 0,
      "z": -11,
      "name": "Wood_Ash_Trunk_Full"
    },
    {
      "x": -11,
      "y": 1,
      "z": -11,
      "name": "Soil_Dirt"
    },
    {
      "x": -11,
      "y": 2,
      "z": -11,
      "name": "Wood_Ash_Trunk_Full"
    },
    {
      "x": -11,
      "y": 3,
      "z": -11,
      "name": "Wood_Ash_Trunk",
      "support": 15
    },
    {
      "x": -11,
      "y": 4,
      "z": -11,
      "name": "Wood_Ash_Trunk_Full"
    },
    {
      "x": -11,
      "y": 0,
      "z": -10,
      "name": "Soil_Dirt"
    },
    {
      "x": -11,
      "y": 1,
      "z": -10,
      "name": "Wood_Ash_Trunk_Full"
    },
    {
      "x": -11,
      "y": 2,
      "z": -10,
      "name": "Wood_Ash_Trunk",
      "support": 15
    },
    {
      "x": -11,
      "y": 3,
      "z": -10,
      "name": "Wood_Ash_Trunk",
      "support": 15
    },
    {
      "x": -11,
      "y": 4,
      "z": -10,
      "name": "Wood_Ash_Trunk_Full"
    },
    {
      "x": -11,
      "y": 0,
      "z": -9,
      "name": "Soil_Dirt"
    },
    {
      "x": -11,
      "y": 1,
      "z": -9,
      "name": "Wood_Ash_Trunk_Full"
    },
    {
      "x": -11,
      "y": 2,
      "z": -9,
      "name": "Wood_Ash_Trunk",
      "support": 15
    },
    {
      "x": -11,
      "y": 3,
      "z": -9,
      "name": "Wood_Ash_Trunk",
      "support": 15
    },
    {
      "x": -11,
      "y": 4,
      "z": -9,
      "name": "Wood_Ash_Trunk_Full"
    },
    {
      "x": -11,
      "y": 0,
      "z": -8,
      "name": "Soil_Dirt"
    },
    {
      "x": -11,
      "y": 1,
      "z": -8,
      "name": "Wood_Ash_Trunk_Full"
    },
    {
      "x": -11,
      "y": 2,
      "z": -8,
      "name": "Wood_Ash_Trunk",
      "support": 15
    },
    {
      "x": -11,
      "y": 3,
      "z": -8,
      "name": "Wood_Ash_Trunk",
      "support": 15
    },
    {
      "x": -11,
      "y": 4,
      "z": -8,
      "name": "Wood_Ash_Trunk",
      "support": 15
    },
    {
      "x": -11,
      "y": 5,
      "z": -8,
      "name": "Wood_Ash_Trunk_Full"
    },
    {
      "x": -11,
      "y": 0,
      "z": -7,
      "name": "Soil_Dirt"
    },
    {
      "x": -11,
      "y": 1,
      "z": -7,
      "name": "Soil_Dirt"
    },
    {
      "x": -11,
      "y": 2,
      "z": -7,
      "name": "Wood_Ash_Trunk_Full"
    },
    {
      "x": -11,
      "y": 3,
      "z": -7,
      "name": "Wood_Ash_Trunk",
      "support": 15
    },
    {
      "x": -11,
      "y": 4,
      "z": -7,
      "name": "Wood_Ash_Trunk",
      "support": 15
    },
    {
      "x": -11,
      "y": 5,
      "z": -7,
      "name": "Wood_Ash_Trunk",
      "support": 15
    },
    {
      "x": -11,
      "y": 6,
      "z": -7,
      "name": "Wood_Ash_Trunk_Full"
    },
    {
      "x": -11,
      "y": 0,
      "z": -6,
      "name": "Soil_Dirt"
    },
    {
      "x": -11,
      "y": 1,
      "z": -6,
      "name": "Soil_Dirt"
    },
    {
      "x": -11,
      "y": 2,
      "z": -6,
      "name": "Wood_Ash_Trunk_Full"
    },
    {
      "x": -11,
      "y": 3,
      "z": -6,
      "name": "Wood_Ash_Trunk",
      "support": 15
    },
    {
      "x": -11,
      "y": 4,
      "z": -6,
      "name": "Wood_Ash_Trunk",
      "support": 15
    },
    {
      "x": -11,
      "y": 5,
      "z": -6,
      "name": "Wood_Ash_Trunk",
      "support": 15
    },
    {
      "x": -11,
      "y": 6,
      "z": -6,
      "name": "Wood_Ash_Trunk",
      "support": 15
    },
    {
      "x": -11,
      "y": 7,
      "z": -6,
      "name": "Wood_Ash_Trunk",
      "support": 15
    },
    {
      "x": -11,
      "y": 8,
      "z": -6,
      "name": "Wood_Ash_Trunk",
      "support": 15
    },
    {
      "x": -11,
      "y": 9,
      "z": -6,
      "name": "Wood_Ash_Trunk_Full"
    },
    {
      "x": -11,
      "y": 0,
      "z": -5,
      "name": "Soil_Dirt"
    },
    {
      "x": -11,
      "y": 1,
      "z": -5,
      "name": "Soil_Dirt"
    },
    {
      "x": -11,
      "y": 2,
      "z": -5,
      "name": "Soil_Dirt"
    },
    {
      "x": -11,
      "y": 3,
      "z": -5,
      "name": "Wood_Ash_Trunk_Full"
    },
    {
      "x": -11,
      "y": 4,
      "z": -5,
      "name": "Wood_Ash_Trunk",
      "support": 15
    },
    {
      "x": -11,
      "y": 5,
      "z": -5,
      "name": "Wood_Ash_Trunk",
      "support": 15
    },
    {
      "x": -11,
      "y": 6,
      "z": -5,
      "name": "Wood_Ash_Trunk",
      "support": 15
    },
    {
      "x": -11,
      "y": 7,
      "z": -5,
      "name": "Wood_Ash_Trunk",
      "support": 15
    },
    {
      "x": -11,
      "y": 8,
      "z": -5,
      "name": "Wood_Ash_Trunk",
      "support": 15
    },
    {
      "x": -11,
      "y": 9,
      "z": -5,
      "name": "Wood_Ash_Trunk",
      "support": 15
    },
    {
      "x": -11,
      "y": 10,
      "z": -5,
      "name": "Wood_Ash_Trunk_Full"
    },
    {
      "x": -11,
      "y": 0,
      "z": -4,
      "name": "Soil_Dirt"
    },
    {
      "x": -11,
      "y": 1,
      "z": -4,
      "name": "Soil_Dirt"
    },
    {
      "x": -11,
      "y": 2,
      "z": -4,
      "name": "Soil_Dirt"
    },
    {
      "x": -11,
      "y": 3,
      "z": -4,
      "name": "Soil_Grass"
    },
    {
      "x": -11,
      "y": 4,
      "z": -4,
      "name": "Wood_Ash_Trunk_Full"
    },
    {
      "x": -11,
      "y": 5,
      "z": -4,
      "name": "Wood_Ash_Trunk",
      "support": 15
    },
    {
      "x": -11,
      "y": 6,
      "z": -4,
      "name": "Wood_Ash_Trunk",
      "support": 15
    },
    {
      "x": -11,
      "y": 7,
      "z": -4,
      "name": "Wood_Ash_Trunk",
      "support": 15
    },
    {
      "x": -11,
      "y": 8,
      "z": -4,
      "name": "Wood_Ash_Trunk",
      "support": 15
    },
    {
      "x": -11,
      "y": 9,
      "z": -4,
      "name": "Wood_Ash_Trunk",
      "support": 15
    },
    {
      "x": -11,
      "y": 10,
      "z": -4,
      "name": "Wood_Ash_Trunk_Full"
    },
    {
      "x": -11,
      "y": 0,
      "z": -3,
      "name": "Soil_Dirt"
    },
    {
      "x": -11,
      "y": 1,
      "z": -3,
      "name": "Soil_Dirt"
    },
    {
      "x": -11,
      "y": 2,
      "z": -3,
      "name": "Soil_Dirt"
    },
    {
      "x": -11,
      "y": 3,
      "z": -3,
      "name": "Soil_Grass"
    },
    {
      "x": -11,
      "y": 5,
      "z": -3,
      "name": "Wood_Ash_Trunk_Full"
    },
    {
      "x": -11,
      "y": 6,
      "z": -3,
      "name": "Wood_Ash_Trunk",
      "support": 15
    },
    {
      "x": -11,
      "y": 7,
      "z": -3,
      "name": "Wood_Ash_Trunk",
      "support": 15
    },
    {
      "x": -11,
      "y": 8,
      "z": -3,
      "name": "Wood_Ash_Trunk",
      "support": 15
    },
    {
      "x": -11,
      "y": 9,
      "z": -3,
      "name": "Wood_Ash_Trunk",
      "support": 15
    },
    {
      "x": -11,
      "y": 10,
      "z": -3,
      "name": "Wood_Ash_Trunk_Full"
    },
    {
      "x": -11,
      "y": 0,
      "z": -2,
      "name": "Soil_Dirt"
    },
    {
      "x": -11,
      "y": 1,
      "z": -2,
      "name": "Soil_Dirt"
    },
    {
      "x": -11,
      "y": 2,
      "z": -2,
      "name": "Soil_Dirt"
    },
    {
      "x": -11,
      "y": 3,
      "z": -2,
      "name": "Soil_Grass"
    },
    {
      "x": -11,
      "y": 6,
      "z": -2,
      "name": "Wood_Ash_Trunk_Full"
    },
    {
      "x": -11,
      "y": 7,
      "z": -2,
      "name": "Wood_Ash_Trunk",
      "support": 15
    },
    {
      "x": -11,
      "y": 8,
      "z": -2,
      "name": "Wood_Ash_Trunk",
      "support": 15
    },
    {
      "x": -11,
      "y": 9,
      "z": -2,
      "name": "Wood_Ash_Trunk",
      "support": 15
    },
    {
      "x": -11,
      "y": 10,
      "z": -2,
      "name": "Wood_Ash_Trunk_Full"
    },
    {
      "x": -11,
      "y": 0,
      "z": -1,
      "name": "Soil_Dirt"
    },
    {
      "x": -11,
      "y": 1,
      "z": -1,
      "name": "Soil_Dirt"
    },
    {
      "x": -11,
      "y": 2,
      "z": -1,
      "name": "Soil_Dirt"
    },
    {
      "x": -11,
      "y": 3,
      "z": -1,
      "name": "Soil_Grass"
    },
    {
      "x": -11,
      "y": 0,
      "z": 0,
      "name": "Soil_Dirt"
    },
    {
      "x": -11,
      "y": 1,
      "z": 0,
      "name": "Soil_Dirt"
    },
    {
      "x": -11,
      "y": 2,
      "z": 0,
      "name": "Soil_Dirt"
    },
    {
      "x": -11,
      "y": 3,
      "z": 0,
      "name": "Soil_Grass"
    },
    {
      "x": -11,
      "y": 0,
      "z": 1,
      "name": "Soil_Dirt"
    },
    {
      "x": -11,
      "y": 1,
      "z": 1,
      "name": "Soil_Dirt"
    },
    {
      "x": -11,
      "y": 2,
      "z": 1,
      "name": "Soil_Dirt"
    },
    {
      "x": -11,
      "y": 3,
      "z": 1,
      "name": "Soil_Grass"
    },
    {
      "x": -11,
      "y": 15,
      "z": 1,
      "name": "Wood_Ash_Trunk_Full"
    },
    {
      "x": -11,
      "y": 16,
      "z": 1,
      "name": "Wood_Ash_Trunk_Full"
    },
    {
      "x": -11,
      "y": 0,
      "z": 2,
      "name": "Soil_Dirt"
    },
    {
      "x": -11,
      "y": 1,
      "z": 2,
      "name": "Soil_Dirt"
    },
    {
      "x": -11,
      "y": 2,
      "z": 2,
      "name": "Soil_Dirt"
    },
    {
      "x": -11,
      "y": 3,
      "z": 2,
      "name": "Soil_Grass"
    },
    {
      "x": -11,
      "y": 13,
      "z": 2,
      "name": "Wood_Ash_Trunk_Full"
    },
    {
      "x": -11,
      "y": 14,
      "z": 2,
      "name": "Wood_Ash_Trunk",
      "support": 15
    },
    {
      "x": -11,
      "y": 15,
      "z": 2,
      "name": "Wood_Ash_Trunk",
      "support": 15
    },
    {
      "x": -11,
      "y": 16,
      "z": 2,
      "name": "Wood_Ash_Trunk",
      "support": 15
    },
    {
      "x": -11,
      "y": 17,
      "z": 2,
      "name": "Wood_Ash_Trunk_Full"
    },
    {
      "x": -11,
      "y": 0,
      "z": 3,
      "name": "Soil_Dirt"
    },
    {
      "x": -11,
      "y": 1,
      "z": 3,
      "name": "Soil_Dirt"
    },
    {
      "x": -11,
      "y": 2,
      "z": 3,
      "name": "Soil_Dirt"
    },
    {
      "x": -11,
      "y": 3,
      "z": 3,
      "name": "Soil_Grass"
    },
    {
      "x": -11,
      "y": 12,
      "z": 3,
      "name": "Wood_Ash_Roots"
    },
    {
      "x": -11,
      "y": 13,
      "z": 3,
      "name": "Wood_Ash_Trunk",
      "support": 15
    },
    {
      "x": -11,
      "y": 14,
      "z": 3,
      "name": "Wood_Ash_Trunk",
      "support": 15
    },
    {
      "x": -11,
      "y": 15,
      "z": 3,
      "name": "Wood_Ash_Trunk",
      "support": 15
    },
    {
      "x": -11,
      "y": 16,
      "z": 3,
      "name": "Wood_Ash_Trunk",
      "support": 15
    },
    {
      "x": -11,
      "y": 17,
      "z": 3,
      "name": "Wood_Ash_Trunk_Full"
    },
    {
      "x": -11,
      "y": 0,
      "z": 4,
      "name": "Soil_Dirt"
    },
    {
      "x": -11,
      "y": 1,
      "z": 4,
      "name": "Soil_Dirt"
    },
    {
      "x": -11,
      "y": 2,
      "z": 4,
      "name": "Soil_Dirt"
    },
    {
      "x": -11,
      "y": 3,
      "z": 4,
      "name": "Soil_Grass"
    },
    {
      "x": -11,
      "y": 10,
      "z": 4,
      "name": "Rock_Stone"
    },
    {
      "x": -11,
      "y": 11,
      "z": 4,
      "name": "Rock_Stone"
    },
    {
      "x": -11,
      "y": 12,
      "z": 4,
      "name": "Rock_Stone"
    },
    {
      "x": -11,
      "y": 13,
      "z": 4,
      "name": "Wood_Ash_Trunk",
      "support": 15
    },
    {
      "x": -11,
      "y": 14,
      "z": 4,
      "name": "Wood_Ash_Trunk",
      "support": 15
    },
    {
      "x": -11,
      "y": 15,
      "z": 4,
      "name": "Wood_Ash_Trunk",
      "support": 15
    },
    {
      "x": -11,
      "y": 16,
      "z": 4,
      "name": "Wood_Ash_Trunk",
      "support": 15
    },
    {
      "x": -11,
      "y": 17,
      "z": 4,
      "name": "Wood_Ash_Trunk_Full"
    },
    {
      "x": -11,
      "y": 0,
      "z": 5,
      "name": "Soil_Dirt"
    },
    {
      "x": -11,
      "y": 1,
      "z": 5,
      "name": "Soil_Dirt"
    },
    {
      "x": -11,
      "y": 2,
      "z": 5,
      "name": "Soil_Dirt"
    },
    {
      "x": -11,
      "y": 3,
      "z": 5,
      "name": "Rock_Stone"
    },
    {
      "x": -11,
      "y": 4,
      "z": 5,
      "name": "Rock_Stone"
    },
    {
      "x": -11,
      "y": 5,
      "z": 5,
      "name": "Rock_Stone"
    },
    {
      "x": -11,
      "y": 6,
      "z": 5,
      "name": "Rock_Stone"
    },
    {
      "x": -11,
      "y": 7,
      "z": 5,
      "name": "Rock_Stone"
    },
    {
      "x": -11,
      "y": 8,
      "z": 5,
      "name": "Rock_Stone"
    },
    {
      "x": -11,
      "y": 9,
      "z": 5,
      "name": "Rock_Stone"
    },
    {
      "x": -11,
      "y": 10,
      "z": 5,
      "name": "Rock_Stone"
    },
    {
      "x": -11,
      "y": 11,
      "z": 5,
      "name": "Rock_Stone"
    },
    {
      "x": -11,
      "y": 12,
      "z": 5,
      "name": "Rock_Stone"
    },
    {
      "x": -11,
      "y": 13,
      "z": 5,
      "name": "Rock_Stone"
    },
    {
      "x": -11,
      "y": 14,
      "z": 5,
      "name": "Rock_Stone"
    },
    {
      "x": -11,
      "y": 15,
      "z": 5,
      "name": "Wood_Ash_Trunk",
      "support": 15
    },
    {
      "x": -11,
      "y": 16,
      "z": 5,
      "name": "Wood_Ash_Trunk",
      "support": 15
    },
    {
      "x": -11,
      "y": 17,
      "z": 5,
      "name": "Wood_Ash_Trunk_Full"
    },
    {
      "x": -11,
      "y": 0,
      "z": 6,
      "name": "Soil_Dirt"
    },
    {
      "x": -11,
      "y": 1,
      "z": 6,
