{
  "version": 8,
  "blockIdVersion": 11,
  "anchorX": 0,
  "anchorY": 0,
  "anchorZ": 0,
  "blocks": [
    {
      "x": -15,
      "y": 0,
      "z": -15,
      "name": "Soil_Dirt"
    },
    {
      "x": -15,
      "y": 1,
      "z": -15,
      "name": "Soil_Dirt"
    },
    {
      "x": -15,
      "y": 2,
      "z": -15,
      "name": "Soil_Dirt"
    },
    {
      "x": -15,
      "y": 3,
      "z": -15,
      "name": "Soil_Grass"
    },
    {
      "x": -15,
      "y": 0,
      "z": -14,
      "name": "Soil_Dirt"
    },
    {
      "x": -15,
      "y": 1,
      "z": -14,
      "name": "Soil_Dirt"
    },
    {
      "x": -15,
      "y": 2,
      "z": -14,
      "name": "Soil_Dirt"
    },
    {
      "x": -15,
      "y": 3,
      "z": -14,
      "name": "Soil_Grass"
    },
    {
      "x": -15,
      "y": 0,
      "z": -13,
      "name": "Soil_Dirt"
    },
    {
      "x": -15,
      "y": 1,
      "z": -13,
      "name": "Soil_Dirt"
    },
    {
      "x": -15,
      "y": 2,
      "z": -13,
      "name": "Soil_Dirt"
    },
    {
      "x": -15,
      "y": 3,
      "z": -13,
      "name": "Soil_Grass"
    },
    {
      "x": -15,
      "y": 0,
      "z": -12,
      "name": "Soil_Dirt"
    },
    {
      "x": -15,
      "y": 1,
      "z": -12,
      "name": "Soil_Dirt"
    },
    {
      "x": -15,
      "y": 2,
      "z": -12,
      "name": "Soil_Dirt",
      "support": 15
    },
    {
      "x": -15,
      "y": 3,
      "z": -12,
      "name": "Soil_Grass"
    },
    {
      "x": -15,
      "y": 0,
      "z": -11,
      "name": "Soil_Dirt"
    },
    {
      "x": -15,
      "y": 1,
      "z": -11,
      "name": "Soil_Dirt"
    },
    {
      "x": -15,
      "y": 2,
      "z": -11,
      "name": "Soil_Dirt",
      "support": 15
    },
    {
      "x": -15,
      "y": 3,
      "z": -11,
      "name": "Soil_Grass",
      "support": 15
    },
    {
      "x": -15,
      "y": 0,
      "z": -10,
      "name": "Soil_Dirt"
    },
    {
      "x": -15,
      "y": 1,
      "z": -10,
      "name": "Soil_Dirt"
    },
    {
      "x": -15,
      "y": 2,
      "z": -10,
      "name": "Wood_Ash_Trunk_Full"
    },
    {
      "x": -15,
      "y": 3,
      "z": -10,
      "name": "Wood_Ash_Trunk",
      "support": 15
    },
    {
      "x": -15,
      "y": 4,
      "z": -10,
      "name": "Wood_Ash_Trunk_Full"
    },
    {
      "x": -15,
      "y": 0,
      "z": -9,
      "name": "Soil_Dirt"
    },
    {
      "x": -15,
      "y": 1,
      "z": -9,
      "name": "Soil_Dirt"
    },
    {
      "x": -15,
      "y": 2,
      "z": -9,
      "name": "Wood_Ash_Trunk_Full"
    },
    {
      "x": -15,
      "y": 3,
      "z": -9,
      "name": "Wood_Ash_Trunk_Full"
    },
    {
      "x": -15,
      "y": 0,
      "z": -8,
      "name": "Soil_Dirt"
    },
    {
      "x": -15,
      "y": 1,
      "z": -8,
      "name": "Soil_Dirt"
    },
    {
      "x": -15,
      "y": 2,
      "z": -8,
      "name": "Soil_Dirt"
    },
    {
      "x": -15,
      "y": 3,
      "z": -8,
      "name": "Soil_Grass"
    },
    {
      "x": -15,
      "y": 0,
      "z": -7,
      "name": "Soil_Dirt"
    },
    {
      "x": -15,
      "y": 1,
      "z": -7,
      "name": "Soil_Dirt"
    },
    {
      "x": -15,
      "y": 2,
      "z": -7,
      "name": "Soil_Dirt"
    },
    {
      "x": -15,
      "y": 3,
      "z": -7,
      "name": "Soil_Grass"
    },
    {
      "x": -15,
      "y": 0,
      "z": -6,
      "name": "Soil_Dirt"
    },
    {
      "x": -15,
      "y": 1,
      "z": -6,
      "name": "Soil_Dirt"
    },
    {
      "x": -15,
      "y": 2,
      "z": -6,
      "name": "Soil_Dirt"
    },
    {
      "x": -15,
      "y": 3,
      "z": -6,
      "name": "Soil_Grass"
    },
    {
      "x": -15,
      "y": 0,
      "z": -5,
      "name": "Soil_Dirt"
    },
    {
      "x": -15,
      "y": 1,
      "z": -5,
      "name": "Soil_Dirt"
    },
    {
      "x": -15,
      "y": 2,
      "z": -5,
      "name": "Soil_Dirt",
      "support": 15
    },
    {
      "x": -15,
      "y": 3,
      "z": -5,
      "name": "Soil_Grass",
      "support": 15
    },
    {
      "x": -15,
      "y": 0,
      "z": -4,
      "name": "Soil_Dirt"
    },
    {
      "x": -15,
      "y": 1,
      "z": -4,
      "name": "Soil_Dirt",
      "support": 15
    },
    {
      "x": -15,
      "y": 2,
      "z": -4,
      "name": "Soil_Dirt"
    },
    {
      "x": -15,
      "y": 3,
      "z": -4,
      "name": "Soil_Grass"
    },
    {
      "x": -15,
      "y": 0,
      "z": -3,
      "name": "Soil_Dirt"
    },
    {
      "x": -15,
      "y": 1,
      "z": -3,
      "name": "Soil_Dirt"
    },
    {
      "x": -15,
      "y": 2,
      "z": -3,
      "name": "Soil_Dirt"
    },
    {
      "x": -15,
      "y": 3,
      "z": -3,
      "name": "Soil_Grass"
    },
    {
      "x": -15,
      "y": 0,
      "z": -2,
      "name": "Soil_Dirt"
    },
    {
      "x": -15,
      "y": 1,
      "z": -2,
      "name": "Soil_Dirt"
    },
    {
      "x": -15,
      "y": 2,
      "z": -2,
      "name": "Soil_Dirt"
    },
    {
      "x": -15,
      "y": 3,
      "z": -2,
      "name": "Soil_Grass"
    },
    {
      "x": -15,
      "y": 0,
      "z": -1,
      "name": "Soil_Dirt"
    },
    {
      "x": -15,
      "y": 1,
      "z": -1,
      "name": "Soil_Dirt"
    },
    {
      "x": -15,
      "y": 2,
      "z": -1,
      "name": "Soil_Dirt"
    },
    {
      "x": -15,
      "y": 3,
      "z": -1,
      "name": "Soil_Grass"
    },
    {
      "x": -15,
      "y": 0,
      "z": 0,
      "name": "Soil_Dirt"
    },
    {
      "x": -15,
      "y": 1,
      "z": 0,
      "name": "Soil_Dirt"
    },
    {
      "x": -15,
      "y": 2,
      "z": 0,
      "name": "Soil_Dirt"
    },
    {
      "x": -15,
      "y": 3,
      "z": 0,
      "name": "Soil_Grass"
    },
    {
      "x": -15,
      "y": 0,
      "z": 1,
      "name": "Soil_Dirt"
    },
    {
      "x": -15,
      "y": 1,
      "z": 1,
      "name": "Soil_Dirt"
    },
    {
      "x": -15,
      "y": 2,
      "z": 1,
      "name": "Soil_Dirt"
    },
    {
      "x": -15,
      "y": 3,
      "z": 1,
      "name": "Soil_Grass"
    },
    {
      "x": -15,
      "y": 0,
      "z": 2,
      "name": "Soil_Dirt"
    },
    {
      "x": -15,
      "y": 1,
      "z": 2,
      "name": "Soil_Dirt"
    },
    {
      "x": -15,
      "y": 2,
      "z": 2,
      "name": "Soil_Dirt"
    },
    {
      "x": -15,
      "y": 3,
      "z": 2,
      "name": "Soil_Grass"
    },
    {
      "x": -15,
      "y": 0,
      "z": 3,
      "name": "Soil_Dirt"
    },
    {
      "x": -15,
      "y": 1,
      "z": 3,
      "name": "Soil_Dirt"
    },
    {
      "x": -15,
      "y": 2,
      "z": 3,
      "name": "Soil_Dirt"
    },
    {
      "x": -15,
      "y": 3,
      "z": 3,
      "name": "Soil_Grass"
    },
    {
      "x": -15,
      "y": 0,
      "z": 4,
      "name": "Soil_Dirt"
    },
    {
      "x": -15,
      "y": 1,
      "z": 4,
      "name": "Soil_Dirt"
    },
    {
      "x": -15,
      "y": 2,
      "z": 4,
      "name": "Soil_Dirt"
    },
    {
      "x": -15,
      "y": 3,
      "z": 4,
      "name": "Soil_Grass"
    },
    {
      "x": -15,
      "y": 0,
      "z": 5,
      "name": "Soil_Dirt"
    },
    {
      "x": -15,
      "y": 1,
      "z": 5,
      "name": "Soil_Dirt"
    },
    {
      "x": -15,
      "y": 2,
      "z": 5,
      "name": "Soil_Dirt"
    },
    {
      "x": -15,
      "y": 3,
      "z": 5,
      "name": "Soil_Grass"
    },
    {
      "x": -15,
      "y": 0,
      "z": 6,
      "name": "Soil_Dirt"
    },
    {
      "x": -15,
      "y": 1,
      "z": 6,
      "name": "Soil_Dirt"
    },
    {
      "x": -15,
      "y": 2,
      "z": 6,
      "name": "Soil_Dirt"
    },
    {
      "x": -15,
      "y": 3,
      "z": 6,
      "name": "Soil_Grass"
    },
    {
      "x": -15,
      "y": 0,
      "z": 7,
      "name": "Soil_Dirt"
    },
    {
      "x": -15,
      "y": 1,
      "z": 7,
      "name": "Soil_Dirt"
    },
    {
      "x": -15,
      "y": 2,
      "z": 7,
      "name": "Soil_Dirt"
    },
    {
      "x": -15,
      "y": 3,
      "z": 7,
      "name": "Soil_Grass"
    },
    {
      "x": -15,
      "y": 0,
      "z": 8,
      "name": "Soil_Dirt",
      "support": 15
    },
    {
      "x": -15,
      "y": 1,
      "z": 8,
      "name": "Soil_Dirt"
    },
    {
      "x": -15,
      "y": 2,
      "z": 8,
      "name": "Soil_Dirt"
    },
    {
      "x": -15,
      "y": 3,
      "z": 8,
      "name": "Soil_Grass"
    },
    {
      "x": -15,
      "y": 0,
      "z": 9,
      "name": "Soil_Dirt"
    },
    {
      "x": -15,
      "y": 1,
      "z": 9,
      "name": "Soil_Dirt",
      "support": 15
    },
    {
      "x": -15,
      "y": 2,
      "z": 9,
      "name": "Soil_Dirt",
      "support": 15
    },
    {
      "x": -15,
      "y": 3,
      "z": 9,
      "name": "Soil_Grass"
    },
    {
      "x": -15,
      "y": 0,
      "z": 10,
      "name": "Soil_Dirt"
    },
    {
      "x": -15,
      "y": 1,
      "z": 10,
      "name": "Soil_Dirt"
    },
    {
      "x": -15,
      "y": 2,
      "z": 10,
      "name": "Soil_Dirt",
      "support": 15
    },
    {
      "x": -15,
      "y": 3,
      "z": 10,
      "name": "Soil_Grass"
    },
    {
      "x": -15,
      "y": 0,
      "z": 11,
      "name": "Soil_Dirt"
    },
    {
      "x": -15,
      "y": 1,
      "z": 11,
      "name": "Soil_Dirt"
    },
    {
      "x": -15,
      "y": 2,
      "z": 11,
      "name": "Soil_Dirt",
      "support": 15
    },
    {
      "x": -15,
      "y": 3,
      "z": 11,
      "name": "Soil_Grass",
      "support": 15
    },
    {
      "x": -15,
      "y": 0,
      "z": 12,
      "name": "Soil_Dirt"
    },
    {
      "x": -15,
      "y": 1,
      "z": 12,
      "name": "Soil_Dirt"
    },
    {
      "x": -15,
      "y": 2,
      "z": 12,
      "name": "Soil_Dirt"
    },
    {
      "x": -15,
      "y": 3,
      "z": 12,
      "name": "Soil_Grass",
      "support": 15
    },
    {
      "x": -15,
      "y": 0,
      "z": 13,
      "name": "Soil_Dirt"
    },
    {
      "x": -15,
      "y": 1,
      "z": 13,
      "name": "Soil_Dirt"
    },
    {
      "x": -15,
      "y": 2,
      "z": 13,
      "name": "Soil_Dirt"
    },
    {
      "x": -15,
      "y": 3,
      "z": 13,
      "name": "Soil_Grass"
    },
    {
      "x": -15,
      "y": 0,
      "z": 14,
      "name": "Soil_Dirt"
    },
    {
      "x": -15,
      "y": 1,
      "z": 14,
      "name": "Soil_Dirt"
    },
    {
      "x": -15,
      "y": 2,
      "z": 14,
      "name": "Soil_Dirt"
    },
    {
      "x": -15,
      "y": 3,
      "z": 14,
      "name": "Soil_Grass"
    },
    {
      "x": -15,
      "y": 0,
      "z": 15,
      "name": "Soil_Dirt"
    },
    {
      "x": -15,
      "y": 1,
      "z": 15,
      "name": "Soil_Dirt"
    },
    {
      "x": -15,
      "y": 2,
      "z": 15,
      "name": "Soil_Dirt"
    },
    {
      "x": -15,
      "y": 3,
      "z": 15,
      "name": "Soil_Grass"
    },
    {
      "x": -15,
      "y": 0,
      "z": 16,
      "name": "Soil_Dirt"
    },
    {
      "x": -15,
      "y": 1,
      "z": 16,
      "name": "Soil_Dirt"
    },
    {
      "x": -15,
      "y": 2,
      "z": 16,
      "name": "Soil_Dirt"
    },
    {
      "x": -15,
      "y": 3,
      "z": 16,
      "name": "Soil_Grass"
    },
    {
      "x": -14,
      "y": 0,
      "z": -15,
      "name": "Soil_Dirt"
    },
    {
      "x": -14,
      "y": 1,
      "z": -15,
      "name": "Soil_Dirt"
    },
    {
      "x": -14,
      "y": 2,
      "z": -15,
      "name": "Soil_Dirt"
    },
    {
      "x": -14,
      "y": 3,
      "z": -15,
      "name": "Soil_Grass"
    },
    {
      "x": -14,
      "y": 0,
      "z": -14,
      "name": "Soil_Dirt"
    },
    {
      "x": -14,
      "y": 1,
      "z": -14,
      "name": "Soil_Dirt"
    },
    {
      "x": -14,
      "y": 2,
      "z": -14,
      "name": "Soil_Dirt"
    },
    {
      "x": -14,
      "y": 3,
      "z": -14,
      "name": "Soil_Grass"
    },
    {
      "x": -14,
      "y": 0,
      "z": -13,
      "name": "Soil_Dirt"
    },
    {
      "x": -14,
      "y": 1,
      "z": -13,
      "name": "Soil_Dirt"
    },
    {
      "x": -14,
      "y": 2,
      "z": -13,
      "name": "Soil_Dirt"
    },
    {
      "x": -14,
      "y": 3,
      "z": -13,
      "name": "Soil_Grass"
    },
    {
      "x": -14,
      "y": 0,
      "z": -12,
      "name": "Soil_Dirt"
    },
    {
      "x": -14,
      "y": 1,
      "z": -12,
      "name": "Soil_Dirt"
    },
    {
      "x": -14,
      "y": 2,
      "z": -12,
      "name": "Soil_Dirt"
    },
    {
      "x": -14,
      "y": 3,
      "z": -12,
      "name": "Soil_Grass"
    },
    {
      "x": -14,
      "y": 0,
      "z": -11,
      "name": "Soil_Dirt"
    },
    {
      "x": -14,
      "y": 1,
      "z": -11,
      "name": "Wood_Ash_Trunk_Full"
    },
    {
      "x": -14,
      "y": 2,
      "z": -11,
      "name": "Wood_Ash_Trunk",
      "support": 15
    },
    {
      "x": -14,
      "y": 3,
      "z": -11,
      "name": "Wood_Ash_Trunk_Full"
    },
    {
      "x": -14,
      "y": 0,
      "z": -10,
      "name": "Soil_Dirt"
    },
    {
      "x": -14,
      "y": 1,
      "z": -10,
      "name": "Soil_Dirt"
    },
    {
      "x": -14,
      "y": 2,
      "z": -10,
      "name": "Wood_Ash_Trunk_Full",
      "rotation": 5
    },
    {
      "x": -14,
      "y": 3,
      "z": -10,
      "name": "Wood_Ash_Trunk",
      "support": 15
    },
    {
      "x": -14,
      "y": 4,
      "z": -10,
      "name": "Wood_Ash_Trunk",
      "support": 15
    },
    {
      "x": -14,
      "y": 5,
      "z": -10,
      "name": "Wood_Ash_Trunk_Full"
    },
    {
      "x": -14,
      "y": 0,
      "z": -9,
      "name": "Soil_Dirt"
    },
    {
      "x": -14,
      "y": 1,
      "z": -9,
      "name": "Soil_Dirt"
    },
    {
      "x": -14,
      "y": 2,
      "z": -9,
      "name": "Soil_Dirt"
    },
    {
      "x": -14,
      "y": 3,
      "z": -9,
      "name": "Wood_Ash_Trunk_Full"
    },
    {
      "x": -14,
      "y": 0,
      "z": -8,
      "name": "Soil_Dirt"
    },
    {
      "x": -14,
      "y": 1,
      "z": -8,
      "name": "Soil_Dirt"
    },
    {
      "x": -14,
      "y": 2,
      "z": -8,
      "name": "Soil_Dirt"
    },
    {
      "x": -14,
      "y": 3,
      "z": -8,
      "name": "Soil_Grass",
      "support": 15
    },
    {
      "x": -14,
      "y": 0,
      "z": -7,
      "name": "Soil_Dirt"
    },
    {
      "x": -14,
      "y": 1,
      "z": -7,
      "name": "Soil_Dirt"
    },
    {
      "x": -14,
      "y": 2,
      "z": -7,
      "name": "Soil_Dirt"
    },
    {
      "x": -14,
      "y": 3,
      "z": -7,
      "name": "Soil_Grass"
    },
    {
      "x": -14,
      "y": 0,
      "z": -6,
      "name": "Soil_Dirt"
    },
    {
      "x": -14,
      "y": 1,
      "z": -6,
      "name": "Soil_Dirt"
    },
    {
      "x": -14,
      "y": 2,
      "z": -6,
      "name": "Soil_Dirt"
    },
    {
      "x": -14,
      "y": 3,
      "z": -6,
      "name": "Soil_Grass"
    },
    {
      "x": -14,
      "y": 0,
      "z": -5,
      "name": "Soil_Dirt"
    },
    {
      "x": -14,
      "y": 1,
      "z": -5,
      "name": "Soil_Dirt"
    },
    {
      "x": -14,
      "y": 2,
      "z": -5,
      "name": "Soil_Dirt"
    },
    {
      "x": -14,
      "y": 3,
      "z": -5,
      "name": "Soil_Grass",
      "support": 15
    },
    {
      "x": -14,
      "y": 0,
      "z": -4,
      "name": "Soil_Dirt"
    },
    {
      "x": -14,
      "y": 1,
      "z": -4,
      "name": "Soil_Dirt"
    },
    {
      "x": -14,
      "y": 2,
      "z": -4,
      "name": "Soil_Dirt"
    },
    {
      "x": -14,
      "y": 3,
      "z": -4,
      "name": "Soil_Grass",
      "support": 15
    },
    {
      "x": -14,
      "y": 0,
      "z": -3,
      "name": "Soil_Dirt"
    },
    {
      "x": -14,
      "y": 1,
      "z": -3,
      "name": "Soil_Dirt"
    },
    {
      "x": -14,
      "y": 2,
      "z": -3,
      "name": "Soil_Dirt"
    },
    {
      "x": -14,
      "y": 3,
      "z": -3,
      "name": "Soil_Grass"
    },
    {
      "x": -14,
      "y": 0,
      "z": -2,
      "name": "Soil_Dirt"
    },
    {
      "x": -14,
      "y": 1,
      "z": -2,
      "name": "Soil_Dirt"
    },
    {
      "x": -14,
      "y": 2,
      "z": -2,
      "name": "Soil_Dirt"
    },
    {
      "x": -14,
      "y": 3,
      "z": -2,
      "name": "Soil_Grass"
    },
    {
      "x": -14,
      "y": 0,
      "z": -1,
      "name": "Soil_Dirt"
    },
    {
      "x": -14,
      "y": 1,
      "z": -1,
      "name": "Soil_Dirt"
    },
    {
      "x": -14,
      "y": 2,
      "z": -1,
      "name": "Soil_Dirt"
    },
    {
      "x": -14,
      "y": 3,
      "z": -1,
      "name": "Soil_Grass"
    },
    {
      "x": -14,
      "y": 0,
      "z": 0,
      "name": "Soil_Dirt"
    },
    {
      "x": -14,
      "y": 1,
      "z": 0,
      "name": "Soil_Dirt"
    },
    {
      "x": -14,
      "y": 2,
      "z": 0,
      "name": "Soil_Dirt"
    },
    {
      "x": -14,
      "y": 3,
      "z": 0,
      "name": "Soil_Grass"
    },
    {
      "x": -14,
      "y": 0,
      "z": 1,
      "name": "Soil_Dirt"
    },
    {
      "x": -14,
      "y": 1,
      "z": 1,
      "name": "Soil_Dirt"
    },
    {
      "x": -14,
      "y": 2,
      "z": 1,
      "name": "Soil_Dirt"
    },
    {
      "x": -14,
      "y": 3,
      "z": 1,
      "name": "Soil_Grass"
    },
    {
      "x": -14,
      "y": 0,
      "z": 2,
      "name": "Soil_Dirt"
    },
    {
      "x": -14,
      "y": 1,
      "z": 2,
      "name": "Soil_Dirt"
    },
    {
      "x": -14,
      "y": 2,
      "z": 2,
      "name": "Soil_Dirt"
    },
    {
      "x": -14,
      "y": 3,
      "z": 2,
      "name": "Soil_Grass"
    },
    {
      "x": -14,
      "y": 0,
      "z": 3,
      "name": "Soil_Dirt"
    },
    {
      "x": -14,
      "y": 1,
      "z": 3,
      "name": "Soil_Dirt"
    },
    {
      "x": -14,
      "y": 2,
      "z": 3,
      "name": "Soil_Dirt"
    },
    {
      "x": -14,
      "y": 3,
      "z": 3,
      "name": "Soil_Grass"
    },
    {
      "x": -14,
      "y": 0,
      "z": 4,
      "name": "Soil_Dirt"
    },
    {
      "x": -14,
      "y": 1,
      "z": 4,
      "name": "Soil_Dirt"
    },
    {
      "x": -14,
      "y": 2,
      "z": 4,
      "name": "Soil_Dirt"
    },
    {
      "x": -14,
      "y": 3,
      "z": 4,
      "name": "Soil_Grass"
    },
    {
      "x": -14,
      "y": 0,
      "z": 5,
      "name": "Soil_Dirt"
    },
    {
      "x": -14,
      "y": 1,
      "z": 5,
      "name": "Soil_Dirt"
    },
    {
      "x": -14,
      "y": 2,
      "z": 5,
      "name": "Soil_Dirt"
    },
    {
      "x": -14,
      "y": 3,
      "z": 5,
      "name": "Soil_Grass"
    },
    {
      "x": -14,
      "y": 0,
      "z": 6,
      "name": "Soil_Dirt"
    },
    {
      "x": -14,
      "y": 1,
      "z": 6,
      "name": "Soil_Dirt"
    },
    {
      "x": -14,
      "y": 2,
      "z": 6,
      "name": "Soil_Dirt"
    },
    {
      "x": -14,
      "y": 3,
      "z": 6,
      "name": "Soil_Grass"
    },
    {
      "x": -14,
      "y": 0,
      "z": 7,
      "name": "Soil_Dirt"
    },
    {
      "x": -14,
      "y": 1,
      "z": 7,
      "name": "Soil_Dirt"
    },
    {
      "x": -14,
      "y": 2,
      "z": 7,
      "name": "Soil_Dirt"
    },
    {
      "x": -14,
      "y": 3,
      "z": 7,
      "name": "Soil_Grass"
    },
    {
      "x": -14,
      "y": 0,
      "z": 8,
      "name": "Soil_Dirt"
    },
    {
      "x": -14,
      "y": 1,
      "z": 8,
      "name": "Soil_Dirt",
      "support": 15
    },
    {
      "x": -14,
      "y": 2,
      "z": 8,
      "name": "Soil_Dirt"
    },
    {
      "x": -14,
      "y": 3,
      "z": 8,
      "name": "Soil_Grass"
    },
    {
      "x": -14,
      "y": 0,
      "z": 9,
      "name": "Soil_Dirt"
    },
    {
      "x": -14,
      "y": 1,
      "z": 9,
      "name": "Soil_Dirt",
      "support": 15
    },
    {
      "x": -14,
      "y": 2,
      "z": 9,
      "name": "Soil_Dirt",
      "support": 15
    },
    {
      "x": -14,
      "y": 3,
      "z": 9,
      "name": "Soil_Grass"
    },
    {
      "x": -14,
      "y": 0,
      "z": 10,
      "name": "Soil_Dirt"
    },
    {
      "x": -14,
      "y": 1,
      "z": 10,
      "name": "Soil_Dirt"
    },
    {
      "x": -14,
      "y": 2,
      "z": 10,
      "name": "Soil_Dirt",
      "support": 15
    },
    {
      "x": -14,
      "y": 3,
      "z": 10,
      "name": "Soil_Grass",
      "support": 15
    },
    {
      "x": -14,
      "y": 0,
      "z": 11,
      "name": "Soil_Dirt"
    },
    {
      "x": -14,
      "y": 1,
      "z": 11,
      "name": "Soil_Dirt"
    },
    {
      "x": -14,
      "y": 2,
      "z": 11,
      "name": "Soil_Dirt"
    },
    {
      "x": -14,
      "y": 3,
      "z": 11,
      "name": "Soil_Grass",
      "support": 15
    },
    {
      "x": -14,
      "y": 0,
      "z": 12,
      "name": "Soil_Dirt"
    },
    {
      "x": -14,
      "y": 1,
      "z": 12,
      "name": "Soil_Dirt"
    },
    {
      "x": -14,
      "y": 2,
      "z": 12,
      "name": "Soil_Dirt"
    },
    {
      "x": -14,
      "y": 3,
      "z": 12,
      "name": "Soil_Grass"
    },
    {
      "x": -14,
      "y": 0,
      "z": 13,
      "name": "Soil_Dirt"
    },
    {
      "x": -14,
      "y": 1,
      "z": 13,
      "name": "Soil_Dirt"
    },
    {
      "x": -14,
      "y": 2,
      "z": 13,
      "name": "Soil_Dirt"
    },
    {
      "x": -14,
      "y": 3,
      "z": 13,
      "name": "Soil_Grass"
    },
    {
      "x": -14,
      "y": 0,
      "z": 14,
      "name": "Soil_Dirt"
    },
    {
      "x": -14,
      "y": 1,
      "z": 14,
      "name": "Soil_Dirt"
    },
    {
      "x": -14,
      "y": 2,
      "z": 14,
      "name": "Soil_Dirt"
    },
    {
      "x": -14,
      "y": 3,
      "z": 14,
      "name": "Soil_Grass"
    },
    {
      "x": -14,
      "y": 0,
      "z": 15,
      "name": "Soil_Dirt"
    },
    {
      "x": -14,
      "y": 1,
      "z": 15,
      "name": "Soil_Dirt"
    },
    {
      "x": -14,
      "y": 2,
      "z": 15,
      "name": "Soil_Dirt"
    },
    {
      "x": -14,
      "y": 3,
      "z": 15,
      "name": "Soil_Grass"
    },
    {
      "x": -14,
      "y": 0,
      "z": 16,
      "name": "Soil_Dirt"
    },
    {
      "x": -14,
      "y": 1,
      "z": 16,
      "name": "Soil_Dirt"
    },
    {
      "x": -14,
      "y": 2,
      "z": 16,
      "name": "Soil_Dirt"
    },
    {
      "x": -14,
      "y": 3,
      "z": 16,
      "name": "Soil_Grass"
    },
    {
      "x": -13,
      "y": 0,
      "z": -15,
      "name": "Soil_Dirt"
    },
    {
      "x": -13,
      "y": 1,
      "z": -15,
      "name": "Soil_Dirt"
    },
    {
      "x": -13,
      "y": 2,
      "z": -15,
      "name": "Soil_Dirt"
    },
    {
      "x": -13,
      "y": 3,
      "z": -15,
      "name": "Soil_Grass"
    },
    {
      "x": -13,
      "y": 0,
      "z": -14,
      "name": "Soil_Dirt"
    },
    {
      "x": -13,
      "y": 1,
      "z": -14,
      "name": "Soil_Dirt"
    },
    {
      "x": -13,
      "y": 2,
      "z": -14,
      "name": "Soil_Dirt"
    },
    {
      "x": -13,
      "y": 3,
      "z": -14,
      "name": "Soil_Grass"
    },
    {
      "x": -13,
      "y": 0,
      "z": -13,
      "name": "Wood_Ash_Trunk_Full"
    },
    {
      "x": -13,
      "y": 1,
      "z": -13,
      "name": "Soil_Dirt"
    },
    {
      "x": -13,
      "y": 2,
      "z": -13,
      "name": "Soil_Dirt"
    },
    {
      "x": -13,
      "y": 3,
      "z": -13,
      "name": "Soil_Grass"
    },
    {
      "x": -13,
      "y": 0,
      "z": -12,
      "name": "Wood_Ash_Trunk",
      "support": 15
    },
    {
      "x": -13,
      "y": 1,
      "z": -12,
      "name": "Wood_Ash_Trunk",
      "support": 15
    },
    {
      "x": -13,
      "y": 2,
      "z": -12,
      "name": "Wood_Ash_Trunk_Full"
    },
    {
      "x": -13,
      "y": 3,
      "z": -12,
      "name": "Soil_Grass"
    },
    {
      "x": -13,
      "y": 0,
      "z": -11,
      "name": "Wood_Ash_Trunk",
      "support": 15
    },
    {
      "x": -13,
      "y": 1,
      "z": -11,
      "name": "Wood_Ash_Trunk",
      "support": 15
    },
    {
      "x": -13,
      "y": 2,
      "z": -11,
      "name": "Wood_Ash_Trunk",
      "support": 15
    },
    {
      "x": -13,
      "y": 3,
      "z": -11,
      "name": "Wood_Ash_Trunk",
      "support": 15
    },
    {
      "x": -13,
      "y": 4,
      "z": -11,
      "name": "Wood_Ash_Trunk",
      "support": 15
    },
    {
      "x": -13,
      "y": 5,
      "z": -11,
      "name": "Wood_Ash_Trunk",
      "support": 15
    },
    {
      "x": -13,
      "y": 6,
      "z": -11,
      "name": "Wood_Ash_Trunk",
      "support": 15
    },
    {
      "x": -13,
      "y": 7,
      "z": -11,
      "name": "Wood_Ash_Trunk_Full"
    },
    {
      "x": -13,
      "y": 0,
      "z": -10,
      "name": "Wood_Ash_Trunk",
      "support": 15
    },
    {
      "x": -13,
      "y": 1,
      "z": -10,
      "name": "Wood_Ash_Trunk",
      "support": 15
    },
    {
      "x": -13,
      "y": 2,
      "z": -10,
      "name": "Wood_Ash_Trunk",
      "support": 15
    },
    {
      "x": -13,
      "y": 3,
      "z": -10,
      "name": "Wood_Ash_Trunk",
      "support": 15
    },
    {
      "x": -13,
      "y": 4,
      "z": -10,
      "name": "Wood_Ash_Trunk",
      "support": 15
    },
    {
      "x": -13,
      "y": 5,
      "z": -10,
      "name": "Wood_Ash_Trunk",
      "support": 15
    },
    {
      "x": -13,
      "y": 6,
      "z": -10,
      "name": "Wood_Ash_Trunk_Full"
    },
    {
      "x": -13,
      "y": 0,
      "z": -9,
      "name": "Soil_Dirt"
    },
    {
      "x": -13,
      "y": 1,
      "z": -9,
      "name": "Soil_Dirt"
    },
    {
      "x": -13,
      "y": 2,
      "z": -9,
      "name": "Soil_Dirt"
    },
    {
      "x": -13,
      "y": 3,
      "z": -9,
      "name": "Soil_Grass",
      "support": 15
    },
    {
      "x": -13,
      "y": 0,
      "z": -8,
      "name": "Soil_Dirt"
    },
    {
      "x": -13,
      "y": 1,
      "z": -8,
      "name": "Soil_Dirt"
    },
    {
      "x": -13,
      "y": 2,
      "z": -8,
      "name": "Soil_Dirt"
    },
    {
      "x": -13,
      "y": 3,
      "z": -8,
      "name": "Soil_Grass",
      "support": 15
    },
    {
      "x": -13,
      "y": 0,
      "z": -7,
      "name": "Soil_Dirt"
    },
    {
      "x": -13,
      "y": 1,
      "z": -7,
      "name": "Soil_Dirt"
    },
    {
      "x": -13,
      "y": 2,
      "z": -7,
      "name": "Soil_Dirt"
    },
    {
      "x": -13,
      "y": 3,
      "z": -7,
      "name": "Soil_Grass",
      "support": 15
    },
    {
      "x": -13,
      "y": 0,
      "z": -6,
      "name": "Soil_Dirt"
    },
    {
      "x": -13,
      "y": 1,
      "z": -6,
      "name": "Soil_Dirt"
    },
    {
      "x": -13,
      "y": 2,
      "z": -6,
      "name": "Soil_Dirt"
    },
    {
      "x": -13,
      "y": 3,
      "z": -6,
      "name": "Soil_Grass",
      "support": 15
    },
    {
      "x": -13,
      "y": 0,
      "z": -5,
      "name": "Soil_Dirt"
    },
    {
      "x": -13,
      "y": 1,
      "z": -5,
      "name": "Soil_Dirt"
    },
    {
      "x": -13,
      "y": 2,
      "z": -5,
      "name": "Soil_Dirt"
    },
    {
      "x": -13,
      "y": 3,
      "z": -5,
      "name": "Soil_Grass"
    },
    {
      "x": -13,
      "y": 0,
      "z": -4,
      "name": "Soil_Dirt"
    },
    {
      "x": -13,
      "y": 1,
      "z": -4,
      "name": "Soil_Dirt"
    },
    {
      "x": -13,
      "y": 2,
      "z": -4,
      "name": "Soil_Dirt"
    },
    {
      "x": -13,
      "y": 3,
      "z": -4,
      "name": "Soil_Grass"
    },
    {
      "x": -13,
      "y": 0,
      "z": -3,
      "name": "Soil_Dirt"
    },
    {
      "x": -13,
      "y": 1,
      "z": -3,
      "name": "Soil_Dirt"
    },
    {
      "x": -13,
      "y": 2,
      "z": -3,
      "name": "Soil_Dirt"
    },
    {
      "x": -13,
      "y": 3,
      "z": -3,
      "name": "Soil_Grass"
    },
    {
      "x": -13,
      "y": 0,
      "z": -2,
      "name": "Soil_Dirt"
    },
    {
      "x": -13,
      "y": 1,
      "z": -2,
      "name": "Soil_Dirt"
    },
    {
      "x": -13,
      "y": 2,
      "z": -2,
      "name": "Soil_Dirt"
    },
    {
      "x": -13,
      "y": 3,
      "z": -2,
      "name": "Soil_Grass"
    },
    {
      "x": -13,
      "y": 0,
      "z": -1,
      "name": "Soil_Dirt"
    },
    {
      "x": -13,
      "y": 1,
      "z": -1,
      "name": "Soil_Dirt"
    },
    {
      "x": -13,
      "y": 2,
      "z": -1,
      "name": "Soil_Dirt"
    },
    {
      "x": -13,
      "y": 3,
      "z": -1,
      "name": "Soil_Grass"
    },
    {
      "x": -13,
      "y": 0,
      "z": 0,
      "name": "Soil_Dirt"
    },
    {
      "x": -13,
      "y": 1,
      "z": 0,
      "name": "Soil_Dirt"
    },
    {
      "x": -13,
      "y": 2,
      "z": 0,
      "name": "Soil_Dirt"
    },
    {
      "x": -13,
      "y": 3,
      "z": 0,
      "name": "Soil_Grass"
    },
    {
      "x": -13,
      "y": 0,
      "z": 1,
      "name": "Soil_Dirt"
    },
    {
      "x": -13,
      "y": 1,
      "z": 1,
      "name": "Soil_Dirt"
    },
    {
      "x": -13,
      "y": 2,
      "z": 1,
      "name": "Soil_Dirt"
    },
    {
      "x": -13,
      "y": 3,
      "z": 1,
      "name": "Soil_Grass"
    },
    {
      "x": -13,
      "y": 0,
      "z": 2,
      "name": "Soil_Dirt"
    },
    {
      "x": -13,
      "y": 1,
      "z": 2,
      "name": "Soil_Dirt"
    },
    {
      "x": -13,
      "y": 2,
      "z": 2,
      "name": "Soil_Dirt"
    },
    {
      "x": -13,
      "y": 3,
      "z": 2,
      "name": "Soil_Grass"
    },
    {
      "x": -13,
      "y": 0,
      "z": 3,
      "name": "Soil_Dirt"
    },
    {
      "x": -13,
      "y": 1,
      "z": 3,
      "name": "Soil_Dirt"
    },
    {
      "x": -13,
      "y": 2,
      "z": 3,
      "name": "Soil_Dirt"
    },
    {
      "x": -13,
      "y": 3,
      "z": 3,
      "name": "Soil_Grass"
    },
    {
      "x": -13,
      "y": 0,
      "z": 4,
      "name": "Soil_Dirt"
    },
    {
      "x": -13,
      "y": 1,
      "z": 4,
      "name": "Soil_Dirt"
    },
    {
      "x": -13,
      "y": 2,
      "z": 4,
      "name": "Soil_Dirt"
    },
    {
      "x": -13,
      "y": 3,
      "z": 4,
      "name": "Soil_Grass"
    },
    {
      "x": -13,
      "y": 0,
      "z": 5,
      "name": "Soil_Dirt"
    },
    {
      "x": -13,
      "y": 1,
      "z": 5,
      "name": "Soil_Dirt"
    },
    {
      "x": -13,
      "y": 2,
      "z": 5,
      "name": "Soil_Dirt"
    },
    {
      "x": -13,
      "y": 3,
      "z": 5,
      "name": "Soil_Grass"
    },
    {
      "x": -13,
      "y": 0,
      "z": 6,
      "name": "Soil_Dirt"
    },
    {
      "x": -13,
      "y": 1,
      "z": 6,
      "name": "Soil_Dirt"
    },
    {
      "x": -13,
      "y": 2,
      "z": 6,
      "name": "Soil_Dirt"
    },
    {
      "x": -13,
      "y": 3,
      "z": 6,
      "name": "Soil_Grass"
    },
    {
      "x": -13,
      "y": 0,
      "z": 7,
      "name": "Soil_Dirt"
    },
    {
      "x": -13,
      "y": 1,
      "z": 7,
      "name": "Soil_Dirt"
    },
    {
      "x": -13,
      "y": 2,
      "z": 7,
      "name": "Soil_Dirt"
    },
    {
      "x": -13,
      "y": 3,
      "z": 7,
      "name": "Soil_Grass"
    },
    {
      "x": -13,
      "y": 0,
      "z": 8,
      "name": "Soil_Dirt"
    },
    {
      "x": -13,
      "y": 1,
      "z": 8,
      "name": "Soil_Dirt"
    },
    {
      "x": -13,
      "y": 2,
      "z": 8,
      "name": "Soil_Dirt",
      "support": 15
    },
    {
      "x": -13,
      "y": 3,
      "z": 8,
      "name": "Soil_Grass",
      "support": 15
    },
    {
      "x": -13,
      "y": 0,
      "z": 9,
      "name": "Soil_Dirt"
    },
    {
      "x": -13,
      "y": 1,
      "z": 9,
      "name": "Soil_Dirt"
    },
    {
      "x": -13,
      "y": 2,
      "z": 9,
      "name": "Soil_Dirt",
      "support": 15
    },
    {
      "x": -13,
      "y": 3,
      "z": 9,
      "name": "Soil_Grass",
      "support": 15
    },
    {
      "x": -13,
      "y": 0,
      "z": 10,
      "name": "Soil_Dirt"
    },
    {
      "x": -13,
      "y": 1,
      "z": 10,
      "name": "Soil_Dirt"
    },
    {
      "x": -13,
      "y": 2,
      "z": 10,
      "name": "Soil_Dirt"
    },
    {
      "x": -13,
      "y": 3,
      "z": 10,
      "name": "Soil_Grass",
      "support": 15
    },
    {
      "x": -13,
      "y": 0,
      "z": 11,
      "name": "Soil_Dirt"
    },
    {
      "x": -13,
      "y": 1,
      "z": 11,
      "name": "Soil_Dirt"
    },
    {
      "x": -13,
      "y": 2,
      "z": 11,
      "name": "Soil_Dirt"
    },
    {
      "x": -13,
      "y": 3,
      "z": 11,
      "name": "Soil_Grass"
    },
    {
      "x": -13,
      "y": 0,
      "z": 12,
      "name": "Soil_Dirt"
    },
    {
      "x": -13,
      "y": 1,
      "z": 12,
      "name": "Soil_Dirt"
    },
    {
      "x": -13,
      "y": 2,
      "z": 12,
      "name": "Soil_Dirt"
    },
    {
      "x": -13,
      "y": 3,
      "z": 12,
      "name": "Soil_Grass"
    },
    {
      "x": -13,
      "y": 0,
      "z": 13,
      "name": "Soil_Dirt"
    },
    {
      "x": -13,
      "y": 1,
      "z": 13,
      "name": "Soil_Dirt",
      "support": 15
    },
    {
      "x": -13,
      "y": 2,
      "z": 13,
      "name": "Soil_Dirt",
      "support": 15
    },
    {
      "x": -13,
      "y": 3,
      "z": 13,
      "name": "Soil_Grass",
      "support": 15
    },
    {
      "x": -13,
      "y": 0,
      "z": 14,
      "name": "Soil_Dirt",
      "support": 15
    },
    {
      "x": -13,
      "y": 1,
      "z": 14,
      "name": "Soil_Dirt",
      "support": 15
    },
    {
      "x": -13,
      "y": 2,
      "z": 14,
      "name": "Soil_Dirt"
    },
    {
      "x": -13,
      "y": 3,
      "z": 14,
      "name": "Soil_Grass"
    },
    {
      "x": -13,
      "y": 0,
      "z": 15,
      "name": "Soil_Dirt"
    },
    {
      "x": -13,
      "y": 1,
      "z": 15,
      "name": "Soil_Dirt"
    },
    {
      "x": -13,
      "y": 2,
      "z": 15,
      "name": "Soil_Dirt"
    },
    {
      "x": -13,
      "y": 3,
      "z": 15,
      "name": "Soil_Grass"
    },
    {
      "x": -13,
      "y": 0,
      "z": 16,
      "name": "Soil_Dirt"
    },
    {
      "x": -13,
      "y": 1,
      "z": 16,
      "name": "Soil_Dirt"
    },
    {
      "x": -13,
      "y": 2,
      "z": 16,
      "name": "Soil_Dirt"
    },
    {
      "x": -13,
      "y": 3,
      "z": 16,
      "name": "Soil_Grass"
    },
    {
      "x": -12,
      "y": 0,
      "z": -15,
      "name": "Soil_Dirt"
    },
    {
      "x": -12,
      "y": 1,
      "z": -15,
      "name": "Soil_Dirt"
    },
    {
      "x": -12,
      "y": 2,
      "z": -15,
      "name": "Soil_Dirt"
    },
    {
      "x": -12,
      "y": 3,
      "z": -15,
      "name": "Soil_Grass"
    },
    {
      "x": -12,
      "y": 0,
      "z": -14,
      "name": "Soil_Dirt"
    },
    {
      "x": -12,
      "y": 1,
      "z": -14,
      "name": "Soil_Dirt"
    },
    {
      "x": -12,
      "y": 2,
      "z": -14,
      "name": "Soil_Dirt"
    },
    {
      "x": -12,
      "y": 3,
      "z": -14,
      "name": "Soil_Grass"
    },
    {
      "x": -12,
      "y": 0,
      "z": -13,
      "name": "Wood_Ash_Trunk",
      "support": 15
    },
    {
      "x": -12,
      "y": 1,
      "z": -13,
      "name": "Wood_Ash_Trunk_Full"
    },
    {
      "x": -12,
      "y": 2,
      "z": -13,
      "name": "Soil_Dirt"
    },
    {
      "x": -12,
      "y": 3,
      "z": -13,
      "name": "Soil_Grass"
    },
    {
      "x": -12,
      "y": 0,
      "z": -12,
      "name": "Wood_Ash_Trunk",
      "support": 15
    },
    {
      "x": -12,
      "y": 1,
      "z": -12,
      "name": "Wood_Ash_Trunk",
      "support": 15
    },
    {
      "x": -12,
      "y": 2,
      "z": -12,
      "name": "Wood_Ash_Trunk",
      "support": 15
    },
    {
      "x": -12,
      "y": 3,
      "z": -12,
      "name": "Wood_Ash_Trunk",
      "support": 15
    },
    {
      "x": -12,
      "y": 4,
      "z": -12,
      "name": "Wood_Ash_Trunk",
      "support": 15
    },
    {
      "x": -12,
      "y": 5,
      "z": -12,
      "name": "Wood_Ash_Trunk",
      "support": 15
    },
    {
      "x": -12,
      "y": 6,
      "z": -12,
      "name": "Wood_Ash_Trunk",
      "support": 15
    },
    {
      "x": -12,
      "y": 7,
      "z": -12,
      "name": "Wood_Ash_Trunk_Full"
    },
    {
      "x": -12,
      "y": 0,
      "z": -11,
      "name": "Wood_Ash_Trunk",
      "support": 15
    },
    {
      "x": -12,
      "y": 1,
      "z": -11,
      "name": "Wood_Ash_Trunk",
      "support": 15
    },
    {
      "x": -12,
      "y": 2,
      "z": -11,
      "name": "Wood_Ash_Trunk",
      "support": 15
    },
    {
      "x": -12,
      "y": 3,
      "z": -11,
      "name": "Wood_Ash_Trunk",
      "support": 15
    },
    {
      "x": -12,
      "y": 4,
      "z": -11,
      "name": "Wood_Ash_Trunk",
      "support": 15
    },
    {
      "x": -12,
      "y": 5,
      "z": -11,
      "name": "Wood_Ash_Trunk",
      "support": 15
    },
    {
      "x": -12,
      "y": 6,
      "z": -11,
      "name": "Wood_Ash_Trunk",
      "support": 15
    },
    {
      "x": -12,
      "y": 7,
      "z": -11,
      "name": "Wood_Ash_Trunk",
      "support": 15
    },
    {
      "x": -12,
      "y": 8,
      "z": -11,
      "name": "Wood_Ash_Trunk_Full"
    },
    {
      "x": -12,
      "y": 0,
      "z": -10,
      "name": "Soil_Dirt"
    },
    {
      "x": -12,
      "y": 1,
      "z": -10,
      "name": "Wood_Ash_Trunk_Full"
    },
    {
      "x": -12,
      "y": 2,
      "z": -10,
      "name": "Wood_Ash_Trunk",
      "support": 15
    },
    {
      "x": -12,
      "y": 3,
      "z": -10,
      "name": "Wood_Ash_Trunk",
      "support": 15
    },
    {
      "x": -12,
      "y": 4,
      "z": -10,
      "name": "Wood_Ash_Trunk",
      "support": 15
    },
    {
      "x": -12,
      "y": 5,
      "z": -10,
      "name": "Wood_Ash_Trunk",
      "support": 15
    },
    {
      "x": -12,
      "y": 6,
      "z": -10,
      "name": "Wood_Ash_Trunk",
      "support": 15
    },
    {
      "x": -12,
      "y": 7,
      "z": -10,
      "name": "Wood_Ash_Trunk_Full"
    },
    {
      "x": -12,
      "y": 0,
      "z": -9,
      "name": "Soil_Dirt"
    },
    {
      "x": -12,
      "y": 1,
      "z": -9,
      "name": "Soil_Dirt"
    },
    {
      "x": -12,
      "y": 2,
      "z": -9,
      "name": "Soil_Dirt",
      "support": 15
    },
    {
      "x": -12,
      "y": 3,
      "z": -9,
      "name": "Soil_Grass",
      "support": 15
    },
    {
      "x": -12,
      "y": 0,
      "z": -8,
      "name": "Soil_Dirt"
    },
    {
      "x": -12,
      "y": 1,
      "z": -8,
      "name": "Soil_Dirt"
    },
    {
      "x": -12,
      "y": 2,
      "z": -8,
      "name": "Soil_Dirt"
    },
    {
      "x": -12,
      "y": 3,
      "z": -8,
      "name": "Soil_Grass",
      "support": 15
    },
    {
      "x": -12,
      "y": 0,
      "z": -7,
      "name": "Soil_Dirt"
    },
    {
      "x": -12,
      "y": 1,
      "z": -7,
      "name": "Soil_Dirt"
    },
    {
      "x": -12,
      "y": 2,
      "z": -7,
      "name": "Soil_Dirt"
    },
    {
      "x": -12,
      "y": 3,
      "z": -7,
      "name": "Soil_Grass",
      "support": 15
    },
    {
      "x": -12,
      "y": 0,
      "z": -6,
      "name": "Soil_Dirt"
    },
    {
      "x": -12,
      "y": 1,
      "z": -6,
      "name": "Soil_Dirt"
    },
    {
      "x": -12,
      "y": 2,
      "z": -6,
      "name": "Soil_Dirt"
    },
    {
      "x": -12,
      "y": 3,
      "z": -6,
      "name": "Soil_Grass",
      "support": 15
    },
    {
      "x": -12,
      "y": 0,
      "z": -5,
      "name": "Soil_Dirt"
    },
    {
      "x": -12,
      "y": 1,
      "z": -5,
      "name": "Soil_Dirt"
    },
    {
      "x": -12,
      "y": 2,
      "z": -5,
      "name": "Soil_Dirt"
    },
    {
      "x": -12,
      "y": 3,
      "z": -5,
      "name": "Soil_Grass",
      "support": 15
    },
    {
      "x": -12,
      "y": 0,
      "z": -4,
      "name": "Soil_Dirt"
    },
    {
      "x": -12,
      "y": 1,
      "z": -4,
      "name": "Soil_Dirt"
    },
    {
      "x": -12,
      "y": 2,
      "z": -4,
      "name": "Soil_Dirt"
    },
    {
      "x": -12,
      "y": 3,
      "z": -4,
      "name": "Soil_Grass"
    },
    {
      "x": -12,
      "y": 0,
      "z": -3,
      "name": "Soil_Dirt"
    },
    {
      "x": -12,
      "y": 1,
      "z": -3,
      "name": "Soil_Dirt"
    },
    {
      "x": -12,
      "y": 2,
      "z": -3,
      "name": "Soil_Dirt"
    },
    {
      "x": -12,
      "y": 3,
      "z": -3,
      "name": "Soil_Grass"
    },
    {
      "x": -12,
      "y": 0,
      "z": -2,
      "name": "Soil_Dirt"
    },
    {
      "x": -12,
      "y": 1,
      "z": -2,
      "name": "Soil_Dirt"
    },
    {
      "x": -12,
      "y": 2,
      "z": -2,
      "name": "Soil_Dirt"
    },
    {
      "x": -12,
      "y": 3,
      "z": -2,
      "name": "Soil_Grass"
    },
    {
      "x": -12,
      "y": 0,
      "z": -1,
      "name": "Soil_Dirt"
    },
    {
      "x": -12,
      "y": 1,
      "z": -1,
      "name": "Soil_Dirt"
    },
    {
      "x": -12,
      "y": 2,
      "z": -1,
      "name": "Soil_Dirt"
    },
    {
      "x": -12,
      "y": 3,
      "z": -1,
      "name": "Soil_Grass"
    },
    {
      "x": -12,
      "y": 0,
      "z": 0,
      "name": "Soil_Dirt"
    },
    {
      "x": -12,
      "y": 1,
      "z": 0,
      "name": "Soil_Dirt"
    },
    {
      "x": -12,
      "y": 2,
      "z": 0,
      "name": "Soil_Dirt"
    },
    {
      "x": -12,
      "y": 3,
      "z": 0,
      "name": "Soil_Grass"
    },
    {
      "x": -12,
      "y": 0,
      "z": 1,
      "name": "Soil_Dirt"
    },
    {
      "x": -12,
      "y": 1,
      "z": 1,
      "name": "Soil_Dirt"
    },
    {
      "x": -12,
      "y": 2,
      "z": 1,
      "name": "Soil_Dirt"
    },
    {
      "x": -12,
      "y": 3,
      "z": 1,
      "name": "Soil_Grass"
    },
    {
      "x": -12,
      "y": 0,
      "z": 2,
      "name": "Soil_Dirt"
    },
    {
      "x": -12,
      "y": 1,
      "z": 2,
      "name": "Soil_Dirt"
    },
    {
      "x": -12,
      "y": 2,
      "z": 2,
      "name": "Soil_Dirt"
    },
    {
      "x": -12,
      "y": 3,
      "z": 2,
      "name": "Soil_Grass"
    },
    {
      "x": -12,
      "y": 0,
      "z": 3,
      "name": "Soil_Dirt"
    },
    {
      "x": -12,
      "y": 1,
      "z": 3,
      "name": "Soil_Dirt"
    },
    {
      "x": -12,
      "y": 2,
      "z": 3,
      "name": "Soil_Dirt"
    },
    {
      "x": -12,
      "y": 3,
      "z": 3,
      "name": "Soil_Grass"
    },
    {
      "x": -12,
      "y": 0,
      "z": 4,
      "name": "Soil_Dirt"
    },
    {
      "x": -12,
      "y": 1,
      "z": 4,
      "name": "Soil_Dirt"
    },
    {
      "x": -12,
      "y": 2,
      "z": 4,
      "name": "Soil_Dirt"
    },
    {
      "x": -12,
      "y": 3,
      "z": 4,
      "name": "Soil_Grass"
    },
    {
      "x": -12,
      "y": 0,
      "z": 5,
      "name": "Soil_Dirt"
    },
    {
      "x": -12,
      "y": 1,
      "z": 5,
      "name": "Soil_Dirt"
    },
    {
      "x": -12,
      "y": 2,
      "z": 5,
      "name": "Soil_Dirt"
    },
    {
      "x": -12,
      "y": 3,
      "z": 5,
      "name": "Soil_Grass"
    },
    {
      "x": -12,
      "y": 0,
      "z": 6,
      "name": "Soil_Dirt"
    },
    {
      "x": -12,
      "y": 1,
      "z": 6,
      "name": "Soil_Dirt"
    },
    {
      "x": -12,
      "y": 2,
      "z": 6,
      "name": "Soil_Dirt"
    },
    {
      "x": -12,
      "y": 3,
      "z": 6,
      "name": "Soil_Grass"
    },
    {
      "x": -12,
      "y": 0,
      "z": 7,
      "name": "Soil_Dirt"
    },
    {
      "x": -12,
      "y": 1,
      "z": 7,
      "name": "Soil_Dirt"
    },
    {
      "x": -12,
      "y": 2,
      "z": 7,
      "name": "Soil_Dirt"
    },
    {
      "x": -12,
      "y": 3,
      "z": 7,
      "name": "Soil_Grass"
    },
    {
      "x": -12,
      "y": 0,
      "z": 8,
      "name": "Soil_Dirt"
    },
    {
      "x": -12,
      "y": 1,
      "z": 8,
      "name": "Soil_Dirt"
    },
    {
      "x": -12,
      "y": 2,
      "z": 8,
      "name": "Soil_Dirt"
    },
    {
      "x": -12,
      "y": 3,
      "z": 8,
      "name": "Soil_Grass"
    },
    {
      "x": -12,
      "y": 0,
      "z": 9,
      "name": "Soil_Dirt"
    },
    {
      "x": -12,
      "y": 1,
      "z": 9,
      "name": "Soil_Dirt"
    },
    {
      "x": -12,
      "y": 2,
      "z": 9,
      "name": "Soil_Dirt",
      "support": 15
    },
    {
      "x": -12,
      "y": 3,
      "z": 9,
      "name": "Soil_Grass"
    },
    {
      "x": -12,
      "y": 0,
      "z": 10,
      "name": "Soil_Dirt"
    },
    {
      "x": -12,
      "y": 1,
      "z": 10,
      "name": "Soil_Dirt"
    },
    {
      "x": -12,
      "y": 2,
      "z": 10,
      "name": "Soil_Dirt",
      "support": 15
    },
    {
      "x": -12,
      "y": 3,
      "z": 10,
      "name": "Soil_Grass"
    },
    {
      "x": -12,
      "y": 0,
      "z": 11,
      "name": "Soil_Dirt"
    },
    {
      "x": -12,
      "y": 1,
      "z": 11,
      "name": "Soil_Dirt"
    },
    {
      "x": -12,
      "y": 2,
      "z": 11,
      "name": "Soil_Dirt"
    },
    {
      "x": -12,
      "y": 3,
      "z": 11,
      "name": "Soil_Grass",
      "support": 15
    },
    {
      "x": -12,
      "y": 0,
      "z": 12,
      "name": "Soil_Dirt",
      "support": 15
    },
    {
      "x": -12,
      "y": 1,
      "z": 12,
      "name": "Soil_Dirt",
      "support": 15
    },
    {
      "x": -12,
      "y": 2,
      "z": 12,
      "name": "Soil_Dirt",
      "support": 15
    },
    {
      "x": -12,
      "y": 3,
      "z": 12,
      "name": "Soil_Grass",
      "support": 15
    },
    {
      "x": -12,
      "y": 0,
      "z": 13,
      "name": "Soil_Dirt",
      "support": 15
    },
    {
      "x": -12,
      "y": 1,
      "z": 13,
      "name": "Soil_Dirt",
      "support": 15
    },
    {
      "x": -12,
      "y": 2,
      "z": 13,
      "name": "Soil_Dirt",
      "support": 15
    },
    {
      "x": -12,
      "y": 3,
      "z": 13,
      "name": "Soil_Grass",
      "support": 15
    },
    {
      "x": -12,
      "y": 0,
      "z": 14,
      "name": "Soil_Dirt",
      "support": 15
    },
    {
      "x": -12,
      "y": 1,
      "z": 14,
      "name": "Soil_Dirt",
      "support": 15
    },
    {
      "x": -12,
      "y": 2,
      "z": 14,
      "name": "Soil_Dirt",
      "support": 15
    },
    {
      "x": -12,
      "y": 3,
      "z": 14,
      "name": "Soil_Grass",
      "support": 15
    },
    {
      "x": -12,
      "y": 0,
      "z": 15,
      "name": "Soil_Dirt"
    },
    {
      "x": -12,
      "y": 1,
      "z": 15,
      "name": "Soil_Dirt"
    },
    {
      "x": -12,
      "y": 2,
      "z": 15,
      "name": "Soil_Dirt"
    },
    {
      "x": -12,
      "y": 3,
      "z": 15,
      "name": "Soil_Grass"
    },
    {
      "x": -12,
      "y": 0,
      "z": 16,
      "name": "Soil_Dirt"
    },
    {
      "x": -12,
      "y": 1,
      "z": 16,
      "name": "Soil_Dirt"
    },
    {
      "x": -12,
      "y": 2,
      "z": 16,
      "name": "Soil_Dirt"
    },
    {
      "x": -12,
      "y": 3,
      "z": 16,
      "name": "Soil_Grass"
    },
    {
      "x": -11,
      "y": 0,
      "z": -15,
      "name": "Soil_Dirt"
    },
    {
      "x": -11,
      "y": 1,
      "z": -15,
      "name": "Soil_Dirt"
    },
    {
      "x": -11,
      "y": 2,
      "z": -15,
      "name": "Soil_Dirt"
    },
    {
      "x": -11,
      "y": 3,
      "z": -15,
      "name": "Soil_Grass"
    },
    {
      "x": -11,
      "y": 0,
      "z": -14,
      "name": "Soil_Dirt"
    },
    {
      "x": -11,
      "y": 1,
      "z": -14,
      "name": "Soil_Dirt"
    },
    {
      "x": -11,
      "y": 2,
      "z": -14,
      "name": "Soil_Dirt"
    },
    {
      "x": -11,
      "y": 3,
      "z": -14,
      "name": "Soil_Grass"
    },
    {
      "x": -11,
      "y": 0,
      "z": -13,
      "name": "Soil_Dirt"
    },
    {
      "x": -11,
      "y": 1,
      "z": -13,
      "name": "Soil_Dirt"
    },
    {
      "x": -11,
      "y": 2,
      "z": -13,
      "name": "Soil_Dirt"
    },
    {
      "x": -11,
      "y": 3,
      "z": -13,
      "name": "Soil_Grass"
    },
    {
      "x": -11,
      "y": 8,
      "z": -13,
      "name": "Wood_Ash_Trunk_Full"
    },
    {
      "x": -11,
      "y": 9,
      "z": -13,
      "name": "Wood_Ash_Trunk",
      "support": 15
    },
    {
      "x": -11,
      "y": 10,
      "z": -13,
      "name": "Wood_Ash_Trunk_Full"
    },
    {
      "x": -11,
      "y": 0,
      "z": -12,
      "name": "Soil_Dirt"
    },
    {
      "x": -11,
      "y": 1,
      "z": -12,
      "name": "Soil_Dirt"
    },
    {
      "x": -11,
      "y": 2,
      "z": -12,
      "name": "Soil_Dirt"
    },
    {
      "x": -11,
      "y": 3,
      "z": -12,
      "name": "Wood_Ash_Trunk_Full"
    },
    {
      "x": -11,
      "y": 4,
      "z": -12,
      "name": "Wood_Ash_Trunk",
      "support": 15
    },
    {
      "x": -11,
      "y": 5,
      "z": -12,
      "name": "Wood_Ash_Trunk",
      "support": 15
    },
    {
      "x": -11,
      "y": 6,
      "z": -12,
      "name": "Wood_Ash_Trunk",
      "support": 15
    },
    {
      "x": -11,
      "y": 7,
      "z": -12,
      "name": "Wood_Ash_Trunk",
      "support": 15
    },
    {
      "x": -11,
      "y": 8,
      "z": -12,
      "name": "Wood_Ash_Trunk",
      "support": 15
    },
    {
      "x": -11,
      "y": 9,
      "z": -12,
      "name": "Wood_Ash_Trunk",
      "support": 15
    },
    {
      "x": -11,
      "y": 10,
      "z": -12,
      "name": "Wood_Ash_Trunk_Full"
    },
    {
      "x": -11,
      "y": 0,
      "z": -11,
      "name": "Wood_Ash_Trunk",
      "support": 15
    },
    {
      "x": -11,
      "y": 1,
      "z": -11,
      "name": "Wood_Ash_Trunk",
      "support": 15
    },
    {
      "x": -11,
      "y": 2,
      "z": -11,
      "name": "Wood_Ash_Trunk",
      "support": 15
    },
    {
      "x": -11,
      "y": 3,
      "z": -11,
      "name": "Wood_Ash_Trunk",
      "support": 15
    },
    {
      "x": -11,
      "y": 4,
      "z": -11,
      "name": "Wood_Ash_Trunk",
      "support": 15
    },
    {
      "x": -11,
      "y": 5,
      "z": -11,
      "name": "Wood_Ash_Trunk",
      "support": 15
    },
    {
      "x": -11,
      "y": 6,
      "z": -11,
      "name": "Wood_Ash_Trunk",
      "support": 15
    },
    {
      "x": -11,
      "y": 7,
      "z": -11,
      "name": "Wood_Ash_Trunk",
      "support": 15
    },
    {
      "x": -11,
      "y": 8,
      "z": -11,
      "name": "Wood_Ash_Trunk",
      "support": 15
    },
    {
      "x": -11,
      "y": 9,
      "z": -11,
      "name": "Wood_Ash_Trunk_Full"
    },
    {
      "x": -11,
      "y": 0,
      "z": -10,
      "name": "Soil_Dirt"
    },
    {
      "x": -11,
      "y": 1,
      "z": -10,
      "name": "Soil_Dirt"
    },
    {
      "x": -11,
      "y": 2,
      "z": -10,
      "name": "Soil_Dirt",
      "support": 15
    },
    {
      "x": -11,
      "y": 3,
      "z": -10,
      "name": "Soil_Dirt",
      "support": 15
    },
    {
      "x": -11,
      "y": 4,
      "z": -10,
      "name": "Wood_Ash_Trunk_Full"
    },
    {
      "x": -11,
      "y": 5,
      "z": -10,
      "name": "Wood_Ash_Trunk",
      "support": 15
    },
    {
      "x": -11,
      "y": 6,
      "z": -10,
      "name": "Wood_Ash_Trunk",
      "support": 15
    },
    {
      "x": -11,
      "y": 7,
      "z": -10,
      "name": "Wood_Ash_Trunk",
      "support": 15
    },
    {
      "x": -11,
      "y": 8,
      "z": -10,
      "name": "Wood_Ash_Trunk_Full"
    },
    {
      "x": -11,
      "y": 0,
      "z": -9,
      "name": "Soil_Dirt"
    },
    {
      "x": -11,
      "y": 1,
      "z": -9,
      "name": "Soil_Dirt"
    },
    {
      "x": -11,
      "y": 2,
      "z": -9,
      "name": "Soil_Dirt",
      "support": 15
    },
    {
      "x": -11,
      "y": 3,
      "z": -9,
      "name": "Soil_Grass",
      "support": 15
    },
    {
      "x": -11,
      "y": 0,
      "z": -8,
      "name": "Soil_Dirt"
    },
    {
      "x": -11,
      "y": 1,
      "z": -8,
      "name": "Soil_Dirt"
    },
    {
      "x": -11,
      "y": 2,
      "z": -8,
      "name": "Soil_Dirt",
      "support": 15
    },
    {
      "x": -11,
      "y": 3,
      "z": -8,
      "name": "Soil_Grass",
      "support": 15
    },
    {
      "x": -11,
      "y": 0,
      "z": -7,
      "name": "Soil_Dirt"
    },
    {
      "x": -11,
      "y": 1,
      "z": -7,
      "name": "Soil_Dirt"
    },
    {
      "x": -11,
      "y": 2,
      "z": -7,
      "name": "Soil_Dirt"
    },
    {
      "x": -11,
      "y": 3,
      "z": -7,
      "name": "Soil_Grass",
      "support": 15
    },
    {
      "x": -11,
      "y": 0,
      "z": -6,
      "name": "Soil_Dirt"
    },
    {
      "x": -11,
      "y": 1,
      "z": -6,
      "name": "Soil_Dirt"
    },
    {
      "x": -11,
      "y": 2,
      "z": -6,
      "name": "Soil_Dirt"
    },
    {
      "x": -11,
      "y": 3,
      "z": -6,
      "name": "Soil_Grass",
      "support": 15
    },
    {
      "x": -11,
      "y": 0,
      "z": -5,
      "name": "Soil_Dirt"
    },
    {
      "x": -11,
      "y": 1,
      "z": -5,
      "name": "Soil_Dirt"
    },
    {
      "x": -11,
      "y": 2,
      "z": -5,
      "name": "Soil_Dirt"
    },
    {
      "x": -11,
      "y": 3,
      "z": -5,
      "name": "Soil_Grass"
    },
    {
      "x": -11,
      "y": 0,
      "z": -4,
      "name": "Soil_Dirt"
    },
    {
      "x": -11,
      "y": 1,
      "z": -4,
      "name": "Soil_Dirt"
    },
    {
      "x": -11,
      "y": 2,
      "z": -4,
      "name": "Soil_Dirt"
    },
    {
      "x": -11,
      "y": 3,
      "z": -4,
      "name": "Soil_Grass"
    },
    {
      "x": -11,
      "y": 0,
      "z": -3,
      "name": "Soil_Dirt"
    },
    {
      "x": -11,
      "y": 1,
      "z": -3,
      "name": "Soil_Dirt"
    },
    {
      "x": -11,
      "y": 2,
      "z": -3,
      "name": "Soil_Dirt"
    },
    {
      "x": -11,
      "y": 3,
      "z": -3,
      "name": "Soil_Grass"
    },
    {
      "x": -11,
      "y": 0,
      "z": -2,
      "name": "Soil_Dirt"
    },
    {
      "x": -11,
      "y": 1,
      "z": -2,
      "name": "Soil_Dirt"
    },
    {
      "x": -11,
      "y": 2,
      "z": -2,
      "name": "Soil_Dirt"
    },
    {
      "x": -11,
      "y": 3,
      "z": -2,
      "name": "Soil_Grass"
    },
    {
      "x": -11,
      "y": 0,
      "z": -1,
      "name": "Soil_Dirt"
    },
    {
      "x": -11,
      "y": 1,
      "z": -1,
      "name": "Soil_Dirt"
    },
    {
      "x": -11,
      "y": 2,
      "z": -1,
      "name": "Soil_Dirt"
    },
    {
      "x": -11,
      "y": 3,
      "z": -1,
      "name": "Soil_Grass"
    },
    {
      "x": -11,
      "y": 0,
      "z": 0,
      "name": "Soil_Dirt"
    },
    {
      "x": -11,
      "y": 1,
      "z": 0,
      "name": "Soil_Dirt"
    },
    {
      "x": -11,
      "y": 2,
      "z": 0,
      "name": "Soil_Dirt"
    },
    {
      "x": -11,
      "y": 3,
      "z": 0,
      "name": "Soil_Grass"
    },
    {
      "x": -11,
      "y": 6,
      "z": 0,
      "name": "Prefab_Spawner_Block",
      "components": {
        "Components": {
          "PrefabSpawner": {
            "PrefabPath": "Npc.Kweebec.Swamp.Guards.*",
            "FitHeightmap": false,
            "InheritSeed": true,
            "InheritHeightCondition": true
          }
        }
      }
    },
    {
      "x": -11,
      "y": 0,
      "z": 1,
      "name": "Soil_Dirt"
    },
    {
      "x": -11,
      "y": 1,
      "z": 1,
      "name": "Soil_Dirt"
    },
    {
      "x": -11,
      "y": 2,
      "z": 1,
      "name": "Soil_Dirt"
    },
    {
      "x": -11,
      "y": 3,
      "z": 1,
      "name": "Soil_Grass"
    },
    {
      "x": -11,
      "y": 0,
      "z": 2,
      "name": "Soil_Dirt"
    },
    {
      "x": -11,
      "y": 1,
      "z": 2,
      "name": "Soil_Dirt"
    },
    {
      "x": -11,
      "y": 2,
      "z": 2,
      "name": "Soil_Dirt"
    },
    {
      "x": -11,
      "y": 3,
      "z": 2,
      "name": "Soil_Grass"
    },
    {
      "x": -11,
      "y": 0,
      "z": 3,
      "name": "Soil_Dirt"
    },
    {
      "x": -11,
      "y": 1,
      "z": 3,
      "name": "Soil_Dirt"
    },
    {
      "x": -11,
      "y": 2,
      "z": 3,
      "name": "Soil_Dirt"
    },
    {
      "x": -11,
      "y": 3,
      "z": 3,
      "name": "Soil_Grass"
    },
    {
      "x": -11,
      "y": 0,
      "z": 4,
      "name": "Soil_Dirt"
    },
    {
      "x": -11,
      "y": 1,
      "z": 4,
      "name": "Soil_Dirt"
    },
    {
      "x": -11,
      "y": 2,
      "z": 4,
      "name": "Soil_Dirt"
    },
    {
      "x": -11,
      "y": 3,
      "z": 4,
      "name": "Soil_Grass"
    },
    {
      "x": -11,
      "y": 0,
      "z": 5,
      "name": "Soil_Dirt"
    },
    {
      "x": -11,
      "y": 1,
      "z": 5,
      "name": "Soil_Dirt"
    },
    {
      "x": -11,
      "y": 2,
      "z": 5,
      "name": "Soil_Dirt"
    },
    {
      "x": -11,
      "y": 3,
      "z": 5,
      "name": "Soil_Grass"
    },
    {
      "x": -11,
      "y": 0,
      "z": 6,
      "name": "Soil_Dirt"
    },
    {
      "x": -11,
      "y": 1,
      "z": 6,
      "name": "Soil_Dirt"
    },
    {
      "x": -11,
      "y": 2,
      "z": 6,
      "name": "Soil_Dirt"
    },
    {
      "x": -11,
      "y": 3,
      "z": 6,
      "name": "Soil_Grass"
    },
    {
      "x": -11,
      "y": 0,
      "z": 7,
      "name": "Soil_Dirt"
    },
    {
      "x": -11,
      "y": 1,
      "z": 7,
      "name": "Soil_Dirt"
    },
    {
      "x": -11,
      "y": 2,
      "z": 7,
      "name": "Soil_Dirt"
    },
    {
      "x": -11,
      "y": 3,
      "z": 7,
      "name": "Soil_Grass"
    },
    {
      "x": -11,
      "y": 0,
      "z": 8,
      "name": "Soil_Dirt"
    },
    {
      "x": -11,
      "y": 1,
      "z": 8,
      "name": "Soil_Dirt"
    },
    {
      "x": -11,
      "y": 2,
      "z": 8,
      "name": "Soil_Dirt"
    },
    {
      "x": -11,
      "y": 3,
      "z": 8,
      "name": "Soil_Grass"
    },
    {
      "x": -11,
      "y": 0,
      "z": 9,
      "name": "Soil_Dirt"
    },
    {
      "x": -11,
      "y": 1,
      "z": 9,
      "name": "Soil_Dirt",
      "support": 15
    },
    {
      "x": -11,
      "y": 2,
      "z": 9,
      "name": "Soil_Dirt"
    },
    {
      "x": -11,
      "y": 3,
      "z": 9,
      "name": "Soil_Grass"
    },
    {
      "x": -11,
      "y": 0,
      "z": 10,
      "name": "Soil_Dirt"
    },
    {
      "x": -11,
      "y": 1,
      "z": 10,
      "name": "Soil_Dirt"
    },
    {
      "x": -11,
      "y": 2,
      "z": 10,
      "name": "Soil_Dirt"
    },
    {
      "x": -11,
      "y": 3,
      "z": 10,
      "name": "Soil_Grass"
    },
    {
      "x": -11,
      "y": 0,
      "z": 11,
      "name": "Soil_Dirt"
    },
    {
      "x": -11,
      "y": 1,
      "z": 11,
      "name": "Soil_Dirt"
    },
    {
      "x": -11,
      "y": 2,
      "z": 11,
      "name": "Soil_Dirt",
      "support": 15
    },
    {
      "x": -11,
      "y": 3,
      "z": 11,
      "name": "Soil_Grass"
    },
    {
      "x": -11,
      "y": 0,
      "z": 12,
      "name": "Soil_Dirt",
      "support": 15
    },
    {
      "x": -11,
      "y": 1,
      "z": 12,
      "name": "Soil_Dirt",
      "support": 15
    },
    {
      "x": -11,
      "y": 2,
      "z": 12,
      "name": "Soil_Dirt",
      "support": 15
    },
    {
      "x": -11,
      "y": 3,
      "z": 12,
      "name": "Soil_Grass",
      "support": 15
    },
    {
      "x": -11,
      "y": 0,
      "z": 13,
      "name": "Soil_Dirt",
      "support": 15
    },
    {
      "x": -11,
      "y": 1,
      "z": 13,
      "name": "Soil_Dirt",
      "support": 15
    },
    {
      "x": -11,
      "y": 2,
      "z": 13,
      "name": "Soil_Dirt",
      "support": 15
    },
    {
      "x": -11,
      "y": 3,
      "z": 13,
      "name": "Soil_Grass",
      "support": 15
    },
    {
      "x": -11,
      "y": 0,
      "z": 14,
      "name": "Soil_Dirt",
      "support": 15
    },
    {
      "x": -11,
      "y": 1,
      "z": 14,
      "name": "Soil_Dirt",
      "support": 15
    },
    {
      "x": -11,
      "y": 2,
      "z": 14,
      "name": "Soil_Dirt",
      "support": 15
    },
    {
      "x": -11,
      "y": 3,
      "z": 14,
      "name": "Soil_Grass",
      "support": 15
    },
    {
      "x": -11,
      "y": 0,
      "z": 15,
      "name": "Soil_Dirt"
    },
    {
      "x": -11,
      "y": 1,
      "z": 15,
      "name": "Soil_Dirt"
    },
    {
      "x": -11,
      "y": 2,
      "z": 15,
      "name": "Soil_Dirt"
    },
    {
      "x": -11,
      "y": 3,
      "z": 15,
      "name": "Soil_Grass"
    },
    {
      "x": -11,
      "y": 0,
      "z": 16,
      "name": "Soil_Dirt"
    },
    {
      "x": -11,
      "y": 1,
      "z": 16,
      "name": "Soil_Dirt"
    },
    {
      "x": -11,
      "y": 2,
      "z": 16,
      "name": "Soil_Dirt"
    },
    {
      "x": -11,
      "y": 3,
      "z": 16,
      "name": "Soil_Grass"
    },
    {
      "x": -10,
      "y": 0,
      "z": -15,
      "name": "Soil_Dirt"
    },
    {
      "x": -10,
      "y": 1,
      "z": -15,
      "name": "Soil_Dirt"
    },
    {
      "x": -10,
      "y": 2,
      "z": -15,
      "name": "Soil_Dirt"
    },
    {
      "x": -10,
      "y": 3,
      "z": -15,
      "name": "Soil_Grass"
    },
    {
      "x": -10,
      "y": 6,
      "z": -15,
      "name": "Wood_Ash_Trunk_Full"
    },
    {
      "x": -10,
      "y": 7,
      "z": -15,
      "name": "Wood_Ash_Trunk",
      "support": 15
    },
    {
      "x": -10,
      "y": 8,
      "z": -15,
      "name": "Wood_Ash_Trunk_Full"
    },
    {
      "x": -10,
      "y": 0,
      "z": -14,
      "name": "Soil_Dirt"
    },
    {
      "x": -10,
      "y": 1,
      "z": -14,
      "name": "Soil_Dirt"
    },
    {
      "x": -10,
      "y": 2,
      "z": -14,
      "name": "Soil_Dirt"
    },
    {
      "x": -10,
      "y": 3,
      "z": -14,
      "name": "Soil_Grass"
    },
    {
      "x": -10,
      "y": 7,
      "z": -14,
      "name": "Wood_Ash_Trunk_Full"
    },
    {
      "x": -10,
      "y": 8,
      "z": -14,
      "name": "Wood_Ash_Trunk",
      "support": 15
    },
    {
      "x": -10,
      "y": 9,
      "z": -14,
      "name": "Wood_Ash_Trunk",
      "support": 15
    },
    {
      "x": -10,
      "y": 10,
      "z": -14,
      "name": "Wood_Ash_Trunk",
      "support": 15
    },
    {
      "x": -10,
      "y": 11,
      "z": -14,
      "name": "Wood_Ash_Trunk_Full"
    },
    {
      "x": -10,
      "y": 0,
      "z": -13,
      "name": "Soil_Dirt"
    },
    {
      "x": -10,
      "y": 1,
      "z": -13,
      "name": "Soil_Dirt"
    },
    {
      "x": -10,
      "y": 2,
      "z": -13,
      "name": "Soil_Dirt"
    },
    {
      "x": -10,
      "y": 3,
      "z": -13,
      "name": "Soil_Grass"
    },
    {
      "x": -10,
      "y": 7,
      "z": -13,
      "name": "Wood_Ash_Trunk_Full"
    },
    {
      "x": -10,
      "y": 8,
      "z": -13,
      "name": "Wood_Ash_Trunk",
      "support": 15
    },
    {
      "x": -10,
      "y": 9,
      "z": -13,
      "name": "Wood_Ash_Trunk",
      "support": 15
    },
    {
      "x": -10,
      "y": 10,
      "z": -13,
      "name": "Wood_Ash_Trunk",
      "support": 15
    },
    {
      "x": -10,
      "y": 11,
      "z": -13,
      "name": "Wood_Ash_Trunk",
      "support": 15
    },
    {
      "x": -10,
      "y": 12,
      "z": -13,
      "name": "Wood_Ash_Trunk_Full"
    },
    {
      "x": -10,
      "y": 0,
      "z": -12,
      "name": "Soil_Dirt",
      "support": 15
    },
    {
      "x": -10,
      "y": 1,
      "z": -12,
      "name": "Soil_Dirt",
      "support": 15
    },
    {
      "x": -10,
      "y": 2,
      "z": -12,
      "name": "Soil_Dirt",
      "support": 15
    },
    {
      "x": -10,
      "y": 3,
      "z": -12,
      "name": "Soil_Grass"
    },
    {
      "x": -10,
      "y": 4,
      "z": -12,
      "name": "Wood_Ash_Roots"
    },
    {
      "x": -10,
      "y": 5,
      "z": -12,
      "name": "Wood_Ash_Trunk_Full"
    },
    {
      "x": -10,
      "y": 6,
      "z": -12,
      "name": "Wood_Ash_Trunk",
      "support": 15
    },
    {
      "x": -10,
      "y": 7,
      "z": -12,
      "name": "Wood_Ash_Trunk",
      "support": 15
    },
    {
      "x": -10,
      "y": 8,
      "z": -12,
      "name": "Wood_Ash_Trunk",
      "support": 15
    },
    {
      "x": -10,
      "y": 9,
      "z": -12,
      "name": "Wood_Ash_Trunk",
      "support": 15
    },
    {
      "x": -10,
      "y": 10,
      "z": -12,
      "name": "Wood_Ash_Trunk",
      "support": 15
    },
    {
      "x": -10,
      "y": 11,
      "z": -12,
      "name": "Wood_Ash_Trunk",
      "support": 15
    },
    {
      "x": -10,
      "y": 12,
      "z": -12,
      "name": "Wood_Ash_Trunk",
      "support": 15
    },
    {
      "x": -10,
      "y": 13,
      "z": -12,
      "name": "Wood_Ash_Trunk_Full"
    },
    {
      "x": -10,
      "y": 0,
      "z": -11,
      "name": "Soil_Dirt"
    },
    {
      "x": -10,
      "y": 1,
      "z": -11,
      "name": "Wood_Ash_Trunk_Full"
    },
    {
      "x": -10,
      "y": 2,
      "z": -11,
      "name": "Wood_Ash_Trunk",
      "support": 15
    },
    {
      "x": -10,
      "y": 3,
      "z": -11,
      "name": "Wood_Ash_Trunk",
      "support": 15
    },
    {
      "x": -10,
      "y": 4,
      "z": -11,
      "name": "Wood_Ash_Trunk",
      "support": 15
    },
    {
      "x": -10,
      "y": 5,
      "z": -11,
      "name": "Wood_Ash_Trunk",
      "support": 15
    },
    {
      "x": -10,
      "y": 6,
      "z": -11,
      "name": "Wood_Ash_Trunk",
      "support": 15
    },
    {
      "x": -10,
      "y": 7,
      "z": -11,
      "name": "Wood_Ash_Trunk",
      "support": 15
    },
    {
      "x": -10,
      "y": 8,
      "z": -11,
      "name": "Wood_Ash_Trunk",
      "support": 15
    },
    {
      "x": -10,
      "y": 9,
      "z": -11,
      "name": "Wood_Ash_Trunk",
      "support": 15
    },
    {
      "x": -10,
      "y": 10,
      "z": -11,
      "name": "Wood_Ash_Trunk",
      "support": 15
    },
    {
      "x": -10,
      "y": 11,
      "z": -11,
      "name": "Wood_Ash_Trunk",
      "support": 15
    },
    {
      "x": -10,
      "y": 12,
      "z": -11,
      "name": "Wood_Ash_Trunk",
      "support": 15
    },
    {
      "x": -10,
      "y": 13,
      "z": -11,
      "name": "Wood_Ash_Trunk_Full"
    },
    {
      "x": -10,
      "y": 0,
      "z": -10,
      "name": "Soil_Dirt"
    },
    {
      "x": -10,
      "y": 1,
      "z": -10,
      "name": "Soil_Dirt"
    },
    {
      "x": -10,
      "y": 2,
      "z": -10,
      "name": "Soil_Dirt",
      "support": 15
    },
    {
      "x": -10,
      "y": 3,
      "z": -10,
      "name": "Soil_Grass",
      "support": 15
    },
    {
      "x": -10,
      "y": 6,
      "z": -10,
      "name": "Wood_Ash_Trunk_Full"
    },
    {
      "x": -10,
      "y": 7,
      "z": -10,
      "name": "Wood_Ash_Trunk",
      "support": 15
    },
    {
      "x": -10,
      "y": 8,
      "z": -10,
      "name": "Wood_Ash_Trunk",
      "support": 15
    },
    {
      "x": -10,
      "y": 9,
      "z": -10,
      "name": "Wood_Ash_Trunk",
      "support": 15
    },
    {
      "x": -10,
      "y": 10,
      "z": -10,
      "name": "Wood_Ash_Trunk_Full"
    },
    {
      "x": -10,
      "y": 0,
      "z": -9,
      "name": "Soil_Dirt"
    },
    {
      "x": -10,
      "y": 1,
      "z": -9,
      "name": "Soil_Dirt"
    },
    {
      "x": -10,
      "y": 2,
      "z": -9,
      "name": "Soil_Dirt",
      "support": 15
    },
    {
      "x": -10,
      "y": 3,
      "z": -9,
      "name": "Soil_Grass",
      "support": 15
    },
    {
      "x": -10,
      "y": 0,
      "z": -8,
      "name": "Soil_Dirt"
    },
    {
      "x": -10,
      "y": 1,
      "z": -8,
      "name": "Soil_Dirt"
    },
    {
      "x": -10,
      "y": 2,
      "z": -8,
      "name": "Soil_Dirt",
      "support": 15
    },
    {
      "x": -10,
      "y": 3,
      "z": -8,
      "name": "Soil_Grass",
      "support": 15
    },
    {
      "x": -10,
      "y": 0,
      "z": -7,
      "name": "Soil_Dirt"
    },
    {
      "x": -10,
      "y": 1,
      "z": -7,
      "name": "Soil_Dirt"
    },
    {
      "x": -10,
      "y": 2,
      "z": -7,
      "name": "Soil_Dirt"
    },
    {
      "x": -10,
      "y": 3,
      "z": -7,
      "name": "Soil_Grass"
    },
    {
      "x": -10,
      "y": 0,
      "z": -6,
      "name": "Soil_Dirt"
    },
    {
      "x": -10,
      "y": 1,
      "z": -6,
      "name": "Soil_Dirt"
    },
    {
      "x": -10,
      "y": 2,
      "z": -6,
      "name": "Soil_Dirt"
    },
    {
      "x": -10,
      "y": 3,
      "z": -6,
      "name": "Soil_Grass"
    },
    {
      "x": -10,
      "y": 0,
      "z": -5,
      "name": "Soil_Dirt"
    },
    {
      "x": -10,
      "y": 1,
      "z": -5,
      "name": "Soil_Dirt"
    },
    {
      "x": -10,
      "y": 2,
      "z": -5,
      "name": "Soil_Dirt"
    },
    {
      "x": -10,
      "y": 3,
      "z": -5,
      "name": "Soil_Grass"
    },
    {
      "x": -10,
      "y": 0,
      "z": -4,
      "name": "Soil_Dirt"
    },
    {
      "x": -10,
      "y": 1,
      "z": -4,
      "name": "Soil_Dirt"
    },
    {
      "x": -10,
      "y": 2,
      "z": -4,
      "name": "Soil_Dirt"
    },
    {
      "x": -10,
      "y": 3,
      "z": -4,
      "name": "Soil_Grass"
    },
    {
      "x": -10,
      "y": 0,
      "z": -3,
      "name": "Soil_Dirt"
    },
    {
      "x": -10,
      "y": 1,
      "z": -3,
      "name": "Soil_Dirt"
    },
    {
      "x": -10,
      "y": 2,
      "z": -3,
      "name": "Soil_Dirt"
    },
    {
      "x": -10,
      "y": 3,
      "z": -3,
      "name": "Soil_Grass"
    },
    {
      "x": -10,
      "y": 0,
      "z": -2,
      "name": "Soil_Dirt"
    },
    {
      "x": -10,
      "y": 1,
      "z": -2,
      "name": "Soil_Dirt"
    },
    {
      "x": -10,
      "y": 2,
      "z": -2,
      "name": "Soil_Dirt"
    },
    {
      "x": -10,
      "y": 3,
      "z": -2,
      "name": "Soil_Grass"
    },
    {
      "x": -10,
      "y": 0,
      "z": -1,
      "name": "Soil_Dirt"
    },
    {
      "x": -10,
      "y": 1,
      "z": -1,
      "name": "Soil_Dirt"
    },
    {
      "x": -10,
      "y": 2,
      "z": -1,
      "name": "Soil_Dirt"
    },
    {
      "x": -10,
      "y": 3,
      "z": -1,
      "name": "Soil_Grass"
    },
    {
      "x": -10,
      "y": 0,
      "z": 0,
      "name": "Soil_Dirt"
    },
    {
      "x": -10,
      "y": 1,
      "z": 0,
      "name": "Soil_Dirt"
    },
    {
      "x": -10,
      "y": 2,
      "z": 0,
      "name": "Soil_Dirt"
    },
    {
      "x": -10,
      "y": 3,
      "z": 0,
      "name": "Soil_Grass"
    },
    {
      "x": -10,
      "y": 0,
      "z": 1,
      "name": "Soil_Dirt"
    },
    {
      "x": -10,
      "y": 1,
      "z": 1,
      "name": "Soil_Dirt"
    },
    {
      "x": -10,
      "y": 2,
      "z": 1,
      "name": "Soil_Dirt"
    },
    {
      "x": -10,
      "y": 3,
      "z": 1,
      "name": "Soil_Grass"
    },
    {
      "x": -10,
      "y": 0,
      "z": 2,
      "name": "Soil_Dirt"
    },
    {
      "x": -10,
      "y": 1,
      "z": 2,
      "name": "Soil_Dirt"
    },
    {
      "x": -10,
      "y": 2,
      "z": 2,
      "name": "Soil_Dirt"
    },
    {
      "x": -10,
      "y": 3,
      "z": 2,
      "name": "Soil_Grass"
    },
    {
      "x": -10,
      "y": 0,
      "z": 3,
      "name": "Soil_Dirt"
    },
    {
      "x": -10,
      "y": 1,
      "z": 3,
      "name": "Soil_Dirt"
    },
    {
      "x": -10,
      "y": 2,
      "z": 3,
      "name": "Soil_Dirt"
    },
    {
      "x": -10,
      "y": 3,
      "z": 3,
      "name": "Soil_Grass"
    },
    {
      "x": -10,
      "y": 0,
      "z": 4,
      "name": "Soil_Dirt"
    },
    {
      "x": -10,
      "y": 1,
      "z": 4,
      "name": "Soil_Dirt"
    },
    {
      "x": -10,
      "y": 2,
      "z": 4,
      "name": "Soil_Dirt"
    },
    {
      "x": -10,
      "y": 3,
      "z": 4,
      "name": "Soil_Grass"
    },
    {
      "x": -10,
      "y": 0,
      "z": 5,
      "name": "Soil_Dirt"
    },
    {
      "x": -10,
      "y": 1,
      "z": 5,
      "name": "Soil_Dirt"
    },
    {
      "x": -10,
      "y": 2,
      "z": 5,
      "name": "Soil_Dirt"
    },
    {
      "x": -10,
      "y": 3,
      "z": 5,
      "name": "Soil_Grass"
    },
    {
      "x": -10,
      "y": 0,
      "z": 6,
      "name": "Soil_Dirt"
    },
    {
      "x": -10,
      "y": 1,
      "z": 6,
      "name": "Soil_Dirt"
    },
    {
      "x": -10,
      "y": 2,
      "z": 6,
      "name": "Soil_Dirt"
    },
    {
      "x": -10,
      "y": 3,
      "z": 6,
      "name": "Soil_Grass"
    },
    {
      "x": -10,
      "y": 0,
      "z": 7,
      "name": "Soil_Dirt"
    },
    {
      "x": -10,
      "y": 1,
      "z": 7,
      "name": "Soil_Dirt"
    },
    {
      "x": -10,
      "y": 2,
      "z": 7,
      "name": "Soil_Dirt"
    },
    {
      "x": -10,
      "y": 3,
      "z": 7,
      "name": "Soil_Grass"
    },
    {
      "x": -10,
      "y": 0,
      "z": 8,
      "name": "Soil_Dirt",
      "support": 15
    },
    {
      "x": -10,
      "y": 1,
      "z": 8,
      "name": "Soil_Dirt",
      "support": 15
    },
    {
      "x": -10,
      "y": 2,
      "z": 8,
      "name": "Soil_Dirt"
    },
    {
      "x": -10,
      "y": 3,
      "z": 8,
      "name": "Soil_Grass"
    },
    {
      "x": -10,
      "y": 0,
      "z": 9,
      "name": "Soil_Dirt"
    },
    {
      "x": -10,
      "y": 1,
      "z": 9,
      "name": "Soil_Dirt",
      "support": 15
    },
    {
      "x": -10,
      "y": 2,
      "z": 9,
      "name": "Soil_Dirt"
    },
    {
      "x": -10,
      "y": 3,
      "z": 9,
      "name": "Soil_Grass"
    },
    {
      "x": -10,
      "y": 0,
      "z": 10,
      "name": "Wood_Ash_Trunk_Full"
    },
    {
      "x": -10,
      "y": 1,
      "z": 10,
      "name": "Soil_Dirt"
    },
    {
      "x": -10,
      "y": 2,
      "z": 10,
      "name": "Soil_Dirt"
    },
    {
      "x": -10,
      "y": 3,
      "z": 10,
      "name": "Soil_Grass"
    },
    {
      "x": -10,
      "y": 0,
      "z": 11,
      "name": "Wood_Ash_Trunk_Full"
    },
    {
      "x": -10,
      "y": 1,
      "z": 11,
      "name": "Wood_Ash_Trunk_Full"
    },
    {
      "x": -10,
      "y": 2,
      "z": 11,
      "name": "Soil_Dirt",
      "support": 15
    },
    {
      "x": -10,
      "y": 3,
      "z": 11,
      "name": "Soil_Grass"
    },
    {
      "x": -10,
      "y": 0,
      "z": 12,
      "name": "Wood_Ash_Trunk_Full"
    },
    {
      "x": -10,
      "y": 1,
      "z": 12,
      "name": "Wood_Ash_Trunk",
      "support": 15
    },
    {
      "x": -10,
      "y": 2,
      "z": 12,
      "name": "Wood_Ash_Trunk_Full"
    },
    {
      "x": -10,
      "y": 3,
      "z": 12,
      "name": "Soil_Grass",
      "support": 15
    },
    {
      "x": -10,
      "y": 0,
      "z": 13,
      "name": "Wood_Ash_Trunk",
      "support": 15
    },
    {
      "x": -10,
      "y": 1,
      "z": 13,
      "name": "Wood_Ash_Trunk_Full"
    },
    {
      "x": -10,
      "y": 2,
      "z": 13,
      "name": "Soil_Dirt"
    },
    {
      "x": -10,
      "y": 3,
      "z": 13,
      "name": "Soil_Grass"
    },
    {
      "x": -10,
      "y": 0,
      "z": 14,
      "name": "Wood_Ash_Trunk_Full"
    },
    {
      "x": -10,
      "y": 1,
      "z": 14,
      "name": "Soil_Dirt"
    },
    {
      "x": -10,
      "y": 2,
      "z": 14,
      "name": "Soil_Dirt"
    },
    {
      "x": -10,
      "y": 3,
      "z": 14,
      "name": "Soil_Grass"
    },
    {
      "x": -10,
      "y": 0,
      "z": 15,
      "name": "Soil_Dirt"
    },
    {
      "x": -10,
      "y": 1,
      "z": 15,
      "name": "Soil_Dirt"
    },
    {
      "x": -10,
      "y": 2,
      "z": 15,
      "name": "Soil_Dirt"
    },
    {
      "x": -10,
      "y": 3,
      "z": 15,
      "name": "Soil_Grass"
    },
    {
      "x": -10,
      "y": 0,
      "z": 16,
      "name": "Soil_Dirt"
    },
    {
      "x": -10,
      "y": 1,
      "z": 16,
      "name": "Soil_Dirt"
    },
    {
      "x": -10,
      "y": 2,
      "z": 16,
      "name": "Soil_Dirt"
    },
    {
      "x": -10,
      "y": 3,
      "z": 16,
      "name": "Soil_Grass"
    },
    {
      "x": -9,
      "y": 0,
      "z": -15,
      "name": "Soil_Dirt"
    },
    {
      "x": -9,
      "y": 1,
      "z": -15,
      "name": "Soil_Dirt"
    },
    {
      "x": -9,
      "y": 2,
      "z": -15,
      "name": "Soil_Dirt"
    },
    {
      "x": -9,
      "y": 3,
      "z": -15,
      "name": "Soil_Grass"
    },
    {
      "x": -9,
      "y": 5,
      "z": -15,
      "name": "Wood_Ash_Trunk_Full"
    },
    {
      "x": -9,
      "y": 6,
      "z": -15,
      "name": "Wood_Ash_Trunk",
      "support": 15
    },
    {
      "x": -9,
      "y": 7,
      "z": -15,
      "name": "Wood_Ash_Trunk",
      "support": 15
    },
    {
      "x": -9,
      "y": 8,
      "z": -15,
      "name": "Wood_Ash_Trunk",
      "support": 15
    },
    {
      "x": -9,
      "y": 9,
      "z": -15,
      "name": "Wood_Ash_Trunk_Full"
    },
    {
      "x": -9,
      "y": 0,
      "z": -14,
      "name": "Soil_Dirt"
    },
    {
      "x": -9,
      "y": 1,
      "z": -14,
      "name": "Soil_Dirt"
    },
    {
      "x": -9,
      "y": 2,
      "z": -14,
      "name": "Soil_Dirt"
    },
    {
      "x": -9,
      "y": 3,
      "z": -14,
      "name": "Soil_Grass"
    },
    {
      "x": -9,
      "y": 5,
      "z": -14,
      "name": "Wood_Ash_Roots"
    },
    {
      "x": -9,
      "y": 6,
      "z": -14,
      "name": "Wood_Ash_Trunk_Full"
    },
    {
      "x": -9,
      "y": 7,
      "z": -14,
      "name": "Wood_Ash_Trunk",
      "support": 15
    },
    {
      "x": -9,
      "y": 8,
      "z": -14,
      "name": "Wood_Ash_Trunk",
      "support": 15
    },
    {
      "x": -9,
      "y": 9,
      "z": -14,
      "name": "Wood_Ash_Trunk",
      "support": 15
    },
    {
      "x": -9,
      "y": 10,
      "z": -14,
      "name": "Wood_Ash_Trunk",
      "support": 15
    },
    {
      "x": -9,
      "y": 11,
      "z": -14,
      "name": "Wood_Ash_Trunk",
      "support": 15
    },
    {
      "x": -9,
      "y": 12,
      "z": -14,
      "name": "Wood_Ash_Trunk_Full"
    },
    {
      "x": -9,
      "y": 0,
      "z": -13,
      "name": "Soil_Dirt",
      "support": 15
    },
    {
      "x": -9,
      "y": 1,
      "z": -13,
      "name": "Soil_Dirt"
    },
    {
      "x": -9,
      "y": 2,
      "z": -13,
      "name": "Soil_Dirt"
    },
    {
      "x": -9,
      "y": 3,
      "z": -13,
      "name": "Soil_Grass"
    },
    {
      "x": -9,
      "y": 6,
      "z": -13,
      "name": "Wood_Ash_Trunk_Full"
    },
    {
      "x": -9,
      "y": 7,
      "z": -13,
      "name": "Wood_Ash_Trunk",
      "support": 15
    },
    {
      "x": -9,
      "y": 8,
      "z": -13,
      "name": "Wood_Ash_Trunk",
      "support": 15
    },
    {
      "x": -9,
      "y": 9,
      "z": -13,
      "name": "Wood_Ash_Trunk",
      "support": 15
    },
    {
      "x": -9,
      "y": 10,
      "z": -13,
      "name": "Wood_Ash_Trunk",
      "support": 15
    },
    {
      "x": -9,
      "y": 11,
      "z": -13,
      "name": "Wood_Ash_Trunk",
      "support": 15
    },
    {
      "x": -9,
      "y": 12,
      "z": -13,
      "name": "Wood_Ash_Trunk",
      "support": 15
    },
    {
      "x": -9,
      "y": 13,
      "z": -13,
      "name": "Wood_Ash_Trunk",
      "support": 15
    },
    {
      "x": -9,
      "y": 14,
      "z": -13,
      "name": "Wood_Ash_Trunk_Full"
    },
    {
      "x": -9,
      "y": 0,
      "z": -12,
      "name": "Soil_Dirt"
    },
    {
      "x": -9,
      "y": 1,
      "z": -12,
      "name": "Soil_Dirt",
      "support": 15
    },
    {
      "x": -9,
      "y": 2,
      "z": -12,
      "name": "Soil_Dirt",
      "support": 15
    },
    {
      "x": -9,
      "y": 3,
      "z": -12,
      "name": "Soil_Grass"
    },
    {
      "x": -9,
      "y": 5,
      "z": -12,
      "name": "Wood_Ash_Trunk_Full",
      "rotation": 5
    },
    {
      "x": -9,
      "y": 6,
      "z": -12,
      "name": "Wood_Ash_Trunk",
      "support": 15
    },
    {
      "x": -9,
      "y": 7,
      "z": -12,
      "name": "Wood_Ash_Trunk",
      "support": 15
    },
    {
      "x": -9,
      "y": 8,
      "z": -12,
      "name": "Wood_Ash_Trunk",
      "support": 15
    },
    {
      "x": -9,
      "y": 9,
      "z": -12,
      "name": "Wood_Ash_Trunk",
      "support": 15
    },
    {
      "x": -9,
      "y": 10,
      "z": -12,
      "name": "Wood_Ash_Trunk",
      "support": 15
    },
    {
      "x": -9,
      "y": 11,
      "z": -12,
      "name": "Wood_Ash_Trunk",
      "support": 15
    },
    {
      "x": -9,
      "y": 12,
      "z": -12,
      "name": "Wood_Ash_Trunk",
      "support": 15
    },
    {
      "x": -9,
      "y": 13,
      "z": -12,
      "name": "Wood_Ash_Trunk",
      "support": 15
    },
    {
      "x": -9,
      "y": 14,
      "z": -12,
      "name": "Wood_Ash_Trunk_Full"
    },
    {
      "x": -9,
      "y": 0,
      "z": -11,
      "name": "Soil_Dirt"
    },
    {
      "x": -9,
      "y": 1,
      "z": -11,
      "name": "Soil_Dirt"
    },
    {
      "x": -9,
      "y": 2,
      "z": -11,
      "name": "Soil_Dirt",
      "support": 15
    },
    {
      "x": -9,
      "y": 3,
      "z": -11,
      "name": "Wood_Ash_Trunk_Full"
    },
    {
      "x": -9,
      "y": 4,
      "z": -11,
      "name": "Wood_Ash_Trunk",
      "support": 15
    },
    {
      "x": -9,
      "y": 5,
      "z": -11,
      "name": "Wood_Ash_Trunk",
      "support": 15
    },
    {
      "x": -9,
      "y": 6,
      "z": -11,
      "name": "Wood_Ash_Trunk",
      "support": 15
    },
    {
      "x": -9,
      "y": 7,
      "z": -11,
      "name": "Wood_Ash_Trunk",
      "support": 15
    },
    {
      "x": -9,
      "y": 8,
      "z": -11,
      "name": "Wood_Ash_Trunk",
      "support": 15
    },
    {
      "x": -9,
      "y": 9,
      "z": -11,
      "name": "Wood_Ash_Trunk",
      "support": 15
    },
    {
      "x": -9,
      "y": 10,
      "z": -11,
      "name": "Wood_Ash_Trunk",
      "support": 15
    },
    {
      "x": -9,
      "y": 11,
      "z": -11,
      "name": "Wood_Ash_Trunk",
      "support": 15
    },
    {
      "x": -9,
      "y": 12,
      "z": -11,
      "name": "Wood_Ash_Trunk",
      "support": 15
    },
    {
      "x": -9,
      "y": 13,
      "z": -11,
      "name": "Wood_Ash_Trunk",
      "support": 15
    },
    {
      "x": -9,
      "y": 14,
      "z": -11,
      "name": "Wood_Ash_Trunk_Full"
    },
    {
      "x": -9,
      "y": 0,
      "z": -10,
      "name": "Soil_Dirt"
    },
    {
      "x": -9,
      "y": 1,
      "z": -10,
      "name": "Soil_Dirt"
    },
    {
      "x": -9,
      "y": 2,
      "z": -10,
      "name": "Soil_Dirt"
    },
    {
      "x": -9,
      "y": 3,
      "z": -10,
      "name": "Soil_Grass"
    },
    {
      "x": -9,
      "y": 7,
      "z": -10,
      "name": "Wood_Ash_Trunk_Full"
    },
    {
      "x": -9,
      "y": 8,
      "z": -10,
      "name": "Wood_Ash_Trunk",
      "support": 15
    },
    {
      "x": -9,
      "y": 9,
      "z": -10,
      "name": "Wood_Ash_Trunk",
      "support": 15
    },
    {
      "x": -9,
      "y": 10,
      "z": -10,
      "name": "Wood_Ash_Trunk",
      "support": 15
    },
    {
      "x": -9,
      "y": 11,
      "z": -10,
      "name": "Wood_Ash_Trunk",
      "support": 15
    },
    {
      "x": -9,
      "y": 12,
      "z": -10,
      "name": "Wood_Ash_Trunk_Full"
    },
    {
      "x": -9,
      "y": 15,
      "z": -10,
      "name": "Plant_Moss_Wall_Green_Dark",
      "rotation": 3
    },
    {
      "x": -9,
      "y": 0,
      "z": -9,
      "name": "Soil_Dirt"
    },
    {
      "x": -9,
      "y": 1,
      "z": -9,
      "name": "Soil_Dirt"
    },
    {
      "x": -9,
      "y": 2,
      "z": -9,
      "name": "Soil_Dirt"
    },
    {
      "x": -9,
      "y": 3,
      "z": -9,
      "name": "Soil_Grass"
    },
    {
      "x": -9,
      "y": 0,
      "z": -8,
      "name": "Soil_Dirt"
    },
    {
      "x": -9,
      "y": 1,
      "z": -8,
      "name": "Soil_Dirt"
    },
    {
      "x": -9,
      "y": 2,
      "z": -8,
      "name": "Soil_Dirt"
    },
    {
      "x": -9,
      "y": 3,
      "z": -8,
      "name": "Soil_Grass"
    },
    {
      "x": -9,
      "y": 0,
      "z": -7,
      "name": "Soil_Dirt"
    },
    {
      "x": -9,
      "y": 1,
      "z": -7,
      "name": "Soil_Dirt"
    },
    {
      "x": -9,
      "y": 2,
      "z": -7,
      "name": "Soil_Dirt"
    },
    {
      "x": -9,
      "y": 3,
      "z": -7,
      "name": "Soil_Grass"
    },
    {
      "x": -9,
      "y": 0,
      "z": -6,
      "name": "Soil_Dirt"
    },
    {
      "x": -9,
      "y": 1,
      "z": -6,
      "name": "Soil_Dirt"
    },
    {
      "x": -9,
      "y": 2,
      "z": -6,
      "name": "Soil_Dirt"
    },
    {
      "x": -9,
      "y": 3,
      "z": -6,
      "name": "Soil_Grass"
    },
    {
      "x": -9,
      "y": 0,
      "z": -5,
      "name": "Soil_Dirt"
    },
    {
      "x": -9,
      "y": 1,
      "z": -5,
      "name": "Soil_Dirt"
    },
    {
      "x": -9,
      "y": 2,
      "z": -5,
      "name": "Soil_Dirt"
    },
    {
      "x": -9,
      "y": 3,
      "z": -5,
      "name": "Soil_Grass"
    },
    {
      "x": -9,
      "y": 0,
      "z": -4,
      "name": "Soil_Dirt"
    },
    {
      "x": -9,
      "y": 1,
      "z": -4,
      "name": "Soil_Dirt"
    },
    {
      "x": -9,
      "y": 2,
      "z": -4,
      "name": "Soil_Dirt"
    },
    {
      "x": -9,
      "y": 3,
      "z": -4,
      "name": "Soil_Grass"
    },
    {
      "x": -9,
      "y": 6,
      "z": -4,
      "name": "Wood_Ash_Roots"
    },
    {
      "x": -9,
      "y": 7,
      "z": -4,
      "name": "Wood_Ash_Trunk",
      "support": 15
    },
    {
      "x": -9,
      "y": 8,
      "z": -4,
      "name": "Wood_Ash_Trunk",
      "support": 15
    },
    {
      "x": -9,
      "y": 9,
      "z": -4,
      "name": "Wood_Ash_Trunk",
      "support": 15
    },
    {
      "x": -9,
      "y": 10,
      "z": -4,
      "name": "Wood_Ash_Trunk_Full"
    },
    {
      "x": -9,
      "y": 0,
      "z": -3,
      "name": "Soil_Dirt"
    },
    {
      "x": -9,
      "y": 1,
      "z": -3,
      "name": "Soil_Dirt"
    },
    {
      "x": -9,
      "y": 2,
      "z": -3,
      "name": "Soil_Dirt"
    },
    {
      "x": -9,
      "y": 3,
      "z": -3,
      "name": "Soil_Grass"
    },
    {
      "x": -9,
      "y": 0,
      "z": -2,
      "name": "Soil_Dirt"
    },
    {
      "x": -9,
      "y": 1,
      "z": -2,
      "name": "Soil_Dirt"
    },
    {
      "x": -9,
      "y": 2,
      "z": -2,
      "name": "Soil_Dirt"
    },
    {
      "x": -9,
      "y": 3,
      "z": -2,
      "name": "Soil_Grass"
    },
    {
      "x": -9,
      "y": 0,
      "z": -1,
      "name": "Soil_Dirt"
    },
    {
      "x": -9,
      "y": 1,
      "z": -1,
      "name": "Soil_Dirt"
    },
    {
      "x": -9,
      "y": 2,
      "z": -1,
      "name": "Soil_Dirt"
    },
    {
      "x": -9,
      "y": 3,
      "z": -1,
      "name": "Soil_Grass",
      "support": 15
    },
    {
      "x": -9,
      "y": 0,
      "z": 0,
      "name": "Soil_Dirt",
      "support": 15
    },
    {
      "x": -9,
      "y": 1,
      "z": 0,
      "name": "Soil_Dirt",
      "support": 15
    },
    {
      "x": -9,
      "y": 2,
      "z": 0,
      "name": "Soil_Dirt"
    },
    {
      "x": -9,
      "y": 3,
      "z": 0,
      "name": "Soil_Grass"
    },
    {
      "x": -9,
      "y": 0,
      "z": 1,
      "name": "Soil_Dirt"
    },
    {
      "x": -9,
      "y": 1,
      "z": 1,
      "name": "Soil_Dirt"
    },
    {
      "x": -9,
      "y": 2,
      "z": 1,
      "name": "Soil_Dirt"
    },
    {
      "x": -9,
      "y": 3,
      "z": 1,
      "name": "Soil_Grass"
    },
    {
      "x": -9,
      "y": 0,
      "z": 2,
      "name": "Soil_Dirt"
    },
    {
      "x": -9,
      "y": 1,
      "z": 2,
      "name": "Soil_Dirt"
    },
    {
      "x": -9,
      "y": 2,
      "z": 2,
      "name": "Soil_Dirt"
    },
    {
      "x": -9,
      "y": 3,
      "z": 2,
      "name": "Soil_Grass"
    },
    {
      "x": -9,
      "y": 0,
      "z": 3,
      "name": "Soil_Dirt"
    },
    {
      "x": -9,
      "y": 1,
      "z": 3,
      "name": "Soil_Dirt"
    },
    {
      "x": -9,
      "y": 2,
      "z": 3,
      "name": "Soil_Dirt"
    },
    {
      "x": -9,
      "y": 3,
      "z": 3,
      "name": "Soil_Grass"
    },
    {
      "x": -9,
      "y": 0,
      "z": 4,
      "name": "Soil_Dirt"
    },
    {
      "x": -9,
      "y": 1,
      "z": 4,
      "name": "Soil_Dirt"
    },
    {
      "x": -9,
      "y": 2,
      "z": 4,
      "name": "Soil_Dirt"
    },
    {
      "x": -9,
      "y": 3,
      "z": 4,
      "name": "Soil_Grass"
    },
    {
      "x": -9,
      "y": 0,
      "z": 5,
      "name": "Wood_Ash_Trunk_Full"
    },
    {
      "x": -9,
      "y": 1,
      "z": 5,
      "name": "Soil_Dirt"
    },
    {
      "x": -9,
      "y": 2,
      "z": 5,
      "name": "Soil_Dirt"
    },
    {
      "x": -9,
      "y": 3,
      "z": 5,
      "name": "Soil_Grass"
    },
    {
      "x": -9,
      "y": 0,
      "z": 6,
      "name": "Wood_Ash_Trunk_Full"
    },
    {
      "x": -9,
      "y": 1,
      "z": 6,
      "name": "Wood_Ash_Trunk",
      "support": 15
    },
    {
      "x": -9,
      "y": 2,
      "z": 6,
      "name": "Wood_Ash_Trunk_Full"
    },
    {
      "x": -9,
      "y": 3,
      "z": 6,
      "name": "Soil_Grass"
    },
    {
      "x": -9,
      "y": 0,
      "z": 7,
      "name": "Soil_Dirt"
    },
    {
      "x": -9,
      "y": 1,
      "z": 7,
      "name": "Soil_Dirt"
    },
    {
      "x": -9,
      "y": 2,
      "z": 7,
      "name": "Wood_Ash_Trunk_Full"
    },
    {
      "x": -9,
      "y": 3,
      "z": 7,
      "name": "Soil_Grass"
    },
    {
      "x": -9,
      "y": 0,
      "z": 8,
      "name": "Soil_Dirt",
      "support": 15
    },
    {
      "x": -9,
      "y": 1,
      "z": 8,
      "name": "Soil_Dirt"
    },
    {
      "x": -9,
      "y": 2,
      "z": 8,
      "name": "Soil_Dirt"
    },
    {
      "x": -9,
      "y": 3,
      "z": 8,
      "name": "Soil_Grass"
    },
    {
      "x": -9,
      "y": 5,
      "z": 8,
      "name": "Wood_Ash_Trunk_Full"
    },
    {
      "x": -9,
      "y": 6,
      "z": 8,
      "name": "Wood_Ash_Trunk_Full"
    },
    {
      "x": -9,
      "y": 0,
      "z": 9,
      "name": "Soil_Dirt",
      "support": 15
    },
    {
      "x": -9,
      "y": 1,
      "z": 9,
      "name": "Soil_Dirt"
    },
    {
      "x": -9,
      "y": 2,
      "z": 9,
      "name": "Soil_Dirt"
    },
    {
      "x": -9,
      "y": 3,
      "z": 9,
      "name": "Soil_Grass"
    },
    {
      "x": -9,
      "y": 6,
      "z": 9,
      "name": "Wood_Ash_Trunk_Full"
    },
    {
      "x": -9,
      "y": 7,
      "z": 9,
      "name": "Wood_Ash_Trunk_Full"
    },
    {
      "x": -9,
      "y": 0,
      "z": 10,
      "name": "Wood_Ash_Trunk_Full"
    },
    {
      "x": -9,
      "y": 1,
      "z": 10,
      "name": "Soil_Dirt"
    },
    {
      "x": -9,
      "y": 2,
      "z": 10,
      "name": "Soil_Dirt"
    },
    {
      "x": -9,
      "y": 3,
      "z": 10,
      "name": "Soil_Grass"
    },
    {
      "x": -9,
      "y": 5,
      "z": 10,
      "name": "Wood_Ash_Trunk_Full"
    },
    {
      "x": -9,
      "y": 6,
      "z": 10,
      "name": "Wood_Ash_Trunk_Full"
    },
    {
      "x": -9,
      "y": 0,
      "z": 11,
      "name": "Wood_Ash_Trunk",
      "support": 15
    },
    {
      "x": -9,
      "y": 1,
      "z": 11,
      "name": "Wood_Ash_Trunk",
      "support": 15
    },
    {
      "x": -9,
      "y": 2,
      "z": 11,
      "name": "Wood_Ash_Trunk",
      "support": 15
    },
    {
      "x": -9,
      "y": 3,
      "z": 11,
      "name": "Wood_Ash_Trunk",
      "support": 15
    },
    {
      "x": -9,
      "y": 4,
      "z": 11,
      "name": "Wood_Ash_Trunk",
      "support": 15
    },
    {
      "x": -9,
      "y": 5,
      "z": 11,
      "name": "Wood_Ash_Trunk_Full"
    },
    {
      "x": -9,
      "y": 0,
      "z": 12,
      "name": "Wood_Ash_Trunk_Full"
    },
    {
      "x": -9,
      "y": 1,
      "z": 12,
      "name": "Wood_Ash_Trunk",
      "support": 15
    },
    {
      "x": -9,
      "y": 2,
      "z": 12,
      "name": "Wood_Ash_Trunk",
      "support": 15
    },
    {
      "x": -9,
      "y": 3,
      "z": 12,
      "name": "Wood_Ash_Trunk_Full"
    },
    {
      "x": -9,
      "y": 0,
      "z": 13,
      "name": "Wood_Ash_Trunk",
      "support": 15
    },
    {
      "x": -9,
      "y": 1,
      "z": 13,
      "name": "Wood_Ash_Trunk",
      "support": 15
    },
    {
      "x": -9,
      "y": 2,
      "z": 13,
      "name": "Wood_Ash_Trunk_Full"
    },
    {
      "x": -9,
      "y": 3,
      "z": 13,
      "name": "Soil_Grass"
    },
    {
      "x": -9,
      "y": 0,
      "z": 14,
      "name": "Soil_Dirt"
    },
    {
      "x": -9,
      "y": 1,
      "z": 14,
      "name": "Soil_Dirt"
    },
    {
      "x": -9,
      "y": 2,
      "z": 14,
      "name": "Soil_Dirt"
    },
    {
      "x": -9,
      "y": 3,
      "z": 14,
      "name": "Soil_Grass"
    },
    {
      "x": -9,
      "y": 0,
      "z": 15,
      "name": "Soil_Dirt"
    },
    {
      "x": -9,
      "y": 1,
      "z": 15,
      "name": "Soil_Dirt"
    },
    {
      "x": -9,
      "y": 2,
      "z": 15,
      "name": "Soil_Dirt"
    },
    {
      "x": -9,
      "y": 3,
      "z": 15,
      "name": "Soil_Grass"
    },
    {
      "x": -9,
      "y": 0,
      "z": 16,
      "name": "Soil_Dirt"
    },
    {
      "x": -9,
      "y": 1,
      "z": 16,
      "name": "Soil_Dirt"
    },
    {
      "x": -9,
      "y": 2,
      "z": 16,
      "name": "Soil_Dirt"
    },
    {
      "x": -9,
      "y": 3,
      "z": 16,
      "name": "Soil_Grass"
    },
    {
      "x": -8,
      "y": 0,
      "z": -15,
      "name": "Soil_Dirt"
    },
    {
      "x": -8,
      "y": 1,
      "z": -15,
      "name": "Soil_Dirt"
    },
    {
      "x": -8,
      "y": 2,
      "z": -15,
      "name": "Soil_Dirt"
    },
    {
      "x": -8,
      "y": 3,
      "z": -15,
      "name": "Soil_Grass"
    },
    {
      "x": -8,
      "y": 5,
      "z": -15,
      "name": "Wood_Ash_Trunk_Full"
    },
    {
      "x": -8,
      "y": 6,
      "z": -15,
      "name": "Wood_Ash_Trunk",
      "support": 15
    },
    {
      "x": -8,
      "y": 7,
      "z": -15,
      "name": "Wood_Ash_Trunk",
      "support": 15
    },
    {
      "x": -8,
      "y": 8,
      "z": -15,
      "name": "Wood_Ash_Trunk_Full"
    },
    {
      "x": -8,
      "y": 12,
      "z": -15,
      "name": "Wood_Ash_Trunk_Full"
    },
    {
      "x": -8,
      "y": 13,
      "z": -15,
      "name": "Wood_Ash_Trunk_Full"
    },
    {
      "x": -8,
      "y": 0,
      "z": -14,
      "name": "Soil_Dirt"
    },
    {
      "x": -8,
      "y": 1,
      "z": -14,
      "name": "Soil_Dirt"
    },
    {
      "x": -8,
      "y": 2,
      "z": -14,
      "name": "Soil_Dirt"
    },
    {
      "x": -8,
      "y": 3,
      "z": -14,
      "name": "Soil_Grass"
    },
    {
      "x": -8,
      "y": 7,
      "z": -14,
      "name": "Wood_Ash_Trunk_Full"
    },
    {
      "x": -8,
      "y": 8,
      "z": -14,
      "name": "Wood_Ash_Trunk",
      "support": 15
    },
    {
      "x": -8,
      "y": 9,
      "z": -14,
      "name": "Wood_Ash_Trunk",
      "support": 15
    },
    {
      "x": -8,
      "y": 10,
      "z": -14,
      "name": "Wood_Ash_Trunk",
      "support": 15
    },
    {
      "x": -8,
      "y": 11,
      "z": -14,
      "name": "Wood_Ash_Trunk",
      "support": 15
    },
    {
      "x": -8,
      "y": 12,
      "z": -14,
      "name": "Wood_Ash_Trunk",
      "support": 15
    },
    {
      "x": -8,
      "y": 13,
      "z": -14,
      "name": "Wood_Ash_Trunk",
      "support": 15
    },
    {
      "x": -8,
      "y": 14,
      "z": -14,
      "name": "Wood_Ash_Trunk_Full"
    },
    {
      "x": -8,
      "y": 0,
      "z": -13,
      "name": "Soil_Dirt",
      "support": 15
    },
    {
      "x": -8,
      "y": 1,
      "z": -13,
      "name": "Soil_Dirt",
      "support": 15
    },
    {
      "x": -8,
      "y": 2,
      "z": -13,
      "name": "Soil_Dirt"
    },
    {
      "x": -8,
      "y": 3,
      "z": -13,
      "name": "Soil_Grass"
    },
    {
      "x": -8,
      "y": 8,
      "z": -13,
      "name": "Wood_Ash_Trunk_Full"
    },
    {
      "x": -8,
      "y": 9,
      "z": -13,
      "name": "Wood_Ash_Trunk",
      "support": 15
    },
    {
      "x": -8,
      "y": 10,
      "z": -13,
      "name": "Wood_Ash_Trunk",
      "support": 15
    },
    {
      "x": -8,
      "y": 11,
      "z": -13,
      "name": "Wood_Ash_Trunk",
      "support": 15
    },
    {
      "x": -8,
      "y": 12,
      "z": -13,
      "name": "Wood_Ash_Trunk",
      "support": 15
    },
    {
      "x": -8,
      "y": 13,
      "z": -13,
      "name": "Wood_Ash_Trunk",
      "support": 15
    },
    {
      "x": -8,
      "y": 14,
      "z": -13,
      "name": "Wood_Ash_Trunk_Full"
    },
    {
      "x": -8,
      "y": 0,
      "z": -12,
      "name": "Soil_Dirt",
      "support": 15
    },
    {
      "x": -8,
      "y": 1,
      "z": -12,
      "name": "Soil_Dirt",
      "support": 15
    },
    {
      "x": -8,
      "y": 2,
      "z": -12,
      "name": "Soil_Dirt",
      "support": 15
    },
    {
      "x": -8,
      "y": 3,
      "z": -12,
      "name": "Soil_Grass"
    },
    {
      "x": -8,
      "y": 8,
      "z": -12,
      "name": "Wood_Ash_Trunk_Full"
    },
    {
      "x": -8,
      "y": 9,
      "z": -12,
      "name": "Wood_Ash_Trunk",
      "support": 15
    },
    {
      "x": -8,
      "y": 10,
      "z": -12,
      "name": "Wood_Ash_Trunk",
      "support": 15
    },
    {
      "x": -8,
      "y": 11,
      "z": -12,
      "name": "Wood_Ash_Trunk",
      "support": 15
    },
    {
      "x": -8,
      "y": 12,
      "z": -12,
      "name": "Wood_Ash_Trunk",
      "support": 15
    },
    {
      "x": -8,
      "y": 13,
      "z": -12,
      "name": "Wood_Ash_Trunk",
      "support": 15
    },
    {
      "x": -8,
      "y": 14,
      "z": -12,
      "name": "Wood_Ash_Trunk",
      "support": 15
    },
    {
      "x": -8,
      "y": 15,
      "z": -12,
      "name": "Wood_Ash_Trunk_Full"
    },
    {
      "x": -8,
      "y": 0,
      "z": -11,
      "name": "Soil_Dirt"
    },
    {
      "x": -8,
      "y": 1,
      "z": -11,
      "name": "Soil_Dirt"
    },
    {
      "x": -8,
      "y": 2,
      "z": -11,
      "name": "Soil_Dirt"
    },
    {
      "x": -8,
      "y": 3,
      "z": -11,
      "name": "Soil_Grass"
    },
    {
      "x": -8,
      "y": 9,
      "z": -11,
      "name": "Wood_Ash_Trunk_Full"
    },
    {
      "x": -8,
      "y": 10,
      "z": -11,
      "name": "Wood_Ash_Trunk",
      "support": 15
    },
    {
      "x": -8,
      "y": 11,
      "z": -11,
      "name": "Wood_Ash_Trunk",
      "support": 15
    },
    {
      "x": -8,
      "y": 12,
      "z": -11,
      "name": "Wood_Ash_Trunk",
      "support": 15
    },
    {
      "x": -8,
      "y": 13,
      "z": -11,
