{
  "version": 8,
  "blockIdVersion": 11,
  "anchorX": 0,
  "anchorY": 0,
  "anchorZ": 0,
  "blocks": [
    {
      "x": -15,
      "y": 0,
      "z": -15,
      "name": "Soil_Dirt"
    },
    {
      "x": -15,
      "y": 1,
      "z": -15,
      "name": "Soil_Dirt"
    },
    {
      "x": -15,
      "y": 2,
      "z": -15,
      "name": "Soil_Dirt"
    },
    {
      "x": -15,
      "y": 3,
      "z": -15,
      "name": "Soil_Grass"
    },
    {
      "x": -15,
      "y": 0,
      "z": -14,
      "name": "Soil_Dirt"
    },
    {
      "x": -15,
      "y": 1,
      "z": -14,
      "name": "Soil_Dirt"
    },
    {
      "x": -15,
      "y": 2,
      "z": -14,
      "name": "Soil_Dirt"
    },
    {
      "x": -15,
      "y": 3,
      "z": -14,
      "name": "Rock_Ledge_Brick"
    },
    {
      "x": -15,
      "y": 0,
      "z": -13,
      "name": "Soil_Dirt"
    },
    {
      "x": -15,
      "y": 1,
      "z": -13,
      "name": "Soil_Dirt"
    },
    {
      "x": -15,
      "y": 2,
      "z": -13,
      "name": "Soil_Dirt"
    },
    {
      "x": -15,
      "y": 3,
      "z": -13,
      "name": "Rock_Ledge_Brick"
    },
    {
      "x": -15,
      "y": 0,
      "z": -12,
      "name": "Soil_Dirt"
    },
    {
      "x": -15,
      "y": 1,
      "z": -12,
      "name": "Soil_Dirt"
    },
    {
      "x": -15,
      "y": 2,
      "z": -12,
      "name": "Soil_Dirt"
    },
    {
      "x": -15,
      "y": 3,
      "z": -12,
      "name": "Rock_Ledge_Brick"
    },
    {
      "x": -15,
      "y": 0,
      "z": -11,
      "name": "Soil_Dirt"
    },
    {
      "x": -15,
      "y": 1,
      "z": -11,
      "name": "Soil_Dirt"
    },
    {
      "x": -15,
      "y": 2,
      "z": -11,
      "name": "Soil_Dirt"
    },
    {
      "x": -15,
      "y": 3,
      "z": -11,
      "name": "Soil_Dirt"
    },
    {
      "x": -15,
      "y": 4,
      "z": -11,
      "name": "Rock_Sandstone_Red_Brick_Smooth"
    },
    {
      "x": -15,
      "y": 5,
      "z": -11,
      "name": "Rock_Sandstone_Red_Brick_Smooth"
    },
    {
      "x": -15,
      "y": 6,
      "z": -11,
      "name": "Rock_Sandstone_Red_Brick_Smooth"
    },
    {
      "x": -15,
      "y": 7,
      "z": -11,
      "name": "Rock_Sandstone_Red_Brick_Smooth"
    },
    {
      "x": -15,
      "y": 8,
      "z": -11,
      "name": "Rock_Sandstone_Red_Brick_Smooth"
    },
    {
      "x": -15,
      "y": 9,
      "z": -11,
      "name": "Rock_Sandstone_Red_Brick_Smooth"
    },
    {
      "x": -15,
      "y": 10,
      "z": -11,
      "name": "Rock_Sandstone_Red_Brick_Smooth"
    },
    {
      "x": -15,
      "y": 11,
      "z": -11,
      "name": "Rock_Sandstone_Red_Brick_Smooth"
    },
    {
      "x": -15,
      "y": 12,
      "z": -11,
      "name": "Rock_Sandstone_Red_Brick_Smooth"
    },
    {
      "x": -15,
      "y": 0,
      "z": -10,
      "name": "Soil_Dirt"
    },
    {
      "x": -15,
      "y": 1,
      "z": -10,
      "name": "Soil_Dirt"
    },
    {
      "x": -15,
      "y": 2,
      "z": -10,
      "name": "Soil_Dirt"
    },
    {
      "x": -15,
      "y": 3,
      "z": -10,
      "name": "Soil_Grass"
    },
    {
      "x": -15,
      "y": 0,
      "z": -9,
      "name": "Soil_Dirt"
    },
    {
      "x": -15,
      "y": 1,
      "z": -9,
      "name": "Soil_Dirt"
    },
    {
      "x": -15,
      "y": 2,
      "z": -9,
      "name": "Soil_Dirt"
    },
    {
      "x": -15,
      "y": 3,
      "z": -9,
      "name": "Soil_Grass"
    },
    {
      "x": -15,
      "y": 0,
      "z": -8,
      "name": "Soil_Dirt"
    },
    {
      "x": -15,
      "y": 1,
      "z": -8,
      "name": "Soil_Dirt"
    },
    {
      "x": -15,
      "y": 2,
      "z": -8,
      "name": "Soil_Dirt"
    },
    {
      "x": -15,
      "y": 3,
      "z": -8,
      "name": "Soil_Grass"
    },
    {
      "x": -15,
      "y": 0,
      "z": -7,
      "name": "Soil_Dirt"
    },
    {
      "x": -15,
      "y": 1,
      "z": -7,
      "name": "Soil_Dirt"
    },
    {
      "x": -15,
      "y": 2,
      "z": -7,
      "name": "Soil_Dirt"
    },
    {
      "x": -15,
      "y": 3,
      "z": -7,
      "name": "Soil_Grass"
    },
    {
      "x": -15,
      "y": 0,
      "z": -6,
      "name": "Soil_Dirt"
    },
    {
      "x": -15,
      "y": 1,
      "z": -6,
      "name": "Soil_Dirt"
    },
    {
      "x": -15,
      "y": 2,
      "z": -6,
      "name": "Soil_Dirt"
    },
    {
      "x": -15,
      "y": 3,
      "z": -6,
      "name": "Soil_Grass"
    },
    {
      "x": -15,
      "y": 0,
      "z": -5,
      "name": "Soil_Dirt"
    },
    {
      "x": -15,
      "y": 1,
      "z": -5,
      "name": "Soil_Dirt"
    },
    {
      "x": -15,
      "y": 2,
      "z": -5,
      "name": "Soil_Dirt"
    },
    {
      "x": -15,
      "y": 3,
      "z": -5,
      "name": "Soil_Grass"
    },
    {
      "x": -15,
      "y": 0,
      "z": -4,
      "name": "Soil_Dirt"
    },
    {
      "x": -15,
      "y": 1,
      "z": -4,
      "name": "Soil_Dirt"
    },
    {
      "x": -15,
      "y": 2,
      "z": -4,
      "name": "Soil_Dirt"
    },
    {
      "x": -15,
      "y": 3,
      "z": -4,
      "name": "Soil_Grass"
    },
    {
      "x": -15,
      "y": 0,
      "z": -3,
      "name": "Soil_Dirt"
    },
    {
      "x": -15,
      "y": 1,
      "z": -3,
      "name": "Soil_Dirt"
    },
    {
      "x": -15,
      "y": 2,
      "z": -3,
      "name": "Soil_Dirt"
    },
    {
      "x": -15,
      "y": 3,
      "z": -3,
      "name": "Rock_Ledge_Brick_Smooth"
    },
    {
      "x": -15,
      "y": 0,
      "z": -2,
      "name": "Soil_Dirt"
    },
    {
      "x": -15,
      "y": 1,
      "z": -2,
      "name": "Soil_Dirt"
    },
    {
      "x": -15,
      "y": 2,
      "z": -2,
      "name": "Soil_Dirt"
    },
    {
      "x": -15,
      "y": 3,
      "z": -2,
      "name": "Rock_Ledge_Brick_Smooth"
    },
    {
      "x": -15,
      "y": 0,
      "z": -1,
      "name": "Soil_Dirt"
    },
    {
      "x": -15,
      "y": 1,
      "z": -1,
      "name": "Soil_Dirt"
    },
    {
      "x": -15,
      "y": 2,
      "z": -1,
      "name": "Soil_Dirt"
    },
    {
      "x": -15,
      "y": 3,
      "z": -1,
      "name": "Rock_Ledge_Brick_Smooth"
    },
    {
      "x": -15,
      "y": 0,
      "z": 0,
      "name": "Soil_Dirt"
    },
    {
      "x": -15,
      "y": 1,
      "z": 0,
      "name": "Soil_Dirt"
    },
    {
      "x": -15,
      "y": 2,
      "z": 0,
      "name": "Soil_Dirt"
    },
    {
      "x": -15,
      "y": 3,
      "z": 0,
      "name": "Rock_Ledge_Brick_Ornate"
    },
    {
      "x": -15,
      "y": 0,
      "z": 1,
      "name": "Soil_Dirt"
    },
    {
      "x": -15,
      "y": 1,
      "z": 1,
      "name": "Soil_Dirt"
    },
    {
      "x": -15,
      "y": 2,
      "z": 1,
      "name": "Soil_Dirt"
    },
    {
      "x": -15,
      "y": 3,
      "z": 1,
      "name": "Rock_Ledge_Brick_Decorative"
    },
    {
      "x": -15,
      "y": 0,
      "z": 2,
      "name": "Soil_Dirt"
    },
    {
      "x": -15,
      "y": 1,
      "z": 2,
      "name": "Soil_Dirt"
    },
    {
      "x": -15,
      "y": 2,
      "z": 2,
      "name": "Soil_Dirt"
    },
    {
      "x": -15,
      "y": 3,
      "z": 2,
      "name": "Rock_Ledge_Brick_Smooth"
    },
    {
      "x": -15,
      "y": 0,
      "z": 3,
      "name": "Soil_Dirt"
    },
    {
      "x": -15,
      "y": 1,
      "z": 3,
      "name": "Soil_Dirt"
    },
    {
      "x": -15,
      "y": 2,
      "z": 3,
      "name": "Soil_Dirt"
    },
    {
      "x": -15,
      "y": 3,
      "z": 3,
      "name": "Rock_Ledge_Brick_Smooth"
    },
    {
      "x": -15,
      "y": 0,
      "z": 4,
      "name": "Soil_Dirt"
    },
    {
      "x": -15,
      "y": 1,
      "z": 4,
      "name": "Soil_Dirt"
    },
    {
      "x": -15,
      "y": 2,
      "z": 4,
      "name": "Soil_Dirt"
    },
    {
      "x": -15,
      "y": 3,
      "z": 4,
      "name": "Rock_Ledge_Brick_Ornate"
    },
    {
      "x": -15,
      "y": 0,
      "z": 5,
      "name": "Soil_Dirt"
    },
    {
      "x": -15,
      "y": 1,
      "z": 5,
      "name": "Soil_Dirt"
    },
    {
      "x": -15,
      "y": 2,
      "z": 5,
      "name": "Soil_Dirt"
    },
    {
      "x": -15,
      "y": 3,
      "z": 5,
      "name": "Rock_Ledge_Brick_Smooth"
    },
    {
      "x": -15,
      "y": 0,
      "z": 6,
      "name": "Soil_Dirt"
    },
    {
      "x": -15,
      "y": 1,
      "z": 6,
      "name": "Soil_Dirt"
    },
    {
      "x": -15,
      "y": 2,
      "z": 6,
      "name": "Soil_Dirt"
    },
    {
      "x": -15,
      "y": 3,
      "z": 6,
      "name": "Rock_Ledge_Brick_Smooth"
    },
    {
      "x": -15,
      "y": 0,
      "z": 7,
      "name": "Soil_Dirt"
    },
    {
      "x": -15,
      "y": 1,
      "z": 7,
      "name": "Soil_Dirt"
    },
    {
      "x": -15,
      "y": 2,
      "z": 7,
      "name": "Soil_Dirt"
    },
    {
      "x": -15,
      "y": 3,
      "z": 7,
      "name": "Rock_Ledge_Brick_Smooth"
    },
    {
      "x": -15,
      "y": 0,
      "z": 8,
      "name": "Soil_Dirt"
    },
    {
      "x": -15,
      "y": 1,
      "z": 8,
      "name": "Soil_Dirt"
    },
    {
      "x": -15,
      "y": 2,
      "z": 8,
      "name": "Soil_Dirt"
    },
    {
      "x": -15,
      "y": 3,
      "z": 8,
      "name": "Rock_Ledge_Brick_Ornate"
    },
    {
      "x": -15,
      "y": 0,
      "z": 9,
      "name": "Soil_Dirt"
    },
    {
      "x": -15,
      "y": 1,
      "z": 9,
      "name": "Soil_Dirt"
    },
    {
      "x": -15,
      "y": 2,
      "z": 9,
      "name": "Soil_Dirt"
    },
    {
      "x": -15,
      "y": 3,
      "z": 9,
      "name": "Rock_Ledge_Brick_Smooth"
    },
    {
      "x": -15,
      "y": 0,
      "z": 10,
      "name": "Soil_Dirt"
    },
    {
      "x": -15,
      "y": 1,
      "z": 10,
      "name": "Soil_Dirt"
    },
    {
      "x": -15,
      "y": 2,
      "z": 10,
      "name": "Soil_Dirt"
    },
    {
      "x": -15,
      "y": 3,
      "z": 10,
      "name": "Rock_Ledge_Brick"
    },
    {
      "x": -15,
      "y": 0,
      "z": 11,
      "name": "Soil_Dirt"
    },
    {
      "x": -15,
      "y": 1,
      "z": 11,
      "name": "Soil_Dirt"
    },
    {
      "x": -15,
      "y": 2,
      "z": 11,
      "name": "Soil_Dirt"
    },
    {
      "x": -15,
      "y": 3,
      "z": 11,
      "name": "Rock_Ledge_Brick_Decorative"
    },
    {
      "x": -15,
      "y": 0,
      "z": 12,
      "name": "Soil_Dirt"
    },
    {
      "x": -15,
      "y": 1,
      "z": 12,
      "name": "Soil_Dirt"
    },
    {
      "x": -15,
      "y": 2,
      "z": 12,
      "name": "Soil_Dirt"
    },
    {
      "x": -15,
      "y": 3,
      "z": 12,
      "name": "Rock_Ledge_Brick_Smooth"
    },
    {
      "x": -15,
      "y": 0,
      "z": 13,
      "name": "Soil_Dirt"
    },
    {
      "x": -15,
      "y": 1,
      "z": 13,
      "name": "Soil_Dirt"
    },
    {
      "x": -15,
      "y": 2,
      "z": 13,
      "name": "Soil_Dirt"
    },
    {
      "x": -15,
      "y": 3,
      "z": 13,
      "name": "Rock_Ledge_Brick"
    },
    {
      "x": -15,
      "y": 0,
      "z": 14,
      "name": "Soil_Dirt"
    },
    {
      "x": -15,
      "y": 1,
      "z": 14,
      "name": "Soil_Dirt"
    },
    {
      "x": -15,
      "y": 2,
      "z": 14,
      "name": "Soil_Dirt"
    },
    {
      "x": -15,
      "y": 3,
      "z": 14,
      "name": "Rock_Ledge_Brick"
    },
    {
      "x": -15,
      "y": 0,
      "z": 15,
      "name": "Soil_Dirt"
    },
    {
      "x": -15,
      "y": 1,
      "z": 15,
      "name": "Soil_Dirt"
    },
    {
      "x": -15,
      "y": 2,
      "z": 15,
      "name": "Soil_Dirt"
    },
    {
      "x": -15,
      "y": 3,
      "z": 15,
      "name": "Rock_Ledge_Brick_Smooth"
    },
    {
      "x": -15,
      "y": 0,
      "z": 16,
      "name": "Soil_Dirt"
    },
    {
      "x": -15,
      "y": 1,
      "z": 16,
      "name": "Soil_Dirt"
    },
    {
      "x": -15,
      "y": 2,
      "z": 16,
      "name": "Soil_Dirt"
    },
    {
      "x": -15,
      "y": 3,
      "z": 16,
      "name": "Rock_Ledge_Cobble"
    },
    {
      "x": -14,
      "y": 0,
      "z": -15,
      "name": "Soil_Dirt"
    },
    {
      "x": -14,
      "y": 1,
      "z": -15,
      "name": "Soil_Dirt"
    },
    {
      "x": -14,
      "y": 2,
      "z": -15,
      "name": "Soil_Dirt"
    },
    {
      "x": -14,
      "y": 3,
      "z": -15,
      "name": "Rock_Ledge_Brick_Smooth"
    },
    {
      "x": -14,
      "y": 0,
      "z": -14,
      "name": "Soil_Dirt"
    },
    {
      "x": -14,
      "y": 1,
      "z": -14,
      "name": "Soil_Dirt"
    },
    {
      "x": -14,
      "y": 2,
      "z": -14,
      "name": "Soil_Dirt"
    },
    {
      "x": -14,
      "y": 3,
      "z": -14,
      "name": "Rock_Ledge_Cobble"
    },
    {
      "x": -14,
      "y": 0,
      "z": -13,
      "name": "Soil_Dirt"
    },
    {
      "x": -14,
      "y": 1,
      "z": -13,
      "name": "Soil_Dirt"
    },
    {
      "x": -14,
      "y": 2,
      "z": -13,
      "name": "Soil_Dirt"
    },
    {
      "x": -14,
      "y": 3,
      "z": -13,
      "name": "Rock_Ledge_Brick"
    },
    {
      "x": -14,
      "y": 0,
      "z": -12,
      "name": "Soil_Dirt"
    },
    {
      "x": -14,
      "y": 1,
      "z": -12,
      "name": "Soil_Dirt"
    },
    {
      "x": -14,
      "y": 2,
      "z": -12,
      "name": "Soil_Dirt"
    },
    {
      "x": -14,
      "y": 3,
      "z": -12,
      "name": "Rock_Ledge_Brick"
    },
    {
      "x": -14,
      "y": 0,
      "z": -11,
      "name": "Soil_Dirt"
    },
    {
      "x": -14,
      "y": 1,
      "z": -11,
      "name": "Soil_Dirt"
    },
    {
      "x": -14,
      "y": 2,
      "z": -11,
      "name": "Soil_Dirt"
    },
    {
      "x": -14,
      "y": 3,
      "z": -11,
      "name": "Soil_Dirt"
    },
    {
      "x": -14,
      "y": 4,
      "z": -11,
      "name": "Rock_Sandstone_Red_Brick_Smooth"
    },
    {
      "x": -14,
      "y": 5,
      "z": -11,
      "name": "Rock_Sandstone_Red_Brick_Smooth"
    },
    {
      "x": -14,
      "y": 6,
      "z": -11,
      "name": "Rock_Sandstone_Red_Brick_Smooth"
    },
    {
      "x": -14,
      "y": 7,
      "z": -11,
      "name": "Rock_Sandstone_Red_Brick_Smooth"
    },
    {
      "x": -14,
      "y": 8,
      "z": -11,
      "name": "Rock_Sandstone_Red_Brick_Smooth"
    },
    {
      "x": -14,
      "y": 9,
      "z": -11,
      "name": "Rock_Sandstone_Red_Brick_Smooth"
    },
    {
      "x": -14,
      "y": 10,
      "z": -11,
      "name": "Rock_Sandstone_Red_Brick_Smooth"
    },
    {
      "x": -14,
      "y": 11,
      "z": -11,
      "name": "Rock_Sandstone_Red_Brick_Smooth"
    },
    {
      "x": -14,
      "y": 12,
      "z": -11,
      "name": "Rock_Sandstone_Red_Brick_Smooth"
    },
    {
      "x": -14,
      "y": 0,
      "z": -10,
      "name": "Soil_Dirt"
    },
    {
      "x": -14,
      "y": 1,
      "z": -10,
      "name": "Soil_Dirt"
    },
    {
      "x": -14,
      "y": 2,
      "z": -10,
      "name": "Soil_Dirt"
    },
    {
      "x": -14,
      "y": 3,
      "z": -10,
      "name": "Soil_Grass"
    },
    {
      "x": -14,
      "y": 0,
      "z": -9,
      "name": "Soil_Dirt"
    },
    {
      "x": -14,
      "y": 1,
      "z": -9,
      "name": "Soil_Dirt"
    },
    {
      "x": -14,
      "y": 2,
      "z": -9,
      "name": "Soil_Dirt"
    },
    {
      "x": -14,
      "y": 3,
      "z": -9,
      "name": "Soil_Grass"
    },
    {
      "x": -14,
      "y": 0,
      "z": -8,
      "name": "Soil_Dirt"
    },
    {
      "x": -14,
      "y": 1,
      "z": -8,
      "name": "Soil_Dirt"
    },
    {
      "x": -14,
      "y": 2,
      "z": -8,
      "name": "Soil_Dirt"
    },
    {
      "x": -14,
      "y": 3,
      "z": -8,
      "name": "Soil_Grass"
    },
    {
      "x": -14,
      "y": 0,
      "z": -7,
      "name": "Soil_Dirt"
    },
    {
      "x": -14,
      "y": 1,
      "z": -7,
      "name": "Soil_Dirt"
    },
    {
      "x": -14,
      "y": 2,
      "z": -7,
      "name": "Soil_Dirt"
    },
    {
      "x": -14,
      "y": 3,
      "z": -7,
      "name": "Soil_Grass"
    },
    {
      "x": -14,
      "y": 0,
      "z": -6,
      "name": "Soil_Dirt"
    },
    {
      "x": -14,
      "y": 1,
      "z": -6,
      "name": "Soil_Dirt"
    },
    {
      "x": -14,
      "y": 2,
      "z": -6,
      "name": "Soil_Dirt"
    },
    {
      "x": -14,
      "y": 3,
      "z": -6,
      "name": "Soil_Grass"
    },
    {
      "x": -14,
      "y": 0,
      "z": -5,
      "name": "Soil_Dirt"
    },
    {
      "x": -14,
      "y": 1,
      "z": -5,
      "name": "Soil_Dirt"
    },
    {
      "x": -14,
      "y": 2,
      "z": -5,
      "name": "Soil_Dirt"
    },
    {
      "x": -14,
      "y": 3,
      "z": -5,
      "name": "Soil_Grass"
    },
    {
      "x": -14,
      "y": 0,
      "z": -4,
      "name": "Soil_Dirt"
    },
    {
      "x": -14,
      "y": 1,
      "z": -4,
      "name": "Soil_Dirt"
    },
    {
      "x": -14,
      "y": 2,
      "z": -4,
      "name": "Soil_Dirt"
    },
    {
      "x": -14,
      "y": 3,
      "z": -4,
      "name": "Soil_Grass"
    },
    {
      "x": -14,
      "y": 0,
      "z": -3,
      "name": "Soil_Dirt"
    },
    {
      "x": -14,
      "y": 1,
      "z": -3,
      "name": "Soil_Dirt"
    },
    {
      "x": -14,
      "y": 2,
      "z": -3,
      "name": "Soil_Dirt"
    },
    {
      "x": -14,
      "y": 3,
      "z": -3,
      "name": "Rock_Ledge_Brick"
    },
    {
      "x": -14,
      "y": 0,
      "z": -2,
      "name": "Soil_Dirt"
    },
    {
      "x": -14,
      "y": 1,
      "z": -2,
      "name": "Soil_Dirt"
    },
    {
      "x": -14,
      "y": 2,
      "z": -2,
      "name": "Soil_Dirt"
    },
    {
      "x": -14,
      "y": 3,
      "z": -2,
      "name": "Rock_Ledge_Brick"
    },
    {
      "x": -14,
      "y": 0,
      "z": -1,
      "name": "Soil_Dirt"
    },
    {
      "x": -14,
      "y": 1,
      "z": -1,
      "name": "Soil_Dirt"
    },
    {
      "x": -14,
      "y": 2,
      "z": -1,
      "name": "Soil_Dirt"
    },
    {
      "x": -14,
      "y": 3,
      "z": -1,
      "name": "Rock_Ledge_Brick_Smooth"
    },
    {
      "x": -14,
      "y": 0,
      "z": 0,
      "name": "Soil_Dirt"
    },
    {
      "x": -14,
      "y": 1,
      "z": 0,
      "name": "Soil_Dirt"
    },
    {
      "x": -14,
      "y": 2,
      "z": 0,
      "name": "Soil_Dirt"
    },
    {
      "x": -14,
      "y": 3,
      "z": 0,
      "name": "Rock_Ledge_Brick_Smooth"
    },
    {
      "x": -14,
      "y": 0,
      "z": 1,
      "name": "Soil_Dirt"
    },
    {
      "x": -14,
      "y": 1,
      "z": 1,
      "name": "Soil_Dirt"
    },
    {
      "x": -14,
      "y": 2,
      "z": 1,
      "name": "Soil_Dirt"
    },
    {
      "x": -14,
      "y": 3,
      "z": 1,
      "name": "Rock_Ledge_Brick_Smooth"
    },
    {
      "x": -14,
      "y": 0,
      "z": 2,
      "name": "Soil_Dirt"
    },
    {
      "x": -14,
      "y": 1,
      "z": 2,
      "name": "Soil_Dirt"
    },
    {
      "x": -14,
      "y": 2,
      "z": 2,
      "name": "Soil_Dirt"
    },
    {
      "x": -14,
      "y": 3,
      "z": 2,
      "name": "Rock_Ledge_Brick_Ornate"
    },
    {
      "x": -14,
      "y": 0,
      "z": 3,
      "name": "Soil_Dirt"
    },
    {
      "x": -14,
      "y": 1,
      "z": 3,
      "name": "Soil_Dirt"
    },
    {
      "x": -14,
      "y": 2,
      "z": 3,
      "name": "Soil_Dirt"
    },
    {
      "x": -14,
      "y": 3,
      "z": 3,
      "name": "Rock_Ledge_Brick"
    },
    {
      "x": -14,
      "y": 0,
      "z": 4,
      "name": "Soil_Dirt"
    },
    {
      "x": -14,
      "y": 1,
      "z": 4,
      "name": "Soil_Dirt"
    },
    {
      "x": -14,
      "y": 2,
      "z": 4,
      "name": "Soil_Dirt"
    },
    {
      "x": -14,
      "y": 3,
      "z": 4,
      "name": "Rock_Ledge_Brick_Smooth"
    },
    {
      "x": -14,
      "y": 0,
      "z": 5,
      "name": "Soil_Dirt"
    },
    {
      "x": -14,
      "y": 1,
      "z": 5,
      "name": "Soil_Dirt"
    },
    {
      "x": -14,
      "y": 2,
      "z": 5,
      "name": "Soil_Dirt"
    },
    {
      "x": -14,
      "y": 3,
      "z": 5,
      "name": "Rock_Ledge_Brick_Decorative"
    },
    {
      "x": -14,
      "y": 0,
      "z": 6,
      "name": "Soil_Dirt"
    },
    {
      "x": -14,
      "y": 1,
      "z": 6,
      "name": "Soil_Dirt"
    },
    {
      "x": -14,
      "y": 2,
      "z": 6,
      "name": "Soil_Dirt"
    },
    {
      "x": -14,
      "y": 3,
      "z": 6,
      "name": "Rock_Ledge_Cobble"
    },
    {
      "x": -14,
      "y": 0,
      "z": 7,
      "name": "Soil_Dirt"
    },
    {
      "x": -14,
      "y": 1,
      "z": 7,
      "name": "Soil_Dirt"
    },
    {
      "x": -14,
      "y": 2,
      "z": 7,
      "name": "Soil_Dirt"
    },
    {
      "x": -14,
      "y": 3,
      "z": 7,
      "name": "Rock_Ledge_Brick_Ornate"
    },
    {
      "x": -14,
      "y": 0,
      "z": 8,
      "name": "Soil_Dirt"
    },
    {
      "x": -14,
      "y": 1,
      "z": 8,
      "name": "Soil_Dirt"
    },
    {
      "x": -14,
      "y": 2,
      "z": 8,
      "name": "Soil_Dirt"
    },
    {
      "x": -14,
      "y": 3,
      "z": 8,
      "name": "Rock_Ledge_Brick_Smooth"
    },
    {
      "x": -14,
      "y": 0,
      "z": 9,
      "name": "Soil_Dirt"
    },
    {
      "x": -14,
      "y": 1,
      "z": 9,
      "name": "Soil_Dirt"
    },
    {
      "x": -14,
      "y": 2,
      "z": 9,
      "name": "Soil_Dirt"
    },
    {
      "x": -14,
      "y": 3,
      "z": 9,
      "name": "Rock_Ledge_Brick_Smooth"
    },
    {
      "x": -14,
      "y": 0,
      "z": 10,
      "name": "Soil_Dirt"
    },
    {
      "x": -14,
      "y": 1,
      "z": 10,
      "name": "Soil_Dirt"
    },
    {
      "x": -14,
      "y": 2,
      "z": 10,
      "name": "Soil_Dirt"
    },
    {
      "x": -14,
      "y": 3,
      "z": 10,
      "name": "Rock_Ledge_Brick_Decorative"
    },
    {
      "x": -14,
      "y": 0,
      "z": 11,
      "name": "Soil_Dirt"
    },
    {
      "x": -14,
      "y": 1,
      "z": 11,
      "name": "Soil_Dirt"
    },
    {
      "x": -14,
      "y": 2,
      "z": 11,
      "name": "Soil_Dirt"
    },
    {
      "x": -14,
      "y": 3,
      "z": 11,
      "name": "Rock_Ledge_Brick_Ornate"
    },
    {
      "x": -14,
      "y": 0,
      "z": 12,
      "name": "Soil_Dirt"
    },
    {
      "x": -14,
      "y": 1,
      "z": 12,
      "name": "Soil_Dirt"
    },
    {
      "x": -14,
      "y": 2,
      "z": 12,
      "name": "Soil_Dirt"
    },
    {
      "x": -14,
      "y": 3,
      "z": 12,
      "name": "Rock_Ledge_Cobble"
    },
    {
      "x": -14,
      "y": 0,
      "z": 13,
      "name": "Soil_Dirt"
    },
    {
      "x": -14,
      "y": 1,
      "z": 13,
      "name": "Soil_Dirt"
    },
    {
      "x": -14,
      "y": 2,
      "z": 13,
      "name": "Soil_Dirt"
    },
    {
      "x": -14,
      "y": 3,
      "z": 13,
      "name": "Rock_Ledge_Brick_Smooth"
    },
    {
      "x": -14,
      "y": 0,
      "z": 14,
      "name": "Soil_Dirt"
    },
    {
      "x": -14,
      "y": 1,
      "z": 14,
      "name": "Soil_Dirt"
    },
    {
      "x": -14,
      "y": 2,
      "z": 14,
      "name": "Soil_Dirt"
    },
    {
      "x": -14,
      "y": 3,
      "z": 14,
      "name": "Rock_Ledge_Cobble"
    },
    {
      "x": -14,
      "y": 0,
      "z": 15,
      "name": "Soil_Dirt"
    },
    {
      "x": -14,
      "y": 1,
      "z": 15,
      "name": "Soil_Dirt"
    },
    {
      "x": -14,
      "y": 2,
      "z": 15,
      "name": "Soil_Dirt"
    },
    {
      "x": -14,
      "y": 3,
      "z": 15,
      "name": "Rock_Ledge_Cobble"
    },
    {
      "x": -14,
      "y": 0,
      "z": 16,
      "name": "Soil_Dirt"
    },
    {
      "x": -14,
      "y": 1,
      "z": 16,
      "name": "Soil_Dirt"
    },
    {
      "x": -14,
      "y": 2,
      "z": 16,
      "name": "Soil_Dirt"
    },
    {
      "x": -14,
      "y": 3,
      "z": 16,
      "name": "Rock_Ledge_Brick"
    },
    {
      "x": -13,
      "y": 0,
      "z": -15,
      "name": "Soil_Dirt"
    },
    {
      "x": -13,
      "y": 1,
      "z": -15,
      "name": "Soil_Dirt"
    },
    {
      "x": -13,
      "y": 2,
      "z": -15,
      "name": "Soil_Dirt"
    },
    {
      "x": -13,
      "y": 3,
      "z": -15,
      "name": "Rock_Ledge_Brick"
    },
    {
      "x": -13,
      "y": 0,
      "z": -14,
      "name": "Soil_Dirt"
    },
    {
      "x": -13,
      "y": 1,
      "z": -14,
      "name": "Soil_Dirt"
    },
    {
      "x": -13,
      "y": 2,
      "z": -14,
      "name": "Soil_Dirt"
    },
    {
      "x": -13,
      "y": 3,
      "z": -14,
      "name": "Rock_Ledge_Brick_Smooth"
    },
    {
      "x": -13,
      "y": 0,
      "z": -13,
      "name": "Soil_Dirt"
    },
    {
      "x": -13,
      "y": 1,
      "z": -13,
      "name": "Soil_Dirt"
    },
    {
      "x": -13,
      "y": 2,
      "z": -13,
      "name": "Soil_Dirt"
    },
    {
      "x": -13,
      "y": 3,
      "z": -13,
      "name": "Rock_Ledge_Brick_Ornate"
    },
    {
      "x": -13,
      "y": 0,
      "z": -12,
      "name": "Soil_Dirt"
    },
    {
      "x": -13,
      "y": 1,
      "z": -12,
      "name": "Soil_Dirt"
    },
    {
      "x": -13,
      "y": 2,
      "z": -12,
      "name": "Soil_Dirt"
    },
    {
      "x": -13,
      "y": 3,
      "z": -12,
      "name": "Rock_Ledge_Brick"
    },
    {
      "x": -13,
      "y": 0,
      "z": -11,
      "name": "Soil_Dirt"
    },
    {
      "x": -13,
      "y": 1,
      "z": -11,
      "name": "Soil_Dirt"
    },
    {
      "x": -13,
      "y": 2,
      "z": -11,
      "name": "Soil_Dirt"
    },
    {
      "x": -13,
      "y": 3,
      "z": -11,
      "name": "Soil_Dirt"
    },
    {
      "x": -13,
      "y": 4,
      "z": -11,
      "name": "Rock_Sandstone_Red_Brick_Smooth"
    },
    {
      "x": -13,
      "y": 5,
      "z": -11,
      "name": "Rock_Sandstone_Red_Brick_Smooth"
    },
    {
      "x": -13,
      "y": 6,
      "z": -11,
      "name": "Rock_Sandstone_Red_Brick_Smooth"
    },
    {
      "x": -13,
      "y": 7,
      "z": -11,
      "name": "Rock_Sandstone_Red_Brick_Smooth"
    },
    {
      "x": -13,
      "y": 8,
      "z": -11,
      "name": "Rock_Sandstone_Red_Brick_Smooth"
    },
    {
      "x": -13,
      "y": 9,
      "z": -11,
      "name": "Rock_Sandstone_Red_Brick_Smooth"
    },
    {
      "x": -13,
      "y": 10,
      "z": -11,
      "name": "Rock_Sandstone_Red_Brick_Smooth"
    },
    {
      "x": -13,
      "y": 11,
      "z": -11,
      "name": "Rock_Sandstone_Red_Brick_Smooth"
    },
    {
      "x": -13,
      "y": 12,
      "z": -11,
      "name": "Rock_Sandstone_Red_Brick_Smooth"
    },
    {
      "x": -13,
      "y": 0,
      "z": -10,
      "name": "Soil_Dirt"
    },
    {
      "x": -13,
      "y": 1,
      "z": -10,
      "name": "Soil_Dirt"
    },
    {
      "x": -13,
      "y": 2,
      "z": -10,
      "name": "Soil_Dirt"
    },
    {
      "x": -13,
      "y": 3,
      "z": -10,
      "name": "Soil_Grass"
    },
    {
      "x": -13,
      "y": 0,
      "z": -9,
      "name": "Soil_Dirt"
    },
    {
      "x": -13,
      "y": 1,
      "z": -9,
      "name": "Soil_Dirt"
    },
    {
      "x": -13,
      "y": 2,
      "z": -9,
      "name": "Soil_Dirt"
    },
    {
      "x": -13,
      "y": 3,
      "z": -9,
      "name": "Soil_Grass"
    },
    {
      "x": -13,
      "y": 0,
      "z": -8,
      "name": "Soil_Dirt"
    },
    {
      "x": -13,
      "y": 1,
      "z": -8,
      "name": "Soil_Dirt"
    },
    {
      "x": -13,
      "y": 2,
      "z": -8,
      "name": "Soil_Dirt"
    },
    {
      "x": -13,
      "y": 3,
      "z": -8,
      "name": "Soil_Grass"
    },
    {
      "x": -13,
      "y": 0,
      "z": -7,
      "name": "Soil_Dirt"
    },
    {
      "x": -13,
      "y": 1,
      "z": -7,
      "name": "Soil_Dirt"
    },
    {
      "x": -13,
      "y": 2,
      "z": -7,
      "name": "Soil_Dirt"
    },
    {
      "x": -13,
      "y": 3,
      "z": -7,
      "name": "Soil_Grass"
    },
    {
      "x": -13,
      "y": 0,
      "z": -6,
      "name": "Soil_Dirt"
    },
    {
      "x": -13,
      "y": 1,
      "z": -6,
      "name": "Soil_Dirt"
    },
    {
      "x": -13,
      "y": 2,
      "z": -6,
      "name": "Soil_Dirt"
    },
    {
      "x": -13,
      "y": 3,
      "z": -6,
      "name": "Soil_Grass"
    },
    {
      "x": -13,
      "y": 0,
      "z": -5,
      "name": "Soil_Dirt"
    },
    {
      "x": -13,
      "y": 1,
      "z": -5,
      "name": "Soil_Dirt"
    },
    {
      "x": -13,
      "y": 2,
      "z": -5,
      "name": "Soil_Dirt"
    },
    {
      "x": -13,
      "y": 3,
      "z": -5,
      "name": "Soil_Grass"
    },
    {
      "x": -13,
      "y": 0,
      "z": -4,
      "name": "Soil_Dirt"
    },
    {
      "x": -13,
      "y": 1,
      "z": -4,
      "name": "Soil_Dirt"
    },
    {
      "x": -13,
      "y": 2,
      "z": -4,
      "name": "Soil_Dirt"
    },
    {
      "x": -13,
      "y": 3,
      "z": -4,
      "name": "Soil_Grass"
    },
    {
      "x": -13,
      "y": 0,
      "z": -3,
      "name": "Soil_Dirt"
    },
    {
      "x": -13,
      "y": 1,
      "z": -3,
      "name": "Soil_Dirt"
    },
    {
      "x": -13,
      "y": 2,
      "z": -3,
      "name": "Soil_Dirt"
    },
    {
      "x": -13,
      "y": 3,
      "z": -3,
      "name": "Rock_Ledge_Brick_Ornate"
    },
    {
      "x": -13,
      "y": 0,
      "z": -2,
      "name": "Soil_Dirt"
    },
    {
      "x": -13,
      "y": 1,
      "z": -2,
      "name": "Soil_Dirt"
    },
    {
      "x": -13,
      "y": 2,
      "z": -2,
      "name": "Soil_Dirt"
    },
    {
      "x": -13,
      "y": 3,
      "z": -2,
      "name": "Rock_Ledge_Cobble"
    },
    {
      "x": -13,
      "y": 0,
      "z": -1,
      "name": "Soil_Dirt"
    },
    {
      "x": -13,
      "y": 1,
      "z": -1,
      "name": "Soil_Dirt"
    },
    {
      "x": -13,
      "y": 2,
      "z": -1,
      "name": "Soil_Dirt"
    },
    {
      "x": -13,
      "y": 3,
      "z": -1,
      "name": "Rock_Ledge_Cobble"
    },
    {
      "x": -13,
      "y": 0,
      "z": 0,
      "name": "Soil_Dirt"
    },
    {
      "x": -13,
      "y": 1,
      "z": 0,
      "name": "Soil_Dirt"
    },
    {
      "x": -13,
      "y": 2,
      "z": 0,
      "name": "Soil_Dirt"
    },
    {
      "x": -13,
      "y": 3,
      "z": 0,
      "name": "Rock_Ledge_Brick"
    },
    {
      "x": -13,
      "y": 0,
      "z": 1,
      "name": "Soil_Dirt"
    },
    {
      "x": -13,
      "y": 1,
      "z": 1,
      "name": "Soil_Dirt"
    },
    {
      "x": -13,
      "y": 2,
      "z": 1,
      "name": "Soil_Dirt"
    },
    {
      "x": -13,
      "y": 3,
      "z": 1,
      "name": "Rock_Ledge_Brick_Smooth"
    },
    {
      "x": -13,
      "y": 0,
      "z": 2,
      "name": "Soil_Dirt"
    },
    {
      "x": -13,
      "y": 1,
      "z": 2,
      "name": "Soil_Dirt"
    },
    {
      "x": -13,
      "y": 2,
      "z": 2,
      "name": "Soil_Dirt"
    },
    {
      "x": -13,
      "y": 3,
      "z": 2,
      "name": "Rock_Ledge_Cobble"
    },
    {
      "x": -13,
      "y": 0,
      "z": 3,
      "name": "Soil_Dirt"
    },
    {
      "x": -13,
      "y": 1,
      "z": 3,
      "name": "Soil_Dirt"
    },
    {
      "x": -13,
      "y": 2,
      "z": 3,
      "name": "Soil_Dirt"
    },
    {
      "x": -13,
      "y": 3,
      "z": 3,
      "name": "Rock_Ledge_Brick_Ornate"
    },
    {
      "x": -13,
      "y": 0,
      "z": 4,
      "name": "Soil_Dirt"
    },
    {
      "x": -13,
      "y": 1,
      "z": 4,
      "name": "Soil_Dirt"
    },
    {
      "x": -13,
      "y": 2,
      "z": 4,
      "name": "Soil_Dirt"
    },
    {
      "x": -13,
      "y": 3,
      "z": 4,
      "name": "Rock_Ledge_Brick"
    },
    {
      "x": -13,
      "y": 0,
      "z": 5,
      "name": "Soil_Dirt"
    },
    {
      "x": -13,
      "y": 1,
      "z": 5,
      "name": "Soil_Dirt"
    },
    {
      "x": -13,
      "y": 2,
      "z": 5,
      "name": "Soil_Dirt"
    },
    {
      "x": -13,
      "y": 3,
      "z": 5,
      "name": "Rock_Ledge_Brick_Ornate"
    },
    {
      "x": -13,
      "y": 0,
      "z": 6,
      "name": "Soil_Dirt"
    },
    {
      "x": -13,
      "y": 1,
      "z": 6,
      "name": "Soil_Dirt"
    },
    {
      "x": -13,
      "y": 2,
      "z": 6,
      "name": "Soil_Dirt"
    },
    {
      "x": -13,
      "y": 3,
      "z": 6,
      "name": "Rock_Ledge_Cobble"
    },
    {
      "x": -13,
      "y": 0,
      "z": 7,
      "name": "Soil_Dirt"
    },
    {
      "x": -13,
      "y": 1,
      "z": 7,
      "name": "Soil_Dirt"
    },
    {
      "x": -13,
      "y": 2,
      "z": 7,
      "name": "Soil_Dirt"
    },
    {
      "x": -13,
      "y": 3,
      "z": 7,
      "name": "Rock_Ledge_Brick_Smooth"
    },
    {
      "x": -13,
      "y": 0,
      "z": 8,
      "name": "Soil_Dirt"
    },
    {
      "x": -13,
      "y": 1,
      "z": 8,
      "name": "Soil_Dirt"
    },
    {
      "x": -13,
      "y": 2,
      "z": 8,
      "name": "Soil_Dirt"
    },
    {
      "x": -13,
      "y": 3,
      "z": 8,
      "name": "Rock_Ledge_Brick"
    },
    {
      "x": -13,
      "y": 0,
      "z": 9,
      "name": "Soil_Dirt"
    },
    {
      "x": -13,
      "y": 1,
      "z": 9,
      "name": "Soil_Dirt"
    },
    {
      "x": -13,
      "y": 2,
      "z": 9,
      "name": "Soil_Dirt"
    },
    {
      "x": -13,
      "y": 3,
      "z": 9,
      "name": "Rock_Ledge_Brick_Decorative"
    },
    {
      "x": -13,
      "y": 0,
      "z": 10,
      "name": "Soil_Dirt"
    },
    {
      "x": -13,
      "y": 1,
      "z": 10,
      "name": "Soil_Dirt"
    },
    {
      "x": -13,
      "y": 2,
      "z": 10,
      "name": "Soil_Dirt"
    },
    {
      "x": -13,
      "y": 3,
      "z": 10,
      "name": "Rock_Ledge_Brick_Smooth"
    },
    {
      "x": -13,
      "y": 0,
      "z": 11,
      "name": "Soil_Dirt"
    },
    {
      "x": -13,
      "y": 1,
      "z": 11,
      "name": "Soil_Dirt"
    },
    {
      "x": -13,
      "y": 2,
      "z": 11,
      "name": "Soil_Dirt"
    },
    {
      "x": -13,
      "y": 3,
      "z": 11,
      "name": "Rock_Ledge_Cobble"
    },
    {
      "x": -13,
      "y": 0,
      "z": 12,
      "name": "Soil_Dirt"
    },
    {
      "x": -13,
      "y": 1,
      "z": 12,
      "name": "Soil_Dirt"
    },
    {
      "x": -13,
      "y": 2,
      "z": 12,
      "name": "Soil_Dirt"
    },
    {
      "x": -13,
      "y": 3,
      "z": 12,
      "name": "Rock_Ledge_Cobble"
    },
    {
      "x": -13,
      "y": 0,
      "z": 13,
      "name": "Soil_Dirt"
    },
    {
      "x": -13,
      "y": 1,
      "z": 13,
      "name": "Soil_Dirt"
    },
    {
      "x": -13,
      "y": 2,
      "z": 13,
      "name": "Soil_Dirt"
    },
    {
      "x": -13,
      "y": 3,
      "z": 13,
      "name": "Rock_Ledge_Cobble"
    },
    {
      "x": -13,
      "y": 0,
      "z": 14,
      "name": "Soil_Dirt"
    },
    {
      "x": -13,
      "y": 1,
      "z": 14,
      "name": "Soil_Dirt"
    },
    {
      "x": -13,
      "y": 2,
      "z": 14,
      "name": "Soil_Dirt"
    },
    {
      "x": -13,
      "y": 3,
      "z": 14,
      "name": "Rock_Ledge_Brick_Ornate"
    },
    {
      "x": -13,
      "y": 0,
      "z": 15,
      "name": "Soil_Dirt"
    },
    {
      "x": -13,
      "y": 1,
      "z": 15,
      "name": "Soil_Dirt"
    },
    {
      "x": -13,
      "y": 2,
      "z": 15,
      "name": "Soil_Dirt"
    },
    {
      "x": -13,
      "y": 3,
      "z": 15,
      "name": "Rock_Ledge_Brick_Smooth"
    },
    {
      "x": -13,
      "y": 0,
      "z": 16,
      "name": "Soil_Dirt"
    },
    {
      "x": -13,
      "y": 1,
      "z": 16,
      "name": "Soil_Dirt"
    },
    {
      "x": -13,
      "y": 2,
      "z": 16,
      "name": "Soil_Dirt"
    },
    {
      "x": -13,
      "y": 3,
      "z": 16,
      "name": "Rock_Ledge_Brick_Decorative"
    },
    {
      "x": -12,
      "y": 0,
      "z": -15,
      "name": "Soil_Dirt"
    },
    {
      "x": -12,
      "y": 1,
      "z": -15,
      "name": "Soil_Dirt"
    },
    {
      "x": -12,
      "y": 2,
      "z": -15,
      "name": "Soil_Dirt"
    },
    {
      "x": -12,
      "y": 3,
      "z": -15,
      "name": "Rock_Ledge_Brick_Smooth"
    },
    {
      "x": -12,
      "y": 0,
      "z": -14,
      "name": "Soil_Dirt"
    },
    {
      "x": -12,
      "y": 1,
      "z": -14,
      "name": "Soil_Dirt"
    },
    {
      "x": -12,
      "y": 2,
      "z": -14,
      "name": "Soil_Dirt"
    },
    {
      "x": -12,
      "y": 3,
      "z": -14,
      "name": "Rock_Ledge_Brick_Smooth"
    },
    {
      "x": -12,
      "y": 0,
      "z": -13,
      "name": "Soil_Dirt"
    },
    {
      "x": -12,
      "y": 1,
      "z": -13,
      "name": "Soil_Dirt"
    },
    {
      "x": -12,
      "y": 2,
      "z": -13,
      "name": "Soil_Dirt"
    },
    {
      "x": -12,
      "y": 3,
      "z": -13,
      "name": "Rock_Ledge_Brick_Smooth"
    },
    {
      "x": -12,
      "y": 0,
      "z": -12,
      "name": "Soil_Dirt"
    },
    {
      "x": -12,
      "y": 1,
      "z": -12,
      "name": "Soil_Dirt"
    },
    {
      "x": -12,
      "y": 2,
      "z": -12,
      "name": "Soil_Dirt"
    },
    {
      "x": -12,
      "y": 3,
      "z": -12,
      "name": "Rock_Ledge_Brick"
    },
    {
      "x": -12,
      "y": 0,
      "z": -11,
      "name": "Soil_Dirt"
    },
    {
      "x": -12,
      "y": 1,
      "z": -11,
      "name": "Soil_Dirt"
    },
    {
      "x": -12,
      "y": 2,
      "z": -11,
      "name": "Soil_Dirt"
    },
    {
      "x": -12,
      "y": 3,
      "z": -11,
      "name": "Soil_Dirt"
    },
    {
      "x": -12,
      "y": 4,
      "z": -11,
      "name": "Rock_Sandstone_Red_Brick_Smooth"
    },
    {
      "x": -12,
      "y": 5,
      "z": -11,
      "name": "Rock_Sandstone_Red_Brick_Smooth"
    },
    {
      "x": -12,
      "y": 6,
      "z": -11,
      "name": "Rock_Sandstone_Red_Brick_Smooth"
    },
    {
      "x": -12,
      "y": 7,
      "z": -11,
      "name": "Rock_Sandstone_Red_Brick_Smooth"
    },
    {
      "x": -12,
      "y": 8,
      "z": -11,
      "name": "Rock_Sandstone_Red_Brick_Smooth"
    },
    {
      "x": -12,
      "y": 9,
      "z": -11,
      "name": "Rock_Sandstone_Red_Brick_Smooth"
    },
    {
      "x": -12,
      "y": 10,
      "z": -11,
      "name": "Rock_Sandstone_Red_Brick_Smooth"
    },
    {
      "x": -12,
      "y": 11,
      "z": -11,
      "name": "Rock_Sandstone_Red_Brick_Smooth"
    },
    {
      "x": -12,
      "y": 12,
      "z": -11,
      "name": "Rock_Sandstone_Red_Brick_Smooth"
    },
    {
      "x": -12,
      "y": 0,
      "z": -10,
      "name": "Soil_Dirt"
    },
    {
      "x": -12,
      "y": 1,
      "z": -10,
      "name": "Soil_Dirt"
    },
    {
      "x": -12,
      "y": 2,
      "z": -10,
      "name": "Soil_Dirt"
    },
    {
      "x": -12,
      "y": 3,
      "z": -10,
      "name": "Soil_Dirt"
    },
    {
      "x": -12,
      "y": 4,
      "z": -10,
      "name": "Rock_Sandstone_Red_Brick_Smooth"
    },
    {
      "x": -12,
      "y": 5,
      "z": -10,
      "name": "Rock_Sandstone_Red_Brick_Smooth"
    },
    {
      "x": -12,
      "y": 6,
      "z": -10,
      "name": "Rock_Sandstone_Red_Brick_Smooth"
    },
    {
      "x": -12,
      "y": 7,
      "z": -10,
      "name": "Rock_Sandstone_Red_Brick_Smooth"
    },
    {
      "x": -12,
      "y": 8,
      "z": -10,
      "name": "Rock_Sandstone_Red_Brick_Smooth"
    },
    {
      "x": -12,
      "y": 9,
      "z": -10,
      "name": "Rock_Sandstone_Red_Brick_Smooth"
    },
    {
      "x": -12,
      "y": 10,
      "z": -10,
      "name": "Rock_Sandstone_Red_Brick_Smooth"
    },
    {
      "x": -12,
      "y": 11,
      "z": -10,
      "name": "Rock_Sandstone_Red_Brick_Smooth"
    },
    {
      "x": -12,
      "y": 12,
      "z": -10,
      "name": "Rock_Sandstone_Red_Brick_Smooth"
    },
    {
      "x": -12,
      "y": 0,
      "z": -9,
      "name": "Soil_Dirt"
    },
    {
      "x": -12,
      "y": 1,
      "z": -9,
      "name": "Soil_Dirt"
    },
    {
      "x": -12,
      "y": 2,
      "z": -9,
      "name": "Soil_Dirt"
    },
    {
      "x": -12,
      "y": 3,
      "z": -9,
      "name": "Soil_Dirt"
    },
    {
      "x": -12,
      "y": 4,
      "z": -9,
      "name": "Rock_Sandstone_Red_Brick_Smooth"
    },
    {
      "x": -12,
      "y": 5,
      "z": -9,
      "name": "Rock_Sandstone_Red_Brick_Smooth"
    },
    {
      "x": -12,
      "y": 6,
      "z": -9,
      "name": "Rock_Sandstone_Red_Brick_Smooth"
    },
    {
      "x": -12,
      "y": 7,
      "z": -9,
      "name": "Rock_Sandstone_Red_Brick_Smooth"
    },
    {
      "x": -12,
      "y": 8,
      "z": -9,
      "name": "Rock_Sandstone_Red_Brick_Smooth"
    },
    {
      "x": -12,
      "y": 9,
      "z": -9,
      "name": "Rock_Sandstone_Red_Brick_Smooth"
    },
    {
      "x": -12,
      "y": 10,
      "z": -9,
      "name": "Rock_Sandstone_Red_Brick_Smooth"
    },
    {
      "x": -12,
      "y": 11,
      "z": -9,
      "name": "Rock_Sandstone_Red_Brick_Smooth"
    },
    {
      "x": -12,
      "y": 12,
      "z": -9,
      "name": "Rock_Sandstone_Red_Brick_Smooth"
    },
    {
      "x": -12,
      "y": 0,
      "z": -8,
      "name": "Soil_Dirt"
    },
    {
      "x": -12,
      "y": 1,
      "z": -8,
      "name": "Soil_Dirt"
    },
    {
      "x": -12,
      "y": 2,
      "z": -8,
      "name": "Soil_Dirt"
    },
    {
      "x": -12,
      "y": 3,
      "z": -8,
      "name": "Soil_Dirt"
    },
    {
      "x": -12,
      "y": 4,
      "z": -8,
      "name": "Rock_Sandstone_Red_Brick_Smooth"
    },
    {
      "x": -12,
      "y": 5,
      "z": -8,
      "name": "Rock_Sandstone_Red_Brick_Smooth"
    },
    {
      "x": -12,
      "y": 6,
      "z": -8,
      "name": "Rock_Sandstone_Red_Brick_Smooth"
    },
    {
      "x": -12,
      "y": 7,
      "z": -8,
      "name": "Rock_Sandstone_Red_Brick_Smooth"
    },
    {
      "x": -12,
      "y": 8,
      "z": -8,
      "name": "Rock_Sandstone_Red_Brick_Smooth"
    },
    {
      "x": -12,
      "y": 9,
      "z": -8,
      "name": "Rock_Sandstone_Red_Brick_Smooth"
    },
    {
      "x": -12,
      "y": 10,
      "z": -8,
      "name": "Rock_Sandstone_Red_Brick_Smooth"
    },
    {
      "x": -12,
      "y": 11,
      "z": -8,
      "name": "Rock_Sandstone_Red_Brick_Smooth"
    },
    {
      "x": -12,
      "y": 12,
      "z": -8,
      "name": "Rock_Sandstone_Red_Brick_Smooth"
    },
    {
      "x": -12,
      "y": 0,
      "z": -7,
      "name": "Soil_Dirt"
    },
    {
      "x": -12,
      "y": 1,
      "z": -7,
      "name": "Soil_Dirt"
    },
    {
      "x": -12,
      "y": 2,
      "z": -7,
      "name": "Soil_Dirt"
    },
    {
      "x": -12,
      "y": 3,
      "z": -7,
      "name": "Soil_Dirt"
    },
    {
      "x": -12,
      "y": 4,
      "z": -7,
      "name": "Rock_Sandstone_Red_Brick_Smooth"
    },
    {
      "x": -12,
      "y": 5,
      "z": -7,
      "name": "Rock_Sandstone_Red_Brick_Smooth"
    },
    {
      "x": -12,
      "y": 6,
      "z": -7,
      "name": "Rock_Sandstone_Red_Brick_Smooth"
    },
    {
      "x": -12,
      "y": 7,
      "z": -7,
      "name": "Rock_Sandstone_Red_Brick_Smooth"
    },
    {
      "x": -12,
      "y": 8,
      "z": -7,
      "name": "Rock_Sandstone_Red_Brick_Smooth"
    },
    {
      "x": -12,
      "y": 9,
      "z": -7,
      "name": "Rock_Sandstone_Red_Brick_Smooth"
    },
    {
      "x": -12,
      "y": 10,
      "z": -7,
      "name": "Rock_Sandstone_Red_Brick_Smooth"
    },
    {
      "x": -12,
      "y": 11,
      "z": -7,
      "name": "Rock_Sandstone_Red_Brick_Smooth"
    },
    {
      "x": -12,
      "y": 12,
      "z": -7,
      "name": "Rock_Sandstone_Red_Brick_Smooth"
    },
    {
      "x": -12,
      "y": 0,
      "z": -6,
      "name": "Soil_Dirt"
    },
    {
      "x": -12,
      "y": 1,
      "z": -6,
      "name": "Soil_Dirt"
    },
    {
      "x": -12,
      "y": 2,
      "z": -6,
      "name": "Soil_Dirt"
    },
    {
      "x": -12,
      "y": 3,
      "z": -6,
      "name": "Soil_Dirt"
    },
    {
      "x": -12,
      "y": 4,
      "z": -6,
      "name": "Rock_Sandstone_Red_Brick_Smooth"
    },
    {
      "x": -12,
      "y": 5,
      "z": -6,
      "name": "Rock_Sandstone_Red_Brick_Smooth"
    },
    {
      "x": -12,
      "y": 6,
      "z": -6,
      "name": "Rock_Sandstone_Red_Brick_Smooth"
    },
    {
      "x": -12,
      "y": 7,
      "z": -6,
      "name": "Rock_Sandstone_Red_Brick_Smooth"
    },
    {
      "x": -12,
      "y": 8,
      "z": -6,
      "name": "Rock_Sandstone_Red_Brick_Smooth"
    },
    {
      "x": -12,
      "y": 9,
      "z": -6,
      "name": "Rock_Sandstone_Red_Brick_Smooth"
    },
    {
      "x": -12,
      "y": 10,
      "z": -6,
      "name": "Rock_Sandstone_Red_Brick_Smooth"
    },
    {
      "x": -12,
      "y": 11,
      "z": -6,
      "name": "Rock_Sandstone_Red_Brick_Smooth"
    },
    {
      "x": -12,
      "y": 12,
      "z": -6,
      "name": "Rock_Sandstone_Red_Brick_Smooth"
    },
    {
      "x": -12,
      "y": 0,
      "z": -5,
      "name": "Soil_Dirt"
    },
    {
      "x": -12,
      "y": 1,
      "z": -5,
      "name": "Soil_Dirt"
    },
    {
      "x": -12,
      "y": 2,
      "z": -5,
      "name": "Soil_Dirt"
    },
    {
      "x": -12,
      "y": 3,
      "z": -5,
      "name": "Rock_Ledge_Cobble"
    },
    {
      "x": -12,
      "y": 4,
      "z": -5,
      "name": "Rock_Sandstone_Red_Brick_Smooth"
    },
    {
      "x": -12,
      "y": 5,
      "z": -5,
      "name": "Rock_Sandstone_Red_Brick_Smooth"
    },
    {
      "x": -12,
      "y": 6,
      "z": -5,
      "name": "Rock_Sandstone_Red_Brick_Smooth"
    },
    {
      "x": -12,
      "y": 7,
      "z": -5,
      "name": "Rock_Sandstone_Red_Brick_Smooth"
    },
    {
      "x": -12,
      "y": 8,
      "z": -5,
      "name": "Rock_Sandstone_Red_Brick_Smooth"
    },
    {
      "x": -12,
      "y": 9,
      "z": -5,
      "name": "Rock_Sandstone_Red_Brick_Smooth"
    },
    {
      "x": -12,
      "y": 10,
      "z": -5,
      "name": "Rock_Sandstone_Red_Brick_Smooth"
    },
    {
      "x": -12,
      "y": 11,
      "z": -5,
      "name": "Rock_Sandstone_Red_Brick_Smooth"
    },
    {
      "x": -12,
      "y": 12,
      "z": -5,
      "name": "Rock_Sandstone_Red_Brick_Smooth"
    },
    {
      "x": -12,
      "y": 0,
      "z": -4,
      "name": "Soil_Dirt"
    },
    {
      "x": -12,
      "y": 1,
      "z": -4,
      "name": "Soil_Dirt"
    },
    {
      "x": -12,
      "y": 2,
      "z": -4,
      "name": "Soil_Dirt"
    },
    {
      "x": -12,
      "y": 3,
      "z": -4,
      "name": "Rock_Ledge_Brick_Decorative"
    },
    {
      "x": -12,
      "y": 0,
      "z": -3,
      "name": "Soil_Dirt"
    },
    {
      "x": -12,
      "y": 1,
      "z": -3,
      "name": "Soil_Dirt"
    },
    {
      "x": -12,
      "y": 2,
      "z": -3,
      "name": "Soil_Dirt"
    },
    {
      "x": -12,
      "y": 3,
      "z": -3,
      "name": "Rock_Ledge_Brick_Decorative"
    },
    {
      "x": -12,
      "y": 0,
      "z": -2,
      "name": "Soil_Dirt"
    },
    {
      "x": -12,
      "y": 1,
      "z": -2,
      "name": "Soil_Dirt"
    },
    {
      "x": -12,
      "y": 2,
      "z": -2,
      "name": "Soil_Dirt"
    },
    {
      "x": -12,
      "y": 3,
      "z": -2,
      "name": "Rock_Ledge_Brick_Smooth"
    },
    {
      "x": -12,
      "y": 0,
      "z": -1,
      "name": "Soil_Dirt"
    },
    {
      "x": -12,
      "y": 1,
      "z": -1,
      "name": "Soil_Dirt"
    },
    {
      "x": -12,
      "y": 2,
      "z": -1,
      "name": "Soil_Dirt"
    },
    {
      "x": -12,
      "y": 3,
      "z": -1,
      "name": "Rock_Ledge_Cobble"
    },
    {
      "x": -12,
      "y": 0,
      "z": 0,
      "name": "Soil_Dirt"
    },
    {
      "x": -12,
      "y": 1,
      "z": 0,
      "name": "Soil_Dirt"
    },
    {
      "x": -12,
      "y": 2,
      "z": 0,
      "name": "Soil_Dirt"
    },
    {
      "x": -12,
      "y": 3,
      "z": 0,
      "name": "Rock_Ledge_Cobble"
    },
    {
      "x": -12,
      "y": 0,
      "z": 1,
      "name": "Soil_Dirt"
    },
    {
      "x": -12,
      "y": 1,
      "z": 1,
      "name": "Soil_Dirt"
    },
    {
      "x": -12,
      "y": 2,
      "z": 1,
      "name": "Soil_Dirt"
    },
    {
      "x": -12,
      "y": 3,
      "z": 1,
      "name": "Rock_Ledge_Brick_Smooth"
    },
    {
      "x": -12,
      "y": 0,
      "z": 2,
      "name": "Soil_Dirt"
    },
    {
      "x": -12,
      "y": 1,
      "z": 2,
      "name": "Soil_Dirt"
    },
    {
      "x": -12,
      "y": 2,
      "z": 2,
      "name": "Soil_Dirt"
    },
    {
      "x": -12,
      "y": 3,
      "z": 2,
      "name": "Rock_Ledge_Cobble"
    },
    {
      "x": -12,
      "y": 0,
      "z": 3,
      "name": "Soil_Dirt"
    },
    {
      "x": -12,
      "y": 1,
      "z": 3,
      "name": "Soil_Dirt"
    },
    {
      "x": -12,
      "y": 2,
      "z": 3,
      "name": "Soil_Dirt"
    },
    {
      "x": -12,
      "y": 3,
      "z": 3,
      "name": "Rock_Ledge_Brick_Smooth"
    },
    {
      "x": -12,
      "y": 0,
      "z": 4,
      "name": "Soil_Dirt"
    },
    {
      "x": -12,
      "y": 1,
      "z": 4,
      "name": "Soil_Dirt"
    },
    {
      "x": -12,
      "y": 2,
      "z": 4,
      "name": "Soil_Dirt"
    },
    {
      "x": -12,
      "y": 3,
      "z": 4,
      "name": "Rock_Ledge_Brick_Smooth"
    },
    {
      "x": -12,
      "y": 0,
      "z": 5,
      "name": "Soil_Dirt"
    },
    {
      "x": -12,
      "y": 1,
      "z": 5,
      "name": "Soil_Dirt"
    },
    {
      "x": -12,
      "y": 2,
      "z": 5,
      "name": "Soil_Dirt"
    },
    {
      "x": -12,
      "y": 3,
      "z": 5,
      "name": "Rock_Ledge_Brick_Smooth"
    },
    {
      "x": -12,
      "y": 0,
      "z": 6,
      "name": "Soil_Dirt"
    },
    {
      "x": -12,
      "y": 1,
      "z": 6,
      "name": "Soil_Dirt"
    },
    {
      "x": -12,
      "y": 2,
      "z": 6,
      "name": "Soil_Dirt"
    },
    {
      "x": -12,
      "y": 3,
      "z": 6,
      "name": "Rock_Ledge_Brick_Ornate"
    },
    {
      "x": -12,
      "y": 0,
      "z": 7,
      "name": "Soil_Dirt"
    },
    {
      "x": -12,
      "y": 1,
      "z": 7,
      "name": "Soil_Dirt"
    },
    {
      "x": -12,
      "y": 2,
      "z": 7,
      "name": "Soil_Dirt"
    },
    {
      "x": -12,
      "y": 3,
      "z": 7,
      "name": "Rock_Ledge_Brick_Ornate"
    },
    {
      "x": -12,
      "y": 0,
      "z": 8,
      "name": "Soil_Dirt"
    },
    {
      "x": -12,
      "y": 1,
      "z": 8,
      "name": "Soil_Dirt"
    },
    {
      "x": -12,
      "y": 2,
      "z": 8,
      "name": "Soil_Dirt"
    },
    {
      "x": -12,
      "y": 3,
      "z": 8,
      "name": "Rock_Ledge_Cobble"
    },
    {
      "x": -12,
      "y": 0,
      "z": 9,
      "name": "Soil_Dirt"
    },
    {
      "x": -12,
      "y": 1,
      "z": 9,
      "name": "Soil_Dirt"
    },
    {
      "x": -12,
      "y": 2,
      "z": 9,
      "name": "Soil_Dirt"
    },
    {
      "x": -12,
      "y": 3,
      "z": 9,
      "name": "Rock_Ledge_Brick_Decorative"
    },
    {
      "x": -12,
      "y": 0,
      "z": 10,
      "name": "Soil_Dirt"
    },
    {
      "x": -12,
      "y": 1,
      "z": 10,
      "name": "Soil_Dirt"
    },
    {
      "x": -12,
      "y": 2,
      "z": 10,
      "name": "Soil_Dirt"
    },
    {
      "x": -12,
      "y": 3,
      "z": 10,
      "name": "Rock_Ledge_Brick"
    },
    {
      "x": -12,
      "y": 0,
      "z": 11,
      "name": "Soil_Dirt"
    },
    {
      "x": -12,
      "y": 1,
      "z": 11,
      "name": "Soil_Dirt"
    },
    {
      "x": -12,
      "y": 2,
      "z": 11,
      "name": "Soil_Dirt"
    },
    {
      "x": -12,
      "y": 3,
      "z": 11,
      "name": "Rock_Ledge_Brick"
    },
    {
      "x": -12,
      "y": 0,
      "z": 12,
      "name": "Soil_Dirt"
    },
    {
      "x": -12,
      "y": 1,
      "z": 12,
      "name": "Soil_Dirt"
    },
    {
      "x": -12,
      "y": 2,
      "z": 12,
      "name": "Soil_Dirt"
    },
    {
      "x": -12,
      "y": 3,
      "z": 12,
      "name": "Rock_Ledge_Brick_Ornate"
    },
    {
      "x": -12,
      "y": 0,
      "z": 13,
      "name": "Soil_Dirt"
    },
    {
      "x": -12,
      "y": 1,
      "z": 13,
      "name": "Soil_Dirt"
    },
    {
      "x": -12,
      "y": 2,
      "z": 13,
      "name": "Soil_Dirt"
    },
    {
      "x": -12,
      "y": 3,
      "z": 13,
      "name": "Rock_Ledge_Brick_Ornate"
    },
    {
      "x": -12,
      "y": 0,
      "z": 14,
      "name": "Soil_Dirt"
    },
    {
      "x": -12,
      "y": 1,
      "z": 14,
      "name": "Soil_Dirt"
    },
    {
      "x": -12,
      "y": 2,
      "z": 14,
      "name": "Soil_Dirt"
    },
    {
      "x": -12,
      "y": 3,
      "z": 14,
      "name": "Rock_Ledge_Cobble"
    },
    {
      "x": -12,
      "y": 0,
      "z": 15,
      "name": "Soil_Dirt"
    },
    {
      "x": -12,
      "y": 1,
      "z": 15,
      "name": "Soil_Dirt"
    },
    {
      "x": -12,
      "y": 2,
      "z": 15,
      "name": "Soil_Dirt"
    },
    {
      "x": -12,
      "y": 3,
      "z": 15,
      "name": "Rock_Ledge_Brick"
    },
    {
      "x": -12,
      "y": 0,
      "z": 16,
      "name": "Soil_Dirt"
    },
    {
      "x": -12,
      "y": 1,
      "z": 16,
      "name": "Soil_Dirt"
    },
    {
      "x": -12,
      "y": 2,
      "z": 16,
      "name": "Soil_Dirt"
    },
    {
      "x": -12,
      "y": 3,
      "z": 16,
      "name": "Rock_Ledge_Brick_Ornate"
    },
    {
      "x": -11,
      "y": 0,
      "z": -15,
      "name": "Soil_Dirt"
    },
    {
      "x": -11,
      "y": 1,
      "z": -15,
      "name": "Soil_Dirt"
    },
    {
      "x": -11,
      "y": 2,
      "z": -15,
      "name": "Soil_Dirt"
    },
    {
      "x": -11,
      "y": 3,
      "z": -15,
      "name": "Rock_Ledge_Brick_Smooth"
    },
    {
      "x": -11,
      "y": 0,
      "z": -14,
      "name": "Soil_Dirt"
    },
    {
      "x": -11,
      "y": 1,
      "z": -14,
      "name": "Soil_Dirt"
    },
    {
      "x": -11,
      "y": 2,
      "z": -14,
      "name": "Soil_Dirt"
    },
    {
      "x": -11,
      "y": 3,
      "z": -14,
      "name": "Rock_Ledge_Cobble"
    },
    {
      "x": -11,
      "y": 0,
      "z": -13,
      "name": "Soil_Dirt"
    },
    {
      "x": -11,
      "y": 1,
      "z": -13,
      "name": "Soil_Dirt"
    },
    {
      "x": -11,
      "y": 2,
      "z": -13,
      "name": "Soil_Dirt"
    },
    {
      "x": -11,
      "y": 3,
      "z": -13,
      "name": "Rock_Ledge_Brick_Smooth"
    },
    {
      "x": -11,
      "y": 0,
      "z": -12,
      "name": "Soil_Dirt"
    },
    {
      "x": -11,
      "y": 1,
      "z": -12,
      "name": "Soil_Dirt"
    },
    {
      "x": -11,
      "y": 2,
      "z": -12,
      "name": "Soil_Dirt"
    },
    {
      "x": -11,
      "y": 3,
      "z": -12,
      "name": "Rock_Ledge_Brick"
    },
    {
      "x": -11,
      "y": 0,
      "z": -11,
      "name": "Soil_Dirt"
    },
    {
      "x": -11,
      "y": 1,
      "z": -11,
      "name": "Soil_Dirt"
    },
    {
      "x": -11,
      "y": 2,
      "z": -11,
      "name": "Soil_Dirt"
    },
    {
      "x": -11,
      "y": 3,
      "z": -11,
      "name": "Rock_Ledge_Brick"
    },
    {
      "x": -11,
      "y": 0,
      "z": -10,
      "name": "Soil_Dirt"
    },
    {
      "x": -11,
      "y": 1,
      "z": -10,
      "name": "Soil_Dirt"
    },
    {
      "x": -11,
      "y": 2,
      "z": -10,
      "name": "Soil_Dirt"
    },
    {
      "x": -11,
      "y": 3,
      "z": -10,
      "name": "Rock_Ledge_Brick"
    },
    {
      "x": -11,
      "y": 0,
      "z": -9,
      "name": "Soil_Dirt"
    },
    {
      "x": -11,
      "y": 1,
      "z": -9,
      "name": "Soil_Dirt"
    },
    {
      "x": -11,
      "y": 2,
      "z": -9,
      "name": "Soil_Dirt"
    },
    {
      "x": -11,
      "y": 3,
      "z": -9,
      "name": "Rock_Ledge_Brick"
    },
    {
      "x": -11,
      "y": 0,
      "z": -8,
      "name": "Soil_Dirt"
    },
    {
      "x": -11,
      "y": 1,
      "z": -8,
      "name": "Soil_Dirt"
    },
    {
      "x": -11,
      "y": 2,
      "z": -8,
      "name": "Soil_Dirt"
    },
    {
      "x": -11,
      "y": 3,
      "z": -8,
      "name": "Rock_Ledge_Brick"
    },
    {
      "x": -11,
      "y": 0,
      "z": -7,
      "name": "Soil_Dirt"
    },
    {
      "x": -11,
      "y": 1,
      "z": -7,
      "name": "Soil_Dirt"
    },
    {
      "x": -11,
      "y": 2,
      "z": -7,
      "name": "Soil_Dirt"
    },
    {
      "x": -11,
      "y": 3,
      "z": -7,
      "name": "Soil_Dirt"
    },
    {
      "x": -11,
      "y": 4,
      "z": -7,
      "name": "Rock_Stone_Aqua"
    },
    {
      "x": -11,
      "y": 5,
      "z": -7,
      "name": "Rock_Stone_Aqua"
    },
    {
      "x": -11,
      "y": 6,
      "z": -7,
      "name": "Rock_Stone_Aqua"
    },
    {
      "x": -11,
      "y": 7,
      "z": -7,
      "name": "Rock_Stone_Aqua"
    },
    {
      "x": -11,
      "y": 8,
      "z": -7,
      "name": "Rock_Stone_Aqua"
    },
    {
      "x": -11,
      "y": 9,
      "z": -7,
      "name": "Rock_Stone_Aqua"
    },
    {
      "x": -11,
      "y": 0,
      "z": -6,
      "name": "Soil_Dirt"
    },
    {
      "x": -11,
      "y": 1,
      "z": -6,
      "name": "Soil_Dirt"
    },
    {
      "x": -11,
      "y": 2,
      "z": -6,
      "name": "Soil_Dirt"
    },
    {
      "x": -11,
      "y": 3,
      "z": -6,
      "name": "Soil_Grass"
    },
    {
      "x": -11,
      "y": 0,
      "z": -5,
      "name": "Soil_Dirt"
    },
    {
      "x": -11,
      "y": 1,
      "z": -5,
      "name": "Soil_Dirt"
    },
    {
      "x": -11,
      "y": 2,
      "z": -5,
      "name": "Soil_Dirt"
    },
    {
      "x": -11,
      "y": 3,
      "z": -5,
      "name": "Rock_Ledge_Brick"
    },
    {
      "x": -11,
      "y": 0,
      "z": -4,
      "name": "Soil_Dirt"
    },
    {
      "x": -11,
      "y": 1,
      "z": -4,
      "name": "Soil_Dirt"
    },
    {
      "x": -11,
      "y": 2,
      "z": -4,
      "name": "Soil_Dirt"
    },
    {
      "x": -11,
      "y": 3,
      "z": -4,
      "name": "Rock_Ledge_Brick_Smooth"
    },
    {
      "x": -11,
      "y": 0,
      "z": -3,
      "name": "Soil_Dirt"
    },
    {
      "x": -11,
      "y": 1,
      "z": -3,
      "name": "Soil_Dirt"
    },
    {
      "x": -11,
      "y": 2,
      "z": -3,
      "name": "Soil_Dirt"
    },
    {
      "x": -11,
      "y": 3,
      "z": -3,
      "name": "Rock_Ledge_Brick_Smooth"
    },
    {
      "x": -11,
      "y": 0,
      "z": -2,
      "name": "Soil_Dirt"
    },
    {
      "x": -11,
      "y": 1,
      "z": -2,
      "name": "Soil_Dirt"
    },
    {
      "x": -11,
      "y": 2,
      "z": -2,
      "name": "Soil_Dirt"
    },
    {
      "x": -11,
      "y": 3,
      "z": -2,
      "name": "Rock_Ledge_Brick_Smooth"
    },
    {
      "x": -11,
      "y": 0,
      "z": -1,
      "name": "Soil_Dirt"
    },
    {
      "x": -11,
      "y": 1,
      "z": -1,
      "name": "Soil_Dirt"
    },
    {
      "x": -11,
      "y": 2,
      "z": -1,
      "name": "Soil_Dirt"
    },
    {
      "x": -11,
      "y": 3,
      "z": -1,
      "name": "Rock_Ledge_Brick_Smooth"
    },
    {
      "x": -11,
      "y": 0,
      "z": 0,
      "name": "Soil_Dirt"
    },
    {
      "x": -11,
      "y": 1,
      "z": 0,
      "name": "Soil_Dirt"
    },
    {
      "x": -11,
      "y": 2,
      "z": 0,
      "name": "Soil_Dirt"
    },
    {
      "x": -11,
      "y": 3,
      "z": 0,
      "name": "Rock_Ledge_Cobble"
    },
    {
      "x": -11,
      "y": 0,
      "z": 1,
      "name": "Soil_Dirt"
    },
    {
      "x": -11,
      "y": 1,
      "z": 1,
      "name": "Soil_Dirt"
    },
    {
      "x": -11,
      "y": 2,
      "z": 1,
      "name": "Soil_Dirt"
    },
    {
      "x": -11,
      "y": 3,
      "z": 1,
      "name": "Rock_Ledge_Brick"
    },
    {
      "x": -11,
      "y": 0,
      "z": 2,
      "name": "Soil_Dirt"
    },
    {
      "x": -11,
      "y": 1,
      "z": 2,
      "name": "Soil_Dirt"
    },
    {
      "x": -11,
      "y": 2,
      "z": 2,
      "name": "Soil_Dirt"
    },
    {
      "x": -11,
      "y": 3,
      "z": 2,
      "name": "Rock_Ledge_Brick_Decorative"
    },
    {
      "x": -11,
      "y": 0,
      "z": 3,
      "name": "Soil_Dirt"
    },
    {
      "x": -11,
      "y": 1,
      "z": 3,
      "name": "Soil_Dirt"
    },
    {
      "x": -11,
      "y": 2,
      "z": 3,
      "name": "Soil_Dirt"
    },
    {
      "x": -11,
      "y": 3,
      "z": 3,
      "name": "Rock_Ledge_Brick_Ornate"
    },
    {
      "x": -11,
      "y": 0,
      "z": 4,
      "name": "Soil_Dirt"
    },
    {
      "x": -11,
      "y": 1,
      "z": 4,
      "name": "Soil_Dirt"
    },
    {
      "x": -11,
      "y": 2,
      "z": 4,
      "name": "Soil_Dirt"
    },
    {
      "x": -11,
      "y": 3,
      "z": 4,
      "name": "Rock_Ledge_Brick"
    },
    {
      "x": -11,
      "y": 0,
      "z": 5,
      "name": "Soil_Dirt"
    },
    {
      "x": -11,
      "y": 1,
      "z": 5,
      "name": "Soil_Dirt"
    },
    {
      "x": -11,
      "y": 2,
      "z": 5,
      "name": "Soil_Dirt"
    },
    {
      "x": -11,
      "y": 3,
      "z": 5,
      "name": "Rock_Ledge_Brick_Decorative"
    },
    {
      "x": -11,
      "y": 0,
      "z": 6,
      "name": "Soil_Dirt"
    },
    {
      "x": -11,
      "y": 1,
      "z": 6,
      "name": "Soil_Dirt"
    },
    {
      "x": -11,
      "y": 2,
      "z": 6,
      "name": "Soil_Dirt"
    },
    {
      "x": -11,
      "y": 3,
      "z": 6,
      "name": "Rock_Ledge_Brick_Ornate"
    },
    {
      "x": -11,
      "y": 0,
      "z": 7,
      "name": "Soil_Dirt"
    },
    {
      "x": -11,
      "y": 1,
      "z": 7,
      "name": "Soil_Dirt"
    },
    {
      "x": -11,
      "y": 2,
      "z": 7,
      "name": "Soil_Dirt"
    },
    {
      "x": -11,
      "y": 3,
      "z": 7,
      "name": "Rock_Ledge_Brick_Ornate"
    },
    {
      "x": -11,
      "y": 0,
      "z": 8,
      "name": "Soil_Dirt"
    },
    {
      "x": -11,
      "y": 1,
      "z": 8,
      "name": "Soil_Dirt"
    },
    {
      "x": -11,
      "y": 2,
      "z": 8,
      "name": "Soil_Dirt"
    },
    {
      "x": -11,
      "y": 3,
      "z": 8,
      "name": "Rock_Ledge_Cobble"
    },
    {
      "x": -11,
      "y": 0,
      "z": 9,
      "name": "Soil_Dirt"
    },
    {
      "x": -11,
      "y": 1,
      "z": 9,
      "name": "Soil_Dirt"
    },
    {
      "x": -11,
      "y": 2,
      "z": 9,
      "name": "Soil_Dirt"
    },
    {
      "x": -11,
      "y": 3,
      "z": 9,
      "name": "Rock_Ledge_Brick_Ornate"
    },
    {
      "x": -11,
      "y": 0,
      "z": 10,
      "name": "Soil_Dirt"
    },
    {
      "x": -11,
      "y": 1,
      "z": 10,
      "name": "Soil_Dirt"
    },
    {
      "x": -11,
      "y": 2,
      "z": 10,
      "name": "Soil_Dirt"
    },
    {
      "x": -11,
      "y": 3,
      "z": 10,
      "name": "Rock_Ledge_Brick_Smooth"
    },
    {
      "x": -11,
      "y": 0,
      "z": 11,
      "name": "Soil_Dirt"
    },
    {
      "x": -11,
      "y": 1,
      "z": 11,
      "name": "Soil_Dirt"
    },
    {
      "x": -11,
      "y": 2,
      "z": 11,
      "name": "Soil_Dirt"
    },
    {
      "x": -11,
      "y": 3,
      "z": 11,
      "name": "Rock_Ledge_Cobble"
    },
    {
      "x": -11,
      "y": 0,
      "z": 12,
      "name": "Soil_Dirt"
    },
    {
      "x": -11,
      "y": 1,
      "z": 12,
      "name": "Soil_Dirt"
    },
    {
      "x": -11,
      "y": 2,
      "z": 12,
      "name": "Soil_Dirt"
    },
    {
      "x": -11,
      "y": 3,
      "z": 12,
      "name": "Rock_Ledge_Brick_Smooth"
    },
    {
      "x": -11,
      "y": 0,
      "z": 13,
      "name": "Soil_Dirt"
    },
    {
      "x": -11,
      "y": 1,
      "z": 13,
      "name": "Soil_Dirt"
    },
    {
      "x": -11,
      "y": 2,
      "z": 13,
      "name": "Soil_Dirt"
    },
    {
      "x": -11,
      "y": 3,
      "z": 13,
      "name": "Rock_Ledge_Cobble"
    },
    {
      "x": -11,
      "y": 0,
      "z": 14,
      "name": "Soil_Dirt"
    },
    {
      "x": -11,
      "y": 1,
      "z": 14,
      "name": "Soil_Dirt"
    },
    {
      "x": -11,
      "y": 2,
      "z": 14,
      "name": "Soil_Dirt"
    },
    {
      "x": -11,
      "y": 3,
      "z": 14,
      "name": "Rock_Ledge_Brick"
    },
    {
      "x": -11,
      "y": 0,
      "z": 15,
      "name": "Soil_Dirt"
    },
    {
      "x": -11,
      "y": 1,
      "z": 15,
      "name": "Soil_Dirt"
    },
    {
      "x": -11,
      "y": 2,
      "z": 15,
      "name": "Soil_Dirt"
    },
    {
      "x": -11,
      "y": 3,
      "z": 15,
      "name": "Rock_Ledge_Cobble"
    },
    {
      "x": -11,
      "y": 0,
      "z": 16,
      "name": "Soil_Dirt"
    },
    {
      "x": -11,
      "y": 1,
      "z": 16,
      "name": "Soil_Dirt"
    },
    {
      "x": -11,
      "y": 2,
      "z": 16,
      "name": "Soil_Dirt"
    },
    {
      "x": -11,
      "y": 3,
      "z": 16,
      "name": "Rock_Ledge_Brick_Smooth"
    },
    {
      "x": -10,
      "y": 0,
      "z": -15,
      "name": "Soil_Dirt"
    },
    {
      "x": -10,
      "y": 1,
      "z": -15,
      "name": "Soil_Dirt"
    },
    {
      "x": -10,
      "y": 2,
      "z": -15,
      "name": "Soil_Dirt"
    },
    {
      "x": -10,
      "y": 3,
      "z": -15,
      "name": "Rock_Ledge_Brick_Smooth"
    },
    {
      "x": -10,
      "y": 0,
      "z": -14,
      "name": "Soil_Dirt"
    },
    {
      "x": -10,
      "y": 1,
      "z": -14,
      "name": "Soil_Dirt"
    },
    {
      "x": -10,
      "y": 2,
      "z": -14,
      "name": "Soil_Dirt"
    },
    {
      "x": -10,
      "y": 3,
      "z": -14,
      "name": "Rock_Ledge_Brick"
    },
    {
      "x": -10,
      "y": 0,
      "z": -13,
      "name": "Soil_Dirt"
    },
    {
      "x": -10,
      "y": 1,
      "z": -13,
      "name": "Soil_Dirt"
    },
    {
      "x": -10,
      "y": 2,
      "z": -13,
      "name": "Soil_Dirt"
    },
    {
      "x": -10,
      "y": 3,
      "z": -13,
      "name": "Rock_Ledge_Brick_Smooth"
    },
    {
      "x": -10,
      "y": 0,
      "z": -12,
      "name": "Soil_Dirt"
    },
    {
      "x": -10,
      "y": 1,
      "z": -12,
      "name": "Soil_Dirt"
    },
    {
      "x": -10,
      "y": 2,
      "z": -12,
      "name": "Soil_Dirt"
    },
    {
      "x": -10,
      "y": 3,
      "z": -12,
      "name": "Rock_Ledge_Brick"
    },
    {
      "x": -10,
      "y": 0,
      "z": -11,
      "name": "Soil_Dirt"
    },
    {
      "x": -10,
      "y": 1,
      "z": -11,
      "name": "Soil_Dirt"
    },
    {
      "x": -10,
      "y": 2,
      "z": -11,
      "name": "Soil_Dirt"
    },
    {
      "x": -10,
      "y": 3,
      "z": -11,
      "name": "Rock_Ledge_Brick"
    },
    {
      "x": -10,
      "y": 0,
      "z": -10,
      "name": "Soil_Dirt"
    },
    {
      "x": -10,
      "y": 1,
      "z": -10,
      "name": "Soil_Dirt"
    },
    {
      "x": -10,
      "y": 2,
      "z": -10,
      "name": "Soil_Dirt"
    },
    {
      "x": -10,
      "y": 3,
      "z": -10,
      "name": "Rock_Ledge_Brick"
    },
    {
      "x": -10,
      "y": 0,
      "z": -9,
      "name": "Soil_Dirt"
    },
    {
      "x": -10,
      "y": 1,
      "z": -9,
      "name": "Soil_Dirt"
    },
    {
      "x": -10,
      "y": 2,
      "z": -9,
      "name": "Soil_Dirt"
    },
    {
      "x": -10,
      "y": 3,
      "z": -9,
      "name": "Rock_Ledge_Brick"
    },
    {
      "x": -10,
      "y": 0,
      "z": -8,
      "name": "Soil_Dirt"
    },
    {
      "x": -10,
      "y": 1,
      "z": -8,
      "name": "Soil_Dirt"
    },
    {
      "x": -10,
      "y": 2,
      "z": -8,
      "name": "Soil_Dirt"
    },
    {
      "x": -10,
      "y": 3,
      "z": -8,
      "name": "Rock_Ledge_Brick"
    },
    {
      "x": -10,
      "y": 0,
      "z": -7,
      "name": "Soil_Dirt"
    },
    {
      "x": -10,
      "y": 1,
      "z": -7,
      "name": "Soil_Dirt"
    },
    {
      "x": -10,
      "y": 2,
      "z": -7,
      "name": "Soil_Dirt"
    },
    {
      "x": -10,
      "y": 3,
      "z": -7,
      "name": "Soil_Dirt"
    },
    {
      "x": -10,
      "y": 4,
      "z": -7,
      "name": "Rock_Stone_Aqua"
    },
    {
      "x": -10,
      "y": 5,
      "z": -7,
      "name": "Rock_Stone_Aqua"
    },
    {
      "x": -10,
      "y": 6,
      "z": -7,
      "name": "Rock_Stone_Aqua"
    },
    {
      "x": -10,
      "y": 7,
      "z": -7,
      "name": "Rock_Stone_Aqua"
    },
    {
      "x": -10,
      "y": 8,
      "z": -7,
      "name": "Rock_Stone_Aqua"
    },
    {
      "x": -10,
      "y": 9,
      "z": -7,
      "name": "Rock_Stone_Aqua"
    },
    {
      "x": -10,
      "y": 0,
      "z": -6,
      "name": "Soil_Dirt"
    },
    {
      "x": -10,
      "y": 1,
      "z": -6,
      "name": "Soil_Dirt"
    },
    {
      "x": -10,
      "y": 2,
      "z": -6,
      "name": "Soil_Dirt"
    },
    {
      "x": -10,
      "y": 3,
      "z": -6,
      "name": "Soil_Grass"
    },
    {
      "x": -10,
      "y": 0,
      "z": -5,
      "name": "Soil_Dirt"
    },
    {
      "x": -10,
      "y": 1,
      "z": -5,
      "name": "Soil_Dirt"
    },
    {
      "x": -10,
      "y": 2,
      "z": -5,
      "name": "Soil_Dirt"
    },
    {
      "x": -10,
      "y": 3,
      "z": -5,
      "name": "Rock_Ledge_Brick_Smooth"
    },
    {
      "x": -10,
      "y": 0,
      "z": -4,
      "name": "Soil_Dirt"
    },
    {
      "x": -10,
      "y": 1,
      "z": -4,
      "name": "Soil_Dirt"
    },
    {
      "x": -10,
      "y": 2,
      "z": -4,
      "name": "Soil_Dirt"
    },
    {
      "x": -10,
      "y": 3,
      "z": -4,
      "name": "Rock_Ledge_Cobble"
    },
    {
      "x": -10,
      "y": 0,
      "z": -3,
      "name": "Soil_Dirt"
    },
    {
      "x": -10,
      "y": 1,
      "z": -3,
      "name": "Soil_Dirt"
    },
    {
      "x": -10,
      "y": 2,
      "z": -3,
      "name": "Soil_Dirt"
    },
    {
      "x": -10,
      "y": 3,
      "z": -3,
      "name": "Rock_Ledge_Brick"
    },
    {
      "x": -10,
      "y": 0,
      "z": -2,
      "name": "Soil_Dirt"
    },
    {
      "x": -10,
      "y": 1,
      "z": -2,
      "name": "Soil_Dirt"
    },
    {
      "x": -10,
      "y": 2,
      "z": -2,
      "name": "Soil_Dirt"
    },
    {
      "x": -10,
      "y": 3,
      "z": -2,
      "name": "Rock_Ledge_Brick_Decorative"
    },
    {
      "x": -10,
      "y": 0,
      "z": -1,
      "name": "Soil_Dirt"
    },
    {
      "x": -10,
      "y": 1,
      "z": -1,
      "name": "Soil_Dirt"
    },
    {
      "x": -10,
      "y": 2,
      "z": -1,
      "name": "Soil_Dirt"
    },
    {
      "x": -10,
      "y": 3,
      "z": -1,
      "name": "Rock_Ledge_Brick"
    },
    {
      "x": -10,
      "y": 0,
      "z": 0,
      "name": "Soil_Dirt"
    },
    {
      "x": -10,
      "y": 1,
      "z": 0,
      "name": "Soil_Dirt"
    },
    {
      "x": -10,
      "y": 2,
      "z": 0,
      "name": "Soil_Dirt"
    },
    {
      "x": -10,
      "y": 3,
      "z": 0,
      "name": "Rock_Ledge_Brick_Ornate"
    },
    {
      "x": -10,
      "y": 0,
      "z": 1,
      "name": "Soil_Dirt"
    },
    {
      "x": -10,
      "y": 1,
      "z": 1,
      "name": "Soil_Dirt"
    },
    {
      "x": -10,
      "y": 2,
      "z": 1,
      "name": "Soil_Dirt"
    },
    {
      "x": -10,
      "y": 3,
      "z": 1,
      "name": "Rock_Ledge_Cobble"
    },
    {
      "x": -10,
      "y": 0,
      "z": 2,
      "name": "Soil_Dirt"
    },
    {
      "x": -10,
      "y": 1,
      "z": 2,
      "name": "Soil_Dirt"
    },
    {
      "x": -10,
      "y": 2,
      "z": 2,
      "name": "Soil_Dirt"
    },
    {
      "x": -10,
      "y": 3,
      "z": 2,
      "name": "Rock_Ledge_Cobble"
    },
    {
      "x": -10,
      "y": 0,
      "z": 3,
      "name": "Soil_Dirt"
    },
    {
      "x": -10,
      "y": 1,
      "z": 3,
      "name": "Soil_Dirt"
    },
    {
      "x": -10,
      "y": 2,
      "z": 3,
      "name": "Soil_Dirt"
    },
    {
      "x": -10,
      "y": 3,
      "z": 3,
      "name": "Rock_Ledge_Brick_Decorative"
    },
    {
      "x": -10,
      "y": 0,
      "z": 4,
      "name": "Soil_Dirt"
    },
    {
      "x": -10,
      "y": 1,
      "z": 4,
      "name": "Soil_Dirt"
    },
    {
      "x": -10,
      "y": 2,
      "z": 4,
      "name": "Soil_Dirt"
    },
    {
      "x": -10,
      "y": 3,
      "z": 4,
      "name": "Rock_Ledge_Cobble"
    },
    {
      "x": -10,
      "y": 0,
      "z": 5,
      "name": "Soil_Dirt"
    },
    {
      "x": -10,
      "y": 1,
      "z": 5,
      "name": "Soil_Dirt"
    },
    {
      "x": -10,
      "y": 2,
      "z": 5,
      "name": "Soil_Dirt"
    },
    {
      "x": -10,
      "y": 3,
      "z": 5,
      "name": "Rock_Ledge_Brick_Smooth"
    },
    {
      "x": -10,
      "y": 0,
      "z": 6,
      "name": "Soil_Dirt"
    },
    {
      "x": -10,
      "y": 1,
      "z": 6,
      "name": "Soil_Dirt"
    },
    {
      "x": -10,
      "y": 2,
      "z": 6,
      "name": "Soil_Dirt"
    },
    {
      "x": -10,
      "y": 3,
      "z": 6,
      "name": "Rock_Ledge_Brick_Smooth"
    },
    {
      "x": -10,
      "y": 0,
      "z": 7,
      "name": "Soil_Dirt"
    },
    {
      "x": -10,
      "y": 1,
      "z": 7,
      "name": "Soil_Dirt"
    },
    {
      "x": -10,
      "y": 2,
      "z": 7,
      "name": "Soil_Dirt"
    },
    {
      "x": -10,
      "y": 3,
      "z": 7,
      "name": "Rock_Ledge_Brick_Ornate"
    },
    {
      "x": -10,
      "y": 0,
      "z": 8,
      "name": "Soil_Dirt"
    },
    {
      "x": -10,
      "y": 1,
      "z": 8,
      "name": "Soil_Dirt"
    },
    {
      "x": -10,
      "y": 2,
      "z": 8,
      "name": "Soil_Dirt"
    },
    {
      "x": -10,
      "y": 3,
      "z": 8,
      "name": "Rock_Ledge_Brick_Smooth"
    },
    {
      "x": -10,
      "y": 0,
      "z": 9,
      "name": "Soil_Dirt"
    },
    {
      "x": -10,
      "y": 1,
      "z": 9,
      "name": "Soil_Dirt"
    },
    {
      "x": -10,
      "y": 2,
      "z": 9,
      "name": "Soil_Dirt"
    },
    {
      "x": -10,
      "y": 3,
      "z": 9,
      "name": "Rock_Ledge_Brick_Decorative"
    },
    {
      "x": -10,
      "y": 0,
      "z": 10,
      "name": "Soil_Dirt"
    },
    {
      "x": -10,
      "y": 1,
      "z": 10,
      "name": "Soil_Dirt"
    },
    {
      "x": -10,
      "y": 2,
      "z": 10,
      "name": "Soil_Dirt"
    },
    {
      "x": -10,
      "y": 3,
      "z": 10,
      "name": "Rock_Ledge_Cobble"
    },
    {
      "x": -10,
      "y": 0,
      "z": 11,
      "name": "Soil_Dirt"
    },
    {
      "x": -10,
      "y": 1,
      "z": 11,
      "name": "Soil_Dirt"
    },
    {
      "x": -10,
      "y": 2,
      "z": 11,
      "name": "Soil_Dirt"
    },
    {
      "x": -10,
      "y": 3,
      "z": 11,
      "name": "Rock_Ledge_Brick_Ornate"
    },
    {
      "x": -10,
      "y": 0,
      "z": 12,
      "name": "Soil_Dirt"
    },
    {
      "x": -10,
      "y": 1,
      "z": 12,
      "name": "Soil_Dirt"
    },
    {
      "x": -10,
      "y": 2,
      "z": 12,
      "name": "Soil_Dirt"
    },
    {
      "x": -10,
      "y": 3,
      "z": 12,
      "name": "Rock_Ledge_Brick_Smooth"
    },
    {
      "x": -10,
      "y": 0,
      "z": 13,
      "name": "Soil_Dirt"
    },
    {
      "x": -10,
      "y": 1,
      "z": 13,
      "name": "Soil_Dirt"
    },
    {
      "x": -10,
      "y": 2,
      "z": 13,
      "name": "Soil_Dirt"
    },
    {
      "x": -10,
      "y": 3,
      "z": 13,
      "name": "Rock_Ledge_Brick_Ornate"
    },
    {
      "x": -10,
      "y": 0,
      "z": 14,
      "name": "Soil_Dirt"
    },
    {
      "x": -10,
      "y": 1,
      "z": 14,
      "name": "Soil_Dirt"
    },
    {
      "x": -10,
      "y": 2,
      "z": 14,
      "name": "Soil_Dirt"
    },
    {
      "x": -10,
      "y": 3,
      "z": 14,
      "name": "Rock_Ledge_Brick_Smooth"
    },
    {
      "x": -10,
      "y": 0,
      "z": 15,
      "name": "Soil_Dirt"
    },
    {
      "x": -10,
      "y": 1,
      "z": 15,
      "name": "Soil_Dirt"
    },
    {
      "x": -10,
      "y": 2,
      "z": 15,
      "name": "Soil_Dirt"
    },
    {
      "x": -10,
      "y": 3,
      "z": 15,
      "name": "Rock_Ledge_Brick_Decorative"
    },
    {
      "x": -10,
      "y": 0,
      "z": 16,
      "name": "Soil_Dirt"
    },
    {
      "x": -10,
      "y": 1,
      "z": 16,
      "name": "Soil_Dirt"
    },
    {
      "x": -10,
      "y": 2,
      "z": 16,
      "name": "Soil_Dirt"
    },
    {
      "x": -10,
      "y": 3,
      "z": 16,
      "name": "Rock_Ledge_Brick_Smooth"
    },
    {
      "x": -9,
      "y": 0,
      "z": -15,
      "name": "Soil_Dirt"
    },
    {
      "x": -9,
      "y": 1,
      "z": -15,
      "name": "Soil_Dirt"
    },
    {
      "x": -9,
      "y": 2,
      "z": -15,
      "name": "Soil_Dirt"
    },
    {
      "x": -9,
      "y": 3,
      "z": -15,
      "name": "Rock_Ledge_Brick_Decorative"
    },
    {
      "x": -9,
      "y": 4,
      "z": -15,
      "name": "*Rock_Quartzite_Cobble_Wall_State_Definitions_Corner",
      "rotation": 1
    },
    {
      "x": -9,
      "y": 5,
      "z": -15,
      "name": "*Rock_Quartzite_Cobble_Wall_State_Definitions_Corner",
      "rotation": 1
    },
    {
      "x": -9,
      "y": 6,
      "z": -15,
      "name": "Cloth_Modern_Blue_Roof",
      "rotation": 3
    },
    {
      "x": -9,
      "y": 0,
      "z": -14,
      "name": "Soil_Dirt"
    },
    {
      "x": -9,
      "y": 1,
      "z": -14,
      "name": "Soil_Dirt"
    },
    {
      "x": -9,
      "y": 2,
      "z": -14,
      "name": "Soil_Dirt"
    },
    {
      "x": -9,
      "y": 3,
      "z": -14,
      "name": "Rock_Ledge_Brick_Smooth"
    },
    {
      "x": -9,
      "y": 4,
      "z": -14,
      "name": "Rock_Quartzite_Cobble_Wall",
      "rotation": 1
    },
    {
      "x": -9,
      "y": 5,
      "z": -14,
      "name": "Rock_Quartzite_Cobble_Wall",
      "rotation": 1
    },
    {
      "x": -9,
      "y": 6,
      "z": -14,
      "name": "Cloth_Modern_Blue_Roof",
      "rotation": 3
    },
    {
      "x": -9,
      "y": 0,
      "z": -13,
      "name": "Soil_Dirt"
    },
    {
      "x": -9,
      "y": 1,
      "z": -13,
      "name": "Soil_Dirt"
    },
    {
      "x": -9,
      "y": 2,
      "z": -13,
      "name": "Soil_Dirt"
    },
    {
      "x": -9,
      "y": 3,
      "z": -13,
      "name": "Rock_Ledge_Brick"
    },
    {
      "x": -9,
      "y": 4,
      "z": -13,
      "name": "Rock_Quartzite_Cobble_Wall",
      "rotation": 1
    },
    {
      "x": -9,
      "y": 5,
      "z": -13,
      "name": "Rock_Quartzite_Cobble_Wall",
      "rotation": 1
    },
    {
      "x": -9,
      "y": 6,
      "z": -13,
      "name": "Cloth_Modern_Blue_Roof",
      "rotation": 3
    },
    {
      "x": -9,
      "y": 0,
      "z": -12,
      "name": "Soil_Dirt"
    },
    {
      "x": -9,
      "y": 1,
      "z": -12,
      "name": "Soil_Dirt"
    },
    {
      "x": -9,
      "y": 2,
      "z": -12,
      "name": "Soil_Dirt"
    },
    {
      "x": -9,
      "y": 3,
      "z": -12,
      "name": "Rock_Ledge_Brick_Smooth"
    },
    {
      "x": -9,
      "y": 4,
      "z": -12,
      "name": "Rock_Quartzite_Cobble_Wall",
      "rotation": 1
    },
    {
      "x": -9,
      "y": 5,
      "z": -12,
      "name": "Rock_Quartzite_Cobble_Wall",
      "rotation": 1
    },
    {
      "x": -9,
      "y": 6,
      "z": -12,
      "name": "Cloth_Modern_Blue_Roof",
      "rotation": 3
    },
    {
      "x": -9,
      "y": 0,
      "z": -11,
      "name": "Soil_Dirt"
    },
    {
      "x": -9,
      "y": 1,
      "z": -11,
      "name": "Soil_Dirt"
    },
    {
      "x": -9,
      "y": 2,
      "z": -11,
      "name": "Soil_Dirt"
    },
    {
      "x": -9,
      "y": 3,
      "z": -11,
      "name": "Rock_Ledge_Brick_Ornate"
    },
    {
      "x": -9,
      "y": 4,
      "z": -11,
      "name": "Rock_Quartzite_Cobble_Wall",
      "rotation": 1
    },
    {
      "x": -9,
      "y": 5,
      "z": -11,
      "name": "Rock_Quartzite_Cobble_Wall",
      "rotation": 1
    },
    {
      "x": -9,
      "y": 6,
      "z": -11,
      "name": "Cloth_Modern_Blue_Roof",
      "rotation": 3
    },
    {
      "x": -9,
      "y": 0,
      "z": -10,
      "name": "Soil_Dirt"
    },
    {
      "x": -9,
      "y": 1,
      "z": -10,
      "name": "Soil_Dirt"
    },
    {
      "x": -9,
      "y": 2,
      "z": -10,
      "name": "Soil_Dirt"
    },
    {
      "x": -9,
      "y": 3,
      "z": -10,
      "name": "Rock_Ledge_Brick_Decorative"
    },
    {
      "x": -9,
      "y": 4,
      "z": -10,
      "name": "Rock_Quartzite_Cobble_Wall",
      "rotation": 1
    },
    {
      "x": -9,
      "y": 5,
      "z": -10,
      "name": "Rock_Quartzite_Cobble_Wall",
      "rotation": 1
    },
    {
      "x": -9,
      "y": 6,
      "z": -10,
      "name": "Cloth_Modern_Blue_Roof",
      "rotation": 3
    },
    {
      "x": -9,
      "y": 0,
      "z": -9,
      "name": "Soil_Dirt"
    },
    {
      "x": -9,
      "y": 1,
      "z": -9,
      "name": "Soil_Dirt"
    },
    {
      "x": -9,
      "y": 2,
      "z": -9,
      "name": "Soil_Dirt"
    },
    {
      "x": -9,
      "y": 3,
      "z": -9,
      "name": "Rock_Ledge_Brick_Smooth"
    },
    {
      "x": -9,
      "y": 4,
      "z": -9,
      "name": "Rock_Quartzite_Cobble_Wall",
      "rotation": 1
    },
    {
      "x": -9,
      "y": 5,
      "z": -9,
      "name": "Rock_Quartzite_Cobble_Wall",
      "rotation": 1
    },
    {
      "x": -9,
      "y": 6,
      "z": -9,
      "name": "Cloth_Modern_Blue_Roof",
      "rotation": 3
    },
    {
      "x": -9,
      "y": 0,
      "z": -8,
      "name": "Soil_Dirt"
    },
    {
      "x": -9,
      "y": 1,
      "z": -8,
      "name": "Soil_Dirt"
    },
    {
      "x": -9,
      "y": 2,
      "z": -8,
      "name": "Soil_Dirt"
    },
    {
      "x": -9,
      "y": 3,
      "z": -8,
      "name": "Rock_Ledge_Brick_Smooth"
    },
    {
      "x": -9,
      "y": 4,
      "z": -8,
      "name": "*Rock_Quartzite_Cobble_Wall_State_Definitions_Corner",
      "rotation": 2
    },
    {
      "x": -9,
      "y": 5,
      "z": -8,
      "name": "*Rock_Quartzite_Cobble_Wall_State_Definitions_Corner",
      "rotation": 2
    },
    {
      "x": -9,
      "y": 6,
      "z": -8,
      "name": "Cloth_Modern_Blue_Roof",
      "rotation": 3
    },
    {
      "x": -9,
      "y": 0,
      "z": -7,
      "name": "Soil_Dirt"
    },
    {
      "x": -9,
      "y": 1,
      "z": -7,
      "name": "Soil_Dirt"
    },
    {
      "x": -9,
      "y": 2,
      "z": -7,
      "name": "Soil_Dirt"
    },
    {
      "x": -9,
      "y": 3,
      "z": -7,
      "name": "Soil_Dirt"
    },
    {
      "x": -9,
      "y": 4,
      "z": -7,
      "name": "Rock_Stone_Aqua"
    },
    {
      "x": -9,
      "y": 5,
      "z": -7,
      "name": "Rock_Stone_Aqua"
    },
    {
      "x": -9,
      "y": 6,
      "z": -7,
      "name": "Rock_Stone_Aqua"
    },
    {
      "x": -9,
      "y": 7,
      "z": -7,
      "name": "Rock_Stone_Aqua"
    },
    {
      "x": -9,
      "y": 8,
      "z": -7,
      "name": "Rock_Stone_Aqua"
    },
    {
      "x": -9,
      "y": 9,
      "z": -7,
      "name": "Rock_Stone_Aqua"
    },
    {
      "x": -9,
      "y": 0,
      "z": -6,
      "name": "Soil_Dirt"
    },
    {
      "x": -9,
      "y": 1,
      "z": -6,
      "name": "Soil_Dirt"
    },
    {
      "x": -9,
      "y": 2,
      "z": -6,
      "name": "Soil_Dirt"
    },
    {
      "x": -9,
      "y": 3,
      "z": -6,
      "name": "Soil_Grass"
    },
    {
      "x": -9,
      "y": 0,
      "z": -5,
      "name": "Soil_Dirt"
    },
    {
      "x": -9,
      "y": 1,
      "z": -5,
      "name": "Soil_Dirt"
    },
    {
      "x": -9,
      "y": 2,
      "z": -5,
      "name": "Soil_Dirt"
    },
    {
      "x": -9,
      "y": 3,
      "z": -5,
      "name": "Rock_Ledge_Brick_Smooth"
    },
    {
      "x": -9,
      "y": 0,
      "z": -4,
      "name": "Soil_Dirt"
    },
    {
      "x": -9,
      "y": 1,
      "z": -4,
      "name": "Soil_Dirt"
    },
    {
      "x": -9,
      "y": 2,
      "z": -4,
      "name": "Soil_Dirt"
    },
    {
      "x": -9,
      "y": 3,
      "z": -4,
      "name": "Rock_Ledge_Brick_Ornate"
    },
    {
      "x": -9,
      "y": 0,
      "z": -3,
      "name": "Soil_Dirt"
    },
    {
      "x": -9,
      "y": 1,
      "z": -3,
      "name": "Soil_Dirt"
    },
    {
      "x": -9,
      "y": 2,
      "z": -3,
      "name": "Soil_Dirt"
    },
    {
      "x": -9,
      "y": 3,
      "z": -3,
      "name": "Rock_Ledge_Brick"
    },
    {
      "x": -9,
      "y": 0,
      "z": -2,
      "name": "Soil_Dirt"
    },
    {
      "x": -9,
      "y": 1,
      "z": -2,
      "name": "Soil_Dirt"
    },
    {
      "x": -9,
      "y": 2,
      "z": -2,
      "name": "Soil_Dirt"
    },
    {
      "x": -9,
      "y": 3,
      "z": -2,
      "name": "Rock_Ledge_Brick_Decorative"
    },
    {
      "x": -9,
      "y": 0,
      "z": -1,
      "name": "Soil_Dirt"
    },
    {
      "x": -9,
      "y": 1,
      "z": -1,
      "name": "Soil_Dirt"
    },
    {
      "x": -9,
      "y": 2,
      "z": -1,
      "name": "Soil_Dirt"
    },
    {
      "x": -9,
      "y": 3,
      "z": -1,
      "name": "Rock_Ledge_Brick_Smooth"
    },
    {
      "x": -9,
      "y": 0,
      "z": 0,
      "name": "Soil_Dirt"
    },
    {
      "x": -9,
      "y": 1,
      "z": 0,
      "name": "Soil_Dirt"
    },
    {
      "x": -9,
      "y": 2,
      "z": 0,
      "name": "Soil_Dirt"
    },
    {
      "x": -9,
      "y": 3,
      "z": 0,
      "name": "Rock_Ledge_Cobble"
    },
    {
      "x": -9,
      "y": 0,
      "z": 1,
      "name": "Soil_Dirt"
    },
    {
      "x": -9,
      "y": 1,
      "z": 1,
      "name": "Soil_Dirt"
    },
    {
      "x": -9,
      "y": 2,
      "z": 1,
      "name": "Soil_Dirt"
    },
    {
      "x": -9,
      "y": 3,
      "z": 1,
      "name": "Rock_Ledge_Brick"
    },
    {
      "x": -9,
      "y": 0,
      "z": 2,
      "name": "Soil_Dirt"
    },
    {
      "x": -9,
      "y": 1,
      "z": 2,
      "name": "Soil_Dirt"
    },
    {
      "x": -9,
      "y": 2,
      "z": 2,
      "name": "Soil_Dirt"
    },
    {
      "x": -9,
      "y": 3,
      "z": 2,
      "name": "Rock_Ledge_Brick_Smooth"
    },
    {
      "x": -9,
      "y": 0,
      "z": 3,
      "name": "Soil_Dirt"
    },
    {
      "x": -9,
      "y": 1,
      "z": 3,
      "name": "Soil_Dirt"
    },
    {
      "x": -9,
      "y": 2,
      "z": 3,
      "name": "Soil_Dirt"
    },
    {
      "x": -9,
      "y": 3,
      "z": 3,
      "name": "Rock_Ledge_Brick_Decorative"
    },
    {
      "x": -9,
      "y": 0,
      "z": 4,
      "name": "Soil_Dirt"
    },
    {
      "x": -9,
      "y": 1,
      "z": 4,
      "name": "Soil_Dirt"
    },
    {
      "x": -9,
      "y": 2,
      "z": 4,
      "name": "Soil_Dirt"
    },
    {
      "x": -9,
      "y": 3,
      "z": 4,
      "name": "Rock_Ledge_Brick_Smooth"
    },
    {
      "x": -9,
      "y": 0,
      "z": 5,
      "name": "Soil_Dirt"
    },
    {
      "x": -9,
      "y": 1,
      "z": 5,
      "name": "Soil_Dirt"
    },
    {
      "x": -9,
      "y": 2,
      "z": 5,
      "name": "Soil_Dirt"
    },
    {
      "x": -9,
      "y": 3,
      "z": 5,
      "name": "Rock_Ledge_Cobble"
    },
    {
      "x": -9,
      "y": 0,
      "z": 6,
      "name": "Soil_Dirt"
    },
    {
      "x": -9,
      "y": 1,
      "z": 6,
      "name": "Soil_Dirt"
    },
    {
      "x": -9,
      "y": 2,
      "z": 6,
      "name": "Soil_Dirt"
    },
    {
      "x": -9,
      "y": 3,
      "z": 6,
      "name": "Rock_Ledge_Brick_Decorative"
    },
    {
      "x": -9,
      "y": 0,
      "z": 7,
      "name": "Soil_Dirt"
    },
    {
      "x": -9,
      "y": 1,
      "z": 7,
      "name": "Soil_Dirt"
    },
    {
      "x": -9,
      "y": 2,
      "z": 7,
      "name": "Soil_Dirt"
    },
    {
      "x": -9,
      "y": 3,
      "z": 7,
      "name": "Rock_Ledge_Brick_Ornate"
    },
    {
      "x": -9,
      "y": 0,
      "z": 8,
      "name": "Soil_Dirt"
    },
    {
      "x": -9,
      "y": 1,
      "z": 8,
      "name": "Soil_Dirt"
    },
    {
      "x": -9,
      "y": 2,
      "z": 8,
      "name": "Soil_Dirt"
    },
    {
      "x": -9,
      "y": 3,
      "z": 8,
      "name": "Rock_Ledge_Brick_Smooth"
    },
    {
      "x": -9,
      "y": 0,
      "z": 9,
      "name": "Soil_Dirt"
    },
    {
      "x": -9,
      "y": 1,
      "z": 9,
      "name": "Soil_Dirt"
    },
    {
      "x": -9,
      "y": 2,
      "z": 9,
      "name": "Soil_Dirt"
    },
    {
      "x": -9,
      "y": 3,
      "z": 9,
      "name": "Rock_Ledge_Brick"
    },
    {
      "x": -9,
      "y": 0,
      "z": 10,
      "name": "Soil_Dirt"
    },
    {
      "x": -9,
      "y": 1,
      "z": 10,
      "name": "Soil_Dirt"
    },
    {
      "x": -9,
      "y": 2,
      "z": 10,
      "name": "Soil_Dirt"
    },
    {
      "x": -9,
      "y": 3,
      "z": 10,
      "name": "Rock_Ledge_Brick_Smooth"
    },
    {
      "x": -9,
      "y": 4,
      "z": 10,
      "name": "Rock_Runic_Blue_Brick"
    },
    {
      "x": -9,
      "y": 5,
      "z": 10,
      "name": "Rock_Runic_Blue_Brick"
    },
    {
      "x": -9,
      "y": 6,
      "z": 10,
      "name": "Rock_Runic_Blue_Brick"
    },
    {
      "x": -9,
      "y": 7,
      "z": 10,
      "name": "Rock_Runic_Blue_Brick"
    },
    {
      "x": -9,
      "y": 8,
      "z": 10,
      "name": "Rock_Runic_Blue_Brick"
    },
    {
      "x": -9,
      "y": 9,
      "z": 10,
      "name": "Rock_Runic_Blue_Brick"
    },
    {
      "x": -9,
      "y": 10,
      "z": 10,
      "name": "Rock_Runic_Blue_Brick"
    },
    {
      "x": -9,
      "y": 0,
      "z": 11,
      "name": "Soil_Dirt"
    },
    {
      "x": -9,
      "y": 1,
      "z": 11,
      "name": "Soil_Dirt"
    },
    {
      "x": -9,
      "y": 2,
      "z": 11,
      "name": "Soil_Dirt"
    },
    {
      "x": -9,
      "y": 3,
      "z": 11,
      "name": "Rock_Ledge_Brick"
    },
    {
      "x": -9,
      "y": 0,
      "z": 12,
      "name": "Soil_Dirt"
    },
    {
      "x": -9,
      "y": 1,
      "z": 12,
      "name": "Soil_Dirt"
    },
    {
      "x": -9,
      "y": 2,
      "z": 12,
      "name": "Soil_Dirt"
    },
    {
      "x": -9,
      "y": 3,
      "z": 12,
      "name": "Rock_Ledge_Brick_Smooth"
    },
    {
      "x": -9,
      "y": 0,
      "z": 13,
      "name": "Soil_Dirt"
    },
    {
      "x": -9,
      "y": 1,
      "z": 13,
      "name": "Soil_Dirt"
    },
    {
      "x": -9,
      "y": 2,
      "z": 13,
      "name": "Soil_Dirt"
    },
    {
      "x": -9,
      "y": 3,
      "z": 13,
      "name": "Rock_Ledge_Brick_Smooth"
    },
    {
      "x": -9,
      "y": 0,
      "z": 14,
      "name": "Soil_Dirt"
    },
    {
      "x": -9,
      "y": 1,
      "z": 14,
      "name": "Soil_Dirt"
    },
    {
      "x": -9,
      "y": 2,
      "z": 14,
      "name": "Soil_Dirt"
    },
    {
      "x": -9,
      "y": 3,
      "z": 14,
      "name": "Rock_Ledge_Brick_Ornate"
    },
    {
      "x": -9,
      "y": 0,
      "z": 15,
      "name": "Soil_Dirt"
    },
    {
      "x": -9,
      "y": 1,
      "z": 15,
      "name": "Soil_Dirt"
    },
    {
      "x": -9,
      "y": 2,
      "z": 15,
      "name": "Soil_Dirt"
    },
    {
      "x": -9,
      "y": 3,
      "z": 15,
      "name": "Rock_Ledge_Brick_Smooth"
    },
    {
      "x": -9,
      "y": 0,
      "z": 16,
      "name": "Soil_Dirt"
    },
    {
      "x": -9,
      "y": 1,
      "z": 16,
      "name": "Soil_Dirt"
    },
    {
      "x": -9,
      "y": 2,
      "z": 16,
      "name": "Soil_Dirt"
    },
    {
      "x": -9,
      "y": 3,
      "z": 16,
      "name": "Rock_Ledge_Brick_Ornate"
    },
    {
      "x": -8,
      "y": 0,
      "z": -15,
      "name": "Soil_Dirt"
    },
    {
      "x": -8,
      "y": 1,
      "z": -15,
      "name": "Soil_Dirt"
    },
    {
      "x": -8,
      "y": 2,
      "z": -15,
      "name": "Soil_Dirt"
    },
    {
      "x": -8,
      "y": 3,
      "z": -15,
      "name": "Rock_Ledge_Brick_Ornate"
    },
    {
      "x": -8,
      "y": 4,
      "z": -15,
      "name": "Rock_Quartzite_Cobble_Wall"
    },
    {
      "x": -8,
      "y": 5,
      "z": -15,
      "name": "Rock_Quartzite_Cobble_Wall"
    },
    {
      "x": -8,
      "y": 6,
      "z": -15,
      "name": "Cloth_Modern_Blue_Roof",
      "rotation": 1
    },
    {
      "x": -8,
      "y": 0,
      "z": -14,
      "name": "Soil_Dirt"
    },
    {
      "x": -8,
      "y": 1,
      "z": -14,
      "name": "Soil_Dirt"
    },
    {
      "x": -8,
      "y": 2,
      "z": -14,
      "name": "Soil_Dirt"
    },
    {
      "x": -8,
      "y": 3,
      "z": -14,
      "name": "Rock_Ledge_Cobble"
    },
    {
      "x": -8,
      "y": 4,
      "z": -14,
      "name": "Metal_Iron_Pipe_Long",
      "support": 15
    },
    {
      "x": -8,
      "y": 5,
      "z": -14,
      "name": "Metal_Iron_Pipe_Long",
      "support": 15
    },
    {
      "x": -8,
      "y": 6,
      "z": -14,
      "name": "Cloth_Modern_Blue_Roof",
      "rotation": 1
    },
    {
      "x": -8,
      "y": 0,
      "z": -13,
      "name": "Soil_Dirt"
    },
    {
      "x": -8,
      "y": 1,
      "z": -13,
      "name": "Soil_Dirt"
    },
    {
      "x": -8,
      "y": 2,
      "z": -13,
      "name": "Soil_Dirt"
    },
    {
      "x": -8,
      "y": 3,
      "z": -13,
      "name": "K2_Slot_Pad_4"
    },
    {
      "x": -8,
      "y": 6,
      "z": -13,
      "name": "Cloth_Modern_Blue_Roof",
      "rotation": 1
    },
    {
      "x": -8,
      "y": 0,
      "z": -12,
      "name": "Soil_Dirt"
    },
    {
      "x": -8,
      "y": 1,
      "z": -12,
      "name": "Soil_Dirt"
    },
    {
      "x": -8,
      "y": 2,
      "z": -12,
      "name": "Soil_Dirt"
    },
    {
      "x": -8,
      "y": 3,
      "z": -12,
      "name": "K2_Slot_Pad_3"
    },
    {
      "x": -8,
      "y": 6,
      "z": -12,
      "name": "Cloth_Modern_Blue_Roof",
      "rotation": 1
    },
    {
      "x": -8,
      "y": 0,
      "z": -11,
      "name": "Soil_Dirt"
    },
    {
      "x": -8,
      "y": 1,
      "z": -11,
      "name": "Soil_Dirt"
    },
    {
      "x": -8,
      "y": 2,
      "z": -11,
      "name": "Soil_Dirt"
    },
    {
      "x": -8,
      "y": 3,
      "z": -11,
      "name": "K2_Slot_Pad_2"
    },
    {
      "x": -8,
      "y": 6,
      "z": -11,
      "name": "Cloth_Modern_Blue_Roof",
      "rotation": 1
    },
    {
      "x": -8,
      "y": 0,
      "z": -10,
      "name": "Soil_Dirt"
    },
    {
      "x": -8,
      "y": 1,
      "z": -10,
      "name": "Soil_Dirt"
    },
    {
      "x": -8,
      "y": 2,
      "z": -10,
      "name": "Soil_Dirt"
    },
    {
      "x": -8,
      "y": 3,
      "z": -10,
      "name": "K2_Slot_Pad_1"
    },
    {
      "x": -8,
      "y": 6,
      "z": -10,
      "name": "Cloth_Modern_Blue_Roof",
      "rotation": 1
    },
    {
      "x": -8,
      "y": 0,
      "z": -9,
      "name": "Soil_Dirt"
    },
    {
      "x": -8,
      "y": 1,
      "z": -9,
      "name": "Soil_Dirt"
    },
    {
      "x": -8,
      "y": 2,
      "z": -9,
      "name": "Soil_Dirt"
    },
    {
      "x": -8,
      "y": 3,
      "z": -9,
      "name": "Rock_Ledge_Cobble"
    },
    {
      "x": -8,
      "y": 4,
      "z": -9,
      "name": "Metal_Iron_Pipe_Long",
      "support": 15
    },
    {
      "x": -8,
      "y": 5,
      "z": -9,
      "name": "Metal_Iron_Pipe_Long",
      "support": 15
    },
    {
      "x": -8,
      "y": 6,
      "z": -9,
      "name": "Cloth_Modern_Blue_Roof",
      "rotation": 1
    },
    {
      "x": -8,
      "y": 0,
      "z": -8,
      "name": "Soil_Dirt"
    },
    {
      "x": -8,
      "y": 1,
      "z": -8,
      "name": "Soil_Dirt"
    },
    {
      "x": -8,
      "y": 2,
      "z": -8,
      "name": "Soil_Dirt"
    },
    {
      "x": -8,
      "y": 3,
      "z": -8,
      "name": "Rock_Ledge_Brick"
    },
    {
      "x": -8,
      "y": 4,
      "z": -8,
      "name": "Rock_Quartzite_Cobble_Wall"
    },
    {
      "x": -8,
      "y": 5,
      "z": -8,
      "name": "Rock_Quartzite_Cobble_Wall"
    },
    {
      "x": -8,
      "y": 6,
      "z": -8,
      "name": "Cloth_Modern_Blue_Roof",
      "rotation": 1
    },
    {
      "x": -8,
      "y": 0,
      "z": -7,
      "name": "Soil_Dirt"
    },
    {
      "x": -8,
      "y": 1,
      "z": -7,
      "name": "Soil_Dirt"
    },
    {
      "x": -8,
      "y": 2,
      "z": -7,
      "name": "Soil_Dirt"
    },
    {
      "x": -8,
      "y": 3,
      "z": -7,
      "name": "Soil_Dirt"
    },
    {
      "x": -8,
      "y": 4,
      "z": -7,
      "name": "Rock_Stone_Aqua"
    },
    {
      "x": -8,
      "y": 5,
      "z": -7,
      "name": "Rock_Stone_Aqua"
    },
    {
      "x": -8,
      "y": 6,
      "z": -7,
      "name": "Rock_Stone_Aqua"
    },
    {
      "x": -8,
      "y": 7,
      "z": -7,
      "name": "Rock_Stone_Aqua"
    },
    {
      "x": -8,
      "y": 8,
      "z": -7,
      "name": "Rock_Stone_Aqua"
    },
    {
      "x": -8,
      "y": 9,
      "z": -7,
      "name": "Rock_Stone_Aqua"
    },
    {
      "x": -8,
      "y": 0,
      "z": -6,
      "name": "Soil_Dirt"
    },
    {
      "x": -8,
      "y": 1,
      "z": -6,
      "name": "Soil_Dirt"
    },
    {
      "x": -8,
      "y": 2,
      "z": -6,
      "name": "Soil_Dirt"
    },
    {
      "x": -8,
      "y": 3,
      "z": -6,
      "name": "Soil_Grass"
    },
    {
      "x": -8,
      "y": 0,
      "z": -5,
      "name": "Soil_Dirt"
    },
    {
      "x": -8,
      "y": 1,
      "z": -5,
      "name": "Soil_Dirt"
    },
    {
      "x": -8,
      "y": 2,
      "z": -5,
      "name": "Soil_Dirt"
    },
    {
      "x": -8,
      "y": 3,
      "z": -5,
      "name": "Rock_Ledge_Cobble"
    },
    {
      "x": -8,
      "y": 0,
      "z": -4,
      "name": "Soil_Dirt"
    },
    {
      "x": -8,
      "y": 1,
      "z": -4,
      "name": "Soil_Dirt"
    },
    {
      "x": -8,
      "y": 2,
      "z": -4,
      "name": "Soil_Dirt"
    },
    {
      "x": -8,
      "y": 3,
      "z": -4,
      "name": "Rock_Ledge_Brick_Ornate"
    },
    {
      "x": -8,
      "y": 0,
      "z": -3,
      "name": "Soil_Dirt"
    },
    {
      "x": -8,
      "y": 1,
      "z": -3,
      "name": "Soil_Dirt"
    },
    {
      "x": -8,
      "y": 2,
      "z": -3,
      "name": "Soil_Dirt"
    },
    {
      "x": -8,
      "y": 3,
      "z": -3,
      "name": "Rock_Ledge_Brick_Decorative"
    },
    {
      "x": -8,
      "y": 0,
      "z": -2,
      "name": "Soil_Dirt"
    },
    {
      "x": -8,
      "y": 1,
      "z": -2,
      "name": "Soil_Dirt"
    },
    {
      "x": -8,
      "y": 2,
      "z": -2,
      "name": "Soil_Dirt"
    },
    {
      "x": -8,
      "y": 3,
      "z": -2,
      "name": "Rock_Ledge_Brick_Smooth"
    },
    {
      "x": -8,
      "y": 0,
      "z": -1,
      "name": "Soil_Dirt"
    },
    {
      "x": -8,
      "y": 1,
      "z": -1,
      "name": "Soil_Dirt"
    },
    {
      "x": -8,
      "y": 2,
      "z": -1,
      "name": "Soil_Dirt"
    },
    {
      "x": -8,
      "y": 3,
      "z": -1,
      "name": "Rock_Ledge_Cobble"
    },
    {
      "x": -8,
      "y": 0,
      "z": 0,
      "name": "Soil_Dirt"
    },
    {
      "x": -8,
      "y": 1,
      "z": 0,
      "name": "Soil_Dirt"
    },
    {
      "x": -8,
      "y": 2,
      "z": 0,
      "name": "Soil_Dirt"
    },
    {
      "x": -8,
      "y": 3,
