{
  "version": 8,
  "blockIdVersion": 11,
  "anchorX": 0,
  "anchorY": 0,
  "anchorZ": 0,
  "blocks": [
    {
      "x": -15,
      "y": 0,
      "z": -15,
      "name": "Soil_Dirt"
    },
    {
      "x": -15,
      "y": 1,
      "z": -15,
      "name": "Soil_Dirt"
    },
    {
      "x": -15,
      "y": 2,
      "z": -15,
      "name": "Soil_Dirt"
    },
    {
      "x": -15,
      "y": 3,
      "z": -15,
      "name": "Soil_Grass"
    },
    {
      "x": -15,
      "y": 0,
      "z": -14,
      "name": "Soil_Dirt"
    },
    {
      "x": -15,
      "y": 1,
      "z": -14,
      "name": "Soil_Dirt"
    },
    {
      "x": -15,
      "y": 2,
      "z": -14,
      "name": "Soil_Dirt"
    },
    {
      "x": -15,
      "y": 3,
      "z": -14,
      "name": "Soil_Grass"
    },
    {
      "x": -15,
      "y": 0,
      "z": -13,
      "name": "Soil_Dirt"
    },
    {
      "x": -15,
      "y": 1,
      "z": -13,
      "name": "Soil_Dirt"
    },
    {
      "x": -15,
      "y": 2,
      "z": -13,
      "name": "Soil_Dirt"
    },
    {
      "x": -15,
      "y": 3,
      "z": -13,
      "name": "Soil_Grass"
    },
    {
      "x": -15,
      "y": 0,
      "z": -12,
      "name": "Soil_Dirt"
    },
    {
      "x": -15,
      "y": 1,
      "z": -12,
      "name": "Soil_Dirt"
    },
    {
      "x": -15,
      "y": 2,
      "z": -12,
      "name": "Soil_Dirt"
    },
    {
      "x": -15,
      "y": 3,
      "z": -12,
      "name": "Soil_Grass"
    },
    {
      "x": -15,
      "y": 0,
      "z": -11,
      "name": "Soil_Dirt"
    },
    {
      "x": -15,
      "y": 1,
      "z": -11,
      "name": "Soil_Dirt"
    },
    {
      "x": -15,
      "y": 2,
      "z": -11,
      "name": "Soil_Dirt"
    },
    {
      "x": -15,
      "y": 3,
      "z": -11,
      "name": "Soil_Grass"
    },
    {
      "x": -15,
      "y": 0,
      "z": -10,
      "name": "Soil_Dirt"
    },
    {
      "x": -15,
      "y": 1,
      "z": -10,
      "name": "Soil_Dirt"
    },
    {
      "x": -15,
      "y": 2,
      "z": -10,
      "name": "Soil_Dirt"
    },
    {
      "x": -15,
      "y": 3,
      "z": -10,
      "name": "Soil_Grass"
    },
    {
      "x": -15,
      "y": 0,
      "z": -9,
      "name": "Soil_Dirt"
    },
    {
      "x": -15,
      "y": 1,
      "z": -9,
      "name": "Soil_Dirt"
    },
    {
      "x": -15,
      "y": 2,
      "z": -9,
      "name": "Soil_Dirt"
    },
    {
      "x": -15,
      "y": 3,
      "z": -9,
      "name": "Soil_Grass"
    },
    {
      "x": -15,
      "y": 0,
      "z": -8,
      "name": "Soil_Dirt"
    },
    {
      "x": -15,
      "y": 1,
      "z": -8,
      "name": "Soil_Dirt"
    },
    {
      "x": -15,
      "y": 2,
      "z": -8,
      "name": "Soil_Dirt"
    },
    {
      "x": -15,
      "y": 3,
      "z": -8,
      "name": "Soil_Grass"
    },
    {
      "x": -15,
      "y": 0,
      "z": -7,
      "name": "Soil_Dirt"
    },
    {
      "x": -15,
      "y": 1,
      "z": -7,
      "name": "Soil_Dirt"
    },
    {
      "x": -15,
      "y": 2,
      "z": -7,
      "name": "Soil_Dirt"
    },
    {
      "x": -15,
      "y": 3,
      "z": -7,
      "name": "Soil_Grass"
    },
    {
      "x": -15,
      "y": 9,
      "z": -7,
      "name": "Soil_Grass",
      "rotation": 1
    },
    {
      "x": -15,
      "y": 0,
      "z": -6,
      "name": "Soil_Dirt"
    },
    {
      "x": -15,
      "y": 1,
      "z": -6,
      "name": "Soil_Dirt"
    },
    {
      "x": -15,
      "y": 2,
      "z": -6,
      "name": "Soil_Dirt"
    },
    {
      "x": -15,
      "y": 3,
      "z": -6,
      "name": "Soil_Grass"
    },
    {
      "x": -15,
      "y": 8,
      "z": -6,
      "name": "Soil_Dirt"
    },
    {
      "x": -15,
      "y": 9,
      "z": -6,
      "name": "Soil_Grass",
      "rotation": 1
    },
    {
      "x": -15,
      "y": 0,
      "z": -5,
      "name": "Soil_Dirt"
    },
    {
      "x": -15,
      "y": 1,
      "z": -5,
      "name": "Soil_Dirt"
    },
    {
      "x": -15,
      "y": 2,
      "z": -5,
      "name": "Soil_Dirt"
    },
    {
      "x": -15,
      "y": 3,
      "z": -5,
      "name": "Soil_Grass"
    },
    {
      "x": -15,
      "y": 8,
      "z": -5,
      "name": "Soil_Dirt"
    },
    {
      "x": -15,
      "y": 9,
      "z": -5,
      "name": "Soil_Grass",
      "rotation": 1
    },
    {
      "x": -15,
      "y": 0,
      "z": -4,
      "name": "Soil_Dirt"
    },
    {
      "x": -15,
      "y": 1,
      "z": -4,
      "name": "Soil_Dirt"
    },
    {
      "x": -15,
      "y": 2,
      "z": -4,
      "name": "Soil_Dirt"
    },
    {
      "x": -15,
      "y": 3,
      "z": -4,
      "name": "Soil_Grass"
    },
    {
      "x": -15,
      "y": 8,
      "z": -4,
      "name": "Soil_Dirt"
    },
    {
      "x": -15,
      "y": 9,
      "z": -4,
      "name": "Soil_Grass",
      "rotation": 1
    },
    {
      "x": -15,
      "y": 0,
      "z": -3,
      "name": "Soil_Dirt"
    },
    {
      "x": -15,
      "y": 1,
      "z": -3,
      "name": "Soil_Dirt"
    },
    {
      "x": -15,
      "y": 2,
      "z": -3,
      "name": "Soil_Dirt"
    },
    {
      "x": -15,
      "y": 3,
      "z": -3,
      "name": "Soil_Grass"
    },
    {
      "x": -15,
      "y": 8,
      "z": -3,
      "name": "Rock_Basalt"
    },
    {
      "x": -15,
      "y": 9,
      "z": -3,
      "name": "Soil_Grass",
      "rotation": 1
    },
    {
      "x": -15,
      "y": 0,
      "z": -2,
      "name": "Soil_Dirt"
    },
    {
      "x": -15,
      "y": 1,
      "z": -2,
      "name": "Soil_Dirt"
    },
    {
      "x": -15,
      "y": 2,
      "z": -2,
      "name": "Soil_Dirt"
    },
    {
      "x": -15,
      "y": 3,
      "z": -2,
      "name": "Soil_Grass"
    },
    {
      "x": -15,
      "y": 8,
      "z": -2,
      "name": "Rock_Basalt"
    },
    {
      "x": -15,
      "y": 9,
      "z": -2,
      "name": "Soil_Grass",
      "rotation": 1
    },
    {
      "x": -15,
      "y": 0,
      "z": -1,
      "name": "Soil_Dirt"
    },
    {
      "x": -15,
      "y": 1,
      "z": -1,
      "name": "Soil_Dirt"
    },
    {
      "x": -15,
      "y": 2,
      "z": -1,
      "name": "Soil_Dirt"
    },
    {
      "x": -15,
      "y": 3,
      "z": -1,
      "name": "Soil_Grass"
    },
    {
      "x": -15,
      "y": 9,
      "z": -1,
      "name": "Soil_Grass",
      "rotation": 1
    },
    {
      "x": -15,
      "y": 0,
      "z": 0,
      "name": "Soil_Dirt"
    },
    {
      "x": -15,
      "y": 1,
      "z": 0,
      "name": "Soil_Dirt"
    },
    {
      "x": -15,
      "y": 2,
      "z": 0,
      "name": "Soil_Dirt"
    },
    {
      "x": -15,
      "y": 3,
      "z": 0,
      "name": "Soil_Grass"
    },
    {
      "x": -15,
      "y": 0,
      "z": 1,
      "name": "Soil_Dirt"
    },
    {
      "x": -15,
      "y": 1,
      "z": 1,
      "name": "Soil_Dirt"
    },
    {
      "x": -15,
      "y": 2,
      "z": 1,
      "name": "Soil_Dirt"
    },
    {
      "x": -15,
      "y": 3,
      "z": 1,
      "name": "Soil_Grass"
    },
    {
      "x": -15,
      "y": 0,
      "z": 2,
      "name": "Soil_Dirt"
    },
    {
      "x": -15,
      "y": 1,
      "z": 2,
      "name": "Soil_Dirt"
    },
    {
      "x": -15,
      "y": 2,
      "z": 2,
      "name": "Soil_Dirt"
    },
    {
      "x": -15,
      "y": 3,
      "z": 2,
      "name": "Soil_Grass"
    },
    {
      "x": -15,
      "y": 0,
      "z": 3,
      "name": "Soil_Dirt"
    },
    {
      "x": -15,
      "y": 1,
      "z": 3,
      "name": "Soil_Dirt"
    },
    {
      "x": -15,
      "y": 2,
      "z": 3,
      "name": "Soil_Dirt"
    },
    {
      "x": -15,
      "y": 3,
      "z": 3,
      "name": "Soil_Grass"
    },
    {
      "x": -15,
      "y": 0,
      "z": 4,
      "name": "Soil_Dirt"
    },
    {
      "x": -15,
      "y": 1,
      "z": 4,
      "name": "Soil_Dirt"
    },
    {
      "x": -15,
      "y": 2,
      "z": 4,
      "name": "Soil_Dirt"
    },
    {
      "x": -15,
      "y": 3,
      "z": 4,
      "name": "Soil_Grass"
    },
    {
      "x": -15,
      "y": 0,
      "z": 5,
      "name": "Soil_Dirt"
    },
    {
      "x": -15,
      "y": 1,
      "z": 5,
      "name": "Soil_Dirt"
    },
    {
      "x": -15,
      "y": 2,
      "z": 5,
      "name": "Soil_Dirt"
    },
    {
      "x": -15,
      "y": 3,
      "z": 5,
      "name": "Soil_Grass"
    },
    {
      "x": -15,
      "y": 0,
      "z": 6,
      "name": "Soil_Dirt"
    },
    {
      "x": -15,
      "y": 1,
      "z": 6,
      "name": "Soil_Dirt"
    },
    {
      "x": -15,
      "y": 2,
      "z": 6,
      "name": "Soil_Dirt"
    },
    {
      "x": -15,
      "y": 3,
      "z": 6,
      "name": "Soil_Grass"
    },
    {
      "x": -15,
      "y": 9,
      "z": 6,
      "name": "Plant_Leaves_Beech"
    },
    {
      "x": -15,
      "y": 14,
      "z": 6,
      "name": "Plant_Leaves_Beech"
    },
    {
      "x": -15,
      "y": 15,
      "z": 6,
      "name": "Plant_Leaves_Beech"
    },
    {
      "x": -15,
      "y": 0,
      "z": 7,
      "name": "Soil_Dirt"
    },
    {
      "x": -15,
      "y": 1,
      "z": 7,
      "name": "Soil_Dirt"
    },
    {
      "x": -15,
      "y": 2,
      "z": 7,
      "name": "Soil_Dirt"
    },
    {
      "x": -15,
      "y": 3,
      "z": 7,
      "name": "Soil_Grass"
    },
    {
      "x": -15,
      "y": 14,
      "z": 7,
      "name": "Plant_Leaves_Beech"
    },
    {
      "x": -15,
      "y": 15,
      "z": 7,
      "name": "Plant_Leaves_Beech"
    },
    {
      "x": -15,
      "y": 16,
      "z": 7,
      "name": "Plant_Leaves_Beech"
    },
    {
      "x": -15,
      "y": 0,
      "z": 8,
      "name": "Soil_Dirt"
    },
    {
      "x": -15,
      "y": 1,
      "z": 8,
      "name": "Soil_Dirt"
    },
    {
      "x": -15,
      "y": 2,
      "z": 8,
      "name": "Soil_Dirt"
    },
    {
      "x": -15,
      "y": 3,
      "z": 8,
      "name": "Soil_Grass"
    },
    {
      "x": -15,
      "y": 14,
      "z": 8,
      "name": "Plant_Leaves_Beech"
    },
    {
      "x": -15,
      "y": 15,
      "z": 8,
      "name": "Plant_Leaves_Beech"
    },
    {
      "x": -15,
      "y": 0,
      "z": 9,
      "name": "Soil_Dirt"
    },
    {
      "x": -15,
      "y": 1,
      "z": 9,
      "name": "Soil_Dirt"
    },
    {
      "x": -15,
      "y": 2,
      "z": 9,
      "name": "Soil_Dirt"
    },
    {
      "x": -15,
      "y": 3,
      "z": 9,
      "name": "Soil_Grass"
    },
    {
      "x": -15,
      "y": 0,
      "z": 10,
      "name": "Soil_Dirt"
    },
    {
      "x": -15,
      "y": 1,
      "z": 10,
      "name": "Soil_Dirt"
    },
    {
      "x": -15,
      "y": 2,
      "z": 10,
      "name": "Soil_Dirt"
    },
    {
      "x": -15,
      "y": 3,
      "z": 10,
      "name": "Soil_Mud_Dry"
    },
    {
      "x": -15,
      "y": 0,
      "z": 11,
      "name": "Soil_Dirt"
    },
    {
      "x": -15,
      "y": 1,
      "z": 11,
      "name": "Soil_Dirt"
    },
    {
      "x": -15,
      "y": 2,
      "z": 11,
      "name": "Soil_Dirt"
    },
    {
      "x": -15,
      "y": 3,
      "z": 11,
      "name": "Soil_Mud_Dry"
    },
    {
      "x": -15,
      "y": 0,
      "z": 12,
      "name": "Soil_Dirt"
    },
    {
      "x": -15,
      "y": 1,
      "z": 12,
      "name": "Soil_Dirt"
    },
    {
      "x": -15,
      "y": 2,
      "z": 12,
      "name": "Soil_Dirt"
    },
    {
      "x": -15,
      "y": 3,
      "z": 12,
      "name": "Soil_Dirt"
    },
    {
      "x": -15,
      "y": 10,
      "z": 12,
      "name": "Plant_Leaves_Beech"
    },
    {
      "x": -15,
      "y": 14,
      "z": 12,
      "name": "Plant_Leaves_Beech"
    },
    {
      "x": -15,
      "y": 17,
      "z": 12,
      "name": "Plant_Leaves_Beech"
    },
    {
      "x": -15,
      "y": 18,
      "z": 12,
      "name": "Plant_Leaves_Beech"
    },
    {
      "x": -15,
      "y": 0,
      "z": 13,
      "name": "Soil_Dirt"
    },
    {
      "x": -15,
      "y": 1,
      "z": 13,
      "name": "Soil_Dirt"
    },
    {
      "x": -15,
      "y": 2,
      "z": 13,
      "name": "Soil_Dirt"
    },
    {
      "x": -15,
      "y": 3,
      "z": 13,
      "name": "Soil_Dirt"
    },
    {
      "x": -15,
      "y": 17,
      "z": 13,
      "name": "Plant_Leaves_Beech"
    },
    {
      "x": -15,
      "y": 18,
      "z": 13,
      "name": "Plant_Leaves_Beech"
    },
    {
      "x": -15,
      "y": 19,
      "z": 13,
      "name": "Plant_Leaves_Beech"
    },
    {
      "x": -15,
      "y": 0,
      "z": 14,
      "name": "Soil_Dirt"
    },
    {
      "x": -15,
      "y": 1,
      "z": 14,
      "name": "Soil_Dirt"
    },
    {
      "x": -15,
      "y": 2,
      "z": 14,
      "name": "Soil_Dirt"
    },
    {
      "x": -15,
      "y": 3,
      "z": 14,
      "name": "Soil_Dirt"
    },
    {
      "x": -15,
      "y": 9,
      "z": 14,
      "name": "Plant_Leaves_Beech",
      "support": 1
    },
    {
      "x": -15,
      "y": 17,
      "z": 14,
      "name": "Plant_Leaves_Beech"
    },
    {
      "x": -15,
      "y": 18,
      "z": 14,
      "name": "Plant_Leaves_Beech"
    },
    {
      "x": -15,
      "y": 19,
      "z": 14,
      "name": "Plant_Leaves_Beech"
    },
    {
      "x": -15,
      "y": 0,
      "z": 15,
      "name": "Soil_Dirt"
    },
    {
      "x": -15,
      "y": 1,
      "z": 15,
      "name": "Soil_Dirt"
    },
    {
      "x": -15,
      "y": 2,
      "z": 15,
      "name": "Soil_Dirt"
    },
    {
      "x": -15,
      "y": 3,
      "z": 15,
      "name": "Soil_Dirt"
    },
    {
      "x": -15,
      "y": 9,
      "z": 15,
      "name": "Plant_Leaves_Beech"
    },
    {
      "x": -15,
      "y": 18,
      "z": 15,
      "name": "Plant_Leaves_Beech"
    },
    {
      "x": -15,
      "y": 19,
      "z": 15,
      "name": "Plant_Leaves_Beech"
    },
    {
      "x": -15,
      "y": 20,
      "z": 15,
      "name": "Plant_Leaves_Beech"
    },
    {
      "x": -15,
      "y": 22,
      "z": 15,
      "name": "Plant_Leaves_Beech"
    },
    {
      "x": -15,
      "y": 23,
      "z": 15,
      "name": "Plant_Leaves_Beech"
    },
    {
      "x": -15,
      "y": 0,
      "z": 16,
      "name": "Soil_Dirt"
    },
    {
      "x": -15,
      "y": 1,
      "z": 16,
      "name": "Soil_Pathway"
    },
    {
      "x": -15,
      "y": 2,
      "z": 16,
      "name": "Soil_Pathway"
    },
    {
      "x": -15,
      "y": 3,
      "z": 16,
      "name": "Soil_Pathway"
    },
    {
      "x": -15,
      "y": 9,
      "z": 16,
      "name": "Wood_Beech_Branch_Long",
      "support": 1,
      "rotation": 5
    },
    {
      "x": -15,
      "y": 14,
      "z": 16,
      "name": "Wood_Beech_Branch_Long",
      "rotation": 5
    },
    {
      "x": -15,
      "y": 19,
      "z": 16,
      "name": "Wood_Beech_Branch_Corner",
      "rotation": 1
    },
    {
      "x": -15,
      "y": 20,
      "z": 16,
      "name": "Plant_Leaves_Beech"
    },
    {
      "x": -15,
      "y": 22,
      "z": 16,
      "name": "Plant_Leaves_Beech"
    },
    {
      "x": -15,
      "y": 23,
      "z": 16,
      "name": "Plant_Leaves_Beech"
    },
    {
      "x": -15,
      "y": 24,
      "z": 16,
      "name": "Plant_Leaves_Beech"
    },
    {
      "x": -14,
      "y": 0,
      "z": -15,
      "name": "Soil_Dirt"
    },
    {
      "x": -14,
      "y": 1,
      "z": -15,
      "name": "Soil_Dirt"
    },
    {
      "x": -14,
      "y": 2,
      "z": -15,
      "name": "Soil_Dirt"
    },
    {
      "x": -14,
      "y": 3,
      "z": -15,
      "name": "Soil_Grass"
    },
    {
      "x": -14,
      "y": 0,
      "z": -14,
      "name": "Soil_Dirt"
    },
    {
      "x": -14,
      "y": 1,
      "z": -14,
      "name": "Soil_Dirt"
    },
    {
      "x": -14,
      "y": 2,
      "z": -14,
      "name": "Soil_Dirt"
    },
    {
      "x": -14,
      "y": 3,
      "z": -14,
      "name": "Soil_Grass"
    },
    {
      "x": -14,
      "y": 0,
      "z": -13,
      "name": "Soil_Dirt"
    },
    {
      "x": -14,
      "y": 1,
      "z": -13,
      "name": "Soil_Dirt"
    },
    {
      "x": -14,
      "y": 2,
      "z": -13,
      "name": "Soil_Dirt"
    },
    {
      "x": -14,
      "y": 3,
      "z": -13,
      "name": "Soil_Grass"
    },
    {
      "x": -14,
      "y": 0,
      "z": -12,
      "name": "Soil_Dirt"
    },
    {
      "x": -14,
      "y": 1,
      "z": -12,
      "name": "Soil_Dirt"
    },
    {
      "x": -14,
      "y": 2,
      "z": -12,
      "name": "Soil_Dirt"
    },
    {
      "x": -14,
      "y": 3,
      "z": -12,
      "name": "Soil_Grass"
    },
    {
      "x": -14,
      "y": 0,
      "z": -11,
      "name": "Soil_Dirt"
    },
    {
      "x": -14,
      "y": 1,
      "z": -11,
      "name": "Soil_Dirt"
    },
    {
      "x": -14,
      "y": 2,
      "z": -11,
      "name": "Soil_Dirt"
    },
    {
      "x": -14,
      "y": 3,
      "z": -11,
      "name": "Soil_Grass"
    },
    {
      "x": -14,
      "y": 0,
      "z": -10,
      "name": "Soil_Dirt"
    },
    {
      "x": -14,
      "y": 1,
      "z": -10,
      "name": "Soil_Dirt"
    },
    {
      "x": -14,
      "y": 2,
      "z": -10,
      "name": "Soil_Dirt"
    },
    {
      "x": -14,
      "y": 3,
      "z": -10,
      "name": "Soil_Grass"
    },
    {
      "x": -14,
      "y": 0,
      "z": -9,
      "name": "Soil_Dirt"
    },
    {
      "x": -14,
      "y": 1,
      "z": -9,
      "name": "Soil_Dirt"
    },
    {
      "x": -14,
      "y": 2,
      "z": -9,
      "name": "Soil_Dirt"
    },
    {
      "x": -14,
      "y": 3,
      "z": -9,
      "name": "Soil_Grass"
    },
    {
      "x": -14,
      "y": 9,
      "z": -9,
      "name": "Soil_Grass",
      "rotation": 1
    },
    {
      "x": -14,
      "y": 0,
      "z": -8,
      "name": "Soil_Dirt"
    },
    {
      "x": -14,
      "y": 1,
      "z": -8,
      "name": "Soil_Dirt"
    },
    {
      "x": -14,
      "y": 2,
      "z": -8,
      "name": "Soil_Dirt"
    },
    {
      "x": -14,
      "y": 3,
      "z": -8,
      "name": "Soil_Grass"
    },
    {
      "x": -14,
      "y": 6,
      "z": -8,
      "name": "Rock_Basalt"
    },
    {
      "x": -14,
      "y": 7,
      "z": -8,
      "name": "Rock_Basalt"
    },
    {
      "x": -14,
      "y": 8,
      "z": -8,
      "name": "Soil_Dirt"
    },
    {
      "x": -14,
      "y": 9,
      "z": -8,
      "name": "Soil_Grass",
      "rotation": 1
    },
    {
      "x": -14,
      "y": 10,
      "z": -8,
      "name": "Plant_Grass_Winter_Short",
      "rotation": 1
    },
    {
      "x": -14,
      "y": 0,
      "z": -7,
      "name": "Soil_Dirt"
    },
    {
      "x": -14,
      "y": 1,
      "z": -7,
      "name": "Soil_Dirt"
    },
    {
      "x": -14,
      "y": 2,
      "z": -7,
      "name": "Soil_Dirt"
    },
    {
      "x": -14,
      "y": 3,
      "z": -7,
      "name": "Soil_Grass"
    },
    {
      "x": -14,
      "y": 5,
      "z": -7,
      "name": "Rock_Basalt"
    },
    {
      "x": -14,
      "y": 6,
      "z": -7,
      "name": "Rock_Basalt"
    },
    {
      "x": -14,
      "y": 7,
      "z": -7,
      "name": "Rock_Basalt"
    },
    {
      "x": -14,
      "y": 8,
      "z": -7,
      "name": "Soil_Dirt"
    },
    {
      "x": -14,
      "y": 9,
      "z": -7,
      "name": "Soil_Grass",
      "rotation": 1
    },
    {
      "x": -14,
      "y": 0,
      "z": -6,
      "name": "Soil_Dirt"
    },
    {
      "x": -14,
      "y": 1,
      "z": -6,
      "name": "Soil_Dirt"
    },
    {
      "x": -14,
      "y": 2,
      "z": -6,
      "name": "Soil_Dirt"
    },
    {
      "x": -14,
      "y": 3,
      "z": -6,
      "name": "Soil_Dirt"
    },
    {
      "x": -14,
      "y": 4,
      "z": -6,
      "name": "Rock_Basalt"
    },
    {
      "x": -14,
      "y": 5,
      "z": -6,
      "name": "Rock_Basalt"
    },
    {
      "x": -14,
      "y": 6,
      "z": -6,
      "name": "Rock_Basalt"
    },
    {
      "x": -14,
      "y": 7,
      "z": -6,
      "name": "Rock_Basalt"
    },
    {
      "x": -14,
      "y": 8,
      "z": -6,
      "name": "Soil_Dirt"
    },
    {
      "x": -14,
      "y": 9,
      "z": -6,
      "name": "Soil_Grass",
      "rotation": 1
    },
    {
      "x": -14,
      "y": 29,
      "z": -6,
      "name": "Plant_Leaves_Redwood",
      "support": 4,
      "rotation": 1
    },
    {
      "x": -14,
      "y": 0,
      "z": -5,
      "name": "Soil_Dirt"
    },
    {
      "x": -14,
      "y": 1,
      "z": -5,
      "name": "Soil_Dirt"
    },
    {
      "x": -14,
      "y": 2,
      "z": -5,
      "name": "Soil_Dirt"
    },
    {
      "x": -14,
      "y": 3,
      "z": -5,
      "name": "Soil_Dirt"
    },
    {
      "x": -14,
      "y": 4,
      "z": -5,
      "name": "Rock_Basalt"
    },
    {
      "x": -14,
      "y": 5,
      "z": -5,
      "name": "Rock_Basalt"
    },
    {
      "x": -14,
      "y": 6,
      "z": -5,
      "name": "Rock_Basalt"
    },
    {
      "x": -14,
      "y": 7,
      "z": -5,
      "name": "Rock_Basalt"
    },
    {
      "x": -14,
      "y": 8,
      "z": -5,
      "name": "Soil_Dirt"
    },
    {
      "x": -14,
      "y": 9,
      "z": -5,
      "name": "Soil_Grass",
      "rotation": 1
    },
    {
      "x": -14,
      "y": 0,
      "z": -4,
      "name": "Soil_Dirt"
    },
    {
      "x": -14,
      "y": 1,
      "z": -4,
      "name": "Soil_Dirt"
    },
    {
      "x": -14,
      "y": 2,
      "z": -4,
      "name": "Soil_Dirt"
    },
    {
      "x": -14,
      "y": 3,
      "z": -4,
      "name": "Soil_Dirt"
    },
    {
      "x": -14,
      "y": 4,
      "z": -4,
      "name": "Rock_Basalt"
    },
    {
      "x": -14,
      "y": 5,
      "z": -4,
      "name": "Rock_Basalt"
    },
    {
      "x": -14,
      "y": 6,
      "z": -4,
      "name": "Rock_Basalt"
    },
    {
      "x": -14,
      "y": 7,
      "z": -4,
      "name": "Rock_Basalt"
    },
    {
      "x": -14,
      "y": 8,
      "z": -4,
      "name": "Soil_Dirt"
    },
    {
      "x": -14,
      "y": 9,
      "z": -4,
      "name": "Soil_Grass",
      "rotation": 1
    },
    {
      "x": -14,
      "y": 0,
      "z": -3,
      "name": "Soil_Dirt"
    },
    {
      "x": -14,
      "y": 1,
      "z": -3,
      "name": "Soil_Dirt"
    },
    {
      "x": -14,
      "y": 2,
      "z": -3,
      "name": "Soil_Dirt"
    },
    {
      "x": -14,
      "y": 3,
      "z": -3,
      "name": "Soil_Dirt"
    },
    {
      "x": -14,
      "y": 4,
      "z": -3,
      "name": "Rock_Basalt"
    },
    {
      "x": -14,
      "y": 5,
      "z": -3,
      "name": "Rock_Basalt"
    },
    {
      "x": -14,
      "y": 6,
      "z": -3,
      "name": "Rock_Basalt"
    },
    {
      "x": -14,
      "y": 7,
      "z": -3,
      "name": "Rock_Basalt"
    },
    {
      "x": -14,
      "y": 8,
      "z": -3,
      "name": "Rock_Basalt"
    },
    {
      "x": -14,
      "y": 9,
      "z": -3,
      "name": "Soil_Grass",
      "rotation": 1
    },
    {
      "x": -14,
      "y": 0,
      "z": -2,
      "name": "Soil_Dirt"
    },
    {
      "x": -14,
      "y": 1,
      "z": -2,
      "name": "Soil_Dirt"
    },
    {
      "x": -14,
      "y": 2,
      "z": -2,
      "name": "Soil_Dirt"
    },
    {
      "x": -14,
      "y": 3,
      "z": -2,
      "name": "Soil_Dirt"
    },
    {
      "x": -14,
      "y": 4,
      "z": -2,
      "name": "Rock_Basalt"
    },
    {
      "x": -14,
      "y": 5,
      "z": -2,
      "name": "Rock_Basalt"
    },
    {
      "x": -14,
      "y": 6,
      "z": -2,
      "name": "Rock_Basalt"
    },
    {
      "x": -14,
      "y": 7,
      "z": -2,
      "name": "Rock_Basalt"
    },
    {
      "x": -14,
      "y": 8,
      "z": -2,
      "name": "Soil_Dirt"
    },
    {
      "x": -14,
      "y": 9,
      "z": -2,
      "name": "Soil_Grass",
      "rotation": 1
    },
    {
      "x": -14,
      "y": 0,
      "z": -1,
      "name": "Soil_Dirt"
    },
    {
      "x": -14,
      "y": 1,
      "z": -1,
      "name": "Soil_Dirt"
    },
    {
      "x": -14,
      "y": 2,
      "z": -1,
      "name": "Soil_Dirt"
    },
    {
      "x": -14,
      "y": 3,
      "z": -1,
      "name": "Soil_Grass"
    },
    {
      "x": -14,
      "y": 5,
      "z": -1,
      "name": "Rock_Basalt"
    },
    {
      "x": -14,
      "y": 6,
      "z": -1,
      "name": "Rock_Basalt"
    },
    {
      "x": -14,
      "y": 7,
      "z": -1,
      "name": "Rock_Basalt"
    },
    {
      "x": -14,
      "y": 8,
      "z": -1,
      "name": "Soil_Dirt"
    },
    {
      "x": -14,
      "y": 9,
      "z": -1,
      "name": "Soil_Grass",
      "rotation": 1
    },
    {
      "x": -14,
      "y": 0,
      "z": 0,
      "name": "Soil_Dirt"
    },
    {
      "x": -14,
      "y": 1,
      "z": 0,
      "name": "Soil_Dirt"
    },
    {
      "x": -14,
      "y": 2,
      "z": 0,
      "name": "Soil_Dirt"
    },
    {
      "x": -14,
      "y": 3,
      "z": 0,
      "name": "Soil_Grass"
    },
    {
      "x": -14,
      "y": 6,
      "z": 0,
      "name": "Rock_Basalt"
    },
    {
      "x": -14,
      "y": 7,
      "z": 0,
      "name": "Rock_Basalt"
    },
    {
      "x": -14,
      "y": 8,
      "z": 0,
      "name": "Soil_Dirt"
    },
    {
      "x": -14,
      "y": 9,
      "z": 0,
      "name": "Soil_Grass",
      "rotation": 1
    },
    {
      "x": -14,
      "y": 0,
      "z": 1,
      "name": "Soil_Dirt"
    },
    {
      "x": -14,
      "y": 1,
      "z": 1,
      "name": "Soil_Dirt"
    },
    {
      "x": -14,
      "y": 2,
      "z": 1,
      "name": "Soil_Dirt"
    },
    {
      "x": -14,
      "y": 3,
      "z": 1,
      "name": "Soil_Grass"
    },
    {
      "x": -14,
      "y": 8,
      "z": 1,
      "name": "Soil_Dirt"
    },
    {
      "x": -14,
      "y": 9,
      "z": 1,
      "name": "Soil_Grass",
      "rotation": 1
    },
    {
      "x": -14,
      "y": 0,
      "z": 2,
      "name": "Soil_Dirt"
    },
    {
      "x": -14,
      "y": 1,
      "z": 2,
      "name": "Soil_Dirt"
    },
    {
      "x": -14,
      "y": 2,
      "z": 2,
      "name": "Soil_Dirt"
    },
    {
      "x": -14,
      "y": 3,
      "z": 2,
      "name": "Soil_Grass"
    },
    {
      "x": -14,
      "y": 0,
      "z": 3,
      "name": "Soil_Dirt"
    },
    {
      "x": -14,
      "y": 1,
      "z": 3,
      "name": "Soil_Dirt"
    },
    {
      "x": -14,
      "y": 2,
      "z": 3,
      "name": "Soil_Dirt"
    },
    {
      "x": -14,
      "y": 3,
      "z": 3,
      "name": "Soil_Grass"
    },
    {
      "x": -14,
      "y": 0,
      "z": 4,
      "name": "Soil_Dirt"
    },
    {
      "x": -14,
      "y": 1,
      "z": 4,
      "name": "Soil_Dirt"
    },
    {
      "x": -14,
      "y": 2,
      "z": 4,
      "name": "Soil_Dirt"
    },
    {
      "x": -14,
      "y": 3,
      "z": 4,
      "name": "Soil_Grass"
    },
    {
      "x": -14,
      "y": 0,
      "z": 5,
      "name": "Soil_Dirt"
    },
    {
      "x": -14,
      "y": 1,
      "z": 5,
      "name": "Soil_Dirt"
    },
    {
      "x": -14,
      "y": 2,
      "z": 5,
      "name": "Soil_Dirt"
    },
    {
      "x": -14,
      "y": 3,
      "z": 5,
      "name": "Soil_Grass"
    },
    {
      "x": -14,
      "y": 0,
      "z": 6,
      "name": "Soil_Dirt"
    },
    {
      "x": -14,
      "y": 1,
      "z": 6,
      "name": "Soil_Dirt"
    },
    {
      "x": -14,
      "y": 2,
      "z": 6,
      "name": "Soil_Dirt"
    },
    {
      "x": -14,
      "y": 3,
      "z": 6,
      "name": "Soil_Grass"
    },
    {
      "x": -14,
      "y": 0,
      "z": 7,
      "name": "Soil_Dirt"
    },
    {
      "x": -14,
      "y": 1,
      "z": 7,
      "name": "Soil_Dirt"
    },
    {
      "x": -14,
      "y": 2,
      "z": 7,
      "name": "Soil_Dirt"
    },
    {
      "x": -14,
      "y": 3,
      "z": 7,
      "name": "Soil_Grass"
    },
    {
      "x": -14,
      "y": 0,
      "z": 8,
      "name": "Soil_Dirt"
    },
    {
      "x": -14,
      "y": 1,
      "z": 8,
      "name": "Soil_Dirt"
    },
    {
      "x": -14,
      "y": 2,
      "z": 8,
      "name": "Soil_Dirt"
    },
    {
      "x": -14,
      "y": 3,
      "z": 8,
      "name": "Soil_Grass"
    },
    {
      "x": -14,
      "y": 0,
      "z": 9,
      "name": "Soil_Dirt"
    },
    {
      "x": -14,
      "y": 1,
      "z": 9,
      "name": "Soil_Dirt"
    },
    {
      "x": -14,
      "y": 2,
      "z": 9,
      "name": "Soil_Dirt"
    },
    {
      "x": -14,
      "y": 3,
      "z": 9,
      "name": "Soil_Grass"
    },
    {
      "x": -14,
      "y": 0,
      "z": 10,
      "name": "Soil_Dirt"
    },
    {
      "x": -14,
      "y": 1,
      "z": 10,
      "name": "Soil_Dirt"
    },
    {
      "x": -14,
      "y": 2,
      "z": 10,
      "name": "Soil_Dirt"
    },
    {
      "x": -14,
      "y": 3,
      "z": 10,
      "name": "Soil_Mud_Dry"
    },
    {
      "x": -14,
      "y": 0,
      "z": 11,
      "name": "Soil_Dirt"
    },
    {
      "x": -14,
      "y": 1,
      "z": 11,
      "name": "Soil_Dirt"
    },
    {
      "x": -14,
      "y": 2,
      "z": 11,
      "name": "Soil_Dirt"
    },
    {
      "x": -14,
      "y": 3,
      "z": 11,
      "name": "Soil_Mud_Dry"
    },
    {
      "x": -14,
      "y": 0,
      "z": 12,
      "name": "Soil_Dirt"
    },
    {
      "x": -14,
      "y": 1,
      "z": 12,
      "name": "Soil_Dirt"
    },
    {
      "x": -14,
      "y": 2,
      "z": 12,
      "name": "Soil_Dirt"
    },
    {
      "x": -14,
      "y": 3,
      "z": 12,
      "name": "Soil_Mud_Dry"
    },
    {
      "x": -14,
      "y": 17,
      "z": 12,
      "name": "Plant_Leaves_Beech"
    },
    {
      "x": -14,
      "y": 0,
      "z": 13,
      "name": "Soil_Dirt"
    },
    {
      "x": -14,
      "y": 1,
      "z": 13,
      "name": "Soil_Dirt"
    },
    {
      "x": -14,
      "y": 2,
      "z": 13,
      "name": "Soil_Dirt"
    },
    {
      "x": -14,
      "y": 3,
      "z": 13,
      "name": "Soil_Dirt"
    },
    {
      "x": -14,
      "y": 17,
      "z": 13,
      "name": "Plant_Leaves_Beech"
    },
    {
      "x": -14,
      "y": 18,
      "z": 13,
      "name": "Plant_Leaves_Beech"
    },
    {
      "x": -14,
      "y": 0,
      "z": 14,
      "name": "Soil_Dirt"
    },
    {
      "x": -14,
      "y": 1,
      "z": 14,
      "name": "Soil_Dirt"
    },
    {
      "x": -14,
      "y": 2,
      "z": 14,
      "name": "Soil_Dirt"
    },
    {
      "x": -14,
      "y": 3,
      "z": 14,
      "name": "Soil_Dirt"
    },
    {
      "x": -14,
      "y": 9,
      "z": 14,
      "name": "Plant_Leaves_Beech",
      "support": 1
    },
    {
      "x": -14,
      "y": 15,
      "z": 14,
      "name": "Plant_Leaves_Beech",
      "support": 3
    },
    {
      "x": -14,
      "y": 18,
      "z": 14,
      "name": "Plant_Leaves_Beech"
    },
    {
      "x": -14,
      "y": 19,
      "z": 14,
      "name": "Plant_Leaves_Beech"
    },
    {
      "x": -14,
      "y": 0,
      "z": 15,
      "name": "Soil_Dirt"
    },
    {
      "x": -14,
      "y": 1,
      "z": 15,
      "name": "Soil_Pathway"
    },
    {
      "x": -14,
      "y": 2,
      "z": 15,
      "name": "Soil_Pathway"
    },
    {
      "x": -14,
      "y": 3,
      "z": 15,
      "name": "Soil_Pathway"
    },
    {
      "x": -14,
      "y": 9,
      "z": 15,
      "name": "Plant_Leaves_Beech"
    },
    {
      "x": -14,
      "y": 10,
      "z": 15,
      "name": "Plant_Leaves_Beech",
      "support": 1
    },
    {
      "x": -14,
      "y": 15,
      "z": 15,
      "name": "Plant_Leaves_Beech",
      "support": 2
    },
    {
      "x": -14,
      "y": 16,
      "z": 15,
      "name": "Plant_Leaves_Beech",
      "support": 3
    },
    {
      "x": -14,
      "y": 18,
      "z": 15,
      "name": "Plant_Leaves_Beech"
    },
    {
      "x": -14,
      "y": 19,
      "z": 15,
      "name": "Plant_Leaves_Beech"
    },
    {
      "x": -14,
      "y": 0,
      "z": 16,
      "name": "Soil_Pathway"
    },
    {
      "x": -14,
      "y": 1,
      "z": 16,
      "name": "Soil_Pathway"
    },
    {
      "x": -14,
      "y": 2,
      "z": 16,
      "name": "Soil_Pathway"
    },
    {
      "x": -14,
      "y": 3,
      "z": 16,
      "name": "Soil_Pathway"
    },
    {
      "x": -14,
      "y": 9,
      "z": 16,
      "name": "Wood_Beech_Branch_Corner",
      "support": 2,
      "rotation": 1
    },
    {
      "x": -14,
      "y": 10,
      "z": 16,
      "name": "Plant_Leaves_Beech"
    },
    {
      "x": -14,
      "y": 12,
      "z": 16,
      "name": "Plant_Leaves_Beech"
    },
    {
      "x": -14,
      "y": 14,
      "z": 16,
      "name": "Wood_Beech_Branch_Long",
      "support": 1,
      "rotation": 5
    },
    {
      "x": -14,
      "y": 18,
      "z": 16,
      "name": "Plant_Leaves_Beech"
    },
    {
      "x": -14,
      "y": 19,
      "z": 16,
      "name": "Plant_Leaves_Beech"
    },
    {
      "x": -14,
      "y": 20,
      "z": 16,
      "name": "Plant_Leaves_Beech"
    },
    {
      "x": -13,
      "y": 0,
      "z": -15,
      "name": "Soil_Dirt"
    },
    {
      "x": -13,
      "y": 1,
      "z": -15,
      "name": "Soil_Dirt"
    },
    {
      "x": -13,
      "y": 2,
      "z": -15,
      "name": "Soil_Dirt"
    },
    {
      "x": -13,
      "y": 3,
      "z": -15,
      "name": "Soil_Grass"
    },
    {
      "x": -13,
      "y": 0,
      "z": -14,
      "name": "Soil_Dirt"
    },
    {
      "x": -13,
      "y": 1,
      "z": -14,
      "name": "Soil_Dirt"
    },
    {
      "x": -13,
      "y": 2,
      "z": -14,
      "name": "Soil_Dirt"
    },
    {
      "x": -13,
      "y": 3,
      "z": -14,
      "name": "Soil_Grass"
    },
    {
      "x": -13,
      "y": 0,
      "z": -13,
      "name": "Soil_Dirt"
    },
    {
      "x": -13,
      "y": 1,
      "z": -13,
      "name": "Soil_Dirt"
    },
    {
      "x": -13,
      "y": 2,
      "z": -13,
      "name": "Soil_Dirt"
    },
    {
      "x": -13,
      "y": 3,
      "z": -13,
      "name": "Soil_Grass"
    },
    {
      "x": -13,
      "y": 0,
      "z": -12,
      "name": "Soil_Dirt"
    },
    {
      "x": -13,
      "y": 1,
      "z": -12,
      "name": "Soil_Dirt"
    },
    {
      "x": -13,
      "y": 2,
      "z": -12,
      "name": "Soil_Dirt"
    },
    {
      "x": -13,
      "y": 3,
      "z": -12,
      "name": "Soil_Grass"
    },
    {
      "x": -13,
      "y": 0,
      "z": -11,
      "name": "Soil_Dirt"
    },
    {
      "x": -13,
      "y": 1,
      "z": -11,
      "name": "Soil_Dirt"
    },
    {
      "x": -13,
      "y": 2,
      "z": -11,
      "name": "Soil_Dirt"
    },
    {
      "x": -13,
      "y": 3,
      "z": -11,
      "name": "Soil_Grass"
    },
    {
      "x": -13,
      "y": 0,
      "z": -10,
      "name": "Soil_Dirt"
    },
    {
      "x": -13,
      "y": 1,
      "z": -10,
      "name": "Soil_Dirt"
    },
    {
      "x": -13,
      "y": 2,
      "z": -10,
      "name": "Soil_Dirt"
    },
    {
      "x": -13,
      "y": 3,
      "z": -10,
      "name": "Soil_Grass"
    },
    {
      "x": -13,
      "y": 6,
      "z": -10,
      "name": "Rock_Basalt"
    },
    {
      "x": -13,
      "y": 7,
      "z": -10,
      "name": "Rock_Basalt"
    },
    {
      "x": -13,
      "y": 8,
      "z": -10,
      "name": "Soil_Dirt"
    },
    {
      "x": -13,
      "y": 9,
      "z": -10,
      "name": "Soil_Grass",
      "rotation": 1
    },
    {
      "x": -13,
      "y": 0,
      "z": -9,
      "name": "Soil_Dirt"
    },
    {
      "x": -13,
      "y": 1,
      "z": -9,
      "name": "Soil_Dirt"
    },
    {
      "x": -13,
      "y": 2,
      "z": -9,
      "name": "Soil_Dirt"
    },
    {
      "x": -13,
      "y": 3,
      "z": -9,
      "name": "Soil_Dirt"
    },
    {
      "x": -13,
      "y": 4,
      "z": -9,
      "name": "Rock_Basalt"
    },
    {
      "x": -13,
      "y": 5,
      "z": -9,
      "name": "Rock_Basalt"
    },
    {
      "x": -13,
      "y": 6,
      "z": -9,
      "name": "Rock_Basalt"
    },
    {
      "x": -13,
      "y": 7,
      "z": -9,
      "name": "Rock_Basalt"
    },
    {
      "x": -13,
      "y": 8,
      "z": -9,
      "name": "Soil_Dirt"
    },
    {
      "x": -13,
      "y": 9,
      "z": -9,
      "name": "Soil_Grass",
      "rotation": 1
    },
    {
      "x": -13,
      "y": 10,
      "z": -9,
      "name": "Plant_Grass_Winter",
      "rotation": 1
    },
    {
      "x": -13,
      "y": 0,
      "z": -8,
      "name": "Soil_Dirt"
    },
    {
      "x": -13,
      "y": 1,
      "z": -8,
      "name": "Rock_Basalt"
    },
    {
      "x": -13,
      "y": 2,
      "z": -8,
      "name": "Rock_Basalt"
    },
    {
      "x": -13,
      "y": 3,
      "z": -8,
      "name": "Rock_Basalt"
    },
    {
      "x": -13,
      "y": 4,
      "z": -8,
      "name": "Rock_Basalt"
    },
    {
      "x": -13,
      "y": 5,
      "z": -8,
      "name": "Rock_Basalt"
    },
    {
      "x": -13,
      "y": 6,
      "z": -8,
      "name": "Rock_Basalt"
    },
    {
      "x": -13,
      "y": 7,
      "z": -8,
      "name": "Rock_Basalt"
    },
    {
      "x": -13,
      "y": 8,
      "z": -8,
      "name": "Soil_Dirt"
    },
    {
      "x": -13,
      "y": 9,
      "z": -8,
      "name": "Soil_Grass",
      "rotation": 1
    },
    {
      "x": -13,
      "y": 10,
      "z": -8,
      "name": "Plant_Grass_Winter",
      "rotation": 1
    },
    {
      "x": -13,
      "y": 0,
      "z": -7,
      "name": "Rock_Basalt"
    },
    {
      "x": -13,
      "y": 1,
      "z": -7,
      "name": "Rock_Basalt"
    },
    {
      "x": -13,
      "y": 2,
      "z": -7,
      "name": "Rock_Basalt"
    },
    {
      "x": -13,
      "y": 3,
      "z": -7,
      "name": "Wood_Redwood_Trunk",
      "support": 15,
      "rotation": 1
    },
    {
      "x": -13,
      "y": 4,
      "z": -7,
      "name": "Rock_Basalt"
    },
    {
      "x": -13,
      "y": 5,
      "z": -7,
      "name": "Rock_Basalt"
    },
    {
      "x": -13,
      "y": 6,
      "z": -7,
      "name": "Rock_Basalt"
    },
    {
      "x": -13,
      "y": 7,
      "z": -7,
      "name": "Rock_Basalt"
    },
    {
      "x": -13,
      "y": 8,
      "z": -7,
      "name": "Soil_Dirt"
    },
    {
      "x": -13,
      "y": 9,
      "z": -7,
      "name": "Soil_Grass",
      "rotation": 1
    },
    {
      "x": -13,
      "y": 10,
      "z": -7,
      "name": "Plant_Grass_Winter_Short",
      "rotation": 1
    },
    {
      "x": -13,
      "y": 28,
      "z": -7,
      "name": "Plant_Leaves_Redwood",
      "support": 3,
      "rotation": 1
    },
    {
      "x": -13,
      "y": 29,
      "z": -7,
      "name": "Plant_Leaves_Redwood",
      "support": 4,
      "rotation": 1
    },
    {
      "x": -13,
      "y": 0,
      "z": -6,
      "name": "Rock_Basalt"
    },
    {
      "x": -13,
      "y": 1,
      "z": -6,
      "name": "Rock_Basalt"
    },
    {
      "x": -13,
      "y": 2,
      "z": -6,
      "name": "Rock_Basalt"
    },
    {
      "x": -13,
      "y": 3,
      "z": -6,
      "name": "Rock_Basalt"
    },
    {
      "x": -13,
      "y": 4,
      "z": -6,
      "name": "Wood_Redwood_Trunk",
      "support": 15,
      "rotation": 1
    },
    {
      "x": -13,
      "y": 5,
      "z": -6,
      "name": "Rock_Basalt"
    },
    {
      "x": -13,
      "y": 6,
      "z": -6,
      "name": "Rock_Basalt"
    },
    {
      "x": -13,
      "y": 7,
      "z": -6,
      "name": "Rock_Basalt"
    },
    {
      "x": -13,
      "y": 8,
      "z": -6,
      "name": "Soil_Dirt"
    },
    {
      "x": -13,
      "y": 9,
      "z": -6,
      "name": "Soil_Needles"
    },
    {
      "x": -13,
      "y": 24,
      "z": -6,
      "name": "Plant_Leaves_Redwood",
      "support": 3,
      "rotation": 1
    },
    {
      "x": -13,
      "y": 25,
      "z": -6,
      "name": "Plant_Leaves_Redwood",
      "support": 4,
      "rotation": 1
    },
    {
      "x": -13,
      "y": 28,
      "z": -6,
      "name": "Plant_Leaves_Redwood",
      "support": 2,
      "rotation": 1
    },
    {
      "x": -13,
      "y": 29,
      "z": -6,
      "name": "Plant_Leaves_Redwood",
      "support": 3,
      "rotation": 1
    },
    {
      "x": -13,
      "y": 0,
      "z": -5,
      "name": "Rock_Basalt"
    },
    {
      "x": -13,
      "y": 1,
      "z": -5,
      "name": "Rock_Basalt"
    },
    {
      "x": -13,
      "y": 2,
      "z": -5,
      "name": "Rock_Basalt"
    },
    {
      "x": -13,
      "y": 3,
      "z": -5,
      "name": "Rock_Basalt"
    },
    {
      "x": -13,
      "y": 4,
      "z": -5,
      "name": "Rock_Basalt"
    },
    {
      "x": -13,
      "y": 5,
      "z": -5,
      "name": "Rock_Basalt"
    },
    {
      "x": -13,
      "y": 6,
      "z": -5,
      "name": "Rock_Basalt"
    },
    {
      "x": -13,
      "y": 7,
      "z": -5,
      "name": "Rock_Basalt"
    },
    {
      "x": -13,
      "y": 8,
      "z": -5,
      "name": "Soil_Dirt"
    },
    {
      "x": -13,
      "y": 9,
      "z": -5,
      "name": "Soil_Needles"
    },
    {
      "x": -13,
      "y": 0,
      "z": -4,
      "name": "Rock_Basalt"
    },
    {
      "x": -13,
      "y": 1,
      "z": -4,
      "name": "Rock_Basalt"
    },
    {
      "x": -13,
      "y": 2,
      "z": -4,
      "name": "Rock_Basalt"
    },
    {
      "x": -13,
      "y": 3,
      "z": -4,
      "name": "Rock_Basalt"
    },
    {
      "x": -13,
      "y": 4,
      "z": -4,
      "name": "Rock_Basalt"
    },
    {
      "x": -13,
      "y": 5,
      "z": -4,
      "name": "Rock_Basalt"
    },
    {
      "x": -13,
      "y": 6,
      "z": -4,
      "name": "Rock_Basalt"
    },
    {
      "x": -13,
      "y": 7,
      "z": -4,
      "name": "Rock_Basalt"
    },
    {
      "x": -13,
      "y": 8,
      "z": -4,
      "name": "Soil_Dirt"
    },
    {
      "x": -13,
      "y": 9,
      "z": -4,
      "name": "Soil_Needles"
    },
    {
      "x": -13,
      "y": 0,
      "z": -3,
      "name": "Rock_Basalt"
    },
    {
      "x": -13,
      "y": 1,
      "z": -3,
      "name": "Rock_Basalt"
    },
    {
      "x": -13,
      "y": 2,
      "z": -3,
      "name": "Rock_Basalt"
    },
    {
      "x": -13,
      "y": 3,
      "z": -3,
      "name": "Rock_Basalt"
    },
    {
      "x": -13,
      "y": 4,
      "z": -3,
      "name": "Rock_Basalt"
    },
    {
      "x": -13,
      "y": 5,
      "z": -3,
      "name": "Rock_Basalt"
    },
    {
      "x": -13,
      "y": 6,
      "z": -3,
      "name": "Rock_Basalt"
    },
    {
      "x": -13,
      "y": 7,
      "z": -3,
      "name": "Rock_Basalt"
    },
    {
      "x": -13,
      "y": 8,
      "z": -3,
      "name": "Rock_Basalt"
    },
    {
      "x": -13,
      "y": 9,
      "z": -3,
      "name": "Soil_Needles"
    },
    {
      "x": -13,
      "y": 0,
      "z": -2,
      "name": "Rock_Basalt"
    },
    {
      "x": -13,
      "y": 1,
      "z": -2,
      "name": "Rock_Basalt"
    },
    {
      "x": -13,
      "y": 2,
      "z": -2,
      "name": "Rock_Basalt"
    },
    {
      "x": -13,
      "y": 3,
      "z": -2,
      "name": "Rock_Basalt"
    },
    {
      "x": -13,
      "y": 4,
      "z": -2,
      "name": "Rock_Basalt"
    },
    {
      "x": -13,
      "y": 5,
      "z": -2,
      "name": "Rock_Basalt"
    },
    {
      "x": -13,
      "y": 6,
      "z": -2,
      "name": "Rock_Basalt"
    },
    {
      "x": -13,
      "y": 7,
      "z": -2,
      "name": "Rock_Basalt"
    },
    {
      "x": -13,
      "y": 8,
      "z": -2,
      "name": "Soil_Dirt"
    },
    {
      "x": -13,
      "y": 9,
      "z": -2,
      "name": "Soil_Needles"
    },
    {
      "x": -13,
      "y": 0,
      "z": -1,
      "name": "Rock_Basalt"
    },
    {
      "x": -13,
      "y": 1,
      "z": -1,
      "name": "Rock_Basalt"
    },
    {
      "x": -13,
      "y": 2,
      "z": -1,
      "name": "Rock_Basalt"
    },
    {
      "x": -13,
      "y": 3,
      "z": -1,
      "name": "Rock_Basalt"
    },
    {
      "x": -13,
      "y": 4,
      "z": -1,
      "name": "Rock_Basalt"
    },
    {
      "x": -13,
      "y": 5,
      "z": -1,
      "name": "Rock_Basalt"
    },
    {
      "x": -13,
      "y": 6,
      "z": -1,
      "name": "Rock_Basalt"
    },
    {
      "x": -13,
      "y": 7,
      "z": -1,
      "name": "Rock_Basalt"
    },
    {
      "x": -13,
      "y": 8,
      "z": -1,
      "name": "Soil_Dirt"
    },
    {
      "x": -13,
      "y": 9,
      "z": -1,
      "name": "Soil_Grass",
      "rotation": 1
    },
    {
      "x": -13,
      "y": 0,
      "z": 0,
      "name": "Soil_Dirt"
    },
    {
      "x": -13,
      "y": 1,
      "z": 0,
      "name": "Rock_Basalt"
    },
    {
      "x": -13,
      "y": 2,
      "z": 0,
      "name": "Rock_Basalt"
    },
    {
      "x": -13,
      "y": 3,
      "z": 0,
      "name": "Rock_Basalt"
    },
    {
      "x": -13,
      "y": 4,
      "z": 0,
      "name": "Rock_Basalt"
    },
    {
      "x": -13,
      "y": 5,
      "z": 0,
      "name": "Rock_Basalt"
    },
    {
      "x": -13,
      "y": 6,
      "z": 0,
      "name": "Rock_Basalt"
    },
    {
      "x": -13,
      "y": 7,
      "z": 0,
      "name": "Rock_Basalt"
    },
    {
      "x": -13,
      "y": 8,
      "z": 0,
      "name": "Soil_Dirt"
    },
    {
      "x": -13,
      "y": 9,
      "z": 0,
      "name": "Soil_Grass",
      "rotation": 1
    },
    {
      "x": -13,
      "y": 10,
      "z": 0,
      "name": "Plant_Flower_Flax_Blue",
      "rotation": 1
    },
    {
      "x": -13,
      "y": 0,
      "z": 1,
      "name": "Soil_Dirt"
    },
    {
      "x": -13,
      "y": 1,
      "z": 1,
      "name": "Soil_Dirt"
    },
    {
      "x": -13,
      "y": 2,
      "z": 1,
      "name": "Soil_Dirt"
    },
    {
      "x": -13,
      "y": 3,
      "z": 1,
      "name": "Rock_Basalt"
    },
    {
      "x": -13,
      "y": 4,
      "z": 1,
      "name": "Rock_Basalt"
    },
    {
      "x": -13,
      "y": 5,
      "z": 1,
      "name": "Rock_Basalt"
    },
    {
      "x": -13,
      "y": 6,
      "z": 1,
      "name": "Rock_Basalt"
    },
    {
      "x": -13,
      "y": 7,
      "z": 1,
      "name": "Rock_Basalt"
    },
    {
      "x": -13,
      "y": 8,
      "z": 1,
      "name": "Soil_Dirt"
    },
    {
      "x": -13,
      "y": 9,
      "z": 1,
      "name": "Soil_Grass",
      "rotation": 1
    },
    {
      "x": -13,
      "y": 0,
      "z": 2,
      "name": "Soil_Dirt"
    },
    {
      "x": -13,
      "y": 1,
      "z": 2,
      "name": "Soil_Dirt"
    },
    {
      "x": -13,
      "y": 2,
      "z": 2,
      "name": "Soil_Dirt"
    },
    {
      "x": -13,
      "y": 3,
      "z": 2,
      "name": "Soil_Grass"
    },
    {
      "x": -13,
      "y": 7,
      "z": 2,
      "name": "Rock_Basalt"
    },
    {
      "x": -13,
      "y": 8,
      "z": 2,
      "name": "Soil_Dirt"
    },
    {
      "x": -13,
      "y": 9,
      "z": 2,
      "name": "Soil_Grass",
      "rotation": 1
    },
    {
      "x": -13,
      "y": 0,
      "z": 3,
      "name": "Soil_Dirt"
    },
    {
      "x": -13,
      "y": 1,
      "z": 3,
      "name": "Soil_Dirt"
    },
    {
      "x": -13,
      "y": 2,
      "z": 3,
      "name": "Soil_Dirt"
    },
    {
      "x": -13,
      "y": 3,
      "z": 3,
      "name": "Soil_Grass"
    },
    {
      "x": -13,
      "y": 0,
      "z": 4,
      "name": "Soil_Dirt"
    },
    {
      "x": -13,
      "y": 1,
      "z": 4,
      "name": "Soil_Dirt"
    },
    {
      "x": -13,
      "y": 2,
      "z": 4,
      "name": "Soil_Dirt"
    },
    {
      "x": -13,
      "y": 3,
      "z": 4,
      "name": "Soil_Grass"
    },
    {
      "x": -13,
      "y": 0,
      "z": 5,
      "name": "Soil_Dirt"
    },
    {
      "x": -13,
      "y": 1,
      "z": 5,
      "name": "Soil_Dirt"
    },
    {
      "x": -13,
      "y": 2,
      "z": 5,
      "name": "Soil_Dirt"
    },
    {
      "x": -13,
      "y": 3,
      "z": 5,
      "name": "Soil_Grass"
    },
    {
      "x": -13,
      "y": 0,
      "z": 6,
      "name": "Soil_Dirt"
    },
    {
      "x": -13,
      "y": 1,
      "z": 6,
      "name": "Soil_Dirt"
    },
    {
      "x": -13,
      "y": 2,
      "z": 6,
      "name": "Soil_Dirt"
    },
    {
      "x": -13,
      "y": 3,
      "z": 6,
      "name": "Soil_Grass"
    },
    {
      "x": -13,
      "y": 0,
      "z": 7,
      "name": "Soil_Dirt"
    },
    {
      "x": -13,
      "y": 1,
      "z": 7,
      "name": "Soil_Dirt"
    },
    {
      "x": -13,
      "y": 2,
      "z": 7,
      "name": "Soil_Dirt"
    },
    {
      "x": -13,
      "y": 3,
      "z": 7,
      "name": "Soil_Grass"
    },
    {
      "x": -13,
      "y": 0,
      "z": 8,
      "name": "Soil_Dirt"
    },
    {
      "x": -13,
      "y": 1,
      "z": 8,
      "name": "Soil_Dirt"
    },
    {
      "x": -13,
      "y": 2,
      "z": 8,
      "name": "Soil_Dirt"
    },
    {
      "x": -13,
      "y": 3,
      "z": 8,
      "name": "Soil_Grass"
    },
    {
      "x": -13,
      "y": 0,
      "z": 9,
      "name": "Soil_Dirt"
    },
    {
      "x": -13,
      "y": 1,
      "z": 9,
      "name": "Soil_Dirt"
    },
    {
      "x": -13,
      "y": 2,
      "z": 9,
      "name": "Soil_Dirt"
    },
    {
      "x": -13,
      "y": 3,
      "z": 9,
      "name": "Soil_Grass"
    },
    {
      "x": -13,
      "y": 0,
      "z": 10,
      "name": "Soil_Dirt"
    },
    {
      "x": -13,
      "y": 1,
      "z": 10,
      "name": "Soil_Dirt"
    },
    {
      "x": -13,
      "y": 2,
      "z": 10,
      "name": "Soil_Dirt"
    },
    {
      "x": -13,
      "y": 3,
      "z": 10,
      "name": "Soil_Mud_Dry"
    },
    {
      "x": -13,
      "y": 0,
      "z": 11,
      "name": "Soil_Dirt"
    },
    {
      "x": -13,
      "y": 1,
      "z": 11,
      "name": "Soil_Dirt"
    },
    {
      "x": -13,
      "y": 2,
      "z": 11,
      "name": "Soil_Dirt"
    },
    {
      "x": -13,
      "y": 3,
      "z": 11,
      "name": "Soil_Mud_Dry"
    },
    {
      "x": -13,
      "y": 0,
      "z": 12,
      "name": "Soil_Pathway"
    },
    {
      "x": -13,
      "y": 1,
      "z": 12,
      "name": "Soil_Dirt"
    },
    {
      "x": -13,
      "y": 2,
      "z": 12,
      "name": "Soil_Pathway"
    },
    {
      "x": -13,
      "y": 3,
      "z": 12,
      "name": "Soil_Pathway"
    },
    {
      "x": -13,
      "y": 0,
      "z": 13,
      "name": "Soil_Pathway"
    },
    {
      "x": -13,
      "y": 1,
      "z": 13,
      "name": "Soil_Pathway"
    },
    {
      "x": -13,
      "y": 2,
      "z": 13,
      "name": "Soil_Pathway"
    },
    {
      "x": -13,
      "y": 3,
      "z": 13,
      "name": "Soil_Pathway"
    },
    {
      "x": -13,
      "y": 0,
      "z": 14,
      "name": "Soil_Dirt"
    },
    {
      "x": -13,
      "y": 1,
      "z": 14,
      "name": "Soil_Pathway"
    },
    {
      "x": -13,
      "y": 2,
      "z": 14,
      "name": "Soil_Pathway"
    },
    {
      "x": -13,
      "y": 3,
      "z": 14,
      "name": "Soil_Mud_Dry"
    },
    {
      "x": -13,
      "y": 9,
      "z": 14,
      "name": "Plant_Leaves_Beech",
      "support": 2
    },
    {
      "x": -13,
      "y": 14,
      "z": 14,
      "name": "Plant_Leaves_Beech",
      "support": 1
    },
    {
      "x": -13,
      "y": 15,
      "z": 14,
      "name": "Plant_Leaves_Beech",
      "support": 2
    },
    {
      "x": -13,
      "y": 0,
      "z": 15,
      "name": "Soil_Dirt"
    },
    {
      "x": -13,
      "y": 1,
      "z": 15,
      "name": "Soil_Pathway"
    },
    {
      "x": -13,
      "y": 2,
      "z": 15,
      "name": "Soil_Pathway"
    },
    {
      "x": -13,
      "y": 3,
      "z": 15,
      "name": "Soil_Pathway"
    },
    {
      "x": -13,
      "y": 9,
      "z": 15,
      "name": "Plant_Leaves_Beech",
      "support": 1
    },
    {
      "x": -13,
      "y": 10,
      "z": 15,
      "name": "Plant_Leaves_Beech",
      "support": 2
    },
    {
      "x": -13,
      "y": 14,
      "z": 15,
      "name": "Plant_Leaves_Beech"
    },
    {
      "x": -13,
      "y": 15,
      "z": 15,
      "name": "Plant_Leaves_Beech",
      "support": 1
    },
    {
      "x": -13,
      "y": 16,
      "z": 15,
      "name": "Plant_Leaves_Beech",
      "support": 2
    },
    {
      "x": -13,
      "y": 0,
      "z": 16,
      "name": "Soil_Pathway"
    },
    {
      "x": -13,
      "y": 1,
      "z": 16,
      "name": "Soil_Pathway"
    },
    {
      "x": -13,
      "y": 2,
      "z": 16,
      "name": "Soil_Dirt"
    },
    {
      "x": -13,
      "y": 3,
      "z": 16,
      "name": "Soil_Dirt"
    },
    {
      "x": -13,
      "y": 9,
      "z": 16,
      "name": "Plant_Leaves_Beech"
    },
    {
      "x": -13,
      "y": 10,
      "z": 16,
      "name": "Plant_Leaves_Beech",
      "support": 1
    },
    {
      "x": -13,
      "y": 14,
      "z": 16,
      "name": "Wood_Beech_Branch_Corner",
      "support": 2,
      "rotation": 1
    },
    {
      "x": -13,
      "y": 15,
      "z": 16,
      "name": "Plant_Leaves_Beech"
    },
    {
      "x": -13,
      "y": 16,
      "z": 16,
      "name": "Plant_Leaves_Beech",
      "support": 1
    },
    {
      "x": -12,
      "y": 0,
      "z": -15,
      "name": "Soil_Dirt"
    },
    {
      "x": -12,
      "y": 1,
      "z": -15,
      "name": "Soil_Dirt"
    },
    {
      "x": -12,
      "y": 2,
      "z": -15,
      "name": "Soil_Dirt"
    },
    {
      "x": -12,
      "y": 3,
      "z": -15,
      "name": "Soil_Grass"
    },
    {
      "x": -12,
      "y": 0,
      "z": -14,
      "name": "Soil_Dirt"
    },
    {
      "x": -12,
      "y": 1,
      "z": -14,
      "name": "Soil_Dirt"
    },
    {
      "x": -12,
      "y": 2,
      "z": -14,
      "name": "Soil_Dirt"
    },
    {
      "x": -12,
      "y": 3,
      "z": -14,
      "name": "Soil_Grass"
    },
    {
      "x": -12,
      "y": 0,
      "z": -13,
      "name": "Soil_Dirt"
    },
    {
      "x": -12,
      "y": 1,
      "z": -13,
      "name": "Soil_Dirt"
    },
    {
      "x": -12,
      "y": 2,
      "z": -13,
      "name": "Soil_Dirt"
    },
    {
      "x": -12,
      "y": 3,
      "z": -13,
      "name": "Soil_Grass"
    },
    {
      "x": -12,
      "y": 0,
      "z": -12,
      "name": "Soil_Dirt"
    },
    {
      "x": -12,
      "y": 1,
      "z": -12,
      "name": "Soil_Dirt"
    },
    {
      "x": -12,
      "y": 2,
      "z": -12,
      "name": "Soil_Dirt"
    },
    {
      "x": -12,
      "y": 3,
      "z": -12,
      "name": "Soil_Grass"
    },
    {
      "x": -12,
      "y": 6,
      "z": -12,
      "name": "Plant_Crop_Mushroom_Block_Yellow",
      "rotation": 1
    },
    {
      "x": -12,
      "y": 7,
      "z": -12,
      "name": "Plant_Moss_Rug_Green",
      "rotation": 1
    },
    {
      "x": -12,
      "y": 0,
      "z": -11,
      "name": "Soil_Dirt"
    },
    {
      "x": -12,
      "y": 1,
      "z": -11,
      "name": "Soil_Dirt"
    },
    {
      "x": -12,
      "y": 2,
      "z": -11,
      "name": "Soil_Dirt"
    },
    {
      "x": -12,
      "y": 3,
      "z": -11,
      "name": "Soil_Grass"
    },
    {
      "x": -12,
      "y": 6,
      "z": -11,
      "name": "Plant_Crop_Mushroom_Block_Yellow",
      "rotation": 1
    },
    {
      "x": -12,
      "y": 0,
      "z": -10,
      "name": "Soil_Dirt"
    },
    {
      "x": -12,
      "y": 1,
      "z": -10,
      "name": "Soil_Dirt"
    },
    {
      "x": -12,
      "y": 2,
      "z": -10,
      "name": "Rock_Basalt"
    },
    {
      "x": -12,
      "y": 3,
      "z": -10,
      "name": "Rock_Basalt"
    },
    {
      "x": -12,
      "y": 4,
      "z": -10,
      "name": "Rock_Basalt"
    },
    {
      "x": -12,
      "y": 5,
      "z": -10,
      "name": "Rock_Basalt"
    },
    {
      "x": -12,
      "y": 6,
      "z": -10,
      "name": "Rock_Basalt"
    },
    {
      "x": -12,
      "y": 7,
      "z": -10,
      "name": "Rock_Basalt"
    },
    {
      "x": -12,
      "y": 8,
      "z": -10,
      "name": "Soil_Dirt"
    },
    {
      "x": -12,
      "y": 9,
      "z": -10,
      "name": "Soil_Grass",
      "rotation": 1
    },
    {
      "x": -12,
      "y": 10,
      "z": -10,
      "name": "Plant_Grass_Winter_Tall",
      "rotation": 1
    },
    {
      "x": -12,
      "y": 11,
      "z": -10,
      "name": "Plant_Grass_Winter_Tall",
      "filler": 1024,
      "rotation": 1
    },
    {
      "x": -12,
      "y": 0,
      "z": -9,
      "name": "Soil_Dirt"
    },
    {
      "x": -12,
      "y": 1,
      "z": -9,
      "name": "Rock_Basalt"
    },
    {
      "x": -12,
      "y": 2,
      "z": -9,
      "name": "Rock_Basalt"
    },
    {
      "x": -12,
      "y": 3,
      "z": -9,
      "name": "Rock_Basalt"
    },
    {
      "x": -12,
      "y": 4,
      "z": -9,
      "name": "Rock_Basalt"
    },
    {
      "x": -12,
      "y": 5,
      "z": -9,
      "name": "Rock_Basalt"
    },
    {
      "x": -12,
      "y": 6,
      "z": -9,
      "name": "Rock_Basalt"
    },
    {
      "x": -12,
      "y": 7,
      "z": -9,
      "name": "Rock_Basalt"
    },
    {
      "x": -12,
      "y": 8,
      "z": -9,
      "name": "Soil_Dirt"
    },
    {
      "x": -12,
      "y": 9,
      "z": -9,
      "name": "Soil_Grass",
      "rotation": 1
    },
    {
      "x": -12,
      "y": 10,
      "z": -9,
      "name": "Plant_Grass_Winter_Tall",
      "rotation": 1
    },
    {
      "x": -12,
      "y": 11,
      "z": -9,
      "name": "Plant_Grass_Winter_Tall",
      "filler": 1024,
      "rotation": 1
    },
    {
      "x": -12,
      "y": 0,
      "z": -8,
      "name": "Rock_Basalt"
    },
    {
      "x": -12,
      "y": 1,
      "z": -8,
      "name": "Rock_Basalt"
    },
    {
      "x": -12,
      "y": 2,
      "z": -8,
      "name": "Rock_Basalt"
    },
    {
      "x": -12,
      "y": 3,
      "z": -8,
      "name": "Rock_Basalt"
    },
    {
      "x": -12,
      "y": 5,
      "z": -8,
      "name": "Rock_Basalt"
    },
    {
      "x": -12,
      "y": 6,
      "z": -8,
      "name": "Rock_Basalt"
    },
    {
      "x": -12,
      "y": 7,
      "z": -8,
      "name": "Rock_Basalt"
    },
    {
      "x": -12,
      "y": 8,
      "z": -8,
      "name": "Soil_Dirt"
    },
    {
      "x": -12,
      "y": 9,
      "z": -8,
      "name": "Soil_Grass",
      "rotation": 1
    },
    {
      "x": -12,
      "y": 10,
      "z": -8,
      "name": "Plant_Grass_Winter",
      "rotation": 1
    },
    {
      "x": -12,
      "y": 0,
      "z": -7,
      "name": "Rock_Basalt"
    },
    {
      "x": -12,
      "y": 1,
      "z": -7,
      "name": "Rock_Basalt"
    },
    {
      "x": -12,
      "y": 2,
      "z": -7,
      "name": "Rock_Basalt"
    },
    {
      "x": -12,
      "y": 3,
      "z": -7,
      "name": "Rock_Basalt"
    },
    {
      "x": -12,
      "y": 5,
      "z": -7,
      "name": "Rock_Basalt"
    },
    {
      "x": -12,
      "y": 6,
      "z": -7,
      "name": "Rock_Basalt"
    },
    {
      "x": -12,
      "y": 7,
      "z": -7,
      "name": "Rock_Basalt"
    },
    {
      "x": -12,
      "y": 8,
      "z": -7,
      "name": "Soil_Dirt"
    },
    {
      "x": -12,
      "y": 9,
      "z": -7,
      "name": "Soil_Needles"
    },
    {
      "x": -12,
      "y": 28,
      "z": -7,
      "name": "Plant_Leaves_Redwood",
      "support": 2,
      "rotation": 1
    },
    {
      "x": -12,
      "y": 36,
      "z": -7,
      "name": "Plant_Leaves_Redwood",
      "rotation": 1
    },
    {
      "x": -12,
      "y": 0,
      "z": -6,
      "name": "Rock_Basalt"
    },
    {
      "x": -12,
      "y": 1,
      "z": -6,
      "name": "Rock_Basalt"
    },
    {
      "x": -12,
      "y": 2,
      "z": -6,
      "name": "Rock_Basalt"
    },
    {
      "x": -12,
      "y": 3,
      "z": -6,
      "name": "Wood_Redwood_Trunk",
      "support": 15,
      "rotation": 1
    },
    {
      "x": -12,
      "y": 4,
      "z": -6,
      "name": "Wood_Redwood_Trunk",
      "support": 15,
      "rotation": 1
    },
    {
      "x": -12,
      "y": 5,
      "z": -6,
      "name": "Wood_Redwood_Trunk",
      "support": 15,
      "rotation": 1
    },
    {
      "x": -12,
      "y": 6,
      "z": -6,
      "name": "Rock_Basalt"
    },
    {
      "x": -12,
      "y": 7,
      "z": -6,
      "name": "Rock_Basalt"
    },
    {
      "x": -12,
      "y": 8,
      "z": -6,
      "name": "Soil_Dirt"
    },
    {
      "x": -12,
      "y": 9,
      "z": -6,
      "name": "Soil_Needles"
    },
    {
      "x": -12,
      "y": 24,
      "z": -6,
      "name": "Plant_Leaves_Redwood",
      "support": 2,
      "rotation": 1
    },
    {
      "x": -12,
      "y": 28,
      "z": -6,
      "name": "Plant_Leaves_Redwood",
      "support": 1,
      "rotation": 1
    },
    {
      "x": -12,
      "y": 43,
      "z": -6,
      "name": "Plant_Leaves_Redwood",
      "rotation": 1
    },
    {
      "x": -12,
      "y": 0,
      "z": -5,
      "name": "Rock_Basalt"
    },
    {
      "x": -12,
      "y": 1,
      "z": -5,
      "name": "Rock_Basalt"
    },
    {
      "x": -12,
      "y": 2,
      "z": -5,
      "name": "Rock_Basalt"
    },
    {
      "x": -12,
      "y": 3,
      "z": -5,
      "name": "Rock_Basalt"
    },
    {
      "x": -12,
      "y": 4,
      "z": -5,
      "name": "Wood_Redwood_Trunk",
      "support": 15,
      "rotation": 1
    },
    {
      "x": -12,
      "y": 5,
      "z": -5,
      "name": "Wood_Redwood_Trunk",
      "support": 15,
      "rotation": 1
    },
    {
      "x": -12,
      "y": 6,
      "z": -5,
      "name": "Rock_Basalt"
    },
    {
      "x": -12,
      "y": 7,
      "z": -5,
      "name": "Rock_Basalt"
    },
    {
      "x": -12,
      "y": 8,
      "z": -5,
      "name": "Soil_Dirt"
    },
    {
      "x": -12,
      "y": 9,
      "z": -5,
      "name": "Soil_Needles"
    },
    {
      "x": -12,
      "y": 10,
      "z": -5,
      "name": "Plant_Crop_Mushroom_Common_Brown",
      "components": {
        "Components": {
          "FarmingBlock": {
            "LastTickGameTime": "0001-01-01T12:00:00Z"
          }
        }
      },
      "rotation": 1
    },
    {
      "x": -12,
      "y": 28,
      "z": -5,
      "name": "Plant_Leaves_Redwood",
      "support": 2,
      "rotation": 1
    },
    {
      "x": -12,
      "y": 43,
      "z": -5,
      "name": "Plant_Leaves_Redwood",
      "rotation": 1
    },
    {
      "x": -12,
      "y": 0,
      "z": -4,
      "name": "Rock_Basalt"
    },
    {
      "x": -12,
      "y": 1,
      "z": -4,
      "name": "Rock_Basalt"
    },
    {
      "x": -12,
      "y": 2,
      "z": -4,
      "name": "Rock_Basalt"
    },
    {
      "x": -12,
      "y": 3,
      "z": -4,
      "name": "Rock_Basalt"
    },
    {
      "x": -12,
      "y": 4,
      "z": -4,
      "name": "Rock_Basalt"
    },
    {
      "x": -12,
      "y": 5,
      "z": -4,
      "name": "Rock_Basalt"
    },
    {
      "x": -12,
      "y": 6,
      "z": -4,
      "name": "Rock_Basalt"
    },
    {
      "x": -12,
      "y": 7,
      "z": -4,
      "name": "Rock_Basalt"
    },
    {
      "x": -12,
      "y": 8,
      "z": -4,
      "name": "Rock_Basalt"
    },
    {
      "x": -12,
      "y": 9,
      "z": -4,
      "name": "Soil_Needles"
    },
    {
      "x": -12,
      "y": 0,
      "z": -3,
      "name": "Rock_Basalt"
    },
    {
      "x": -12,
      "y": 1,
      "z": -3,
      "name": "Rock_Basalt"
    },
    {
      "x": -12,
      "y": 2,
      "z": -3,
      "name": "Rock_Basalt"
    },
    {
      "x": -12,
      "y": 3,
      "z": -3,
      "name": "Rock_Basalt"
    },
    {
      "x": -12,
      "y": 4,
      "z": -3,
      "name": "Rock_Basalt"
    },
    {
      "x": -12,
      "y": 5,
      "z": -3,
      "name": "Rock_Basalt"
    },
    {
      "x": -12,
      "y": 6,
      "z": -3,
      "name": "Rock_Basalt"
    },
    {
      "x": -12,
      "y": 7,
      "z": -3,
      "name": "Rock_Basalt"
    },
    {
      "x": -12,
      "y": 8,
      "z": -3,
      "name": "Rock_Basalt"
    },
    {
      "x": -12,
      "y": 9,
      "z": -3,
      "name": "Soil_Needles"
    },
    {
      "x": -12,
      "y": 0,
      "z": -2,
      "name": "Rock_Basalt"
    },
    {
      "x": -12,
      "y": 1,
      "z": -2,
      "name": "Rock_Basalt"
    },
    {
      "x": -12,
      "y": 2,
      "z": -2,
      "name": "Rock_Basalt"
    },
    {
      "x": -12,
      "y": 3,
      "z": -2,
      "name": "Rock_Basalt"
    },
    {
      "x": -12,
      "y": 4,
      "z": -2,
      "name": "Rock_Basalt"
    },
    {
      "x": -12,
      "y": 5,
      "z": -2,
      "name": "Rock_Basalt"
    },
    {
      "x": -12,
      "y": 6,
      "z": -2,
      "name": "Rock_Basalt"
    },
    {
      "x": -12,
      "y": 7,
      "z": -2,
      "name": "Rock_Basalt"
    },
    {
      "x": -12,
      "y": 8,
      "z": -2,
      "name": "Soil_Dirt"
    },
    {
      "x": -12,
      "y": 9,
      "z": -2,
      "name": "Soil_Needles"
    },
    {
      "x": -12,
      "y": 0,
      "z": -1,
      "name": "Rock_Basalt"
    },
    {
      "x": -12,
      "y": 1,
      "z": -1,
      "name": "Rock_Basalt"
    },
    {
      "x": -12,
      "y": 2,
      "z": -1,
      "name": "Wood_Redwood_Trunk",
      "support": 15,
      "rotation": 1
    },
    {
      "x": -12,
      "y": 3,
      "z": -1,
      "name": "Wood_Redwood_Trunk",
      "support": 15,
      "rotation": 1
    },
    {
      "x": -12,
      "y": 4,
      "z": -1,
      "name": "Wood_Redwood_Trunk",
      "support": 15,
      "rotation": 1
    },
    {
      "x": -12,
      "y": 5,
      "z": -1,
      "name": "Wood_Redwood_Trunk",
      "support": 15,
      "rotation": 1
    },
    {
      "x": -12,
      "y": 6,
      "z": -1,
      "name": "Rock_Basalt"
    },
    {
      "x": -12,
      "y": 7,
      "z": -1,
      "name": "Rock_Basalt"
    },
    {
      "x": -12,
      "y": 8,
      "z": -1,
      "name": "Soil_Dirt"
    },
    {
      "x": -12,
      "y": 9,
      "z": -1,
      "name": "Soil_Needles"
    },
    {
      "x": -12,
      "y": 0,
      "z": 0,
      "name": "Rock_Basalt"
    },
    {
      "x": -12,
      "y": 1,
      "z": 0,
      "name": "Rock_Basalt"
    },
    {
      "x": -12,
      "y": 2,
      "z": 0,
      "name": "Rock_Basalt"
    },
    {
      "x": -12,
      "y": 3,
      "z": 0,
      "name": "Rock_Basalt"
    },
    {
      "x": -12,
      "y": 4,
      "z": 0,
      "name": "Wood_Redwood_Trunk",
      "support": 15,
      "rotation": 1
    },
    {
      "x": -12,
      "y": 5,
      "z": 0,
      "name": "Wood_Redwood_Trunk",
      "support": 15,
      "rotation": 1
    },
    {
      "x": -12,
      "y": 6,
      "z": 0,
      "name": "Rock_Basalt"
    },
    {
      "x": -12,
      "y": 7,
      "z": 0,
      "name": "Rock_Basalt"
    },
    {
      "x": -12,
      "y": 8,
      "z": 0,
      "name": "Soil_Dirt"
    },
    {
      "x": -12,
      "y": 9,
      "z": 0,
      "name": "Soil_Grass",
      "rotation": 1
    },
    {
      "x": -12,
      "y": 0,
      "z": 1,
      "name": "Rock_Basalt"
    },
    {
      "x": -12,
      "y": 1,
      "z": 1,
      "name": "Rock_Basalt"
    },
    {
      "x": -12,
      "y": 2,
      "z": 1,
      "name": "Rock_Basalt"
    },
    {
      "x": -12,
      "y": 3,
      "z": 1,
      "name": "Rock_Basalt"
    },
    {
      "x": -12,
      "y": 4,
      "z": 1,
      "name": "Rock_Basalt"
    },
    {
      "x": -12,
      "y": 5,
      "z": 1,
      "name": "Rock_Basalt"
    },
    {
      "x": -12,
      "y": 6,
      "z": 1,
      "name": "Rock_Basalt"
    },
    {
      "x": -12,
      "y": 7,
      "z": 1,
      "name": "Rock_Basalt"
    },
    {
      "x": -12,
      "y": 8,
      "z": 1,
      "name": "Soil_Dirt"
    },
    {
      "x": -12,
      "y": 9,
      "z": 1,
      "name": "Soil_Grass",
      "rotation": 1
    },
    {
      "x": -12,
      "y": 10,
      "z": 1,
      "name": "Plant_Flower_Flax_Blue",
      "rotation": 1
    },
    {
      "x": -12,
      "y": 0,
      "z": 2,
      "name": "Soil_Dirt"
    },
    {
      "x": -12,
      "y": 1,
      "z": 2,
      "name": "Soil_Dirt"
    },
    {
      "x": -12,
      "y": 2,
      "z": 2,
      "name": "Soil_Dirt"
    },
    {
      "x": -12,
      "y": 3,
      "z": 2,
      "name": "Soil_Dirt"
    },
    {
      "x": -12,
      "y": 4,
      "z": 2,
      "name": "Rock_Basalt"
    },
    {
      "x": -12,
      "y": 5,
      "z": 2,
      "name": "Rock_Basalt"
    },
    {
      "x": -12,
      "y": 6,
      "z": 2,
      "name": "Rock_Basalt"
    },
    {
      "x": -12,
      "y": 7,
      "z": 2,
      "name": "Rock_Basalt"
    },
    {
      "x": -12,
      "y": 8,
      "z": 2,
      "name": "Soil_Dirt"
    },
    {
      "x": -12,
      "y": 9,
      "z": 2,
      "name": "Soil_Grass",
      "rotation": 1
    },
    {
      "x": -12,
      "y": 0,
      "z": 3,
      "name": "Soil_Dirt"
    },
    {
      "x": -12,
      "y": 1,
      "z": 3,
      "name": "Soil_Dirt"
    },
    {
      "x": -12,
      "y": 2,
      "z": 3,
      "name": "Soil_Dirt"
    },
    {
      "x": -12,
      "y": 3,
      "z": 3,
      "name": "Soil_Grass"
    },
    {
      "x": -12,
      "y": 4,
      "z": 3,
      "name": "Wood_Hardwood_Fence",
      "rotation": 1
    },
    {
      "x": -12,
      "y": 5,
      "z": 3,
      "name": "K2_Slot_Barrier"
    },
    {
      "x": -12,
      "y": 6,
      "z": 3,
      "name": "K2_Slot_Barrier"
    },
    {
      "x": -12,
      "y": 7,
      "z": 3,
      "name": "K2_Slot_Barrier"
    },
    {
      "x": -12,
      "y": 8,
      "z": 3,
      "name": "Soil_Dirt"
    },
    {
      "x": -12,
      "y": 9,
      "z": 3,
      "name": "Soil_Grass",
      "rotation": 1
    },
    {
      "x": -12,
      "y": 0,
      "z": 4,
      "name": "Soil_Dirt"
    },
    {
      "x": -12,
      "y": 1,
      "z": 4,
      "name": "Soil_Dirt"
    },
    {
      "x": -12,
      "y": 2,
      "z": 4,
      "name": "Soil_Dirt"
    },
    {
      "x": -12,
      "y": 3,
      "z": 4,
      "name": "Soil_Grass"
    },
    {
      "x": -12,
      "y": 4,
      "z": 4,
      "name": "Wood_Hardwood_Fence",
      "rotation": 1
    },
    {
      "x": -12,
      "y": 5,
      "z": 4,
      "name": "K2_Slot_Barrier"
    },
    {
      "x": -12,
      "y": 6,
      "z": 4,
      "name": "K2_Slot_Barrier"
    },
    {
      "x": -12,
      "y": 7,
      "z": 4,
      "name": "K2_Slot_Barrier"
    },
    {
      "x": -12,
      "y": 8,
      "z": 4,
      "name": "K2_Slot_Barrier"
    },
    {
      "x": -12,
      "y": 0,
      "z": 5,
      "name": "Soil_Dirt"
    },
    {
      "x": -12,
      "y": 1,
      "z": 5,
      "name": "Soil_Dirt"
    },
    {
      "x": -12,
      "y": 2,
      "z": 5,
      "name": "Soil_Dirt"
    },
    {
      "x": -12,
      "y": 3,
      "z": 5,
      "name": "Soil_Grass"
    },
    {
      "x": -12,
      "y": 4,
      "z": 5,
      "name": "Wood_Hardwood_Fence",
      "rotation": 1
    },
    {
      "x": -12,
      "y": 5,
      "z": 5,
      "name": "K2_Slot_Barrier"
    },
    {
      "x": -12,
      "y": 6,
      "z": 5,
      "name": "K2_Slot_Barrier"
    },
    {
      "x": -12,
      "y": 7,
      "z": 5,
      "name": "K2_Slot_Barrier"
    },
    {
      "x": -12,
      "y": 8,
      "z": 5,
      "name": "K2_Slot_Barrier"
    },
    {
      "x": -12,
      "y": 0,
      "z": 6,
      "name": "Soil_Dirt"
    },
    {
      "x": -12,
      "y": 1,
      "z": 6,
      "name": "Soil_Dirt"
    },
    {
      "x": -12,
      "y": 2,
      "z": 6,
      "name": "Soil_Dirt"
    },
    {
      "x": -12,
      "y": 3,
      "z": 6,
      "name": "Soil_Grass"
    },
    {
      "x": -12,
      "y": 4,
      "z": 6,
      "name": "Wood_Hardwood_Fence",
      "rotation": 1
    },
    {
      "x": -12,
      "y": 5,
      "z": 6,
      "name": "K2_Slot_Barrier"
    },
    {
      "x": -12,
      "y": 6,
      "z": 6,
      "name": "K2_Slot_Barrier"
    },
    {
      "x": -12,
      "y": 7,
      "z": 6,
      "name": "K2_Slot_Barrier"
    },
    {
      "x": -12,
      "y": 8,
      "z": 6,
      "name": "K2_Slot_Barrier"
    },
    {
      "x": -12,
      "y": 0,
      "z": 7,
      "name": "Soil_Dirt"
    },
    {
      "x": -12,
      "y": 1,
      "z": 7,
      "name": "Soil_Dirt"
    },
    {
      "x": -12,
      "y": 2,
      "z": 7,
      "name": "Soil_Dirt"
    },
    {
      "x": -12,
      "y": 3,
      "z": 7,
      "name": "Soil_Grass"
    },
    {
      "x": -12,
      "y": 4,
      "z": 7,
      "name": "Wood_Hardwood_Fence",
      "rotation": 1
    },
    {
      "x": -12,
      "y": 5,
      "z": 7,
      "name": "K2_Slot_Barrier"
    },
    {
      "x": -12,
      "y": 6,
      "z": 7,
      "name": "K2_Slot_Barrier"
    },
    {
      "x": -12,
      "y": 7,
      "z": 7,
      "name": "K2_Slot_Barrier"
    },
    {
      "x": -12,
      "y": 8,
      "z": 7,
      "name": "K2_Slot_Barrier"
    },
    {
      "x": -12,
      "y": 0,
      "z": 8,
      "name": "Soil_Dirt"
    },
    {
      "x": -12,
      "y": 1,
      "z": 8,
      "name": "Soil_Dirt"
    },
    {
      "x": -12,
      "y": 2,
      "z": 8,
      "name": "Soil_Dirt"
    },
    {
      "x": -12,
      "y": 3,
      "z": 8,
      "name": "Soil_Mud_Dry"
    },
    {
      "x": -12,
      "y": 4,
      "z": 8,
      "name": "Wood_Hardwood_Fence",
      "rotation": 1
    },
    {
      "x": -12,
      "y": 5,
      "z": 8,
      "name": "K2_Slot_Barrier"
    },
    {
      "x": -12,
      "y": 6,
      "z": 8,
      "name": "K2_Slot_Barrier"
    },
    {
      "x": -12,
      "y": 7,
      "z": 8,
      "name": "K2_Slot_Barrier"
    },
    {
      "x": -12,
      "y": 8,
      "z": 8,
      "name": "K2_Slot_Barrier"
    },
    {
      "x": -12,
      "y": 0,
      "z": 9,
      "name": "Soil_Dirt"
    },
    {
      "x": -12,
      "y": 1,
      "z": 9,
      "name": "Soil_Dirt"
    },
    {
      "x": -12,
      "y": 2,
      "z": 9,
      "name": "Soil_Dirt"
    },
    {
      "x": -12,
      "y": 3,
      "z": 9,
      "name": "Soil_Dirt"
    },
    {
      "x": -12,
      "y": 4,
      "z": 9,
      "name": "Wood_Redwood_Trunk",
      "support": 15
    },
    {
      "x": -12,
      "y": 5,
      "z": 9,
      "name": "Wood_Redwood_Trunk",
      "support": 15
    },
    {
      "x": -12,
      "y": 6,
      "z": 9,
      "name": "K2_Slot_Barrier"
    },
    {
      "x": -12,
      "y": 7,
      "z": 9,
      "name": "K2_Slot_Barrier"
    },
    {
      "x": -12,
      "y": 8,
      "z": 9,
      "name": "K2_Slot_Barrier"
    },
    {
      "x": -12,
      "y": 0,
      "z": 10,
      "name": "Soil_Dirt"
    },
    {
      "x": -12,
      "y": 1,
      "z": 10,
      "name": "Soil_Dirt"
    },
    {
      "x": -12,
      "y": 2,
      "z": 10,
      "name": "Soil_Dirt"
    },
    {
      "x": -12,
      "y": 3,
      "z": 10,
      "name": "Soil_Grass"
    },
    {
      "x": -12,
      "y": 0,
      "z": 11,
      "name": "Soil_Dirt"
    },
    {
      "x": -12,
      "y": 1,
      "z": 11,
      "name": "Soil_Dirt"
    },
    {
      "x": -12,
      "y": 2,
      "z": 11,
      "name": "Soil_Dirt"
    },
    {
      "x": -12,
      "y": 3,
      "z": 11,
      "name": "Soil_Mud_Dry"
    },
    {
      "x": -12,
      "y": 0,
      "z": 12,
      "name": "Soil_Dirt"
    },
    {
      "x": -12,
      "y": 1,
      "z": 12,
      "name": "Soil_Dirt"
    },
    {
      "x": -12,
      "y": 2,
      "z": 12,
      "name": "Soil_Dirt"
    },
    {
      "x": -12,
      "y": 3,
      "z": 12,
      "name": "Soil_Mud_Dry"
    },
    {
      "x": -12,
      "y": 0,
      "z": 13,
      "name": "Soil_Pathway"
    },
    {
      "x": -12,
      "y": 1,
      "z": 13,
      "name": "Soil_Pathway"
    },
    {
      "x": -12,
      "y": 2,
      "z": 13,
      "name": "Soil_Dirt"
    },
    {
      "x": -12,
      "y": 3,
      "z": 13,
      "name": "Soil_Pathway"
    },
    {
      "x": -12,
      "y": 0,
      "z": 14,
      "name": "Soil_Dirt"
    },
    {
      "x": -12,
      "y": 1,
      "z": 14,
      "name": "Soil_Dirt"
    },
    {
      "x": -12,
      "y": 2,
      "z": 14,
      "name": "Soil_Pathway"
    },
    {
      "x": -12,
      "y": 3,
      "z": 14,
      "name": "Soil_Pathway"
    },
    {
      "x": -12,
      "y": 11,
      "z": 14,
      "name": "Plant_Leaves_Beech",
      "support": 2
    },
    {
      "x": -12,
      "y": 12,
      "z": 14,
      "name": "Plant_Leaves_Beech",
      "support": 1
    },
    {
      "x": -12,
      "y": 13,
      "z": 14,
      "name": "Plant_Leaves_Beech",
      "support": 2
    },
    {
      "x": -12,
      "y": 0,
      "z": 15,
      "name": "Soil_Pathway"
    },
    {
      "x": -12,
      "y": 1,
      "z": 15,
      "name": "Soil_Pathway"
    },
    {
      "x": -12,
      "y": 2,
      "z": 15,
      "name": "Soil_Dirt"
    },
    {
      "x": -12,
      "y": 3,
      "z": 15,
      "name": "Soil_Dirt"
    },
    {
      "x": -12,
      "y": 9,
      "z": 15,
      "name": "Plant_Leaves_Beech",
      "support": 2
    },
    {
      "x": -12,
      "y": 11,
      "z": 15,
      "name": "Plant_Leaves_Beech",
      "support": 1
    },
    {
      "x": -12,
      "y": 12,
      "z": 15,
      "name": "Plant_Leaves_Beech"
    },
    {
      "x": -12,
      "y": 13,
      "z": 15,
      "name": "Plant_Leaves_Beech",
      "support": 1
    },
    {
      "x": -12,
      "y": 14,
      "z": 15,
      "name": "Plant_Leaves_Beech",
      "support": 1
    },
    {
      "x": -12,
      "y": 15,
      "z": 15,
      "name": "Plant_Leaves_Beech",
      "support": 2
    },
    {
      "x": -12,
      "y": 0,
      "z": 16,
      "name": "Soil_Pathway"
    },
    {
      "x": -12,
      "y": 1,
      "z": 16,
      "name": "Soil_Dirt"
    },
    {
      "x": -12,
      "y": 2,
      "z": 16,
      "name": "Soil_Dirt"
    },
    {
      "x": -12,
      "y": 3,
      "z": 16,
      "name": "Soil_Dirt"
    },
    {
      "x": -12,
      "y": 11,
      "z": 16,
      "name": "Plant_Leaves_Beech",
      "support": 2
    },
    {
      "x": -12,
      "y": 12,
      "z": 16,
      "name": "Plant_Leaves_Beech",
      "support": 1
    },
    {
      "x": -12,
      "y": 14,
      "z": 16,
      "name": "Plant_Leaves_Beech"
    },
    {
      "x": -12,
      "y": 15,
      "z": 16,
      "name": "Plant_Leaves_Beech",
      "support": 1
    },
    {
      "x": -12,
      "y": 16,
      "z": 16,
      "name": "Plant_Leaves_Beech",
      "support": 2
    },
    {
      "x": -11,
      "y": 0,
      "z": -15,
      "name": "Soil_Dirt"
    },
    {
      "x": -11,
      "y": 1,
      "z": -15,
      "name": "Soil_Dirt"
    },
    {
      "x": -11,
      "y": 2,
      "z": -15,
      "name": "Soil_Dirt"
    },
    {
      "x": -11,
      "y": 3,
      "z": -15,
      "name": "Soil_Grass"
    },
    {
      "x": -11,
      "y": 0,
      "z": -14,
      "name": "Soil_Dirt"
    },
    {
      "x": -11,
      "y": 1,
      "z": -14,
      "name": "Soil_Dirt"
    },
    {
      "x": -11,
      "y": 2,
      "z": -14,
      "name": "Soil_Dirt"
    },
    {
      "x": -11,
      "y": 3,
      "z": -14,
      "name": "Soil_Grass"
    },
    {
      "x": -11,
      "y": 0,
      "z": -13,
      "name": "Soil_Dirt"
    },
    {
      "x": -11,
      "y": 1,
      "z": -13,
      "name": "Soil_Dirt"
    },
    {
      "x": -11,
      "y": 2,
      "z": -13,
      "name": "Soil_Dirt"
    },
    {
      "x": -11,
      "y": 3,
      "z": -13,
      "name": "Soil_Grass"
    },
    {
      "x": -11,
      "y": 6,
      "z": -13,
      "name": "Plant_Crop_Mushroom_Block_Yellow",
      "rotation": 1
    },
    {
      "x": -11,
      "y": 7,
      "z": -13,
      "name": "Plant_Moss_Rug_Green",
      "rotation": 1
    },
    {
      "x": -11,
      "y": 0,
      "z": -12,
      "name": "Soil_Dirt"
    },
    {
      "x": -11,
      "y": 1,
      "z": -12,
      "name": "Soil_Dirt"
    },
    {
      "x": -11,
      "y": 2,
      "z": -12,
      "name": "Soil_Dirt"
    },
    {
      "x": -11,
      "y": 3,
      "z": -12,
      "name": "Wood_Redwood_Trunk_Full",
      "rotation": 1
    },
    {
      "x": -11,
      "y": 6,
      "z": -12,
      "name": "Plant_Crop_Mushroom_Block_Yellow",
      "rotation": 1
    },
    {
      "x": -11,
      "y": 7,
      "z": -12,
      "name": "Plant_Moss_Rug_Green",
      "rotation": 1
    },
    {
      "x": -11,
      "y": 0,
      "z": -11,
      "name": "Soil_Dirt"
    },
    {
      "x": -11,
      "y": 1,
      "z": -11,
      "name": "Soil_Dirt"
    },
    {
      "x": -11,
      "y": 2,
      "z": -11,
      "name": "Soil_Dirt"
    },
    {
      "x": -11,
      "y": 3,
      "z": -11,
      "name": "Wood_Redwood_Trunk",
      "support": 15,
      "rotation": 1
    },
    {
      "x": -11,
      "y": 4,
      "z": -11,
      "name": "Wood_Redwood_Trunk",
      "support": 15,
      "rotation": 1
    },
    {
      "x": -11,
      "y": 5,
      "z": -11,
      "name": "Wood_Redwood_Trunk",
      "support": 15,
      "rotation": 1
    },
    {
      "x": -11,
      "y": 6,
      "z": -11,
      "name": "Wood_Redwood_Trunk",
      "support": 15,
      "rotation": 1
    },
    {
      "x": -11,
      "y": 7,
      "z": -11,
      "name": "Rock_Basalt"
    },
    {
      "x": -11,
      "y": 8,
      "z": -11,
      "name": "Soil_Dirt"
    },
    {
      "x": -11,
      "y": 9,
      "z": -11,
      "name": "Soil_Grass",
      "rotation": 1
    },
    {
      "x": -11,
      "y": 10,
      "z": -11,
      "name": "Plant_Grass_Winter",
      "rotation": 1
    },
    {
      "x": -11,
      "y": 0,
      "z": -10,
      "name": "Rock_Basalt"
    },
    {
      "x": -11,
      "y": 1,
      "z": -10,
      "name": "Rock_Basalt"
    },
    {
      "x": -11,
      "y": 2,
      "z": -10,
      "name": "Rock_Basalt"
    },
    {
      "x": -11,
      "y": 3,
      "z": -10,
      "name": "Rock_Basalt"
    },
    {
      "x": -11,
      "y": 4,
      "z": -10,
      "name": "Rock_Basalt"
    },
    {
      "x": -11,
      "y": 5,
      "z": -10,
      "name": "Wood_Redwood_Roots",
      "rotation": 1
    },
    {
      "x": -11,
      "y": 6,
      "z": -10,
      "name": "Wood_Redwood_Trunk",
      "support": 15,
      "rotation": 1
    },
    {
      "x": -11,
      "y": 7,
      "z": -10,
      "name": "Wood_Redwood_Trunk",
      "support": 15,
      "rotation": 1
    },
    {
      "x": -11,
      "y": 8,
      "z": -10,
      "name": "Wood_Redwood_Trunk",
      "support": 15,
      "rotation": 1
    },
    {
      "x": -11,
      "y": 9,
      "z": -10,
      "name": "Soil_Grass",
      "rotation": 1
    },
    {
      "x": -11,
      "y": 10,
      "z": -10,
      "name": "Plant_Grass_Winter_Tall",
      "rotation": 1
    },
    {
      "x": -11,
      "y": 11,
      "z": -10,
      "name": "Plant_Grass_Winter_Tall",
      "filler": 1024,
      "rotation": 1
    },
    {
      "x": -11,
      "y": 0,
      "z": -9,
      "name": "Rock_Basalt"
    },
    {
      "x": -11,
      "y": 1,
      "z": -9,
      "name": "Rock_Basalt"
    },
    {
      "x": -11,
      "y": 2,
      "z": -9,
      "name": "Rock_Basalt"
    },
    {
      "x": -11,
      "y": 3,
      "z": -9,
      "name": "Rock_Basalt"
    },
    {
      "x": -11,
      "y": 7,
      "z": -9,
      "name": "Rock_Basalt"
    },
    {
      "x": -11,
      "y": 8,
      "z": -9,
      "name": "Soil_Dirt"
    },
    {
      "x": -11,
      "y": 9,
      "z": -9,
      "name": "Soil_Grass",
      "rotation": 1
    },
    {
      "x": -11,
      "y": 10,
      "z": -9,
      "name": "Plant_Grass_Winter_Tall",
      "rotation": 1
    },
    {
      "x": -11,
      "y": 11,
      "z": -9,
      "name": "Plant_Grass_Winter_Tall",
      "filler": 1024,
      "rotation": 1
    },
    {
      "x": -11,
      "y": 0,
      "z": -8,
      "name": "Rock_Basalt"
    },
    {
      "x": -11,
      "y": 1,
      "z": -8,
      "name": "Rock_Basalt"
    },
    {
      "x": -11,
      "y": 2,
      "z": -8,
      "name": "Rock_Basalt"
    },
    {
      "x": -11,
      "y": 3,
      "z": -8,
      "name": "Rock_Basalt"
    },
    {
      "x": -11,
      "y": 7,
      "z": -8,
      "name": "Rock_Basalt"
    },
    {
      "x": -11,
      "y": 8,
      "z": -8,
      "name": "Soil_Dirt"
    },
    {
      "x": -11,
      "y": 9,
      "z": -8,
      "name": "Soil_Grass",
      "rotation": 1
    },
    {
      "x": -11,
      "y": 0,
      "z": -7,
      "name": "Rock_Basalt"
    },
    {
      "x": -11,
      "y": 1,
      "z": -7,
      "name": "Rock_Basalt"
    },
    {
      "x": -11,
      "y": 2,
      "z": -7,
      "name": "Rock_Basalt"
    },
    {
      "x": -11,
      "y": 3,
      "z": -7,
      "name": "Rock_Basalt"
    },
    {
      "x": -11,
      "y": 6,
      "z": -7,
      "name": "Rock_Basalt"
    },
    {
      "x": -11,
      "y": 7,
      "z": -7,
      "name": "Rock_Basalt"
    },
    {
      "x": -11,
      "y": 8,
      "z": -7,
      "name": "Soil_Dirt"
    },
    {
      "x": -11,
      "y": 9,
      "z": -7,
      "name": "Soil_Needles"
    },
    {
      "x": -11,
      "y": 10,
      "z": -7,
      "name": "Plant_Crop_Mushroom_Common_Brown",
      "components": {
        "Components": {
          "FarmingBlock": {
            "LastTickGameTime": "0001-01-01T12:00:00Z"
          }
        }
      },
      "rotation": 1
    },
    {
      "x": -11,
      "y": 24,
      "z": -7,
      "name": "Plant_Leaves_Redwood",
      "support": 2,
      "rotation": 1
    },
    {
      "x": -11,
      "y": 28,
      "z": -7,
      "name": "Plant_Leaves_Redwood",
      "support": 1,
      "rotation": 1
    },
    {
      "x": -11,
      "y": 36,
      "z": -7,
      "name": "Plant_Leaves_Redwood",
      "rotation": 1
    },
    {
      "x": -11,
      "y": 0,
      "z": -6,
      "name": "Rock_Basalt"
    },
    {
      "x": -11,
      "y": 1,
      "z": -6,
      "name": "Rock_Basalt"
    },
    {
      "x": -11,
      "y": 2,
      "z": -6,
      "name": "Rock_Basalt"
    },
    {
      "x": -11,
      "y": 3,
      "z": -6,
      "name": "Wood_Redwood_Trunk_Full",
      "rotation": 5
    },
    {
      "x": -11,
      "y": 5,
      "z": -6,
      "name": "Wood_Redwood_Trunk_Full",
      "support": 1,
      "rotation": 1
    },
    {
      "x": -11,
      "y": 6,
      "z": -6,
      "name": "Rock_Basalt"
    },
    {
      "x": -11,
      "y": 7,
      "z": -6,
      "name": "Rock_Basalt"
    },
    {
      "x": -11,
      "y": 8,
      "z": -6,
      "name": "Soil_Dirt"
    },
    {
      "x": -11,
      "y": 9,
      "z": -6,
      "name": "Soil_Needles"
    },
    {
      "x": -11,
      "y": 10,
      "z": -6,
      "name": "Plant_Crop_Mushroom_Common_Brown",
      "components": {
        "Components": {
          "FarmingBlock": {
            "LastTickGameTime": "0001-01-01T12:00:00Z"
          }
        }
      },
      "rotation": 1
    },
    {
      "x": -11,
      "y": 24,
      "z": -6,
      "name": "Plant_Leaves_Redwood",
      "support": 1,
      "rotation": 1
    },
    {
      "x": -11,
      "y": 28,
      "z": -6,
      "name": "Plant_Leaves_Redwood",
      "rotation": 1
    },
    {
      "x": -11,
      "y": 36,
      "z": -6,
      "name": "Plant_Leaves_Redwood",
      "rotation": 1
    },
    {
      "x": -11,
      "y": 43,
      "z": -6,
      "name": "Plant_Leaves_Redwood",
      "rotation": 1
    },
    {
      "x": -11,
      "y": 0,
      "z": -5,
      "name": "Rock_Basalt"
    },
    {
      "x": -11,
      "y": 1,
      "z": -5,
      "name": "Rock_Basalt"
    },
    {
      "x": -11,
      "y": 2,
      "z": -5,
      "name": "Rock_Basalt"
    },
    {
      "x": -11,
      "y": 4,
      "z": -5,
      "name": "Wood_Redwood_Trunk",
      "support": 15,
      "rotation": 5
    },
    {
      "x": -11,
      "y": 5,
      "z": -5,
      "name": "Wood_Redwood_Trunk_Full",
      "rotation": 1
    },
    {
      "x": -11,
      "y": 6,
      "z": -5,
      "name": "Wood_Redwood_Trunk",
      "support": 15,
      "rotation": 1
    },
    {
      "x": -11,
      "y": 7,
      "z": -5,
      "name": "Rock_Basalt"
    },
    {
      "x": -11,
      "y": 8,
      "z": -5,
      "name": "Soil_Dirt"
    },
    {
      "x": -11,
      "y": 9,
      "z": -5,
      "name": "Soil_Needles"
    },
    {
      "x": -11,
      "y": 24,
      "z": -5,
      "name": "Plant_Leaves_Redwood",
      "support": 2,
      "rotation": 1
    },
    {
      "x": -11,
      "y": 28,
      "z": -5,
      "name": "Plant_Leaves_Redwood",
      "support": 1,
      "rotation": 1
    },
    {
      "x": -11,
      "y": 43,
      "z": -5,
      "name": "Plant_Leaves_Redwood",
      "rotation": 1
    },
    {
      "x": -11,
      "y": 0,
      "z": -4,
      "name": "Rock_Basalt"
    },
    {
      "x": -11,
      "y": 1,
      "z": -4,
      "name": "Rock_Basalt"
    },
    {
      "x": -11,
      "y": 2,
      "z": -4,
      "name": "Rock_Basalt"
    },
    {
      "x": -11,
      "y": 3,
      "z": -4,
      "name": "Rock_Basalt"
    },
    {
      "x": -11,
      "y": 4,
      "z": -4,
      "name": "Wood_Redwood_Roots",
      "rotation": 1
    },
    {
      "x": -11,
      "y": 5,
      "z": -4,
      "name": "Wood_Redwood_Trunk",
      "support": 15,
      "rotation": 1
    },
    {
      "x": -11,
      "y": 6,
      "z": -4,
      "name": "Wood_Redwood_Trunk",
      "support": 15,
      "rotation": 1
    },
    {
      "x": -11,
      "y": 7,
      "z": -4,
      "name": "Rock_Basalt"
    },
    {
      "x": -11,
      "y": 8,
      "z": -4,
      "name": "Soil_Dirt"
    },
    {
      "x": -11,
      "y": 9,
      "z": -4,
      "name": "Soil_Needles"
    },
    {
      "x": -11,
      "y": 0,
      "z": -3,
      "name": "Rock_Basalt"
    },
    {
      "x": -11,
      "y": 1,
      "z": -3,
      "name": "Rock_Basalt"
    },
    {
      "x": -11,
      "y": 2,
      "z": -3,
      "name": "Rock_Basalt"
    },
    {
      "x": -11,
      "y": 3,
      "z": -3,
      "name": "Rock_Basalt"
    },
    {
      "x": -11,
      "y": 4,
      "z": -3,
      "name": "Rock_Basalt"
    },
    {
      "x": -11,
      "y": 5,
      "z": -3,
      "name": "Rock_Basalt"
    },
    {
      "x": -11,
      "y": 6,
      "z": -3,
      "name": "Rock_Basalt"
    },
    {
      "x": -11,
      "y": 7,
      "z": -3,
      "name": "Rock_Basalt"
    },
    {
      "x": -11,
      "y": 8,
      "z": -3,
      "name": "Soil_Dirt"
    },
    {
      "x": -11,
      "y": 9,
      "z": -3,
      "name": "Soil_Needles"
    },
    {
      "x": -11,
      "y": 0,
      "z": -2,
      "name": "Rock_Basalt"
    },
    {
      "x": -11,
      "y": 1,
      "z": -2,
      "name": "Rock_Basalt"
    },
    {
      "x": -11,
      "y": 2,
      "z": -2,
      "name": "Rock_Basalt"
    },
    {
      "x": -11,
      "y": 3,
      "z": -2,
      "name": "Rock_Basalt"
    },
    {
      "x": -11,
      "y": 4,
      "z": -2,
      "name": "Rock_Basalt"
    },
    {
      "x": -11,
      "y": 5,
      "z": -2,
      "name": "Rock_Basalt"
    },
    {
      "x": -11,
      "y": 6,
      "z": -2,
      "name": "Wood_Redwood_Trunk",
      "support": 15,
      "rotation": 1
    },
    {
      "x": -11,
      "y": 7,
      "z": -2,
      "name": "Wood_Redwood_Trunk",
      "support": 15,
      "rotation": 1
    },
    {
      "x": -11,
      "y": 8,
      "z": -2,
      "name": "Wood_Redwood_Trunk",
      "support": 15,
      "rotation": 1
    },
    {
      "x": -11,
      "y": 9,
      "z": -2,
      "name": "Soil_Needles"
    },
    {
      "x": -11,
      "y": 34,
      "z": -2,
      "name": "Plant_Leaves_Redwood",
      "rotation": 1
    },
    {
      "x": -11,
      "y": 0,
      "z": -1,
      "name": "Rock_Basalt"
    },
    {
      "x": -11,
      "y": 1,
      "z": -1,
      "name": "Rock_Basalt"
    },
    {
      "x": -11,
      "y": 2,
      "z": -1,
      "name": "Rock_Basalt"
    },
    {
      "x": -11,
      "y": 3,
      "z": -1,
      "name": "Rock_Basalt"
    },
    {
      "x": -11,
      "y": 4,
      "z": -1,
      "name": "Wood_Redwood_Trunk",
      "support": 15,
      "rotation": 1
    },
    {
      "x": -11,
      "y": 5,
      "z": -1,
      "name": "Wood_Redwood_Trunk",
      "support": 15,
      "rotation": 1
    },
    {
      "x": -11,
      "y": 6,
      "z": -1,
      "name": "Wood_Redwood_Trunk",
      "support": 15,
      "rotation": 1
    },
    {
      "x": -11,
      "y": 7,
      "z": -1,
      "name": "Wood_Redwood_Trunk",
      "support": 15,
      "rotation": 1
    },
    {
      "x": -11,
      "y": 8,
      "z": -1,
      "name": "Wood_Redwood_Trunk",
      "support": 15,
      "rotation": 1
    },
    {
      "x": -11,
      "y": 9,
      "z": -1,
      "name": "Soil_Needles"
    },
    {
      "x": -11,
      "y": 34,
      "z": -1,
      "name": "Plant_Leaves_Redwood",
      "rotation": 1
    },
    {
      "x": -11,
      "y": 0,
      "z": 0,
      "name": "Rock_Basalt"
    },
    {
      "x": -11,
      "y": 1,
      "z": 0,
      "name": "Rock_Basalt"
    },
    {
      "x": -11,
      "y": 2,
      "z": 0,
      "name": "Rock_Basalt"
    },
    {
      "x": -11,
      "y": 3,
      "z": 0,
      "name": "Wood_Redwood_Trunk",
      "support": 15,
      "rotation": 1
    },
    {
      "x": -11,
      "y": 4,
      "z": 0,
      "name": "Wood_Redwood_Trunk",
      "support": 15,
      "rotation": 1
    },
    {
      "x": -11,
      "y": 5,
      "z": 0,
      "name": "Wood_Redwood_Trunk",
      "support": 15,
      "rotation": 1
    },
    {
      "x": -11,
      "y": 6,
      "z": 0,
      "name": "Rock_Basalt"
    },
    {
      "x": -11,
      "y": 7,
      "z": 0,
      "name": "Rock_Basalt"
    },
    {
      "x": -11,
      "y": 8,
      "z": 0,
      "name": "Soil_Dirt"
    },
    {
      "x": -11,
      "y": 9,
      "z": 0,
      "name": "Soil_Grass",
      "rotation": 1
    },
    {
      "x": -11,
      "y": 0,
      "z": 1,
      "name": "Rock_Basalt"
    },
    {
      "x": -11,
      "y": 1,
      "z": 1,
      "name": "Rock_Basalt"
    },
    {
      "x": -11,
      "y": 2,
      "z": 1,
      "name": "Rock_Basalt"
    },
    {
      "x": -11,
      "y": 3,
      "z": 1,
      "name": "Rock_Basalt"
    },
    {
      "x": -11,
      "y": 4,
      "z": 1,
      "name": "Rock_Basalt"
    },
    {
      "x": -11,
      "y": 5,
      "z": 1,
      "name": "Rock_Basalt"
    },
    {
      "x": -11,
      "y": 6,
      "z": 1,
      "name": "Rock_Basalt"
    },
    {
      "x": -11,
      "y": 7,
      "z": 1,
      "name": "Rock_Basalt"
    },
    {
      "x": -11,
      "y": 8,
      "z": 1,
      "name": "Soil_Dirt"
    },
    {
      "x": -11,
      "y": 9,
      "z": 1,
      "name": "Soil_Grass",
      "rotation": 1
    },
    {
      "x": -11,
      "y": 10,
      "z": 1,
      "name": "Plant_Flower_Flax_Blue",
      "rotation": 1
    },
    {
      "x": -11,
      "y": 0,
      "z": 2,
      "name": "Rock_Basalt"
    },
    {
      "x": -11,
      "y": 1,
      "z": 2,
      "name": "Rock_Basalt"
    },
    {
      "x": -11,
      "y": 2,
      "z": 2,
      "name": "Rock_Basalt"
    },
    {
      "x": -11,
      "y": 3,
      "z": 2,
      "name": "Rock_Basalt"
    },
    {
      "x": -11,
      "y": 4,
      "z": 2,
      "name": "Rock_Basalt"
    },
    {
      "x": -11,
      "y": 5,
      "z": 2,
      "name": "Rock_Basalt"
    },
    {
      "x": -11,
      "y": 6,
      "z": 2,
      "name": "Rock_Basalt"
    },
    {
      "x": -11,
      "y": 7,
      "z": 2,
      "name": "Rock_Basalt"
    },
    {
      "x": -11,
      "y": 8,
      "z": 2,
      "name": "Soil_Dirt"
    },
    {
      "x": -11,
      "y": 9,
      "z": 2,
      "name": "Soil_Grass",
      "rotation": 1
    },
    {
      "x": -11,
      "y": 0,
      "z": 3,
      "name": "Soil_Dirt"
    },
    {
      "x": -11,
      "y": 1,
      "z": 3,
      "name": "Soil_Dirt"
    },
    {
      "x": -11,
      "y": 2,
      "z": 3,
      "name": "Soil_Dirt"
    },
    {
      "x": -11,
      "y": 3,
      "z": 3,
      "name": "Soil_Grass"
    },
    {
      "x": -11,
      "y": 6,
      "z": 3,
      "name": "Rock_Basalt"
    },
    {
      "x": -11,
      "y": 7,
      "z": 3,
      "name": "Rock_Basalt"
    },
    {
      "x": -11,
      "y": 8,
      "z": 3,
      "name": "Soil_Dirt"
    },
    {
      "x": -11,
      "y": 9,
      "z": 3,
      "name": "Soil_Grass",
      "rotation": 1
    },
    {
      "x": -11,
      "y": 0,
      "z": 4,
      "name": "Soil_Dirt"
    },
    {
      "x": -11,
      "y": 1,
      "z": 4,
      "name": "Soil_Dirt"
    },
    {
      "x": -11,
      "y": 2,
      "z": 4,
      "name": "Soil_Dirt"
    },
    {
      "x": -11,
      "y": 3,
      "z": 4,
      "name": "Soil_Grass"
    },
    {
      "x": -11,
      "y": 8,
      "z": 4,
      "name": "K2_Slot_Barrier"
    },
    {
      "x": -11,
      "y": 0,
      "z": 5,
      "name": "Soil_Dirt"
    },
    {
      "x": -11,
      "y": 1,
      "z": 5,
      "name": "Soil_Dirt"
    },
    {
      "x": -11,
      "y": 2,
      "z": 5,
      "name": "Soil_Dirt"
    },
    {
      "x": -11,
      "y": 3,
      "z": 5,
      "name": "Soil_Grass"
    },
    {
      "x": -11,
      "y": 8,
      "z": 5,
      "name": "K2_Slot_Barrier"
    },
    {
      "x": -11,
      "y": 0,
      "z": 6,
      "name": "Soil_Dirt"
    },
    {
      "x": -11,
      "y": 1,
      "z": 6,
      "name": "Soil_Dirt"
    },
    {
      "x": -11,
      "y": 2,
      "z": 6,
      "name": "Soil_Dirt"
    },
    {
      "x": -11,
      "y": 3,
      "z": 6,
      "name": "Soil_Grass"
    },
    {
      "x": -11,
      "y": 8,
      "z": 6,
      "name": "K2_Slot_Barrier"
    },
    {
      "x": -11,
      "y": 0,
      "z": 7,
      "name": "Soil_Dirt"
    },
    {
      "x": -11,
      "y": 1,
      "z": 7,
      "name": "Soil_Dirt"
    },
    {
      "x": -11,
      "y": 2,
      "z": 7,
      "name": "Soil_Dirt"
    },
    {
      "x": -11,
      "y": 3,
      "z": 7,
      "name": "Soil_Grass"
    },
    {
      "x": -11,
      "y": 8,
      "z": 7,
      "name": "K2_Slot_Barrier"
    },
    {
      "x": -11,
      "y": 0,
      "z": 8,
      "name": "Soil_Dirt"
    },
    {
      "x": -11,
      "y": 1,
      "z": 8,
      "name": "Soil_Dirt"
    },
    {
      "x": -11,
      "y": 2,
      "z": 8,
      "name": "Soil_Dirt"
    },
    {
      "x": -11,
      "y": 3,
      "z": 8,
      "name": "Soil_Grass"
    },
    {
      "x": -11,
      "y": 8,
      "z": 8,
      "name": "K2_Slot_Barrier"
    },
    {
      "x": -11,
      "y": 0,
      "z": 9,
      "name": "Soil_Dirt"
    },
    {
      "x": -11,
      "y": 1,
      "z": 9,
      "name": "Soil_Dirt"
    },
    {
      "x": -11,
      "y": 2,
      "z": 9,
      "name": "Soil_Dirt"
    },
    {
      "x": -11,
      "y": 3,
      "z": 9,
      "name": "Soil_Grass"
    },
    {
      "x": -11,
      "y": 4,
      "z": 9,
      "name": "Wood_Hardwood_Fence",
      "rotation": 2
    },
    {
      "x": -11,
      "y": 6,
      "z": 9,
      "name": "K2_Slot_Barrier"
    },
    {
      "x": -11,
      "y": 7,
      "z": 9,
      "name": "K2_Slot_Barrier"
    },
    {
      "x": -11,
      "y": 8,
      "z": 9,
      "name": "K2_Slot_Barrier"
    },
    {
      "x": -11,
      "y": 0,
      "z": 10,
      "name": "Soil_Dirt"
    },
    {
      "x": -11,
      "y": 1,
      "z": 10,
      "name": "Soil_Dirt"
    },
    {
      "x": -11,
      "y": 2,
      "z": 10,
      "name": "Soil_Dirt"
    },
    {
      "x": -11,
      "y": 3,
      "z": 10,
      "name": "Soil_Mud_Dry"
    },
    {
      "x": -11,
      "y": 0,
      "z": 11,
      "name": "Soil_Dirt"
    },
    {
      "x": -11,
      "y": 1,
      "z": 11,
      "name": "Soil_Dirt"
    },
    {
      "x": -11,
      "y": 2,
      "z": 11,
      "name": "Soil_Dirt"
    },
    {
      "x": -11,
      "y": 3,
      "z": 11,
      "name": "Soil_Mud_Dry"
    },
    {
      "x": -11,
      "y": 0,
      "z": 12,
      "name": "Soil_Dirt"
    },
    {
      "x": -11,
      "y": 1,
      "z": 12,
      "name": "Soil_Dirt"
    },
    {
      "x": -11,
      "y": 2,
      "z": 12,
