{"version": 8, "blockIdVersion": 11, "anchorX": 0, "anchorY": 0, "anchorZ": 0, "blocks": [{"x": 0, "y": -3, "z": 0, "name": "Soil_Dirt"}, {"x": 0, "y": -2, "z": 0, "name": "Soil_Dirt"}, {"x": 0, "y": -1, "z": 0, "name": "Soil_Dirt"}, {"x": 0, "y": 0, "z": 0, "name": "Soil_Grass"}, {"x": 0, "y": 1, "z": 0, "name": "K2_Slot_Size_Small"}, {"x": 0, "y": -3, "z": 1, "name": "Soil_Dirt"}, {"x": 0, "y": -2, "z": 1, "name": "Soil_Dirt"}, {"x": 0, "y": -1, "z": 1, "name": "Soil_Dirt"}, {"x": 0, "y": 0, "z": 1, "name": "Rock_Ledge_Brick"}, {"x": 0, "y": -3, "z": 2, "name": "Soil_Dirt"}, {"x": 0, "y": -2, "z": 2, "name": "Soil_Dirt"}, {"x": 0, "y": -1, "z": 2, "name": "Soil_Dirt"}, {"x": 0, "y": 0, "z": 2, "name": "Rock_Ledge_Cobble"}, {"x": 0, "y": -3, "z": 3, "name": "Soil_Dirt"}, {"x": 0, "y": -2, "z": 3, "name": "Soil_Dirt"}, {"x": 0, "y": -1, "z": 3, "name": "Soil_Dirt"}, {"x": 0, "y": 0, "z": 3, "name": "Rock_Ledge_Cobble"}, {"x": 0, "y": -3, "z": 4, "name": "Soil_Dirt"}, {"x": 0, "y": -2, "z": 4, "name": "Soil_Dirt"}, {"x": 0, "y": -1, "z": 4, "name": "Soil_Dirt"}, {"x": 0, "y": 0, "z": 4, "name": "Rock_Ledge_Brick_Ornate"}, {"x": 0, "y": 1, "z": 4, "name": "Rock_Quartzite_Cobble_Wall", "rotation": 1}, {"x": 0, "y": 2, "z": 4, "name": "Rock_Quartzite_Cobble_Wall", "rotation": 1}, {"x": 0, "y": 3, "z": 4, "name": "Cloth_Modern_Blue_Roof", "rotation": 2}, {"x": 0, "y": -3, "z": 5, "name": "Soil_Dirt"}, {"x": 0, "y": -2, "z": 5, "name": "Soil_Dirt"}, {"x": 0, "y": -1, "z": 5, "name": "Soil_Dirt"}, {"x": 0, "y": 0, "z": 5, "name": "Rock_Ledge_Brick_Decorative"}, {"x": 0, "y": 1, "z": 5, "name": "*Rock_Quartzite_Cobble_Wall_State_Definitions_Corner", "rotation": 2}, {"x": 0, "y": 2, "z": 5, "name": "*Rock_Quartzite_Cobble_Wall_State_Definitions_Corner", "rotation": 2}, {"x": 0, "y": 3, "z": 5, "name": "Cloth_Modern_Blue_Roof"}, {"x": 0, "y": -3, "z": 6, "name": "Soil_Dirt"}, {"x": 0, "y": -2, "z": 6, "name": "Soil_Dirt"}, {"x": 0, "y": -1, "z": 6, "name": "Soil_Dirt"}, {"x": 0, "y": 0, "z": 6, "name": "Rock_Ledge_Brick_Smooth"}, {"x": 0, "y": -3, "z": 7, "name": "Soil_Dirt"}, {"x": 0, "y": -2, "z": 7, "name": "Soil_Dirt"}, {"x": 0, "y": -1, "z": 7, "name": "Soil_Dirt"}, {"x": 0, "y": 0, "z": 7, "name": "Rock_Ledge_Brick"}, {"x": 0, "y": -3, "z": 8, "name": "Soil_Dirt"}, {"x": 0, "y": -2, "z": 8, "name": "Soil_Dirt"}, {"x": 0, "y": -1, "z": 8, "name": "Soil_Dirt"}, {"x": 0, "y": 0, "z": 8, "name": "Rock_Ledge_Brick_Smooth"}, {"x": 0, "y": -3, "z": 9, "name": "Soil_Dirt"}, {"x": 0, "y": -2, "z": 9, "name": "Soil_Dirt"}, {"x": 0, "y": -1, "z": 9, "name": "Soil_Dirt"}, {"x": 0, "y": 0, "z": 9, "name": "Rock_Ledge_Brick_Smooth"}, {"x": 0, "y": -3, "z": 10, "name": "Soil_Dirt"}, {"x": 0, "y": -2, "z": 10, "name": "Soil_Dirt"}, {"x": 0, "y": -1, "z": 10, "name": "Soil_Dirt"}, {"x": 0, "y": 0, "z": 10, "name": "Rock_Ledge_Brick"}, {"x": 0, "y": -3, "z": 11, "name": "Soil_Dirt"}, {"x": 0, "y": -2, "z": 11, "name": "Soil_Dirt"}, {"x": 0, "y": -1, "z": 11, "name": "Soil_Dirt"}, {"x": 0, "y": 0, "z": 11, "name": "Rock_Ledge_Brick"}, {"x": 0, "y": -3, "z": 12, "name": "Soil_Dirt"}, {"x": 0, "y": -2, "z": 12, "name": "Soil_Dirt"}, {"x": 0, "y": -1, "z": 12, "name": "Soil_Dirt"}, {"x": 0, "y": 0, "z": 12, "name": "Rock_Ledge_Brick_Smooth"}, {"x": 0, "y": -3, "z": 13, "name": "Soil_Dirt"}, {"x": 0, "y": -2, "z": 13, "name": "Soil_Dirt"}, {"x": 0, "y": -1, "z": 13, "name": "Soil_Dirt"}, {"x": 0, "y": 0, "z": 13, "name": "Rock_Ledge_Brick_Ornate"}, {"x": 0, "y": -3, "z": 14, "name": "Soil_Dirt"}, {"x": 0, "y": -2, "z": 14, "name": "Soil_Dirt"}, {"x": 0, "y": -1, "z": 14, "name": "Soil_Dirt"}, {"x": 0, "y": 0, "z": 14, "name": "Rock_Ledge_Brick_Ornate"}, {"x": 0, "y": -3, "z": 15, "name": "Soil_Dirt"}, {"x": 0, "y": -2, "z": 15, "name": "Soil_Dirt"}, {"x": 0, "y": -1, "z": 15, "name": "Soil_Dirt"}, {"x": 0, "y": 0, "z": 15, "name": "Rock_Ledge_Brick_Smooth"}, {"x": 0, "y": -3, "z": 16, "name": "Soil_Dirt"}, {"x": 0, "y": -2, "z": 16, "name": "Soil_Dirt"}, {"x": 0, "y": -1, "z": 16, "name": "Soil_Dirt"}, {"x": 0, "y": 0, "z": 16, "name": "Rock_Ledge_Brick_Decorative"}, {"x": 0, "y": -3, "z": 17, "name": "Soil_Dirt"}, {"x": 0, "y": -2, "z": 17, "name": "Soil_Dirt"}, {"x": 0, "y": -1, "z": 17, "name": "Soil_Dirt"}, {"x": 0, "y": 0, "z": 17, "name": "Rock_Ledge_Cobble"}, {"x": 0, "y": -3, "z": 18, "name": "Soil_Dirt"}, {"x": 0, "y": -2, "z": 18, "name": "Soil_Dirt"}, {"x": 0, "y": -1, "z": 18, "name": "Soil_Dirt"}, {"x": 0, "y": 0, "z": 18, "name": "Rock_Ledge_Brick_Decorative"}, {"x": 0, "y": -3, "z": 19, "name": "Soil_Dirt"}, {"x": 0, "y": -2, "z": 19, "name": "Soil_Dirt"}, {"x": 0, "y": -1, "z": 19, "name": "Soil_Dirt"}, {"x": 0, "y": 0, "z": 19, "name": "Rock_Ledge_Cobble"}, {"x": 0, "y": -3, "z": 20, "name": "Soil_Dirt"}, {"x": 0, "y": -2, "z": 20, "name": "Soil_Dirt"}, {"x": 0, "y": -1, "z": 20, "name": "Soil_Dirt"}, {"x": 0, "y": 0, "z": 20, "name": "Rock_Ledge_Brick"}, {"x": 0, "y": -3, "z": 21, "name": "Soil_Dirt"}, {"x": 0, "y": -2, "z": 21, "name": "Soil_Dirt"}, {"x": 0, "y": -1, "z": 21, "name": "Soil_Dirt"}, {"x": 0, "y": 0, "z": 21, "name": "Rock_Ledge_Brick_Ornate"}, {"x": 0, "y": -3, "z": 22, "name": "Soil_Dirt"}, {"x": 0, "y": -2, "z": 22, "name": "Soil_Dirt"}, {"x": 0, "y": -1, "z": 22, "name": "Soil_Dirt"}, {"x": 0, "y": 0, "z": 22, "name": "Rock_Ledge_Brick_Smooth"}, {"x": 0, "y": -3, "z": 23, "name": "Soil_Dirt"}, {"x": 0, "y": -2, "z": 23, "name": "Soil_Dirt"}, {"x": 0, "y": -1, "z": 23, "name": "Soil_Dirt"}, {"x": 0, "y": 0, "z": 23, "name": "Rock_Ledge_Brick_Smooth"}, {"x": 0, "y": -3, "z": 24, "name": "Soil_Dirt"}, {"x": 0, "y": -2, "z": 24, "name": "Soil_Dirt"}, {"x": 0, "y": -1, "z": 24, "name": "Soil_Dirt"}, {"x": 0, "y": 0, "z": 24, "name": "Rock_Ledge_Brick_Decorative"}, {"x": 0, "y": -3, "z": 25, "name": "Soil_Dirt"}, {"x": 0, "y": -2, "z": 25, "name": "Soil_Dirt"}, {"x": 0, "y": -1, "z": 25, "name": "Soil_Dirt"}, {"x": 0, "y": 0, "z": 25, "name": "Rock_Ledge_Brick_Smooth"}, {"x": 0, "y": -3, "z": 26, "name": "Soil_Dirt"}, {"x": 0, "y": -2, "z": 26, "name": "Soil_Dirt"}, {"x": 0, "y": -1, "z": 26, "name": "Soil_Dirt"}, {"x": 0, "y": 0, "z": 26, "name": "Rock_Ledge_Brick"}, {"x": 0, "y": -3, "z": 27, "name": "Soil_Dirt"}, {"x": 0, "y": -2, "z": 27, "name": "Soil_Dirt"}, {"x": 0, "y": -1, "z": 27, "name": "Soil_Dirt"}, {"x": 0, "y": 0, "z": 27, "name": "Rock_Ledge_Cobble"}, {"x": 0, "y": -3, "z": 28, "name": "Soil_Dirt"}, {"x": 0, "y": -2, "z": 28, "name": "Soil_Dirt"}, {"x": 0, "y": -1, "z": 28, "name": "Soil_Dirt"}, {"x": 0, "y": 0, "z": 28, "name": "Rock_Ledge_Brick_Ornate"}, {"x": 0, "y": -3, "z": 29, "name": "Soil_Dirt"}, {"x": 0, "y": -2, "z": 29, "name": "Soil_Dirt"}, {"x": 0, "y": -1, "z": 29, "name": "Soil_Dirt"}, {"x": 0, "y": 0, "z": 29, "name": "Rock_Ledge_Brick_Smooth"}, {"x": 0, "y": -3, "z": 30, "name": "Soil_Dirt"}, {"x": 0, "y": -2, "z": 30, "name": "Soil_Dirt"}, {"x": 0, "y": -1, "z": 30, "name": "Soil_Dirt"}, {"x": 0, "y": 0, "z": 30, "name": "Rock_Ledge_Brick_Smooth"}, {"x": 0, "y": -3, "z": 31, "name": "Soil_Dirt"}, {"x": 0, "y": -2, "z": 31, "name": "Soil_Dirt"}, {"x": 0, "y": -1, "z": 31, "name": "Soil_Dirt"}, {"x": 0, "y": 0, "z": 31, "name": "Rock_Ledge_Brick_Smooth"}, {"x": 1, "y": -3, "z": 0, "name": "Soil_Dirt"}, {"x": 1, "y": -2, "z": 0, "name": "Soil_Dirt"}, {"x": 1, "y": -1, "z": 0, "name": "Soil_Dirt"}, {"x": 1, "y": 0, "z": 0, "name": "Rock_Ledge_Brick"}, {"x": 1, "y": -3, "z": 1, "name": "Soil_Dirt"}, {"x": 1, "y": -2, "z": 1, "name": "Soil_Dirt"}, {"x": 1, "y": -1, "z": 1, "name": "Soil_Dirt"}, {"x": 1, "y": 0, "z": 1, "name": "Rock_Ledge_Cobble"}, {"x": 1, "y": -3, "z": 2, "name": "Soil_Dirt"}, {"x": 1, "y": -2, "z": 2, "name": "Soil_Dirt"}, {"x": 1, "y": -1, "z": 2, "name": "Soil_Dirt"}, {"x": 1, "y": 0, "z": 2, "name": "Rock_Ledge_Brick_Smooth"}, {"x": 1, "y": -3, "z": 3, "name": "Soil_Dirt"}, {"x": 1, "y": -2, "z": 3, "name": "Soil_Dirt"}, {"x": 1, "y": -1, "z": 3, "name": "Soil_Dirt"}, {"x": 1, "y": 0, "z": 3, "name": "Rock_Ledge_Brick"}, {"x": 1, "y": -3, "z": 4, "name": "Soil_Dirt"}, {"x": 1, "y": -2, "z": 4, "name": "Soil_Dirt"}, {"x": 1, "y": -1, "z": 4, "name": "Soil_Dirt"}, {"x": 1, "y": 0, "z": 4, "name": "Rock_Ledge_Cobble"}, {"x": 1, "y": 1, "z": 4, "name": "Metal_Iron_Pipe_Long", "support": 15, "rotation": 1}, {"x": 1, "y": 2, "z": 4, "name": "Metal_Iron_Pipe_Long", "support": 15, "rotation": 1}, {"x": 1, "y": 3, "z": 4, "name": "Cloth_Modern_Blue_Roof", "rotation": 2}, {"x": 1, "y": -3, "z": 5, "name": "Soil_Dirt"}, {"x": 1, "y": -2, "z": 5, "name": "Soil_Dirt"}, {"x": 1, "y": -1, "z": 5, "name": "Soil_Dirt"}, {"x": 1, "y": 0, "z": 5, "name": "Rock_Ledge_Brick_Smooth"}, {"x": 1, "y": 1, "z": 5, "name": "Rock_Quartzite_Cobble_Wall", "rotation": 2}, {"x": 1, "y": 2, "z": 5, "name": "Rock_Quartzite_Cobble_Wall", "rotation": 2}, {"x": 1, "y": 3, "z": 5, "name": "Cloth_Modern_Blue_Roof"}, {"x": 1, "y": -3, "z": 6, "name": "Soil_Dirt"}, {"x": 1, "y": -2, "z": 6, "name": "Soil_Dirt"}, {"x": 1, "y": -1, "z": 6, "name": "Soil_Dirt"}, {"x": 1, "y": 0, "z": 6, "name": "Rock_Ledge_Cobble"}, {"x": 1, "y": -3, "z": 7, "name": "Soil_Dirt"}, {"x": 1, "y": -2, "z": 7, "name": "Soil_Dirt"}, {"x": 1, "y": -1, "z": 7, "name": "Soil_Dirt"}, {"x": 1, "y": 0, "z": 7, "name": "Rock_Ledge_Brick_Ornate"}, {"x": 1, "y": -3, "z": 8, "name": "Soil_Dirt"}, {"x": 1, "y": -2, "z": 8, "name": "Soil_Dirt"}, {"x": 1, "y": -1, "z": 8, "name": "Soil_Dirt"}, {"x": 1, "y": 0, "z": 8, "name": "Rock_Ledge_Brick_Ornate"}, {"x": 1, "y": -3, "z": 9, "name": "Soil_Dirt"}, {"x": 1, "y": -2, "z": 9, "name": "Soil_Dirt"}, {"x": 1, "y": -1, "z": 9, "name": "Soil_Dirt"}, {"x": 1, "y": 0, "z": 9, "name": "Rock_Ledge_Brick_Ornate"}, {"x": 1, "y": -3, "z": 10, "name": "Soil_Dirt"}, {"x": 1, "y": -2, "z": 10, "name": "Soil_Dirt"}, {"x": 1, "y": -1, "z": 10, "name": "Soil_Dirt"}, {"x": 1, "y": 0, "z": 10, "name": "Rock_Ledge_Brick_Smooth"}, {"x": 1, "y": -3, "z": 11, "name": "Soil_Dirt"}, {"x": 1, "y": -2, "z": 11, "name": "Soil_Dirt"}, {"x": 1, "y": -1, "z": 11, "name": "Soil_Dirt"}, {"x": 1, "y": 0, "z": 11, "name": "Rock_Ledge_Brick_Ornate"}, {"x": 1, "y": -3, "z": 12, "name": "Soil_Dirt"}, {"x": 1, "y": -2, "z": 12, "name": "Soil_Dirt"}, {"x": 1, "y": -1, "z": 12, "name": "Soil_Dirt"}, {"x": 1, "y": 0, "z": 12, "name": "Rock_Ledge_Brick_Ornate"}, {"x": 1, "y": -3, "z": 13, "name": "Soil_Dirt"}, {"x": 1, "y": -2, "z": 13, "name": "Soil_Dirt"}, {"x": 1, "y": -1, "z": 13, "name": "Soil_Dirt"}, {"x": 1, "y": 0, "z": 13, "name": "Rock_Ledge_Brick_Decorative"}, {"x": 1, "y": -3, "z": 14, "name": "Soil_Dirt"}, {"x": 1, "y": -2, "z": 14, "name": "Soil_Dirt"}, {"x": 1, "y": -1, "z": 14, "name": "Soil_Dirt"}, {"x": 1, "y": 0, "z": 14, "name": "Rock_Ledge_Brick"}, {"x": 1, "y": -3, "z": 15, "name": "Soil_Dirt"}, {"x": 1, "y": -2, "z": 15, "name": "Soil_Dirt"}, {"x": 1, "y": -1, "z": 15, "name": "Soil_Dirt"}, {"x": 1, "y": 0, "z": 15, "name": "Rock_Ledge_Brick"}, {"x": 1, "y": -3, "z": 16, "name": "Soil_Dirt"}, {"x": 1, "y": -2, "z": 16, "name": "Soil_Dirt"}, {"x": 1, "y": -1, "z": 16, "name": "Soil_Dirt"}, {"x": 1, "y": 0, "z": 16, "name": "Rock_Ledge_Brick_Smooth"}, {"x": 1, "y": -3, "z": 17, "name": "Soil_Dirt"}, {"x": 1, "y": -2, "z": 17, "name": "Soil_Dirt"}, {"x": 1, "y": -1, "z": 17, "name": "Soil_Dirt"}, {"x": 1, "y": 0, "z": 17, "name": "Rock_Ledge_Brick_Decorative"}, {"x": 1, "y": -3, "z": 18, "name": "Soil_Dirt"}, {"x": 1, "y": -2, "z": 18, "name": "Soil_Dirt"}, {"x": 1, "y": -1, "z": 18, "name": "Soil_Dirt"}, {"x": 1, "y": 0, "z": 18, "name": "Rock_Ledge_Brick_Ornate"}, {"x": 1, "y": -3, "z": 19, "name": "Soil_Dirt"}, {"x": 1, "y": -2, "z": 19, "name": "Soil_Dirt"}, {"x": 1, "y": -1, "z": 19, "name": "Soil_Dirt"}, {"x": 1, "y": 0, "z": 19, "name": "Rock_Ledge_Brick"}, {"x": 1, "y": -3, "z": 20, "name": "Soil_Dirt"}, {"x": 1, "y": -2, "z": 20, "name": "Soil_Dirt"}, {"x": 1, "y": -1, "z": 20, "name": "Soil_Dirt"}, {"x": 1, "y": 0, "z": 20, "name": "Rock_Ledge_Cobble"}, {"x": 1, "y": -3, "z": 21, "name": "Soil_Dirt"}, {"x": 1, "y": -2, "z": 21, "name": "Soil_Dirt"}, {"x": 1, "y": -1, "z": 21, "name": "Soil_Dirt"}, {"x": 1, "y": 0, "z": 21, "name": "Rock_Ledge_Brick_Decorative"}, {"x": 1, "y": -3, "z": 22, "name": "Soil_Dirt"}, {"x": 1, "y": -2, "z": 22, "name": "Soil_Dirt"}, {"x": 1, "y": -1, "z": 22, "name": "Soil_Dirt"}, {"x": 1, "y": 0, "z": 22, "name": "Rock_Ledge_Brick_Smooth"}, {"x": 1, "y": -3, "z": 23, "name": "Soil_Dirt"}, {"x": 1, "y": -2, "z": 23, "name": "Soil_Dirt"}, {"x": 1, "y": -1, "z": 23, "name": "Soil_Dirt"}, {"x": 1, "y": 0, "z": 23, "name": "Rock_Ledge_Cobble"}, {"x": 1, "y": -3, "z": 24, "name": "Soil_Dirt"}, {"x": 1, "y": -2, "z": 24, "name": "Soil_Dirt"}, {"x": 1, "y": -1, "z": 24, "name": "Soil_Dirt"}, {"x": 1, "y": 0, "z": 24, "name": "Rock_Ledge_Brick"}, {"x": 1, "y": -3, "z": 25, "name": "Soil_Dirt"}, {"x": 1, "y": -2, "z": 25, "name": "Soil_Dirt"}, {"x": 1, "y": -1, "z": 25, "name": "Soil_Dirt"}, {"x": 1, "y": 0, "z": 25, "name": "Rock_Ledge_Brick_Ornate"}, {"x": 1, "y": -3, "z": 26, "name": "Soil_Dirt"}, {"x": 1, "y": -2, "z": 26, "name": "Soil_Dirt"}, {"x": 1, "y": -1, "z": 26, "name": "Soil_Dirt"}, {"x": 1, "y": 0, "z": 26, "name": "Rock_Ledge_Cobble"}, {"x": 1, "y": -3, "z": 27, "name": "Soil_Dirt"}, {"x": 1, "y": -2, "z": 27, "name": "Soil_Dirt"}, {"x": 1, "y": -1, "z": 27, "name": "Soil_Dirt"}, {"x": 1, "y": 0, "z": 27, "name": "Rock_Ledge_Brick_Ornate"}, {"x": 1, "y": -3, "z": 28, "name": "Soil_Dirt"}, {"x": 1, "y": -2, "z": 28, "name": "Soil_Dirt"}, {"x": 1, "y": -1, "z": 28, "name": "Soil_Dirt"}, {"x": 1, "y": 0, "z": 28, "name": "Rock_Ledge_Brick_Decorative"}, {"x": 1, "y": -3, "z": 29, "name": "Soil_Dirt"}, {"x": 1, "y": -2, "z": 29, "name": "Soil_Dirt"}, {"x": 1, "y": -1, "z": 29, "name": "Soil_Dirt"}, {"x": 1, "y": 0, "z": 29, "name": "Rock_Ledge_Brick_Decorative"}, {"x": 1, "y": -3, "z": 30, "name": "Soil_Dirt"}, {"x": 1, "y": -2, "z": 30, "name": "Soil_Dirt"}, {"x": 1, "y": -1, "z": 30, "name": "Soil_Dirt"}, {"x": 1, "y": 0, "z": 30, "name": "Rock_Ledge_Brick_Smooth"}, {"x": 1, "y": -3, "z": 31, "name": "Soil_Dirt"}, {"x": 1, "y": -2, "z": 31, "name": "Soil_Dirt"}, {"x": 1, "y": -1, "z": 31, "name": "Soil_Dirt"}, {"x": 1, "y": 0, "z": 31, "name": "Rock_Ledge_Brick_Smooth"}, {"x": 2, "y": -3, "z": 0, "name": "Soil_Dirt"}, {"x": 2, "y": -2, "z": 0, "name": "Soil_Dirt"}, {"x": 2, "y": -1, "z": 0, "name": "Soil_Dirt"}, {"x": 2, "y": 0, "z": 0, "name": "Rock_Ledge_Brick_Smooth"}, {"x": 2, "y": -3, "z": 1, "name": "Soil_Dirt"}, {"x": 2, "y": -2, "z": 1, "name": "Soil_Dirt"}, {"x": 2, "y": -1, "z": 1, "name": "Soil_Dirt"}, {"x": 2, "y": 0, "z": 1, "name": "Rock_Ledge_Brick_Smooth"}, {"x": 2, "y": -3, "z": 2, "name": "Soil_Dirt"}, {"x": 2, "y": -2, "z": 2, "name": "Soil_Dirt"}, {"x": 2, "y": -1, "z": 2, "name": "Soil_Dirt"}, {"x": 2, "y": 0, "z": 2, "name": "K2_Slot_Arrival"}, {"x": 2, "y": -3, "z": 3, "name": "Soil_Dirt"}, {"x": 2, "y": -2, "z": 3, "name": "Soil_Dirt"}, {"x": 2, "y": -1, "z": 3, "name": "Soil_Dirt"}, {"x": 2, "y": 0, "z": 3, "name": "Rock_Ledge_Brick_Ornate"}, {"x": 2, "y": -3, "z": 4, "name": "Soil_Dirt"}, {"x": 2, "y": -2, "z": 4, "name": "Soil_Dirt"}, {"x": 2, "y": -1, "z": 4, "name": "Soil_Dirt"}, {"x": 2, "y": 0, "z": 4, "name": "K2_Slot_Pad_4", "rotation": 1}, {"x": 2, "y": 3, "z": 4, "name": "Cloth_Modern_Blue_Roof", "rotation": 2}, {"x": 2, "y": -3, "z": 5, "name": "Soil_Dirt"}, {"x": 2, "y": -2, "z": 5, "name": "Soil_Dirt"}, {"x": 2, "y": -1, "z": 5, "name": "Soil_Dirt"}, {"x": 2, "y": 0, "z": 5, "name": "Rock_Ledge_Brick"}, {"x": 2, "y": 1, "z": 5, "name": "Rock_Quartzite_Cobble_Wall", "rotation": 2}, {"x": 2, "y": 2, "z": 5, "name": "Rock_Quartzite_Cobble_Wall", "rotation": 2}, {"x": 2, "y": 3, "z": 5, "name": "Cloth_Modern_Blue_Roof"}, {"x": 2, "y": -3, "z": 6, "name": "Soil_Dirt"}, {"x": 2, "y": -2, "z": 6, "name": "Soil_Dirt"}, {"x": 2, "y": -1, "z": 6, "name": "Soil_Dirt"}, {"x": 2, "y": 0, "z": 6, "name": "Rock_Ledge_Brick_Ornate"}, {"x": 2, "y": -3, "z": 7, "name": "Soil_Dirt"}, {"x": 2, "y": -2, "z": 7, "name": "Soil_Dirt"}, {"x": 2, "y": -1, "z": 7, "name": "Soil_Dirt"}, {"x": 2, "y": 0, "z": 7, "name": "Rock_Ledge_Brick_Smooth"}, {"x": 2, "y": -3, "z": 8, "name": "Soil_Dirt"}, {"x": 2, "y": -2, "z": 8, "name": "Soil_Dirt"}, {"x": 2, "y": -1, "z": 8, "name": "Soil_Dirt"}, {"x": 2, "y": 0, "z": 8, "name": "Rock_Ledge_Brick"}, {"x": 2, "y": -3, "z": 9, "name": "Soil_Dirt"}, {"x": 2, "y": -2, "z": 9, "name": "Soil_Dirt"}, {"x": 2, "y": -1, "z": 9, "name": "Soil_Dirt"}, {"x": 2, "y": 0, "z": 9, "name": "Rock_Ledge_Brick_Decorative"}, {"x": 2, "y": -3, "z": 10, "name": "Soil_Dirt"}, {"x": 2, "y": -2, "z": 10, "name": "Soil_Dirt"}, {"x": 2, "y": -1, "z": 10, "name": "Soil_Dirt"}, {"x": 2, "y": 0, "z": 10, "name": "Rock_Ledge_Cobble"}, {"x": 2, "y": -3, "z": 11, "name": "Soil_Dirt"}, {"x": 2, "y": -2, "z": 11, "name": "Soil_Dirt"}, {"x": 2, "y": -1, "z": 11, "name": "Soil_Dirt"}, {"x": 2, "y": 0, "z": 11, "name": "Rock_Ledge_Brick_Ornate"}, {"x": 2, "y": -3, "z": 12, "name": "Soil_Dirt"}, {"x": 2, "y": -2, "z": 12, "name": "Soil_Dirt"}, {"x": 2, "y": -1, "z": 12, "name": "Soil_Dirt"}, {"x": 2, "y": 0, "z": 12, "name": "Rock_Ledge_Brick_Smooth"}, {"x": 2, "y": -3, "z": 13, "name": "Soil_Dirt"}, {"x": 2, "y": -2, "z": 13, "name": "Soil_Dirt"}, {"x": 2, "y": -1, "z": 13, "name": "Soil_Dirt"}, {"x": 2, "y": 0, "z": 13, "name": "Rock_Ledge_Brick_Ornate"}, {"x": 2, "y": -3, "z": 14, "name": "Soil_Dirt"}, {"x": 2, "y": -2, "z": 14, "name": "Soil_Dirt"}, {"x": 2, "y": -1, "z": 14, "name": "Soil_Dirt"}, {"x": 2, "y": 0, "z": 14, "name": "Rock_Ledge_Brick_Ornate"}, {"x": 2, "y": -3, "z": 15, "name": "Soil_Dirt"}, {"x": 2, "y": -2, "z": 15, "name": "Soil_Dirt"}, {"x": 2, "y": -1, "z": 15, "name": "Soil_Dirt"}, {"x": 2, "y": 0, "z": 15, "name": "Rock_Ledge_Brick_Smooth"}, {"x": 2, "y": -3, "z": 16, "name": "Soil_Dirt"}, {"x": 2, "y": -2, "z": 16, "name": "Soil_Dirt"}, {"x": 2, "y": -1, "z": 16, "name": "Soil_Dirt"}, {"x": 2, "y": 0, "z": 16, "name": "Rock_Ledge_Brick_Decorative"}, {"x": 2, "y": -3, "z": 17, "name": "Soil_Dirt"}, {"x": 2, "y": -2, "z": 17, "name": "Soil_Dirt"}, {"x": 2, "y": -1, "z": 17, "name": "Soil_Dirt"}, {"x": 2, "y": 0, "z": 17, "name": "Rock_Ledge_Brick_Smooth"}, {"x": 2, "y": -3, "z": 18, "name": "Soil_Dirt"}, {"x": 2, "y": -2, "z": 18, "name": "Soil_Dirt"}, {"x": 2, "y": -1, "z": 18, "name": "Soil_Dirt"}, {"x": 2, "y": 0, "z": 18, "name": "Rock_Ledge_Brick"}, {"x": 2, "y": -3, "z": 19, "name": "Soil_Dirt"}, {"x": 2, "y": -2, "z": 19, "name": "Soil_Dirt"}, {"x": 2, "y": -1, "z": 19, "name": "Soil_Dirt"}, {"x": 2, "y": 0, "z": 19, "name": "Rock_Ledge_Cobble"}, {"x": 2, "y": -3, "z": 20, "name": "Soil_Dirt"}, {"x": 2, "y": -2, "z": 20, "name": "Soil_Dirt"}, {"x": 2, "y": -1, "z": 20, "name": "Soil_Dirt"}, {"x": 2, "y": 0, "z": 20, "name": "Rock_Ledge_Brick_Ornate"}, {"x": 2, "y": -3, "z": 21, "name": "Soil_Dirt"}, {"x": 2, "y": -2, "z": 21, "name": "Soil_Dirt"}, {"x": 2, "y": -1, "z": 21, "name": "Soil_Dirt"}, {"x": 2, "y": 0, "z": 21, "name": "Rock_Ledge_Brick_Smooth"}, {"x": 2, "y": -3, "z": 22, "name": "Soil_Dirt"}, {"x": 2, "y": -2, "z": 22, "name": "Soil_Dirt"}, {"x": 2, "y": -1, "z": 22, "name": "Soil_Dirt"}, {"x": 2, "y": 0, "z": 22, "name": "Rock_Ledge_Brick_Ornate"}, {"x": 2, "y": -3, "z": 23, "name": "Soil_Dirt"}, {"x": 2, "y": -2, "z": 23, "name": "Soil_Dirt"}, {"x": 2, "y": -1, "z": 23, "name": "Soil_Dirt"}, {"x": 2, "y": 0, "z": 23, "name": "Rock_Ledge_Brick_Smooth"}, {"x": 2, "y": -3, "z": 24, "name": "Soil_Dirt"}, {"x": 2, "y": -2, "z": 24, "name": "Soil_Dirt"}, {"x": 2, "y": -1, "z": 24, "name": "Soil_Dirt"}, {"x": 2, "y": 0, "z": 24, "name": "Rock_Ledge_Brick_Smooth"}, {"x": 2, "y": -3, "z": 25, "name": "Soil_Dirt"}, {"x": 2, "y": -2, "z": 25, "name": "Soil_Dirt"}, {"x": 2, "y": -1, "z": 25, "name": "Soil_Dirt"}, {"x": 2, "y": 0, "z": 25, "name": "Rock_Ledge_Brick_Smooth"}, {"x": 2, "y": -3, "z": 26, "name": "Soil_Dirt"}, {"x": 2, "y": -2, "z": 26, "name": "Soil_Dirt"}, {"x": 2, "y": -1, "z": 26, "name": "Soil_Dirt"}, {"x": 2, "y": 0, "z": 26, "name": "Rock_Ledge_Brick_Decorative"}, {"x": 2, "y": -3, "z": 27, "name": "Soil_Dirt"}, {"x": 2, "y": -2, "z": 27, "name": "Soil_Dirt"}, {"x": 2, "y": -1, "z": 27, "name": "Soil_Dirt"}, {"x": 2, "y": 0, "z": 27, "name": "Rock_Ledge_Brick_Smooth"}, {"x": 2, "y": -3, "z": 28, "name": "Soil_Dirt"}, {"x": 2, "y": -2, "z": 28, "name": "Soil_Dirt"}, {"x": 2, "y": -1, "z": 28, "name": "Soil_Dirt"}, {"x": 2, "y": 0, "z": 28, "name": "Rock_Ledge_Brick"}, {"x": 2, "y": -3, "z": 29, "name": "Soil_Dirt"}, {"x": 2, "y": -2, "z": 29, "name": "Soil_Dirt"}, {"x": 2, "y": -1, "z": 29, "name": "Soil_Dirt"}, {"x": 2, "y": 0, "z": 29, "name": "Rock_Ledge_Brick_Ornate"}, {"x": 2, "y": -3, "z": 30, "name": "Soil_Dirt"}, {"x": 2, "y": -2, "z": 30, "name": "Soil_Dirt"}, {"x": 2, "y": -1, "z": 30, "name": "Soil_Dirt"}, {"x": 2, "y": 0, "z": 30, "name": "Rock_Ledge_Brick_Ornate"}, {"x": 2, "y": -3, "z": 31, "name": "Soil_Dirt"}, {"x": 2, "y": -2, "z": 31, "name": "Soil_Dirt"}, {"x": 2, "y": -1, "z": 31, "name": "Soil_Dirt"}, {"x": 2, "y": 0, "z": 31, "name": "Rock_Ledge_Brick"}, {"x": 3, "y": -3, "z": 0, "name": "Soil_Dirt"}, {"x": 3, "y": -2, "z": 0, "name": "Soil_Dirt"}, {"x": 3, "y": -1, "z": 0, "name": "Soil_Dirt"}, {"x": 3, "y": 0, "z": 0, "name": "Rock_Ledge_Brick"}, {"x": 3, "y": -3, "z": 1, "name": "Soil_Dirt"}, {"x": 3, "y": -2, "z": 1, "name": "Soil_Dirt"}, {"x": 3, "y": -1, "z": 1, "name": "Soil_Dirt"}, {"x": 3, "y": 0, "z": 1, "name": "Rock_Ledge_Brick_Smooth"}, {"x": 3, "y": -3, "z": 2, "name": "Soil_Dirt"}, {"x": 3, "y": -2, "z": 2, "name": "Soil_Dirt"}, {"x": 3, "y": -1, "z": 2, "name": "Soil_Dirt"}, {"x": 3, "y": 0, "z": 2, "name": "Rock_Ledge_Brick_Smooth"}, {"x": 3, "y": -3, "z": 3, "name": "Soil_Dirt"}, {"x": 3, "y": -2, "z": 3, "name": "Soil_Dirt"}, {"x": 3, "y": -1, "z": 3, "name": "Soil_Dirt"}, {"x": 3, "y": 0, "z": 3, "name": "Rock_Ledge_Brick"}, {"x": 3, "y": -3, "z": 4, "name": "Soil_Dirt"}, {"x": 3, "y": -2, "z": 4, "name": "Soil_Dirt"}, {"x": 3, "y": -1, "z": 4, "name": "Soil_Dirt"}, {"x": 3, "y": 0, "z": 4, "name": "K2_Slot_Pad_3", "rotation": 1}, {"x": 3, "y": 3, "z": 4, "name": "Cloth_Modern_Blue_Roof", "rotation": 2}, {"x": 3, "y": -3, "z": 5, "name": "Soil_Dirt"}, {"x": 3, "y": -2, "z": 5, "name": "Soil_Dirt"}, {"x": 3, "y": -1, "z": 5, "name": "Soil_Dirt"}, {"x": 3, "y": 0, "z": 5, "name": "Rock_Ledge_Brick_Smooth"}, {"x": 3, "y": 1, "z": 5, "name": "Rock_Quartzite_Cobble_Wall", "rotation": 2}, {"x": 3, "y": 2, "z": 5, "name": "Rock_Quartzite_Cobble_Wall", "rotation": 2}, {"x": 3, "y": 3, "z": 5, "name": "Cloth_Modern_Blue_Roof"}, {"x": 3, "y": -3, "z": 6, "name": "Soil_Dirt"}, {"x": 3, "y": -2, "z": 6, "name": "Soil_Dirt"}, {"x": 3, "y": -1, "z": 6, "name": "Soil_Dirt"}, {"x": 3, "y": 0, "z": 6, "name": "Rock_Ledge_Brick_Smooth"}, {"x": 3, "y": -3, "z": 7, "name": "Soil_Dirt"}, {"x": 3, "y": -2, "z": 7, "name": "Soil_Dirt"}, {"x": 3, "y": -1, "z": 7, "name": "Soil_Dirt"}, {"x": 3, "y": 0, "z": 7, "name": "Rock_Ledge_Cobble"}, {"x": 3, "y": -3, "z": 8, "name": "Soil_Dirt"}, {"x": 3, "y": -2, "z": 8, "name": "Soil_Dirt"}, {"x": 3, "y": -1, "z": 8, "name": "Soil_Dirt"}, {"x": 3, "y": 0, "z": 8, "name": "Rock_Ledge_Brick"}, {"x": 3, "y": -3, "z": 9, "name": "Soil_Dirt"}, {"x": 3, "y": -2, "z": 9, "name": "Soil_Dirt"}, {"x": 3, "y": -1, "z": 9, "name": "Soil_Dirt"}, {"x": 3, "y": 0, "z": 9, "name": "Rock_Ledge_Brick"}, {"x": 3, "y": -3, "z": 10, "name": "Soil_Dirt"}, {"x": 3, "y": -2, "z": 10, "name": "Soil_Dirt"}, {"x": 3, "y": -1, "z": 10, "name": "Soil_Dirt"}, {"x": 3, "y": 0, "z": 10, "name": "Rock_Ledge_Brick_Smooth"}, {"x": 3, "y": -3, "z": 11, "name": "Soil_Dirt"}, {"x": 3, "y": -2, "z": 11, "name": "Soil_Dirt"}, {"x": 3, "y": -1, "z": 11, "name": "Soil_Dirt"}, {"x": 3, "y": 0, "z": 11, "name": "Rock_Ledge_Brick"}, {"x": 3, "y": -3, "z": 12, "name": "Soil_Dirt"}, {"x": 3, "y": -2, "z": 12, "name": "Soil_Dirt"}, {"x": 3, "y": -1, "z": 12, "name": "Soil_Dirt"}, {"x": 3, "y": 0, "z": 12, "name": "Rock_Ledge_Brick_Ornate"}, {"x": 3, "y": -3, "z": 13, "name": "Soil_Dirt"}, {"x": 3, "y": -2, "z": 13, "name": "Soil_Dirt"}, {"x": 3, "y": -1, "z": 13, "name": "Soil_Dirt"}, {"x": 3, "y": 0, "z": 13, "name": "Rock_Ledge_Brick_Decorative"}, {"x": 3, "y": -3, "z": 14, "name": "Soil_Dirt"}, {"x": 3, "y": -2, "z": 14, "name": "Soil_Dirt"}, {"x": 3, "y": -1, "z": 14, "name": "Soil_Dirt"}, {"x": 3, "y": 0, "z": 14, "name": "Rock_Ledge_Cobble"}, {"x": 3, "y": -3, "z": 15, "name": "Soil_Dirt"}, {"x": 3, "y": -2, "z": 15, "name": "Soil_Dirt"}, {"x": 3, "y": -1, "z": 15, "name": "Soil_Dirt"}, {"x": 3, "y": 0, "z": 15, "name": "Rock_Ledge_Cobble"}, {"x": 3, "y": -3, "z": 16, "name": "Soil_Dirt"}, {"x": 3, "y": -2, "z": 16, "name": "Soil_Dirt"}, {"x": 3, "y": -1, "z": 16, "name": "Soil_Dirt"}, {"x": 3, "y": 0, "z": 16, "name": "Rock_Ledge_Brick_Smooth"}, {"x": 3, "y": -3, "z": 17, "name": "Soil_Dirt"}, {"x": 3, "y": -2, "z": 17, "name": "Soil_Dirt"}, {"x": 3, "y": -1, "z": 17, "name": "Soil_Dirt"}, {"x": 3, "y": 0, "z": 17, "name": "Rock_Ledge_Brick_Smooth"}, {"x": 3, "y": -3, "z": 18, "name": "Soil_Dirt"}, {"x": 3, "y": -2, "z": 18, "name": "Soil_Dirt"}, {"x": 3, "y": -1, "z": 18, "name": "Soil_Dirt"}, {"x": 3, "y": 0, "z": 18, "name": "Rock_Ledge_Cobble"}, {"x": 3, "y": -3, "z": 19, "name": "Soil_Dirt"}, {"x": 3, "y": -2, "z": 19, "name": "Soil_Dirt"}, {"x": 3, "y": -1, "z": 19, "name": "Soil_Dirt"}, {"x": 3, "y": 0, "z": 19, "name": "Rock_Ledge_Brick_Decorative"}, {"x": 3, "y": -3, "z": 20, "name": "Soil_Dirt"}, {"x": 3, "y": -2, "z": 20, "name": "Soil_Dirt"}, {"x": 3, "y": -1, "z": 20, "name": "Soil_Dirt"}, {"x": 3, "y": 0, "z": 20, "name": "Rock_Ledge_Cobble"}, {"x": 3, "y": -3, "z": 21, "name": "Soil_Dirt"}, {"x": 3, "y": -2, "z": 21, "name": "Soil_Dirt"}, {"x": 3, "y": -1, "z": 21, "name": "Soil_Dirt"}, {"x": 3, "y": 0, "z": 21, "name": "Rock_Ledge_Brick_Smooth"}, {"x": 3, "y": -3, "z": 22, "name": "Soil_Dirt"}, {"x": 3, "y": -2, "z": 22, "name": "Soil_Dirt"}, {"x": 3, "y": -1, "z": 22, "name": "Soil_Dirt"}, {"x": 3, "y": 0, "z": 22, "name": "Rock_Ledge_Brick"}, {"x": 3, "y": -3, "z": 23, "name": "Soil_Dirt"}, {"x": 3, "y": -2, "z": 23, "name": "Soil_Dirt"}, {"x": 3, "y": -1, "z": 23, "name": "Soil_Dirt"}, {"x": 3, "y": 0, "z": 23, "name": "Rock_Ledge_Brick"}, {"x": 3, "y": -3, "z": 24, "name": "Soil_Dirt"}, {"x": 3, "y": -2, "z": 24, "name": "Soil_Dirt"}, {"x": 3, "y": -1, "z": 24, "name": "Soil_Dirt"}, {"x": 3, "y": 0, "z": 24, "name": "Rock_Ledge_Brick_Ornate"}, {"x": 3, "y": -3, "z": 25, "name": "Soil_Dirt"}, {"x": 3, "y": -2, "z": 25, "name": "Soil_Dirt"}, {"x": 3, "y": -1, "z": 25, "name": "Soil_Dirt"}, {"x": 3, "y": 0, "z": 25, "name": "Rock_Ledge_Brick"}, {"x": 3, "y": -3, "z": 26, "name": "Soil_Dirt"}, {"x": 3, "y": -2, "z": 26, "name": "Soil_Dirt"}, {"x": 3, "y": -1, "z": 26, "name": "Soil_Dirt"}, {"x": 3, "y": 0, "z": 26, "name": "Rock_Ledge_Brick"}, {"x": 3, "y": -3, "z": 27, "name": "Soil_Dirt"}, {"x": 3, "y": -2, "z": 27, "name": "Soil_Dirt"}, {"x": 3, "y": -1, "z": 27, "name": "Soil_Dirt"}, {"x": 3, "y": 0, "z": 27, "name": "Rock_Ledge_Cobble"}, {"x": 3, "y": -3, "z": 28, "name": "Soil_Dirt"}, {"x": 3, "y": -2, "z": 28, "name": "Soil_Dirt"}, {"x": 3, "y": -1, "z": 28, "name": "Soil_Dirt"}, {"x": 3, "y": 0, "z": 28, "name": "Rock_Ledge_Brick_Smooth"}, {"x": 3, "y": -3, "z": 29, "name": "Soil_Dirt"}, {"x": 3, "y": -2, "z": 29, "name": "Soil_Dirt"}, {"x": 3, "y": -1, "z": 29, "name": "Soil_Dirt"}, {"x": 3, "y": 0, "z": 29, "name": "Rock_Ledge_Brick_Decorative"}, {"x": 3, "y": -3, "z": 30, "name": "Soil_Dirt"}, {"x": 3, "y": -2, "z": 30, "name": "Soil_Dirt"}, {"x": 3, "y": -1, "z": 30, "name": "Soil_Dirt"}, {"x": 3, "y": 0, "z": 30, "name": "Rock_Ledge_Brick_Smooth"}, {"x": 3, "y": -3, "z": 31, "name": "Soil_Dirt"}, {"x": 3, "y": -2, "z": 31, "name": "Soil_Dirt"}, {"x": 3, "y": -1, "z": 31, "name": "Soil_Dirt"}, {"x": 3, "y": 0, "z": 31, "name": "Rock_Ledge_Brick_Smooth"}, {"x": 4, "y": -3, "z": 0, "name": "Soil_Dirt"}, {"x": 4, "y": -2, "z": 0, "name": "Soil_Dirt"}, {"x": 4, "y": -1, "z": 0, "name": "Soil_Dirt"}, {"x": 4, "y": 0, "z": 0, "name": "Rock_Ledge_Brick_Smooth"}, {"x": 4, "y": -3, "z": 1, "name": "Soil_Dirt"}, {"x": 4, "y": -2, "z": 1, "name": "Soil_Dirt"}, {"x": 4, "y": -1, "z": 1, "name": "Soil_Dirt"}, {"x": 4, "y": 0, "z": 1, "name": "Rock_Ledge_Brick_Ornate"}, {"x": 4, "y": -3, "z": 2, "name": "Soil_Dirt"}, {"x": 4, "y": -2, "z": 2, "name": "Soil_Dirt"}, {"x": 4, "y": -1, "z": 2, "name": "Soil_Dirt"}, {"x": 4, "y": 0, "z": 2, "name": "Rock_Ledge_Cobble"}, {"x": 4, "y": -3, "z": 3, "name": "Soil_Dirt"}, {"x": 4, "y": -2, "z": 3, "name": "Soil_Dirt"}, {"x": 4, "y": -1, "z": 3, "name": "Soil_Dirt"}, {"x": 4, "y": 0, "z": 3, "name": "Rock_Ledge_Cobble"}, {"x": 4, "y": -3, "z": 4, "name": "Soil_Dirt"}, {"x": 4, "y": -2, "z": 4, "name": "Soil_Dirt"}, {"x": 4, "y": -1, "z": 4, "name": "Soil_Dirt"}, {"x": 4, "y": 0, "z": 4, "name": "K2_Slot_Pad_2", "rotation": 1}, {"x": 4, "y": 3, "z": 4, "name": "Cloth_Modern_Blue_Roof", "rotation": 2}, {"x": 4, "y": -3, "z": 5, "name": "Soil_Dirt"}, {"x": 4, "y": -2, "z": 5, "name": "Soil_Dirt"}, {"x": 4, "y": -1, "z": 5, "name": "Soil_Dirt"}, {"x": 4, "y": 0, "z": 5, "name": "Rock_Ledge_Brick_Ornate"}, {"x": 4, "y": 1, "z": 5, "name": "Rock_Quartzite_Cobble_Wall", "rotation": 2}, {"x": 4, "y": 2, "z": 5, "name": "Rock_Quartzite_Cobble_Wall", "rotation": 2}, {"x": 4, "y": 3, "z": 5, "name": "Cloth_Modern_Blue_Roof"}, {"x": 4, "y": -3, "z": 6, "name": "Soil_Dirt"}, {"x": 4, "y": -2, "z": 6, "name": "Soil_Dirt"}, {"x": 4, "y": -1, "z": 6, "name": "Soil_Dirt"}, {"x": 4, "y": 0, "z": 6, "name": "Rock_Ledge_Cobble"}, {"x": 4, "y": -3, "z": 7, "name": "Soil_Dirt"}, {"x": 4, "y": -2, "z": 7, "name": "Soil_Dirt"}, {"x": 4, "y": -1, "z": 7, "name": "Soil_Dirt"}, {"x": 4, "y": 0, "z": 7, "name": "Rock_Ledge_Brick_Decorative"}, {"x": 4, "y": -3, "z": 8, "name": "Soil_Dirt"}, {"x": 4, "y": -2, "z": 8, "name": "Soil_Dirt"}, {"x": 4, "y": -1, "z": 8, "name": "Soil_Dirt"}, {"x": 4, "y": 0, "z": 8, "name": "Rock_Ledge_Brick"}, {"x": 4, "y": -3, "z": 9, "name": "Soil_Dirt"}, {"x": 4, "y": -2, "z": 9, "name": "Soil_Dirt"}, {"x": 4, "y": -1, "z": 9, "name": "Soil_Dirt"}, {"x": 4, "y": 0, "z": 9, "name": "Rock_Ledge_Brick_Smooth"}, {"x": 4, "y": -3, "z": 10, "name": "Soil_Dirt"}, {"x": 4, "y": -2, "z": 10, "name": "Soil_Dirt"}, {"x": 4, "y": -1, "z": 10, "name": "Soil_Dirt"}, {"x": 4, "y": 0, "z": 10, "name": "Rock_Ledge_Brick_Ornate"}, {"x": 4, "y": -3, "z": 11, "name": "Soil_Dirt"}, {"x": 4, "y": -2, "z": 11, "name": "Soil_Dirt"}, {"x": 4, "y": -1, "z": 11, "name": "Soil_Dirt"}, {"x": 4, "y": 0, "z": 11, "name": "Rock_Ledge_Brick_Decorative"}, {"x": 4, "y": -3, "z": 12, "name": "Soil_Dirt"}, {"x": 4, "y": -2, "z": 12, "name": "Soil_Dirt"}, {"x": 4, "y": -1, "z": 12, "name": "Soil_Dirt"}, {"x": 4, "y": 0, "z": 12, "name": "Rock_Ledge_Brick_Ornate"}, {"x": 4, "y": -3, "z": 13, "name": "Soil_Dirt"}, {"x": 4, "y": -2, "z": 13, "name": "Soil_Dirt"}, {"x": 4, "y": -1, "z": 13, "name": "Soil_Dirt"}, {"x": 4, "y": 0, "z": 13, "name": "Rock_Ledge_Brick_Smooth"}, {"x": 4, "y": -3, "z": 14, "name": "Soil_Dirt"}, {"x": 4, "y": -2, "z": 14, "name": "Soil_Dirt"}, {"x": 4, "y": -1, "z": 14, "name": "Soil_Dirt"}, {"x": 4, "y": 0, "z": 14, "name": "Rock_Ledge_Brick_Ornate"}, {"x": 4, "y": -3, "z": 15, "name": "Soil_Dirt"}, {"x": 4, "y": -2, "z": 15, "name": "Soil_Dirt"}, {"x": 4, "y": -1, "z": 15, "name": "Soil_Dirt"}, {"x": 4, "y": 0, "z": 15, "name": "Rock_Ledge_Brick_Smooth"}, {"x": 4, "y": -3, "z": 16, "name": "Soil_Dirt"}, {"x": 4, "y": -2, "z": 16, "name": "Soil_Dirt"}, {"x": 4, "y": -1, "z": 16, "name": "Soil_Dirt"}, {"x": 4, "y": 0, "z": 16, "name": "Rock_Ledge_Cobble"}, {"x": 4, "y": -3, "z": 17, "name": "Soil_Dirt"}, {"x": 4, "y": -2, "z": 17, "name": "Soil_Dirt"}, {"x": 4, "y": -1, "z": 17, "name": "Soil_Dirt"}, {"x": 4, "y": 0, "z": 17, "name": "Rock_Ledge_Cobble"}, {"x": 4, "y": -3, "z": 18, "name": "Soil_Dirt"}, {"x": 4, "y": -2, "z": 18, "name": "Soil_Dirt"}, {"x": 4, "y": -1, "z": 18, "name": "Soil_Dirt"}, {"x": 4, "y": 0, "z": 18, "name": "Rock_Ledge_Brick_Decorative"}, {"x": 4, "y": -3, "z": 19, "name": "Soil_Dirt"}, {"x": 4, "y": -2, "z": 19, "name": "Soil_Dirt"}, {"x": 4, "y": -1, "z": 19, "name": "Soil_Dirt"}, {"x": 4, "y": 0, "z": 19, "name": "Rock_Ledge_Brick_Decorative"}, {"x": 4, "y": -3, "z": 20, "name": "Soil_Dirt"}, {"x": 4, "y": -2, "z": 20, "name": "Soil_Dirt"}, {"x": 4, "y": -1, "z": 20, "name": "Soil_Dirt"}, {"x": 4, "y": 0, "z": 20, "name": "Rock_Ledge_Cobble"}, {"x": 4, "y": -3, "z": 21, "name": "Soil_Dirt"}, {"x": 4, "y": -2, "z": 21, "name": "Soil_Dirt"}, {"x": 4, "y": -1, "z": 21, "name": "Soil_Dirt"}, {"x": 4, "y": 0, "z": 21, "name": "Rock_Ledge_Cobble"}, {"x": 4, "y": -3, "z": 22, "name": "Soil_Dirt"}, {"x": 4, "y": -2, "z": 22, "name": "Soil_Dirt"}, {"x": 4, "y": -1, "z": 22, "name": "Soil_Dirt"}, {"x": 4, "y": 0, "z": 22, "name": "Rock_Ledge_Cobble"}, {"x": 4, "y": -3, "z": 23, "name": "Soil_Dirt"}, {"x": 4, "y": -2, "z": 23, "name": "Soil_Dirt"}, {"x": 4, "y": -1, "z": 23, "name": "Soil_Dirt"}, {"x": 4, "y": 0, "z": 23, "name": "Rock_Ledge_Brick_Smooth"}, {"x": 4, "y": 1, "z": 23, "name": "Rock_Quartzite_Brick_Smooth"}, {"x": 4, "y": 2, "z": 23, "name": "Rock_Quartzite_Brick_Smooth"}, {"x": 4, "y": 3, "z": 23, "name": "Rock_Quartzite_Brick_Smooth"}, {"x": 4, "y": 4, "z": 23, "name": "Rock_Quartzite_Brick_Smooth"}, {"x": 4, "y": 5, "z": 23, "name": "Rock_Quartzite_Brick_Smooth"}, {"x": 4, "y": 6, "z": 23, "name": "Rock_Quartzite_Brick_Smooth"}, {"x": 4, "y": -3, "z": 24, "name": "Soil_Dirt"}, {"x": 4, "y": -2, "z": 24, "name": "Soil_Dirt"}, {"x": 4, "y": -1, "z": 24, "name": "Soil_Dirt"}, {"x": 4, "y": 0, "z": 24, "name": "Rock_Ledge_Brick_Smooth"}, {"x": 4, "y": -3, "z": 25, "name": "Soil_Dirt"}, {"x": 4, "y": -2, "z": 25, "name": "Soil_Dirt"}, {"x": 4, "y": -1, "z": 25, "name": "Soil_Dirt"}, {"x": 4, "y": 0, "z": 25, "name": "Rock_Ledge_Brick_Decorative"}, {"x": 4, "y": -3, "z": 26, "name": "Soil_Dirt"}, {"x": 4, "y": -2, "z": 26, "name": "Soil_Dirt"}, {"x": 4, "y": -1, "z": 26, "name": "Soil_Dirt"}, {"x": 4, "y": 0, "z": 26, "name": "Rock_Ledge_Cobble"}, {"x": 4, "y": -3, "z": 27, "name": "Soil_Dirt"}, {"x": 4, "y": -2, "z": 27, "name": "Soil_Dirt"}, {"x": 4, "y": -1, "z": 27, "name": "Soil_Dirt"}, {"x": 4, "y": 0, "z": 27, "name": "Rock_Ledge_Brick_Ornate"}, {"x": 4, "y": -3, "z": 28, "name": "Soil_Dirt"}, {"x": 4, "y": -2, "z": 28, "name": "Soil_Dirt"}, {"x": 4, "y": -1, "z": 28, "name": "Soil_Dirt"}, {"x": 4, "y": 0, "z": 28, "name": "Rock_Ledge_Brick_Smooth"}, {"x": 4, "y": -3, "z": 29, "name": "Soil_Dirt"}, {"x": 4, "y": -2, "z": 29, "name": "Soil_Dirt"}, {"x": 4, "y": -1, "z": 29, "name": "Soil_Dirt"}, {"x": 4, "y": 0, "z": 29, "name": "Rock_Ledge_Brick_Smooth"}, {"x": 4, "y": -3, "z": 30, "name": "Soil_Dirt"}, {"x": 4, "y": -2, "z": 30, "name": "Soil_Dirt"}, {"x": 4, "y": -1, "z": 30, "name": "Soil_Dirt"}, {"x": 4, "y": 0, "z": 30, "name": "Rock_Ledge_Brick_Smooth"}, {"x": 4, "y": -3, "z": 31, "name": "Soil_Dirt"}, {"x": 4, "y": -2, "z": 31, "name": "Soil_Dirt"}, {"x": 4, "y": -1, "z": 31, "name": "Soil_Dirt"}, {"x": 4, "y": 0, "z": 31, "name": "Rock_Ledge_Cobble"}, {"x": 5, "y": -3, "z": 0, "name": "Soil_Dirt"}, {"x": 5, "y": -2, "z": 0, "name": "Soil_Dirt"}, {"x": 5, "y": -1, "z": 0, "name": "Soil_Dirt"}, {"x": 5, "y": 0, "z": 0, "name": "Rock_Ledge_Brick_Smooth"}, {"x": 5, "y": -3, "z": 1, "name": "Soil_Dirt"}, {"x": 5, "y": -2, "z": 1, "name": "Soil_Dirt"}, {"x": 5, "y": -1, "z": 1, "name": "Soil_Dirt"}, {"x": 5, "y": 0, "z": 1, "name": "Rock_Ledge_Brick_Smooth"}, {"x": 5, "y": -3, "z": 2, "name": "Soil_Dirt"}, {"x": 5, "y": -2, "z": 2, "name": "Soil_Dirt"}, {"x": 5, "y": -1, "z": 2, "name": "Soil_Dirt"}, {"x": 5, "y": 0, "z": 2, "name": "Rock_Ledge_Brick_Smooth"}, {"x": 5, "y": -3, "z": 3, "name": "Soil_Dirt"}, {"x": 5, "y": -2, "z": 3, "name": "Soil_Dirt"}, {"x": 5, "y": -1, "z": 3, "name": "Soil_Dirt"}, {"x": 5, "y": 0, "z": 3, "name": "Rock_Ledge_Brick_Smooth"}, {"x": 5, "y": -3, "z": 4, "name": "Soil_Dirt"}, {"x": 5, "y": -2, "z": 4, "name": "Soil_Dirt"}, {"x": 5, "y": -1, "z": 4, "name": "Soil_Dirt"}, {"x": 5, "y": 0, "z": 4, "name": "K2_Slot_Pad_1", "rotation": 1}, {"x": 5, "y": 3, "z": 4, "name": "Cloth_Modern_Blue_Roof", "rotation": 2}, {"x": 5, "y": -3, "z": 5, "name": "Soil_Dirt"}, {"x": 5, "y": -2, "z": 5, "name": "Soil_Dirt"}, {"x": 5, "y": -1, "z": 5, "name": "Soil_Dirt"}, {"x": 5, "y": 0, "z": 5, "name": "Rock_Ledge_Brick_Decorative"}, {"x": 5, "y": 1, "z": 5, "name": "Rock_Quartzite_Cobble_Wall", "rotation": 2}, {"x": 5, "y": 2, "z": 5, "name": "Rock_Quartzite_Cobble_Wall", "rotation": 2}, {"x": 5, "y": 3, "z": 5, "name": "Cloth_Modern_Blue_Roof"}, {"x": 5, "y": -3, "z": 6, "name": "Soil_Dirt"}, {"x": 5, "y": -2, "z": 6, "name": "Soil_Dirt"}, {"x": 5, "y": -1, "z": 6, "name": "Soil_Dirt"}, {"x": 5, "y": 0, "z": 6, "name": "Soil_Dirt"}, {"x": 5, "y": 1, "z": 6, "name": "Rock_Calcite_Brick_Decorative"}, {"x": 5, "y": 2, "z": 6, "name": "Rock_Lime_Brick_Smooth"}, {"x": 5, "y": 3, "z": 6, "name": "Rock_Lime_Brick_Smooth"}, {"x": 5, "y": 4, "z": 6, "name": "Rock_Lime_Brick_Smooth"}, {"x": 5, "y": 5, "z": 6, "name": "Rock_Calcite_Brick_Smooth_Half"}, {"x": 5, "y": -3, "z": 7, "name": "Soil_Dirt"}, {"x": 5, "y": -2, "z": 7, "name": "Soil_Dirt"}, {"x": 5, "y": -1, "z": 7, "name": "Soil_Dirt"}, {"x": 5, "y": 0, "z": 7, "name": "Soil_Dirt"}, {"x": 5, "y": 1, "z": 7, "name": "Rock_Calcite_Brick_Decorative"}, {"x": 5, "y": 2, "z": 7, "name": "Rock_Lime_Brick_Smooth"}, {"x": 5, "y": 3, "z": 7, "name": "Rock_Lime_Brick_Smooth"}, {"x": 5, "y": 4, "z": 7, "name": "Rock_Lime_Brick_Smooth"}, {"x": 5, "y": 5, "z": 7, "name": "Rock_Calcite_Brick_Smooth_Half"}, {"x": 5, "y": -3, "z": 8, "name": "Soil_Dirt"}, {"x": 5, "y": -2, "z": 8, "name": "Soil_Dirt"}, {"x": 5, "y": -1, "z": 8, "name": "Soil_Dirt"}, {"x": 5, "y": 0, "z": 8, "name": "Soil_Dirt"}, {"x": 5, "y": 1, "z": 8, "name": "Rock_Calcite_Brick_Decorative"}, {"x": 5, "y": 2, "z": 8, "name": "Furniture_Temple_Dark_Window", "rotation": 1}, {"x": 5, "y": 3, "z": 8, "name": "Furniture_Temple_Dark_Window", "rotation": 1}, {"x": 5, "y": 4, "z": 8, "name": "Rock_Lime_Brick_Smooth"}, {"x": 5, "y": 5, "z": 8, "name": "Rock_Calcite_Brick_Smooth_Half"}, {"x": 5, "y": -3, "z": 9, "name": "Soil_Dirt"}, {"x": 5, "y": -2, "z": 9, "name": "Soil_Dirt"}, {"x": 5, "y": -1, "z": 9, "name": "Soil_Dirt"}, {"x": 5, "y": 0, "z": 9, "name": "Soil_Dirt"}, {"x": 5, "y": 1, "z": 9, "name": "Rock_Calcite_Brick_Decorative"}, {"x": 5, "y": 2, "z": 9, "name": "Rock_Lime_Brick_Smooth"}, {"x": 5, "y": 3, "z": 9, "name": "Rock_Lime_Brick_Smooth"}, {"x": 5, "y": 4, "z": 9, "name": "Rock_Lime_Brick_Smooth"}, {"x": 5, "y": 5, "z": 9, "name": "Rock_Calcite_Brick_Smooth_Half"}, {"x": 5, "y": -3, "z": 10, "name": "Soil_Dirt"}, {"x": 5, "y": -2, "z": 10, "name": "Soil_Dirt"}, {"x": 5, "y": -1, "z": 10, "name": "Soil_Dirt"}, {"x": 5, "y": 0, "z": 10, "name": "Soil_Dirt"}, {"x": 5, "y": 1, "z": 10, "name": "Rock_Calcite_Brick_Decorative"}, {"x": 5, "y": 2, "z": 10, "name": "Furniture_Temple_Dark_Window", "rotation": 1}, {"x": 5, "y": 3, "z": 10, "name": "Furniture_Temple_Dark_Window", "rotation": 1}, {"x": 5, "y": 4, "z": 10, "name": "Rock_Lime_Brick_Smooth"}, {"x": 5, "y": 5, "z": 10, "name": "Rock_Calcite_Brick_Smooth_Half"}, {"x": 5, "y": -3, "z": 11, "name": "Soil_Dirt"}, {"x": 5, "y": -2, "z": 11, "name": "Soil_Dirt"}, {"x": 5, "y": -1, "z": 11, "name": "Soil_Dirt"}, {"x": 5, "y": 0, "z": 11, "name": "Soil_Dirt"}, {"x": 5, "y": 1, "z": 11, "name": "Rock_Calcite_Brick_Decorative"}, {"x": 5, "y": 2, "z": 11, "name": "Rock_Lime_Brick_Smooth"}, {"x": 5, "y": 3, "z": 11, "name": "Rock_Lime_Brick_Smooth"}, {"x": 5, "y": 4, "z": 11, "name": "Rock_Lime_Brick_Smooth"}, {"x": 5, "y": 5, "z": 11, "name": "Rock_Calcite_Brick_Smooth_Half"}, {"x": 5, "y": -3, "z": 12, "name": "Soil_Dirt"}, {"x": 5, "y": -2, "z": 12, "name": "Soil_Dirt"}, {"x": 5, "y": -1, "z": 12, "name": "Soil_Dirt"}, {"x": 5, "y": 0, "z": 12, "name": "Soil_Dirt"}, {"x": 5, "y": 1, "z": 12, "name": "Rock_Calcite_Brick_Decorative"}, {"x": 5, "y": 2, "z": 12, "name": "Furniture_Temple_Dark_Window", "rotation": 1}, {"x": 5, "y": 3, "z": 12, "name": "Furniture_Temple_Dark_Window", "rotation": 1}, {"x": 5, "y": 4, "z": 12, "name": "Rock_Lime_Brick_Smooth"}, {"x": 5, "y": 5, "z": 12, "name": "Rock_Calcite_Brick_Smooth_Half"}, {"x": 5, "y": -3, "z": 13, "name": "Soil_Dirt"}, {"x": 5, "y": -2, "z": 13, "name": "Soil_Dirt"}, {"x": 5, "y": -1, "z": 13, "name": "Soil_Dirt"}, {"x": 5, "y": 0, "z": 13, "name": "Soil_Dirt"}, {"x": 5, "y": 1, "z": 13, "name": "Rock_Calcite_Brick_Decorative"}, {"x": 5, "y": 2, "z": 13, "name": "Rock_Lime_Brick_Smooth"}, {"x": 5, "y": 3, "z": 13, "name": "Rock_Lime_Brick_Smooth"}, {"x": 5, "y": 4, "z": 13, "name": "Rock_Lime_Brick_Smooth"}, {"x": 5, "y": 5, "z": 13, "name": "Rock_Calcite_Brick_Smooth_Half"}, {"x": 5, "y": -3, "z": 14, "name": "Soil_Dirt"}, {"x": 5, "y": -2, "z": 14, "name": "Soil_Dirt"}, {"x": 5, "y": -1, "z": 14, "name": "Soil_Dirt"}, {"x": 5, "y": 0, "z": 14, "name": "Soil_Dirt"}, {"x": 5, "y": 1, "z": 14, "name": "Rock_Calcite_Brick_Decorative"}, {"x": 5, "y": 2, "z": 14, "name": "Rock_Lime_Brick_Smooth"}, {"x": 5, "y": 3, "z": 14, "name": "Rock_Lime_Brick_Smooth"}, {"x": 5, "y": 4, "z": 14, "name": "Rock_Lime_Brick_Smooth"}, {"x": 5, "y": 5, "z": 14, "name": "Rock_Calcite_Brick_Smooth_Half"}, {"x": 5, "y": -3, "z": 15, "name": "Soil_Dirt"}, {"x": 5, "y": -2, "z": 15, "name": "Soil_Dirt"}, {"x": 5, "y": -1, "z": 15, "name": "Soil_Dirt"}, {"x": 5, "y": 0, "z": 15, "name": "Rock_Ledge_Brick_Smooth"}, {"x": 5, "y": -3, "z": 16, "name": "Soil_Dirt"}, {"x": 5, "y": -2, "z": 16, "name": "Soil_Dirt"}, {"x": 5, "y": -1, "z": 16, "name": "Soil_Dirt"}, {"x": 5, "y": 0, "z": 16, "name": "Rock_Ledge_Cobble"}, {"x": 5, "y": -3, "z": 17, "name": "Soil_Dirt"}, {"x": 5, "y": -2, "z": 17, "name": "Soil_Dirt"}, {"x": 5, "y": -1, "z": 17, "name": "Soil_Dirt"}, {"x": 5, "y": 0, "z": 17, "name": "Rock_Ledge_Brick_Ornate"}, {"x": 5, "y": -3, "z": 18, "name": "Soil_Dirt"}, {"x": 5, "y": -2, "z": 18, "name": "Soil_Dirt"}, {"x": 5, "y": -1, "z": 18, "name": "Soil_Dirt"}, {"x": 5, "y": 0, "z": 18, "name": "Rock_Ledge_Brick"}, {"x": 5, "y": -3, "z": 19, "name": "Soil_Dirt"}, {"x": 5, "y": -2, "z": 19, "name": "Soil_Dirt"}, {"x": 5, "y": -1, "z": 19, "name": "Soil_Dirt"}, {"x": 5, "y": 0, "z": 19, "name": "Rock_Ledge_Brick_Smooth"}, {"x": 5, "y": -3, "z": 20, "name": "Soil_Dirt"}, {"x": 5, "y": -2, "z": 20, "name": "Soil_Dirt"}, {"x": 5, "y": -1, "z": 20, "name": "Soil_Dirt"}, {"x": 5, "y": 0, "z": 20, "name": "Rock_Ledge_Brick_Decorative"}, {"x": 5, "y": -3, "z": 21, "name": "Soil_Dirt"}, {"x": 5, "y": -2, "z": 21, "name": "Soil_Dirt"}, {"x": 5, "y": -1, "z": 21, "name": "Soil_Dirt"}, {"x": 5, "y": 0, "z": 21, "name": "Rock_Ledge_Brick_Ornate"}, {"x": 5, "y": -3, "z": 22, "name": "Soil_Dirt"}, {"x": 5, "y": -2, "z": 22, "name": "Soil_Dirt"}, {"x": 5, "y": -1, "z": 22, "name": "Soil_Dirt"}, {"x": 5, "y": 0, "z": 22, "name": "Rock_Ledge_Brick"}, {"x": 5, "y": -3, "z": 23, "name": "Soil_Dirt"}, {"x": 5, "y": -2, "z": 23, "name": "Soil_Dirt"}, {"x": 5, "y": -1, "z": 23, "name": "Soil_Dirt"}, {"x": 5, "y": 0, "z": 23, "name": "Rock_Ledge_Brick_Smooth"}, {"x": 5, "y": 1, "z": 23, "name": "Rock_Quartzite_Brick_Smooth"}, {"x": 5, "y": 2, "z": 23, "name": "Rock_Quartzite_Brick_Smooth"}, {"x": 5, "y": 3, "z": 23, "name": "Rock_Quartzite_Brick_Smooth"}, {"x": 5, "y": 4, "z": 23, "name": "Rock_Quartzite_Brick_Smooth"}, {"x": 5, "y": 5, "z": 23, "name": "Rock_Quartzite_Brick_Smooth"}, {"x": 5, "y": 6, "z": 23, "name": "Rock_Quartzite_Brick_Smooth"}, {"x": 5, "y": -3, "z": 24, "name": "Soil_Dirt"}, {"x": 5, "y": -2, "z": 24, "name": "Soil_Dirt"}, {"x": 5, "y": -1, "z": 24, "name": "Soil_Dirt"}, {"x": 5, "y": 0, "z": 24, "name": "Rock_Ledge_Brick_Smooth"}, {"x": 5, "y": -3, "z": 25, "name": "Soil_Dirt"}, {"x": 5, "y": -2, "z": 25, "name": "Soil_Dirt"}, {"x": 5, "y": -1, "z": 25, "name": "Soil_Dirt"}, {"x": 5, "y": 0, "z": 25, "name": "Rock_Ledge_Brick_Smooth"}, {"x": 5, "y": -3, "z": 26, "name": "Soil_Dirt"}, {"x": 5, "y": -2, "z": 26, "name": "Soil_Dirt"}, {"x": 5, "y": -1, "z": 26, "name": "Soil_Dirt"}, {"x": 5, "y": 0, "z": 26, "name": "Rock_Ledge_Brick_Smooth"}, {"x": 5, "y": -3, "z": 27, "name": "Soil_Dirt"}, {"x": 5, "y": -2, "z": 27, "name": "Soil_Dirt"}, {"x": 5, "y": -1, "z": 27, "name": "Soil_Dirt"}, {"x": 5, "y": 0, "z": 27, "name": "Rock_Ledge_Brick_Smooth"}, {"x": 5, "y": -3, "z": 28, "name": "Soil_Dirt"}, {"x": 5, "y": -2, "z": 28, "name": "Soil_Dirt"}, {"x": 5, "y": -1, "z": 28, "name": "Soil_Dirt"}, {"x": 5, "y": 0, "z": 28, "name": "Rock_Ledge_Cobble"}, {"x": 5, "y": -3, "z": 29, "name": "Soil_Dirt"}, {"x": 5, "y": -2, "z": 29, "name": "Soil_Dirt"}, {"x": 5, "y": -1, "z": 29, "name": "Soil_Dirt"}, {"x": 5, "y": 0, "z": 29, "name": "Rock_Ledge_Brick_Smooth"}, {"x": 5, "y": -3, "z": 30, "name": "Soil_Dirt"}, {"x": 5, "y": -2, "z": 30, "name": "Soil_Dirt"}, {"x": 5, "y": -1, "z": 30, "name": "Soil_Dirt"}, {"x": 5, "y": 0, "z": 30, "name": "Rock_Ledge_Brick_Smooth"}, {"x": 5, "y": -3, "z": 31, "name": "Soil_Dirt"}, {"x": 5, "y": -2, "z": 31, "name": "Soil_Dirt"}, {"x": 5, "y": -1, "z": 31, "name": "Soil_Dirt"}, {"x": 5, "y": 0, "z": 31, "name": "Rock_Ledge_Cobble"}, {"x": 6, "y": -3, "z": 0, "name": "Soil_Dirt"}, {"x": 6, "y": -2, "z": 0, "name": "Soil_Dirt"}, {"x": 6, "y": -1, "z": 0, "name": "Soil_Dirt"}, {"x": 6, "y": 0, "z": 0, "name": "Rock_Ledge_Brick_Smooth"}, {"x": 6, "y": -3, "z": 1, "name": "Soil_Dirt"}, {"x": 6, "y": -2, "z": 1, "name": "Soil_Dirt"}, {"x": 6, "y": -1, "z": 1, "name": "Soil_Dirt"}, {"x": 6, "y": 0, "z": 1, "name": "Rock_Ledge_Brick_Ornate"}, {"x": 6, "y": -3, "z": 2, "name": "Soil_Dirt"}, {"x": 6, "y": -2, "z": 2, "name": "Soil_Dirt"}, {"x": 6, "y": -1, "z": 2, "name": "Soil_Dirt"}, {"x": 6, "y": 0, "z": 2, "name": "Rock_Ledge_Brick_Ornate"}, {"x": 6, "y": -3, "z": 3, "name": "Soil_Dirt"}, {"x": 6, "y": -2, "z": 3, "name": "Soil_Dirt"}, {"x": 6, "y": -1, "z": 3, "name": "Soil_Dirt"}, {"x": 6, "y": 0, "z": 3, "name": "Rock_Ledge_Brick"}, {"x": 6, "y": -3, "z": 4, "name": "Soil_Dirt"}, {"x": 6, "y": -2, "z": 4, "name": "Soil_Dirt"}, {"x": 6, "y": -1, "z": 4, "name": "Soil_Dirt"}, {"x": 6, "y": 0, "z": 4, "name": "Rock_Ledge_Cobble"}, {"x": 6, "y": 1, "z": 4, "name": "Metal_Iron_Pipe_Long", "support": 15, "rotation": 1}, {"x": 6, "y": 2, "z": 4, "name": "Metal_Iron_Pipe_Long", "support": 15, "rotation": 1}, {"x": 6, "y": 3, "z": 4, "name": "Cloth_Modern_Blue_Roof", "rotation": 2}, {"x": 6, "y": -3, "z": 5, "name": "Soil_Dirt"}, {"x": 6, "y": -2, "z": 5, "name": "Soil_Dirt"}, {"x": 6, "y": -1, "z": 5, "name": "Soil_Dirt"}, {"x": 6, "y": 0, "z": 5, "name": "Rock_Ledge_Brick_Smooth"}, {"x": 6, "y": 1, "z": 5, "name": "Rock_Quartzite_Cobble_Wall", "rotation": 2}, {"x": 6, "y": 2, "z": 5, "name": "Rock_Quartzite_Cobble_Wall", "rotation": 2}, {"x": 6, "y": 3, "z": 5, "name": "Cloth_Modern_Blue_Roof"}, {"x": 6, "y": -3, "z": 6, "name": "Soil_Dirt"}, {"x": 6, "y": -2, "z": 6, "name": "Soil_Dirt"}, {"x": 6, "y": -1, "z": 6, "name": "Soil_Dirt"}, {"x": 6, "y": 0, "z": 6, "name": "Soil_Dirt"}, {"x": 6, "y": 1, "z": 6, "name": "Rock_Calcite_Brick_Decorative"}, {"x": 6, "y": 2, "z": 6, "name": "Rock_Lime_Brick_Smooth"}, {"x": 6, "y": 3, "z": 6, "name": "Rock_Lime_Brick_Smooth"}, {"x": 6, "y": 4, "z": 6, "name": "Rock_Lime_Brick_Smooth"}, {"x": 6, "y": 5, "z": 6, "name": "Rock_Calcite_Brick_Smooth_Half"}, {"x": 6, "y": -3, "z": 7, "name": "Soil_Dirt"}, {"x": 6, "y": -2, "z": 7, "name": "Soil_Dirt"}, {"x": 6, "y": -1, "z": 7, "name": "Soil_Dirt"}, {"x": 6, "y": 0, "z": 7, "name": "Rock_Slate_Brick_Smooth"}, {"x": 6, "y": 1, "z": 7, "name": "K2_Slot_Station_Wash"}, {"x": 6, "y": 4, "z": 7, "name": "Rock_Calcite_Brick_Smooth_Half", "rotation": 8}, {"x": 6, "y": -3, "z": 8, "name": "Soil_Dirt"}, {"x": 6, "y": -2, "z": 8, "name": "Soil_Dirt"}, {"x": 6, "y": -1, "z": 8, "name": "Soil_Dirt"}, {"x": 6, "y": 0, "z": 8, "name": "Rock_Chalk_Brick_Smooth"}, {"x": 6, "y": 1, "z": 8, "name": "K2_Slot_Station_Rack"}, {"x": 6, "y": 4, "z": 8, "name": "Rock_Calcite_Brick_Smooth_Half", "rotation": 8}, {"x": 6, "y": -3, "z": 9, "name": "Soil_Dirt"}, {"x": 6, "y": -2, "z": 9, "name": "Soil_Dirt"}, {"x": 6, "y": -1, "z": 9, "name": "Soil_Dirt"}, {"x": 6, "y": 0, "z": 9, "name": "Rock_Slate_Brick_Smooth"}, {"x": 6, "y": 1, "z": 9, "name": "K2_Slot_Station_Press"}, {"x": 6, "y": 4, "z": 9, "name": "Rock_Calcite_Brick_Smooth_Half", "rotation": 8}, {"x": 6, "y": -3, "z": 10, "name": "Soil_Dirt"}, {"x": 6, "y": -2, "z": 10, "name": "Soil_Dirt"}, {"x": 6, "y": -1, "z": 10, "name": "Soil_Dirt"}, {"x": 6, "y": 0, "z": 10, "name": "Rock_Chalk_Brick_Smooth"}, {"x": 6, "y": 1, "z": 10, "name": "K2_Slot_Station_Heat"}, {"x": 6, "y": 4, "z": 10, "name": "Rock_Calcite_Brick_Smooth_Half", "rotation": 8}, {"x": 6, "y": -3, "z": 11, "name": "Soil_Dirt"}, {"x": 6, "y": -2, "z": 11, "name": "Soil_Dirt"}, {"x": 6, "y": -1, "z": 11, "name": "Soil_Dirt"}, {"x": 6, "y": 0, "z": 11, "name": "Rock_Slate_Brick_Smooth"}, {"x": 6, "y": 4, "z": 11, "name": "Rock_Calcite_Brick_Smooth_Half", "rotation": 8}, {"x": 6, "y": -3, "z": 12, "name": "Soil_Dirt"}, {"x": 6, "y": -2, "z": 12, "name": "Soil_Dirt"}, {"x": 6, "y": -1, "z": 12, "name": "Soil_Dirt"}, {"x": 6, "y": 0, "z": 12, "name": "Rock_Chalk_Brick_Smooth"}, {"x": 6, "y": 4, "z": 12, "name": "Rock_Calcite_Brick_Smooth_Half", "rotation": 8}, {"x": 6, "y": -3, "z": 13, "name": "Soil_Dirt"}, {"x": 6, "y": -2, "z": 13, "name": "Soil_Dirt"}, {"x": 6, "y": -1, "z": 13, "name": "Soil_Dirt"}, {"x": 6, "y": 0, "z": 13, "name": "Rock_Slate_Brick_Smooth"}, {"x": 6, "y": 1, "z": 13, "name": "K2_Slot_Station_Bin"}, {"x": 6, "y": 4, "z": 13, "name": "Rock_Calcite_Brick_Smooth_Half", "rotation": 8}, {"x": 6, "y": -3, "z": 14, "name": "Soil_Dirt"}, {"x": 6, "y": -2, "z": 14, "name": "Soil_Dirt"}, {"x": 6, "y": -1, "z": 14, "name": "Soil_Dirt"}, {"x": 6, "y": 0, "z": 14, "name": "Soil_Dirt"}, {"x": 6, "y": 1, "z": 14, "name": "Rock_Calcite_Brick_Decorative"}, {"x": 6, "y": 2, "z": 14, "name": "Rock_Lime_Brick_Smooth"}, {"x": 6, "y": 3, "z": 14, "name": "Rock_Lime_Brick_Smooth"}, {"x": 6, "y": 4, "z": 14, "name": "Rock_Lime_Brick_Smooth"}, {"x": 6, "y": 5, "z": 14, "name": "Rock_Calcite_Brick_Smooth_Half"}, {"x": 6, "y": -3, "z": 15, "name": "Soil_Dirt"}, {"x": 6, "y": -2, "z": 15, "name": "Soil_Dirt"}, {"x": 6, "y": -1, "z": 15, "name": "Soil_Dirt"}, {"x": 6, "y": 0, "z": 15, "name": "Rock_Ledge_Brick_Decorative"}, {"x": 6, "y": -3, "z": 16, "name": "Soil_Dirt"}, {"x": 6, "y": -2, "z": 16, "name": "Soil_Dirt"}, {"x": 6, "y": -1, "z": 16, "name": "Soil_Dirt"}, {"x": 6, "y": 0, "z": 16, "name": "Rock_Ledge_Cobble"}, {"x": 6, "y": -3, "z": 17, "name": "Soil_Dirt"}, {"x": 6, "y": -2, "z": 17, "name": "Soil_Dirt"}, {"x": 6, "y": -1, "z": 17, "name": "Soil_Dirt"}, {"x": 6, "y": 0, "z": 17, "name": "Rock_Ledge_Brick_Decorative"}, {"x": 6, "y": -3, "z": 18, "name": "Soil_Dirt"}, {"x": 6, "y": -2, "z": 18, "name": "Soil_Dirt"}, {"x": 6, "y": -1, "z": 18, "name": "Soil_Dirt"}, {"x": 6, "y": 0, "z": 18, "name": "Rock_Ledge_Cobble"}, {"x": 6, "y": -3, "z": 19, "name": "Soil_Dirt"}, {"x": 6, "y": -2, "z": 19, "name": "Soil_Dirt"}, {"x": 6, "y": -1, "z": 19, "name": "Soil_Dirt"}, {"x": 6, "y": 0, "z": 19, "name": "Rock_Ledge_Cobble"}, {"x": 6, "y": -3, "z": 20, "name": "Soil_Dirt"}, {"x": 6, "y": -2, "z": 20, "name": "Soil_Dirt"}, {"x": 6, "y": -1, "z": 20, "name": "Soil_Dirt"}, {"x": 6, "y": 0, "z": 20, "name": "Rock_Ledge_Brick_Smooth"}, {"x": 6, "y": -3, "z": 21, "name": "Soil_Dirt"}, {"x": 6, "y": -2, "z": 21, "name": "Soil_Dirt"}, {"x": 6, "y": -1, "z": 21, "name": "Soil_Dirt"}, {"x": 6, "y": 0, "z": 21, "name": "Rock_Ledge_Brick"}, {"x": 6, "y": -3, "z": 22, "name": "Soil_Dirt"}, {"x": 6, "y": -2, "z": 22, "name": "Soil_Dirt"}, {"x": 6, "y": -1, "z": 22, "name": "Soil_Dirt"}, {"x": 6, "y": 0, "z": 22, "name": "Rock_Ledge_Brick_Decorative"}, {"x": 6, "y": -3, "z": 23, "name": "Soil_Dirt"}, {"x": 6, "y": -2, "z": 23, "name": "Soil_Dirt"}, {"x": 6, "y": -1, "z": 23, "name": "Soil_Dirt"}, {"x": 6, "y": 0, "z": 23, "name": "Rock_Ledge_Brick_Smooth"}, {"x": 6, "y": 1, "z": 23, "name": "Rock_Quartzite_Brick_Smooth"}, {"x": 6, "y": 2, "z": 23, "name": "Rock_Quartzite_Brick_Smooth"}, {"x": 6, "y": 3, "z": 23, "name": "Rock_Quartzite_Brick_Smooth"}, {"x": 6, "y": 4, "z": 23, "name": "Rock_Quartzite_Brick_Smooth"}, {"x": 6, "y": 5, "z": 23, "name": "Rock_Quartzite_Brick_Smooth"}, {"x": 6, "y": 6, "z": 23, "name": "Rock_Quartzite_Brick_Smooth"}, {"x": 6, "y": -3, "z": 24, "name": "Soil_Dirt"}, {"x": 6, "y": -2, "z": 24, "name": "Soil_Dirt"}, {"x": 6, "y": -1, "z": 24, "name": "Soil_Dirt"}, {"x": 6, "y": 0, "z": 24, "name": "Rock_Ledge_Brick_Smooth"}, {"x": 6, "y": -3, "z": 25, "name": "Soil_Dirt"}, {"x": 6, "y": -2, "z": 25, "name": "Soil_Dirt"}, {"x": 6, "y": -1, "z": 25, "name": "Soil_Dirt"}, {"x": 6, "y": 0, "z": 25, "name": "Rock_Ledge_Brick_Smooth"}, {"x": 6, "y": -3, "z": 26, "name": "Soil_Dirt"}, {"x": 6, "y": -2, "z": 26, "name": "Soil_Dirt"}, {"x": 6, "y": -1, "z": 26, "name": "Soil_Dirt"}, {"x": 6, "y": 0, "z": 26, "name": "Rock_Ledge_Brick_Decorative"}, {"x": 6, "y": -3, "z": 27, "name": "Soil_Dirt"}, {"x": 6, "y": -2, "z": 27, "name": "Soil_Dirt"}, {"x": 6, "y": -1, "z": 27, "name": "Soil_Dirt"}, {"x": 6, "y": 0, "z": 27, "name": "Rock_Ledge_Brick"}, {"x": 6, "y": -3, "z": 28, "name": "Soil_Dirt"}, {"x": 6, "y": -2, "z": 28, "name": "Soil_Dirt"}, {"x": 6, "y": -1, "z": 28, "name": "Soil_Dirt"}, {"x": 6, "y": 0, "z": 28, "name": "Rock_Ledge_Brick_Smooth"}, {"x": 6, "y": -3, "z": 29, "name": "Soil_Dirt"}, {"x": 6, "y": -2, "z": 29, "name": "Soil_Dirt"}, {"x": 6, "y": -1, "z": 29, "name": "Soil_Dirt"}, {"x": 6, "y": 0, "z": 29, "name": "Rock_Ledge_Brick"}, {"x": 6, "y": -3, "z": 30, "name": "Soil_Dirt"}, {"x": 6, "y": -2, "z": 30, "name": "Soil_Dirt"}, {"x": 6, "y": -1, "z": 30, "name": "Soil_Dirt"}, {"x": 6, "y": 0, "z": 30, "name": "Rock_Ledge_Cobble"}, {"x": 6, "y": -3, "z": 31, "name": "Soil_Dirt"}, {"x": 6, "y": -2, "z": 31, "name": "Soil_Dirt"}, {"x": 6, "y": -1, "z": 31, "name": "Soil_Dirt"}, {"x": 6, "y": 0, "z": 31, "name": "Rock_Ledge_Brick_Decorative"}, {"x": 7, "y": -3, "z": 0, "name": "Soil_Dirt"}, {"x": 7, "y": -2, "z": 0, "name": "Soil_Dirt"}, {"x": 7, "y": -1, "z": 0, "name": "Soil_Dirt"}, {"x": 7, "y": 0, "z": 0, "name": "Rock_Ledge_Cobble"}, {"x": 7, "y": -3, "z": 1, "name": "Soil_Dirt"}, {"x": 7, "y": -2, "z": 1, "name": "Soil_Dirt"}, {"x": 7, "y": -1, "z": 1, "name": "Soil_Dirt"}, {"x": 7, "y": 0, "z": 1, "name": "Rock_Ledge_Brick_Smooth"}, {"x": 7, "y": -3, "z": 2, "name": "Soil_Dirt"}, {"x": 7, "y": -2, "z": 2, "name": "Soil_Dirt"}, {"x": 7, "y": -1, "z": 2, "name": "Soil_Dirt"}, {"x": 7, "y": 0, "z": 2, "name": "Rock_Ledge_Brick_Smooth"}, {"x": 7, "y": -3, "z": 3, "name": "Soil_Dirt"}, {"x": 7, "y": -2, "z": 3, "name": "Soil_Dirt"}, {"x": 7, "y": -1, "z": 3, "name": "Soil_Dirt"}, {"x": 7, "y": 0, "z": 3, "name": "Rock_Ledge_Cobble"}, {"x": 7, "y": -3, "z": 4, "name": "Soil_Dirt"}, {"x": 7, "y": -2, "z": 4, "name": "Soil_Dirt"}, {"x": 7, "y": -1, "z": 4, "name": "Soil_Dirt"}, {"x": 7, "y": 0, "z": 4, "name": "Rock_Ledge_Brick"}, {"x": 7, "y": 1, "z": 4, "name": "Rock_Quartzite_Cobble_Wall", "rotation": 1}, {"x": 7, "y": 2, "z": 4, "name": "Rock_Quartzite_Cobble_Wall", "rotation": 1}, {"x": 7, "y": 3, "z": 4, "name": "Cloth_Modern_Blue_Roof", "rotation": 2}, {"x": 7, "y": -3, "z": 5, "name": "Soil_Dirt"}, {"x": 7, "y": -2, "z": 5, "name": "Soil_Dirt"}, {"x": 7, "y": -1, "z": 5, "name": "Soil_Dirt"}, {"x": 7, "y": 0, "z": 5, "name": "Rock_Ledge_Brick_Smooth"}, {"x": 7, "y": 1, "z": 5, "name": "*Rock_Quartzite_Cobble_Wall_State_Definitions_Corner", "rotation": 3}, {"x": 7, "y": 2, "z": 5, "name": "*Rock_Quartzite_Cobble_Wall_State_Definitions_Corner", "rotation": 3}, {"x": 7, "y": 3, "z": 5, "name": "Cloth_Modern_Blue_Roof"}, {"x": 7, "y": -3, "z": 6, "name": "Soil_Dirt"}, {"x": 7, "y": -2, "z": 6, "name": "Soil_Dirt"}, {"x": 7, "y": -1, "z": 6, "name": "Soil_Dirt"}, {"x": 7, "y": 0, "z": 6, "name": "Soil_Dirt"}, {"x": 7, "y": 1, "z": 6, "name": "Rock_Calcite_Brick_Decorative"}, {"x": 7, "y": 2, "z": 6, "name": "Rock_Lime_Brick_Smooth"}, {"x": 7, "y": 3, "z": 6, "name": "Rock_Lime_Brick_Smooth"}, {"x": 7, "y": 4, "z": 6, "name": "Rock_Lime_Brick_Smooth"}, {"x": 7, "y": 5, "z": 6, "name": "Rock_Calcite_Brick_Smooth_Half"}, {"x": 7, "y": -3, "z": 7, "name": "Soil_Dirt"}, {"x": 7, "y": -2, "z": 7, "name": "Soil_Dirt"}, {"x": 7, "y": -1, "z": 7, "name": "Soil_Dirt"}, {"x": 7, "y": 0, "z": 7, "name": "Rock_Chalk_Brick_Smooth"}, {"x": 7, "y": 4, "z": 7, "name": "Rock_Calcite_Brick_Smooth_Half", "rotation": 8}, {"x": 7, "y": -3, "z": 8, "name": "Soil_Dirt"}, {"x": 7, "y": -2, "z": 8, "name": "Soil_Dirt"}, {"x": 7, "y": -1, "z": 8, "name": "Soil_Dirt"}, {"x": 7, "y": 0, "z": 8, "name": "Rock_Slate_Brick_Smooth"}, {"x": 7, "y": 5, "z": 8, "name": "Build_Lightsource_White", "rotation": 5}, {"x": 7, "y": -3, "z": 9, "name": "Soil_Dirt"}, {"x": 7, "y": -2, "z": 9, "name": "Soil_Dirt"}, {"x": 7, "y": -1, "z": 9, "name": "Soil_Dirt"}, {"x": 7, "y": 0, "z": 9, "name": "Rock_Chalk_Brick_Smooth"}, {"x": 7, "y": 4, "z": 9, "name": "Rock_Calcite_Brick_Smooth_Half", "rotation": 8}, {"x": 7, "y": -3, "z": 10, "name": "Soil_Dirt"}, {"x": 7, "y": -2, "z": 10, "name": "Soil_Dirt"}, {"x": 7, "y": -1, "z": 10, "name": "Soil_Dirt"}, {"x": 7, "y": 0, "z": 10, "name": "Rock_Slate_Brick_Smooth"}, {"x": 7, "y": 4, "z": 10, "name": "Rock_Calcite_Brick_Smooth_Half", "rotation": 8}, {"x": 7, "y": -3, "z": 11, "name": "Soil_Dirt"}, {"x": 7, "y": -2, "z": 11, "name": "Soil_Dirt"}, {"x": 7, "y": -1, "z": 11, "name": "Soil_Dirt"}, {"x": 7, "y": 0, "z": 11, "name": "Rock_Chalk_Brick_Smooth"}, {"x": 7, "y": 4, "z": 11, "name": "Rock_Calcite_Brick_Smooth_Half", "rotation": 8}, {"x": 7, "y": -3, "z": 12, "name": "Soil_Dirt"}, {"x": 7, "y": -2, "z": 12, "name": "Soil_Dirt"}, {"x": 7, "y": -1, "z": 12, "name": "Soil_Dirt"}, {"x": 7, "y": 0, "z": 12, "name": "Rock_Slate_Brick_Smooth"}, {"x": 7, "y": 5, "z": 12, "name": "Build_Lightsource_White", "rotation": 5}, {"x": 7, "y": -3, "z": 13, "name": "Soil_Dirt"}, {"x": 7, "y": -2, "z": 13, "name": "Soil_Dirt"}, {"x": 7, "y": -1, "z": 13, "name": "Soil_Dirt"}, {"x": 7, "y": 0, "z": 13, "name": "Rock_Chalk_Brick_Smooth"}, {"x": 7, "y": 4, "z": 13, "name": "Rock_Calcite_Brick_Smooth_Half", "rotation": 8}, {"x": 7, "y": -3, "z": 14, "name": "Soil_Dirt"}, {"x": 7, "y": -2, "z": 14, "name": "Soil_Dirt"}, {"x": 7, "y": -1, "z": 14, "name": "Soil_Dirt"}, {"x": 7, "y": 0, "z": 14, "name": "Soil_Dirt"}, {"x": 7, "y": 1, "z": 14, "name": "Rock_Calcite_Brick_Decorative"}, {"x": 7, "y": 2, "z": 14, "name": "Furniture_Temple_Dark_Window"}, {"x": 7, "y": 3, "z": 14, "name": "Furniture_Temple_Dark_Window"}, {"x": 7, "y": 4, "z": 14, "name": "Rock_Lime_Brick_Smooth"}, {"x": 7, "y": 5, "z": 14, "name": "Rock_Calcite_Brick_Smooth_Half"}, {"x": 7, "y": -3, "z": 15, "name": "Soil_Dirt"}, {"x": 7, "y": -2, "z": 15, "name": "Soil_Dirt"}, {"x": 7, "y": -1, "z": 15, "name": "Soil_Dirt"}, {"x": 7, "y": 0, "z": 15, "name": "Rock_Ledge_Brick_Decorative"}, {"x": 7, "y": -3, "z": 16, "name": "Soil_Dirt"}, {"x": 7, "y": -2, "z": 16, "name": "Soil_Dirt"}, {"x": 7, "y": -1, "z": 16, "name": "Soil_Dirt"}, {"x": 7, "y": 0, "z": 16, "name": "Rock_Ledge_Brick_Decorative"}, {"x": 7, "y": -3, "z": 17, "name": "Soil_Dirt"}, {"x": 7, "y": -2, "z": 17, "name": "Soil_Dirt"}, {"x": 7, "y": -1, "z": 17, "name": "Soil_Dirt"}, {"x": 7, "y": 0, "z": 17, "name": "Rock_Ledge_Brick"}, {"x": 7, "y": -3, "z": 18, "name": "Soil_Dirt"}, {"x": 7, "y": -2, "z": 18, "name": "Soil_Dirt"}, {"x": 7, "y": -1, "z": 18, "name": "Soil_Dirt"}, {"x": 7, "y": 0, "z": 18, "name": "Rock_Ledge_Brick_Decorative"}, {"x": 7, "y": -3, "z": 19, "name": "Soil_Dirt"}, {"x": 7, "y": -2, "z": 19, "name": "Soil_Dirt"}, {"x": 7, "y": -1, "z": 19, "name": "Soil_Dirt"}, {"x": 7, "y": 0, "z": 19, "name": "Rock_Ledge_Brick"}, {"x": 7, "y": -3, "z": 20, "name": "Soil_Dirt"}, {"x": 7, "y": -2, "z": 20, "name": "Soil_Dirt"}, {"x": 7, "y": -1, "z": 20, "name": "Soil_Dirt"}, {"x": 7, "y": 0, "z": 20, "name": "Rock_Ledge_Brick_Smooth"}, {"x": 7, "y": -3, "z": 21, "name": "Soil_Dirt"}, {"x": 7, "y": -2, "z": 21, "name": "Soil_Dirt"}, {"x": 7, "y": -1, "z": 21, "name": "Soil_Dirt"}, {"x": 7, "y": 0, "z": 21, "name": "Rock_Ledge_Brick_Decorative"}, {"x": 7, "y": -3, "z": 22, "name": "Soil_Dirt"}, {"x": 7, "y": -2, "z": 22, "name": "Soil_Dirt"}, {"x": 7, "y": -1, "z": 22, "name": "Soil_Dirt"}, {"x": 7, "y": 0, "z": 22, "name": "Rock_Ledge_Brick_Decorative"}, {"x": 7, "y": -3, "z": 23, "name": "Soil_Dirt"}, {"x": 7, "y": -2, "z": 23, "name": "Soil_Dirt"}, {"x": 7, "y": -1, "z": 23, "name": "Soil_Dirt"}, {"x": 7, "y": 0, "z": 23, "name": "Rock_Ledge_Brick_Smooth"}, {"x": 7, "y": 1, "z": 23, "name": "Rock_Quartzite_Brick_Smooth"}, {"x": 7, "y": 2, "z": 23, "name": "Rock_Quartzite_Brick_Smooth"}, {"x": 7, "y": 3, "z": 23, "name": "Rock_Quartzite_Brick_Smooth"}, {"x": 7, "y": 4, "z": 23, "name": "Rock_Quartzite_Brick_Smooth"}, {"x": 7, "y": 5, "z": 23, "name": "Rock_Quartzite_Brick_Smooth"}, {"x": 7, "y": 6, "z": 23, "name": "Rock_Quartzite_Brick_Smooth"}, {"x": 7, "y": -3, "z": 24, "name": "Soil_Dirt"}, {"x": 7, "y": -2, "z": 24, "name": "Soil_Dirt"}, {"x": 7, "y": -1, "z": 24, "name": "Soil_Dirt"}, {"x": 7, "y": 0, "z": 24, "name": "Rock_Ledge_Brick_Decorative"}, {"x": 7, "y": -3, "z": 25, "name": "Soil_Dirt"}, {"x": 7, "y": -2, "z": 25, "name": "Soil_Dirt"}, {"x": 7, "y": -1, "z": 25, "name": "Soil_Dirt"}, {"x": 7, "y": 0, "z": 25, "name": "Rock_Ledge_Brick_Ornate"}, {"x": 7, "y": -3, "z": 26, "name": "Soil_Dirt"}, {"x": 7, "y": -2, "z": 26, "name": "Soil_Dirt"}, {"x": 7, "y": -1, "z": 26, "name": "Soil_Dirt"}, {"x": 7, "y": 0, "z": 26, "name": "Rock_Ledge_Cobble"}, {"x": 7, "y": -3, "z": 27, "name": "Soil_Dirt"}, {"x": 7, "y": -2, "z": 27, "name": "Soil_Dirt"}, {"x": 7, "y": -1, "z": 27, "name": "Soil_Dirt"}, {"x": 7, "y": 0, "z": 27, "name": "Rock_Ledge_Brick"}, {"x": 7, "y": -3, "z": 28, "name": "Soil_Dirt"}, {"x": 7, "y": -2, "z": 28, "name": "Soil_Dirt"}, {"x": 7, "y": -1, "z": 28, "name": "Soil_Dirt"}, {"x": 7, "y": 0, "z": 28, "name": "Rock_Ledge_Brick_Smooth"}, {"x": 7, "y": -3, "z": 29, "name": "Soil_Dirt"}, {"x": 7, "y": -2, "z": 29, "name": "Soil_Dirt"}, {"x": 7, "y": -1, "z": 29, "name": "Soil_Dirt"}, {"x": 7, "y": 0, "z": 29, "name": "Rock_Ledge_Brick_Smooth"}, {"x": 7, "y": -3, "z": 30, "name": "Soil_Dirt"}, {"x": 7, "y": -2, "z": 30, "name": "Soil_Dirt"}, {"x": 7, "y": -1, "z": 30, "name": "Soil_Dirt"}, {"x": 7, "y": 0, "z": 30, "name": "Rock_Ledge_Brick"}, {"x": 7, "y": -3, "z": 31, "name": "Soil_Dirt"}, {"x": 7, "y": -2, "z": 31, "name": "Soil_Dirt"}, {"x": 7, "y": -1, "z": 31, "name": "Soil_Dirt"}, {"x": 7, "y": 0, "z": 31, "name": "Rock_Ledge_Brick_Smooth"}, {"x": 8, "y": -3, "z": 0, "name": "Soil_Dirt"}, {"x": 8, "y": -2, "z": 0, "name": "Soil_Dirt"}, {"x": 8, "y": -1, "z": 0, "name": "Soil_Dirt"}, {"x": 8, "y": 0, "z": 0, "name": "Rock_Ledge_Brick_Smooth"}, {"x": 8, "y": -3, "z": 1, "name": "Soil_Dirt"}, {"x": 8, "y": -2, "z": 1, "name": "Soil_Dirt"}, {"x": 8, "y": -1, "z": 1, "name": "Soil_Dirt"}, {"x": 8, "y": 0, "z": 1, "name": "Rock_Ledge_Brick"}, {"x": 8, "y": -3, "z": 2, "name": "Soil_Dirt"}, {"x": 8, "y": -2, "z": 2, "name": "Soil_Dirt"}, {"x": 8, "y": -1, "z": 2, "name": "Soil_Dirt"}, {"x": 8, "y": 0, "z": 2, "name": "Rock_Ledge_Cobble"}, {"x": 8, "y": -3, "z": 3, "name": "Soil_Dirt"}, {"x": 8, "y": -2, "z": 3, "name": "Soil_Dirt"}, {"x": 8, "y": -1, "z": 3, "name": "Soil_Dirt"}, {"x": 8, "y": 0, "z": 3, "name": "Rock_Ledge_Brick_Decorative"}, {"x": 8, "y": -3, "z": 4, "name": "Soil_Dirt"}, {"x": 8, "y": -2, "z": 4, "name": "Soil_Dirt"}, {"x": 8, "y": -1, "z": 4, "name": "Soil_Dirt"}, {"x": 8, "y": 0, "z": 4, "name": "Rock_Ledge_Brick_Ornate"}, {"x": 8, "y": -3, "z": 5, "name": "Soil_Dirt"}, {"x": 8, "y": -2, "z": 5, "name": "Soil_Dirt"}, {"x": 8, "y": -1, "z": 5, "name": "Soil_Dirt"}, {"x": 8, "y": 0, "z": 5, "name": "Rock_Ledge_Brick_Decorative"}, {"x": 8, "y": -3, "z": 6, "name": "Soil_Dirt"}, {"x": 8, "y": -2, "z": 6, "name": "Soil_Dirt"}, {"x": 8, "y": -1, "z": 6, "name": "Soil_Dirt"}, {"x": 8, "y": 0, "z": 6, "name": "Soil_Dirt"}, {"x": 8, "y": 1, "z": 6, "name": "Rock_Calcite_Brick_Decorative"}, {"x": 8, "y": 2, "z": 6, "name": "Rock_Lime_Brick_Smooth"}, {"x": 8, "y": 3, "z": 6, "name": "Rock_Lime_Brick_Smooth"}, {"x": 8, "y": 4, "z": 6, "name": "Rock_Lime_Brick_Smooth"}, {"x": 8, "y": 5, "z": 6, "name": "Rock_Calcite_Brick_Smooth_Half"}, {"x": 8, "y": -3, "z": 7, "name": "Soil_Dirt"}, {"x": 8, "y": -2, "z": 7, "name": "Soil_Dirt"}, {"x": 8, "y": -1, "z": 7, "name": "Soil_Dirt"}, {"x": 8, "y": 0, "z": 7, "name": "Rock_Slate_Brick_Smooth"}, {"x": 8, "y": 4, "z": 7, "name": "Rock_Calcite_Brick_Smooth_Half", "rotation": 8}, {"x": 8, "y": -3, "z": 8, "name": "Soil_Dirt"}, {"x": 8, "y": -2, "z": 8, "name": "Soil_Dirt"}, {"x": 8, "y": -1, "z": 8, "name": "Soil_Dirt"}, {"x": 8, "y": 0, "z": 8, "name": "Rock_Chalk_Brick_Smooth"}, {"x": 8, "y": 5, "z": 8, "name": "Build_Lightsource_White", "rotation": 5}, {"x": 8, "y": -3, "z": 9, "name": "Soil_Dirt"}, {"x": 8, "y": -2, "z": 9, "name": "Soil_Dirt"}, {"x": 8, "y": -1, "z": 9, "name": "Soil_Dirt"}, {"x": 8, "y": 0, "z": 9, "name": "Rock_Slate_Brick_Smooth"}, {"x": 8, "y": 4, "z": 9, "name": "Rock_Calcite_Brick_Smooth_Half", "rotation": 8}, {"x": 8, "y": -3, "z": 10, "name": "Soil_Dirt"}, {"x": 8, "y": -2, "z": 10, "name": "Soil_Dirt"}, {"x": 8, "y": -1, "z": 10, "name": "Soil_Dirt"}, {"x": 8, "y": 0, "z": 10, "name": "Rock_Chalk_Brick_Smooth"}, {"x": 8, "y": 4, "z": 10, "name": "Rock_Calcite_Brick_Smooth_Half", "rotation": 8}, {"x": 8, "y": -3, "z": 11, "name": "Soil_Dirt"}, {"x": 8, "y": -2, "z": 11, "name": "Soil_Dirt"}, {"x": 8, "y": -1, "z": 11, "name": "Soil_Dirt"}, {"x": 8, "y": 0, "z": 11, "name": "Rock_Slate_Brick_Smooth"}, {"x": 8, "y": 4, "z": 11, "name": "Rock_Calcite_Brick_Smooth_Half", "rotation": 8}, {"x": 8, "y": -3, "z": 12, "name": "Soil_Dirt"}, {"x": 8, "y": -2, "z": 12, "name": "Soil_Dirt"}, {"x": 8, "y": -1, "z": 12, "name": "Soil_Dirt"}, {"x": 8, "y": 0, "z": 12, "name": "Rock_Chalk_Brick_Smooth"}, {"x": 8, "y": 5, "z": 12, "name": "Build_Lightsource_White", "rotation": 5}, {"x": 8, "y": -3, "z": 13, "name": "Soil_Dirt"}, {"x": 8, "y": -2, "z": 13, "name": "Soil_Dirt"}, {"x": 8, "y": -1, "z": 13, "name": "Soil_Dirt"}, {"x": 8, "y": 0, "z": 13, "name": "Rock_Slate_Brick_Smooth"}, {"x": 8, "y": 4, "z": 13, "name": "Rock_Calcite_Brick_Smooth_Half", "rotation": 8}, {"x": 8, "y": -3, "z": 14, "name": "Soil_Dirt"}, {"x": 8, "y": -2, "z": 14, "name": "Soil_Dirt"}, {"x": 8, "y": -1, "z": 14, "name": "Soil_Dirt"}, {"x": 8, "y": 0, "z": 14, "name": "Soil_Dirt"}, {"x": 8, "y": 1, "z": 14, "name": "Rock_Calcite_Brick_Decorative"}, {"x": 8, "y": 2, "z": 14, "name": "Furniture_Temple_Dark_Window"}, {"x": 8, "y": 3, "z": 14, "name": "Furniture_Temple_Dark_Window"}, {"x": 8, "y": 4, "z": 14, "name": "Rock_Lime_Brick_Smooth"}, {"x": 8, "y": 5, "z": 14, "name": "Rock_Calcite_Brick_Smooth_Half"}, {"x": 8, "y": -3, "z": 15, "name": "Soil_Dirt"}, {"x": 8, "y": -2, "z": 15, "name": "Soil_Dirt"}, {"x": 8, "y": -1, "z": 15, "name": "Soil_Dirt"}, {"x": 8, "y": 0, "z": 15, "name": "Rock_Ledge_Cobble"}, {"x": 8, "y": -3, "z": 16, "name": "Soil_Dirt"}, {"x": 8, "y": -2, "z": 16, "name": "Soil_Dirt"}, {"x": 8, "y": -1, "z": 16, "name": "Soil_Dirt"}, {"x": 8, "y": 0, "z": 16, "name": "Rock_Ledge_Brick_Smooth"}, {"x": 8, "y": -3, "z": 17, "name": "Soil_Dirt"}, {"x": 8, "y": -2, "z": 17, "name": "Soil_Dirt"}, {"x": 8, "y": -1, "z": 17, "name": "Soil_Dirt"}, {"x": 8, "y": 0, "z": 17, "name": "Rock_Ledge_Brick_Smooth"}, {"x": 8, "y": -3, "z": 18, "name": "Soil_Dirt"}, {"x": 8, "y": -2, "z": 18, "name": "Soil_Dirt"}, {"x": 8, "y": -1, "z": 18, "name": "Soil_Dirt"}, {"x": 8, "y": 0, "z": 18, "name": "Rock_Ledge_Brick"}, {"x": 8, "y": -3, "z": 19, "name": "Soil_Dirt"}, {"x": 8, "y": -2, "z": 19, "name": "Soil_Dirt"}, {"x": 8, "y": -1, "z": 19, "name": "Soil_Dirt"}, {"x": 8, "y": 0, "z": 19, "name": "Rock_Ledge_Brick_Decorative"}, {"x": 8, "y": -3, "z": 20, "name": "Soil_Dirt"}, {"x": 8, "y": -2, "z": 20, "name": "Soil_Dirt"}, {"x": 8, "y": -1, "z": 20, "name": "Soil_Dirt"}, {"x": 8, "y": 0, "z": 20, "name": "Rock_Ledge_Brick"}, {"x": 8, "y": -3, "z": 21, "name": "Soil_Dirt"}, {"x": 8, "y": -2, "z": 21, "name": "Soil_Dirt"}, {"x": 8, "y": -1, "z": 21, "name": "Soil_Dirt"}, {"x": 8, "y": 0, "z": 21, "name": "Rock_Ledge_Brick_Smooth"}, {"x": 8, "y": -3, "z": 22, "name": "Soil_Dirt"}, {"x": 8, "y": -2, "z": 22, "name": "Soil_Dirt"}, {"x": 8, "y": -1, "z": 22, "name": "Soil_Dirt"}, {"x": 8, "y": 0, "z": 22, "name": "Rock_Ledge_Brick_Ornate"}, {"x": 8, "y": -3, "z": 23, "name": "Soil_Dirt"}, {"x": 8, "y": -2, "z": 23, "name": "Soil_Dirt"}, {"x": 8, "y": -1, "z": 23, "name": "Soil_Dirt"}, {"x": 8, "y": 0, "z": 23, "name": "Rock_Ledge_Brick_Smooth"}, {"x": 8, "y": 1, "z": 23, "name": "Rock_Quartzite_Brick_Smooth"}, {"x": 8, "y": 2, "z": 23, "name": "Rock_Quartzite_Brick_Smooth"}, {"x": 8, "y": 3, "z": 23, "name": "Rock_Quartzite_Brick_Smooth"}, {"x": 8, "y": 4, "z": 23, "name": "Rock_Quartzite_Brick_Smooth"}, {"x": 8, "y": 5, "z": 23, "name": "Rock_Quartzite_Brick_Smooth"}, {"x": 8, "y": 6, "z": 23, "name": "Rock_Quartzite_Brick_Smooth"}, {"x": 8, "y": -3, "z": 24, "name": "Soil_Dirt"}, {"x": 8, "y": -2, "z": 24, "name": "Soil_Dirt"}, {"x": 8, "y": -1, "z": 24, "name": "Soil_Dirt"}, {"x": 8, "y": 0, "z": 24, "name": "Rock_Ledge_Brick_Decorative"}, {"x": 8, "y": -3, "z": 25, "name": "Soil_Dirt"}, {"x": 8, "y": -2, "z": 25, "name": "Soil_Dirt"}, {"x": 8, "y": -1, "z": 25, "name": "Soil_Dirt"}, {"x": 8, "y": 0, "z": 25, "name": "Rock_Ledge_Brick_Smooth"}, {"x": 8, "y": -3, "z": 26, "name": "Soil_Dirt"}, {"x": 8, "y": -2, "z": 26, "name": "Soil_Dirt"}, {"x": 8, "y": -1, "z": 26, "name": "Soil_Dirt"}, {"x": 8, "y": 0, "z": 26, "name": "Rock_Ledge_Brick_Smooth"}, {"x": 8, "y": -3, "z": 27, "name": "Soil_Dirt"}, {"x": 8, "y": -2, "z": 27, "name": "Soil_Dirt"}, {"x": 8, "y": -1, "z": 27, "name": "Soil_Dirt"}, {"x": 8, "y": 0, "z": 27, "name": "Rock_Ledge_Brick_Smooth"}, {"x": 8, "y": -3, "z": 28, "name": "Soil_Dirt"}, {"x": 8, "y": -2, "z": 28, "name": "Soil_Dirt"}, {"x": 8, "y": -1, "z": 28, "name": "Soil_Dirt"}, {"x": 8, "y": 0, "z": 28, "name": "Rock_Ledge_Cobble"}, {"x": 8, "y": -3, "z": 29, "name": "Soil_Dirt"}, {"x": 8, "y": -2, "z": 29, "name": "Soil_Dirt"}, {"x": 8, "y": -1, "z": 29, "name": "Soil_Dirt"}, {"x": 8, "y": 0, "z": 29, "name": "Rock_Ledge_Brick_Decorative"}, {"x": 8, "y": -3, "z": 30, "name": "Soil_Dirt"}, {"x": 8, "y": -2, "z": 30, "name": "Soil_Dirt"}, {"x": 8, "y": -1, "z": 30, "name": "Soil_Dirt"}, {"x": 8, "y": 0, "z": 30, "name": "Rock_Ledge_Brick_Decorative"}, {"x": 8, "y": -3, "z": 31, "name": "Soil_Dirt"}, {"x": 8, "y": -2, "z": 31, "name": "Soil_Dirt"}, {"x": 8, "y": -1, "z": 31, "name": "Soil_Dirt"}, {"x": 8, "y": 0, "z": 31, "name": "Rock_Ledge_Cobble"}, {"x": 9, "y": -3, "z": 0, "name": "Soil_Dirt"}, {"x": 9, "y": -2, "z": 0, "name": "Soil_Dirt"}, {"x": 9, "y": -1, "z": 0, "name": "Soil_Dirt"}, {"x": 9, "y": 0, "z": 0, "name": "Rock_Ledge_Cobble"}, {"x": 9, "y": -3, "z": 1, "name": "Soil_Dirt"}, {"x": 9, "y": -2, "z": 1, "name": "Soil_Dirt"}, {"x": 9, "y": -1, "z": 1, "name": "Soil_Dirt"}, {"x": 9, "y": 0, "z": 1, "name": "Rock_Ledge_Cobble"}, {"x": 9, "y": -3, "z": 2, "name": "Soil_Dirt"}, {"x": 9, "y": -2, "z": 2, "name": "Soil_Dirt"}, {"x": 9, "y": -1, "z": 2, "name": "Soil_Dirt"}, {"x": 9, "y": 0, "z": 2, "name": "Rock_Ledge_Brick"}, {"x": 9, "y": -3, "z": 3, "name": "Soil_Dirt"}, {"x": 9, "y": -2, "z": 3, "name": "Soil_Dirt"}, {"x": 9, "y": -1, "z": 3, "name": "Soil_Dirt"}, {"x": 9, "y": 0, "z": 3, "name": "Rock_Ledge_Brick_Smooth"}, {"x": 9, "y": -3, "z": 4, "name": "Soil_Dirt"}, {"x": 9, "y": -2, "z": 4, "name": "Soil_Dirt"}, {"x": 9, "y": -1, "z": 4, "name": "Soil_Dirt"}, {"x": 9, "y": 0, "z": 4, "name": "Rock_Ledge_Brick_Ornate"}, {"x": 9, "y": -3, "z": 5, "name": "Soil_Dirt"}, {"x": 9, "y": -2, "z": 5, "name": "Soil_Dirt"}, {"x": 9, "y": -1, "z": 5, "name": "Soil_Dirt"}, {"x": 9, "y": 0, "z": 5, "name": "Rock_Ledge_Brick_Smooth"}, {"x": 9, "y": -3, "z": 6, "name": "Soil_Dirt"}, {"x": 9, "y": -2, "z": 6, "name": "Soil_Dirt"}, {"x": 9, "y": -1, "z": 6, "name": "Soil_Dirt"}, {"x": 9, "y": 0, "z": 6, "name": "Soil_Dirt"}, {"x": 9, "y": 1, "z": 6, "name": "Rock_Calcite_Brick_Decorative"}, {"x": 9, "y": 2, "z": 6, "name": "Rock_Lime_Brick_Smooth"}, {"x": 9, "y": 3, "z": 6, "name": "Rock_Lime_Brick_Smooth"}, {"x": 9, "y": 4, "z": 6, "name": "Rock_Lime_Brick_Smooth"}, {"x": 9, "y": 5, "z": 6, "name": "Rock_Calcite_Brick_Smooth_Half"}, {"x": 9, "y": -3, "z": 7, "name": "Soil_Dirt"}, {"x": 9, "y": -2, "z": 7, "name": "Soil_Dirt"}, {"x": 9, "y": -1, "z": 7, "name": "Soil_Dirt"}, {"x": 9, "y": 0, "z": 7, "name": "Rock_Chalk_Brick_Smooth"}, {"x": 9, "y": 4, "z": 7, "name": "Rock_Calcite_Brick_Smooth_Half", "rotation": 8}, {"x": 9, "y": -3, "z": 8, "name": "Soil_Dirt"}, {"x": 9, "y": -2, "z": 8, "name": "Soil_Dirt"}, {"x": 9, "y": -1, "z": 8, "name": "Soil_Dirt"}, {"x": 9, "y": 0, "z": 8, "name": "Rock_Slate_Brick_Smooth"}, {"x": 9, "y": 4, "z": 8, "name": "Rock_Calcite_Brick_Smooth_Half", "rotation": 8}, {"x": 9, "y": -3, "z": 9, "name": "Soil_Dirt"}, {"x": 9, "y": -2, "z": 9, "name": "Soil_Dirt"}, {"x": 9, "y": -1, "z": 9, "name": "Soil_Dirt"}, {"x": 9, "y": 0, "z": 9, "name": "Rock_Chalk_Brick_Smooth"}, {"x": 9, "y": 4, "z": 9, "name": "Rock_Calcite_Brick_Smooth_Half", "rotation": 8}, {"x": 9, "y": -3, "z": 10, "name": "Soil_Dirt"}, {"x": 9, "y": -2, "z": 10, "name": "Soil_Dirt"}, {"x": 9, "y": -1, "z": 10, "name": "Soil_Dirt"}, {"x": 9, "y": 0, "z": 10, "name": "Rock_Slate_Brick_Smooth"}, {"x": 9, "y": 4, "z": 10, "name": "Rock_Calcite_Brick_Smooth_Half", "rotation": 8}, {"x": 9, "y": -3, "z": 11, "name": "Soil_Dirt"}, {"x": 9, "y": -2, "z": 11, "name": "Soil_Dirt"}, {"x": 9, "y": -1, "z": 11, "name": "Soil_Dirt"}, {"x": 9, "y": 0, "z": 11, "name": "Rock_Chalk_Brick_Smooth"}, {"x": 9, "y": 4, "z": 11, "name": "Rock_Calcite_Brick_Smooth_Half", "rotation": 8}, {"x": 9, "y": -3, "z": 12, "name": "Soil_Dirt"}, {"x": 9, "y": -2, "z": 12, "name": "Soil_Dirt"}, {"x": 9, "y": -1, "z": 12, "name": "Soil_Dirt"}, {"x": 9, "y": 0, "z": 12, "name": "Rock_Slate_Brick_Smooth"}, {"x": 9, "y": 4, "z": 12, "name": "Rock_Calcite_Brick_Smooth_Half", "rotation": 8}, {"x": 9, "y": -3, "z": 13, "name": "Soil_Dirt"}, {"x": 9, "y": -2, "z": 13, "name": "Soil_Dirt"}, {"x": 9, "y": -1, "z": 13, "name": "Soil_Dirt"}, {"x": 9, "y": 0, "z": 13, "name": "Rock_Chalk_Brick_Smooth"}, {"x": 9, "y": 4, "z": 13, "name": "Rock_Calcite_Brick_Smooth_Half", "rotation": 8}, {"x": 9, "y": -3, "z": 14, "name": "Soil_Dirt"}, {"x": 9, "y": -2, "z": 14, "name": "Soil_Dirt"}, {"x": 9, "y": -1, "z": 14, "name": "Soil_Dirt"}, {"x": 9, "y": 0, "z": 14, "name": "Soil_Dirt"}, {"x": 9, "y": 1, "z": 14, "name": "Rock_Calcite_Brick_Decorative"}, {"x": 9, "y": 2, "z": 14, "name": "Rock_Lime_Brick_Smooth"}, {"x": 9, "y": 3, "z": 14, "name": "Rock_Lime_Brick_Smooth"}, {"x": 9, "y": 4, "z": 14, "name": "Rock_Lime_Brick_Smooth"}, {"x": 9, "y": 5, "z": 14, "name": "Rock_Calcite_Brick_Smooth_Half"}, {"x": 9, "y": -3, "z": 15, "name": "Soil_Dirt"}, {"x": 9, "y": -2, "z": 15, "name": "Soil_Dirt"}, {"x": 9, "y": -1, "z": 15, "name": "Soil_Dirt"}, {"x": 9, "y": 0, "z": 15, "name": "Rock_Ledge_Brick_Ornate"}, {"x": 9, "y": -3, "z": 16, "name": "Soil_Dirt"}, {"x": 9, "y": -2, "z": 16, "name": "Soil_Dirt"}, {"x": 9, "y": -1, "z": 16, "name": "Soil_Dirt"}, {"x": 9, "y": 0, "z": 16, "name": "Rock_Ledge_Brick_Smooth"}, {"x": 9, "y": -3, "z": 17, "name": "Soil_Dirt"}, {"x": 9, "y": -2, "z": 17, "name": "Soil_Dirt"}, {"x": 9, "y": -1, "z": 17, "name": "Soil_Dirt"}, {"x": 9, "y": 0, "z": 17, "name": "Rock_Ledge_Cobble"}, {"x": 9, "y": -3, "z": 18, "name": "Soil_Dirt"}, {"x": 9, "y": -2, "z": 18, "name": "Soil_Dirt"}, {"x": 9, "y": -1, "z": 18, "name": "Soil_Dirt"}, {"x": 9, "y": 0, "z": 18, "name": "Rock_Ledge_Brick_Ornate"}, {"x": 9, "y": -3, "z": 19, "name": "Soil_Dirt"}, {"x": 9, "y": -2, "z": 19, "name": "Soil_Dirt"}, {"x": 9, "y": -1, "z": 19, "name": "Soil_Dirt"}, {"x": 9, "y": 0, "z": 19, "name": "Rock_Ledge_Brick_Ornate"}, {"x": 9, "y": -3, "z": 20, "name": "Soil_Dirt"}, {"x": 9, "y": -2, "z": 20, "name": "Soil_Dirt"}, {"x": 9, "y": -1, "z": 20, "name": "Soil_Dirt"}, {"x": 9, "y": 0, "z": 20, "name": "Rock_Ledge_Brick_Ornate"}, {"x": 9, "y": -3, "z": 21, "name": "Soil_Dirt"}, {"x": 9, "y": -2, "z": 21, "name": "Soil_Dirt"}, {"x": 9, "y": -1, "z": 21, "name": "Soil_Dirt"}, {"x": 9, "y": 0, "z": 21, "name": "Rock_Ledge_Brick_Decorative"}, {"x": 9, "y": -3, "z": 22, "name": "Soil_Dirt"}, {"x": 9, "y": -2, "z": 22, "name": "Soil_Dirt"}, {"x": 9, "y": -1, "z": 22, "name": "Soil_Dirt"}, {"x": 9, "y": 0, "z": 22, "name": "Rock_Ledge_Brick_Decorative"}, {"x": 9, "y": -3, "z": 23, "name": "Soil_Dirt"}, {"x": 9, "y": -2, "z": 23, "name": "Soil_Dirt"}, {"x": 9, "y": -1, "z": 23, "name": "Soil_Dirt"}, {"x": 9, "y": 0, "z": 23, "name": "Rock_Ledge_Brick_Ornate"}, {"x": 9, "y": 1, "z": 23, "name": "Rock_Quartzite_Brick_Smooth"}, {"x": 9, "y": 2, "z": 23, "name": "Rock_Quartzite_Brick_Smooth"}, {"x": 9, "y": 3, "z": 23, "name": "Rock_Quartzite_Brick_Smooth"}, {"x": 9, "y": 4, "z": 23, "name": "Rock_Quartzite_Brick_Smooth"}, {"x": 9, "y": 5, "z": 23, "name": "Rock_Quartzite_Brick_Smooth"}, {"x": 9, "y": 6, "z": 23, "name": "Rock_Quartzite_Brick_Smooth"}, {"x": 9, "y": -3, "z": 24, "name": "Soil_Dirt"}, {"x": 9, "y": -2, "z": 24, "name": "Soil_Dirt"}, {"x": 9, "y": -1, "z": 24, "name": "Soil_Dirt"}, {"x": 9, "y": 0, "z": 24, "name": "Rock_Ledge_Brick_Decorative"}, {"x": 9, "y": -3, "z": 25, "name": "Soil_Dirt"}, {"x": 9, "y": -2, "z": 25, "name": "Soil_Dirt"}, {"x": 9, "y": -1, "z": 25, "name": "Soil_Dirt"}, {"x": 9, "y": 0, "z": 25, "name": "Rock_Ledge_Brick"}, {"x": 9, "y": -3, "z": 26, "name": "Soil_Dirt"}, {"x": 9, "y": -2, "z": 26, "name": "Soil_Dirt"}, {"x": 9, "y": -1, "z": 26, "name": "Soil_Dirt"}, {"x": 9, "y": 0, "z": 26, "name": "Rock_Ledge_Brick_Smooth"}, {"x": 9, "y": -3, "z": 27, "name": "Soil_Dirt"}, {"x": 9, "y": -2, "z": 27, "name": "Soil_Dirt"}, {"x": 9, "y": -1, "z": 27, "name": "Soil_Dirt"}, {"x": 9, "y": 0, "z": 27, "name": "Rock_Ledge_Brick"}, {"x": 9, "y": -3, "z": 28, "name": "Soil_Dirt"}, {"x": 9, "y": -2, "z": 28, "name": "Soil_Dirt"}, {"x": 9, "y": -1, "z": 28, "name": "Soil_Grass"}, {"x": 9, "y": 0, "z": 28, "name": "Rock_Ledge_Brick"}, {"x": 9, "y": -3, "z": 29, "name": "Soil_Dirt"}, {"x": 9, "y": -2, "z": 29, "name": "Soil_Dirt"}, {"x": 9, "y": -1, "z": 29, "name": "Soil_Dirt"}, {"x": 9, "y": 0, "z": 29, "name": "Rock_Ledge_Brick_Smooth"}, {"x": 9, "y": -3, "z": 30, "name": "Soil_Dirt"}, {"x": 9, "y": -2, "z": 30, "name": "Soil_Dirt"}, {"x": 9, "y": -1, "z": 30, "name": "Soil_Dirt"}, {"x": 9, "y": 0, "z": 30, "name": "Rock_Ledge_Brick_Smooth"}, {"x": 9, "y": -3, "z": 31, "name": "Soil_Dirt"}, {"x": 9, "y": -2, "z": 31, "name": "Soil_Dirt"}, {"x": 9, "y": -1, "z": 31, "name": "Soil_Dirt"}, {"x": 9, "y": 0, "z": 31, "name": "Rock_Ledge_Brick_Decorative"}, {"x": 10, "y": -3, "z": 0, "name": "Soil_Dirt"}, {"x": 10, "y": -2, "z": 0, "name": "Soil_Dirt"}, {"x": 10, "y": -1, "z": 0, "name": "Soil_Dirt"}, {"x": 10, "y": 0, "z": 0, "name": "Rock_Ledge_Brick_Ornate"}, {"x": 10, "y": -3, "z": 1, "name": "Soil_Dirt"}, {"x": 10, "y": -2, "z": 1, "name": "Soil_Dirt"}, {"x": 10, "y": -1, "z": 1, "name": "Soil_Dirt"}, {"x": 10, "y": 0, "z": 1, "name": "Rock_Ledge_Brick_Smooth"}, {"x": 10, "y": -3, "z": 2, "name": "Soil_Dirt"}, {"x": 10, "y": -2, "z": 2, "name": "Soil_Dirt"}, {"x": 10, "y": -1, "z": 2, "name": "Soil_Dirt"}, {"x": 10, "y": 0, "z": 2, "name": "Rock_Ledge_Brick_Decorative"}, {"x": 10, "y": -3, "z": 3, "name": "Soil_Dirt"}, {"x": 10, "y": -2, "z": 3, "name": "Soil_Dirt"}, {"x": 10, "y": -1, "z": 3, "name": "Soil_Dirt"}, {"x": 10, "y": 0, "z": 3, "name": "Rock_Ledge_Brick"}, {"x": 10, "y": -3, "z": 4, "name": "Soil_Dirt"}, {"x": 10, "y": -2, "z": 4, "name": "Soil_Dirt"}, {"x": 10, "y": -1, "z": 4, "name": "Soil_Dirt"}, {"x": 10, "y": 0, "z": 4, "name": "Rock_Ledge_Brick_Smooth"}, {"x": 10, "y": -3, "z": 5, "name": "Soil_Dirt"}, {"x": 10, "y": -2, "z": 5, "name": "Soil_Dirt"}, {"x": 10, "y": -1, "z": 5, "name": "Soil_Dirt"}, {"x": 10, "y": 0, "z": 5, "name": "Rock_Ledge_Brick_Smooth"}, {"x": 10, "y": -3, "z": 6, "name": "Soil_Dirt"}, {"x": 10, "y": -2, "z": 6, "name": "Soil_Dirt"}, {"x": 10, "y": -1, "z": 6, "name": "Soil_Dirt"}, {"x": 10, "y": 0, "z": 6, "name": "Soil_Dirt"}, {"x": 10, "y": 1, "z": 6, "name": "Rock_Calcite_Brick_Decorative"}, {"x": 10, "y": 2, "z": 6, "name": "Rock_Lime_Brick_Smooth"}, {"x": 10, "y": 3, "z": 6, "name": "Rock_Lime_Brick_Smooth"}, {"x": 10, "y": 4, "z": 6, "name": "Rock_Lime_Brick_Smooth"}, {"x": 10, "y": 5, "z": 6, "name": "Rock_Calcite_Brick_Smooth_Half"}, {"x": 10, "y": -3, "z": 7, "name": "Soil_Dirt"}, {"x": 10, "y": -2, "z": 7, "name": "Soil_Dirt"}, {"x": 10, "y": -1, "z": 7, "name": "Soil_Dirt"}, {"x": 10, "y": 0, "z": 7, "name": "Rock_Calcite_Brick_Smooth"}, {"x": 10, "y": 1, "z": 7, "name": "K2_Slot_Station_Combine"}, {"x": 10, "y": 3, "z": 7, "name": "Rock_Calcite_Brick_Smooth_Half", "rotation": 8}, {"x": 10, "y": 4, "z": 7, "name": "Rock_Lime_Brick_Smooth"}, {"x": 10, "y": -3, "z": 8, "name": "Soil_Dirt"}, {"x": 10, "y": -2, "z": 8, "name": "Soil_Dirt"}, {"x": 10, "y": -1, "z": 8, "name": "Soil_Dirt"}, {"x": 10, "y": 0, "z": 8, "name": "Rock_Calcite_Brick_Smooth"}, {"x": 10, "y": 1, "z": 8, "name": "K2_Slot_Station_Combine"}, {"x": 10, "y": 3, "z": 8, "name": "Rock_Calcite_Brick_Smooth_Half", "rotation": 8}, {"x": 10, "y": 4, "z": 8, "name": "Rock_Lime_Brick_Smooth"}, {"x": 10, "y": -3, "z": 9, "name": "Soil_Dirt"}, {"x": 10, "y": -2, "z": 9, "name": "Soil_Dirt"}, {"x": 10, "y": -1, "z": 9, "name": "Soil_Dirt"}, {"x": 10, "y": 0, "z": 9, "name": "Rock_Calcite_Brick_Smooth"}, {"x": 10, "y": 1, "z": 9, "name": "K2_Slot_Station_Combine"}, {"x": 10, "y": 3, "z": 9, "name": "Rock_Calcite_Brick_Smooth_Half", "rotation": 8}, {"x": 10, "y": 4, "z": 9, "name": "Rock_Lime_Brick_Smooth"}, {"x": 10, "y": -3, "z": 10, "name": "Soil_Dirt"}, {"x": 10, "y": -2, "z": 10, "name": "Soil_Dirt"}, {"x": 10, "y": -1, "z": 10, "name": "Soil_Dirt"}, {"x": 10, "y": 0, "z": 10, "name": "Soil_Dirt"}, {"x": 10, "y": 1, "z": 10, "name": "Rock_Calcite_Brick_Decorative"}, {"x": 10, "y": 2, "z": 10, "name": "Rock_Lime_Brick_Smooth"}, {"x": 10, "y": 3, "z": 10, "name": "Rock_Lime_Brick_Smooth"}, {"x": 10, "y": 4, "z": 10, "name": "Rock_Lime_Brick_Smooth"}, {"x": 10, "y": -3, "z": 11, "name": "Soil_Dirt"}, {"x": 10, "y": -2, "z": 11, "name": "Soil_Dirt"}, {"x": 10, "y": -1, "z": 11, "name": "Soil_Dirt"}, {"x": 10, "y": 0, "z": 11, "name": "Soil_Dirt"}, {"x": 10, "y": 1, "z": 11, "name": "Rock_Calcite_Brick_Decorative"}, {"x": 10, "y": 2, "z": 11, "name": "Rock_Lime_Brick_Smooth"}, {"x": 10, "y": 3, "z": 11, "name": "Rock_Lime_Brick_Smooth"}, {"x": 10, "y": 4, "z": 11, "name": "Rock_Lime_Brick_Smooth"}, {"x": 10, "y": -3, "z": 12, "name": "Soil_Dirt"}, {"x": 10, "y": -2, "z": 12, "name": "Soil_Dirt"}, {"x": 10, "y": -1, "z": 12, "name": "Soil_Dirt"}, {"x": 10, "y": 0, "z": 12, "name": "Soil_Dirt"}, {"x": 10, "y": 1, "z": 12, "name": "Rock_Calcite_Brick_Decorative"}, {"x": 10, "y": 2, "z": 12, "name": "Rock_Lime_Brick_Smooth"}, {"x": 10, "y": 3, "z": 12, "name": "Rock_Lime_Brick_Smooth"}, {"x": 10, "y": 4, "z": 12, "name": "Rock_Lime_Brick_Smooth"}, {"x": 10, "y": -3, "z": 13, "name": "Soil_Dirt"}, {"x": 10, "y": -2, "z": 13, "name": "Soil_Dirt"}, {"x": 10, "y": -1, "z": 13, "name": "Soil_Dirt"}, {"x": 10, "y": 0, "z": 13, "name": "Rock_Calcite_Brick_Smooth"}, {"x": 10, "y": 3, "z": 13, "name": "Rock_Lime_Brick_Smooth"}, {"x": 10, "y": 4, "z": 13, "name": "Rock_Lime_Brick_Smooth"}, {"x": 10, "y": -3, "z": 14, "name": "Soil_Dirt"}, {"x": 10, "y": -2, "z": 14, "name": "Soil_Dirt"}, {"x": 10, "y": -1, "z": 14, "name": "Soil_Dirt"}, {"x": 10, "y": 0, "z": 14, "name": "Soil_Dirt"}, {"x": 10, "y": 1, "z": 14, "name": "Rock_Calcite_Brick_Decorative"}, {"x": 10, "y": 2, "z": 14, "name": "Rock_Lime_Brick_Smooth"}, {"x": 10, "y": 3, "z": 14, "name": "Rock_Lime_Brick_Smooth"}, {"x": 10, "y": 4, "z": 14, "name": "Rock_Lime_Brick_Smooth"}, {"x": 10, "y": 5, "z": 14, "name": "Rock_Calcite_Brick_Smooth_Half"}, {"x": 10, "y": -3, "z": 15, "name": "Soil_Dirt"}, {"x": 10, "y": -2, "z": 15, "name": "Soil_Dirt"}, {"x": 10, "y": -1, "z": 15, "name": "Soil_Dirt"}, {"x": 10, "y": 0, "z": 15, "name": "Soil_Dirt"}, {"x": 10, "y": 1, "z": 15, "name": "Rock_Calcite_Brick_Decorative"}, {"x": 10, "y": 2, "z": 15, "name": "Rock_Lime_Brick_Smooth"}, {"x": 10, "y": 3, "z": 15, "name": "Rock_Lime_Brick_Smooth"}, {"x": 10, "y": 4, "z": 15, "name": "Rock_Lime_Brick_Smooth"}, {"x": 10, "y": 5, "z": 15, "name": "Rock_Calcite_Brick_Smooth_Half"}, {"x": 10, "y": -3, "z": 16, "name": "Soil_Dirt"}, {"x": 10, "y": -2, "z": 16, "name": "Soil_Dirt"}, {"x": 10, "y": -1, "z": 16, "name": "Soil_Dirt"}, {"x": 10, "y": 0, "z": 16, "name": "Rock_Ledge_Brick_Decorative"}, {"x": 10, "y": -3, "z": 17, "name": "Soil_Dirt"}, {"x": 10, "y": -2, "z": 17, "name": "Soil_Dirt"}, {"x": 10, "y": -1, "z": 17, "name": "Soil_Dirt"}, {"x": 10, "y": 0, "z": 17, "name": "Rock_Ledge_Brick_Smooth"}, {"x": 10, "y": -3, "z": 18, "name": "Soil_Dirt"}, {"x": 10, "y": -2, "z": 18, "name": "Soil_Dirt"}, {"x": 10, "y": -1, "z": 18, "name": "Soil_Dirt"}, {"x": 10, "y": 0, "z": 18, "name": "Rock_Ledge_Brick_Smooth"}, {"x": 10, "y": -3, "z": 19, "name": "Soil_Dirt"}, {"x": 10, "y": -2, "z": 19, "name": "Soil_Dirt"}, {"x": 10, "y": -1, "z": 19, "name": "Soil_Dirt"}, {"x": 10, "y": 0, "z": 19, "name": "Rock_Ledge_Cobble"}, {"x": 10, "y": -3, "z": 20, "name": "Soil_Dirt"}, {"x": 10, "y": -2, "z": 20, "name": "Soil_Dirt"}, {"x": 10, "y": -1, "z": 20, "name": "Soil_Dirt"}, {"x": 10, "y": 0, "z": 20, "name": "Rock_Ledge_Brick"}, {"x": 10, "y": -3, "z": 21, "name": "Soil_Dirt"}, {"x": 10, "y": -2, "z": 21, "name": "Soil_Dirt"}, {"x": 10, "y": -1, "z": 21, "name": "Soil_Dirt"}, {"x": 10, "y": 0, "z": 21, "name": "Rock_Ledge_Cobble"}, {"x": 10, "y": -3, "z": 22, "name": "Soil_Dirt"}, {"x": 10, "y": -2, "z": 22, "name": "Soil_Dirt"}, {"x": 10, "y": -1, "z": 22, "name": "Soil_Dirt"}, {"x": 10, "y": 0, "z": 22, "name": "Rock_Ledge_Brick_Ornate"}, {"x": 10, "y": -3, "z": 23, "name": "Soil_Dirt"}, {"x": 10, "y": -2, "z": 23, "name": "Soil_Dirt"}, {"x": 10, "y": -1, "z": 23, "name": "Soil_Dirt"}, {"x": 10, "y": 0, "z": 23, "name": "Rock_Ledge_Brick_Ornate"}, {"x": 10, "y": 1, "z": 23, "name": "Rock_Quartzite_Brick_Smooth"}, {"x": 10, "y": 2, "z": 23, "name": "Rock_Quartzite_Brick_Smooth"}, {"x": 10, "y": 3, "z": 23, "name": "Rock_Quartzite_Brick_Smooth"}, {"x": 10, "y": 4, "z": 23, "name": "Rock_Quartzite_Brick_Smooth"}, {"x": 10, "y": 5, "z": 23, "name": "Rock_Quartzite_Brick_Smooth"}, {"x": 10, "y": 6, "z": 23, "name": "Rock_Quartzite_Brick_Smooth"}, {"x": 10, "y": -3, "z": 24, "name": "Soil_Dirt"}, {"x": 10, "y": -2, "z": 24, "name": "Soil_Dirt"}, {"x": 10, "y": -1, "z": 24, "name": "Soil_Dirt"}, {"x": 10, "y": 0, "z": 24, "name": "Rock_Ledge_Brick_Smooth"}, {"x": 10, "y": -3, "z": 25, "name": "Soil_Dirt"}, {"x": 10, "y": -2, "z": 25, "name": "Soil_Dirt"}, {"x": 10, "y": -1, "z": 25, "name": "Soil_Dirt"}, {"x": 10, "y": 0, "z": 25, "name": "Rock_Ledge_Brick_Ornate"}, {"x": 10, "y": -3, "z": 26, "name": "Soil_Dirt"}, {"x": 10, "y": -2, "z": 26, "name": "Soil_Dirt"}, {"x": 10, "y": -1, "z": 26, "name": "Soil_Dirt"}, {"x": 10, "y": 0, "z": 26, "name": "Rock_Ledge_Brick"}, {"x": 10, "y": -3, "z": 27, "name": "Soil_Dirt"}, {"x": 10, "y": -2, "z": 27, "name": "Soil_Dirt"}, {"x": 10, "y": -1, "z": 27, "name": "Soil_Dirt"}, {"x": 10, "y": 0, "z": 27, "name": "Rock_Ledge_Brick_Ornate"}, {"x": 10, "y": -3, "z": 28, "name": "Soil_Dirt"}, {"x": 10, "y": -2, "z": 28, "name": "Soil_Dirt"}, {"x": 10, "y": -1, "z": 28, "name": "Soil_Dirt"}, {"x": 10, "y": 0, "z": 28, "name": "Rock_Ledge_Brick_Smooth"}, {"x": 10, "y": -3, "z": 29, "name": "Soil_Dirt"}, {"x": 10, "y": -2, "z": 29, "name": "Soil_Dirt"}, {"x": 10, "y": -1, "z": 29, "name": "Soil_Dirt"}, {"x": 10, "y": 0, "z": 29, "name": "Rock_Ledge_Brick_Smooth"}, {"x": 10, "y": -3, "z": 30, "name": "Soil_Dirt"}, {"x": 10, "y": -2, "z": 30, "name": "Soil_Dirt"}, {"x": 10, "y": -1, "z": 30, "name": "Soil_Dirt"}, {"x": 10, "y": 0, "z": 30, "name": "Rock_Ledge_Cobble"}, {"x": 10, "y": -3, "z": 31, "name": "Soil_Dirt"}, {"x": 10, "y": -2, "z": 31, "name": "Soil_Dirt"}, {"x": 10, "y": -1, "z": 31, "name": "Soil_Dirt"}, {"x": 10, "y": 0, "z": 31, "name": "Rock_Ledge_Brick_Ornate"}, {"x": 11, "y": -3, "z": 0, "name": "Soil_Dirt"}, {"x": 11, "y": -2, "z": 0, "name": "Soil_Dirt"}, {"x": 11, "y": -1, "z": 0, "name": "Soil_Dirt"}, {"x": 11, "y": 0, "z": 0, "name": "Rock_Ledge_Brick"}, {"x": 11, "y": -3, "z": 1, "name": "Soil_Dirt"}, {"x": 11, "y": -2, "z": 1, "name": "Soil_Dirt"}, {"x": 11, "y": -1, "z": 1, "name": "Soil_Dirt"}, {"x": 11, "y": 0, "z": 1, "name": "Rock_Ledge_Brick_Ornate"}, {"x": 11, "y": -3, "z": 2, "name": "Soil_Dirt"}, {"x": 11, "y": -2, "z": 2, "name": "Soil_Dirt"}, {"x": 11, "y": -1, "z": 2, "name": "Soil_Dirt"}, {"x": 11, "y": 0, "z": 2, "name": "Rock_Ledge_Cobble"}, {"x": 11, "y": -3, "z": 3, "name": "Soil_Dirt"}, {"x": 11, "y": -2, "z": 3, "name": "Soil_Dirt"}, {"x": 11, "y": -1, "z": 3, "name": "Soil_Dirt"}, {"x": 11, "y": 0, "z": 3, "name": "Rock_Ledge_Cobble"}, {"x": 11, "y": -3, "z": 4, "name": "Soil_Dirt"}, {"x": 11, "y": -2, "z": 4, "name": "Soil_Dirt"}, {"x": 11, "y": -1, "z": 4, "name": "Soil_Dirt"}, {"x": 11, "y": 0, "z": 4, "name": "Soil_Dirt"}, {"x": 11, "y": 1, "z": 4, "name": "Rock_Calcite_Brick_Decorative"}, {"x": 11, "y": 2, "z": 4, "name": "Rock_Lime_Brick_Smooth"}, {"x": 11, "y": 3, "z": 4, "name": "Rock_Lime_Brick_Smooth"}, {"x": 11, "y": 4, "z": 4, "name": "Rock_Lime_Brick_Smooth"}, {"x": 11, "y": 5, "z": 4, "name": "Rock_Calcite_Brick_Smooth_Half"}, {"x": 11, "y": -3, "z": 5, "name": "Soil_Dirt"}, {"x": 11, "y": -2, "z": 5, "name": "Soil_Dirt"}, {"x": 11, "y": -1, "z": 5, "name": "Soil_Dirt"}, {"x": 11, "y": 0, "z": 5, "name": "Soil_Dirt"}, {"x": 11, "y": 1, "z": 5, "name": "Rock_Calcite_Brick_Decorative"}, {"x": 11, "y": 2, "z": 5, "name": "Rock_Lime_Brick_Smooth"}, {"x": 11, "y": 3, "z": 5, "name": "Rock_Lime_Brick_Smooth"}, {"x": 11, "y": 4, "z": 5, "name": "Rock_Lime_Brick_Smooth"}, {"x": 11, "y": 5, "z": 5, "name": "Rock_Calcite_Brick_Smooth_Half"}, {"x": 11, "y": -3, "z": 6, "name": "Soil_Dirt"}, {"x": 11, "y": -2, "z": 6, "name": "Soil_Dirt"}, {"x": 11, "y": -1, "z": 6, "name": "Soil_Dirt"}, {"x": 11, "y": 0, "z": 6, "name": "Soil_Dirt"}, {"x": 11, "y": 1, "z": 6, "name": "Rock_Calcite_Brick_Decorative"}, {"x": 11, "y": 2, "z": 6, "name": "Rock_Lime_Brick_Smooth"}, {"x": 11, "y": 3, "z": 6, "name": "Rock_Lime_Brick_Smooth"}, {"x": 11, "y": 4, "z": 6, "name": "Rock_Lime_Brick_Smooth"}, {"x": 11, "y": 5, "z": 6, "name": "Rock_Calcite_Brick_Smooth_Half"}, {"x": 11, "y": -3, "z": 7, "name": "Soil_Dirt"}, {"x": 11, "y": -2, "z": 7, "name": "Soil_Dirt"}, {"x": 11, "y": -1, "z": 7, "name": "Soil_Dirt"}, {"x": 11, "y": 0, "z": 7, "name": "Wood_Hardwood_Planks"}, {"x": 11, "y": 4, "z": 7, "name": "Rock_Calcite_Brick_Smooth_Half", "rotation": 8}, {"x": 11, "y": -3, "z": 8, "name": "Soil_Dirt"}, {"x": 11, "y": -2, "z": 8, "name": "Soil_Dirt"}, {"x": 11, "y": -1, "z": 8, "name": "Soil_Dirt"}, {"x": 11, "y": 0, "z": 8, "name": "Wood_Hardwood_Planks"}, {"x": 11, "y": 4, "z": 8, "name": "Rock_Calcite_Brick_Smooth_Half", "rotation": 8}, {"x": 11, "y": -3, "z": 9, "name": "Soil_Dirt"}, {"x": 11, "y": -2, "z": 9, "name": "Soil_Dirt"}, {"x": 11, "y": -1, "z": 9, "name": "Soil_Dirt"}, {"x": 11, "y": 0, "z": 9, "name": "Wood_Hardwood_Planks"}, {"x": 11, "y": 4, "z": 9, "name": "Rock_Calcite_Brick_Smooth_Half", "rotation": 8}, {"x": 11, "y": -3, "z": 10, "name": "Soil_Dirt"}, {"x": 11, "y": -2, "z": 10, "name": "Soil_Dirt"}, {"x": 11, "y": -1, "z": 10, "name": "Soil_Dirt"}, {"x": 11, "y": 0, "z": 10, "name": "Wood_Hardwood_Planks"}, {"x": 11, "y": 4, "z": 10, "name": "Rock_Calcite_Brick_Smooth_Half", "rotation": 8}, {"x": 11, "y": -3, "z": 11, "name": "Soil_Dirt"}, {"x": 11, "y": -2, "z": 11, "name": "Soil_Dirt"}, {"x": 11, "y": -1, "z": 11, "name": "Soil_Dirt"}, {"x": 11, "y": 0, "z": 11, "name": "Soil_Dirt"}, {"x": 11, "y": 1, "z": 11, "name": "Rock_Calcite_Brick_Decorative"}, {"x": 11, "y": 2, "z": 11, "name": "Rock_Lime_Brick_Smooth"}, {"x": 11, "y": 3, "z": 11, "name": "Rock_Lime_Brick_Smooth"}, {"x": 11, "y": 4, "z": 11, "name": "Rock_Lime_Brick_Smooth"}, {"x": 11, "y": -3, "z": 12, "name": "Soil_Dirt"}, {"x": 11, "y": -2, "z": 12, "name": "Soil_Dirt"}, {"x": 11, "y": -1, "z": 12, "name": "Soil_Dirt"}, {"x": 11, "y": 0, "z": 12, "name": "K2_Slot_Station_Tool"}, {"x": 11, "y": 4, "z": 12, "name": "Rock_Calcite_Brick_Smooth_Half", "rotation": 8}, {"x": 11, "y": -3, "z": 13, "name": "Soil_Dirt"}, {"x": 11, "y": -2, "z": 13, "name": "Soil_Dirt"}, {"x": 11, "y": -1, "z": 13, "name": "Soil_Dirt"}, {"x": 11, "y": 0, "z": 13, "name": "Wood_Hardwood_Planks"}, {"x": 11, "y": 4, "z": 13, "name": "Rock_Calcite_Brick_Smooth_Half", "rotation": 8}, {"x": 11, "y": -3, "z": 14, "name": "Soil_Dirt"}, {"x": 11, "y": -2, "z": 14, "name": "Soil_Dirt"}, {"x": 11, "y": -1, "z": 14, "name": "Soil_Dirt"}, {"x": 11, "y": 0, "z": 14, "name": "Wood_Hardwood_Planks"}, {"x": 11, "y": 4, "z": 14, "name": "Rock_Calcite_Brick_Smooth_Half", "rotation": 8}, {"x": 11, "y": -3, "z": 15, "name": "Soil_Dirt"}, {"x": 11, "y": -2, "z": 15, "name": "Soil_Dirt"}, {"x": 11, "y": -1, "z": 15, "name": "Soil_Dirt"}, {"x": 11, "y": 0, "z": 15, "name": "Soil_Dirt"}, {"x": 11, "y": 1, "z": 15, "name": "Rock_Calcite_Brick_Decorative"}, {"x": 11, "y": 2, "z": 15, "name": "Rock_Lime_Brick_Smooth"}, {"x": 11, "y": 3, "z": 15, "name": "Rock_Lime_Brick_Smooth"}, {"x": 11, "y": 4, "z": 15, "name": "Rock_Lime_Brick_Smooth"}, {"x": 11, "y": 5, "z": 15, "name": "Rock_Calcite_Brick_Smooth_Half"}, {"x": 11, "y": -3, "z": 16, "name": "Soil_Dirt"}, {"x": 11, "y": -2, "z": 16, "name": "Soil_Dirt"}, {"x": 11, "y": -1, "z": 16, "name": "Soil_Dirt"}, {"x": 11, "y": 0, "z": 16, "name": "Rock_Ledge_Brick_Decorative"}, {"x": 11, "y": -3, "z": 17, "name": "Soil_Dirt"}, {"x": 11, "y": -2, "z": 17, "name": "Soil_Dirt"}, {"x": 11, "y": -1, "z": 17, "name": "Soil_Dirt"}, {"x": 11, "y": 0, "z": 17, "name": "Rock_Ledge_Brick_Smooth"}, {"x": 11, "y": -3, "z": 18, "name": "Soil_Dirt"}, {"x": 11, "y": -2, "z": 18, "name": "Soil_Dirt"}, {"x": 11, "y": -1, "z": 18, "name": "Soil_Dirt"}, {"x": 11, "y": 0, "z": 18, "name": "Rock_Ledge_Brick_Ornate"}, {"x": 11, "y": -3, "z": 19, "name": "Soil_Dirt"}, {"x": 11, "y": -2, "z": 19, "name": "Soil_Dirt"}, {"x": 11, "y": -1, "z": 19, "name": "Soil_Dirt"}, {"x": 11, "y": 0, "z": 19, "name": "Rock_Ledge_Brick_Smooth"}, {"x": 11, "y": -3, "z": 20, "name": "Soil_Dirt"}, {"x": 11, "y": -2, "z": 20, "name": "Soil_Dirt"}, {"x": 11, "y": -1, "z": 20, "name": "Soil_Dirt"}, {"x": 11, "y": 0, "z": 20, "name": "Rock_Ledge_Cobble"}, {"x": 11, "y": -3, "z": 21, "name": "Soil_Dirt"}, {"x": 11, "y": -2, "z": 21, "name": "Soil_Dirt"}, {"x": 11, "y": -1, "z": 21, "name": "Soil_Dirt"}, {"x": 11, "y": 0, "z": 21, "name": "Rock_Ledge_Brick_Decorative"}, {"x": 11, "y": -3, "z": 22, "name": "Soil_Dirt"}, {"x": 11, "y": -2, "z": 22, "name": "Soil_Dirt"}, {"x": 11, "y": -1, "z": 22, "name": "Soil_Dirt"}, {"x": 11, "y": 0, "z": 22, "name": "Rock_Ledge_Brick_Smooth"}, {"x": 11, "y": -3, "z": 23, "name": "Soil_Dirt"}, {"x": 11, "y": -2, "z": 23, "name": "Soil_Dirt"}, {"x": 11, "y": -1, "z": 23, "name": "Soil_Dirt"}, {"x": 11, "y": 0, "z": 23, "name": "Rock_Ledge_Brick_Smooth"}, {"x": 11, "y": 1, "z": 23, "name": "Rock_Quartzite_Brick_Smooth"}, {"x": 11, "y": 2, "z": 23, "name": "Rock_Quartzite_Brick_Smooth"}, {"x": 11, "y": 3, "z": 23, "name": "Rock_Quartzite_Brick_Smooth"}, {"x": 11, "y": 4, "z": 23, "name": "Rock_Quartzite_Brick_Smooth"}, {"x": 11, "y": 5, "z": 23, "name": "Rock_Quartzite_Brick_Smooth"}, {"x": 11, "y": 6, "z": 23, "name": "Rock_Quartzite_Brick_Smooth"}, {"x": 11, "y": -3, "z": 24, "name": "Soil_Dirt"}, {"x": 11, "y": -2, "z": 24, "name": "Soil_Dirt"}, {"x": 11, "y": -1, "z": 24, "name": "Soil_Dirt"}, {"x": 11, "y": 0, "z": 24, "name": "Rock_Ledge_Brick_Smooth"}, {"x": 11, "y": -3, "z": 25, "name": "Soil_Dirt"}, {"x": 11, "y": -2, "z": 25, "name": "Soil_Dirt"}, {"x": 11, "y": -1, "z": 25, "name": "Soil_Dirt"}, {"x": 11, "y": 0, "z": 25, "name": "Rock_Ledge_Cobble"}, {"x": 11, "y": -3, "z": 26, "name": "Soil_Dirt"}, {"x": 11, "y": -2, "z": 26, "name": "Soil_Dirt"}, {"x": 11, "y": -1, "z": 26, "name": "Soil_Dirt"}, {"x": 11, "y": 0, "z": 26, "name": "Rock_Ledge_Brick_Ornate"}, {"x": 11, "y": -3, "z": 27, "name": "Soil_Dirt"}, {"x": 11, "y": -2, "z": 27, "name": "Soil_Dirt"}, {"x": 11, "y": -1, "z": 27, "name": "Soil_Dirt"}, {"x": 11, "y": 0, "z": 27, "name": "Rock_Ledge_Cobble"}, {"x": 11, "y": -3, "z": 28, "name": "Soil_Dirt"}, {"x": 11, "y": -2, "z": 28, "name": "Soil_Dirt"}, {"x": 11, "y": -1, "z": 28, "name": "Soil_Dirt"}, {"x": 11, "y": 0, "z": 28, "name": "Rock_Ledge_Brick_Decorative"}, {"x": 11, "y": -3, "z": 29, "name": "Soil_Dirt"}, {"x": 11, "y": -2, "z": 29, "name": "Soil_Dirt"}, {"x": 11, "y": -1, "z": 29, "name": "Soil_Dirt"}, {"x": 11, "y": 0, "z": 29, "name": "Rock_Ledge_Brick"}, {"x": 11, "y": -3, "z": 30, "name": "Soil_Dirt"}, {"x": 11, "y": -2, "z": 30, "name": "Soil_Dirt"}, {"x": 11, "y": -1, "z": 30, "name": "Soil_Dirt"}, {"x": 11, "y": 0, "z": 30, "name": "Rock_Ledge_Brick_Smooth"}, {"x": 11, "y": -3, "z": 31, "name": "Soil_Dirt"}, {"x": 11, "y": -2, "z": 31, "name": "Soil_Dirt"}, {"x": 11, "y": -1, "z": 31, "name": "Soil_Dirt"}, {"x": 11, "y": 0, "z": 31, "name": "Rock_Ledge_Brick_Smooth"}, {"x": 12, "y": -3, "z": 0, "name": "Soil_Dirt"}, {"x": 12, "y": -2, "z": 0, "name": "Soil_Dirt"}, {"x": 12, "y": -1, "z": 0, "name": "Soil_Dirt"}, {"x": 12, "y": 0, "z": 0, "name": "Rock_Ledge_Brick"}, {"x": 12, "y": -3, "z": 1, "name": "Soil_Dirt"}, {"x": 12, "y": -2, "z": 1, "name": "Soil_Dirt"}, {"x": 12, "y": -1, "z": 1, "name": "Soil_Dirt"}, {"x": 12, "y": 0, "z": 1, "name": "Rock_Ledge_Brick_Ornate"}, {"x": 12, "y": -3, "z": 2, "name": "Soil_Dirt"}, {"x": 12, "y": -2, "z": 2, "name": "Soil_Dirt"}, {"x": 12, "y": -1, "z": 2, "name": "Soil_Dirt"}, {"x": 12, "y": 0, "z": 2, "name": "Rock_Ledge_Brick_Decorative"}, {"x": 12, "y": -3, "z": 3, "name": "Soil_Dirt"}, {"x": 12, "y": -2, "z": 3, "name": "Soil_Dirt"}, {"x": 12, "y": -1, "z": 3, "name": "Soil_Dirt"}, {"x": 12, "y": 0, "z": 3, "name": "Rock_Ledge_Brick"}, {"x": 12, "y": -3, "z": 4, "name": "Soil_Dirt"}, {"x": 12, "y": -2, "z": 4, "name": "Soil_Dirt"}, {"x": 12, "y": -1, "z": 4, "name": "Soil_Dirt"}, {"x": 12, "y": 0, "z": 4, "name": "Rock_Calcite_Brick_Smooth"}, {"x": 12, "y": 3, "z": 4, "name": "Rock_Lime_Brick_Smooth"}, {"x": 12, "y": 4, "z": 4, "name": "Rock_Lime_Brick_Smooth"}, {"x": 12, "y": 5, "z": 4, "name": "Rock_Calcite_Brick_Smooth_Half"}, {"x": 12, "y": -3, "z": 5, "name": "Soil_Dirt"}, {"x": 12, "y": -2, "z": 5, "name": "Soil_Dirt"}, {"x": 12, "y": -1, "z": 5, "name": "Soil_Dirt"}, {"x": 12, "y": 0, "z": 5, "name": "Wood_Hardwood_Planks"}, {"x": 12, "y": 4, "z": 5, "name": "Rock_Calcite_Brick_Smooth_Half", "rotation": 8}, {"x": 12, "y": -3, "z": 6, "name": "Soil_Dirt"}, {"x": 12, "y": -2, "z": 6, "name": "Soil_Dirt"},