{"version": 8, "blockIdVersion": 11, "anchorX": 0, "anchorY": 0, "anchorZ": 0, "blocks": [{"x": 0, "y": -3, "z": 0, "name": "Soil_Dirt"}, {"x": 0, "y": -2, "z": 0, "name": "Soil_Dirt"}, {"x": 0, "y": -1, "z": 0, "name": "Soil_Dirt"}, {"x": 0, "y": 0, "z": 0, "name": "Soil_Grass"}, {"x": 0, "y": -3, "z": 1, "name": "Soil_Dirt"}, {"x": 0, "y": -2, "z": 1, "name": "Soil_Dirt"}, {"x": 0, "y": -1, "z": 1, "name": "Soil_Dirt"}, {"x": 0, "y": 0, "z": 1, "name": "Soil_Grass"}, {"x": 0, "y": -3, "z": 2, "name": "Soil_Dirt"}, {"x": 0, "y": -2, "z": 2, "name": "Soil_Dirt"}, {"x": 0, "y": -1, "z": 2, "name": "Soil_Dirt"}, {"x": 0, "y": 0, "z": 2, "name": "Soil_Grass"}, {"x": 0, "y": -3, "z": 3, "name": "Soil_Dirt"}, {"x": 0, "y": -2, "z": 3, "name": "Soil_Dirt"}, {"x": 0, "y": -1, "z": 3, "name": "Soil_Dirt"}, {"x": 0, "y": 0, "z": 3, "name": "Soil_Grass"}, {"x": 0, "y": -3, "z": 4, "name": "Soil_Dirt"}, {"x": 0, "y": -2, "z": 4, "name": "Soil_Dirt"}, {"x": 0, "y": -1, "z": 4, "name": "Soil_Dirt"}, {"x": 0, "y": 0, "z": 4, "name": "Soil_Grass"}, {"x": 0, "y": -3, "z": 5, "name": "Soil_Dirt"}, {"x": 0, "y": -2, "z": 5, "name": "Soil_Dirt"}, {"x": 0, "y": -1, "z": 5, "name": "Soil_Dirt"}, {"x": 0, "y": 0, "z": 5, "name": "Soil_Grass"}, {"x": 0, "y": -3, "z": 6, "name": "Soil_Dirt"}, {"x": 0, "y": -2, "z": 6, "name": "Soil_Dirt"}, {"x": 0, "y": -1, "z": 6, "name": "Soil_Dirt"}, {"x": 0, "y": 0, "z": 6, "name": "Soil_Grass"}, {"x": 0, "y": -3, "z": 7, "name": "Soil_Dirt"}, {"x": 0, "y": -2, "z": 7, "name": "Soil_Dirt"}, {"x": 0, "y": -1, "z": 7, "name": "Soil_Dirt"}, {"x": 0, "y": 0, "z": 7, "name": "Soil_Grass"}, {"x": 0, "y": -3, "z": 8, "name": "Soil_Dirt"}, {"x": 0, "y": -2, "z": 8, "name": "Soil_Dirt"}, {"x": 0, "y": -1, "z": 8, "name": "Soil_Dirt"}, {"x": 0, "y": 0, "z": 8, "name": "Soil_Grass"}, {"x": 0, "y": -3, "z": 9, "name": "Soil_Dirt"}, {"x": 0, "y": -2, "z": 9, "name": "Soil_Dirt"}, {"x": 0, "y": -1, "z": 9, "name": "Soil_Dirt"}, {"x": 0, "y": 0, "z": 9, "name": "Soil_Grass"}, {"x": 0, "y": -3, "z": 10, "name": "Soil_Dirt"}, {"x": 0, "y": -2, "z": 10, "name": "Soil_Dirt"}, {"x": 0, "y": -1, "z": 10, "name": "Soil_Dirt"}, {"x": 0, "y": 0, "z": 10, "name": "Soil_Grass"}, {"x": 0, "y": -3, "z": 11, "name": "Soil_Dirt"}, {"x": 0, "y": -2, "z": 11, "name": "Soil_Dirt"}, {"x": 0, "y": -1, "z": 11, "name": "Soil_Dirt"}, {"x": 0, "y": 0, "z": 11, "name": "Soil_Grass"}, {"x": 0, "y": -3, "z": 12, "name": "Soil_Dirt"}, {"x": 0, "y": -2, "z": 12, "name": "Soil_Dirt"}, {"x": 0, "y": -1, "z": 12, "name": "Soil_Dirt"}, {"x": 0, "y": 0, "z": 12, "name": "Soil_Grass"}, {"x": 0, "y": -3, "z": 13, "name": "Soil_Dirt"}, {"x": 0, "y": -2, "z": 13, "name": "Soil_Dirt"}, {"x": 0, "y": -1, "z": 13, "name": "Soil_Dirt"}, {"x": 0, "y": 0, "z": 13, "name": "Soil_Grass"}, {"x": 0, "y": -3, "z": 14, "name": "Soil_Dirt"}, {"x": 0, "y": -2, "z": 14, "name": "Soil_Dirt"}, {"x": 0, "y": -1, "z": 14, "name": "Soil_Dirt"}, {"x": 0, "y": 0, "z": 14, "name": "Soil_Grass"}, {"x": 0, "y": -3, "z": 15, "name": "Soil_Dirt"}, {"x": 0, "y": -2, "z": 15, "name": "Soil_Dirt"}, {"x": 0, "y": -1, "z": 15, "name": "Soil_Dirt"}, {"x": 0, "y": 0, "z": 15, "name": "Soil_Grass"}, {"x": 0, "y": -3, "z": 16, "name": "Soil_Dirt"}, {"x": 0, "y": -2, "z": 16, "name": "Soil_Dirt"}, {"x": 0, "y": -1, "z": 16, "name": "Soil_Dirt"}, {"x": 0, "y": 0, "z": 16, "name": "Soil_Grass"}, {"x": 0, "y": -3, "z": 17, "name": "Soil_Dirt"}, {"x": 0, "y": -2, "z": 17, "name": "Soil_Dirt"}, {"x": 0, "y": -1, "z": 17, "name": "Soil_Dirt"}, {"x": 0, "y": 0, "z": 17, "name": "Soil_Grass"}, {"x": 0, "y": -3, "z": 18, "name": "Soil_Dirt"}, {"x": 0, "y": -2, "z": 18, "name": "Soil_Dirt"}, {"x": 0, "y": -1, "z": 18, "name": "Soil_Dirt"}, {"x": 0, "y": 0, "z": 18, "name": "Soil_Grass"}, {"x": 0, "y": -3, "z": 19, "name": "Soil_Dirt"}, {"x": 0, "y": -2, "z": 19, "name": "Soil_Dirt"}, {"x": 0, "y": -1, "z": 19, "name": "Soil_Dirt"}, {"x": 0, "y": 0, "z": 19, "name": "Soil_Grass"}, {"x": 0, "y": -3, "z": 20, "name": "Soil_Dirt"}, {"x": 0, "y": -2, "z": 20, "name": "Soil_Dirt"}, {"x": 0, "y": -1, "z": 20, "name": "Soil_Dirt"}, {"x": 0, "y": 0, "z": 20, "name": "Soil_Grass"}, {"x": 0, "y": -3, "z": 21, "name": "Soil_Dirt"}, {"x": 0, "y": -2, "z": 21, "name": "Soil_Dirt"}, {"x": 0, "y": -1, "z": 21, "name": "Soil_Dirt"}, {"x": 0, "y": 0, "z": 21, "name": "Soil_Grass"}, {"x": 0, "y": -3, "z": 22, "name": "Soil_Dirt"}, {"x": 0, "y": -2, "z": 22, "name": "Soil_Dirt"}, {"x": 0, "y": -1, "z": 22, "name": "Soil_Dirt"}, {"x": 0, "y": 0, "z": 22, "name": "Soil_Grass"}, {"x": 0, "y": -3, "z": 23, "name": "Soil_Dirt"}, {"x": 0, "y": -2, "z": 23, "name": "Soil_Dirt"}, {"x": 0, "y": -1, "z": 23, "name": "Soil_Dirt"}, {"x": 0, "y": 0, "z": 23, "name": "Soil_Grass"}, {"x": 0, "y": -3, "z": 24, "name": "Soil_Dirt"}, {"x": 0, "y": -2, "z": 24, "name": "Soil_Dirt"}, {"x": 0, "y": -1, "z": 24, "name": "Soil_Dirt"}, {"x": 0, "y": 0, "z": 24, "name": "Soil_Grass"}, {"x": 0, "y": -3, "z": 25, "name": "Soil_Dirt"}, {"x": 0, "y": -2, "z": 25, "name": "Soil_Dirt"}, {"x": 0, "y": -1, "z": 25, "name": "Soil_Dirt"}, {"x": 0, "y": 0, "z": 25, "name": "Soil_Grass"}, {"x": 0, "y": -3, "z": 26, "name": "Soil_Dirt"}, {"x": 0, "y": -2, "z": 26, "name": "Soil_Dirt"}, {"x": 0, "y": -1, "z": 26, "name": "Soil_Dirt"}, {"x": 0, "y": 0, "z": 26, "name": "Soil_Grass"}, {"x": 0, "y": -3, "z": 27, "name": "Soil_Dirt"}, {"x": 0, "y": -2, "z": 27, "name": "Soil_Dirt"}, {"x": 0, "y": -1, "z": 27, "name": "Soil_Dirt"}, {"x": 0, "y": 0, "z": 27, "name": "Soil_Grass"}, {"x": 0, "y": -3, "z": 28, "name": "Soil_Dirt"}, {"x": 0, "y": -2, "z": 28, "name": "Soil_Dirt"}, {"x": 0, "y": -1, "z": 28, "name": "Soil_Dirt"}, {"x": 0, "y": 0, "z": 28, "name": "Soil_Grass"}, {"x": 0, "y": -3, "z": 29, "name": "Soil_Dirt"}, {"x": 0, "y": -2, "z": 29, "name": "Soil_Dirt"}, {"x": 0, "y": -1, "z": 29, "name": "Soil_Dirt"}, {"x": 0, "y": 0, "z": 29, "name": "Soil_Grass"}, {"x": 0, "y": -3, "z": 30, "name": "Soil_Dirt"}, {"x": 0, "y": -2, "z": 30, "name": "Soil_Dirt"}, {"x": 0, "y": -1, "z": 30, "name": "Soil_Dirt"}, {"x": 0, "y": 0, "z": 30, "name": "Soil_Grass"}, {"x": 0, "y": -3, "z": 31, "name": "Soil_Dirt"}, {"x": 0, "y": -2, "z": 31, "name": "Soil_Dirt"}, {"x": 0, "y": -1, "z": 31, "name": "Soil_Dirt"}, {"x": 0, "y": 0, "z": 31, "name": "Soil_Grass"}, {"x": 1, "y": -3, "z": 0, "name": "Soil_Dirt"}, {"x": 1, "y": -2, "z": 0, "name": "Soil_Dirt"}, {"x": 1, "y": -1, "z": 0, "name": "Soil_Dirt"}, {"x": 1, "y": 0, "z": 0, "name": "Soil_Grass"}, {"x": 1, "y": -3, "z": 1, "name": "Soil_Dirt"}, {"x": 1, "y": -2, "z": 1, "name": "Soil_Dirt"}, {"x": 1, "y": -1, "z": 1, "name": "Soil_Dirt"}, {"x": 1, "y": 0, "z": 1, "name": "Soil_Grass"}, {"x": 1, "y": -3, "z": 2, "name": "Soil_Dirt"}, {"x": 1, "y": -2, "z": 2, "name": "Soil_Dirt"}, {"x": 1, "y": -1, "z": 2, "name": "Soil_Dirt"}, {"x": 1, "y": 0, "z": 2, "name": "Soil_Grass"}, {"x": 1, "y": -3, "z": 3, "name": "Soil_Dirt"}, {"x": 1, "y": -2, "z": 3, "name": "Soil_Dirt"}, {"x": 1, "y": -1, "z": 3, "name": "Soil_Dirt"}, {"x": 1, "y": 0, "z": 3, "name": "Soil_Grass"}, {"x": 1, "y": -3, "z": 4, "name": "Soil_Dirt"}, {"x": 1, "y": -2, "z": 4, "name": "Soil_Dirt"}, {"x": 1, "y": -1, "z": 4, "name": "Soil_Dirt"}, {"x": 1, "y": 0, "z": 4, "name": "Soil_Grass"}, {"x": 1, "y": -3, "z": 5, "name": "Soil_Dirt"}, {"x": 1, "y": -2, "z": 5, "name": "Soil_Dirt"}, {"x": 1, "y": -1, "z": 5, "name": "Soil_Dirt"}, {"x": 1, "y": 0, "z": 5, "name": "Soil_Grass"}, {"x": 1, "y": -3, "z": 6, "name": "Soil_Dirt"}, {"x": 1, "y": -2, "z": 6, "name": "Soil_Dirt"}, {"x": 1, "y": -1, "z": 6, "name": "Soil_Dirt"}, {"x": 1, "y": 0, "z": 6, "name": "Soil_Grass"}, {"x": 1, "y": -3, "z": 7, "name": "Soil_Dirt"}, {"x": 1, "y": -2, "z": 7, "name": "Soil_Dirt"}, {"x": 1, "y": -1, "z": 7, "name": "Soil_Dirt"}, {"x": 1, "y": 0, "z": 7, "name": "Soil_Grass"}, {"x": 1, "y": -3, "z": 8, "name": "Soil_Dirt"}, {"x": 1, "y": -2, "z": 8, "name": "Soil_Dirt"}, {"x": 1, "y": -1, "z": 8, "name": "Soil_Dirt"}, {"x": 1, "y": 0, "z": 8, "name": "Soil_Grass"}, {"x": 1, "y": -3, "z": 9, "name": "Soil_Dirt"}, {"x": 1, "y": -2, "z": 9, "name": "Soil_Dirt"}, {"x": 1, "y": -1, "z": 9, "name": "Soil_Dirt"}, {"x": 1, "y": 0, "z": 9, "name": "Soil_Grass"}, {"x": 1, "y": -3, "z": 10, "name": "Soil_Dirt"}, {"x": 1, "y": -2, "z": 10, "name": "Soil_Dirt"}, {"x": 1, "y": -1, "z": 10, "name": "Soil_Dirt"}, {"x": 1, "y": 0, "z": 10, "name": "Soil_Grass"}, {"x": 1, "y": -3, "z": 11, "name": "Soil_Dirt"}, {"x": 1, "y": -2, "z": 11, "name": "Soil_Dirt"}, {"x": 1, "y": -1, "z": 11, "name": "Soil_Dirt"}, {"x": 1, "y": 0, "z": 11, "name": "Soil_Grass"}, {"x": 1, "y": -3, "z": 12, "name": "Soil_Dirt"}, {"x": 1, "y": -2, "z": 12, "name": "Soil_Dirt"}, {"x": 1, "y": -1, "z": 12, "name": "Soil_Dirt"}, {"x": 1, "y": 0, "z": 12, "name": "Soil_Grass"}, {"x": 1, "y": -3, "z": 13, "name": "Soil_Dirt"}, {"x": 1, "y": -2, "z": 13, "name": "Soil_Dirt"}, {"x": 1, "y": -1, "z": 13, "name": "Soil_Dirt"}, {"x": 1, "y": 0, "z": 13, "name": "Soil_Grass"}, {"x": 1, "y": -3, "z": 14, "name": "Soil_Dirt"}, {"x": 1, "y": -2, "z": 14, "name": "Soil_Dirt"}, {"x": 1, "y": -1, "z": 14, "name": "Soil_Dirt"}, {"x": 1, "y": 0, "z": 14, "name": "Soil_Grass"}, {"x": 1, "y": -3, "z": 15, "name": "Soil_Dirt"}, {"x": 1, "y": -2, "z": 15, "name": "Soil_Dirt"}, {"x": 1, "y": -1, "z": 15, "name": "Soil_Dirt"}, {"x": 1, "y": 0, "z": 15, "name": "Soil_Grass"}, {"x": 1, "y": -3, "z": 16, "name": "Soil_Dirt"}, {"x": 1, "y": -2, "z": 16, "name": "Soil_Dirt"}, {"x": 1, "y": -1, "z": 16, "name": "Soil_Dirt"}, {"x": 1, "y": 0, "z": 16, "name": "Soil_Grass"}, {"x": 1, "y": -3, "z": 17, "name": "Soil_Dirt"}, {"x": 1, "y": -2, "z": 17, "name": "Soil_Dirt"}, {"x": 1, "y": -1, "z": 17, "name": "Soil_Dirt"}, {"x": 1, "y": 0, "z": 17, "name": "Soil_Grass"}, {"x": 1, "y": -3, "z": 18, "name": "Soil_Dirt"}, {"x": 1, "y": -2, "z": 18, "name": "Soil_Dirt"}, {"x": 1, "y": -1, "z": 18, "name": "Soil_Dirt"}, {"x": 1, "y": 0, "z": 18, "name": "Soil_Grass"}, {"x": 1, "y": -3, "z": 19, "name": "Soil_Dirt"}, {"x": 1, "y": -2, "z": 19, "name": "Soil_Dirt"}, {"x": 1, "y": -1, "z": 19, "name": "Soil_Dirt"}, {"x": 1, "y": 0, "z": 19, "name": "Soil_Grass"}, {"x": 1, "y": -3, "z": 20, "name": "Soil_Dirt"}, {"x": 1, "y": -2, "z": 20, "name": "Soil_Dirt"}, {"x": 1, "y": -1, "z": 20, "name": "Soil_Dirt"}, {"x": 1, "y": 0, "z": 20, "name": "Soil_Grass"}, {"x": 1, "y": -3, "z": 21, "name": "Soil_Dirt"}, {"x": 1, "y": -2, "z": 21, "name": "Soil_Dirt"}, {"x": 1, "y": -1, "z": 21, "name": "Soil_Dirt"}, {"x": 1, "y": 0, "z": 21, "name": "Soil_Grass"}, {"x": 1, "y": -3, "z": 22, "name": "Soil_Dirt"}, {"x": 1, "y": -2, "z": 22, "name": "Soil_Dirt"}, {"x": 1, "y": -1, "z": 22, "name": "Soil_Dirt"}, {"x": 1, "y": 0, "z": 22, "name": "Soil_Grass"}, {"x": 1, "y": -3, "z": 23, "name": "Soil_Dirt"}, {"x": 1, "y": -2, "z": 23, "name": "Soil_Dirt"}, {"x": 1, "y": -1, "z": 23, "name": "Soil_Dirt"}, {"x": 1, "y": 0, "z": 23, "name": "Soil_Grass"}, {"x": 1, "y": -3, "z": 24, "name": "Soil_Dirt"}, {"x": 1, "y": -2, "z": 24, "name": "Soil_Dirt"}, {"x": 1, "y": -1, "z": 24, "name": "Soil_Dirt"}, {"x": 1, "y": 0, "z": 24, "name": "Soil_Grass"}, {"x": 1, "y": -3, "z": 25, "name": "Soil_Dirt"}, {"x": 1, "y": -2, "z": 25, "name": "Soil_Dirt"}, {"x": 1, "y": -1, "z": 25, "name": "Soil_Dirt"}, {"x": 1, "y": 0, "z": 25, "name": "Soil_Grass"}, {"x": 1, "y": -3, "z": 26, "name": "Soil_Dirt"}, {"x": 1, "y": -2, "z": 26, "name": "Soil_Dirt"}, {"x": 1, "y": -1, "z": 26, "name": "Soil_Dirt"}, {"x": 1, "y": 0, "z": 26, "name": "Soil_Grass"}, {"x": 1, "y": -3, "z": 27, "name": "Soil_Dirt"}, {"x": 1, "y": -2, "z": 27, "name": "Soil_Dirt"}, {"x": 1, "y": -1, "z": 27, "name": "Soil_Dirt"}, {"x": 1, "y": 0, "z": 27, "name": "Soil_Grass"}, {"x": 1, "y": -3, "z": 28, "name": "Soil_Dirt"}, {"x": 1, "y": -2, "z": 28, "name": "Soil_Dirt"}, {"x": 1, "y": -1, "z": 28, "name": "Soil_Dirt"}, {"x": 1, "y": 0, "z": 28, "name": "Soil_Grass"}, {"x": 1, "y": -3, "z": 29, "name": "Soil_Dirt"}, {"x": 1, "y": -2, "z": 29, "name": "Soil_Dirt"}, {"x": 1, "y": -1, "z": 29, "name": "Soil_Dirt"}, {"x": 1, "y": 0, "z": 29, "name": "Soil_Grass"}, {"x": 1, "y": -3, "z": 30, "name": "Soil_Dirt"}, {"x": 1, "y": -2, "z": 30, "name": "Soil_Dirt"}, {"x": 1, "y": -1, "z": 30, "name": "Soil_Dirt"}, {"x": 1, "y": 0, "z": 30, "name": "Soil_Grass"}, {"x": 1, "y": -3, "z": 31, "name": "Soil_Dirt"}, {"x": 1, "y": -2, "z": 31, "name": "Soil_Dirt"}, {"x": 1, "y": -1, "z": 31, "name": "Soil_Dirt"}, {"x": 1, "y": 0, "z": 31, "name": "Soil_Grass"}, {"x": 2, "y": -3, "z": 0, "name": "Soil_Dirt"}, {"x": 2, "y": -2, "z": 0, "name": "Soil_Dirt"}, {"x": 2, "y": -1, "z": 0, "name": "Soil_Dirt"}, {"x": 2, "y": 0, "z": 0, "name": "Soil_Grass"}, {"x": 2, "y": -3, "z": 1, "name": "Soil_Dirt"}, {"x": 2, "y": -2, "z": 1, "name": "Soil_Dirt"}, {"x": 2, "y": -1, "z": 1, "name": "Soil_Dirt"}, {"x": 2, "y": 0, "z": 1, "name": "Soil_Grass"}, {"x": 2, "y": -3, "z": 2, "name": "Soil_Dirt"}, {"x": 2, "y": -2, "z": 2, "name": "Soil_Dirt"}, {"x": 2, "y": -1, "z": 2, "name": "Soil_Dirt"}, {"x": 2, "y": 0, "z": 2, "name": "Soil_Grass"}, {"x": 2, "y": -3, "z": 3, "name": "Soil_Dirt"}, {"x": 2, "y": -2, "z": 3, "name": "Soil_Dirt"}, {"x": 2, "y": -1, "z": 3, "name": "Soil_Dirt"}, {"x": 2, "y": 0, "z": 3, "name": "Soil_Grass"}, {"x": 2, "y": -3, "z": 4, "name": "Soil_Dirt"}, {"x": 2, "y": -2, "z": 4, "name": "Soil_Dirt"}, {"x": 2, "y": -1, "z": 4, "name": "Soil_Dirt"}, {"x": 2, "y": 0, "z": 4, "name": "Soil_Grass"}, {"x": 2, "y": -3, "z": 5, "name": "Soil_Dirt"}, {"x": 2, "y": -2, "z": 5, "name": "Soil_Dirt"}, {"x": 2, "y": -1, "z": 5, "name": "Soil_Dirt"}, {"x": 2, "y": 0, "z": 5, "name": "Soil_Grass"}, {"x": 2, "y": -3, "z": 6, "name": "Soil_Dirt"}, {"x": 2, "y": -2, "z": 6, "name": "Soil_Dirt"}, {"x": 2, "y": -1, "z": 6, "name": "Soil_Dirt"}, {"x": 2, "y": 0, "z": 6, "name": "Soil_Grass"}, {"x": 2, "y": -3, "z": 7, "name": "Soil_Dirt"}, {"x": 2, "y": -2, "z": 7, "name": "Soil_Dirt"}, {"x": 2, "y": -1, "z": 7, "name": "Soil_Dirt"}, {"x": 2, "y": 0, "z": 7, "name": "Soil_Grass"}, {"x": 2, "y": -3, "z": 8, "name": "Soil_Dirt"}, {"x": 2, "y": -2, "z": 8, "name": "Soil_Dirt"}, {"x": 2, "y": -1, "z": 8, "name": "Soil_Dirt"}, {"x": 2, "y": 0, "z": 8, "name": "Soil_Grass"}, {"x": 2, "y": -3, "z": 9, "name": "Soil_Dirt"}, {"x": 2, "y": -2, "z": 9, "name": "Soil_Dirt"}, {"x": 2, "y": -1, "z": 9, "name": "Soil_Dirt"}, {"x": 2, "y": 0, "z": 9, "name": "Soil_Grass"}, {"x": 2, "y": -3, "z": 10, "name": "Soil_Dirt"}, {"x": 2, "y": -2, "z": 10, "name": "Soil_Dirt"}, {"x": 2, "y": -1, "z": 10, "name": "Soil_Dirt"}, {"x": 2, "y": 0, "z": 10, "name": "Soil_Grass"}, {"x": 2, "y": -3, "z": 11, "name": "Soil_Dirt"}, {"x": 2, "y": -2, "z": 11, "name": "Soil_Dirt"}, {"x": 2, "y": -1, "z": 11, "name": "Soil_Dirt"}, {"x": 2, "y": 0, "z": 11, "name": "Soil_Grass"}, {"x": 2, "y": -3, "z": 12, "name": "Soil_Dirt"}, {"x": 2, "y": -2, "z": 12, "name": "Soil_Dirt"}, {"x": 2, "y": -1, "z": 12, "name": "Soil_Dirt"}, {"x": 2, "y": 0, "z": 12, "name": "Soil_Grass"}, {"x": 2, "y": -3, "z": 13, "name": "Soil_Dirt"}, {"x": 2, "y": -2, "z": 13, "name": "Soil_Dirt"}, {"x": 2, "y": -1, "z": 13, "name": "Soil_Dirt"}, {"x": 2, "y": 0, "z": 13, "name": "Soil_Grass"}, {"x": 2, "y": -3, "z": 14, "name": "Soil_Dirt"}, {"x": 2, "y": -2, "z": 14, "name": "Soil_Dirt"}, {"x": 2, "y": -1, "z": 14, "name": "Soil_Dirt"}, {"x": 2, "y": 0, "z": 14, "name": "Soil_Grass"}, {"x": 2, "y": -3, "z": 15, "name": "Soil_Dirt"}, {"x": 2, "y": -2, "z": 15, "name": "Soil_Dirt"}, {"x": 2, "y": -1, "z": 15, "name": "Soil_Dirt"}, {"x": 2, "y": 0, "z": 15, "name": "Soil_Grass"}, {"x": 2, "y": -3, "z": 16, "name": "Soil_Dirt"}, {"x": 2, "y": -2, "z": 16, "name": "Soil_Dirt"}, {"x": 2, "y": -1, "z": 16, "name": "Soil_Dirt"}, {"x": 2, "y": 0, "z": 16, "name": "Soil_Grass"}, {"x": 2, "y": -3, "z": 17, "name": "Soil_Dirt"}, {"x": 2, "y": -2, "z": 17, "name": "Soil_Dirt"}, {"x": 2, "y": -1, "z": 17, "name": "Soil_Dirt"}, {"x": 2, "y": 0, "z": 17, "name": "Soil_Grass"}, {"x": 2, "y": -3, "z": 18, "name": "Soil_Dirt"}, {"x": 2, "y": -2, "z": 18, "name": "Soil_Dirt"}, {"x": 2, "y": -1, "z": 18, "name": "Soil_Dirt"}, {"x": 2, "y": 0, "z": 18, "name": "Soil_Grass"}, {"x": 2, "y": -3, "z": 19, "name": "Soil_Dirt"}, {"x": 2, "y": -2, "z": 19, "name": "Soil_Dirt"}, {"x": 2, "y": -1, "z": 19, "name": "Soil_Dirt"}, {"x": 2, "y": 0, "z": 19, "name": "Soil_Grass"}, {"x": 2, "y": -3, "z": 20, "name": "Soil_Dirt"}, {"x": 2, "y": -2, "z": 20, "name": "Soil_Dirt"}, {"x": 2, "y": -1, "z": 20, "name": "Soil_Dirt"}, {"x": 2, "y": 0, "z": 20, "name": "Soil_Grass"}, {"x": 2, "y": -3, "z": 21, "name": "Soil_Dirt"}, {"x": 2, "y": -2, "z": 21, "name": "Soil_Dirt"}, {"x": 2, "y": -1, "z": 21, "name": "Soil_Dirt"}, {"x": 2, "y": 0, "z": 21, "name": "Soil_Grass"}, {"x": 2, "y": -3, "z": 22, "name": "Soil_Dirt"}, {"x": 2, "y": -2, "z": 22, "name": "Soil_Dirt"}, {"x": 2, "y": -1, "z": 22, "name": "Soil_Dirt"}, {"x": 2, "y": 0, "z": 22, "name": "Soil_Grass"}, {"x": 2, "y": -3, "z": 23, "name": "Soil_Dirt"}, {"x": 2, "y": -2, "z": 23, "name": "Soil_Dirt"}, {"x": 2, "y": -1, "z": 23, "name": "Soil_Dirt"}, {"x": 2, "y": 0, "z": 23, "name": "Soil_Grass"}, {"x": 2, "y": -3, "z": 24, "name": "Soil_Dirt"}, {"x": 2, "y": -2, "z": 24, "name": "Soil_Dirt"}, {"x": 2, "y": -1, "z": 24, "name": "Soil_Dirt"}, {"x": 2, "y": 0, "z": 24, "name": "Soil_Grass"}, {"x": 2, "y": -3, "z": 25, "name": "Soil_Dirt"}, {"x": 2, "y": -2, "z": 25, "name": "Soil_Dirt"}, {"x": 2, "y": -1, "z": 25, "name": "Soil_Dirt"}, {"x": 2, "y": 0, "z": 25, "name": "Soil_Grass"}, {"x": 2, "y": -3, "z": 26, "name": "Soil_Dirt"}, {"x": 2, "y": -2, "z": 26, "name": "Soil_Dirt"}, {"x": 2, "y": -1, "z": 26, "name": "Soil_Dirt"}, {"x": 2, "y": 0, "z": 26, "name": "Soil_Grass"}, {"x": 2, "y": -3, "z": 27, "name": "Soil_Dirt"}, {"x": 2, "y": -2, "z": 27, "name": "Soil_Dirt"}, {"x": 2, "y": -1, "z": 27, "name": "Soil_Dirt"}, {"x": 2, "y": 0, "z": 27, "name": "Soil_Grass"}, {"x": 2, "y": -3, "z": 28, "name": "Soil_Dirt"}, {"x": 2, "y": -2, "z": 28, "name": "Soil_Dirt"}, {"x": 2, "y": -1, "z": 28, "name": "Soil_Dirt"}, {"x": 2, "y": 0, "z": 28, "name": "Soil_Grass"}, {"x": 2, "y": -3, "z": 29, "name": "Soil_Dirt"}, {"x": 2, "y": -2, "z": 29, "name": "Soil_Dirt"}, {"x": 2, "y": -1, "z": 29, "name": "Soil_Dirt"}, {"x": 2, "y": 0, "z": 29, "name": "Soil_Grass"}, {"x": 2, "y": -3, "z": 30, "name": "Soil_Dirt"}, {"x": 2, "y": -2, "z": 30, "name": "Soil_Dirt"}, {"x": 2, "y": -1, "z": 30, "name": "Soil_Dirt"}, {"x": 2, "y": 0, "z": 30, "name": "Soil_Grass"}, {"x": 2, "y": -3, "z": 31, "name": "Soil_Dirt"}, {"x": 2, "y": -2, "z": 31, "name": "Soil_Dirt"}, {"x": 2, "y": -1, "z": 31, "name": "Soil_Dirt"}, {"x": 2, "y": 0, "z": 31, "name": "Soil_Grass"}, {"x": 3, "y": -3, "z": 0, "name": "Soil_Dirt"}, {"x": 3, "y": -2, "z": 0, "name": "Soil_Dirt"}, {"x": 3, "y": -1, "z": 0, "name": "Soil_Dirt"}, {"x": 3, "y": 0, "z": 0, "name": "Soil_Grass"}, {"x": 3, "y": -3, "z": 1, "name": "Soil_Dirt"}, {"x": 3, "y": -2, "z": 1, "name": "Soil_Dirt"}, {"x": 3, "y": -1, "z": 1, "name": "Soil_Dirt"}, {"x": 3, "y": 0, "z": 1, "name": "Soil_Grass"}, {"x": 3, "y": -3, "z": 2, "name": "Soil_Dirt"}, {"x": 3, "y": -2, "z": 2, "name": "Soil_Dirt"}, {"x": 3, "y": -1, "z": 2, "name": "Soil_Dirt"}, {"x": 3, "y": 0, "z": 2, "name": "Soil_Grass"}, {"x": 3, "y": -3, "z": 3, "name": "Soil_Dirt"}, {"x": 3, "y": -2, "z": 3, "name": "Soil_Dirt"}, {"x": 3, "y": -1, "z": 3, "name": "Soil_Dirt"}, {"x": 3, "y": 0, "z": 3, "name": "Soil_Grass"}, {"x": 3, "y": -3, "z": 4, "name": "Soil_Dirt"}, {"x": 3, "y": -2, "z": 4, "name": "Soil_Dirt"}, {"x": 3, "y": -1, "z": 4, "name": "Soil_Dirt"}, {"x": 3, "y": 0, "z": 4, "name": "Soil_Grass"}, {"x": 3, "y": -3, "z": 5, "name": "Soil_Dirt"}, {"x": 3, "y": -2, "z": 5, "name": "Soil_Dirt"}, {"x": 3, "y": -1, "z": 5, "name": "Soil_Dirt"}, {"x": 3, "y": 0, "z": 5, "name": "Soil_Grass"}, {"x": 3, "y": -3, "z": 6, "name": "Soil_Dirt"}, {"x": 3, "y": -2, "z": 6, "name": "Soil_Dirt"}, {"x": 3, "y": -1, "z": 6, "name": "Soil_Dirt"}, {"x": 3, "y": 0, "z": 6, "name": "Soil_Grass"}, {"x": 3, "y": -3, "z": 7, "name": "Soil_Dirt"}, {"x": 3, "y": -2, "z": 7, "name": "Soil_Dirt"}, {"x": 3, "y": -1, "z": 7, "name": "Soil_Dirt"}, {"x": 3, "y": 0, "z": 7, "name": "Soil_Grass"}, {"x": 3, "y": -3, "z": 8, "name": "Soil_Dirt"}, {"x": 3, "y": -2, "z": 8, "name": "Soil_Dirt"}, {"x": 3, "y": -1, "z": 8, "name": "Soil_Dirt"}, {"x": 3, "y": 0, "z": 8, "name": "Soil_Grass"}, {"x": 3, "y": -3, "z": 9, "name": "Soil_Dirt"}, {"x": 3, "y": -2, "z": 9, "name": "Soil_Dirt"}, {"x": 3, "y": -1, "z": 9, "name": "Soil_Dirt"}, {"x": 3, "y": 0, "z": 9, "name": "Soil_Grass"}, {"x": 3, "y": -3, "z": 10, "name": "Soil_Dirt"}, {"x": 3, "y": -2, "z": 10, "name": "Soil_Dirt"}, {"x": 3, "y": -1, "z": 10, "name": "Soil_Dirt"}, {"x": 3, "y": 0, "z": 10, "name": "Soil_Grass"}, {"x": 3, "y": -3, "z": 11, "name": "Soil_Dirt"}, {"x": 3, "y": -2, "z": 11, "name": "Soil_Dirt"}, {"x": 3, "y": -1, "z": 11, "name": "Soil_Dirt"}, {"x": 3, "y": 0, "z": 11, "name": "Soil_Grass"}, {"x": 3, "y": -3, "z": 12, "name": "Soil_Dirt"}, {"x": 3, "y": -2, "z": 12, "name": "Soil_Dirt"}, {"x": 3, "y": -1, "z": 12, "name": "Soil_Dirt"}, {"x": 3, "y": 0, "z": 12, "name": "Soil_Grass"}, {"x": 3, "y": -3, "z": 13, "name": "Soil_Dirt"}, {"x": 3, "y": -2, "z": 13, "name": "Soil_Dirt"}, {"x": 3, "y": -1, "z": 13, "name": "Soil_Dirt"}, {"x": 3, "y": 0, "z": 13, "name": "Soil_Grass"}, {"x": 3, "y": -3, "z": 14, "name": "Soil_Dirt"}, {"x": 3, "y": -2, "z": 14, "name": "Soil_Dirt"}, {"x": 3, "y": -1, "z": 14, "name": "Soil_Dirt"}, {"x": 3, "y": 0, "z": 14, "name": "Soil_Grass"}, {"x": 3, "y": -3, "z": 15, "name": "Soil_Dirt"}, {"x": 3, "y": -2, "z": 15, "name": "Soil_Dirt"}, {"x": 3, "y": -1, "z": 15, "name": "Soil_Dirt"}, {"x": 3, "y": 0, "z": 15, "name": "Soil_Grass"}, {"x": 3, "y": -3, "z": 16, "name": "Soil_Dirt"}, {"x": 3, "y": -2, "z": 16, "name": "Soil_Dirt"}, {"x": 3, "y": -1, "z": 16, "name": "Soil_Dirt"}, {"x": 3, "y": 0, "z": 16, "name": "Soil_Grass"}, {"x": 3, "y": -3, "z": 17, "name": "Soil_Dirt"}, {"x": 3, "y": -2, "z": 17, "name": "Soil_Dirt"}, {"x": 3, "y": -1, "z": 17, "name": "Soil_Dirt"}, {"x": 3, "y": 0, "z": 17, "name": "Soil_Grass"}, {"x": 3, "y": -3, "z": 18, "name": "Soil_Dirt"}, {"x": 3, "y": -2, "z": 18, "name": "Soil_Dirt"}, {"x": 3, "y": -1, "z": 18, "name": "Soil_Dirt"}, {"x": 3, "y": 0, "z": 18, "name": "Soil_Grass"}, {"x": 3, "y": -3, "z": 19, "name": "Soil_Dirt"}, {"x": 3, "y": -2, "z": 19, "name": "Soil_Dirt"}, {"x": 3, "y": -1, "z": 19, "name": "Soil_Dirt"}, {"x": 3, "y": 0, "z": 19, "name": "Soil_Grass"}, {"x": 3, "y": -3, "z": 20, "name": "Soil_Dirt"}, {"x": 3, "y": -2, "z": 20, "name": "Soil_Dirt"}, {"x": 3, "y": -1, "z": 20, "name": "Soil_Dirt"}, {"x": 3, "y": 0, "z": 20, "name": "Soil_Grass"}, {"x": 3, "y": -3, "z": 21, "name": "Soil_Dirt"}, {"x": 3, "y": -2, "z": 21, "name": "Soil_Dirt"}, {"x": 3, "y": -1, "z": 21, "name": "Soil_Dirt"}, {"x": 3, "y": 0, "z": 21, "name": "Soil_Grass"}, {"x": 3, "y": -3, "z": 22, "name": "Soil_Dirt"}, {"x": 3, "y": -2, "z": 22, "name": "Soil_Dirt"}, {"x": 3, "y": -1, "z": 22, "name": "Soil_Dirt"}, {"x": 3, "y": 0, "z": 22, "name": "Soil_Grass"}, {"x": 3, "y": -3, "z": 23, "name": "Soil_Dirt"}, {"x": 3, "y": -2, "z": 23, "name": "Soil_Dirt"}, {"x": 3, "y": -1, "z": 23, "name": "Soil_Dirt"}, {"x": 3, "y": 0, "z": 23, "name": "Soil_Grass"}, {"x": 3, "y": -3, "z": 24, "name": "Soil_Dirt"}, {"x": 3, "y": -2, "z": 24, "name": "Soil_Dirt"}, {"x": 3, "y": -1, "z": 24, "name": "Soil_Dirt"}, {"x": 3, "y": 0, "z": 24, "name": "Soil_Grass"}, {"x": 3, "y": -3, "z": 25, "name": "Soil_Dirt"}, {"x": 3, "y": -2, "z": 25, "name": "Soil_Dirt"}, {"x": 3, "y": -1, "z": 25, "name": "Soil_Dirt"}, {"x": 3, "y": 0, "z": 25, "name": "Soil_Grass"}, {"x": 3, "y": -3, "z": 26, "name": "Soil_Dirt"}, {"x": 3, "y": -2, "z": 26, "name": "Soil_Dirt"}, {"x": 3, "y": -1, "z": 26, "name": "Soil_Dirt"}, {"x": 3, "y": 0, "z": 26, "name": "Soil_Grass"}, {"x": 3, "y": -3, "z": 27, "name": "Soil_Dirt"}, {"x": 3, "y": -2, "z": 27, "name": "Soil_Dirt"}, {"x": 3, "y": -1, "z": 27, "name": "Soil_Dirt"}, {"x": 3, "y": 0, "z": 27, "name": "Soil_Grass"}, {"x": 3, "y": -3, "z": 28, "name": "Soil_Dirt"}, {"x": 3, "y": -2, "z": 28, "name": "Soil_Dirt"}, {"x": 3, "y": -1, "z": 28, "name": "Soil_Dirt"}, {"x": 3, "y": 0, "z": 28, "name": "Soil_Grass"}, {"x": 3, "y": -3, "z": 29, "name": "Soil_Dirt"}, {"x": 3, "y": -2, "z": 29, "name": "Soil_Dirt"}, {"x": 3, "y": -1, "z": 29, "name": "Soil_Dirt"}, {"x": 3, "y": 0, "z": 29, "name": "Soil_Grass"}, {"x": 3, "y": -3, "z": 30, "name": "Soil_Dirt"}, {"x": 3, "y": -2, "z": 30, "name": "Soil_Dirt"}, {"x": 3, "y": -1, "z": 30, "name": "Soil_Dirt"}, {"x": 3, "y": 0, "z": 30, "name": "Soil_Grass"}, {"x": 3, "y": -3, "z": 31, "name": "Soil_Dirt"}, {"x": 3, "y": -2, "z": 31, "name": "Soil_Dirt"}, {"x": 3, "y": -1, "z": 31, "name": "Soil_Dirt"}, {"x": 3, "y": 0, "z": 31, "name": "Soil_Grass"}, {"x": 4, "y": -3, "z": 0, "name": "Soil_Dirt"}, {"x": 4, "y": -2, "z": 0, "name": "Soil_Dirt"}, {"x": 4, "y": -1, "z": 0, "name": "Soil_Dirt"}, {"x": 4, "y": 0, "z": 0, "name": "Soil_Grass"}, {"x": 4, "y": -3, "z": 1, "name": "Soil_Dirt"}, {"x": 4, "y": -2, "z": 1, "name": "Soil_Dirt"}, {"x": 4, "y": -1, "z": 1, "name": "Soil_Dirt"}, {"x": 4, "y": 0, "z": 1, "name": "Soil_Grass"}, {"x": 4, "y": -3, "z": 2, "name": "Soil_Dirt"}, {"x": 4, "y": -2, "z": 2, "name": "Soil_Dirt"}, {"x": 4, "y": -1, "z": 2, "name": "Soil_Dirt"}, {"x": 4, "y": 0, "z": 2, "name": "Soil_Grass"}, {"x": 4, "y": -3, "z": 3, "name": "Soil_Dirt"}, {"x": 4, "y": -2, "z": 3, "name": "Soil_Dirt"}, {"x": 4, "y": -1, "z": 3, "name": "Soil_Dirt"}, {"x": 4, "y": 0, "z": 3, "name": "Soil_Grass"}, {"x": 4, "y": -3, "z": 4, "name": "Soil_Dirt"}, {"x": 4, "y": -2, "z": 4, "name": "Soil_Dirt"}, {"x": 4, "y": -1, "z": 4, "name": "Soil_Dirt"}, {"x": 4, "y": 0, "z": 4, "name": "Soil_Grass"}, {"x": 4, "y": -3, "z": 5, "name": "Soil_Dirt"}, {"x": 4, "y": -2, "z": 5, "name": "Soil_Dirt"}, {"x": 4, "y": -1, "z": 5, "name": "Soil_Dirt"}, {"x": 4, "y": 0, "z": 5, "name": "Soil_Grass"}, {"x": 4, "y": -3, "z": 6, "name": "Soil_Dirt"}, {"x": 4, "y": -2, "z": 6, "name": "Soil_Dirt"}, {"x": 4, "y": -1, "z": 6, "name": "Soil_Dirt"}, {"x": 4, "y": 0, "z": 6, "name": "Soil_Grass"}, {"x": 4, "y": -3, "z": 7, "name": "Soil_Dirt"}, {"x": 4, "y": -2, "z": 7, "name": "Soil_Dirt"}, {"x": 4, "y": -1, "z": 7, "name": "Soil_Dirt"}, {"x": 4, "y": 0, "z": 7, "name": "Soil_Grass"}, {"x": 4, "y": -3, "z": 8, "name": "Soil_Dirt"}, {"x": 4, "y": -2, "z": 8, "name": "Soil_Dirt"}, {"x": 4, "y": -1, "z": 8, "name": "Soil_Dirt"}, {"x": 4, "y": 0, "z": 8, "name": "Soil_Grass"}, {"x": 4, "y": -3, "z": 9, "name": "Soil_Dirt"}, {"x": 4, "y": -2, "z": 9, "name": "Soil_Dirt"}, {"x": 4, "y": -1, "z": 9, "name": "Soil_Dirt"}, {"x": 4, "y": 0, "z": 9, "name": "Soil_Grass"}, {"x": 4, "y": -3, "z": 10, "name": "Soil_Dirt"}, {"x": 4, "y": -2, "z": 10, "name": "Soil_Dirt"}, {"x": 4, "y": -1, "z": 10, "name": "Soil_Dirt"}, {"x": 4, "y": 0, "z": 10, "name": "Soil_Grass"}, {"x": 4, "y": -3, "z": 11, "name": "Soil_Dirt"}, {"x": 4, "y": -2, "z": 11, "name": "Soil_Dirt"}, {"x": 4, "y": -1, "z": 11, "name": "Soil_Dirt"}, {"x": 4, "y": 0, "z": 11, "name": "Soil_Grass"}, {"x": 4, "y": -3, "z": 12, "name": "Soil_Dirt"}, {"x": 4, "y": -2, "z": 12, "name": "Soil_Dirt"}, {"x": 4, "y": -1, "z": 12, "name": "Soil_Dirt"}, {"x": 4, "y": 0, "z": 12, "name": "Soil_Grass"}, {"x": 4, "y": -3, "z": 13, "name": "Soil_Dirt"}, {"x": 4, "y": -2, "z": 13, "name": "Soil_Dirt"}, {"x": 4, "y": -1, "z": 13, "name": "Soil_Dirt"}, {"x": 4, "y": 0, "z": 13, "name": "Soil_Grass"}, {"x": 4, "y": -3, "z": 14, "name": "Soil_Dirt"}, {"x": 4, "y": -2, "z": 14, "name": "Soil_Dirt"}, {"x": 4, "y": -1, "z": 14, "name": "Soil_Dirt"}, {"x": 4, "y": 0, "z": 14, "name": "Soil_Grass"}, {"x": 4, "y": -3, "z": 15, "name": "Soil_Dirt"}, {"x": 4, "y": -2, "z": 15, "name": "Soil_Dirt"}, {"x": 4, "y": -1, "z": 15, "name": "Soil_Dirt"}, {"x": 4, "y": 0, "z": 15, "name": "Soil_Grass"}, {"x": 4, "y": -3, "z": 16, "name": "Soil_Dirt"}, {"x": 4, "y": -2, "z": 16, "name": "Soil_Dirt"}, {"x": 4, "y": -1, "z": 16, "name": "Soil_Dirt"}, {"x": 4, "y": 0, "z": 16, "name": "Soil_Grass"}, {"x": 4, "y": -3, "z": 17, "name": "Soil_Dirt"}, {"x": 4, "y": -2, "z": 17, "name": "Soil_Dirt"}, {"x": 4, "y": -1, "z": 17, "name": "Soil_Dirt"}, {"x": 4, "y": 0, "z": 17, "name": "Soil_Grass"}, {"x": 4, "y": -3, "z": 18, "name": "Soil_Dirt"}, {"x": 4, "y": -2, "z": 18, "name": "Soil_Dirt"}, {"x": 4, "y": -1, "z": 18, "name": "Soil_Dirt"}, {"x": 4, "y": 0, "z": 18, "name": "Soil_Grass"}, {"x": 4, "y": -3, "z": 19, "name": "Soil_Dirt"}, {"x": 4, "y": -2, "z": 19, "name": "Soil_Dirt"}, {"x": 4, "y": -1, "z": 19, "name": "Soil_Dirt"}, {"x": 4, "y": 0, "z": 19, "name": "Soil_Grass"}, {"x": 4, "y": -3, "z": 20, "name": "Soil_Dirt"}, {"x": 4, "y": -2, "z": 20, "name": "Soil_Dirt"}, {"x": 4, "y": -1, "z": 20, "name": "Soil_Dirt"}, {"x": 4, "y": 0, "z": 20, "name": "Soil_Grass"}, {"x": 4, "y": -3, "z": 21, "name": "Soil_Dirt"}, {"x": 4, "y": -2, "z": 21, "name": "Soil_Dirt"}, {"x": 4, "y": -1, "z": 21, "name": "Soil_Dirt"}, {"x": 4, "y": 0, "z": 21, "name": "Soil_Grass"}, {"x": 4, "y": -3, "z": 22, "name": "Soil_Dirt"}, {"x": 4, "y": -2, "z": 22, "name": "Soil_Dirt"}, {"x": 4, "y": -1, "z": 22, "name": "Soil_Dirt"}, {"x": 4, "y": 0, "z": 22, "name": "Soil_Grass"}, {"x": 4, "y": -3, "z": 23, "name": "Soil_Dirt"}, {"x": 4, "y": -2, "z": 23, "name": "Soil_Dirt"}, {"x": 4, "y": -1, "z": 23, "name": "Soil_Dirt"}, {"x": 4, "y": 0, "z": 23, "name": "Soil_Grass"}, {"x": 4, "y": -3, "z": 24, "name": "Soil_Dirt"}, {"x": 4, "y": -2, "z": 24, "name": "Soil_Dirt"}, {"x": 4, "y": -1, "z": 24, "name": "Soil_Dirt"}, {"x": 4, "y": 0, "z": 24, "name": "Soil_Grass"}, {"x": 4, "y": -3, "z": 25, "name": "Soil_Dirt"}, {"x": 4, "y": -2, "z": 25, "name": "Soil_Dirt"}, {"x": 4, "y": -1, "z": 25, "name": "Soil_Dirt"}, {"x": 4, "y": 0, "z": 25, "name": "Soil_Grass"}, {"x": 4, "y": -3, "z": 26, "name": "Soil_Dirt"}, {"x": 4, "y": -2, "z": 26, "name": "Soil_Dirt"}, {"x": 4, "y": -1, "z": 26, "name": "Soil_Dirt"}, {"x": 4, "y": 0, "z": 26, "name": "Soil_Grass"}, {"x": 4, "y": -3, "z": 27, "name": "Soil_Dirt"}, {"x": 4, "y": -2, "z": 27, "name": "Soil_Dirt"}, {"x": 4, "y": -1, "z": 27, "name": "Soil_Dirt"}, {"x": 4, "y": 0, "z": 27, "name": "Soil_Grass"}, {"x": 4, "y": -3, "z": 28, "name": "Soil_Dirt"}, {"x": 4, "y": -2, "z": 28, "name": "Soil_Dirt"}, {"x": 4, "y": -1, "z": 28, "name": "Soil_Dirt"}, {"x": 4, "y": 0, "z": 28, "name": "Soil_Grass"}, {"x": 4, "y": -3, "z": 29, "name": "Soil_Dirt"}, {"x": 4, "y": -2, "z": 29, "name": "Soil_Dirt"}, {"x": 4, "y": -1, "z": 29, "name": "Soil_Dirt"}, {"x": 4, "y": 0, "z": 29, "name": "Soil_Grass"}, {"x": 4, "y": -3, "z": 30, "name": "Soil_Dirt"}, {"x": 4, "y": -2, "z": 30, "name": "Soil_Dirt"}, {"x": 4, "y": -1, "z": 30, "name": "Soil_Dirt"}, {"x": 4, "y": 0, "z": 30, "name": "Soil_Grass"}, {"x": 4, "y": -3, "z": 31, "name": "Soil_Dirt"}, {"x": 4, "y": -2, "z": 31, "name": "Soil_Dirt"}, {"x": 4, "y": -1, "z": 31, "name": "Soil_Dirt"}, {"x": 4, "y": 0, "z": 31, "name": "Soil_Grass"}, {"x": 5, "y": -3, "z": 0, "name": "Soil_Dirt"}, {"x": 5, "y": -2, "z": 0, "name": "Soil_Dirt"}, {"x": 5, "y": -1, "z": 0, "name": "Soil_Dirt"}, {"x": 5, "y": 0, "z": 0, "name": "Soil_Grass"}, {"x": 5, "y": -3, "z": 1, "name": "Soil_Dirt"}, {"x": 5, "y": -2, "z": 1, "name": "Soil_Dirt"}, {"x": 5, "y": -1, "z": 1, "name": "Soil_Dirt"}, {"x": 5, "y": 0, "z": 1, "name": "Soil_Grass"}, {"x": 5, "y": -3, "z": 2, "name": "Soil_Dirt"}, {"x": 5, "y": -2, "z": 2, "name": "Soil_Dirt"}, {"x": 5, "y": -1, "z": 2, "name": "Soil_Dirt"}, {"x": 5, "y": 0, "z": 2, "name": "Soil_Grass"}, {"x": 5, "y": -3, "z": 3, "name": "Soil_Dirt"}, {"x": 5, "y": -2, "z": 3, "name": "Soil_Dirt"}, {"x": 5, "y": -1, "z": 3, "name": "Soil_Dirt"}, {"x": 5, "y": 0, "z": 3, "name": "Soil_Grass"}, {"x": 5, "y": -3, "z": 4, "name": "Soil_Dirt"}, {"x": 5, "y": -2, "z": 4, "name": "Soil_Dirt"}, {"x": 5, "y": -1, "z": 4, "name": "Soil_Dirt"}, {"x": 5, "y": 0, "z": 4, "name": "Soil_Grass"}, {"x": 5, "y": -3, "z": 5, "name": "Soil_Dirt"}, {"x": 5, "y": -2, "z": 5, "name": "Soil_Dirt"}, {"x": 5, "y": -1, "z": 5, "name": "Soil_Dirt"}, {"x": 5, "y": 0, "z": 5, "name": "Soil_Grass"}, {"x": 5, "y": -3, "z": 6, "name": "Soil_Dirt"}, {"x": 5, "y": -2, "z": 6, "name": "Soil_Dirt"}, {"x": 5, "y": -1, "z": 6, "name": "Soil_Dirt"}, {"x": 5, "y": 0, "z": 6, "name": "Soil_Grass"}, {"x": 5, "y": -3, "z": 7, "name": "Soil_Dirt"}, {"x": 5, "y": -2, "z": 7, "name": "Soil_Dirt"}, {"x": 5, "y": -1, "z": 7, "name": "Soil_Dirt"}, {"x": 5, "y": 0, "z": 7, "name": "Soil_Grass"}, {"x": 5, "y": -3, "z": 8, "name": "Soil_Dirt"}, {"x": 5, "y": -2, "z": 8, "name": "Soil_Dirt"}, {"x": 5, "y": -1, "z": 8, "name": "Soil_Dirt"}, {"x": 5, "y": 0, "z": 8, "name": "Soil_Grass"}, {"x": 5, "y": -3, "z": 9, "name": "Soil_Dirt"}, {"x": 5, "y": -2, "z": 9, "name": "Soil_Dirt"}, {"x": 5, "y": -1, "z": 9, "name": "Soil_Dirt"}, {"x": 5, "y": 0, "z": 9, "name": "Soil_Grass"}, {"x": 5, "y": -3, "z": 10, "name": "Soil_Dirt"}, {"x": 5, "y": -2, "z": 10, "name": "Soil_Dirt"}, {"x": 5, "y": -1, "z": 10, "name": "Soil_Dirt"}, {"x": 5, "y": 0, "z": 10, "name": "Soil_Grass"}, {"x": 5, "y": -3, "z": 11, "name": "Soil_Dirt"}, {"x": 5, "y": -2, "z": 11, "name": "Soil_Dirt"}, {"x": 5, "y": -1, "z": 11, "name": "Soil_Dirt"}, {"x": 5, "y": 0, "z": 11, "name": "Soil_Grass"}, {"x": 5, "y": -3, "z": 12, "name": "Soil_Dirt"}, {"x": 5, "y": -2, "z": 12, "name": "Soil_Dirt"}, {"x": 5, "y": -1, "z": 12, "name": "Soil_Dirt"}, {"x": 5, "y": 0, "z": 12, "name": "Soil_Grass"}, {"x": 5, "y": -3, "z": 13, "name": "Soil_Dirt"}, {"x": 5, "y": -2, "z": 13, "name": "Soil_Dirt"}, {"x": 5, "y": -1, "z": 13, "name": "Soil_Dirt"}, {"x": 5, "y": 0, "z": 13, "name": "Soil_Clay"}, {"x": 5, "y": 1, "z": 13, "name": "*Wood_Hardwood_Fence_State_Definitions_Corner", "rotation": 1}, {"x": 5, "y": 2, "z": 13, "name": "*Wood_Hardwood_Fence_State_Definitions_Corner", "rotation": 1}, {"x": 5, "y": -3, "z": 14, "name": "Soil_Dirt"}, {"x": 5, "y": -2, "z": 14, "name": "Soil_Dirt"}, {"x": 5, "y": -1, "z": 14, "name": "Soil_Dirt"}, {"x": 5, "y": 0, "z": 14, "name": "Soil_Clay"}, {"x": 5, "y": 1, "z": 14, "name": "Wood_Hardwood_Fence", "rotation": 1}, {"x": 5, "y": 2, "z": 14, "name": "Wood_Hardwood_Fence", "rotation": 1}, {"x": 5, "y": -3, "z": 15, "name": "Soil_Dirt"}, {"x": 5, "y": -2, "z": 15, "name": "Soil_Dirt"}, {"x": 5, "y": -1, "z": 15, "name": "Soil_Dirt"}, {"x": 5, "y": 0, "z": 15, "name": "Soil_Clay"}, {"x": 5, "y": 1, "z": 15, "name": "Wood_Hardwood_Fence", "rotation": 1}, {"x": 5, "y": 2, "z": 15, "name": "Wood_Hardwood_Fence", "rotation": 1}, {"x": 5, "y": -3, "z": 16, "name": "Soil_Dirt"}, {"x": 5, "y": -2, "z": 16, "name": "Soil_Dirt"}, {"x": 5, "y": -1, "z": 16, "name": "Soil_Dirt"}, {"x": 5, "y": 0, "z": 16, "name": "Soil_Clay"}, {"x": 5, "y": 1, "z": 16, "name": "Wood_Hardwood_Fence", "rotation": 1}, {"x": 5, "y": 2, "z": 16, "name": "Wood_Hardwood_Fence", "rotation": 1}, {"x": 5, "y": -3, "z": 17, "name": "Soil_Dirt"}, {"x": 5, "y": -2, "z": 17, "name": "Soil_Dirt"}, {"x": 5, "y": -1, "z": 17, "name": "Soil_Dirt"}, {"x": 5, "y": 0, "z": 17, "name": "Soil_Clay"}, {"x": 5, "y": 1, "z": 17, "name": "Wood_Hardwood_Fence", "rotation": 1}, {"x": 5, "y": 2, "z": 17, "name": "Wood_Hardwood_Fence", "rotation": 1}, {"x": 5, "y": -3, "z": 18, "name": "Soil_Dirt"}, {"x": 5, "y": -2, "z": 18, "name": "Soil_Dirt"}, {"x": 5, "y": -1, "z": 18, "name": "Soil_Dirt"}, {"x": 5, "y": 0, "z": 18, "name": "Soil_Clay"}, {"x": 5, "y": 1, "z": 18, "name": "Wood_Hardwood_Fence", "rotation": 1}, {"x": 5, "y": 2, "z": 18, "name": "Wood_Hardwood_Fence", "rotation": 1}, {"x": 5, "y": -3, "z": 19, "name": "Soil_Dirt"}, {"x": 5, "y": -2, "z": 19, "name": "Soil_Dirt"}, {"x": 5, "y": -1, "z": 19, "name": "Soil_Dirt"}, {"x": 5, "y": 0, "z": 19, "name": "Soil_Clay"}, {"x": 5, "y": 1, "z": 19, "name": "Wood_Hardwood_Fence", "rotation": 1}, {"x": 5, "y": 2, "z": 19, "name": "Wood_Hardwood_Fence", "rotation": 1}, {"x": 5, "y": -3, "z": 20, "name": "Soil_Dirt"}, {"x": 5, "y": -2, "z": 20, "name": "Soil_Dirt"}, {"x": 5, "y": -1, "z": 20, "name": "Soil_Dirt"}, {"x": 5, "y": 0, "z": 20, "name": "Soil_Clay"}, {"x": 5, "y": 1, "z": 20, "name": "Wood_Hardwood_Fence", "rotation": 1}, {"x": 5, "y": 2, "z": 20, "name": "Wood_Hardwood_Fence", "rotation": 1}, {"x": 5, "y": -3, "z": 21, "name": "Soil_Dirt"}, {"x": 5, "y": -2, "z": 21, "name": "Soil_Dirt"}, {"x": 5, "y": -1, "z": 21, "name": "Soil_Dirt"}, {"x": 5, "y": 0, "z": 21, "name": "Soil_Clay"}, {"x": 5, "y": 1, "z": 21, "name": "*Wood_Hardwood_Fence_State_Definitions_Corner", "rotation": 2}, {"x": 5, "y": 2, "z": 21, "name": "*Wood_Hardwood_Fence_State_Definitions_Corner", "rotation": 2}, {"x": 5, "y": -3, "z": 22, "name": "Soil_Dirt"}, {"x": 5, "y": -2, "z": 22, "name": "Soil_Dirt"}, {"x": 5, "y": -1, "z": 22, "name": "Soil_Dirt"}, {"x": 5, "y": 0, "z": 22, "name": "Soil_Grass"}, {"x": 5, "y": -3, "z": 23, "name": "Soil_Dirt"}, {"x": 5, "y": -2, "z": 23, "name": "Soil_Dirt"}, {"x": 5, "y": -1, "z": 23, "name": "Soil_Dirt"}, {"x": 5, "y": 0, "z": 23, "name": "Soil_Grass"}, {"x": 5, "y": -3, "z": 24, "name": "Soil_Dirt"}, {"x": 5, "y": -2, "z": 24, "name": "Soil_Dirt"}, {"x": 5, "y": -1, "z": 24, "name": "Soil_Dirt"}, {"x": 5, "y": 0, "z": 24, "name": "Soil_Grass"}, {"x": 5, "y": -3, "z": 25, "name": "Soil_Dirt"}, {"x": 5, "y": -2, "z": 25, "name": "Soil_Dirt"}, {"x": 5, "y": -1, "z": 25, "name": "Soil_Dirt"}, {"x": 5, "y": 0, "z": 25, "name": "Soil_Grass"}, {"x": 5, "y": -3, "z": 26, "name": "Soil_Dirt"}, {"x": 5, "y": -2, "z": 26, "name": "Soil_Dirt"}, {"x": 5, "y": -1, "z": 26, "name": "Soil_Dirt"}, {"x": 5, "y": 0, "z": 26, "name": "Soil_Grass"}, {"x": 5, "y": -3, "z": 27, "name": "Soil_Dirt"}, {"x": 5, "y": -2, "z": 27, "name": "Soil_Dirt"}, {"x": 5, "y": -1, "z": 27, "name": "Soil_Dirt"}, {"x": 5, "y": 0, "z": 27, "name": "Soil_Grass"}, {"x": 5, "y": -3, "z": 28, "name": "Soil_Dirt"}, {"x": 5, "y": -2, "z": 28, "name": "Soil_Dirt"}, {"x": 5, "y": -1, "z": 28, "name": "Soil_Dirt"}, {"x": 5, "y": 0, "z": 28, "name": "Soil_Grass"}, {"x": 5, "y": -3, "z": 29, "name": "Soil_Dirt"}, {"x": 5, "y": -2, "z": 29, "name": "Soil_Dirt"}, {"x": 5, "y": -1, "z": 29, "name": "Soil_Dirt"}, {"x": 5, "y": 0, "z": 29, "name": "Soil_Grass"}, {"x": 5, "y": -3, "z": 30, "name": "Soil_Dirt"}, {"x": 5, "y": -2, "z": 30, "name": "Soil_Dirt"}, {"x": 5, "y": -1, "z": 30, "name": "Soil_Dirt"}, {"x": 5, "y": 0, "z": 30, "name": "Soil_Grass"}, {"x": 5, "y": -3, "z": 31, "name": "Soil_Dirt"}, {"x": 5, "y": -2, "z": 31, "name": "Soil_Dirt"}, {"x": 5, "y": -1, "z": 31, "name": "Soil_Dirt"}, {"x": 5, "y": 0, "z": 31, "name": "Soil_Grass"}, {"x": 6, "y": -3, "z": 0, "name": "Soil_Dirt"}, {"x": 6, "y": -2, "z": 0, "name": "Soil_Dirt"}, {"x": 6, "y": -1, "z": 0, "name": "Soil_Dirt"}, {"x": 6, "y": 0, "z": 0, "name": "Soil_Grass"}, {"x": 6, "y": -3, "z": 1, "name": "Soil_Dirt"}, {"x": 6, "y": -2, "z": 1, "name": "Soil_Dirt"}, {"x": 6, "y": -1, "z": 1, "name": "Soil_Dirt"}, {"x": 6, "y": 0, "z": 1, "name": "Soil_Grass"}, {"x": 6, "y": -3, "z": 2, "name": "Soil_Dirt"}, {"x": 6, "y": -2, "z": 2, "name": "Soil_Dirt"}, {"x": 6, "y": -1, "z": 2, "name": "Soil_Dirt"}, {"x": 6, "y": 0, "z": 2, "name": "Soil_Grass"}, {"x": 6, "y": -3, "z": 3, "name": "Soil_Dirt"}, {"x": 6, "y": -2, "z": 3, "name": "Soil_Dirt"}, {"x": 6, "y": -1, "z": 3, "name": "Soil_Dirt"}, {"x": 6, "y": 0, "z": 3, "name": "Soil_Grass"}, {"x": 6, "y": -3, "z": 4, "name": "Soil_Dirt"}, {"x": 6, "y": -2, "z": 4, "name": "Soil_Dirt"}, {"x": 6, "y": -1, "z": 4, "name": "Soil_Dirt"}, {"x": 6, "y": 0, "z": 4, "name": "Soil_Grass"}, {"x": 6, "y": -3, "z": 5, "name": "Soil_Dirt"}, {"x": 6, "y": -2, "z": 5, "name": "Soil_Dirt"}, {"x": 6, "y": -1, "z": 5, "name": "Soil_Dirt"}, {"x": 6, "y": 0, "z": 5, "name": "Soil_Grass"}, {"x": 6, "y": -3, "z": 6, "name": "Soil_Dirt"}, {"x": 6, "y": -2, "z": 6, "name": "Soil_Dirt"}, {"x": 6, "y": -1, "z": 6, "name": "Soil_Dirt"}, {"x": 6, "y": 0, "z": 6, "name": "Soil_Grass"}, {"x": 6, "y": -3, "z": 7, "name": "Soil_Dirt"}, {"x": 6, "y": -2, "z": 7, "name": "Soil_Dirt"}, {"x": 6, "y": -1, "z": 7, "name": "Soil_Dirt"}, {"x": 6, "y": 0, "z": 7, "name": "Soil_Grass"}, {"x": 6, "y": -3, "z": 8, "name": "Soil_Dirt"}, {"x": 6, "y": -2, "z": 8, "name": "Soil_Dirt"}, {"x": 6, "y": -1, "z": 8, "name": "Soil_Dirt"}, {"x": 6, "y": 0, "z": 8, "name": "Soil_Grass"}, {"x": 6, "y": -3, "z": 9, "name": "Soil_Dirt"}, {"x": 6, "y": -2, "z": 9, "name": "Soil_Dirt"}, {"x": 6, "y": -1, "z": 9, "name": "Soil_Dirt"}, {"x": 6, "y": 0, "z": 9, "name": "Soil_Grass"}, {"x": 6, "y": -3, "z": 10, "name": "Soil_Dirt"}, {"x": 6, "y": -2, "z": 10, "name": "Soil_Dirt"}, {"x": 6, "y": -1, "z": 10, "name": "Soil_Dirt"}, {"x": 6, "y": 0, "z": 10, "name": "Soil_Grass"}, {"x": 6, "y": -3, "z": 11, "name": "Soil_Dirt"}, {"x": 6, "y": -2, "z": 11, "name": "Soil_Dirt"}, {"x": 6, "y": -1, "z": 11, "name": "Soil_Dirt"}, {"x": 6, "y": 0, "z": 11, "name": "Soil_Grass"}, {"x": 6, "y": -3, "z": 12, "name": "Soil_Dirt"}, {"x": 6, "y": -2, "z": 12, "name": "Soil_Dirt"}, {"x": 6, "y": -1, "z": 12, "name": "Soil_Dirt"}, {"x": 6, "y": 0, "z": 12, "name": "Soil_Grass"}, {"x": 6, "y": -3, "z": 13, "name": "Soil_Dirt"}, {"x": 6, "y": -2, "z": 13, "name": "Soil_Dirt"}, {"x": 6, "y": -1, "z": 13, "name": "Soil_Dirt"}, {"x": 6, "y": 0, "z": 13, "name": "Soil_Clay"}, {"x": 6, "y": 1, "z": 13, "name": "Wood_Hardwood_Fence"}, {"x": 6, "y": 2, "z": 13, "name": "Wood_Hardwood_Fence"}, {"x": 6, "y": -3, "z": 14, "name": "Soil_Dirt"}, {"x": 6, "y": -2, "z": 14, "name": "Soil_Dirt"}, {"x": 6, "y": -1, "z": 14, "name": "Soil_Dirt"}, {"x": 6, "y": 0, "z": 14, "name": "Soil_Clay"}, {"x": 6, "y": -3, "z": 15, "name": "Soil_Dirt"}, {"x": 6, "y": -2, "z": 15, "name": "Soil_Dirt"}, {"x": 6, "y": -1, "z": 15, "name": "Soil_Dirt"}, {"x": 6, "y": 0, "z": 15, "name": "Soil_Clay"}, {"x": 6, "y": -3, "z": 16, "name": "Soil_Dirt"}, {"x": 6, "y": -2, "z": 16, "name": "Soil_Dirt"}, {"x": 6, "y": -1, "z": 16, "name": "Soil_Dirt"}, {"x": 6, "y": 0, "z": 16, "name": "Soil_Clay"}, {"x": 6, "y": -3, "z": 17, "name": "Soil_Dirt"}, {"x": 6, "y": -2, "z": 17, "name": "Soil_Dirt"}, {"x": 6, "y": -1, "z": 17, "name": "Soil_Dirt"}, {"x": 6, "y": 0, "z": 17, "name": "Soil_Clay"}, {"x": 6, "y": -3, "z": 18, "name": "Soil_Dirt"}, {"x": 6, "y": -2, "z": 18, "name": "Soil_Dirt"}, {"x": 6, "y": -1, "z": 18, "name": "Soil_Dirt"}, {"x": 6, "y": 0, "z": 18, "name": "Soil_Clay"}, {"x": 6, "y": -3, "z": 19, "name": "Soil_Dirt"}, {"x": 6, "y": -2, "z": 19, "name": "Soil_Dirt"}, {"x": 6, "y": -1, "z": 19, "name": "Soil_Dirt"}, {"x": 6, "y": 0, "z": 19, "name": "Soil_Clay"}, {"x": 6, "y": -3, "z": 20, "name": "Soil_Dirt"}, {"x": 6, "y": -2, "z": 20, "name": "Soil_Dirt"}, {"x": 6, "y": -1, "z": 20, "name": "Soil_Dirt"}, {"x": 6, "y": 0, "z": 20, "name": "Soil_Clay"}, {"x": 6, "y": -3, "z": 21, "name": "Soil_Dirt"}, {"x": 6, "y": -2, "z": 21, "name": "Soil_Dirt"}, {"x": 6, "y": -1, "z": 21, "name": "Soil_Dirt"}, {"x": 6, "y": 0, "z": 21, "name": "Soil_Clay"}, {"x": 6, "y": 1, "z": 21, "name": "Wood_Hardwood_Fence", "rotation": 2}, {"x": 6, "y": 2, "z": 21, "name": "Wood_Hardwood_Fence", "rotation": 2}, {"x": 6, "y": -3, "z": 22, "name": "Soil_Dirt"}, {"x": 6, "y": -2, "z": 22, "name": "Soil_Dirt"}, {"x": 6, "y": -1, "z": 22, "name": "Soil_Dirt"}, {"x": 6, "y": 0, "z": 22, "name": "Soil_Grass"}, {"x": 6, "y": -3, "z": 23, "name": "Soil_Dirt"}, {"x": 6, "y": -2, "z": 23, "name": "Soil_Dirt"}, {"x": 6, "y": -1, "z": 23, "name": "Soil_Dirt"}, {"x": 6, "y": 0, "z": 23, "name": "Soil_Grass"}, {"x": 6, "y": -3, "z": 24, "name": "Soil_Dirt"}, {"x": 6, "y": -2, "z": 24, "name": "Soil_Dirt"}, {"x": 6, "y": -1, "z": 24, "name": "Soil_Dirt"}, {"x": 6, "y": 0, "z": 24, "name": "Soil_Grass"}, {"x": 6, "y": -3, "z": 25, "name": "Soil_Dirt"}, {"x": 6, "y": -2, "z": 25, "name": "Soil_Dirt"}, {"x": 6, "y": -1, "z": 25, "name": "Soil_Dirt"}, {"x": 6, "y": 0, "z": 25, "name": "Soil_Grass"}, {"x": 6, "y": -3, "z": 26, "name": "Soil_Dirt"}, {"x": 6, "y": -2, "z": 26, "name": "Soil_Dirt"}, {"x": 6, "y": -1, "z": 26, "name": "Soil_Dirt"}, {"x": 6, "y": 0, "z": 26, "name": "Soil_Grass"}, {"x": 6, "y": -3, "z": 27, "name": "Soil_Dirt"}, {"x": 6, "y": -2, "z": 27, "name": "Soil_Dirt"}, {"x": 6, "y": -1, "z": 27, "name": "Soil_Dirt"}, {"x": 6, "y": 0, "z": 27, "name": "Soil_Grass"}, {"x": 6, "y": -3, "z": 28, "name": "Soil_Dirt"}, {"x": 6, "y": -2, "z": 28, "name": "Soil_Dirt"}, {"x": 6, "y": -1, "z": 28, "name": "Soil_Dirt"}, {"x": 6, "y": 0, "z": 28, "name": "Soil_Grass"}, {"x": 6, "y": -3, "z": 29, "name": "Soil_Dirt"}, {"x": 6, "y": -2, "z": 29, "name": "Soil_Dirt"}, {"x": 6, "y": -1, "z": 29, "name": "Soil_Dirt"}, {"x": 6, "y": 0, "z": 29, "name": "Soil_Grass"}, {"x": 6, "y": -3, "z": 30, "name": "Soil_Dirt"}, {"x": 6, "y": -2, "z": 30, "name": "Soil_Dirt"}, {"x": 6, "y": -1, "z": 30, "name": "Soil_Dirt"}, {"x": 6, "y": 0, "z": 30, "name": "Soil_Grass"}, {"x": 6, "y": -3, "z": 31, "name": "Soil_Dirt"}, {"x": 6, "y": -2, "z": 31, "name": "Soil_Dirt"}, {"x": 6, "y": -1, "z": 31, "name": "Soil_Dirt"}, {"x": 6, "y": 0, "z": 31, "name": "Soil_Grass"}, {"x": 7, "y": -3, "z": 0, "name": "Soil_Dirt"}, {"x": 7, "y": -2, "z": 0, "name": "Soil_Dirt"}, {"x": 7, "y": -1, "z": 0, "name": "Soil_Dirt"}, {"x": 7, "y": 0, "z": 0, "name": "Soil_Grass"}, {"x": 7, "y": -3, "z": 1, "name": "Soil_Dirt"}, {"x": 7, "y": -2, "z": 1, "name": "Soil_Dirt"}, {"x": 7, "y": -1, "z": 1, "name": "Soil_Dirt"}, {"x": 7, "y": 0, "z": 1, "name": "Soil_Grass"}, {"x": 7, "y": -3, "z": 2, "name": "Soil_Dirt"}, {"x": 7, "y": -2, "z": 2, "name": "Soil_Dirt"}, {"x": 7, "y": -1, "z": 2, "name": "Soil_Dirt"}, {"x": 7, "y": 0, "z": 2, "name": "Soil_Grass"}, {"x": 7, "y": -3, "z": 3, "name": "Soil_Dirt"}, {"x": 7, "y": -2, "z": 3, "name": "Soil_Dirt"}, {"x": 7, "y": -1, "z": 3, "name": "Soil_Dirt"}, {"x": 7, "y": 0, "z": 3, "name": "Soil_Grass"}, {"x": 7, "y": -3, "z": 4, "name": "Soil_Dirt"}, {"x": 7, "y": -2, "z": 4, "name": "Soil_Dirt"}, {"x": 7, "y": -1, "z": 4, "name": "Soil_Dirt"}, {"x": 7, "y": 0, "z": 4, "name": "Soil_Grass"}, {"x": 7, "y": -3, "z": 5, "name": "Soil_Dirt"}, {"x": 7, "y": -2, "z": 5, "name": "Soil_Dirt"}, {"x": 7, "y": -1, "z": 5, "name": "Soil_Dirt"}, {"x": 7, "y": 0, "z": 5, "name": "Soil_Grass"}, {"x": 7, "y": -3, "z": 6, "name": "Soil_Dirt"}, {"x": 7, "y": -2, "z": 6, "name": "Soil_Dirt"}, {"x": 7, "y": -1, "z": 6, "name": "Soil_Dirt"}, {"x": 7, "y": 0, "z": 6, "name": "Soil_Grass"}, {"x": 7, "y": -3, "z": 7, "name": "Soil_Dirt"}, {"x": 7, "y": -2, "z": 7, "name": "Soil_Dirt"}, {"x": 7, "y": -1, "z": 7, "name": "Soil_Dirt"}, {"x": 7, "y": 0, "z": 7, "name": "Soil_Grass"}, {"x": 7, "y": -3, "z": 8, "name": "Soil_Dirt"}, {"x": 7, "y": -2, "z": 8, "name": "Soil_Dirt"}, {"x": 7, "y": -1, "z": 8, "name": "Soil_Dirt"}, {"x": 7, "y": 0, "z": 8, "name": "Soil_Grass"}, {"x": 7, "y": -3, "z": 9, "name": "Soil_Dirt"}, {"x": 7, "y": -2, "z": 9, "name": "Soil_Dirt"}, {"x": 7, "y": -1, "z": 9, "name": "Soil_Dirt"}, {"x": 7, "y": 0, "z": 9, "name": "Soil_Grass"}, {"x": 7, "y": -3, "z": 10, "name": "Soil_Dirt"}, {"x": 7, "y": -2, "z": 10, "name": "Soil_Dirt"}, {"x": 7, "y": -1, "z": 10, "name": "Soil_Dirt"}, {"x": 7, "y": 0, "z": 10, "name": "Soil_Grass"}, {"x": 7, "y": -3, "z": 11, "name": "Soil_Dirt"}, {"x": 7, "y": -2, "z": 11, "name": "Soil_Dirt"}, {"x": 7, "y": -1, "z": 11, "name": "Soil_Dirt"}, {"x": 7, "y": 0, "z": 11, "name": "Soil_Grass"}, {"x": 7, "y": -3, "z": 12, "name": "Soil_Dirt"}, {"x": 7, "y": -2, "z": 12, "name": "Soil_Dirt"}, {"x": 7, "y": -1, "z": 12, "name": "Soil_Dirt"}, {"x": 7, "y": 0, "z": 12, "name": "Soil_Grass"}, {"x": 7, "y": -3, "z": 13, "name": "Soil_Dirt"}, {"x": 7, "y": -2, "z": 13, "name": "Soil_Dirt"}, {"x": 7, "y": -1, "z": 13, "name": "Soil_Dirt"}, {"x": 7, "y": 0, "z": 13, "name": "Soil_Clay"}, {"x": 7, "y": 1, "z": 13, "name": "Wood_Hardwood_Fence"}, {"x": 7, "y": 2, "z": 13, "name": "Wood_Hardwood_Fence"}, {"x": 7, "y": 4, "z": 13, "name": "Wood_Ash_Trunk", "rotation": 5}, {"x": 7, "y": -3, "z": 14, "name": "Soil_Dirt"}, {"x": 7, "y": -2, "z": 14, "name": "Soil_Dirt"}, {"x": 7, "y": -1, "z": 14, "name": "Soil_Dirt"}, {"x": 7, "y": 0, "z": 14, "name": "Soil_Clay"}, {"x": 7, "y": -3, "z": 15, "name": "Soil_Dirt"}, {"x": 7, "y": -2, "z": 15, "name": "Soil_Dirt"}, {"x": 7, "y": -1, "z": 15, "name": "Soil_Dirt"}, {"x": 7, "y": 0, "z": 15, "name": "Soil_Clay"}, {"x": 7, "y": -3, "z": 16, "name": "Soil_Dirt"}, {"x": 7, "y": -2, "z": 16, "name": "Soil_Dirt"}, {"x": 7, "y": -1, "z": 16, "name": "Soil_Dirt"}, {"x": 7, "y": 0, "z": 16, "name": "Soil_Clay"}, {"x": 7, "y": -3, "z": 17, "name": "Soil_Dirt"}, {"x": 7, "y": -2, "z": 17, "name": "Soil_Dirt"}, {"x": 7, "y": -1, "z": 17, "name": "Soil_Dirt"}, {"x": 7, "y": 0, "z": 17, "name": "Soil_Clay"}, {"x": 7, "y": -3, "z": 18, "name": "Soil_Dirt"}, {"x": 7, "y": -2, "z": 18, "name": "Soil_Dirt"}, {"x": 7, "y": -1, "z": 18, "name": "Soil_Dirt"}, {"x": 7, "y": 0, "z": 18, "name": "Soil_Clay"}, {"x": 7, "y": -3, "z": 19, "name": "Soil_Dirt"}, {"x": 7, "y": -2, "z": 19, "name": "Soil_Dirt"}, {"x": 7, "y": -1, "z": 19, "name": "Soil_Dirt"}, {"x": 7, "y": 0, "z": 19, "name": "Soil_Clay"}, {"x": 7, "y": -3, "z": 20, "name": "Soil_Dirt"}, {"x": 7, "y": -2, "z": 20, "name": "Soil_Dirt"}, {"x": 7, "y": -1, "z": 20, "name": "Soil_Dirt"}, {"x": 7, "y": 0, "z": 20, "name": "Soil_Clay"}, {"x": 7, "y": -3, "z": 21, "name": "Soil_Dirt"}, {"x": 7, "y": -2, "z": 21, "name": "Soil_Dirt"}, {"x": 7, "y": -1, "z": 21, "name": "Soil_Dirt"}, {"x": 7, "y": 0, "z": 21, "name": "Soil_Clay"}, {"x": 7, "y": 1, "z": 21, "name": "Wood_Hardwood_Fence", "rotation": 2}, {"x": 7, "y": 2, "z": 21, "name": "Wood_Hardwood_Fence", "rotation": 2}, {"x": 7, "y": 4, "z": 21, "name": "Wood_Ash_Trunk", "rotation": 5}, {"x": 7, "y": -3, "z": 22, "name": "Soil_Dirt"}, {"x": 7, "y": -2, "z": 22, "name": "Soil_Dirt"}, {"x": 7, "y": -1, "z": 22, "name": "Soil_Dirt"}, {"x": 7, "y": 0, "z": 22, "name": "Soil_Grass"}, {"x": 7, "y": -3, "z": 23, "name": "Soil_Dirt"}, {"x": 7, "y": -2, "z": 23, "name": "Soil_Dirt"}, {"x": 7, "y": -1, "z": 23, "name": "Soil_Dirt"}, {"x": 7, "y": 0, "z": 23, "name": "Soil_Grass"}, {"x": 7, "y": -3, "z": 24, "name": "Soil_Dirt"}, {"x": 7, "y": -2, "z": 24, "name": "Soil_Dirt"}, {"x": 7, "y": -1, "z": 24, "name": "Soil_Dirt"}, {"x": 7, "y": 0, "z": 24, "name": "Soil_Grass"}, {"x": 7, "y": -3, "z": 25, "name": "Soil_Dirt"}, {"x": 7, "y": -2, "z": 25, "name": "Soil_Dirt"}, {"x": 7, "y": -1, "z": 25, "name": "Soil_Dirt"}, {"x": 7, "y": 0, "z": 25, "name": "Soil_Grass"}, {"x": 7, "y": -3, "z": 26, "name": "Soil_Dirt"}, {"x": 7, "y": -2, "z": 26, "name": "Soil_Dirt"}, {"x": 7, "y": -1, "z": 26, "name": "Soil_Dirt"}, {"x": 7, "y": 0, "z": 26, "name": "Soil_Grass"}, {"x": 7, "y": -3, "z": 27, "name": "Soil_Dirt"}, {"x": 7, "y": -2, "z": 27, "name": "Soil_Dirt"}, {"x": 7, "y": -1, "z": 27, "name": "Soil_Dirt"}, {"x": 7, "y": 0, "z": 27, "name": "Soil_Grass"}, {"x": 7, "y": -3, "z": 28, "name": "Soil_Dirt"}, {"x": 7, "y": -2, "z": 28, "name": "Soil_Dirt"}, {"x": 7, "y": -1, "z": 28, "name": "Soil_Dirt"}, {"x": 7, "y": 0, "z": 28, "name": "Soil_Grass"}, {"x": 7, "y": -3, "z": 29, "name": "Soil_Dirt"}, {"x": 7, "y": -2, "z": 29, "name": "Soil_Dirt"}, {"x": 7, "y": -1, "z": 29, "name": "Soil_Dirt"}, {"x": 7, "y": 0, "z": 29, "name": "Soil_Grass"}, {"x": 7, "y": -3, "z": 30, "name": "Soil_Dirt"}, {"x": 7, "y": -2, "z": 30, "name": "Soil_Dirt"}, {"x": 7, "y": -1, "z": 30, "name": "Soil_Dirt"}, {"x": 7, "y": 0, "z": 30, "name": "Soil_Grass"}, {"x": 7, "y": -3, "z": 31, "name": "Soil_Dirt"}, {"x": 7, "y": -2, "z": 31, "name": "Soil_Dirt"}, {"x": 7, "y": -1, "z": 31, "name": "Soil_Dirt"}, {"x": 7, "y": 0, "z": 31, "name": "Soil_Grass"}, {"x": 8, "y": -3, "z": 0, "name": "Soil_Dirt"}, {"x": 8, "y": -2, "z": 0, "name": "Soil_Dirt"}, {"x": 8, "y": -1, "z": 0, "name": "Soil_Dirt"}, {"x": 8, "y": 0, "z": 0, "name": "Soil_Grass"}, {"x": 8, "y": -3, "z": 1, "name": "Soil_Dirt"}, {"x": 8, "y": -2, "z": 1, "name": "Soil_Dirt"}, {"x": 8, "y": -1, "z": 1, "name": "Soil_Dirt"}, {"x": 8, "y": 0, "z": 1, "name": "Soil_Grass"}, {"x": 8, "y": -3, "z": 2, "name": "Soil_Dirt"}, {"x": 8, "y": -2, "z": 2, "name": "Soil_Dirt"}, {"x": 8, "y": -1, "z": 2, "name": "Soil_Dirt"}, {"x": 8, "y": 0, "z": 2, "name": "Soil_Grass"}, {"x": 8, "y": -3, "z": 3, "name": "Soil_Dirt"}, {"x": 8, "y": -2, "z": 3, "name": "Soil_Dirt"}, {"x": 8, "y": -1, "z": 3, "name": "Soil_Dirt"}, {"x": 8, "y": 0, "z": 3, "name": "Soil_Grass"}, {"x": 8, "y": -3, "z": 4, "name": "Soil_Dirt"}, {"x": 8, "y": -2, "z": 4, "name": "Soil_Dirt"}, {"x": 8, "y": -1, "z": 4, "name": "Soil_Dirt"}, {"x": 8, "y": 0, "z": 4, "name": "Soil_Grass"}, {"x": 8, "y": -3, "z": 5, "name": "Soil_Dirt"}, {"x": 8, "y": -2, "z": 5, "name": "Soil_Dirt"}, {"x": 8, "y": -1, "z": 5, "name": "Soil_Dirt"}, {"x": 8, "y": 0, "z": 5, "name": "Soil_Grass"}, {"x": 8, "y": -3, "z": 6, "name": "Soil_Dirt"}, {"x": 8, "y": -2, "z": 6, "name": "Soil_Dirt"}, {"x": 8, "y": -1, "z": 6, "name": "Soil_Dirt"}, {"x": 8, "y": 0, "z": 6, "name": "Soil_Grass"}, {"x": 8, "y": -3, "z": 7, "name": "Soil_Dirt"}, {"x": 8, "y": -2, "z": 7, "name": "Soil_Dirt"}, {"x": 8, "y": -1, "z": 7, "name": "Soil_Dirt"}, {"x": 8, "y": 0, "z": 7, "name": "Soil_Grass"}, {"x": 8, "y": -3, "z": 8, "name": "Soil_Dirt"}, {"x": 8, "y": -2, "z": 8, "name": "Soil_Dirt"}, {"x": 8, "y": -1, "z": 8, "name": "Soil_Dirt"}, {"x": 8, "y": 0, "z": 8, "name": "Soil_Grass"}, {"x": 8, "y": -3, "z": 9, "name": "Soil_Dirt"}, {"x": 8, "y": -2, "z": 9, "name": "Soil_Dirt"}, {"x": 8, "y": -1, "z": 9, "name": "Soil_Dirt"}, {"x": 8, "y": 0, "z": 9, "name": "Soil_Grass"}, {"x": 8, "y": -3, "z": 10, "name": "Soil_Dirt"}, {"x": 8, "y": -2, "z": 10, "name": "Soil_Dirt"}, {"x": 8, "y": -1, "z": 10, "name": "Soil_Dirt"}, {"x": 8, "y": 0, "z": 10, "name": "Soil_Grass"}, {"x": 8, "y": -3, "z": 11, "name": "Soil_Dirt"}, {"x": 8, "y": -2, "z": 11, "name": "Soil_Dirt"}, {"x": 8, "y": -1, "z": 11, "name": "Soil_Dirt"}, {"x": 8, "y": 0, "z": 11, "name": "Soil_Grass"}, {"x": 8, "y": -3, "z": 12, "name": "Soil_Dirt"}, {"x": 8, "y": -2, "z": 12, "name": "Soil_Dirt"}, {"x": 8, "y": -1, "z": 12, "name": "Soil_Dirt"}, {"x": 8, "y": 0, "z": 12, "name": "Soil_Grass"}, {"x": 8, "y": -3, "z": 13, "name": "Soil_Dirt"}, {"x": 8, "y": -2, "z": 13, "name": "Soil_Dirt"}, {"x": 8, "y": -1, "z": 13, "name": "Soil_Dirt"}, {"x": 8, "y": 0, "z": 13, "name": "Soil_Clay"}, {"x": 8, "y": 1, "z": 13, "name": "Wood_Ash_Trunk_Full"}, {"x": 8, "y": 2, "z": 13, "name": "Wood_Ash_Trunk_Full"}, {"x": 8, "y": 3, "z": 13, "name": "Wood_Ash_Trunk_Full"}, {"x": 8, "y": 4, "z": 13, "name": "Wood_Ash_Trunk_Full", "rotation": 5}, {"x": 8, "y": -3, "z": 14, "name": "Soil_Dirt"}, {"x": 8, "y": -2, "z": 14, "name": "Soil_Dirt"}, {"x": 8, "y": -1, "z": 14, "name": "Soil_Dirt"}, {"x": 8, "y": 0, "z": 14, "name": "Soil_Clay"}, {"x": 8, "y": -3, "z": 15, "name": "Soil_Dirt"}, {"x": 8, "y": -2, "z": 15, "name": "Soil_Dirt"}, {"x": 8, "y": -1, "z": 15, "name": "Soil_Dirt"}, {"x": 8, "y": 0, "z": 15, "name": "Soil_Clay"}, {"x": 8, "y": -3, "z": 16, "name": "Soil_Dirt"}, {"x": 8, "y": -2, "z": 16, "name": "Soil_Dirt"}, {"x": 8, "y": -1, "z": 16, "name": "Soil_Dirt"}, {"x": 8, "y": 0, "z": 16, "name": "Plant_Crop_Mushroom_Block_Brown"}, {"x": 8, "y": -3, "z": 17, "name": "Soil_Dirt"}, {"x": 8, "y": -2, "z": 17, "name": "Soil_Dirt"}, {"x": 8, "y": -1, "z": 17, "name": "Soil_Dirt"}, {"x": 8, "y": 0, "z": 17, "name": "Plant_Crop_Mushroom_Block_Brown"}, {"x": 8, "y": -3, "z": 18, "name": "Soil_Dirt"}, {"x": 8, "y": -2, "z": 18, "name": "Soil_Dirt"}, {"x": 8, "y": -1, "z": 18, "name": "Soil_Dirt"}, {"x": 8, "y": 0, "z": 18, "name": "Plant_Crop_Mushroom_Block_Brown"}, {"x": 8, "y": -3, "z": 19, "name": "Soil_Dirt"}, {"x": 8, "y": -2, "z": 19, "name": "Soil_Dirt"}, {"x": 8, "y": -1, "z": 19, "name": "Soil_Dirt"}, {"x": 8, "y": 0, "z": 19, "name": "Soil_Clay"}, {"x": 8, "y": -3, "z": 20, "name": "Soil_Dirt"}, {"x": 8, "y": -2, "z": 20, "name": "Soil_Dirt"}, {"x": 8, "y": -1, "z": 20, "name": "Soil_Dirt"}, {"x": 8, "y": 0, "z": 20, "name": "Soil_Clay"}, {"x": 8, "y": -3, "z": 21, "name": "Soil_Dirt"}, {"x": 8, "y": -2, "z": 21, "name": "Soil_Dirt"}, {"x": 8, "y": -1, "z": 21, "name": "Soil_Dirt"}, {"x": 8, "y": 0, "z": 21, "name": "Soil_Clay"}, {"x": 8, "y": 1, "z": 21, "name": "Wood_Ash_Trunk_Full"}, {"x": 8, "y": 2, "z": 21, "name": "Wood_Ash_Trunk_Full"}, {"x": 8, "y": 3, "z": 21, "name": "Wood_Ash_Trunk_Full"}, {"x": 8, "y": 4, "z": 21, "name": "Wood_Ash_Trunk_Full", "rotation": 5}, {"x": 8, "y": -3, "z": 22, "name": "Soil_Dirt"}, {"x": 8, "y": -2, "z": 22, "name": "Soil_Dirt"}, {"x": 8, "y": -1, "z": 22, "name": "Soil_Dirt"}, {"x": 8, "y": 0, "z": 22, "name": "Soil_Grass"}, {"x": 8, "y": -3, "z": 23, "name": "Soil_Dirt"}, {"x": 8, "y": -2, "z": 23, "name": "Soil_Dirt"}, {"x": 8, "y": -1, "z": 23, "name": "Soil_Dirt"}, {"x": 8, "y": 0, "z": 23, "name": "Soil_Grass"}, {"x": 8, "y": -3, "z": 24, "name": "Soil_Dirt"}, {"x": 8, "y": -2, "z": 24, "name": "Soil_Dirt"}, {"x": 8, "y": -1, "z": 24, "name": "Soil_Dirt"}, {"x": 8, "y": 0, "z": 24, "name": "Soil_Grass"}, {"x": 8, "y": -3, "z": 25, "name": "Soil_Dirt"}, {"x": 8, "y": -2, "z": 25, "name": "Soil_Dirt"}, {"x": 8, "y": -1, "z": 25, "name": "Soil_Dirt"}, {"x": 8, "y": 0, "z": 25, "name": "Soil_Grass"}, {"x": 8, "y": -3, "z": 26, "name": "Soil_Dirt"}, {"x": 8, "y": -2, "z": 26, "name": "Soil_Dirt"}, {"x": 8, "y": -1, "z": 26, "name": "Soil_Dirt"}, {"x": 8, "y": 0, "z": 26, "name": "Soil_Grass"}, {"x": 8, "y": -3, "z": 27, "name": "Soil_Dirt"}, {"x": 8, "y": -2, "z": 27, "name": "Soil_Dirt"}, {"x": 8, "y": -1, "z": 27, "name": "Soil_Dirt"}, {"x": 8, "y": 0, "z": 27, "name": "Soil_Grass"}, {"x": 8, "y": -3, "z": 28, "name": "Soil_Dirt"}, {"x": 8, "y": -2, "z": 28, "name": "Soil_Dirt"}, {"x": 8, "y": -1, "z": 28, "name": "Soil_Dirt"}, {"x": 8, "y": 0, "z": 28, "name": "Soil_Grass"}, {"x": 8, "y": -3, "z": 29, "name": "Soil_Dirt"}, {"x": 8, "y": -2, "z": 29, "name": "Soil_Dirt"}, {"x": 8, "y": -1, "z": 29, "name": "Soil_Dirt"}, {"x": 8, "y": 0, "z": 29, "name": "Soil_Grass"}, {"x": 8, "y": -3, "z": 30, "name": "Soil_Dirt"}, {"x": 8, "y": -2, "z": 30, "name": "Soil_Dirt"}, {"x": 8, "y": -1, "z": 30, "name": "Soil_Dirt"}, {"x": 8, "y": 0, "z": 30, "name": "Soil_Grass"}, {"x": 8, "y": -3, "z": 31, "name": "Soil_Dirt"}, {"x": 8, "y": -2, "z": 31, "name": "Soil_Dirt"}, {"x": 8, "y": -1, "z": 31, "name": "Soil_Dirt"}, {"x": 8, "y": 0, "z": 31, "name": "Soil_Grass"}, {"x": 9, "y": -3, "z": 0, "name": "Soil_Dirt"}, {"x": 9, "y": -2, "z": 0, "name": "Soil_Dirt"}, {"x": 9, "y": -1, "z": 0, "name": "Soil_Dirt"}, {"x": 9, "y": 0, "z": 0, "name": "Soil_Grass"}, {"x": 9, "y": -3, "z": 1, "name": "Soil_Dirt"}, {"x": 9, "y": -2, "z": 1, "name": "Soil_Dirt"}, {"x": 9, "y": -1, "z": 1, "name": "Soil_Dirt"}, {"x": 9, "y": 0, "z": 1, "name": "Soil_Grass"}, {"x": 9, "y": -3, "z": 2, "name": "Soil_Dirt"}, {"x": 9, "y": -2, "z": 2, "name": "Soil_Dirt"}, {"x": 9, "y": -1, "z": 2, "name": "Soil_Dirt"}, {"x": 9, "y": 0, "z": 2, "name": "Soil_Grass"}, {"x": 9, "y": -3, "z": 3, "name": "Soil_Dirt"}, {"x": 9, "y": -2, "z": 3, "name": "Soil_Dirt"}, {"x": 9, "y": -1, "z": 3, "name": "Soil_Dirt"}, {"x": 9, "y": 0, "z": 3, "name": "Soil_Grass"}, {"x": 9, "y": -3, "z": 4, "name": "Soil_Dirt"}, {"x": 9, "y": -2, "z": 4, "name": "Soil_Dirt"}, {"x": 9, "y": -1, "z": 4, "name": "Soil_Dirt"}, {"x": 9, "y": 0, "z": 4, "name": "Soil_Grass"}, {"x": 9, "y": -3, "z": 5, "name": "Soil_Dirt"}, {"x": 9, "y": -2, "z": 5, "name": "Soil_Dirt"}, {"x": 9, "y": -1, "z": 5, "name": "Soil_Dirt"}, {"x": 9, "y": 0, "z": 5, "name": "Soil_Grass"}, {"x": 9, "y": -3, "z": 6, "name": "Soil_Dirt"}, {"x": 9, "y": -2, "z": 6, "name": "Soil_Dirt"}, {"x": 9, "y": -1, "z": 6, "name": "Soil_Dirt"}, {"x": 9, "y": 0, "z": 6, "name": "Soil_Grass"}, {"x": 9, "y": -3, "z": 7, "name": "Soil_Dirt"}, {"x": 9, "y": -2, "z": 7, "name": "Soil_Dirt"}, {"x": 9, "y": -1, "z": 7, "name": "Soil_Dirt"}, {"x": 9, "y": 0, "z": 7, "name": "Soil_Grass"}, {"x": 9, "y": -3, "z": 8, "name": "Soil_Dirt"}, {"x": 9, "y": -2, "z": 8, "name": "Soil_Dirt"}, {"x": 9, "y": -1, "z": 8, "name": "Soil_Dirt"}, {"x": 9, "y": 0, "z": 8, "name": "Soil_Grass"}, {"x": 9, "y": -3, "z": 9, "name": "Soil_Dirt"}, {"x": 9, "y": -2, "z": 9, "name": "Soil_Dirt"}, {"x": 9, "y": -1, "z": 9, "name": "Soil_Dirt"}, {"x": 9, "y": 0, "z": 9, "name": "Soil_Grass"}, {"x": 9, "y": -3, "z": 10, "name": "Soil_Dirt"}, {"x": 9, "y": -2, "z": 10, "name": "Soil_Dirt"}, {"x": 9, "y": -1, "z": 10, "name": "Soil_Dirt"}, {"x": 9, "y": 0, "z": 10, "name": "Soil_Grass"}, {"x": 9, "y": -3, "z": 11, "name": "Soil_Dirt"}, {"x": 9, "y": -2, "z": 11, "name": "Soil_Dirt"}, {"x": 9, "y": -1, "z": 11, "name": "Soil_Dirt"}, {"x": 9, "y": 0, "z": 11, "name": "Wood_Ash_Trunk_Full"}, {"x": 9, "y": 1, "z": 11, "name": "Wood_Ash_Trunk_Full"}, {"x": 9, "y": 2, "z": 11, "name": "Wood_Ash_Trunk_Full"}, {"x": 9, "y": 3, "z": 11, "name": "Wood_Ash_Trunk_Full"}, {"x": 9, "y": 4, "z": 11, "name": "Wood_Ash_Trunk_Full"}, {"x": 9, "y": 5, "z": 11, "name": "Wood_Ash_Trunk"}, {"x": 9, "y": -3, "z": 12, "name": "Soil_Dirt"}, {"x": 9, "y": -2, "z": 12, "name": "Soil_Dirt"}, {"x": 9, "y": -1, "z": 12, "name": "Soil_Dirt"}, {"x": 9, "y": 0, "z": 12, "name": "Wood_Hardwood_Planks"}, {"x": 9, "y": 1, "z": 12, "name": "Wood_Hardwood_Planks"}, {"x": 9, "y": 2, "z": 12, "name": "Wood_Hardwood_Planks"}, {"x": 9, "y": 3, "z": 12, "name": "Wood_Hardwood_Planks"}, {"x": 9, "y": 4, "z": 12, "name": "Wood_Ash_Trunk_Full", "rotation": 4}, {"x": 9, "y": -3, "z": 13, "name": "Soil_Dirt"}, {"x": 9, "y": -2, "z": 13, "name": "Soil_Dirt"}, {"x": 9, "y": -1, "z": 13, "name": "Soil_Dirt"}, {"x": 9, "y": 0, "z": 13, "name": "Soil_Clay"}, {"x": 9, "y": 3, "z": 13, "name": "Wood_Hardwood_Planks_Half", "rotation": 8}, {"x": 9, "y": 4, "z": 13, "name": "Wood_Ash_Trunk_Full", "rotation": 4}, {"x": 9, "y": 5, "z": 13, "name": "Wood_Hardwood_Planks_Half"}, {"x": 9, "y": -3, "z": 14, "name": "Soil_Dirt"}, {"x": 9, "y": -2, "z": 14, "name": "Soil_Dirt"}, {"x": 9, "y": -1, "z": 14, "name": "Soil_Dirt"}, {"x": 9, "y": 0, "z": 14, "name": "Soil_Clay"}, {"x": 9, "y": 4, "z": 14, "name": "Wood_Ash_Trunk_Full", "rotation": 4}, {"x": 9, "y": -3, "z": 15, "name": "Soil_Dirt"}, {"x": 9, "y": -2, "z": 15, "name": "Soil_Dirt"}, {"x": 9, "y": -1, "z": 15, "name": "Soil_Dirt"}, {"x": 9, "y": 0, "z": 15, "name": "Soil_Clay"}, {"x": 9, "y": 4, "z": 15, "name": "Wood_Ash_Trunk_Full", "rotation": 4}, {"x": 9, "y": -3, "z": 16, "name": "Soil_Dirt"}, {"x": 9, "y": -2, "z": 16, "name": "Soil_Dirt"}, {"x": 9, "y": -1, "z": 16, "name": "Soil_Dirt"}, {"x": 9, "y": 0, "z": 16, "name": "Plant_Crop_Mushroom_Block_Brown"}, {"x": 9, "y": 4, "z": 16, "name": "Wood_Ash_Trunk_Full", "rotation": 4}, {"x": 9, "y": -3, "z": 17, "name": "Soil_Dirt"}, {"x": 9, "y": -2, "z": 17, "name": "Soil_Dirt"}, {"x": 9, "y": -1, "z": 17, "name": "Soil_Dirt"}, {"x": 9, "y": 0, "z": 17, "name": "Plant_Crop_Mushroom_Block_Brown"}, {"x": 9, "y": 1, "z": 17, "name": "Wood_Ash_Trunk_Full"}, {"x": 9, "y": 2, "z": 17, "name": "Wood_Ash_Trunk_Full"}, {"x": 9, "y": 3, "z": 17, "name": "Wood_Ash_Trunk_Full"}, {"x": 9, "y": 4, "z": 17, "name": "Wood_Ash_Trunk_Full"}, {"x": 9, "y": 5, "z": 17, "name": "Wood_Ash_Trunk"}, {"x": 9, "y": 6, "z": 17, "name": "Wood_Hardwood_Planks_Half"}, {"x": 9, "y": -3, "z": 18, "name": "Soil_Dirt"}, {"x": 9, "y": -2, "z": 18, "name": "Soil_Dirt"}, {"x": 9, "y": -1, "z": 18, "name": "Soil_Dirt"}, {"x": 9, "y": 0, "z": 18, "name": "Plant_Crop_Mushroom_Block_Brown"}, {"x": 9, "y": 4, "z": 18, "name": "Wood_Ash_Trunk_Full", "rotation": 4}, {"x": 9, "y": -3, "z": 19, "name": "Soil_Dirt"}, {"x": 9, "y": -2, "z": 19, "name": "Soil_Dirt"}, {"x": 9, "y": -1, "z": 19, "name": "Soil_Dirt"}, {"x": 9, "y": 0, "z": 19, "name": "Soil_Clay"}, {"x": 9, "y": 4, "z": 19, "name": "Wood_Ash_Trunk_Full", "rotation": 4}, {"x": 9, "y": -3, "z": 20, "name": "Soil_Dirt"}, {"x": 9, "y": -2, "z": 20, "name": "Soil_Dirt"}, {"x": 9, "y": -1, "z": 20, "name": "Soil_Dirt"}, {"x": 9, "y": 0, "z": 20, "name": "Soil_Clay"}, {"x": 9, "y": 4, "z": 20, "name": "Wood_Ash_Trunk_Full", "rotation": 4}, {"x": 9, "y": -3, "z": 21, "name": "Soil_Dirt"}, {"x": 9, "y": -2, "z": 21, "name": "Soil_Dirt"}, {"x": 9, "y": -1, "z": 21, "name": "Soil_Dirt"}, {"x": 9, "y": 0, "z": 21, "name": "Soil_Clay"}, {"x": 9, "y": 3, "z": 21, "name": "Wood_Hardwood_Planks_Half", "rotation": 8}, {"x": 9, "y": 4, "z": 21, "name": "Wood_Ash_Trunk_Full", "rotation": 4}, {"x": 9, "y": 5, "z": 21, "name": "Wood_Hardwood_Planks_Half"}, {"x": 9, "y": -3, "z": 22, "name": "Soil_Dirt"}, {"x": 9, "y": -2, "z": 22, "name": "Soil_Dirt"}, {"x": 9, "y": -1, "z": 22, "name": "Soil_Dirt"}, {"x": 9, "y": 0, "z": 22, "name": "Wood_Hardwood_Planks"}, {"x": 9, "y": 1, "z": 22, "name": "Wood_Hardwood_Planks"}, {"x": 9, "y": 2, "z": 22, "name": "Wood_Hardwood_Planks"}, {"x": 9, "y": 3, "z": 22, "name": "Wood_Hardwood_Planks"}, {"x": 9, "y": 4, "z": 22, "name": "Wood_Ash_Trunk_Full", "rotation": 4}, {"x": 9, "y": -3, "z": 23, "name": "Soil_Dirt"}, {"x": 9, "y": -2, "z": 23, "name": "Soil_Dirt"}, {"x": 9, "y": -1, "z": 23, "name": "Soil_Dirt"}, {"x": 9, "y": 0, "z": 23, "name": "Wood_Ash_Trunk_Full"}, {"x": 9, "y": 1, "z": 23, "name": "Wood_Ash_Trunk_Full"}, {"x": 9, "y": 2, "z": 23, "name": "Wood_Ash_Trunk_Full"}, {"x": 9, "y": 3, "z": 23, "name": "Wood_Ash_Trunk_Full"}, {"x": 9, "y": 4, "z": 23, "name": "Wood_Ash_Trunk_Full"}, {"x": 9, "y": 5, "z": 23, "name": "Wood_Ash_Trunk"}, {"x": 9, "y": -3, "z": 24, "name": "Soil_Dirt"}, {"x": 9, "y": -2, "z": 24, "name": "Soil_Dirt"}, {"x": 9, "y": -1, "z": 24, "name": "Soil_Dirt"}, {"x": 9, "y": 0, "z": 24, "name": "Soil_Grass"}, {"x": 9, "y": -3, "z": 25, "name": "Soil_Dirt"}, {"x": 9, "y": -2, "z": 25, "name": "Soil_Dirt"}, {"x": 9, "y": -1, "z": 25, "name": "Soil_Dirt"}, {"x": 9, "y": 0, "z": 25, "name": "Soil_Grass"}, {"x": 9, "y": -3, "z": 26, "name": "Soil_Dirt"}, {"x": 9, "y": -2, "z": 26, "name": "Soil_Dirt"}, {"x": 9, "y": -1, "z": 26, "name": "Soil_Dirt"}, {"x": 9, "y": 0, "z": 26, "name": "Soil_Grass"}, {"x": 9, "y": -3, "z": 27, "name": "Soil_Dirt"}, {"x": 9, "y": -2, "z": 27, "name": "Soil_Dirt"}, {"x": 9, "y": -1, "z": 27, "name": "Soil_Dirt"}, {"x": 9, "y": 0, "z": 27, "name": "Soil_Grass"}, {"x": 9, "y": -3, "z": 28, "name": "Soil_Dirt"}, {"x": 9, "y": -2, "z": 28, "name": "Soil_Dirt"}, {"x": 9, "y": -1, "z": 28, "name": "Soil_Dirt"}, {"x": 9, "y": 0, "z": 28, "name": "Soil_Grass"}, {"x": 9, "y": -3, "z": 29, "name": "Soil_Dirt"}, {"x": 9, "y": -2, "z": 29, "name": "Soil_Dirt"}, {"x": 9, "y": -1, "z": 29, "name": "Soil_Dirt"}, {"x": 9, "y": 0, "z": 29, "name": "Soil_Grass"}, {"x": 9, "y": -3, "z": 30, "name": "Soil_Dirt"}, {"x": 9, "y": -2, "z": 30, "name": "Soil_Dirt"}, {"x": 9, "y": -1, "z": 30, "name": "Soil_Dirt"}, {"x": 9, "y": 0, "z": 30, "name": "Soil_Grass"}, {"x": 9, "y": -3, "z": 31, "name": "Soil_Dirt"}, {"x": 9, "y": -2, "z": 31, "name": "Soil_Dirt"}, {"x": 9, "y": -1, "z": 31, "name": "Soil_Dirt"}, {"x": 9, "y": 0, "z": 31, "name": "Soil_Grass"}, {"x": 10, "y": -3, "z": 0, "name": "Soil_Dirt"}, {"x": 10, "y": -2, "z": 0, "name": "Soil_Dirt"}, {"x": 10, "y": -1, "z": 0, "name": "Soil_Dirt"}, {"x": 10, "y": 0, "z": 0, "name": "Soil_Grass"}, {"x": 10, "y": -3, "z": 1, "name": "Soil_Dirt"}, {"x": 10, "y": -2, "z": 1, "name": "Soil_Dirt"}, {"x": 10, "y": -1, "z": 1, "name": "Soil_Dirt"}, {"x": 10, "y": 0, "z": 1, "name": "Soil_Grass"}, {"x": 10, "y": -3, "z": 2, "name": "Soil_Dirt"}, {"x": 10, "y": -2, "z": 2, "name": "Soil_Dirt"}, {"x": 10, "y": -1, "z": 2, "name": "Soil_Dirt"}, {"x": 10, "y": 0, "z": 2, "name": "Soil_Grass"}, {"x": 10, "y": -3, "z": 3, "name": "Soil_Dirt"}, {"x": 10, "y": -2, "z": 3, "name": "Soil_Dirt"}, {"x": 10, "y": -1, "z": 3, "name": "Soil_Dirt"}, {"x": 10, "y": 0, "z": 3, "name": "Soil_Grass"}, {"x": 10, "y": -3, "z": 4, "name": "Soil_Dirt"}, {"x": 10, "y": -2, "z": 4, "name": "Soil_Dirt"}, {"x": 10, "y": -1, "z": 4, "name": "Soil_Dirt"}, {"x": 10, "y": 0, "z": 4, "name": "Soil_Grass"}, {"x": 10, "y": -3, "z": 5, "name": "Soil_Dirt"}, {"x": 10, "y": -2, "z": 5, "name": "Soil_Dirt"}, {"x": 10, "y": -1, "z": 5, "name": "Soil_Dirt"}, {"x": 10, "y": 0, "z": 5, "name": "Soil_Grass"}, {"x": 10, "y": -3, "z": 6, "name": "Soil_Dirt"}, {"x": 10, "y": -2, "z": 6, "name": "Soil_Dirt"}, {"x": 10, "y": -1, "z": 6, "name": "Soil_Dirt"}, {"x": 10, "y": 0, "z": 6, "name": "Soil_Grass"}, {"x": 10, "y": -3, "z": 7, "name": "Soil_Dirt"}, {"x": 10, "y": -2, "z": 7, "name": "Soil_Dirt"}, {"x": 10, "y": -1, "z": 7, "name": "Soil_Dirt"}, {"x": 10, "y": 0, "z": 7, "name": "Soil_Grass"}, {"x": 10, "y": -3, "z": 8, "name": "Soil_Dirt"}, {"x": 10, "y": -2, "z": 8, "name": "Soil_Dirt"}, {"x": 10, "y": -1, "z": 8, "name": "Soil_Dirt"}, {"x": 10, "y": 0, "z": 8, "name": "Soil_Grass"}, {"x": 10, "y": -3, "z": 9, "name": "Soil_Dirt"}, {"x": 10, "y": -2, "z": 9, "name": "Soil_Dirt"}, {"x": 10, "y": -1, "z": 9, "name": "Soil_Dirt"}, {"x": 10, "y": 0, "z": 9, "name": "Soil_Grass"}, {"x": 10, "y": -3, "z": 10, "name": "Soil_Dirt"}, {"x": 10, "y": -2, "z": 10, "name": "Soil_Dirt"}, {"x": 10, "y": -1, "z": 10, "name": "Soil_Dirt"}, {"x": 10, "y": 0, "z": 10, "name": "Soil_Grass"}, {"x": 10, "y": -3, "z": 11, "name": "Soil_Dirt"}, {"x": 10, "y": -2, "z": 11, "name": "Soil_Dirt"}, {"x": 10, "y": -1, "z": 11, "name": "Soil_Dirt"}, {"x": 10, "y": 0, "z": 11, "name": "Wood_Hardwood_Planks"}, {"x": 10, "y": 1, "z": 11, "name": "Wood_Hardwood_Planks"}, {"x": 10, "y": 2, "z": 11, "name": "Wood_Hardwood_Planks"}, {"x": 10, "y": 3, "z": 11, "name": "Wood_Hardwood_Planks"}, {"x": 10, "y": 4, "z": 11, "name": "Wood_Ash_Trunk_Full", "rotation": 5}, {"x": 10, "y": -3, "z": 12, "name": "Soil_Dirt"}, {"x": 10, "y": -2, "z": 12, "name": "Soil_Dirt"}, {"x": 10, "y": -1, "z": 12, "name": "Soil_Dirt"}, {"x": 10, "y": 0, "z": 12, "name": "Soil_Clay"}, {"x": 10, "y": 1, "z": 12, "name": "*Wood_Hardwood_Fence_State_Definitions_Corner", "rotation": 3}, {"x": 10, "y": 2, "z": 12, "name": "Deco_Lantern"}, {"x": 10, "y": -3, "z": 13, "name": "Soil_Dirt"}, {"x": 10, "y": -2, "z": 13, "name": "Soil_Dirt"}, {"x": 10, "y": -1, "z": 13, "name": "Soil_Dirt"}, {"x": 10, "y": 0, "z": 13, "name": "Soil_Clay"}, {"x": 10, "y": 4, "z": 13, "name": "Wood_Hardwood_Planks_Half", "rotation": 5}, {"x": 10, "y": -3, "z": 14, "name": "Soil_Dirt"}, {"x": 10, "y": -2, "z": 14, "name": "Soil_Dirt"}, {"x": 10, "y": -1, "z": 14, "name": "Soil_Dirt"}, {"x": 10, "y": 0, "z": 14, "name": "Soil_Clay"}, {"x": 10, "y": -3, "z": 15, "name": "Soil_Dirt"}, {"x": 10, "y": -2, "z": 15, "name": "Soil_Dirt"}, {"x": 10, "y": -1, "z": 15, "name": "Soil_Dirt"}, {"x": 10, "y": 0, "z": 15, "name": "Soil_Clay"}, {"x": 10, "y": -3, "z": 16, "name": "Soil_Dirt"}, {"x": 10, "y": -2, "z": 16, "name": "Soil_Dirt"}, {"x": 10, "y": -1, "z": 16, "name": "Soil_Dirt"}, {"x": 10, "y": 0, "z": 16, "name": "Plant_Crop_Mushroom_Block_Brown"}, {"x": 10, "y": -3, "z": 17, "name": "Soil_Dirt"}, {"x": 10, "y": -2, "z": 17, "name": "Soil_Dirt"}, {"x": 10, "y": -1, "z": 17, "name": "Soil_Dirt"}, {"x": 10, "y": 0, "z": 17, "name": "Plant_Crop_Mushroom_Block_Brown"}, {"x": 10, "y": 1, "z": 17, "name": "Wood_Hardwood_Fence", "rotation": 1}, {"x": 10, "y": 3, "z": 17, "name": "Wood_Torch_Wall", "rotation": 1}, {"x": 10, "y": -3, "z": 18, "name": "Soil_Dirt"}, {"x": 10, "y": -2, "z": 18, "name": "Soil_Dirt"}, {"x": 10, "y": -1, "z": 18, "name": "Soil_Dirt"}, {"x": 10, "y": 0, "z": 18, "name": "Plant_Crop_Mushroom_Block_Brown"}, {"x": 10, "y": -3, "z": 19, "name": "Soil_Dirt"}, {"x": 10, "y": -2, "z": 19, "name": "Soil_Dirt"}, {"x": 10, "y": -1, "z": 19, "name": "Soil_Dirt"}, {"x": 10, "y": 0, "z": 19, "name": "Soil_Clay"}, {"x": 10, "y": -3, "z": 20, "name": "Soil_Dirt"}, {"x": 10, "y": -2, "z": 20, "name": "Soil_Dirt"}, {"x": 10, "y": -1, "z": 20, "name": "Soil_Dirt"}, {"x": 10, "y": 0, "z": 20, "name": "Soil_Clay"}, {"x": 10, "y": -3, "z": 21, "name": "Soil_Dirt"}, {"x": 10, "y": -2, "z": 21, "name": "Soil_Dirt"}, {"x": 10, "y": -1, "z": 21, "name": "Soil_Dirt"}, {"x": 10, "y": 0, "z": 21, "name": "Soil_Clay"}, {"x": 10, "y": 4, "z": 21, "name": "Wood_Hardwood_Planks_Half", "rotation": 5}, {"x": 10, "y": -3, "z": 22, "name": "Soil_Dirt"}, {"x": 10, "y": -2, "z": 22, "name": "Soil_Dirt"}, {"x": 10, "y": -1, "z": 22, "name": "Soil_Dirt"}, {"x": 10, "y": 0, "z": 22, "name": "Soil_Clay"}, {"x": 10, "y": 1, "z": 22, "name": "*Wood_Hardwood_Fence_State_Definitions_Corner"}, {"x": 10, "y": 2, "z": 22, "name": "Deco_Lantern"}, {"x": 10, "y": -3, "z": 23, "name": "Soil_Dirt"}, {"x": 10, "y": -2, "z": 23, "name": "Soil_Dirt"}, {"x": 10, "y": -1, "z": 23, "name": "Soil_Dirt"}, {"x": 10, "y": 0, "z": 23, "name": "Wood_Hardwood_Planks"}, {"x": 10, "y": 1, "z": 23, "name": "Wood_Hardwood_Planks"}, {"x": 10, "y": 2, "z": 23, "name": "Wood_Hardwood_Planks"}, {"x": 10, "y": 3, "z": 23, "name": "Wood_Hardwood_Planks"}, {"x": 10, "y": 4, "z": 23, "name": "Wood_Ash_Trunk_Full", "rotation": 5}, {"x": 10, "y": -3, "z": 24, "name": "Soil_Dirt"}, {"x": 10, "y": -2, "z": 24, "name": "Soil_Dirt"}, {"x": 10, "y": -1, "z": 24, "name": "Soil_Dirt"}, {"x": 10, "y": 0, "z": 24, "name": "Soil_Grass"}, {"x": 10, "y": -3, "z": 25, "name": "Soil_Dirt"}, {"x": 10, "y": -2, "z": 25, "name": "Soil_Dirt"}, {"x": 10, "y": -1, "z": 25, "name": "Soil_Dirt"}, {"x": 10, "y": 0, "z": 25, "name": "Soil_Grass"}, {"x": 10, "y": -3, "z": 26, "name": "Soil_Dirt"}, {"x": 10, "y": -2, "z": 26, "name": "Soil_Dirt"}, {"x": 10, "y": -1, "z": 26, "name": "Soil_Dirt"}, {"x": 10, "y": 0, "z": 26, "name": "Soil_Grass"}, {"x": 10, "y": -3, "z": 27, "name": "Soil_Dirt"}, {"x": 10, "y": -2, "z": 27, "name": "Soil_Dirt"}, {"x": 10, "y": -1, "z": 27, "name": "Soil_Dirt"}, {"x": 10, "y": 0, "z": 27, "name": "Soil_Grass"}, {"x": 10, "y": -3, "z": 28, "name": "Soil_Dirt"}, {"x": 10, "y": -2, "z": 28, "name": "Soil_Dirt"}, {"x": 10, "y": -1, "z": 28, "name": "Soil_Dirt"}, {"x": 10, "y": 0, "z": 28, "name": "Soil_Grass"}, {"x": 10, "y": -3, "z": 29, "name": "Soil_Dirt"}, {"x": 10, "y": -2, "z": 29, "name": "Soil_Dirt"}, {"x": 10, "y": -1, "z": 29, "name": "Soil_Dirt"}, {"x": 10, "y": 0, "z": 29, "name": "Soil_Grass"}, {"x": 10, "y": -3, "z": 30, "name": "Soil_Dirt"}, {"x": 10, "y": -2, "z": 30, "name": "Soil_Dirt"}, {"x": 10, "y": -1, "z": 30, "name": "Soil_Dirt"}, {"x": 10, "y": 0, "z": 30, "name": "Soil_Grass"}, {"x": 10, "y": -3, "z": 31, "name": "Soil_Dirt"}, {"x": 10, "y": -2, "z": 31, "name": "Soil_Dirt"}, {"x": 10, "y": -1, "z": 31, "name": "Soil_Dirt"}, {"x": 10, "y": 0, "z": 31, "name": "Soil_Grass"}, {"x": 11, "y": -3, "z": 0, "name": "Soil_Dirt"}, {"x": 11, "y": -2, "z": 0, "name": "Soil_Dirt"}, {"x": 11, "y": -1, "z": 0, "name": "Soil_Dirt"}, {"x": 11, "y": 0, "z": 0, "name": "Soil_Grass"}, {"x": 11, "y": -3, "z": 1, "name": "Soil_Dirt"}, {"x": 11, "y": -2, "z": 1, "name": "Soil_Dirt"}, {"x": 11, "y": -1, "z": 1, "name": "Soil_Dirt"}, {"x": 11, "y": 0, "z": 1, "name": "Soil_Grass"}, {"x": 11, "y": -3, "z": 2, "name": "Soil_Dirt"}, {"x": 11, "y": -2, "z": 2, "name": "Soil_Dirt"}, {"x": 11, "y": -1, "z": 2, "name": "Soil_Dirt"}, {"x": 11, "y": 0, "z": 2, "name": "Soil_Grass"}, {"x": 11, "y": -3, "z": 3, "name": "Soil_Dirt"}, {"x": 11, "y": -2, "z": 3, "name": "Soil_Dirt"}, {"x": 11, "y": -1, "z": 3, "name": "Soil_Dirt"}, {"x": 11, "y": 0, "z": 3, "name": "Soil_Grass"}, {"x": 11, "y": -3, "z": 4, "name": "Soil_Dirt"}, {"x": 11, "y": -2, "z": 4, "name": "Soil_Dirt"}, {"x": 11, "y": -1, "z": 4, "name": "Soil_Dirt"}, {"x": 11, "y": 0, "z": 4, "name": "Soil_Grass"}, {"x": 11, "y": -3, "z": 5, "name": "Soil_Dirt"}, {"x": 11, "y": -2, "z": 5, "name": "Soil_Dirt"}, {"x": 11, "y": -1, "z": 5, "name": "Soil_Dirt"}, {"x": 11, "y": 0, "z": 5, "name": "Soil_Grass"}, {"x": 11, "y": -3, "z": 6, "name": "Soil_Dirt"}, {"x": 11, "y": -2, "z": 6, "name": "Soil_Dirt"}, {"x": 11, "y": -1, "z": 6, "name": "Soil_Dirt"}, {"x": 11, "y": 0, "z": 6, "name": "Soil_Grass"}, {"x": 11, "y": -3, "z": 7, "name": "Soil_Dirt"}, {"x": 11, "y": -2, "z": 7, "name": "Soil_Dirt"}, {"x": 11, "y": -1, "z": 7, "name": "Soil_Dirt"}, {"x": 11, "y": 0, "z": 7, "name": "Soil_Clay"}, {"x": 11, "y": 1, "z": 7, "name": "*Wood_Hardwood_Fence_State_Definitions_Corner", "rotation": 1}, {"x": 11, "y": 2, "z": 7, "name": "*Wood_Hardwood_Fence_State_Definitions_Corner", "rotation": 1}, {"x": 11, "y": -3, "z": 8, "name": "Soil_Dirt"}, {"x": 11, "y": -2, "z": 8, "name": "Soil_Dirt"}, {"x": 11, "y": -1, "z": 8, "name": "Soil_Dirt"}, {"x": 11, "y": 0, "z": 8, "name": "Soil_Clay"}, {"x": 11, "y": 1, "z": 8, "name": "Wood_Hardwood_Fence", "rotation": 1}, {"x": 11, "y": 2, "z": 8, "name": "Wood_Hardwood_Fence", "rotation": 1}, {"x": 11, "y": -3, "z": 9, "name": "Soil_Dirt"}, {"x": 11, "y": -2, "z": 9, "name": "Soil_Dirt"}, {"x": 11, "y": -1, "z": 9, "name": "Soil_Dirt"}, {"x": 11, "y": 0, "z": 9, "name": "Soil_Clay"}, {"x": 11, "y": 1, "z": 9, "name": "Wood_Hardwood_Fence", "rotation": 1}, {"x": 11, "y": 2, "z": 9, "name": "Wood_Hardwood_Fence", "rotation": 1}, {"x": 11, "y": 4, "z": 9, "name": "Wood_Ash_Trunk", "rotation": 4}, {"x": 11, "y": -3, "z": 10, "name": "Soil_Dirt"}, {"x": 11, "y": -2, "z": 10, "name": "Soil_Dirt"}, {"x": 11, "y": -1, "z": 10, "name": "Soil_Dirt"}, {"x": 11, "y": 0, "z": 10, "name": "Wood_Ash_Trunk_Full"}, {"x": 11, "y": 1, "z": 10, "name": "Wood_Ash_Trunk_Full"}, {"x": 11, "y": 2, "z": 10, "name": "Wood_Ash_Trunk_Full"}, {"x": 11, "y": 3, "z": 10, "name": "Wood_Ash_Trunk_Full"}, {"x": 11, "y": 4, "z": 10, "name": "Wood_Ash_Trunk_Full", "rotation": 4}, {"x": 11, "y": -3, "z": 11, "name": "Soil_Dirt"}, {"x": 11, "y": -2, "z": 11, "name": "Soil_Dirt"}, {"x": 11, "y": -1, "z": 11, "name": "Soil_Dirt"}, {"x": 11, "y": 0, "z": 11, "name": "Soil_Clay"}, {"x": 11, "y": 3, "z": 11, "name": "Wood_Hardwood_Planks_Half", "rotation": 8}, {"x": 11, "y": 4, "z": 11, "name": "Wood_Ash_Trunk_Full", "rotation": 5}, {"x": 11, "y": 5, "z": 11, "name": "Wood_Hardwood_Planks_Half"}, {"x": 11, "y": -3, "z": 12, "name": "Soil_Dirt"}, {"x": 11, "y": -2, "z": 12, "name": "Soil_Dirt"}, {"x": 11, "y": -1, "z": 12, "name": "Soil_Dirt"}, {"x": 11, "y": 0, "z": 12, "name": "Soil_Clay"}, {"x": 11, "y": 4, "z": 12, "name": "Wood_Hardwood_Planks_Half", "rotation": 4}, {"x": 11, "y": -3, "z": 13, "name": "Soil_Dirt"}, {"x": 11, "y": -2, "z": 13, "name": "Soil_Dirt"}, {"x": 11, "y": -1, "z": 13, "name": "Soil_Dirt"}, {"x": 11, "y": 0, "z": 13, "name": "Soil_Clay"}, {"x": 11, "y": -3, "z": 14, "name": "Soil_Dirt"}, {"x": 11, "y": -2, "z": 14, "name": "Soil_Dirt"}, {"x": 11, "y": -1, "z": 14, "name": "Soil_Dirt"}, {"x": 11, "y": 0, "z": 14, "name": "Soil_Clay"}, {"x": 11, "y": -3, "z": 15, "name": "Soil_Dirt"}, {"x": 11, "y": -2, "z": 15, "name": "Soil_Dirt"}, {"x": 11, "y": -1, "z": 15, "name": "Soil_Dirt"}, {"x": 11, "y": 0, "z": 15, "name": "Soil_Clay"}, {"x": 11, "y": -3, "z": 16, "name": "Soil_Dirt"}, {"x": 11, "y": -2, "z": 16, "name": "Soil_Dirt"}, {"x": 11, "y": -1, "z": 16, "name": "Soil_Dirt"}, {"x": 11, "y": 0, "z": 16, "name": "Soil_Clay"}, {"x": 11, "y": -3, "z": 17, "name": "Soil_Dirt"}, {"x": 11, "y": -2, "z": 17, "name": "Soil_Dirt"}, {"x": 11, "y": -1, "z": 17, "name": "Soil_Dirt"}, {"x": 11, "y": 0, "z": 17, "name": "Soil_Clay"}, {"x": 11, "y": -3, "z": 18, "name": "Soil_Dirt"}, {"x": 11, "y": -2, "z": 18, "name": "Soil_Dirt"}, {"x": 11, "y": -1, "z": 18, "name": "Soil_Dirt"}, {"x": 11, "y": 0, "z": 18, "name": "Soil_Clay"}, {"x": 11, "y": -3, "z": 19, "name": "Soil_Dirt"}, {"x": 11, "y": -2, "z": 19, "name": "Soil_Dirt"}, {"x": 11, "y": -1, "z": 19, "name": "Soil_Dirt"}, {"x": 11, "y": 0, "z": 19, "name": "Soil_Clay"}, {"x": 11, "y": -3, "z": 20, "name": "Soil_Dirt"}, {"x": 11, "y": -2, "z": 20, "name": "Soil_Dirt"}, {"x": 11, "y": -1, "z": 20, "name": "Soil_Dirt"}, {"x": 11, "y": 0, "z": 20, "name": "Soil_Clay"}, {"x": 11, "y": -3, "z": 21, "name": "Soil_Dirt"}, {"x": 11, "y": -2, "z": 21, "name": "Soil_Dirt"}, {"x": 11, "y": -1, "z": 21, "name": "Soil_Dirt"}, {"x": 11, "y": 0, "z": 21, "name": "Soil_Clay"}, {"x": 11, "y": -3, "z": 22, "name": "Soil_Dirt"}, {"x": 11, "y": -2, "z": 22, "name": "Soil_Dirt"}, {"x": 11, "y": -1, "z": 22, "name": "Soil_Dirt"}, {"x": 11, "y": 0, "z": 22, "name": "Soil_Clay"}, {"x": 11, "y": 4, "z": 22, "name": "Wood_Hardwood_Planks_Half", "rotation": 6}, {"x": 11, "y": -3, "z": 23, "name": "Soil_Dirt"}, {"x": 11, "y": -2, "z": 23, "name": "Soil_Dirt"}, {"x": 11, "y": -1, "z": 23, "name": "Soil_Dirt"}, {"x": 11, "y": 0, "z": 23, "name": "Soil_Clay"}, {"x": 11, "y": 3, "z": 23, "name": "Wood_Hardwood_Planks_Half", "rotation": 8}, {"x": 11, "y": 4, "z": 23, "name": "Wood_Ash_Trunk_Full", "rotation": 5}, {"x": 11, "y": 5, "z": 23, "name": "Wood_Hardwood_Planks_Half"}, {"x": 11, "y": -3, "z": 24, "name": "Soil_Dirt"}, {"x": 11, "y": -2, "z": 24, "name": "Soil_Dirt"}, {"x": 11, "y": -1, "z": 24, "name": "Soil_Dirt"}, {"x": 11, "y": 0, "z": 24, "name": "Wood_Ash_Trunk_Full"}, {"x": 11, "y": 1, "z": 24, "name": "Wood_Ash_Trunk_Full"}, {"x": 11, "y": 2, "z": 24, "name": "Wood_Ash_Trunk_Full"}, {"x": 11, "y": 3, "z": 24, "name": "Wood_Ash_Trunk_Full"}, {"x": 11, "y": 4, "z": 24, "name": "Wood_Ash_Trunk_Full", "rotation": 4}, {"x": 11, "y": -3, "z": 25, "name": "Soil_Dirt"}, {"x": 11, "y": -2, "z": 25, "name": "Soil_Dirt"}, {"x": 11, "y": -1, "z": 25, "name": "Soil_Dirt"}, {"x": 11, "y": 0, "z": 25, "name": "Soil_Clay"}, {"x": 11, "y": 1, "z": 25, "name": "Wood_Hardwood_Fence", "rotation": 3}, {"x": 11, "y": 2, "z": 25, "name": "Wood_Hardwood_Fence", "rotation": 1}, {"x": 11, "y": 4, "z": 25, "name": "Wood_Ash_Trunk", "rotation": 4}, {"x": 11, "y": -3, "z": 26, "name": "Soil_Dirt"}, {"x": 11, "y": -2, "z": 26, "name": "Soil_Dirt"}, {"x": 11, "y": -1, "z": 26, "name": "Soil_Dirt"}, {"x": 11, "y": 0, "z": 26, "name": "Soil_Clay"}, {"x": 11, "y": 1, "z": 26, "name": "Wood_Hardwood_Fence", "rotation": 3}, {"x": 11, "y": 2, "z": 26, "name": "Wood_Hardwood_Fence", "rotation": 1}, {"x": 11, "y": -3, "z": 27, "name": "Soil_Dirt"}, {"x": 11, "y": -2, "z": 27, "name": "Soil_Dirt"}, {"x": 11, "y": -1, "z": 27, "name": "Soil_Dirt"}, {"x": 11, "y": 0, "z": 27, "name": "Soil_Clay"}, {"x": 11, "y": 1, "z": 27, "name": "*Wood_Hardwood_Fence_State_Definitions_Corner", "rotation": 2}, {"x": 11, "y": 2, "z": 27, "name": "*Wood_Hardwood_Fence_State_Definitions_Corner", "rotation": 2}, {"x": 11, "y": -3, "z": 28, "name": "Soil_Dirt"}, {"x": 11, "y": -2, "z": 28, "name": "Soil_Dirt"}, {"x": 11, "y": -1, "z": 28, "name": "Soil_Dirt"}, {"x": 11, "y": 0, "z": 28, "name": "Soil_Grass"}, {"x": 11, "y": -3, "z": 29, "name": "Soil_Dirt"}, {"x": 11, "y": -2, "z": 29, "name": "Soil_Dirt"}, {"x": 11, "y": -1, "z": 29, "name": "Soil_Dirt"}, {"x": 11, "y": 0, "z": 29, "name": "Soil_Grass"}, {"x": 11, "y": -3, "z": 30, "name": "Soil_Dirt"}, {"x": 11, "y": -2, "z": 30, "name": "Soil_Dirt"}, {"x": 11, "y": -1, "z": 30, "name": "Soil_Dirt"}, {"x": 11, "y": 0, "z": 30, "name": "Soil_Grass"}, {"x": 11, "y": -3, "z": 31, "name": "Soil_Dirt"}, {"x": 11, "y": -2, "z": 31, "name": "Soil_Dirt"}, {"x": 11, "y": -1, "z": 31, "name": "Soil_Dirt"}, {"x": 11, "y": 0, "z": 31, "name": "Soil_Grass"}, {"x": 12, "y": -3, "z": 0, "name": "Soil_Dirt"}, {"x": 12, "y": -2, "z": 0, "name": "Soil_Dirt"}, {"x": 12, "y": -1, "z": 0, "name": "Soil_Dirt"}, {"x": 12, "y": 0, "z": 0, "name": "Soil_Grass"}, {"x": 12, "y": -3, "z": 1, "name": "Soil_Dirt"}, {"x": 12, "y": -2, "z": 1, "name": "Soil_Dirt"}, {"x": 12, "y": -1, "z": 1, "name": "Soil_Dirt"}, {"x": 12, "y": 0, "z": 1, "name": "Soil_Grass"}, {"x": 12, "y": -3, "z": 2, "name": "Soil_Dirt"}, {"x": 12, "y": -2, "z": 2, "name": "Soil_Dirt"}, {"x": 12, "y": -1, "z": 2, "name": "Soil_Dirt"}, {"x": 12, "y": 0, "z": 2, "name": "Soil_Grass"}, {"x": 12, "y": -3, "z": 3, "name": "Soil_Dirt"}, {"x": 12, "y": -2, "z": 3, "name": "Soil_Dirt"}, {"x": 12, "y": -1, "z": 3, "name": "Soil_Dirt"}, {"x": 12, "y": 0, "z": 3, "name": "Soil_Grass"}, {"x": 12, "y": -3, "z": 4, "name": "Soil_Dirt"}, {"x": 12, "y": -2, "z": 4, "name": "Soil_Dirt"}, {"x": 12, "y": -1, "z": 4, "name": "Soil_Dirt"}, {"x": 12, "y": 0, "z": 4, "name": "Soil_Grass"}, {"x": 12, "y": -3, "z": 5, "name": "Soil_Dirt"}, {"x": 12, "y": -2, "z": 5, "name": "Soil_Dirt"}, {"x": 12, "y": -1, "z": 5, "name": "Soil_Dirt"}, {"x": 12, "y": 0, "z": 5, "name": "Soil_Grass"}, {"x": 12, "y": -3, "z": 6, "name": "Soil_Dirt"}, {"x": 12, "y": -2, "z": 6, "name": "Soil_Dirt"}, {"x": 12, "y": -1, "z": 6, "name": "Soil_Dirt"}, {"x": 12, "y": 0, "z": 6, "name": "Soil_Grass"}, {"x": 12, "y": -3, "z": 7, "name": "Soil_Dirt"}, {"x": 12, "y": -2, "z": 7, "name": "Soil_Dirt"}, {"x": 12, "y": -1, "z": 7, "name": "Soil_Dirt"}, {"x": 12, "y": 0, "z": 7, "name": "Soil_Clay"}, {"x": 12, "y": 1, "z": 7, "name": "Wood_Hardwood_Fence"}, {"x": 12, "y": 2, "z": 7, "name": "Wood_Hardwood_Fence"}, {"x": 12, "y": -3, "z": 8, "name": "Soil_Dirt"}, {"x": 12, "y": -2, "z": 8, "name": "Soil_Dirt"}, {"x": 12, "y": -1, "z": 8, "name": "Soil_Dirt"}, {"x": 12, "y": 0, "z": 8, "name": "Soil_Clay"}, {"x": 12, "y": -3, "z": 9, "name": "Soil_Dirt"}, {"x": 12, "y": -2, "z": 9, "name": "Soil_Dirt"}, {"x": 12, "y": -1, "z": 9, "name": "Soil_Dirt"}, {"x": 12, "y": 0, "z": 9, "name": "Soil_Clay"}, {"x": 12, "y": -3, "z": 10, "name": "Soil_Dirt"}, {"x": 12, "y": -2, "z": 10, "name": "Soil_Dirt"}, {"x": 12, "y": -1, "z": 10, "name": "Soil_Dirt"}, {"x": 12, "y": 0, "z": 10, "name": "Soil_Clay"}, {"x": 12, "y": -3, "z": 11, "name": "Soil_Dirt"}, {"x": 12, "y": -2, "z": 11, "name": "Soil_Dirt"}, {"x": 12, "y": -1, "z": 11, "name": "Soil_Dirt"}, {"x": 12, "y": 0, "z": 11, "name": "Soil_Clay"}, {"x": 12, "y": 4, "z": 11, "name": "Wood_Ash_Trunk_Full", "rotation": 5}, {"x": 12, "y": -3, "z": 12, "name": "Soil_Dirt"}, {"x": 12, "y": -2, "z": 12, "name": "Soil_Dirt"}, {"x": 12, "y": -1, "z": 12, "name": "Soil_Dirt"}, {"x": 12, "y": 0, "z": 12, "name": "Soil_Clay"}, {"x": 12, "y": -3, "z": 13, "name": "Soil_Dirt"}, {"x": 12, "y": -2, "z": 13, "name": "Soil_Dirt"}, {"x": 12, "y": -1, "z": 13, "name": "Soil_Dirt"}, {"x": 12, "y": 0, "z": 13, "name": "Soil_Clay"}, {"x": 12, "y": -3, "z": 14, "name": "Soil_Dirt"}, {"x": 12, "y": -2, "z": 14, "name": "Soil_Dirt"}, {"x": 12, "y": -1, "z": 14, "name": "Soil_Dirt"}, {"x": 12, "y": 0, "z": 14, "name": "Soil_Clay"}, {"x": 12, "y": -3, "z": 15, "name": "Soil_Dirt"}, {"x": 12, "y": -2, "z": 15, "name": "Soil_Dirt"}, {"x": 12, "y": -1, "z": 15, "name": "Soil_Dirt"}, {"x": 12, "y": 0, "z": 15, "name": "Soil_Clay"}, {"x": 12, "y": -3, "z": 16, "name": "Soil_Dirt"}, {"x": 12, "y": -2, "z": 16, "name": "Soil_Dirt"}, {"x": 12, "y": -1, "z": 16, "name": "Soil_Dirt"}, {"x": 12, "y": 0, "z": 16, "name": "Soil_Clay"}, {"x": 12, "y": -3, "z": 17, "name": "Soil_Dirt"}, {"x": 12, "y": -2, "z": 17, "name": "Soil_Dirt"}, {"x": 12, "y": -1, "z": 17, "name": "Soil_Dirt"}, {"x": 12, "y": 0, "z": 17, "name": "Soil_Clay"}, {"x": 12, "y": -3, "z": 18, "name": "Soil_Dirt"}, {"x": 12, "y": -2, "z": 18, "name": "Soil_Dirt"}, {"x": 12, "y": -1, "z": 18, "name": "Soil_Dirt"}, {"x": 12, "y": 0, "z": 18, "name": "Soil_Clay"}, {"x": 12, "y": -3, "z": 19, "name": "Soil_Dirt"}, {"x": 12, "y": -2, "z": 19, "name": "Soil_Dirt"}, {"x": 12, "y": -1, "z": 19, "name": "Soil_Dirt"}, {"x": 12, "y": 0, "z": 19, "name": "Soil_Clay"}, {"x": 12, "y": -3, "z": 20, "name": "Soil_Dirt"}, {"x": 12, "y": -2, "z": 20, "name": "Soil_Dirt"}, {"x": 12, "y": -1, "z": 20, "name": "Soil_Dirt"}, {"x": 12, "y": 0, "z": 20, "name": "Soil_Clay"}, {"x": 12, "y": -3, "z": 21, "name": "Soil_Dirt"}, {"x": 12, "y": -2, "z": 21, "name": "Soil_Dirt"}, {"x": 12, "y": -1, "z": 21, "name": "Soil_Dirt"}, {"x": 12, "y": 0, "z": 21, "name": "Soil_Clay"}, {"x": 12, "y": -3, "z": 22, "name": "Soil_Dirt"}, {"x": 12, "y": -2, "z": 22, "name": "Soil_Dirt"}, {"x": 12, "y": -1, "z": 22, "name": "Soil_Dirt"}, {"x": 12, "y": 0, "z": 22, "name": "Soil_Clay"}, {"x": 12, "y": -3, "z": 23, "name": "Soil_Dirt"}, {"x": 12, "y": -2, "z": 23, "name": "Soil_Dirt"}, {"x": 12, "y": -1, "z": 23, "name": "Soil_Dirt"}, {"x": 12, "y": 0, "z": 23, "name": "Soil_Clay"}, {"x": 12, "y": 4, "z": 23, "name": "Wood_Ash_Trunk_Full", "rotation": 5}, {"x": 12, "y": -3, "z": 24, "name": "Soil_Dirt"}, {"x": 12, "y": -2, "z": 24, "name": "Soil_Dirt"}, {"x": 12, "y": -1, "z": 24, "name": "Soil_Dirt"}, {"x": 12, "y": 0, "z": 24, "name": "Soil_Clay"}, {"x": 12, "y": -3, "z": 25, "name": "Soil_Dirt"}, {"x": 12, "y": -2, "z": 25, "name": "Soil_Dirt"}, {"x": 12, "y": -1, "z": 25, "name": "Soil_Dirt"}, {"x": 12, "y": 0, "z": 25, "name": "Soil_Clay"}, {"x": 12, "y": -3, "z": 26, "name": "Soil_Dirt"}, {"x": 12, "y": -2, "z": 26, "name": "Soil_Dirt"}, {"x": 12, "y": -1, "z": 26, "name": "Soil_Dirt"}, {"x": 12, "y": 0, "z": 26, "name": "K2_Slot_Portal_4"}, {"x": 12, "y": -3, "z": 27, "name": "Soil_Dirt"}, {"x": 12, "y": -2, "z": 27, "name": "Soil_Dirt"}, {"x": 12, "y": -1, "z": 27, "name": "Soil_Dirt"}, {"x": 12, "y": 0, "z": 27, "name": "Soil_Clay"}, {"x": 12, "y": 1, "z": 27, "name": "Wood_Hardwood_Fence", "rotation": 2}, {"x": 12, "y": 2, "z": 27, "name": "Wood_Hardwood_Fence", "rotation": 2}, {"x": 12, "y": -3, "z": 28, "name": "Soil_Dirt"}, {"x": 12, "y": -2, "z": 28, "name": "Soil_Dirt"}, {"x": 12, "y": -1, "z": 28, "name": "Soil_Dirt"}, {"x": 12, "y": 0, "z": 28, "name": "Soil_Grass"}, {"x": 12, "y": -3, "z": 29, "name": "Soil_Dirt"}, {"x": 12, "y": -2, "z": 29, "name": "Soil_Dirt"}, {"x": 12, "y": -1, "z": 29, "name": "Soil_Dirt"}, {"x": 12, "y": 0, "z": 29, "name": "Soil_Grass"}, {"x": 12, "y": -3, "z": 30, "name": "Soil_Dirt"}, {"x": 12, "y": -2, "z": 30, "name": "Soil_Dirt"}, {"x": 12, "y": -1, "z": 30, "name": "Soil_Dirt"}, {"x": 12, "y": 0, "z": 30, "name": "Soil_Grass"}, {"x": 12, "y": -3, "z": 31, "name": "Soil_Dirt"}, {"x": 12, "y": -2, "z": 31, "name": "Soil_Dirt"}, {"x": 12, "y": -1, "z": 31, "name": "Soil_Dirt"}, {"x": 12, "y": 0, "z": 31, "name": "Soil_Grass"}, {"x": 13, "y": -3, "z": 0, "name": "Soil_Dirt"}, {"x": 13, "y": -2, "z": 0, "name": "Soil_Dirt"}, {"x": 13, "y": -1, "z": 0, "name": "Soil_Dirt"}, {"x": 13, "y": 0, "z": 0, "name": "Soil_Grass"}, {"x": 13, "y": -3, "z": 1, "name": "Soil_Dirt"}, {"x": 13, "y": -2, "z": 1, "name": "Soil_Dirt"}, {"x": 13, "y": -1, "z": 1, "name": "Soil_Dirt"}, {"x": 13, "y": 0, "z": 1, "name": "Soil_Grass"}, {"x": 13, "y": -3, "z": 2, "name": "Soil_Dirt"}, {"x": 13, "y": -2, "z": 2, "name": "Soil_Dirt"}, {"x": 13, "y": -1, "z": 2, "name": "Soil_Dirt"}, {"x": 13, "y": 0, "z": 2, "name": "Soil_Grass"}, {"x": 13, "y": -3, "z": 3, "name": "Soil_Dirt"}, {"x": 13, "y": -2, "z": 3, "name": "Soil_Dirt"}, {"x": 13, "y": -1, "z": 3, "name": "Soil_Dirt"}, {"x": 13, "y": 0, "z": 3, "name": "Soil_Grass"}, {"x": 13, "y": -3, "z": 4, "name": "Soil_Dirt"}, {"x": 13, "y": -2, "z": 4, "name": "Soil_Dirt"}, {"x": 13, "y": -1, "z": 4, "name": "Soil_Dirt"}, {"x": 13, "y": 0, "z": 4, "name": "Soil_Grass"}, {"x": 13, "y": -3, "z": 5, "name": "Soil_Dirt"}, {"x": 13, "y": -2, "z": 5, "name": "Soil_Dirt"}, {"x": 13, "y": -1, "z": 5, "name": "Soil_Dirt"}, {"x": 13, "y": 0, "z": 5, "name": "Soil_Grass"}, {"x": 13, "y": -3, "z": 6, "name": "Soil_Dirt"}, {"x": 13, "y": -2, "z": 6, "name": "Soil_Dirt"}, {"x": 13, "y": -1, "z": 6, "name": "Soil_Dirt"}, {"x": 13, "y": 0, "z": 6, "name": "Soil_Grass"}, {"x": 13, "y": -3, "z": 7, "name": "Soil_Dirt"}, {"x": 13, "y": -2, "z": 7, "name": "Soil_Dirt"}, {"x": 13, "y": -1, "z": 7, "name": "Soil_Dirt"}, {"x": 13, "y": 0, "z": 7, "name": "Soil_Clay"}, {"x": 13, "y": 1, "z": 7, "name": "Wood_Hardwood_Fence"}, {"x": 13, "y": 2, "z": 7, "name": "Wood_Hardwood_Fence"}, {"x": 13, "y": -3, "z": 8, "name": "Soil_Dirt"}, {"x": 13, "y": -2, "z": 8, "name": "Soil_Dirt"}, {"x": 13, "y": -1, "z": 8, "name": "Soil_Dirt"}, {"x": 13, "y": 0, "z": 8, "name": "Soil_Clay"}, {"x": 13, "y": -3, "z": 9, "name": "Soil_Dirt"}, {"x": 13, "y": -2, "z": 9, "name": "Soil_Dirt"}, {"x": 13, "y": -1, "z": 9, "name": "Soil_Dirt"}, {"x": 13, "y": 0, "z": 9, "name": "Soil_Clay"}, {"x": 13, "y": -3, "z": 10, "name": "Soil_Dirt"}, {"x": 13, "y": -2, "z": 10, "name": "Soil_Dirt"}, {"x": 13, "y": -1, "z": 10, "name": "Soil_Dirt"}, {"x": 13, "y": 0, "z": 10, "name": "Soil_Clay"}, {"x": 13, "y": -3, "z": 11, "name": "Soil_Dirt"}, {"x": 13, "y": -2, "z": 11, "name": "Soil_Dirt"}, {"x": 13, "y": -1, "z": 11, "name": "Soil_Dirt"}, {"x": 13, "y": 0, "z": 11, "name": "Soil_Clay"}, {"x": 13, "y": 4, "z": 11, "name": "Wood_Ash_Trunk_Full", "rotation": 5}, {"x": 13, "y": -3, "z": 12, "name": "Soil_Dirt"}, {"x": 13, "y": -2, "z": 12, "name": "Soil_Dirt"}, {"x": 13, "y": -1, "z": 12, "name": "Soil_Dirt"}, {"x": 13, "y": 0, "z": 12, "name": "Soil_Clay"}, {"x": 13, "y": -3, "z": 13, "name": "Soil_Dirt"}, {"x": 13, "y": -2, "z": 13, "name": "Soil_Dirt"}, {"x": 13, "y": -1, "z": 13, "name": "Soil_Dirt"}, {"x": 13, "y": 0, "z": 13, "name": "Soil_Clay"}, {"x": 13, "y": -3, "z": 14, "name": "Soil_Dirt"}, {"x": 13, "y": -2, "z": 14, "name": "Soil_Dirt"}, {"x": 13, "y": -1, "z": 14, "name": "Soil_Dirt"}, {"x": 13, "y": 0, "z": 14, "name": "Soil_Clay"}, {"x": 13, "y": -3, "z": 15, "name": "Soil_Dirt"}, {"x": 13, "y": -2, "z": 15, "name": "Soil_Dirt"}, {"x": 13, "y": -1, "z": 15, "name": "Soil_Dirt"}, {"x": 13, "y": 0, "z": 15, "name": "Soil_Clay"}, {"x": 13, "y": -3, "z": 16, "name": "Soil_Dirt"}, {"x": 13, "y": -2, "z": 16, "name": "Soil_Dirt"}, {"x": 13, "y": -1, "z": 16, "name": "Soil_Dirt"}, {"x": 13, "y": 0, "z": 16, "name": "Soil_Clay"}, {"x": 13, "y": -3, "z": 17, "name": "Soil_Dirt"}, {"x": 13, "y": -2, "z": 17, "name": "Soil_Dirt"}, {"x": 13, "y": -1, "z": 17, "name": "Soil_Dirt"}, {"x": 13, "y": 0, "z": 17, "name": "Soil_Clay"}, {"x": 13, "y": -3, "z": 18, "name": "Soil_Dirt"}, {"x": 13, "y": -2, "z": 18, "name": "Soil_Dirt"}, {"x": 13, "y": -1, "z": 18, "name": "Soil_Dirt"}, {"x": 13, "y": 0, "z": 18, "name": "Soil_Clay"}, {"x": 13, "y": -3, "z": 19, "name": "Soil_Dirt"}, {"x": 13, "y": -2, "z": 19, "name": "Soil_Dirt"}, {"x": 13, "y": -1, "z": 19, "name": "Soil_Dirt"}, {"x": 13, "y": 0, "z": 19, "name": "Soil_Clay"}, {"x": 13, "y": -3, "z": 20, "name": "Soil_Dirt"}, {"x": 13, "y": -2, "z": 20, "name": "Soil_Dirt"}, {"x": 13, "y": -1, "z": 20, "name": "Soil_Dirt"}, {"x": 13, "y": 0, "z": 20, "name": "Soil_Clay"}, {"x": 13, "y": -3, "z": 21, "name": "Soil_Dirt"}, {"x": 13, "y": -2, "z": 21, "name": "Soil_Dirt"}, {"x": 13, "y": -1, "z": 21, "name": "Soil_Dirt"}, {"x": 13, "y": 0, "z": 21, "name": "Soil_Clay"}, {"x": 13, "y": -3, "z": 22, "name": "Soil_Dirt"}, {"x": 13, "y": -2, "z": 22, "name": "Soil_Dirt"}, {"x": 13, "y": -1, "z": 22, "name": "Soil_Dirt"}, {"x": 13, "y": 0, "z": 22, "name": "Soil_Clay"}, {"x": 13, "y": -3, "z": 23, "name": "Soil_Dirt"}, {"x": 13, "y": -2, "z": 23, "name": "Soil_Dirt"}, {"x": 13, "y": -1, "z": 23, "name": "Soil_Dirt"}, {"x": 13, "y": 0, "z": 23, "name": "Soil_Clay"}, {"x": 13, "y": 4, "z": 23, "name": "Wood_Ash_Trunk_Full", "rotation": 5}, {"x": 13, "y": -3, "z": 24, "name": "Soil_Dirt"}, {"x": 13, "y": -2, "z": 24, "name": "Soil_Dirt"}, {"x": 13, "y": -1, "z": 24, "name": "Soil_Dirt"}, {"x": 13, "y": 0, "z": 24, "name": "Soil_Clay"}, {"x": 13, "y": -3, "z": 25, "name": "Soil_Dirt"}, {"x": 13, "y": -2, "z": 25, "name": "Soil_Dirt"}, {"x": 13, "y": -1, "z": 25, "name": "Soil_Dirt"}, {"x": 13, "y": 0, "z": 25, "name": "Soil_Clay"}, {"x": 13, "y": -3, "z": 26, "name": "Soil_Dirt"}, {"x": 13, "y": -2, "z": 26, "name": "Soil_Dirt"}, {"x": 13, "y": -1, "z": 26, "name": "Soil_Dirt"}, {"x": 13, "y": 0, "z": 26, "name": "Soil_Clay"}, {"x": 13, "y": -3, "z": 27, "name": "Soil_Dirt"}, {"x": 13, "y": -2, "z": 27, "name": "Soil_Dirt"}, {"x": 13, "y": -1, "z": 27, "name": "Soil_Dirt"}, {"x": 13, "y": 0, "z": 27, "name": "Soil_Clay"}, {"x": 13, "y": 1, "z": 27, "name": "Wood_Hardwood_Fence", "rotation": 2}, {"x": 13, "y": 2, "z": 27, "name": "Wood_Hardwood_Fence", "rotation": 2}, {"x": 13, "y": -3, "z": 28, "name": "Soil_Dirt"}, {"x": 13, "y": -2, "z": 28, "name": "Soil_Dirt"}, {"x": 13, "y": -1, "z": 28, "name": "Soil_Dirt"}, {"x": 13, "y": 0, "z": 28, "name": "Soil_Grass"}, {"x": 13, "y": -3, "z": 29, "name": "Soil_Dirt"}, {"x": 13, "y": -2, "z": 29, "name": "Soil_Dirt"}, {"x": 13, "y": -1, "z": 29, "name": "Soil_Dirt"}, {"x": 13, "y": 0, "z": 29, "name": "Soil_Grass"}, {"x": 13, "y": -3, "z": 30, "name": "Soil_Dirt"}, {"x": 13, "y": -2, "z": 30, "name": "Soil_Dirt"}, {"x": 13, "y": -1, "z": 30, "name": "Soil_Dirt"}, {"x": 13, "y": 0, "z": 30, "name": "Soil_Grass"}, {"x": 13, "y": -3, "z": 31, "name": "Soil_Dirt"}, {"x": 13, "y": -2, "z": 31, "name": "Soil_Dirt"}, {"x": 13, "y": -1, "z": 31, "name": "Soil_Dirt"}, {"x": 13, "y": 0, "z": 31, "name": "Soil_Grass"}, {"x": 14, "y": -3, "z": 0, "name": "Soil_Dirt"}, {"x": 14, "y": -2, "z": 0, "name": "Soil_Dirt"}, {"x": 14, "y": -1, "z": 0, "name": "Soil_Dirt"}, {"x": 14, "y": 0, "z": 0, "name": "Soil_Grass"}, {"x": 14, "y": -3, "z": 1, "name": "Soil_Dirt"}, {"x": 14, "y": -2, "z": 1, "name": "Soil_Dirt"}, {"x": 14, "y": -1, "z": 1, "name": "Soil_Dirt"}, {"x": 14, "y": 0, "z": 1, "name": "Soil_Grass"}, {"x": 14, "y": -3, "z": 2, "name": "Soil_Dirt"}, {"x": 14, "y": -2, "z": 2, "name": "Soil_Dirt"}, {"x": 14, "y": -1, "z": 2, "name": "Soil_Dirt"}, {"x": 14, "y": 0, "z": 2, "name": "Soil_Grass"}, {"x": 14, "y": -3, "z": 3, "name": "Soil_Dirt"}, {"x": 14, "y": -2, "z": 3, "name": "Soil_Dirt"}, {"x": 14, "y": -1, "z": 3, "name": "Soil_Dirt"}, {"x": 14, "y": 0, "z": 3, "name": "Soil_Grass"}, {"x": 14, "y": -3, "z": 4, "name": "Soil_Dirt"}, {"x": 14, "y": -2, "z": 4, "name": "Soil_Dirt"}, {"x": 14, "y": -1, "z": 4, "name": "Soil_Dirt"}, {"x": 14, "y": 0, "z": 4, "name": "Soil_Grass"}, {"x": 14, "y": -3, "z": 5, "name": "Soil_Dirt"}, {"x": 14, "y": -2, "z": 5, "name": "Soil_Dirt"}, {"x": 14, "y": -1, "z": 5, "name": "Soil_Dirt"}, {"x": 14, "y": 0, "z": 5, "name": "Soil_Grass"}, {"x": 14, "y": -3, "z": 6, "name": "Soil_Dirt"}, {"x": 14, "y": -2, "z": 6, "name": "Soil_Dirt"}, {"x": 14, "y": -1, "z": 6, "name": "Soil_Dirt"}, {"x": 14, "y": 0, "z": 6, "name": "Soil_Grass"}, {"x": 14, "y": -3, "z": 7, "name": "Soil_Dirt"}, {"x": 14, "y": -2, "z": 7, "name": "Soil_Dirt"}, {"x": 14, "y": -1, "z": 7, "name": "Soil_Dirt"}, {"x": 14, "y": 0, "z": 7, "name": "Soil_Clay"}, {"x": 14, "y": 1, "z": 7, "name": "Wood_Hardwood_Fence"}, {"x": 14, "y": 2, "z": 7, "name": "Wood_Hardwood_Fence"}, {"x": 14, "y": -3, "z": 8, "name": "Soil_Dirt"}, {"x": 14, "y": -2, "z": 8, "name": "Soil_Dirt"}, {"x": 14, "y": -1, "z": 8, "name": "Soil_Dirt"}, {"x": 14, "y": 0, "z": 8, "name": "Soil_Clay"}, {"x": 14, "y": -3, "z": 9, "name": "Soil_Dirt"}, {"x": 14, "y": -2, "z": 9, "name": "Soil_Dirt"}, {"x": 14, "y": -1, "z": 9, "name": "Soil_Dirt"}, {"x": 14, "y": 0, "z": 9, "name": "Soil_Clay"}, {"x": 14, "y": -3, "z": 10, "name": "Soil_Dirt"}, {"x": 14, "y": -2, "z": 10, "name": "Soil_Dirt"}, {"x": 14, "y": -1, "z": 10, "name": "Soil_Dirt"}, {"x": 14, "y": 0, "z": 10, "name": "Plant_Crop_Mushroom_Block_Brown"}, {"x": 14, "y": -3, "z": 11, "name": "Soil_Dirt"}, {"x": 14, "y": -2, "z": 11, "name": "Soil_Dirt"}, {"x": 14, "y": -1, "z": 11, "name": "Soil_Dirt"}, {"x": 14, "y": 0, "z": 11, "name": "Plant_Crop_Mushroom_Block_Brown"}, {"x": 14, "y": 4, "z": 11, "name": "Wood_Ash_Trunk_Full", "rotation": 5}, {"x": 14, "y": -3, "z": 12, "name": "Soil_Dirt"}, {"x": 14, "y": -2, "z": 12, "name": "Soil_Dirt"}, {"x": 14, "y": -1, "z": 12, "name": "Soil_Dirt"}, {"x": 14, "y": 0, "z": 12, "name": "Plant_Crop_Mushroom_Block_Brown"}, {"x": 14, "y": -3, "z": 13, "name": "Soil_Dirt"}, {"x": 14, "y": -2, "z": 13, "name": "Soil_Dirt"}, {"x": 14, "y": -1, "z": 13, "name": "Soil_Dirt"},