{"version": 8, "blockIdVersion": 11, "anchorX": 0, "anchorY": 0, "anchorZ": 0, "blocks": [{"x": 0, "y": -3, "z": 0, "name": "Soil_Dirt"}, {"x": 0, "y": -2, "z": 0, "name": "Soil_Dirt"}, {"x": 0, "y": -1, "z": 0, "name": "Soil_Dirt"}, {"x": 0, "y": 0, "z": 0, "name": "Soil_Grass"}, {"x": 0, "y": -3, "z": 1, "name": "Soil_Dirt"}, {"x": 0, "y": -2, "z": 1, "name": "Soil_Dirt"}, {"x": 0, "y": -1, "z": 1, "name": "Soil_Dirt"}, {"x": 0, "y": 0, "z": 1, "name": "Soil_Grass"}, {"x": 0, "y": -3, "z": 2, "name": "Soil_Dirt"}, {"x": 0, "y": -2, "z": 2, "name": "Soil_Dirt"}, {"x": 0, "y": -1, "z": 2, "name": "Soil_Dirt"}, {"x": 0, "y": 0, "z": 2, "name": "Soil_Grass"}, {"x": 0, "y": -3, "z": 3, "name": "Soil_Dirt"}, {"x": 0, "y": -2, "z": 3, "name": "Soil_Dirt"}, {"x": 0, "y": -1, "z": 3, "name": "Soil_Dirt"}, {"x": 0, "y": 0, "z": 3, "name": "Soil_Grass"}, {"x": 0, "y": -3, "z": 4, "name": "Soil_Dirt"}, {"x": 0, "y": -2, "z": 4, "name": "Soil_Dirt"}, {"x": 0, "y": -1, "z": 4, "name": "Soil_Dirt"}, {"x": 0, "y": 0, "z": 4, "name": "Soil_Grass"}, {"x": 0, "y": -3, "z": 5, "name": "Soil_Dirt"}, {"x": 0, "y": -2, "z": 5, "name": "Soil_Dirt"}, {"x": 0, "y": -1, "z": 5, "name": "Soil_Dirt"}, {"x": 0, "y": 0, "z": 5, "name": "Soil_Grass"}, {"x": 0, "y": -3, "z": 6, "name": "Soil_Dirt"}, {"x": 0, "y": -2, "z": 6, "name": "Soil_Dirt"}, {"x": 0, "y": -1, "z": 6, "name": "Soil_Dirt"}, {"x": 0, "y": 0, "z": 6, "name": "Soil_Grass"}, {"x": 0, "y": -3, "z": 7, "name": "Soil_Dirt"}, {"x": 0, "y": -2, "z": 7, "name": "Soil_Dirt"}, {"x": 0, "y": -1, "z": 7, "name": "Soil_Dirt"}, {"x": 0, "y": 0, "z": 7, "name": "Soil_Grass"}, {"x": 0, "y": -3, "z": 8, "name": "Soil_Dirt"}, {"x": 0, "y": -2, "z": 8, "name": "Soil_Dirt"}, {"x": 0, "y": -1, "z": 8, "name": "Soil_Dirt"}, {"x": 0, "y": 0, "z": 8, "name": "Soil_Grass"}, {"x": 0, "y": -3, "z": 9, "name": "Soil_Dirt"}, {"x": 0, "y": -2, "z": 9, "name": "Soil_Dirt"}, {"x": 0, "y": -1, "z": 9, "name": "Soil_Dirt"}, {"x": 0, "y": 0, "z": 9, "name": "Soil_Grass"}, {"x": 0, "y": -3, "z": 10, "name": "Soil_Dirt"}, {"x": 0, "y": -2, "z": 10, "name": "Soil_Dirt"}, {"x": 0, "y": -1, "z": 10, "name": "Soil_Dirt"}, {"x": 0, "y": 0, "z": 10, "name": "Soil_Dirt"}, {"x": 0, "y": 1, "z": 10, "name": "Rock_Calcite_Brick_Decorative"}, {"x": 0, "y": 2, "z": 10, "name": "Rock_Lime_Brick_Smooth"}, {"x": 0, "y": 3, "z": 10, "name": "Rock_Lime_Brick_Smooth"}, {"x": 0, "y": 4, "z": 10, "name": "Rock_Lime_Brick_Smooth"}, {"x": 0, "y": 5, "z": 10, "name": "Rock_Calcite_Brick"}, {"x": 0, "y": -3, "z": 11, "name": "Soil_Dirt"}, {"x": 0, "y": -2, "z": 11, "name": "Soil_Dirt"}, {"x": 0, "y": -1, "z": 11, "name": "Soil_Dirt"}, {"x": 0, "y": 0, "z": 11, "name": "Soil_Dirt"}, {"x": 0, "y": 1, "z": 11, "name": "Rock_Calcite_Brick_Decorative"}, {"x": 0, "y": 2, "z": 11, "name": "Rock_Lime_Brick_Smooth"}, {"x": 0, "y": 3, "z": 11, "name": "Rock_Lime_Brick_Smooth"}, {"x": 0, "y": 4, "z": 11, "name": "Rock_Lime_Brick_Smooth"}, {"x": 0, "y": 5, "z": 11, "name": "Rock_Calcite_Brick"}, {"x": 0, "y": -3, "z": 12, "name": "Soil_Dirt"}, {"x": 0, "y": -2, "z": 12, "name": "Soil_Dirt"}, {"x": 0, "y": -1, "z": 12, "name": "Soil_Dirt"}, {"x": 0, "y": 0, "z": 12, "name": "Soil_Dirt"}, {"x": 0, "y": 1, "z": 12, "name": "Rock_Calcite_Brick_Decorative"}, {"x": 0, "y": 2, "z": 12, "name": "Rock_Lime_Brick_Smooth"}, {"x": 0, "y": 3, "z": 12, "name": "Rock_Lime_Brick_Smooth"}, {"x": 0, "y": 4, "z": 12, "name": "Rock_Lime_Brick_Smooth"}, {"x": 0, "y": 5, "z": 12, "name": "Rock_Calcite_Brick"}, {"x": 0, "y": -3, "z": 13, "name": "Soil_Dirt"}, {"x": 0, "y": -2, "z": 13, "name": "Soil_Dirt"}, {"x": 0, "y": -1, "z": 13, "name": "Soil_Dirt"}, {"x": 0, "y": 0, "z": 13, "name": "Soil_Dirt"}, {"x": 0, "y": 1, "z": 13, "name": "Rock_Calcite_Brick_Decorative"}, {"x": 0, "y": 2, "z": 13, "name": "Rock_Lime_Brick_Smooth"}, {"x": 0, "y": 3, "z": 13, "name": "Rock_Lime_Brick_Smooth"}, {"x": 0, "y": 4, "z": 13, "name": "Rock_Lime_Brick_Smooth"}, {"x": 0, "y": 5, "z": 13, "name": "Rock_Calcite_Brick"}, {"x": 0, "y": -3, "z": 14, "name": "Soil_Dirt"}, {"x": 0, "y": -2, "z": 14, "name": "Soil_Dirt"}, {"x": 0, "y": -1, "z": 14, "name": "Soil_Dirt"}, {"x": 0, "y": 0, "z": 14, "name": "Soil_Dirt"}, {"x": 0, "y": 1, "z": 14, "name": "Rock_Calcite_Brick_Decorative"}, {"x": 0, "y": 2, "z": 14, "name": "Rock_Lime_Brick_Smooth"}, {"x": 0, "y": 3, "z": 14, "name": "Rock_Lime_Brick_Smooth"}, {"x": 0, "y": 4, "z": 14, "name": "Rock_Lime_Brick_Smooth"}, {"x": 0, "y": 5, "z": 14, "name": "Rock_Calcite_Brick"}, {"x": 0, "y": -3, "z": 15, "name": "Soil_Dirt"}, {"x": 0, "y": -2, "z": 15, "name": "Soil_Dirt"}, {"x": 0, "y": -1, "z": 15, "name": "Soil_Dirt"}, {"x": 0, "y": 0, "z": 15, "name": "Soil_Dirt"}, {"x": 0, "y": 1, "z": 15, "name": "Rock_Calcite_Brick_Decorative"}, {"x": 0, "y": 2, "z": 15, "name": "Rock_Lime_Brick_Smooth"}, {"x": 0, "y": 3, "z": 15, "name": "Rock_Lime_Brick_Smooth"}, {"x": 0, "y": 4, "z": 15, "name": "Rock_Lime_Brick_Smooth"}, {"x": 0, "y": 5, "z": 15, "name": "Rock_Calcite_Brick"}, {"x": 0, "y": -3, "z": 16, "name": "Soil_Dirt"}, {"x": 0, "y": -2, "z": 16, "name": "Soil_Dirt"}, {"x": 0, "y": -1, "z": 16, "name": "Soil_Dirt"}, {"x": 0, "y": 0, "z": 16, "name": "Soil_Dirt"}, {"x": 0, "y": 1, "z": 16, "name": "Rock_Calcite_Brick_Decorative"}, {"x": 0, "y": 2, "z": 16, "name": "Rock_Lime_Brick_Smooth"}, {"x": 0, "y": 3, "z": 16, "name": "Rock_Lime_Brick_Smooth"}, {"x": 0, "y": 4, "z": 16, "name": "Rock_Lime_Brick_Smooth"}, {"x": 0, "y": 5, "z": 16, "name": "Rock_Calcite_Brick"}, {"x": 0, "y": -3, "z": 17, "name": "Soil_Dirt"}, {"x": 0, "y": -2, "z": 17, "name": "Soil_Dirt"}, {"x": 0, "y": -1, "z": 17, "name": "Soil_Dirt"}, {"x": 0, "y": 0, "z": 17, "name": "Soil_Dirt"}, {"x": 0, "y": -3, "z": 18, "name": "Soil_Dirt"}, {"x": 0, "y": -2, "z": 18, "name": "Soil_Dirt"}, {"x": 0, "y": -1, "z": 18, "name": "Soil_Dirt"}, {"x": 0, "y": 0, "z": 18, "name": "Soil_Dirt"}, {"x": 0, "y": 1, "z": 18, "name": "Rock_Calcite_Brick_Decorative"}, {"x": 0, "y": 2, "z": 18, "name": "Rock_Lime_Brick_Smooth"}, {"x": 0, "y": 3, "z": 18, "name": "Rock_Lime_Brick_Smooth"}, {"x": 0, "y": 4, "z": 18, "name": "Rock_Lime_Brick_Smooth"}, {"x": 0, "y": 5, "z": 18, "name": "Rock_Calcite_Brick"}, {"x": 0, "y": -3, "z": 19, "name": "Soil_Dirt"}, {"x": 0, "y": -2, "z": 19, "name": "Soil_Dirt"}, {"x": 0, "y": -1, "z": 19, "name": "Soil_Dirt"}, {"x": 0, "y": 0, "z": 19, "name": "Soil_Dirt"}, {"x": 0, "y": 1, "z": 19, "name": "Rock_Calcite_Brick_Decorative"}, {"x": 0, "y": 2, "z": 19, "name": "Rock_Lime_Brick_Smooth"}, {"x": 0, "y": 3, "z": 19, "name": "Rock_Lime_Brick_Smooth"}, {"x": 0, "y": 4, "z": 19, "name": "Rock_Lime_Brick_Smooth"}, {"x": 0, "y": 5, "z": 19, "name": "Rock_Calcite_Brick"}, {"x": 0, "y": -3, "z": 20, "name": "Soil_Dirt"}, {"x": 0, "y": -2, "z": 20, "name": "Soil_Dirt"}, {"x": 0, "y": -1, "z": 20, "name": "Soil_Dirt"}, {"x": 0, "y": 0, "z": 20, "name": "Soil_Dirt"}, {"x": 0, "y": 1, "z": 20, "name": "Rock_Calcite_Brick_Decorative"}, {"x": 0, "y": 2, "z": 20, "name": "Rock_Lime_Brick_Smooth"}, {"x": 0, "y": 3, "z": 20, "name": "Rock_Lime_Brick_Smooth"}, {"x": 0, "y": 4, "z": 20, "name": "Rock_Lime_Brick_Smooth"}, {"x": 0, "y": 5, "z": 20, "name": "Rock_Calcite_Brick"}, {"x": 0, "y": -3, "z": 21, "name": "Soil_Dirt"}, {"x": 0, "y": -2, "z": 21, "name": "Soil_Dirt"}, {"x": 0, "y": -1, "z": 21, "name": "Soil_Dirt"}, {"x": 0, "y": 0, "z": 21, "name": "Soil_Dirt"}, {"x": 0, "y": 1, "z": 21, "name": "Rock_Calcite_Brick_Decorative"}, {"x": 0, "y": 2, "z": 21, "name": "Rock_Lime_Brick_Smooth"}, {"x": 0, "y": 3, "z": 21, "name": "Rock_Lime_Brick_Smooth"}, {"x": 0, "y": 4, "z": 21, "name": "Rock_Lime_Brick_Smooth"}, {"x": 0, "y": 5, "z": 21, "name": "Rock_Calcite_Brick"}, {"x": 0, "y": -3, "z": 22, "name": "Soil_Dirt"}, {"x": 0, "y": -2, "z": 22, "name": "Soil_Dirt"}, {"x": 0, "y": -1, "z": 22, "name": "Soil_Dirt"}, {"x": 0, "y": 0, "z": 22, "name": "Soil_Dirt"}, {"x": 0, "y": 1, "z": 22, "name": "Rock_Calcite_Brick_Decorative"}, {"x": 0, "y": 2, "z": 22, "name": "Rock_Lime_Brick_Smooth"}, {"x": 0, "y": 3, "z": 22, "name": "Rock_Lime_Brick_Smooth"}, {"x": 0, "y": 4, "z": 22, "name": "Rock_Lime_Brick_Smooth"}, {"x": 0, "y": 5, "z": 22, "name": "Rock_Calcite_Brick"}, {"x": 0, "y": -3, "z": 23, "name": "Soil_Dirt"}, {"x": 0, "y": -2, "z": 23, "name": "Soil_Dirt"}, {"x": 0, "y": -1, "z": 23, "name": "Soil_Dirt"}, {"x": 0, "y": 0, "z": 23, "name": "Soil_Dirt"}, {"x": 0, "y": 1, "z": 23, "name": "Rock_Calcite_Brick_Decorative"}, {"x": 0, "y": 2, "z": 23, "name": "Rock_Lime_Brick_Smooth"}, {"x": 0, "y": 3, "z": 23, "name": "Rock_Lime_Brick_Smooth"}, {"x": 0, "y": 4, "z": 23, "name": "Rock_Lime_Brick_Smooth"}, {"x": 0, "y": 5, "z": 23, "name": "Rock_Calcite_Brick"}, {"x": 0, "y": -3, "z": 24, "name": "Soil_Dirt"}, {"x": 0, "y": -2, "z": 24, "name": "Soil_Dirt"}, {"x": 0, "y": -1, "z": 24, "name": "Soil_Dirt"}, {"x": 0, "y": 0, "z": 24, "name": "Soil_Dirt"}, {"x": 0, "y": 1, "z": 24, "name": "Rock_Calcite_Brick_Decorative"}, {"x": 0, "y": 2, "z": 24, "name": "Rock_Lime_Brick_Smooth"}, {"x": 0, "y": 3, "z": 24, "name": "Rock_Lime_Brick_Smooth"}, {"x": 0, "y": 4, "z": 24, "name": "Rock_Lime_Brick_Smooth"}, {"x": 0, "y": 5, "z": 24, "name": "Rock_Calcite_Brick"}, {"x": 0, "y": -3, "z": 25, "name": "Soil_Dirt"}, {"x": 0, "y": -2, "z": 25, "name": "Soil_Dirt"}, {"x": 0, "y": -1, "z": 25, "name": "Soil_Dirt"}, {"x": 0, "y": 0, "z": 25, "name": "Soil_Dirt"}, {"x": 0, "y": 1, "z": 25, "name": "Rock_Calcite_Brick_Decorative"}, {"x": 0, "y": 2, "z": 25, "name": "Rock_Lime_Brick_Smooth"}, {"x": 0, "y": 3, "z": 25, "name": "Rock_Lime_Brick_Smooth"}, {"x": 0, "y": 4, "z": 25, "name": "Rock_Lime_Brick_Smooth"}, {"x": 0, "y": 5, "z": 25, "name": "Rock_Calcite_Brick"}, {"x": 0, "y": -3, "z": 26, "name": "Soil_Dirt"}, {"x": 0, "y": -2, "z": 26, "name": "Soil_Dirt"}, {"x": 0, "y": -1, "z": 26, "name": "Soil_Dirt"}, {"x": 0, "y": 0, "z": 26, "name": "Soil_Dirt"}, {"x": 0, "y": 1, "z": 26, "name": "Rock_Calcite_Brick_Decorative"}, {"x": 0, "y": 2, "z": 26, "name": "Rock_Lime_Brick_Smooth"}, {"x": 0, "y": 3, "z": 26, "name": "Rock_Lime_Brick_Smooth"}, {"x": 0, "y": 4, "z": 26, "name": "Rock_Lime_Brick_Smooth"}, {"x": 0, "y": 5, "z": 26, "name": "Rock_Calcite_Brick"}, {"x": 0, "y": -3, "z": 27, "name": "Soil_Dirt"}, {"x": 0, "y": -2, "z": 27, "name": "Soil_Dirt"}, {"x": 0, "y": -1, "z": 27, "name": "Soil_Dirt"}, {"x": 0, "y": 0, "z": 27, "name": "Soil_Dirt"}, {"x": 0, "y": 1, "z": 27, "name": "Rock_Calcite_Brick_Decorative"}, {"x": 0, "y": 2, "z": 27, "name": "Rock_Lime_Brick_Smooth"}, {"x": 0, "y": 3, "z": 27, "name": "Rock_Lime_Brick_Smooth"}, {"x": 0, "y": 4, "z": 27, "name": "Rock_Lime_Brick_Smooth"}, {"x": 0, "y": 5, "z": 27, "name": "Rock_Calcite_Brick"}, {"x": 0, "y": -3, "z": 28, "name": "Soil_Dirt"}, {"x": 0, "y": -2, "z": 28, "name": "Soil_Dirt"}, {"x": 0, "y": -1, "z": 28, "name": "Soil_Dirt"}, {"x": 0, "y": 0, "z": 28, "name": "Soil_Dirt"}, {"x": 0, "y": 1, "z": 28, "name": "Rock_Calcite_Brick_Decorative"}, {"x": 0, "y": 2, "z": 28, "name": "Rock_Lime_Brick_Smooth"}, {"x": 0, "y": 3, "z": 28, "name": "Rock_Lime_Brick_Smooth"}, {"x": 0, "y": 4, "z": 28, "name": "Rock_Lime_Brick_Smooth"}, {"x": 0, "y": 5, "z": 28, "name": "Rock_Calcite_Brick"}, {"x": 0, "y": -3, "z": 29, "name": "Soil_Dirt"}, {"x": 0, "y": -2, "z": 29, "name": "Soil_Dirt"}, {"x": 0, "y": -1, "z": 29, "name": "Soil_Dirt"}, {"x": 0, "y": 0, "z": 29, "name": "Soil_Dirt"}, {"x": 0, "y": 1, "z": 29, "name": "Rock_Calcite_Brick_Decorative"}, {"x": 0, "y": 2, "z": 29, "name": "Rock_Lime_Brick_Smooth"}, {"x": 0, "y": 3, "z": 29, "name": "Rock_Lime_Brick_Smooth"}, {"x": 0, "y": 4, "z": 29, "name": "Rock_Lime_Brick_Smooth"}, {"x": 0, "y": 5, "z": 29, "name": "Rock_Calcite_Brick"}, {"x": 0, "y": -3, "z": 30, "name": "Soil_Dirt"}, {"x": 0, "y": -2, "z": 30, "name": "Soil_Dirt"}, {"x": 0, "y": -1, "z": 30, "name": "Soil_Dirt"}, {"x": 0, "y": 0, "z": 30, "name": "Soil_Dirt"}, {"x": 0, "y": 1, "z": 30, "name": "Rock_Calcite_Brick_Decorative"}, {"x": 0, "y": 2, "z": 30, "name": "Rock_Lime_Brick_Smooth"}, {"x": 0, "y": 3, "z": 30, "name": "Rock_Lime_Brick_Smooth"}, {"x": 0, "y": 4, "z": 30, "name": "Rock_Lime_Brick_Smooth"}, {"x": 0, "y": 5, "z": 30, "name": "Rock_Calcite_Brick"}, {"x": 0, "y": -3, "z": 31, "name": "Soil_Dirt"}, {"x": 0, "y": -2, "z": 31, "name": "Soil_Dirt"}, {"x": 0, "y": -1, "z": 31, "name": "Soil_Dirt"}, {"x": 0, "y": 0, "z": 31, "name": "Soil_Dirt"}, {"x": 0, "y": 1, "z": 31, "name": "Rock_Calcite_Brick_Decorative"}, {"x": 1, "y": -3, "z": 0, "name": "Soil_Dirt"}, {"x": 1, "y": -2, "z": 0, "name": "Soil_Dirt"}, {"x": 1, "y": -1, "z": 0, "name": "Soil_Dirt"}, {"x": 1, "y": 0, "z": 0, "name": "Soil_Grass"}, {"x": 1, "y": -3, "z": 1, "name": "Soil_Dirt"}, {"x": 1, "y": -2, "z": 1, "name": "Soil_Dirt"}, {"x": 1, "y": -1, "z": 1, "name": "Soil_Dirt"}, {"x": 1, "y": 0, "z": 1, "name": "Soil_Grass"}, {"x": 1, "y": -3, "z": 2, "name": "Soil_Dirt"}, {"x": 1, "y": -2, "z": 2, "name": "Soil_Dirt"}, {"x": 1, "y": -1, "z": 2, "name": "Soil_Dirt"}, {"x": 1, "y": 0, "z": 2, "name": "Soil_Grass"}, {"x": 1, "y": -3, "z": 3, "name": "Soil_Dirt"}, {"x": 1, "y": -2, "z": 3, "name": "Soil_Dirt"}, {"x": 1, "y": -1, "z": 3, "name": "Soil_Dirt"}, {"x": 1, "y": 0, "z": 3, "name": "Soil_Grass"}, {"x": 1, "y": -3, "z": 4, "name": "Soil_Dirt"}, {"x": 1, "y": -2, "z": 4, "name": "Soil_Dirt"}, {"x": 1, "y": -1, "z": 4, "name": "Soil_Dirt"}, {"x": 1, "y": 0, "z": 4, "name": "Soil_Grass"}, {"x": 1, "y": -3, "z": 5, "name": "Soil_Dirt"}, {"x": 1, "y": -2, "z": 5, "name": "Soil_Dirt"}, {"x": 1, "y": -1, "z": 5, "name": "Soil_Dirt"}, {"x": 1, "y": 0, "z": 5, "name": "Soil_Grass"}, {"x": 1, "y": -3, "z": 6, "name": "Soil_Dirt"}, {"x": 1, "y": -2, "z": 6, "name": "Soil_Dirt"}, {"x": 1, "y": -1, "z": 6, "name": "Soil_Dirt"}, {"x": 1, "y": 0, "z": 6, "name": "Soil_Grass"}, {"x": 1, "y": -3, "z": 7, "name": "Soil_Dirt"}, {"x": 1, "y": -2, "z": 7, "name": "Soil_Dirt"}, {"x": 1, "y": -1, "z": 7, "name": "Soil_Dirt"}, {"x": 1, "y": 0, "z": 7, "name": "Soil_Grass"}, {"x": 1, "y": -3, "z": 8, "name": "Soil_Dirt"}, {"x": 1, "y": -2, "z": 8, "name": "Soil_Dirt"}, {"x": 1, "y": -1, "z": 8, "name": "Soil_Dirt"}, {"x": 1, "y": 0, "z": 8, "name": "Soil_Grass"}, {"x": 1, "y": -3, "z": 9, "name": "Soil_Dirt"}, {"x": 1, "y": -2, "z": 9, "name": "Soil_Dirt"}, {"x": 1, "y": -1, "z": 9, "name": "Soil_Dirt"}, {"x": 1, "y": 0, "z": 9, "name": "Soil_Dirt"}, {"x": 1, "y": 1, "z": 9, "name": "Rock_Calcite_Brick_Decorative"}, {"x": 1, "y": 2, "z": 9, "name": "Rock_Lime_Brick_Smooth"}, {"x": 1, "y": 3, "z": 9, "name": "Rock_Lime_Brick_Smooth"}, {"x": 1, "y": 4, "z": 9, "name": "Rock_Lime_Brick_Smooth"}, {"x": 1, "y": 5, "z": 9, "name": "Rock_Calcite_Brick"}, {"x": 1, "y": -3, "z": 10, "name": "Soil_Dirt"}, {"x": 1, "y": -2, "z": 10, "name": "Soil_Dirt"}, {"x": 1, "y": -1, "z": 10, "name": "Soil_Dirt"}, {"x": 1, "y": 0, "z": 10, "name": "Rock_Calcite_Brick_Smooth"}, {"x": 1, "y": 6, "z": 10, "name": "Rock_Calcite_Brick_Smooth_Half"}, {"x": 1, "y": -3, "z": 11, "name": "Soil_Dirt"}, {"x": 1, "y": -2, "z": 11, "name": "Soil_Dirt"}, {"x": 1, "y": -1, "z": 11, "name": "Soil_Dirt"}, {"x": 1, "y": 0, "z": 11, "name": "K2_Slot_Shelf_Recipe_Bread"}, {"x": 1, "y": 6, "z": 11, "name": "Rock_Calcite_Brick_Smooth_Half"}, {"x": 1, "y": -3, "z": 12, "name": "Soil_Dirt"}, {"x": 1, "y": -2, "z": 12, "name": "Soil_Dirt"}, {"x": 1, "y": -1, "z": 12, "name": "Soil_Dirt"}, {"x": 1, "y": 0, "z": 12, "name": "K2_Slot_Shelf_Recipe_Mushroom_Salad"}, {"x": 1, "y": 6, "z": 12, "name": "Rock_Calcite_Brick_Smooth_Half"}, {"x": 1, "y": -3, "z": 13, "name": "Soil_Dirt"}, {"x": 1, "y": -2, "z": 13, "name": "Soil_Dirt"}, {"x": 1, "y": -1, "z": 13, "name": "Soil_Dirt"}, {"x": 1, "y": 0, "z": 13, "name": "K2_Slot_Shelf_Recipe_Fruit_Kebab"}, {"x": 1, "y": 6, "z": 13, "name": "Rock_Calcite_Brick_Smooth_Half"}, {"x": 1, "y": -3, "z": 14, "name": "Soil_Dirt"}, {"x": 1, "y": -2, "z": 14, "name": "Soil_Dirt"}, {"x": 1, "y": -1, "z": 14, "name": "Soil_Dirt"}, {"x": 1, "y": 0, "z": 14, "name": "K2_Slot_Shelf_Recipe_Berry_Salad"}, {"x": 1, "y": 6, "z": 14, "name": "Rock_Calcite_Brick_Smooth_Half"}, {"x": 1, "y": -3, "z": 15, "name": "Soil_Dirt"}, {"x": 1, "y": -2, "z": 15, "name": "Soil_Dirt"}, {"x": 1, "y": -1, "z": 15, "name": "Soil_Dirt"}, {"x": 1, "y": 0, "z": 15, "name": "K2_Slot_Shelf_Recipe_Roasted_Corn"}, {"x": 1, "y": 6, "z": 15, "name": "Rock_Calcite_Brick_Smooth_Half"}, {"x": 1, "y": -3, "z": 16, "name": "Soil_Dirt"}, {"x": 1, "y": -2, "z": 16, "name": "Soil_Dirt"}, {"x": 1, "y": -1, "z": 16, "name": "Soil_Dirt"}, {"x": 1, "y": 0, "z": 16, "name": "Rock_Calcite_Brick_Smooth"}, {"x": 1, "y": 6, "z": 16, "name": "Rock_Calcite_Brick_Smooth_Half"}, {"x": 1, "y": -3, "z": 17, "name": "Soil_Dirt"}, {"x": 1, "y": -2, "z": 17, "name": "Soil_Dirt"}, {"x": 1, "y": -1, "z": 17, "name": "Soil_Dirt"}, {"x": 1, "y": 0, "z": 17, "name": "Rock_Calcite_Brick_Smooth"}, {"x": 1, "y": 1, "z": 17, "name": "Rock_Calcite_Brick_Decorative"}, {"x": 1, "y": 2, "z": 17, "name": "Rock_Lime_Brick_Smooth"}, {"x": 1, "y": 3, "z": 17, "name": "Rock_Lime_Brick_Smooth"}, {"x": 1, "y": 4, "z": 17, "name": "Rock_Lime_Brick_Smooth"}, {"x": 1, "y": 5, "z": 17, "name": "Rock_Calcite_Brick"}, {"x": 1, "y": 6, "z": 17, "name": "Rock_Calcite_Brick"}, {"x": 1, "y": -3, "z": 18, "name": "Soil_Dirt"}, {"x": 1, "y": -2, "z": 18, "name": "Soil_Dirt"}, {"x": 1, "y": -1, "z": 18, "name": "Soil_Dirt"}, {"x": 1, "y": 0, "z": 18, "name": "Rock_Calcite_Brick_Smooth"}, {"x": 1, "y": 6, "z": 18, "name": "Rock_Calcite_Brick_Smooth_Half"}, {"x": 1, "y": -3, "z": 19, "name": "Soil_Dirt"}, {"x": 1, "y": -2, "z": 19, "name": "Soil_Dirt"}, {"x": 1, "y": -1, "z": 19, "name": "Soil_Dirt"}, {"x": 1, "y": 0, "z": 19, "name": "K2_Slot_Shelf_Dishwasher"}, {"x": 1, "y": 6, "z": 19, "name": "Rock_Calcite_Brick_Smooth_Half"}, {"x": 1, "y": -3, "z": 20, "name": "Soil_Dirt"}, {"x": 1, "y": -2, "z": 20, "name": "Soil_Dirt"}, {"x": 1, "y": -1, "z": 20, "name": "Soil_Dirt"}, {"x": 1, "y": 0, "z": 20, "name": "K2_Slot_Shelf_Dishwasher_Cheap"}, {"x": 1, "y": 6, "z": 20, "name": "Rock_Calcite_Brick_Smooth_Half"}, {"x": 1, "y": -3, "z": 21, "name": "Soil_Dirt"}, {"x": 1, "y": -2, "z": 21, "name": "Soil_Dirt"}, {"x": 1, "y": -1, "z": 21, "name": "Soil_Dirt"}, {"x": 1, "y": 0, "z": 21, "name": "K2_Slot_Shelf_Sink"}, {"x": 1, "y": 6, "z": 21, "name": "Rock_Calcite_Brick_Smooth_Half"}, {"x": 1, "y": -3, "z": 22, "name": "Soil_Dirt"}, {"x": 1, "y": -2, "z": 22, "name": "Soil_Dirt"}, {"x": 1, "y": -1, "z": 22, "name": "Soil_Dirt"}, {"x": 1, "y": 0, "z": 22, "name": "Rock_Calcite_Brick_Ornate"}, {"x": 1, "y": 6, "z": 22, "name": "Rock_Calcite_Brick_Smooth_Half"}, {"x": 1, "y": -3, "z": 23, "name": "Soil_Dirt"}, {"x": 1, "y": -2, "z": 23, "name": "Soil_Dirt"}, {"x": 1, "y": -1, "z": 23, "name": "Soil_Dirt"}, {"x": 1, "y": 0, "z": 23, "name": "K2_Slot_Shelf_Stove_Safe"}, {"x": 1, "y": 6, "z": 23, "name": "Rock_Calcite_Brick_Smooth_Half"}, {"x": 1, "y": -3, "z": 24, "name": "Soil_Dirt"}, {"x": 1, "y": -2, "z": 24, "name": "Soil_Dirt"}, {"x": 1, "y": -1, "z": 24, "name": "Soil_Dirt"}, {"x": 1, "y": 0, "z": 24, "name": "K2_Slot_Shelf_Stove_Fast"}, {"x": 1, "y": 6, "z": 24, "name": "Rock_Calcite_Brick_Smooth_Half"}, {"x": 1, "y": -3, "z": 25, "name": "Soil_Dirt"}, {"x": 1, "y": -2, "z": 25, "name": "Soil_Dirt"}, {"x": 1, "y": -1, "z": 25, "name": "Soil_Dirt"}, {"x": 1, "y": 0, "z": 25, "name": "K2_Slot_Shelf_Stove"}, {"x": 1, "y": 6, "z": 25, "name": "Rock_Calcite_Brick_Smooth_Half"}, {"x": 1, "y": -3, "z": 26, "name": "Soil_Dirt"}, {"x": 1, "y": -2, "z": 26, "name": "Soil_Dirt"}, {"x": 1, "y": -1, "z": 26, "name": "Soil_Dirt"}, {"x": 1, "y": 0, "z": 26, "name": "Rock_Calcite_Brick_Ornate"}, {"x": 1, "y": 6, "z": 26, "name": "Rock_Calcite_Brick_Smooth_Half"}, {"x": 1, "y": -3, "z": 27, "name": "Soil_Dirt"}, {"x": 1, "y": -2, "z": 27, "name": "Soil_Dirt"}, {"x": 1, "y": -1, "z": 27, "name": "Soil_Dirt"}, {"x": 1, "y": 0, "z": 27, "name": "K2_Slot_Shelf_Mat_Rubber"}, {"x": 1, "y": 6, "z": 27, "name": "Rock_Calcite_Brick_Smooth_Half"}, {"x": 1, "y": -3, "z": 28, "name": "Soil_Dirt"}, {"x": 1, "y": -2, "z": 28, "name": "Soil_Dirt"}, {"x": 1, "y": -1, "z": 28, "name": "Soil_Dirt"}, {"x": 1, "y": 0, "z": 28, "name": "K2_Slot_Shelf_Mat"}, {"x": 1, "y": 6, "z": 28, "name": "Rock_Calcite_Brick_Smooth_Half"}, {"x": 1, "y": -3, "z": 29, "name": "Soil_Dirt"}, {"x": 1, "y": -2, "z": 29, "name": "Soil_Dirt"}, {"x": 1, "y": -1, "z": 29, "name": "Soil_Dirt"}, {"x": 1, "y": 0, "z": 29, "name": "K2_Slot_Shelf_Bin"}, {"x": 1, "y": 6, "z": 29, "name": "Rock_Calcite_Brick_Smooth_Half"}, {"x": 1, "y": -3, "z": 30, "name": "Soil_Dirt"}, {"x": 1, "y": -2, "z": 30, "name": "Soil_Dirt"}, {"x": 1, "y": -1, "z": 30, "name": "Soil_Dirt"}, {"x": 1, "y": 0, "z": 30, "name": "Rock_Calcite_Brick_Smooth"}, {"x": 1, "y": 6, "z": 30, "name": "Rock_Calcite_Brick_Smooth_Half"}, {"x": 1, "y": -3, "z": 31, "name": "Soil_Dirt"}, {"x": 1, "y": -2, "z": 31, "name": "Soil_Dirt"}, {"x": 1, "y": -1, "z": 31, "name": "Soil_Dirt"}, {"x": 1, "y": 0, "z": 31, "name": "Soil_Dirt"}, {"x": 1, "y": 1, "z": 31, "name": "Rock_Calcite_Brick_Decorative"}, {"x": 1, "y": 2, "z": 31, "name": "Rock_Lime_Brick_Smooth"}, {"x": 1, "y": 3, "z": 31, "name": "Rock_Lime_Brick_Smooth"}, {"x": 1, "y": 4, "z": 31, "name": "Rock_Lime_Brick_Smooth"}, {"x": 1, "y": 5, "z": 31, "name": "Rock_Calcite_Brick"}, {"x": 1, "y": 6, "z": 31, "name": "Rock_Calcite_Brick"}, {"x": 2, "y": -3, "z": 0, "name": "Soil_Dirt"}, {"x": 2, "y": -2, "z": 0, "name": "Soil_Dirt"}, {"x": 2, "y": -1, "z": 0, "name": "Soil_Dirt"}, {"x": 2, "y": 0, "z": 0, "name": "Soil_Grass"}, {"x": 2, "y": -3, "z": 1, "name": "Soil_Dirt"}, {"x": 2, "y": -2, "z": 1, "name": "Soil_Dirt"}, {"x": 2, "y": -1, "z": 1, "name": "Soil_Dirt"}, {"x": 2, "y": 0, "z": 1, "name": "Soil_Grass"}, {"x": 2, "y": -3, "z": 2, "name": "Soil_Dirt"}, {"x": 2, "y": -2, "z": 2, "name": "Soil_Dirt"}, {"x": 2, "y": -1, "z": 2, "name": "Soil_Dirt"}, {"x": 2, "y": 0, "z": 2, "name": "Soil_Grass"}, {"x": 2, "y": -3, "z": 3, "name": "Soil_Dirt"}, {"x": 2, "y": -2, "z": 3, "name": "Soil_Dirt"}, {"x": 2, "y": -1, "z": 3, "name": "Soil_Dirt"}, {"x": 2, "y": 0, "z": 3, "name": "Soil_Grass"}, {"x": 2, "y": -3, "z": 4, "name": "Soil_Dirt"}, {"x": 2, "y": -2, "z": 4, "name": "Soil_Dirt"}, {"x": 2, "y": -1, "z": 4, "name": "Soil_Dirt"}, {"x": 2, "y": 0, "z": 4, "name": "Soil_Grass"}, {"x": 2, "y": -3, "z": 5, "name": "Soil_Dirt"}, {"x": 2, "y": -2, "z": 5, "name": "Soil_Dirt"}, {"x": 2, "y": -1, "z": 5, "name": "Soil_Dirt"}, {"x": 2, "y": 0, "z": 5, "name": "Soil_Grass"}, {"x": 2, "y": -3, "z": 6, "name": "Soil_Dirt"}, {"x": 2, "y": -2, "z": 6, "name": "Soil_Dirt"}, {"x": 2, "y": -1, "z": 6, "name": "Soil_Dirt"}, {"x": 2, "y": 0, "z": 6, "name": "Soil_Grass"}, {"x": 2, "y": -3, "z": 7, "name": "Soil_Dirt"}, {"x": 2, "y": -2, "z": 7, "name": "Soil_Dirt"}, {"x": 2, "y": -1, "z": 7, "name": "Soil_Dirt"}, {"x": 2, "y": 0, "z": 7, "name": "Soil_Grass"}, {"x": 2, "y": -3, "z": 8, "name": "Soil_Dirt"}, {"x": 2, "y": -2, "z": 8, "name": "Soil_Dirt"}, {"x": 2, "y": -1, "z": 8, "name": "Soil_Dirt"}, {"x": 2, "y": 0, "z": 8, "name": "Soil_Grass"}, {"x": 2, "y": -3, "z": 9, "name": "Soil_Dirt"}, {"x": 2, "y": -2, "z": 9, "name": "Soil_Dirt"}, {"x": 2, "y": -1, "z": 9, "name": "Soil_Dirt"}, {"x": 2, "y": 0, "z": 9, "name": "Soil_Dirt"}, {"x": 2, "y": 1, "z": 9, "name": "Rock_Calcite_Brick_Decorative"}, {"x": 2, "y": 2, "z": 9, "name": "Rock_Lime_Brick_Smooth"}, {"x": 2, "y": 3, "z": 9, "name": "Rock_Lime_Brick_Smooth"}, {"x": 2, "y": 4, "z": 9, "name": "Rock_Lime_Brick_Smooth"}, {"x": 2, "y": 5, "z": 9, "name": "Rock_Calcite_Brick"}, {"x": 2, "y": 6, "z": 9, "name": "Rock_Calcite_Brick"}, {"x": 2, "y": -3, "z": 10, "name": "Soil_Dirt"}, {"x": 2, "y": -2, "z": 10, "name": "Soil_Dirt"}, {"x": 2, "y": -1, "z": 10, "name": "Soil_Dirt"}, {"x": 2, "y": 0, "z": 10, "name": "Wood_Softwood_Planks"}, {"x": 2, "y": 6, "z": 10, "name": "Rock_Calcite_Brick_Smooth_Half", "rotation": 8}, {"x": 2, "y": -3, "z": 11, "name": "Soil_Dirt"}, {"x": 2, "y": -2, "z": 11, "name": "Soil_Dirt"}, {"x": 2, "y": -1, "z": 11, "name": "Soil_Dirt"}, {"x": 2, "y": 0, "z": 11, "name": "Wood_Softwood_Planks"}, {"x": 2, "y": 6, "z": 11, "name": "Rock_Calcite_Brick_Smooth_Half", "rotation": 8}, {"x": 2, "y": -3, "z": 12, "name": "Soil_Dirt"}, {"x": 2, "y": -2, "z": 12, "name": "Soil_Dirt"}, {"x": 2, "y": -1, "z": 12, "name": "Soil_Dirt"}, {"x": 2, "y": 0, "z": 12, "name": "Wood_Softwood_Planks"}, {"x": 2, "y": 6, "z": 12, "name": "Rock_Calcite_Brick_Smooth_Half", "rotation": 8}, {"x": 2, "y": -3, "z": 13, "name": "Soil_Dirt"}, {"x": 2, "y": -2, "z": 13, "name": "Soil_Dirt"}, {"x": 2, "y": -1, "z": 13, "name": "Soil_Dirt"}, {"x": 2, "y": 0, "z": 13, "name": "Wood_Softwood_Planks"}, {"x": 2, "y": 6, "z": 13, "name": "Rock_Calcite_Brick_Smooth_Half", "rotation": 8}, {"x": 2, "y": -3, "z": 14, "name": "Soil_Dirt"}, {"x": 2, "y": -2, "z": 14, "name": "Soil_Dirt"}, {"x": 2, "y": -1, "z": 14, "name": "Soil_Dirt"}, {"x": 2, "y": 0, "z": 14, "name": "Wood_Softwood_Planks"}, {"x": 2, "y": 6, "z": 14, "name": "Rock_Calcite_Brick_Smooth_Half", "rotation": 8}, {"x": 2, "y": -3, "z": 15, "name": "Soil_Dirt"}, {"x": 2, "y": -2, "z": 15, "name": "Soil_Dirt"}, {"x": 2, "y": -1, "z": 15, "name": "Soil_Dirt"}, {"x": 2, "y": 0, "z": 15, "name": "Wood_Softwood_Planks"}, {"x": 2, "y": 6, "z": 15, "name": "Rock_Calcite_Brick_Smooth_Half", "rotation": 8}, {"x": 2, "y": -3, "z": 16, "name": "Soil_Dirt"}, {"x": 2, "y": -2, "z": 16, "name": "Soil_Dirt"}, {"x": 2, "y": -1, "z": 16, "name": "Soil_Dirt"}, {"x": 2, "y": 0, "z": 16, "name": "Wood_Softwood_Planks"}, {"x": 2, "y": 6, "z": 16, "name": "Rock_Calcite_Brick_Smooth_Half", "rotation": 8}, {"x": 2, "y": -3, "z": 17, "name": "Soil_Dirt"}, {"x": 2, "y": -2, "z": 17, "name": "Soil_Dirt"}, {"x": 2, "y": -1, "z": 17, "name": "Soil_Dirt"}, {"x": 2, "y": 0, "z": 17, "name": "Rock_Calcite_Brick_Smooth"}, {"x": 2, "y": 1, "z": 17, "name": "Rock_Calcite_Brick_Decorative"}, {"x": 2, "y": 2, "z": 17, "name": "Rock_Lime_Brick_Smooth"}, {"x": 2, "y": 3, "z": 17, "name": "Rock_Lime_Brick_Smooth"}, {"x": 2, "y": 4, "z": 17, "name": "Rock_Lime_Brick_Smooth"}, {"x": 2, "y": 5, "z": 17, "name": "Rock_Calcite_Brick"}, {"x": 2, "y": 6, "z": 17, "name": "Rock_Calcite_Brick"}, {"x": 2, "y": -3, "z": 18, "name": "Soil_Dirt"}, {"x": 2, "y": -2, "z": 18, "name": "Soil_Dirt"}, {"x": 2, "y": -1, "z": 18, "name": "Soil_Dirt"}, {"x": 2, "y": 0, "z": 18, "name": "Wood_Softwood_Planks"}, {"x": 2, "y": 6, "z": 18, "name": "Rock_Calcite_Brick_Smooth_Half", "rotation": 8}, {"x": 2, "y": -3, "z": 19, "name": "Soil_Dirt"}, {"x": 2, "y": -2, "z": 19, "name": "Soil_Dirt"}, {"x": 2, "y": -1, "z": 19, "name": "Soil_Dirt"}, {"x": 2, "y": 0, "z": 19, "name": "Wood_Softwood_Planks"}, {"x": 2, "y": 6, "z": 19, "name": "Rock_Calcite_Brick_Smooth_Half", "rotation": 8}, {"x": 2, "y": -3, "z": 20, "name": "Soil_Dirt"}, {"x": 2, "y": -2, "z": 20, "name": "Soil_Dirt"}, {"x": 2, "y": -1, "z": 20, "name": "Soil_Dirt"}, {"x": 2, "y": 0, "z": 20, "name": "Wood_Softwood_Planks"}, {"x": 2, "y": 6, "z": 20, "name": "Rock_Calcite_Brick_Smooth_Half", "rotation": 8}, {"x": 2, "y": -3, "z": 21, "name": "Soil_Dirt"}, {"x": 2, "y": -2, "z": 21, "name": "Soil_Dirt"}, {"x": 2, "y": -1, "z": 21, "name": "Soil_Dirt"}, {"x": 2, "y": 0, "z": 21, "name": "Wood_Softwood_Planks"}, {"x": 2, "y": 6, "z": 21, "name": "Rock_Calcite_Brick_Smooth_Half", "rotation": 8}, {"x": 2, "y": -3, "z": 22, "name": "Soil_Dirt"}, {"x": 2, "y": -2, "z": 22, "name": "Soil_Dirt"}, {"x": 2, "y": -1, "z": 22, "name": "Soil_Dirt"}, {"x": 2, "y": 0, "z": 22, "name": "Wood_Softwood_Planks"}, {"x": 2, "y": 6, "z": 22, "name": "Rock_Calcite_Brick_Smooth_Half", "rotation": 8}, {"x": 2, "y": -3, "z": 23, "name": "Soil_Dirt"}, {"x": 2, "y": -2, "z": 23, "name": "Soil_Dirt"}, {"x": 2, "y": -1, "z": 23, "name": "Soil_Dirt"}, {"x": 2, "y": 0, "z": 23, "name": "Wood_Softwood_Planks"}, {"x": 2, "y": 6, "z": 23, "name": "Rock_Calcite_Brick_Smooth_Half", "rotation": 8}, {"x": 2, "y": -3, "z": 24, "name": "Soil_Dirt"}, {"x": 2, "y": -2, "z": 24, "name": "Soil_Dirt"}, {"x": 2, "y": -1, "z": 24, "name": "Soil_Dirt"}, {"x": 2, "y": 0, "z": 24, "name": "Wood_Softwood_Planks"}, {"x": 2, "y": 6, "z": 24, "name": "Rock_Calcite_Brick_Smooth_Half", "rotation": 8}, {"x": 2, "y": -3, "z": 25, "name": "Soil_Dirt"}, {"x": 2, "y": -2, "z": 25, "name": "Soil_Dirt"}, {"x": 2, "y": -1, "z": 25, "name": "Soil_Dirt"}, {"x": 2, "y": 0, "z": 25, "name": "Wood_Softwood_Planks"}, {"x": 2, "y": 6, "z": 25, "name": "Rock_Calcite_Brick_Smooth_Half", "rotation": 8}, {"x": 2, "y": -3, "z": 26, "name": "Soil_Dirt"}, {"x": 2, "y": -2, "z": 26, "name": "Soil_Dirt"}, {"x": 2, "y": -1, "z": 26, "name": "Soil_Dirt"}, {"x": 2, "y": 0, "z": 26, "name": "Wood_Softwood_Planks"}, {"x": 2, "y": 6, "z": 26, "name": "Rock_Calcite_Brick_Smooth_Half", "rotation": 8}, {"x": 2, "y": -3, "z": 27, "name": "Soil_Dirt"}, {"x": 2, "y": -2, "z": 27, "name": "Soil_Dirt"}, {"x": 2, "y": -1, "z": 27, "name": "Soil_Dirt"}, {"x": 2, "y": 0, "z": 27, "name": "Wood_Softwood_Planks"}, {"x": 2, "y": 6, "z": 27, "name": "Rock_Calcite_Brick_Smooth_Half", "rotation": 8}, {"x": 2, "y": -3, "z": 28, "name": "Soil_Dirt"}, {"x": 2, "y": -2, "z": 28, "name": "Soil_Dirt"}, {"x": 2, "y": -1, "z": 28, "name": "Soil_Dirt"}, {"x": 2, "y": 0, "z": 28, "name": "Wood_Softwood_Planks"}, {"x": 2, "y": 6, "z": 28, "name": "Rock_Calcite_Brick_Smooth_Half", "rotation": 8}, {"x": 2, "y": -3, "z": 29, "name": "Soil_Dirt"}, {"x": 2, "y": -2, "z": 29, "name": "Soil_Dirt"}, {"x": 2, "y": -1, "z": 29, "name": "Soil_Dirt"}, {"x": 2, "y": 0, "z": 29, "name": "Wood_Softwood_Planks"}, {"x": 2, "y": 6, "z": 29, "name": "Rock_Calcite_Brick_Smooth_Half", "rotation": 8}, {"x": 2, "y": -3, "z": 30, "name": "Soil_Dirt"}, {"x": 2, "y": -2, "z": 30, "name": "Soil_Dirt"}, {"x": 2, "y": -1, "z": 30, "name": "Soil_Dirt"}, {"x": 2, "y": 0, "z": 30, "name": "K2_Slot_Shelf_Board"}, {"x": 2, "y": 6, "z": 30, "name": "Rock_Calcite_Brick_Smooth_Half", "rotation": 8}, {"x": 2, "y": -3, "z": 31, "name": "Soil_Dirt"}, {"x": 2, "y": -2, "z": 31, "name": "Soil_Dirt"}, {"x": 2, "y": -1, "z": 31, "name": "Soil_Dirt"}, {"x": 2, "y": 0, "z": 31, "name": "Soil_Dirt"}, {"x": 2, "y": 1, "z": 31, "name": "Rock_Calcite_Brick_Decorative"}, {"x": 2, "y": 2, "z": 31, "name": "Rock_Lime_Brick_Smooth"}, {"x": 2, "y": 3, "z": 31, "name": "Rock_Lime_Brick_Smooth"}, {"x": 2, "y": 4, "z": 31, "name": "Rock_Lime_Brick_Smooth"}, {"x": 2, "y": 5, "z": 31, "name": "Rock_Calcite_Brick"}, {"x": 2, "y": 6, "z": 31, "name": "Rock_Calcite_Brick"}, {"x": 3, "y": -3, "z": 0, "name": "Soil_Dirt"}, {"x": 3, "y": -2, "z": 0, "name": "Soil_Dirt"}, {"x": 3, "y": -1, "z": 0, "name": "Soil_Dirt"}, {"x": 3, "y": 0, "z": 0, "name": "Soil_Grass"}, {"x": 3, "y": -3, "z": 1, "name": "Soil_Dirt"}, {"x": 3, "y": -2, "z": 1, "name": "Soil_Dirt"}, {"x": 3, "y": -1, "z": 1, "name": "Soil_Dirt"}, {"x": 3, "y": 0, "z": 1, "name": "Soil_Grass"}, {"x": 3, "y": -3, "z": 2, "name": "Soil_Dirt"}, {"x": 3, "y": -2, "z": 2, "name": "Soil_Dirt"}, {"x": 3, "y": -1, "z": 2, "name": "Soil_Dirt"}, {"x": 3, "y": 0, "z": 2, "name": "Soil_Grass"}, {"x": 3, "y": -3, "z": 3, "name": "Soil_Dirt"}, {"x": 3, "y": -2, "z": 3, "name": "Soil_Dirt"}, {"x": 3, "y": -1, "z": 3, "name": "Soil_Dirt"}, {"x": 3, "y": 0, "z": 3, "name": "Soil_Grass"}, {"x": 3, "y": -3, "z": 4, "name": "Soil_Dirt"}, {"x": 3, "y": -2, "z": 4, "name": "Soil_Dirt"}, {"x": 3, "y": -1, "z": 4, "name": "Soil_Dirt"}, {"x": 3, "y": 0, "z": 4, "name": "Soil_Grass"}, {"x": 3, "y": -3, "z": 5, "name": "Soil_Dirt"}, {"x": 3, "y": -2, "z": 5, "name": "Soil_Dirt"}, {"x": 3, "y": -1, "z": 5, "name": "Soil_Dirt"}, {"x": 3, "y": 0, "z": 5, "name": "Soil_Grass"}, {"x": 3, "y": -3, "z": 6, "name": "Soil_Dirt"}, {"x": 3, "y": -2, "z": 6, "name": "Soil_Dirt"}, {"x": 3, "y": -1, "z": 6, "name": "Soil_Dirt"}, {"x": 3, "y": 0, "z": 6, "name": "Soil_Grass"}, {"x": 3, "y": -3, "z": 7, "name": "Soil_Dirt"}, {"x": 3, "y": -2, "z": 7, "name": "Soil_Dirt"}, {"x": 3, "y": -1, "z": 7, "name": "Soil_Dirt"}, {"x": 3, "y": 0, "z": 7, "name": "Soil_Grass"}, {"x": 3, "y": -3, "z": 8, "name": "Soil_Dirt"}, {"x": 3, "y": -2, "z": 8, "name": "Soil_Dirt"}, {"x": 3, "y": -1, "z": 8, "name": "Soil_Dirt"}, {"x": 3, "y": 0, "z": 8, "name": "Soil_Grass"}, {"x": 3, "y": -3, "z": 9, "name": "Soil_Dirt"}, {"x": 3, "y": -2, "z": 9, "name": "Soil_Dirt"}, {"x": 3, "y": -1, "z": 9, "name": "Soil_Dirt"}, {"x": 3, "y": 0, "z": 9, "name": "Soil_Dirt"}, {"x": 3, "y": 1, "z": 9, "name": "Rock_Calcite_Brick_Decorative"}, {"x": 3, "y": 2, "z": 9, "name": "Rock_Lime_Brick_Smooth"}, {"x": 3, "y": 3, "z": 9, "name": "Rock_Lime_Brick_Smooth"}, {"x": 3, "y": 4, "z": 9, "name": "Rock_Lime_Brick_Smooth"}, {"x": 3, "y": 5, "z": 9, "name": "Rock_Calcite_Brick"}, {"x": 3, "y": 6, "z": 9, "name": "Rock_Calcite_Brick"}, {"x": 3, "y": -3, "z": 10, "name": "Soil_Dirt"}, {"x": 3, "y": -2, "z": 10, "name": "Soil_Dirt"}, {"x": 3, "y": -1, "z": 10, "name": "Soil_Dirt"}, {"x": 3, "y": 0, "z": 10, "name": "Wood_Softwood_Planks"}, {"x": 3, "y": 6, "z": 10, "name": "Rock_Calcite_Brick_Smooth_Half", "rotation": 8}, {"x": 3, "y": -3, "z": 11, "name": "Soil_Dirt"}, {"x": 3, "y": -2, "z": 11, "name": "Soil_Dirt"}, {"x": 3, "y": -1, "z": 11, "name": "Soil_Dirt"}, {"x": 3, "y": 0, "z": 11, "name": "Wood_Softwood_Planks"}, {"x": 3, "y": 5, "z": 11, "name": "Build_Lightsource_White"}, {"x": 3, "y": 6, "z": 11, "name": "Rock_Calcite_Brick_Smooth_Half", "rotation": 8}, {"x": 3, "y": -3, "z": 12, "name": "Soil_Dirt"}, {"x": 3, "y": -2, "z": 12, "name": "Soil_Dirt"}, {"x": 3, "y": -1, "z": 12, "name": "Soil_Dirt"}, {"x": 3, "y": 0, "z": 12, "name": "Wood_Softwood_Planks"}, {"x": 3, "y": 6, "z": 12, "name": "Rock_Calcite_Brick_Smooth_Half", "rotation": 8}, {"x": 3, "y": -3, "z": 13, "name": "Soil_Dirt"}, {"x": 3, "y": -2, "z": 13, "name": "Soil_Dirt"}, {"x": 3, "y": -1, "z": 13, "name": "Soil_Dirt"}, {"x": 3, "y": 0, "z": 13, "name": "Wood_Softwood_Planks"}, {"x": 3, "y": 6, "z": 13, "name": "Rock_Calcite_Brick_Smooth_Half", "rotation": 8}, {"x": 3, "y": -3, "z": 14, "name": "Soil_Dirt"}, {"x": 3, "y": -2, "z": 14, "name": "Soil_Dirt"}, {"x": 3, "y": -1, "z": 14, "name": "Soil_Dirt"}, {"x": 3, "y": 0, "z": 14, "name": "Wood_Softwood_Planks"}, {"x": 3, "y": 6, "z": 14, "name": "Rock_Calcite_Brick_Smooth_Half", "rotation": 8}, {"x": 3, "y": -3, "z": 15, "name": "Soil_Dirt"}, {"x": 3, "y": -2, "z": 15, "name": "Soil_Dirt"}, {"x": 3, "y": -1, "z": 15, "name": "Soil_Dirt"}, {"x": 3, "y": 0, "z": 15, "name": "Wood_Softwood_Planks"}, {"x": 3, "y": 5, "z": 15, "name": "Build_Lightsource_White"}, {"x": 3, "y": 6, "z": 15, "name": "Rock_Calcite_Brick_Smooth_Half", "rotation": 8}, {"x": 3, "y": -3, "z": 16, "name": "Soil_Dirt"}, {"x": 3, "y": -2, "z": 16, "name": "Soil_Dirt"}, {"x": 3, "y": -1, "z": 16, "name": "Soil_Dirt"}, {"x": 3, "y": 0, "z": 16, "name": "Wood_Softwood_Planks"}, {"x": 3, "y": 6, "z": 16, "name": "Rock_Calcite_Brick_Smooth_Half", "rotation": 8}, {"x": 3, "y": -3, "z": 17, "name": "Soil_Dirt"}, {"x": 3, "y": -2, "z": 17, "name": "Soil_Dirt"}, {"x": 3, "y": -1, "z": 17, "name": "Soil_Dirt"}, {"x": 3, "y": 0, "z": 17, "name": "Rock_Calcite_Brick_Smooth"}, {"x": 3, "y": 1, "z": 17, "name": "Rock_Calcite_Brick_Decorative"}, {"x": 3, "y": 2, "z": 17, "name": "Rock_Lime_Brick_Smooth"}, {"x": 3, "y": 3, "z": 17, "name": "Rock_Lime_Brick_Smooth"}, {"x": 3, "y": 4, "z": 17, "name": "Rock_Lime_Brick_Smooth"}, {"x": 3, "y": 5, "z": 17, "name": "Rock_Calcite_Brick"}, {"x": 3, "y": 6, "z": 17, "name": "Rock_Calcite_Brick"}, {"x": 3, "y": -3, "z": 18, "name": "Soil_Dirt"}, {"x": 3, "y": -2, "z": 18, "name": "Soil_Dirt"}, {"x": 3, "y": -1, "z": 18, "name": "Soil_Dirt"}, {"x": 3, "y": 0, "z": 18, "name": "Wood_Softwood_Planks"}, {"x": 3, "y": 6, "z": 18, "name": "Rock_Calcite_Brick_Smooth_Half", "rotation": 8}, {"x": 3, "y": -3, "z": 19, "name": "Soil_Dirt"}, {"x": 3, "y": -2, "z": 19, "name": "Soil_Dirt"}, {"x": 3, "y": -1, "z": 19, "name": "Soil_Dirt"}, {"x": 3, "y": 0, "z": 19, "name": "Wood_Softwood_Planks"}, {"x": 3, "y": 6, "z": 19, "name": "Rock_Calcite_Brick_Smooth_Half", "rotation": 8}, {"x": 3, "y": -3, "z": 20, "name": "Soil_Dirt"}, {"x": 3, "y": -2, "z": 20, "name": "Soil_Dirt"}, {"x": 3, "y": -1, "z": 20, "name": "Soil_Dirt"}, {"x": 3, "y": 0, "z": 20, "name": "Wood_Softwood_Planks"}, {"x": 3, "y": 5, "z": 20, "name": "Build_Lightsource_White"}, {"x": 3, "y": 6, "z": 20, "name": "Rock_Calcite_Brick_Smooth_Half", "rotation": 8}, {"x": 3, "y": -3, "z": 21, "name": "Soil_Dirt"}, {"x": 3, "y": -2, "z": 21, "name": "Soil_Dirt"}, {"x": 3, "y": -1, "z": 21, "name": "Soil_Dirt"}, {"x": 3, "y": 0, "z": 21, "name": "Wood_Softwood_Planks"}, {"x": 3, "y": 6, "z": 21, "name": "Rock_Calcite_Brick_Smooth_Half", "rotation": 8}, {"x": 3, "y": -3, "z": 22, "name": "Soil_Dirt"}, {"x": 3, "y": -2, "z": 22, "name": "Soil_Dirt"}, {"x": 3, "y": -1, "z": 22, "name": "Soil_Dirt"}, {"x": 3, "y": 0, "z": 22, "name": "Wood_Softwood_Planks"}, {"x": 3, "y": 6, "z": 22, "name": "Rock_Calcite_Brick_Smooth_Half", "rotation": 8}, {"x": 3, "y": -3, "z": 23, "name": "Soil_Dirt"}, {"x": 3, "y": -2, "z": 23, "name": "Soil_Dirt"}, {"x": 3, "y": -1, "z": 23, "name": "Soil_Dirt"}, {"x": 3, "y": 0, "z": 23, "name": "Wood_Softwood_Planks"}, {"x": 3, "y": 6, "z": 23, "name": "Rock_Calcite_Brick_Smooth_Half", "rotation": 8}, {"x": 3, "y": -3, "z": 24, "name": "Soil_Dirt"}, {"x": 3, "y": -2, "z": 24, "name": "Soil_Dirt"}, {"x": 3, "y": -1, "z": 24, "name": "Soil_Dirt"}, {"x": 3, "y": 0, "z": 24, "name": "Wood_Softwood_Planks"}, {"x": 3, "y": 5, "z": 24, "name": "Build_Lightsource_White"}, {"x": 3, "y": 6, "z": 24, "name": "Rock_Calcite_Brick_Smooth_Half", "rotation": 8}, {"x": 3, "y": -3, "z": 25, "name": "Soil_Dirt"}, {"x": 3, "y": -2, "z": 25, "name": "Soil_Dirt"}, {"x": 3, "y": -1, "z": 25, "name": "Soil_Dirt"}, {"x": 3, "y": 0, "z": 25, "name": "Wood_Softwood_Planks"}, {"x": 3, "y": 6, "z": 25, "name": "Rock_Calcite_Brick_Smooth_Half", "rotation": 8}, {"x": 3, "y": -3, "z": 26, "name": "Soil_Dirt"}, {"x": 3, "y": -2, "z": 26, "name": "Soil_Dirt"}, {"x": 3, "y": -1, "z": 26, "name": "Soil_Dirt"}, {"x": 3, "y": 0, "z": 26, "name": "Wood_Softwood_Planks"}, {"x": 3, "y": 6, "z": 26, "name": "Rock_Calcite_Brick_Smooth_Half", "rotation": 8}, {"x": 3, "y": -3, "z": 27, "name": "Soil_Dirt"}, {"x": 3, "y": -2, "z": 27, "name": "Soil_Dirt"}, {"x": 3, "y": -1, "z": 27, "name": "Soil_Dirt"}, {"x": 3, "y": 0, "z": 27, "name": "Wood_Softwood_Planks"}, {"x": 3, "y": 6, "z": 27, "name": "Rock_Calcite_Brick_Smooth_Half", "rotation": 8}, {"x": 3, "y": -3, "z": 28, "name": "Soil_Dirt"}, {"x": 3, "y": -2, "z": 28, "name": "Soil_Dirt"}, {"x": 3, "y": -1, "z": 28, "name": "Soil_Dirt"}, {"x": 3, "y": 0, "z": 28, "name": "Wood_Softwood_Planks"}, {"x": 3, "y": 5, "z": 28, "name": "Build_Lightsource_White"}, {"x": 3, "y": 6, "z": 28, "name": "Rock_Calcite_Brick_Smooth_Half", "rotation": 8}, {"x": 3, "y": -3, "z": 29, "name": "Soil_Dirt"}, {"x": 3, "y": -2, "z": 29, "name": "Soil_Dirt"}, {"x": 3, "y": -1, "z": 29, "name": "Soil_Dirt"}, {"x": 3, "y": 0, "z": 29, "name": "Wood_Softwood_Planks"}, {"x": 3, "y": 6, "z": 29, "name": "Rock_Calcite_Brick_Smooth_Half", "rotation": 8}, {"x": 3, "y": -3, "z": 30, "name": "Soil_Dirt"}, {"x": 3, "y": -2, "z": 30, "name": "Soil_Dirt"}, {"x": 3, "y": -1, "z": 30, "name": "Soil_Dirt"}, {"x": 3, "y": 0, "z": 30, "name": "K2_Slot_Shelf_Counter"}, {"x": 3, "y": 6, "z": 30, "name": "Rock_Calcite_Brick_Smooth_Half", "rotation": 8}, {"x": 3, "y": -3, "z": 31, "name": "Soil_Dirt"}, {"x": 3, "y": -2, "z": 31, "name": "Soil_Dirt"}, {"x": 3, "y": -1, "z": 31, "name": "Soil_Dirt"}, {"x": 3, "y": 0, "z": 31, "name": "Soil_Dirt"}, {"x": 3, "y": 1, "z": 31, "name": "Rock_Calcite_Brick_Decorative"}, {"x": 3, "y": 2, "z": 31, "name": "Rock_Lime_Brick_Smooth"}, {"x": 3, "y": 3, "z": 31, "name": "Rock_Lime_Brick_Smooth"}, {"x": 3, "y": 4, "z": 31, "name": "Rock_Lime_Brick_Smooth"}, {"x": 3, "y": 5, "z": 31, "name": "Rock_Calcite_Brick"}, {"x": 3, "y": 6, "z": 31, "name": "Rock_Calcite_Brick"}, {"x": 4, "y": -3, "z": 0, "name": "Soil_Dirt"}, {"x": 4, "y": -2, "z": 0, "name": "Soil_Dirt"}, {"x": 4, "y": -1, "z": 0, "name": "Soil_Dirt"}, {"x": 4, "y": 0, "z": 0, "name": "Soil_Grass"}, {"x": 4, "y": -3, "z": 1, "name": "Soil_Dirt"}, {"x": 4, "y": -2, "z": 1, "name": "Soil_Dirt"}, {"x": 4, "y": -1, "z": 1, "name": "Soil_Dirt"}, {"x": 4, "y": 0, "z": 1, "name": "Soil_Grass"}, {"x": 4, "y": -3, "z": 2, "name": "Soil_Dirt"}, {"x": 4, "y": -2, "z": 2, "name": "Soil_Dirt"}, {"x": 4, "y": -1, "z": 2, "name": "Soil_Dirt"}, {"x": 4, "y": 0, "z": 2, "name": "Soil_Grass"}, {"x": 4, "y": -3, "z": 3, "name": "Soil_Dirt"}, {"x": 4, "y": -2, "z": 3, "name": "Soil_Dirt"}, {"x": 4, "y": -1, "z": 3, "name": "Soil_Dirt"}, {"x": 4, "y": 0, "z": 3, "name": "Soil_Grass"}, {"x": 4, "y": -3, "z": 4, "name": "Soil_Dirt"}, {"x": 4, "y": -2, "z": 4, "name": "Soil_Dirt"}, {"x": 4, "y": -1, "z": 4, "name": "Soil_Dirt"}, {"x": 4, "y": 0, "z": 4, "name": "Soil_Grass"}, {"x": 4, "y": -3, "z": 5, "name": "Soil_Dirt"}, {"x": 4, "y": -2, "z": 5, "name": "Soil_Dirt"}, {"x": 4, "y": -1, "z": 5, "name": "Soil_Dirt"}, {"x": 4, "y": 0, "z": 5, "name": "Soil_Grass"}, {"x": 4, "y": -3, "z": 6, "name": "Soil_Dirt"}, {"x": 4, "y": -2, "z": 6, "name": "Soil_Dirt"}, {"x": 4, "y": -1, "z": 6, "name": "Soil_Dirt"}, {"x": 4, "y": 0, "z": 6, "name": "Soil_Grass"}, {"x": 4, "y": -3, "z": 7, "name": "Soil_Dirt"}, {"x": 4, "y": -2, "z": 7, "name": "Soil_Dirt"}, {"x": 4, "y": -1, "z": 7, "name": "Soil_Dirt"}, {"x": 4, "y": 0, "z": 7, "name": "Soil_Grass"}, {"x": 4, "y": -3, "z": 8, "name": "Soil_Dirt"}, {"x": 4, "y": -2, "z": 8, "name": "Soil_Dirt"}, {"x": 4, "y": -1, "z": 8, "name": "Soil_Dirt"}, {"x": 4, "y": 0, "z": 8, "name": "Soil_Grass"}, {"x": 4, "y": -3, "z": 9, "name": "Soil_Dirt"}, {"x": 4, "y": -2, "z": 9, "name": "Soil_Dirt"}, {"x": 4, "y": -1, "z": 9, "name": "Soil_Dirt"}, {"x": 4, "y": 0, "z": 9, "name": "Soil_Dirt"}, {"x": 4, "y": 1, "z": 9, "name": "Rock_Calcite_Brick_Decorative"}, {"x": 4, "y": 2, "z": 9, "name": "Rock_Lime_Brick_Smooth"}, {"x": 4, "y": 3, "z": 9, "name": "Rock_Lime_Brick_Smooth"}, {"x": 4, "y": 4, "z": 9, "name": "Rock_Lime_Brick_Smooth"}, {"x": 4, "y": 5, "z": 9, "name": "Rock_Calcite_Brick"}, {"x": 4, "y": 6, "z": 9, "name": "Rock_Calcite_Brick"}, {"x": 4, "y": -3, "z": 10, "name": "Soil_Dirt"}, {"x": 4, "y": -2, "z": 10, "name": "Soil_Dirt"}, {"x": 4, "y": -1, "z": 10, "name": "Soil_Dirt"}, {"x": 4, "y": 0, "z": 10, "name": "Wood_Softwood_Planks"}, {"x": 4, "y": 7, "z": 10, "name": "Rock_Calcite_Brick_Smooth_Half"}, {"x": 4, "y": -3, "z": 11, "name": "Soil_Dirt"}, {"x": 4, "y": -2, "z": 11, "name": "Soil_Dirt"}, {"x": 4, "y": -1, "z": 11, "name": "Soil_Dirt"}, {"x": 4, "y": 0, "z": 11, "name": "Wood_Softwood_Planks"}, {"x": 4, "y": 7, "z": 11, "name": "Rock_Calcite_Brick_Smooth_Half"}, {"x": 4, "y": -3, "z": 12, "name": "Soil_Dirt"}, {"x": 4, "y": -2, "z": 12, "name": "Soil_Dirt"}, {"x": 4, "y": -1, "z": 12, "name": "Soil_Dirt"}, {"x": 4, "y": 0, "z": 12, "name": "Wood_Softwood_Planks"}, {"x": 4, "y": 7, "z": 12, "name": "Rock_Calcite_Brick_Smooth_Half"}, {"x": 4, "y": -3, "z": 13, "name": "Soil_Dirt"}, {"x": 4, "y": -2, "z": 13, "name": "Soil_Dirt"}, {"x": 4, "y": -1, "z": 13, "name": "Soil_Dirt"}, {"x": 4, "y": 0, "z": 13, "name": "Wood_Softwood_Planks"}, {"x": 4, "y": 7, "z": 13, "name": "Rock_Calcite_Brick_Smooth_Half"}, {"x": 4, "y": -3, "z": 14, "name": "Soil_Dirt"}, {"x": 4, "y": -2, "z": 14, "name": "Soil_Dirt"}, {"x": 4, "y": -1, "z": 14, "name": "Soil_Dirt"}, {"x": 4, "y": 0, "z": 14, "name": "Wood_Softwood_Planks"}, {"x": 4, "y": 7, "z": 14, "name": "Rock_Calcite_Brick_Smooth_Half"}, {"x": 4, "y": -3, "z": 15, "name": "Soil_Dirt"}, {"x": 4, "y": -2, "z": 15, "name": "Soil_Dirt"}, {"x": 4, "y": -1, "z": 15, "name": "Soil_Dirt"}, {"x": 4, "y": 0, "z": 15, "name": "Wood_Softwood_Planks"}, {"x": 4, "y": 7, "z": 15, "name": "Rock_Calcite_Brick_Smooth_Half"}, {"x": 4, "y": -3, "z": 16, "name": "Soil_Dirt"}, {"x": 4, "y": -2, "z": 16, "name": "Soil_Dirt"}, {"x": 4, "y": -1, "z": 16, "name": "Soil_Dirt"}, {"x": 4, "y": 0, "z": 16, "name": "Wood_Softwood_Planks"}, {"x": 4, "y": 7, "z": 16, "name": "Rock_Calcite_Brick_Smooth_Half"}, {"x": 4, "y": -3, "z": 17, "name": "Soil_Dirt"}, {"x": 4, "y": -2, "z": 17, "name": "Soil_Dirt"}, {"x": 4, "y": -1, "z": 17, "name": "Soil_Dirt"}, {"x": 4, "y": 0, "z": 17, "name": "Rock_Calcite_Brick_Smooth"}, {"x": 4, "y": 5, "z": 17, "name": "Rock_Calcite_Brick"}, {"x": 4, "y": 6, "z": 17, "name": "Rock_Calcite_Brick"}, {"x": 4, "y": 7, "z": 17, "name": "Rock_Calcite_Brick_Smooth_Half"}, {"x": 4, "y": -3, "z": 18, "name": "Soil_Dirt"}, {"x": 4, "y": -2, "z": 18, "name": "Soil_Dirt"}, {"x": 4, "y": -1, "z": 18, "name": "Soil_Dirt"}, {"x": 4, "y": 0, "z": 18, "name": "Wood_Softwood_Planks"}, {"x": 4, "y": 7, "z": 18, "name": "Rock_Calcite_Brick_Smooth_Half"}, {"x": 4, "y": -3, "z": 19, "name": "Soil_Dirt"}, {"x": 4, "y": -2, "z": 19, "name": "Soil_Dirt"}, {"x": 4, "y": -1, "z": 19, "name": "Soil_Dirt"}, {"x": 4, "y": 0, "z": 19, "name": "Wood_Softwood_Planks"}, {"x": 4, "y": 7, "z": 19, "name": "Rock_Calcite_Brick_Smooth_Half"}, {"x": 4, "y": -3, "z": 20, "name": "Soil_Dirt"}, {"x": 4, "y": -2, "z": 20, "name": "Soil_Dirt"}, {"x": 4, "y": -1, "z": 20, "name": "Soil_Dirt"}, {"x": 4, "y": 0, "z": 20, "name": "Wood_Softwood_Planks"}, {"x": 4, "y": 7, "z": 20, "name": "Rock_Calcite_Brick_Smooth_Half"}, {"x": 4, "y": -3, "z": 21, "name": "Soil_Dirt"}, {"x": 4, "y": -2, "z": 21, "name": "Soil_Dirt"}, {"x": 4, "y": -1, "z": 21, "name": "Soil_Dirt"}, {"x": 4, "y": 0, "z": 21, "name": "Wood_Softwood_Planks"}, {"x": 4, "y": 7, "z": 21, "name": "Rock_Calcite_Brick_Smooth_Half"}, {"x": 4, "y": -3, "z": 22, "name": "Soil_Dirt"}, {"x": 4, "y": -2, "z": 22, "name": "Soil_Dirt"}, {"x": 4, "y": -1, "z": 22, "name": "Soil_Dirt"}, {"x": 4, "y": 0, "z": 22, "name": "Wood_Softwood_Planks"}, {"x": 4, "y": 7, "z": 22, "name": "Rock_Calcite_Brick_Smooth_Half"}, {"x": 4, "y": -3, "z": 23, "name": "Soil_Dirt"}, {"x": 4, "y": -2, "z": 23, "name": "Soil_Dirt"}, {"x": 4, "y": -1, "z": 23, "name": "Soil_Dirt"}, {"x": 4, "y": 0, "z": 23, "name": "Wood_Softwood_Planks"}, {"x": 4, "y": 7, "z": 23, "name": "Rock_Calcite_Brick_Smooth_Half"}, {"x": 4, "y": -3, "z": 24, "name": "Soil_Dirt"}, {"x": 4, "y": -2, "z": 24, "name": "Soil_Dirt"}, {"x": 4, "y": -1, "z": 24, "name": "Soil_Dirt"}, {"x": 4, "y": 0, "z": 24, "name": "Wood_Softwood_Planks"}, {"x": 4, "y": 7, "z": 24, "name": "Rock_Calcite_Brick_Smooth_Half"}, {"x": 4, "y": -3, "z": 25, "name": "Soil_Dirt"}, {"x": 4, "y": -2, "z": 25, "name": "Soil_Dirt"}, {"x": 4, "y": -1, "z": 25, "name": "Soil_Dirt"}, {"x": 4, "y": 0, "z": 25, "name": "Wood_Softwood_Planks"}, {"x": 4, "y": 7, "z": 25, "name": "Rock_Calcite_Brick_Smooth_Half"}, {"x": 4, "y": -3, "z": 26, "name": "Soil_Dirt"}, {"x": 4, "y": -2, "z": 26, "name": "Soil_Dirt"}, {"x": 4, "y": -1, "z": 26, "name": "Soil_Dirt"}, {"x": 4, "y": 0, "z": 26, "name": "Wood_Softwood_Planks"}, {"x": 4, "y": 7, "z": 26, "name": "Rock_Calcite_Brick_Smooth_Half"}, {"x": 4, "y": -3, "z": 27, "name": "Soil_Dirt"}, {"x": 4, "y": -2, "z": 27, "name": "Soil_Dirt"}, {"x": 4, "y": -1, "z": 27, "name": "Soil_Dirt"}, {"x": 4, "y": 0, "z": 27, "name": "Wood_Softwood_Planks"}, {"x": 4, "y": 7, "z": 27, "name": "Rock_Calcite_Brick_Smooth_Half"}, {"x": 4, "y": -3, "z": 28, "name": "Soil_Dirt"}, {"x": 4, "y": -2, "z": 28, "name": "Soil_Dirt"}, {"x": 4, "y": -1, "z": 28, "name": "Soil_Dirt"}, {"x": 4, "y": 0, "z": 28, "name": "Wood_Softwood_Planks"}, {"x": 4, "y": 7, "z": 28, "name": "Rock_Calcite_Brick_Smooth_Half"}, {"x": 4, "y": -3, "z": 29, "name": "Soil_Dirt"}, {"x": 4, "y": -2, "z": 29, "name": "Soil_Dirt"}, {"x": 4, "y": -1, "z": 29, "name": "Soil_Dirt"}, {"x": 4, "y": 0, "z": 29, "name": "Wood_Softwood_Planks"}, {"x": 4, "y": 7, "z": 29, "name": "Rock_Calcite_Brick_Smooth_Half"}, {"x": 4, "y": -3, "z": 30, "name": "Soil_Dirt"}, {"x": 4, "y": -2, "z": 30, "name": "Soil_Dirt"}, {"x": 4, "y": -1, "z": 30, "name": "Soil_Dirt"}, {"x": 4, "y": 0, "z": 30, "name": "K2_Slot_Shelf_Rack"}, {"x": 4, "y": 7, "z": 30, "name": "Rock_Calcite_Brick_Smooth_Half"}, {"x": 4, "y": -3, "z": 31, "name": "Soil_Dirt"}, {"x": 4, "y": -2, "z": 31, "name": "Soil_Dirt"}, {"x": 4, "y": -1, "z": 31, "name": "Soil_Dirt"}, {"x": 4, "y": 0, "z": 31, "name": "Soil_Dirt"}, {"x": 4, "y": 1, "z": 31, "name": "Rock_Calcite_Brick_Decorative"}, {"x": 4, "y": 2, "z": 31, "name": "Rock_Lime_Brick_Smooth"}, {"x": 4, "y": 3, "z": 31, "name": "Rock_Lime_Brick_Smooth"}, {"x": 4, "y": 4, "z": 31, "name": "Rock_Lime_Brick_Smooth"}, {"x": 4, "y": 5, "z": 31, "name": "Rock_Calcite_Brick"}, {"x": 4, "y": 6, "z": 31, "name": "Rock_Calcite_Brick"}, {"x": 5, "y": -3, "z": 0, "name": "Soil_Dirt"}, {"x": 5, "y": -2, "z": 0, "name": "Soil_Dirt"}, {"x": 5, "y": -1, "z": 0, "name": "Soil_Dirt"}, {"x": 5, "y": 0, "z": 0, "name": "Soil_Grass"}, {"x": 5, "y": -3, "z": 1, "name": "Soil_Dirt"}, {"x": 5, "y": -2, "z": 1, "name": "Soil_Dirt"}, {"x": 5, "y": -1, "z": 1, "name": "Soil_Dirt"}, {"x": 5, "y": 0, "z": 1, "name": "Soil_Grass"}, {"x": 5, "y": -3, "z": 2, "name": "Soil_Dirt"}, {"x": 5, "y": -2, "z": 2, "name": "Soil_Dirt"}, {"x": 5, "y": -1, "z": 2, "name": "Soil_Dirt"}, {"x": 5, "y": 0, "z": 2, "name": "Soil_Grass"}, {"x": 5, "y": -3, "z": 3, "name": "Soil_Dirt"}, {"x": 5, "y": -2, "z": 3, "name": "Soil_Dirt"}, {"x": 5, "y": -1, "z": 3, "name": "Soil_Dirt"}, {"x": 5, "y": 0, "z": 3, "name": "Soil_Grass"}, {"x": 5, "y": -3, "z": 4, "name": "Soil_Dirt"}, {"x": 5, "y": -2, "z": 4, "name": "Soil_Dirt"}, {"x": 5, "y": -1, "z": 4, "name": "Soil_Dirt"}, {"x": 5, "y": 0, "z": 4, "name": "Soil_Grass"}, {"x": 5, "y": -3, "z": 5, "name": "Soil_Dirt"}, {"x": 5, "y": -2, "z": 5, "name": "Soil_Dirt"}, {"x": 5, "y": -1, "z": 5, "name": "Soil_Dirt"}, {"x": 5, "y": 0, "z": 5, "name": "Soil_Grass"}, {"x": 5, "y": -3, "z": 6, "name": "Soil_Dirt"}, {"x": 5, "y": -2, "z": 6, "name": "Soil_Dirt"}, {"x": 5, "y": -1, "z": 6, "name": "Soil_Grass"}, {"x": 5, "y": -3, "z": 7, "name": "Soil_Dirt"}, {"x": 5, "y": -2, "z": 7, "name": "Soil_Dirt"}, {"x": 5, "y": -1, "z": 7, "name": "Soil_Grass"}, {"x": 5, "y": -3, "z": 8, "name": "Soil_Dirt"}, {"x": 5, "y": -2, "z": 8, "name": "Soil_Dirt"}, {"x": 5, "y": -1, "z": 8, "name": "Soil_Grass"}, {"x": 5, "y": -3, "z": 9, "name": "Soil_Dirt"}, {"x": 5, "y": -2, "z": 9, "name": "Soil_Dirt"}, {"x": 5, "y": -1, "z": 9, "name": "Soil_Grass"}, {"x": 5, "y": 1, "z": 9, "name": "Rock_Calcite_Brick_Decorative"}, {"x": 5, "y": 2, "z": 9, "name": "Rock_Lime_Brick_Smooth"}, {"x": 5, "y": 3, "z": 9, "name": "Rock_Lime_Brick_Smooth"}, {"x": 5, "y": 4, "z": 9, "name": "Rock_Lime_Brick_Smooth"}, {"x": 5, "y": 5, "z": 9, "name": "Rock_Calcite_Brick"}, {"x": 5, "y": 6, "z": 9, "name": "Rock_Calcite_Brick"}, {"x": 5, "y": -3, "z": 10, "name": "Soil_Dirt"}, {"x": 5, "y": -2, "z": 10, "name": "Soil_Dirt"}, {"x": 5, "y": -1, "z": 10, "name": "Soil_Dirt"}, {"x": 5, "y": 0, "z": 10, "name": "Wood_Softwood_Planks"}, {"x": 5, "y": 7, "z": 10, "name": "Rock_Calcite_Brick_Smooth_Half"}, {"x": 5, "y": -3, "z": 11, "name": "Soil_Dirt"}, {"x": 5, "y": -2, "z": 11, "name": "Soil_Dirt"}, {"x": 5, "y": -1, "z": 11, "name": "Soil_Dirt"}, {"x": 5, "y": 0, "z": 11, "name": "Wood_Softwood_Planks"}, {"x": 5, "y": 7, "z": 11, "name": "Rock_Calcite_Brick_Smooth_Half"}, {"x": 5, "y": -3, "z": 12, "name": "Soil_Dirt"}, {"x": 5, "y": -2, "z": 12, "name": "Soil_Dirt"}, {"x": 5, "y": -1, "z": 12, "name": "Soil_Dirt"}, {"x": 5, "y": 0, "z": 12, "name": "Wood_Softwood_Planks"}, {"x": 5, "y": 7, "z": 12, "name": "Rock_Calcite_Brick_Smooth_Half"}, {"x": 5, "y": -3, "z": 13, "name": "Soil_Dirt"}, {"x": 5, "y": -2, "z": 13, "name": "Soil_Dirt"}, {"x": 5, "y": -1, "z": 13, "name": "Soil_Dirt"}, {"x": 5, "y": 0, "z": 13, "name": "Wood_Softwood_Planks"}, {"x": 5, "y": 7, "z": 13, "name": "Rock_Calcite_Brick_Smooth_Half"}, {"x": 5, "y": -3, "z": 14, "name": "Soil_Dirt"}, {"x": 5, "y": -2, "z": 14, "name": "Soil_Dirt"}, {"x": 5, "y": -1, "z": 14, "name": "Soil_Dirt"}, {"x": 5, "y": 0, "z": 14, "name": "Wood_Softwood_Planks"}, {"x": 5, "y": 7, "z": 14, "name": "Rock_Calcite_Brick_Smooth_Half"}, {"x": 5, "y": -3, "z": 15, "name": "Soil_Dirt"}, {"x": 5, "y": -2, "z": 15, "name": "Soil_Dirt"}, {"x": 5, "y": -1, "z": 15, "name": "Soil_Dirt"}, {"x": 5, "y": 0, "z": 15, "name": "Wood_Softwood_Planks"}, {"x": 5, "y": 7, "z": 15, "name": "Rock_Calcite_Brick_Smooth_Half"}, {"x": 5, "y": -3, "z": 16, "name": "Soil_Dirt"}, {"x": 5, "y": -2, "z": 16, "name": "Soil_Dirt"}, {"x": 5, "y": -1, "z": 16, "name": "Soil_Dirt"}, {"x": 5, "y": 0, "z": 16, "name": "Wood_Softwood_Planks"}, {"x": 5, "y": 7, "z": 16, "name": "Rock_Calcite_Brick_Smooth_Half"}, {"x": 5, "y": -3, "z": 17, "name": "Soil_Dirt"}, {"x": 5, "y": -2, "z": 17, "name": "Soil_Dirt"}, {"x": 5, "y": -1, "z": 17, "name": "Soil_Dirt"}, {"x": 5, "y": 0, "z": 17, "name": "Rock_Calcite_Brick_Smooth"}, {"x": 5, "y": 5, "z": 17, "name": "Rock_Calcite_Brick"}, {"x": 5, "y": 6, "z": 17, "name": "Rock_Calcite_Brick"}, {"x": 5, "y": 7, "z": 17, "name": "Rock_Calcite_Brick_Smooth_Half"}, {"x": 5, "y": -3, "z": 18, "name": "Soil_Dirt"}, {"x": 5, "y": -2, "z": 18, "name": "Soil_Dirt"}, {"x": 5, "y": -1, "z": 18, "name": "Soil_Dirt"}, {"x": 5, "y": 0, "z": 18, "name": "Wood_Softwood_Planks"}, {"x": 5, "y": 7, "z": 18, "name": "Rock_Calcite_Brick_Smooth_Half"}, {"x": 5, "y": -3, "z": 19, "name": "Soil_Dirt"}, {"x": 5, "y": -2, "z": 19, "name": "Soil_Dirt"}, {"x": 5, "y": -1, "z": 19, "name": "Soil_Dirt"}, {"x": 5, "y": 0, "z": 19, "name": "Wood_Softwood_Planks"}, {"x": 5, "y": 7, "z": 19, "name": "Rock_Calcite_Brick_Smooth_Half"}, {"x": 5, "y": -3, "z": 20, "name": "Soil_Dirt"}, {"x": 5, "y": -2, "z": 20, "name": "Soil_Dirt"}, {"x": 5, "y": -1, "z": 20, "name": "Soil_Dirt"}, {"x": 5, "y": 0, "z": 20, "name": "Wood_Softwood_Planks"}, {"x": 5, "y": 7, "z": 20, "name": "Rock_Calcite_Brick_Smooth_Half"}, {"x": 5, "y": -3, "z": 21, "name": "Soil_Dirt"}, {"x": 5, "y": -2, "z": 21, "name": "Soil_Dirt"}, {"x": 5, "y": -1, "z": 21, "name": "Soil_Dirt"}, {"x": 5, "y": 0, "z": 21, "name": "Wood_Softwood_Planks"}, {"x": 5, "y": 7, "z": 21, "name": "Rock_Calcite_Brick_Smooth_Half"}, {"x": 5, "y": -3, "z": 22, "name": "Soil_Dirt"}, {"x": 5, "y": -2, "z": 22, "name": "Soil_Dirt"}, {"x": 5, "y": -1, "z": 22, "name": "Soil_Dirt"}, {"x": 5, "y": 0, "z": 22, "name": "Wood_Softwood_Planks"}, {"x": 5, "y": 7, "z": 22, "name": "Rock_Calcite_Brick_Smooth_Half"}, {"x": 5, "y": -3, "z": 23, "name": "Soil_Dirt"}, {"x": 5, "y": -2, "z": 23, "name": "Soil_Dirt"}, {"x": 5, "y": -1, "z": 23, "name": "Soil_Dirt"}, {"x": 5, "y": 0, "z": 23, "name": "Wood_Softwood_Planks"}, {"x": 5, "y": 7, "z": 23, "name": "Rock_Calcite_Brick_Smooth_Half"}, {"x": 5, "y": -3, "z": 24, "name": "Soil_Dirt"}, {"x": 5, "y": -2, "z": 24, "name": "Soil_Dirt"}, {"x": 5, "y": -1, "z": 24, "name": "Soil_Dirt"}, {"x": 5, "y": 0, "z": 24, "name": "Wood_Softwood_Planks"}, {"x": 5, "y": 7, "z": 24, "name": "Rock_Calcite_Brick_Smooth_Half"}, {"x": 5, "y": -3, "z": 25, "name": "Soil_Dirt"}, {"x": 5, "y": -2, "z": 25, "name": "Soil_Dirt"}, {"x": 5, "y": -1, "z": 25, "name": "Soil_Dirt"}, {"x": 5, "y": 0, "z": 25, "name": "Wood_Softwood_Planks"}, {"x": 5, "y": 7, "z": 25, "name": "Rock_Calcite_Brick_Smooth_Half"}, {"x": 5, "y": -3, "z": 26, "name": "Soil_Dirt"}, {"x": 5, "y": -2, "z": 26, "name": "Soil_Dirt"}, {"x": 5, "y": -1, "z": 26, "name": "Soil_Dirt"}, {"x": 5, "y": 0, "z": 26, "name": "Wood_Softwood_Planks"}, {"x": 5, "y": 7, "z": 26, "name": "Rock_Calcite_Brick_Smooth_Half"}, {"x": 5, "y": -3, "z": 27, "name": "Soil_Dirt"}, {"x": 5, "y": -2, "z": 27, "name": "Soil_Dirt"}, {"x": 5, "y": -1, "z": 27, "name": "Soil_Dirt"}, {"x": 5, "y": 0, "z": 27, "name": "Wood_Softwood_Planks"}, {"x": 5, "y": 7, "z": 27, "name": "Rock_Calcite_Brick_Smooth_Half"}, {"x": 5, "y": -3, "z": 28, "name": "Soil_Dirt"}, {"x": 5, "y": -2, "z": 28, "name": "Soil_Dirt"}, {"x": 5, "y": -1, "z": 28, "name": "Soil_Dirt"}, {"x": 5, "y": 0, "z": 28, "name": "Wood_Softwood_Planks"}, {"x": 5, "y": 7, "z": 28, "name": "Rock_Calcite_Brick_Smooth_Half"}, {"x": 5, "y": -3, "z": 29, "name": "Soil_Dirt"}, {"x": 5, "y": -2, "z": 29, "name": "Soil_Dirt"}, {"x": 5, "y": -1, "z": 29, "name": "Soil_Dirt"}, {"x": 5, "y": 0, "z": 29, "name": "Wood_Softwood_Planks"}, {"x": 5, "y": 7, "z": 29, "name": "Rock_Calcite_Brick_Smooth_Half"}, {"x": 5, "y": -3, "z": 30, "name": "Soil_Dirt"}, {"x": 5, "y": -2, "z": 30, "name": "Soil_Dirt"}, {"x": 5, "y": -1, "z": 30, "name": "Soil_Dirt"}, {"x": 5, "y": 0, "z": 30, "name": "Rock_Calcite_Brick_Ornate"}, {"x": 5, "y": 7, "z": 30, "name": "Rock_Calcite_Brick_Smooth_Half"}, {"x": 5, "y": -3, "z": 31, "name": "Soil_Dirt"}, {"x": 5, "y": -2, "z": 31, "name": "Soil_Dirt"}, {"x": 5, "y": -1, "z": 31, "name": "Soil_Dirt"}, {"x": 5, "y": 0, "z": 31, "name": "Soil_Dirt"}, {"x": 5, "y": 1, "z": 31, "name": "Rock_Calcite_Brick_Decorative"}, {"x": 5, "y": 2, "z": 31, "name": "Rock_Lime_Brick_Smooth"}, {"x": 5, "y": 3, "z": 31, "name": "Rock_Lime_Brick_Smooth"}, {"x": 5, "y": 4, "z": 31, "name": "Rock_Lime_Brick_Smooth"}, {"x": 5, "y": 5, "z": 31, "name": "Rock_Calcite_Brick"}, {"x": 5, "y": 6, "z": 31, "name": "Rock_Calcite_Brick"}, {"x": 6, "y": -3, "z": 0, "name": "Soil_Dirt"}, {"x": 6, "y": -2, "z": 0, "name": "Soil_Dirt"}, {"x": 6, "y": -1, "z": 0, "name": "Soil_Dirt"}, {"x": 6, "y": 0, "z": 0, "name": "Soil_Grass"}, {"x": 6, "y": -3, "z": 1, "name": "Soil_Dirt"}, {"x": 6, "y": -2, "z": 1, "name": "Soil_Dirt"}, {"x": 6, "y": -1, "z": 1, "name": "Soil_Dirt"}, {"x": 6, "y": 0, "z": 1, "name": "Soil_Grass"}, {"x": 6, "y": -3, "z": 2, "name": "Soil_Dirt"}, {"x": 6, "y": -2, "z": 2, "name": "Soil_Dirt"}, {"x": 6, "y": -1, "z": 2, "name": "Soil_Dirt"}, {"x": 6, "y": 0, "z": 2, "name": "Soil_Grass"}, {"x": 6, "y": -3, "z": 3, "name": "Soil_Dirt"}, {"x": 6, "y": -2, "z": 3, "name": "Soil_Dirt"}, {"x": 6, "y": -1, "z": 3, "name": "Soil_Dirt"}, {"x": 6, "y": 0, "z": 3, "name": "Soil_Grass"}, {"x": 6, "y": -3, "z": 4, "name": "Soil_Dirt"}, {"x": 6, "y": -2, "z": 4, "name": "Soil_Dirt"}, {"x": 6, "y": -1, "z": 4, "name": "Soil_Dirt"}, {"x": 6, "y": 0, "z": 4, "name": "Soil_Grass"}, {"x": 6, "y": -3, "z": 5, "name": "Soil_Dirt"}, {"x": 6, "y": -2, "z": 5, "name": "Soil_Dirt"}, {"x": 6, "y": -1, "z": 5, "name": "Soil_Dirt"}, {"x": 6, "y": 0, "z": 5, "name": "Soil_Grass"}, {"x": 6, "y": -3, "z": 6, "name": "Soil_Dirt"}, {"x": 6, "y": -2, "z": 6, "name": "Soil_Dirt"}, {"x": 6, "y": -1, "z": 6, "name": "Soil_Grass"}, {"x": 6, "y": -3, "z": 7, "name": "Soil_Dirt"}, {"x": 6, "y": -2, "z": 7, "name": "Soil_Dirt"}, {"x": 6, "y": -1, "z": 7, "name": "Soil_Grass"}, {"x": 6, "y": -3, "z": 8, "name": "Soil_Dirt"}, {"x": 6, "y": -2, "z": 8, "name": "Soil_Dirt"}, {"x": 6, "y": -1, "z": 8, "name": "Soil_Grass"}, {"x": 6, "y": -3, "z": 9, "name": "Soil_Dirt"}, {"x": 6, "y": -2, "z": 9, "name": "Soil_Dirt"}, {"x": 6, "y": -1, "z": 9, "name": "Soil_Grass"}, {"x": 6, "y": 1, "z": 9, "name": "Rock_Calcite_Brick_Decorative"}, {"x": 6, "y": 2, "z": 9, "name": "Rock_Lime_Brick_Smooth"}, {"x": 6, "y": 3, "z": 9, "name": "Rock_Lime_Brick_Smooth"}, {"x": 6, "y": 4, "z": 9, "name": "Rock_Lime_Brick_Smooth"}, {"x": 6, "y": 5, "z": 9, "name": "Rock_Calcite_Brick"}, {"x": 6, "y": 6, "z": 9, "name": "Rock_Calcite_Brick"}, {"x": 6, "y": -3, "z": 10, "name": "Soil_Dirt"}, {"x": 6, "y": -2, "z": 10, "name": "Soil_Dirt"}, {"x": 6, "y": -1, "z": 10, "name": "Soil_Dirt"}, {"x": 6, "y": 0, "z": 10, "name": "Wood_Softwood_Planks"}, {"x": 6, "y": 6, "z": 10, "name": "Rock_Calcite_Brick_Smooth_Half", "rotation": 8}, {"x": 6, "y": -3, "z": 11, "name": "Soil_Dirt"}, {"x": 6, "y": -2, "z": 11, "name": "Soil_Dirt"}, {"x": 6, "y": -1, "z": 11, "name": "Soil_Dirt"}, {"x": 6, "y": 0, "z": 11, "name": "Wood_Softwood_Planks"}, {"x": 6, "y": 5, "z": 11, "name": "Build_Lightsource_White"}, {"x": 6, "y": 6, "z": 11, "name": "Rock_Calcite_Brick_Smooth_Half", "rotation": 8}, {"x": 6, "y": -3, "z": 12, "name": "Soil_Dirt"}, {"x": 6, "y": -2, "z": 12, "name": "Soil_Dirt"}, {"x": 6, "y": -1, "z": 12, "name": "Soil_Dirt"}, {"x": 6, "y": 0, "z": 12, "name": "Wood_Softwood_Planks"}, {"x": 6, "y": 6, "z": 12, "name": "Rock_Calcite_Brick_Smooth_Half", "rotation": 8}, {"x": 6, "y": -3, "z": 13, "name": "Soil_Dirt"}, {"x": 6, "y": -2, "z": 13, "name": "Soil_Dirt"}, {"x": 6, "y": -1, "z": 13, "name": "Soil_Dirt"}, {"x": 6, "y": 0, "z": 13, "name": "Wood_Softwood_Planks"}, {"x": 6, "y": 6, "z": 13, "name": "Rock_Calcite_Brick_Smooth_Half", "rotation": 8}, {"x": 6, "y": -3, "z": 14, "name": "Soil_Dirt"}, {"x": 6, "y": -2, "z": 14, "name": "Soil_Dirt"}, {"x": 6, "y": -1, "z": 14, "name": "Soil_Dirt"}, {"x": 6, "y": 0, "z": 14, "name": "Wood_Softwood_Planks"}, {"x": 6, "y": 6, "z": 14, "name": "Rock_Calcite_Brick_Smooth_Half", "rotation": 8}, {"x": 6, "y": -3, "z": 15, "name": "Soil_Dirt"}, {"x": 6, "y": -2, "z": 15, "name": "Soil_Dirt"}, {"x": 6, "y": -1, "z": 15, "name": "Soil_Dirt"}, {"x": 6, "y": 0, "z": 15, "name": "Wood_Softwood_Planks"}, {"x": 6, "y": 5, "z": 15, "name": "Build_Lightsource_White"}, {"x": 6, "y": 6, "z": 15, "name": "Rock_Calcite_Brick_Smooth_Half", "rotation": 8}, {"x": 6, "y": -3, "z": 16, "name": "Soil_Dirt"}, {"x": 6, "y": -2, "z": 16, "name": "Soil_Dirt"}, {"x": 6, "y": -1, "z": 16, "name": "Soil_Dirt"}, {"x": 6, "y": 0, "z": 16, "name": "Wood_Softwood_Planks"}, {"x": 6, "y": 6, "z": 16, "name": "Rock_Calcite_Brick_Smooth_Half", "rotation": 8}, {"x": 6, "y": -3, "z": 17, "name": "Soil_Dirt"}, {"x": 6, "y": -2, "z": 17, "name": "Soil_Dirt"}, {"x": 6, "y": -1, "z": 17, "name": "Soil_Dirt"}, {"x": 6, "y": 0, "z": 17, "name": "Rock_Calcite_Brick_Smooth"}, {"x": 6, "y": 1, "z": 17, "name": "Rock_Calcite_Brick_Decorative"}, {"x": 6, "y": 2, "z": 17, "name": "Rock_Lime_Brick_Smooth"}, {"x": 6, "y": 3, "z": 17, "name": "Rock_Lime_Brick_Smooth"}, {"x": 6, "y": 4, "z": 17, "name": "Rock_Lime_Brick_Smooth"}, {"x": 6, "y": 5, "z": 17, "name": "Rock_Calcite_Brick"}, {"x": 6, "y": 6, "z": 17, "name": "Rock_Calcite_Brick"}, {"x": 6, "y": -3, "z": 18, "name": "Soil_Dirt"}, {"x": 6, "y": -2, "z": 18, "name": "Soil_Dirt"}, {"x": 6, "y": -1, "z": 18, "name": "Soil_Dirt"}, {"x": 6, "y": 0, "z": 18, "name": "Wood_Softwood_Planks"}, {"x": 6, "y": 6, "z": 18, "name": "Rock_Calcite_Brick_Smooth_Half", "rotation": 8}, {"x": 6, "y": -3, "z": 19, "name": "Soil_Dirt"}, {"x": 6, "y": -2, "z": 19, "name": "Soil_Dirt"}, {"x": 6, "y": -1, "z": 19, "name": "Soil_Dirt"}, {"x": 6, "y": 0, "z": 19, "name": "Wood_Softwood_Planks"}, {"x": 6, "y": 6, "z": 19, "name": "Rock_Calcite_Brick_Smooth_Half", "rotation": 8}, {"x": 6, "y": -3, "z": 20, "name": "Soil_Dirt"}, {"x": 6, "y": -2, "z": 20, "name": "Soil_Dirt"}, {"x": 6, "y": -1, "z": 20, "name": "Soil_Dirt"}, {"x": 6, "y": 0, "z": 20, "name": "Wood_Softwood_Planks"}, {"x": 6, "y": 5, "z": 20, "name": "Build_Lightsource_White"}, {"x": 6, "y": 6, "z": 20, "name": "Rock_Calcite_Brick_Smooth_Half", "rotation": 8}, {"x": 6, "y": -3, "z": 21, "name": "Soil_Dirt"}, {"x": 6, "y": -2, "z": 21, "name": "Soil_Dirt"}, {"x": 6, "y": -1, "z": 21, "name": "Soil_Dirt"}, {"x": 6, "y": 0, "z": 21, "name": "Wood_Softwood_Planks"}, {"x": 6, "y": 6, "z": 21, "name": "Rock_Calcite_Brick_Smooth_Half", "rotation": 8}, {"x": 6, "y": -3, "z": 22, "name": "Soil_Dirt"}, {"x": 6, "y": -2, "z": 22, "name": "Soil_Dirt"}, {"x": 6, "y": -1, "z": 22, "name": "Soil_Dirt"}, {"x": 6, "y": 0, "z": 22, "name": "Wood_Softwood_Planks"}, {"x": 6, "y": 6, "z": 22, "name": "Rock_Calcite_Brick_Smooth_Half", "rotation": 8}, {"x": 6, "y": -3, "z": 23, "name": "Soil_Dirt"}, {"x": 6, "y": -2, "z": 23, "name": "Soil_Dirt"}, {"x": 6, "y": -1, "z": 23, "name": "Soil_Dirt"}, {"x": 6, "y": 0, "z": 23, "name": "Wood_Softwood_Planks"}, {"x": 6, "y": 6, "z": 23, "name": "Rock_Calcite_Brick_Smooth_Half", "rotation": 8}, {"x": 6, "y": -3, "z": 24, "name": "Soil_Dirt"}, {"x": 6, "y": -2, "z": 24, "name": "Soil_Dirt"}, {"x": 6, "y": -1, "z": 24, "name": "Soil_Dirt"}, {"x": 6, "y": 0, "z": 24, "name": "Wood_Softwood_Planks"}, {"x": 6, "y": 5, "z": 24, "name": "Build_Lightsource_White"}, {"x": 6, "y": 6, "z": 24, "name": "Rock_Calcite_Brick_Smooth_Half", "rotation": 8}, {"x": 6, "y": -3, "z": 25, "name": "Soil_Dirt"}, {"x": 6, "y": -2, "z": 25, "name": "Soil_Dirt"}, {"x": 6, "y": -1, "z": 25, "name": "Soil_Dirt"}, {"x": 6, "y": 0, "z": 25, "name": "Wood_Softwood_Planks"}, {"x": 6, "y": 6, "z": 25, "name": "Rock_Calcite_Brick_Smooth_Half", "rotation": 8}, {"x": 6, "y": -3, "z": 26, "name": "Soil_Dirt"}, {"x": 6, "y": -2, "z": 26, "name": "Soil_Dirt"}, {"x": 6, "y": -1, "z": 26, "name": "Soil_Dirt"}, {"x": 6, "y": 0, "z": 26, "name": "Wood_Softwood_Planks"}, {"x": 6, "y": 6, "z": 26, "name": "Rock_Calcite_Brick_Smooth_Half", "rotation": 8}, {"x": 6, "y": -3, "z": 27, "name": "Soil_Dirt"}, {"x": 6, "y": -2, "z": 27, "name": "Soil_Dirt"}, {"x": 6, "y": -1, "z": 27, "name": "Soil_Dirt"}, {"x": 6, "y": 0, "z": 27, "name": "Wood_Softwood_Planks"}, {"x": 6, "y": 6, "z": 27, "name": "Rock_Calcite_Brick_Smooth_Half", "rotation": 8}, {"x": 6, "y": -3, "z": 28, "name": "Soil_Dirt"}, {"x": 6, "y": -2, "z": 28, "name": "Soil_Dirt"}, {"x": 6, "y": -1, "z": 28, "name": "Soil_Dirt"}, {"x": 6, "y": 0, "z": 28, "name": "Wood_Softwood_Planks"}, {"x": 6, "y": 5, "z": 28, "name": "Build_Lightsource_White"}, {"x": 6, "y": 6, "z": 28, "name": "Rock_Calcite_Brick_Smooth_Half", "rotation": 8}, {"x": 6, "y": -3, "z": 29, "name": "Soil_Dirt"}, {"x": 6, "y": -2, "z": 29, "name": "Soil_Dirt"}, {"x": 6, "y": -1, "z": 29, "name": "Soil_Dirt"}, {"x": 6, "y": 0, "z": 29, "name": "Wood_Softwood_Planks"}, {"x": 6, "y": 6, "z": 29, "name": "Rock_Calcite_Brick_Smooth_Half", "rotation": 8}, {"x": 6, "y": -3, "z": 30, "name": "Soil_Dirt"}, {"x": 6, "y": -2, "z": 30, "name": "Soil_Dirt"}, {"x": 6, "y": -1, "z": 30, "name": "Soil_Dirt"}, {"x": 6, "y": 0, "z": 30, "name": "K2_Slot_Shelf_Chair"}, {"x": 6, "y": 6, "z": 30, "name": "Rock_Calcite_Brick_Smooth_Half", "rotation": 8}, {"x": 6, "y": -3, "z": 31, "name": "Soil_Dirt"}, {"x": 6, "y": -2, "z": 31, "name": "Soil_Dirt"}, {"x": 6, "y": -1, "z": 31, "name": "Soil_Dirt"}, {"x": 6, "y": 0, "z": 31, "name": "Soil_Dirt"}, {"x": 6, "y": 1, "z": 31, "name": "Rock_Calcite_Brick_Decorative"}, {"x": 6, "y": 2, "z": 31, "name": "Rock_Lime_Brick_Smooth"}, {"x": 6, "y": 3, "z": 31, "name": "Rock_Lime_Brick_Smooth"}, {"x": 6, "y": 4, "z": 31, "name": "Rock_Lime_Brick_Smooth"}, {"x": 6, "y": 5, "z": 31, "name": "Rock_Calcite_Brick"}, {"x": 6, "y": 6, "z": 31, "name": "Rock_Calcite_Brick"}, {"x": 7, "y": -3, "z": 0, "name": "Soil_Dirt"}, {"x": 7, "y": -2, "z": 0, "name": "Soil_Dirt"}, {"x": 7, "y": -1, "z": 0, "name": "Soil_Dirt"}, {"x": 7, "y": 0, "z": 0, "name": "Soil_Grass"}, {"x": 7, "y": -3, "z": 1, "name": "Soil_Dirt"}, {"x": 7, "y": -2, "z": 1, "name": "Soil_Dirt"}, {"x": 7, "y": -1, "z": 1, "name": "Soil_Dirt"}, {"x": 7, "y": 0, "z": 1, "name": "Soil_Grass"}, {"x": 7, "y": -3, "z": 2, "name": "Soil_Dirt"}, {"x": 7, "y": -2, "z": 2, "name": "Soil_Dirt"}, {"x": 7, "y": -1, "z": 2, "name": "Soil_Dirt"}, {"x": 7, "y": 0, "z": 2, "name": "Soil_Grass"}, {"x": 7, "y": -3, "z": 3, "name": "Soil_Dirt"}, {"x": 7, "y": -2, "z": 3, "name": "Soil_Dirt"}, {"x": 7, "y": -1, "z": 3, "name": "Soil_Dirt"}, {"x": 7, "y": 0, "z": 3, "name": "Soil_Grass"}, {"x": 7, "y": -3, "z": 4, "name": "Soil_Dirt"}, {"x": 7, "y": -2, "z": 4, "name": "Soil_Dirt"}, {"x": 7, "y": -1, "z": 4, "name": "Soil_Dirt"}, {"x": 7, "y": 0, "z": 4, "name": "Soil_Grass"}, {"x": 7, "y": -3, "z": 5, "name": "Soil_Dirt"}, {"x": 7, "y": -2, "z": 5, "name": "Soil_Dirt"}, {"x": 7, "y": -1, "z": 5, "name": "Soil_Dirt"}, {"x": 7, "y": 0, "z": 5, "name": "Soil_Grass"}, {"x": 7, "y": -3, "z": 6, "name": "Soil_Dirt"}, {"x": 7, "y": -2, "z": 6, "name": "Soil_Dirt"}, {"x": 7, "y": -1, "z": 6, "name": "Soil_Grass"}, {"x": 7, "y": -3, "z": 7, "name": "Soil_Dirt"}, {"x": 7, "y": -2, "z": 7, "name": "Soil_Dirt"}, {"x": 7, "y": -1, "z": 7, "name": "Soil_Grass"}, {"x": 7, "y": -3, "z": 8, "name": "Soil_Dirt"}, {"x": 7, "y": -2, "z": 8, "name": "Soil_Dirt"}, {"x": 7, "y": -1, "z": 8, "name": "Soil_Grass"}, {"x": 7, "y": -3, "z": 9, "name": "Soil_Dirt"}, {"x": 7, "y": -2, "z": 9, "name": "Soil_Dirt"}, {"x": 7, "y": -1, "z": 9, "name": "Soil_Grass"}, {"x": 7, "y": 1, "z": 9, "name": "Rock_Calcite_Brick_Decorative"}, {"x": 7, "y": 2, "z": 9, "name": "Rock_Lime_Brick_Smooth"}, {"x": 7, "y": 3, "z": 9, "name": "Rock_Lime_Brick_Smooth"}, {"x": 7, "y": 4, "z": 9, "name": "Rock_Lime_Brick_Smooth"}, {"x": 7, "y": 5, "z": 9, "name": "Rock_Calcite_Brick"}, {"x": 7, "y": 6, "z": 9, "name": "Rock_Calcite_Brick"}, {"x": 7, "y": -3, "z": 10, "name": "Soil_Dirt"}, {"x": 7, "y": -2, "z": 10, "name": "Soil_Dirt"}, {"x": 7, "y": -1, "z": 10, "name": "Soil_Dirt"}, {"x": 7, "y": 0, "z": 10, "name": "Wood_Softwood_Planks"}, {"x": 7, "y": 6, "z": 10, "name": "Rock_Calcite_Brick_Smooth_Half", "rotation": 8}, {"x": 7, "y": -3, "z": 11, "name": "Soil_Dirt"}, {"x": 7, "y": -2, "z": 11, "name": "Soil_Dirt"}, {"x": 7, "y": -1, "z": 11, "name": "Soil_Dirt"}, {"x": 7, "y": 0, "z": 11, "name": "Wood_Softwood_Planks"}, {"x": 7, "y": 6, "z": 11, "name": "Rock_Calcite_Brick_Smooth_Half", "rotation": 8}, {"x": 7, "y": -3, "z": 12, "name": "Soil_Dirt"}, {"x": 7, "y": -2, "z": 12, "name": "Soil_Dirt"}, {"x": 7, "y": -1, "z": 12, "name": "Soil_Dirt"}, {"x": 7, "y": 0, "z": 12, "name": "Wood_Softwood_Planks"}, {"x": 7, "y": 6, "z": 12, "name": "Rock_Calcite_Brick_Smooth_Half", "rotation": 8}, {"x": 7, "y": -3, "z": 13, "name": "Soil_Dirt"}, {"x": 7, "y": -2, "z": 13, "name": "Soil_Dirt"}, {"x": 7, "y": -1, "z": 13, "name": "Soil_Dirt"}, {"x": 7, "y": 0, "z": 13, "name": "Wood_Softwood_Planks"}, {"x": 7, "y": 6, "z": 13, "name": "Rock_Calcite_Brick_Smooth_Half", "rotation": 8}, {"x": 7, "y": -3, "z": 14, "name": "Soil_Dirt"}, {"x": 7, "y": -2, "z": 14, "name": "Soil_Dirt"}, {"x": 7, "y": -1, "z": 14, "name": "Soil_Dirt"}, {"x": 7, "y": 0, "z": 14, "name": "Wood_Softwood_Planks"}, {"x": 7, "y": 6, "z": 14, "name": "Rock_Calcite_Brick_Smooth_Half", "rotation": 8}, {"x": 7, "y": -3, "z": 15, "name": "Soil_Dirt"}, {"x": 7, "y": -2, "z": 15, "name": "Soil_Dirt"}, {"x": 7, "y": -1, "z": 15, "name": "Soil_Dirt"}, {"x": 7, "y": 0, "z": 15, "name": "Wood_Softwood_Planks"}, {"x": 7, "y": 6, "z": 15, "name": "Rock_Calcite_Brick_Smooth_Half", "rotation": 8}, {"x": 7, "y": -3, "z": 16, "name": "Soil_Dirt"}, {"x": 7, "y": -2, "z": 16, "name": "Soil_Dirt"}, {"x": 7, "y": -1, "z": 16, "name": "Soil_Dirt"}, {"x": 7, "y": 0, "z": 16, "name": "Wood_Softwood_Planks"}, {"x": 7, "y": 6, "z": 16, "name": "Rock_Calcite_Brick_Smooth_Half", "rotation": 8}, {"x": 7, "y": -3, "z": 17, "name": "Soil_Dirt"}, {"x": 7, "y": -2, "z": 17, "name": "Soil_Dirt"}, {"x": 7, "y": -1, "z": 17, "name": "Soil_Dirt"}, {"x": 7, "y": 0, "z": 17, "name": "Rock_Calcite_Brick_Smooth"}, {"x": 7, "y": 1, "z": 17, "name": "Rock_Calcite_Brick_Decorative"}, {"x": 7, "y": 2, "z": 17, "name": "Rock_Lime_Brick_Smooth"}, {"x": 7, "y": 3, "z": 17, "name": "Rock_Lime_Brick_Smooth"}, {"x": 7, "y": 4, "z": 17, "name": "Rock_Lime_Brick_Smooth"}, {"x": 7, "y": 5, "z": 17, "name": "Rock_Calcite_Brick"}, {"x": 7, "y": 6, "z": 17, "name": "Rock_Calcite_Brick"}, {"x": 7, "y": -3, "z": 18, "name": "Soil_Dirt"}, {"x": 7, "y": -2, "z": 18, "name": "Soil_Dirt"}, {"x": 7, "y": -1, "z": 18, "name": "Soil_Dirt"}, {"x": 7, "y": 0, "z": 18, "name": "Wood_Softwood_Planks"}, {"x": 7, "y": 6, "z": 18, "name": "Rock_Calcite_Brick_Smooth_Half", "rotation": 8}, {"x": 7, "y": -3, "z": 19, "name": "Soil_Dirt"}, {"x": 7, "y": -2, "z": 19, "name": "Soil_Dirt"}, {"x": 7, "y": -1, "z": 19, "name": "Soil_Dirt"}, {"x": 7, "y": 0, "z": 19, "name": "Wood_Softwood_Planks"}, {"x": 7, "y": 6, "z": 19, "name": "Rock_Calcite_Brick_Smooth_Half", "rotation": 8}, {"x": 7, "y": -3, "z": 20, "name": "Soil_Dirt"}, {"x": 7, "y": -2, "z": 20, "name": "Soil_Dirt"}, {"x": 7, "y": -1, "z": 20, "name": "Soil_Dirt"}, {"x": 7, "y": 0, "z": 20, "name": "Wood_Softwood_Planks"}, {"x": 7, "y": 6, "z": 20, "name": "Rock_Calcite_Brick_Smooth_Half", "rotation": 8}, {"x": 7, "y": -3, "z": 21, "name": "Soil_Dirt"}, {"x": 7, "y": -2, "z": 21, "name": "Soil_Dirt"}, {"x": 7, "y": -1, "z": 21, "name": "Soil_Dirt"}, {"x": 7, "y": 0, "z": 21, "name": "Wood_Softwood_Planks"}, {"x": 7, "y": 6, "z": 21, "name": "Rock_Calcite_Brick_Smooth_Half", "rotation": 8}, {"x": 7, "y": -3, "z": 22, "name": "Soil_Dirt"}, {"x": 7, "y": -2, "z": 22, "name": "Soil_Dirt"}, {"x": 7, "y": -1, "z": 22, "name": "Soil_Dirt"}, {"x": 7, "y": 0, "z": 22, "name": "Wood_Softwood_Planks"}, {"x": 7, "y": 6, "z": 22, "name": "Rock_Calcite_Brick_Smooth_Half", "rotation": 8}, {"x": 7, "y": -3, "z": 23, "name": "Soil_Dirt"}, {"x": 7, "y": -2, "z": 23, "name": "Soil_Dirt"}, {"x": 7, "y": -1, "z": 23, "name": "Soil_Dirt"}, {"x": 7, "y": 0, "z": 23, "name": "Wood_Softwood_Planks"}, {"x": 7, "y": 6, "z": 23, "name": "Rock_Calcite_Brick_Smooth_Half", "rotation": 8}, {"x": 7, "y": -3, "z": 24, "name": "Soil_Dirt"}, {"x": 7, "y": -2, "z": 24, "name": "Soil_Dirt"}, {"x": 7, "y": -1, "z": 24, "name": "Soil_Dirt"}, {"x": 7, "y": 0, "z": 24, "name": "Wood_Softwood_Planks"}, {"x": 7, "y": 6, "z": 24, "name": "Rock_Calcite_Brick_Smooth_Half", "rotation": 8}, {"x": 7, "y": -3, "z": 25, "name": "Soil_Dirt"}, {"x": 7, "y": -2, "z": 25, "name": "Soil_Dirt"}, {"x": 7, "y": -1, "z": 25, "name": "Soil_Dirt"}, {"x": 7, "y": 0, "z": 25, "name": "Wood_Softwood_Planks"}, {"x": 7, "y": 6, "z": 25, "name": "Rock_Calcite_Brick_Smooth_Half", "rotation": 8}, {"x": 7, "y": -3, "z": 26, "name": "Soil_Dirt"}, {"x": 7, "y": -2, "z": 26, "name": "Soil_Dirt"}, {"x": 7, "y": -1, "z": 26, "name": "Soil_Dirt"}, {"x": 7, "y": 0, "z": 26, "name": "Wood_Softwood_Planks"}, {"x": 7, "y": 6, "z": 26, "name": "Rock_Calcite_Brick_Smooth_Half", "rotation": 8}, {"x": 7, "y": -3, "z": 27, "name": "Soil_Dirt"}, {"x": 7, "y": -2, "z": 27, "name": "Soil_Dirt"}, {"x": 7, "y": -1, "z": 27, "name": "Soil_Dirt"}, {"x": 7, "y": 0, "z": 27, "name": "Wood_Softwood_Planks"}, {"x": 7, "y": 6, "z": 27, "name": "Rock_Calcite_Brick_Smooth_Half", "rotation": 8}, {"x": 7, "y": -3, "z": 28, "name": "Soil_Dirt"}, {"x": 7, "y": -2, "z": 28, "name": "Soil_Dirt"}, {"x": 7, "y": -1, "z": 28, "name": "Soil_Dirt"}, {"x": 7, "y": 0, "z": 28, "name": "Wood_Softwood_Planks"}, {"x": 7, "y": 6, "z": 28, "name": "Rock_Calcite_Brick_Smooth_Half", "rotation": 8}, {"x": 7, "y": -3, "z": 29, "name": "Soil_Dirt"}, {"x": 7, "y": -2, "z": 29, "name": "Soil_Dirt"}, {"x": 7, "y": -1, "z": 29, "name": "Soil_Dirt"}, {"x": 7, "y": 0, "z": 29, "name": "Wood_Softwood_Planks"}, {"x": 7, "y": 6, "z": 29, "name": "Rock_Calcite_Brick_Smooth_Half", "rotation": 8}, {"x": 7, "y": -3, "z": 30, "name": "Soil_Dirt"}, {"x": 7, "y": -2, "z": 30, "name": "Soil_Dirt"}, {"x": 7, "y": -1, "z": 30, "name": "Soil_Dirt"}, {"x": 7, "y": 0, "z": 30, "name": "K2_Slot_Shelf_Start_Coins"}, {"x": 7, "y": 6, "z": 30, "name": "Rock_Calcite_Brick_Smooth_Half", "rotation": 8}, {"x": 7, "y": -3, "z": 31, "name": "Soil_Dirt"}, {"x": 7, "y": -2, "z": 31, "name": "Soil_Dirt"}, {"x": 7, "y": -1, "z": 31, "name": "Soil_Dirt"}, {"x": 7, "y": 0, "z": 31, "name": "Soil_Dirt"}, {"x": 7, "y": 1, "z": 31, "name": "Rock_Calcite_Brick_Decorative"}, {"x": 7, "y": 2, "z": 31, "name": "Rock_Lime_Brick_Smooth"}, {"x": 7, "y": 3, "z": 31, "name": "Rock_Lime_Brick_Smooth"}, {"x": 7, "y": 4, "z": 31, "name": "Rock_Lime_Brick_Smooth"}, {"x": 7, "y": 5, "z": 31, "name": "Rock_Calcite_Brick"}, {"x": 7, "y": 6, "z": 31, "name": "Rock_Calcite_Brick"}, {"x": 8, "y": -3, "z": 0, "name": "Soil_Dirt"}, {"x": 8, "y": -2, "z": 0, "name": "Soil_Dirt"}, {"x": 8, "y": -1, "z": 0, "name": "Soil_Dirt"}, {"x": 8, "y": 0, "z": 0, "name": "Soil_Grass"}, {"x": 8, "y": -3, "z": 1, "name": "Soil_Dirt"}, {"x": 8, "y": -2, "z": 1, "name": "Soil_Dirt"}, {"x": 8, "y": -1, "z": 1, "name": "Soil_Dirt"}, {"x": 8, "y": 0, "z": 1, "name": "Soil_Grass"}, {"x": 8, "y": -3, "z": 2, "name": "Soil_Dirt"}, {"x": 8, "y": -2, "z": 2, "name": "Soil_Dirt"}, {"x": 8, "y": -1, "z": 2, "name": "Soil_Dirt"}, {"x": 8, "y": 0, "z": 2, "name": "Soil_Grass"}, {"x": 8, "y": -3, "z": 3, "name": "Soil_Dirt"}, {"x": 8, "y": -2, "z": 3, "name": "Soil_Dirt"}, {"x": 8, "y": -1, "z": 3, "name": "Soil_Dirt"}, {"x": 8, "y": 0, "z": 3, "name": "Soil_Grass"}, {"x": 8, "y": -3, "z": 4, "name": "Soil_Dirt"}, {"x": 8, "y": -2, "z": 4, "name": "Soil_Dirt"}, {"x": 8, "y": -1, "z": 4, "name": "Soil_Dirt"}, {"x": 8, "y": 0, "z": 4, "name": "Soil_Grass"}, {"x": 8, "y": -3, "z": 5, "name": "Soil_Dirt"}, {"x": 8, "y": -2, "z": 5, "name": "Soil_Dirt"}, {"x": 8, "y": -1, "z": 5, "name": "Soil_Dirt"}, {"x": 8, "y": 0, "z": 5, "name": "Soil_Grass"}, {"x": 8, "y": -3, "z": 6, "name": "Soil_Dirt"}, {"x": 8, "y": -2, "z": 6, "name": "Soil_Dirt"}, {"x": 8, "y": -1, "z": 6, "name": "Soil_Grass"}, {"x": 8, "y": -3, "z": 7, "name": "Soil_Dirt"}, {"x": 8, "y": -2, "z": 7, "name": "Soil_Dirt"}, {"x": 8, "y": -1, "z": 7, "name": "Soil_Grass"}, {"x": 8, "y": -3, "z": 8, "name": "Soil_Dirt"}, {"x": 8, "y": -2, "z": 8, "name": "Soil_Dirt"}, {"x": 8, "y": -1, "z": 8, "name": "Soil_Grass"}, {"x": 8, "y": -3, "z": 9, "name": "Soil_Dirt"}, {"x": 8, "y": -2, "z": 9, "name": "Soil_Dirt"}, {"x": 8, "y": -1, "z": 9, "name": "Soil_Grass"}, {"x": 8, "y": 1, "z": 9, "name": "Rock_Calcite_Brick_Decorative"}, {"x": 8, "y": 2, "z": 9, "name": "Rock_Lime_Brick_Smooth"}, {"x": 8, "y": 3, "z": 9, "name": "Rock_Lime_Brick_Smooth"}, {"x": 8, "y": 4, "z": 9, "name": "Rock_Lime_Brick_Smooth"}, {"x": 8, "y": 5, "z": 9, "name": "Rock_Calcite_Brick"}, {"x": 8, "y": -3, "z": 10, "name": "Soil_Dirt"}, {"x": 8, "y": -2, "z": 10, "name": "Soil_Dirt"}, {"x": 8, "y": -1, "z": 10, "name": "Soil_Dirt"}, {"x": 8, "y": 0, "z": 10, "name": "Rock_Calcite_Brick_Smooth"}, {"x": 8, "y": 6, "z": 10, "name": "Rock_Calcite_Brick_Smooth_Half"}, {"x": 8, "y": -3, "z": 11, "name": "Soil_Dirt"}, {"x": 8, "y": -2, "z": 11, "name": "Soil_Dirt"}, {"x": 8, "y": -1, "z": 11, "name": "Soil_Dirt"}, {"x": 8, "y": 0, "z": 11, "name": "K2_Slot_Shelf_Recipe_Meat_Pie"}, {"x": 8, "y": 6, "z": 11, "name": "Rock_Calcite_Brick_Smooth_Half"}, {"x": 8, "y": -3, "z": 12, "name": "Soil_Dirt"}, {"x": 8, "y": -2, "z": 12, "name": "Soil_Dirt"}, {"x": 8, "y": -1, "z": 12, "name": "Soil_Grass"}, {"x": 8, "y": 0, "z": 12, "name": "K2_Slot_Shelf_Recipe_Apple_Pie"}, {"x": 8, "y": 6, "z": 12, "name": "Rock_Calcite_Brick_Smooth_Half"}, {"x": 8, "y": -3, "z": 13, "name": "Soil_Dirt"}, {"x": 8, "y": -2, "z": 13, "name": "Soil_Dirt"}, {"x": 8, "y": -1, "z": 13, "name": "Soil_Dirt"}, {"x": 8, "y": 0, "z": 13, "name": "K2_Slot_Shelf_Recipe_Mushroom_Pie"}, {"x": 8, "y": 6, "z": 13, "name": "Rock_Calcite_Brick_Smooth_Half"}, {"x": 8, "y": -3, "z": 14, "name": "Soil_Dirt"}, {"x": 8, "y": -2, "z": 14, "name": "Soil_Dirt"}, {"x": 8, "y": -1, "z": 14, "name": "Soil_Grass"}, {"x": 8, "y": 0, "z": 14, "name": "K2_Slot_Shelf_Recipe_Pumpkin_Pie"}, {"x": 8, "y": 6, "z": 14, "name": "Rock_Calcite_Brick_Smooth_Half"}, {"x": 8, "y": -3, "z": 15, "name": "Soil_Dirt"}, {"x": 8, "y": -2, "z": 15, "name": "Soil_Dirt"}, {"x": 8, "y": -1, "z": 15, "name": "Soil_Grass"}, {"x": 8, "y": 0, "z": 15, "name": "K2_Slot_Shelf_Recipe_Mushroom_Kebab"}, {"x": 8, "y": 6, "z": 15, "name": "Rock_Calcite_Brick_Smooth_Half"}, {"x": 8, "y": -3, "z": 16, "name": "Soil_Dirt"}, {"x": 8, "y": -2, "z": 16, "name": "Soil_Dirt"}, {"x": 8, "y": -1, "z": 16, "name": "Soil_Dirt"}, {"x": 8, "y": 0, "z": 16, "name": "Rock_Calcite_Brick_Smooth"}, {"x": 8, "y": 6, "z": 16, "name": "Rock_Calcite_Brick_Smooth_Half"}, {"x": 8, "y": -3, "z": 17, "name": "Soil_Dirt"}, {"x": 8, "y": -2, "z": 17, "name": "Soil_Dirt"}, {"x": 8, "y": -1, "z": 17, "name": "Soil_Dirt"}, {"x": 8, "y": 0, "z": 17, "name": "Rock_Calcite_Brick_Smooth"}, {"x": 8, "y": 1, "z": 17, "name": "Rock_Calcite_Brick_Decorative"}, {"x": 8, "y": 2, "z": 17, "name": "Rock_Lime_Brick_Smooth"}, {"x": 8, "y": 3, "z": 17, "name": "Rock_Lime_Brick_Smooth"}, {"x": 8, "y": 4, "z": 17, "name": "Rock_Lime_Brick_Smooth"}, {"x": 8, "y": 5, "z": 17, "name": "Rock_Calcite_Brick"}, {"x": 8, "y": 6, "z": 17, "name": "Rock_Calcite_Brick"}, {"x": 8, "y": -3, "z": 18, "name": "Soil_Dirt"}, {"x": 8, "y": -2, "z": 18, "name": "Soil_Dirt"}, {"x": 8, "y": -1, "z": 18, "name": "Soil_Dirt"}, {"x": 8, "y": 0, "z": 18, "name": "Rock_Calcite_Brick_Smooth"}, {"x": 8, "y": 6, "z": 18, "name": "Rock_Calcite_Brick_Smooth_Half"}, {"x": 8, "y": -3, "z": 19, "name": "Soil_Dirt"}, {"x": 8, "y": -2, "z": 19, "name": "Soil_Dirt"}, {"x": 8, "y": -1, "z": 19, "name": "Soil_Dirt"}, {"x": 8, "y": 0, "z": 19, "name": "Rock_Calcite_Brick_Smooth"}, {"x": 8, "y": 6, "z": 19, "name": "Rock_Calcite_Brick_Smooth_Half"}, {"x": 8, "y": -3, "z": 20, "name": "Soil_Dirt"}, {"x": 8, "y": -2, "z": 20, "name": "Soil_Dirt"}, {"x": 8, "y": -1, "z": 20, "name": "Soil_Dirt"}, {"x": 8, "y": 0, "z": 20, "name": "Rock_Calcite_Brick_Smooth"}, {"x": 8, "y": 6, "z": 20, "name": "Rock_Calcite_Brick_Smooth_Half"}, {"x": 8, "y": -3, "z": 21, "name": "Soil_Dirt"}, {"x": 8, "y": -2, "z": 21, "name": "Soil_Dirt"}, {"x": 8, "y": -1, "z": 21, "name": "Soil_Dirt"}, {"x": 8, "y": 0, "z": 21, "name": "Rock_Calcite_Brick_Smooth"}, {"x": 8, "y": 6, "z": 21, "name": "Rock_Calcite_Brick_Smooth_Half"}, {"x": 8, "y": -3, "z": 22, "name": "Soil_Dirt"}, {"x": 8, "y": -2, "z": 22, "name": "Soil_Dirt"}, {"x": 8, "y": -1, "z": 22, "name": "Soil_Dirt"}, {"x": 8, "y": 0, "z": 22, "name": "Rock_Calcite_Brick_Smooth"}, {"x": 8, "y": 6, "z": 22, "name": "Rock_Calcite_Brick_Smooth_Half"}, {"x": 8, "y": -3, "z": 23, "name": "Soil_Dirt"}, {"x": 8, "y": -2, "z": 23, "name": "Soil_Dirt"}, {"x": 8, "y": -1, "z": 23, "name": "Soil_Dirt"}, {"x": 8, "y": 0, "z": 23, "name": "Rock_Calcite_Brick_Smooth"}, {"x": 8, "y": 6, "z": 23, "name": "Rock_Calcite_Brick_Smooth_Half"}, {"x": 8, "y": -3, "z": 24, "name": "Soil_Dirt"}, {"x": 8, "y": -2, "z": 24, "name": "Soil_Dirt"}, {"x": 8, "y": -1, "z": 24, "name": "Soil_Dirt"}, {"x": 8, "y": 0, "z": 24, "name": "Rock_Calcite_Brick_Smooth"}, {"x": 8, "y": 6, "z": 24, "name": "Rock_Calcite_Brick_Smooth_Half"}, {"x": 8, "y": -3, "z": 25, "name": "Soil_Dirt"}, {"x": 8, "y": -2, "z": 25, "name": "Soil_Dirt"}, {"x": 8, "y": -1, "z": 25, "name": "Soil_Dirt"}, {"x": 8, "y": 0, "z": 25, "name": "Rock_Calcite_Brick_Smooth"}, {"x": 8, "y": 6, "z": 25, "name": "Rock_Calcite_Brick_Smooth_Half"}, {"x": 8, "y": -3, "z": 26, "name": "Soil_Dirt"}, {"x": 8, "y": -2, "z": 26, "name": "Soil_Dirt"}, {"x": 8, "y": -1, "z": 26, "name": "Soil_Dirt"}, {"x": 8, "y": 0, "z": 26, "name": "Rock_Calcite_Brick_Smooth"}, {"x": 8, "y": 6, "z": 26, "name": "Rock_Calcite_Brick_Smooth_Half"}, {"x": 8, "y": -3, "z": 27, "name": "Soil_Dirt"}, {"x": 8, "y": -2, "z": 27, "name": "Soil_Dirt"}, {"x": 8, "y": -1, "z": 27, "name": "Soil_Dirt"}, {"x": 8, "y": 0, "z": 27, "name": "Rock_Calcite_Brick_Smooth"}, {"x": 8, "y": 6, "z": 27, "name": "Rock_Calcite_Brick_Smooth_Half"}, {"x": 8, "y": -3, "z": 28, "name": "Soil_Dirt"}, {"x": 8, "y": -2, "z": 28, "name": "Soil_Dirt"}, {"x": 8, "y": -1, "z": 28, "name": "Soil_Dirt"}, {"x": 8, "y": 0, "z": 28, "name": "Rock_Calcite_Brick_Smooth"}, {"x": 8, "y": 6, "z": 28, "name": "Rock_Calcite_Brick_Smooth_Half"}, {"x": 8, "y": -3, "z": 29, "name": "Soil_Dirt"}, {"x": 8, "y": -2, "z": 29, "name": "Soil_Dirt"}, {"x": 8, "y": -1, "z": 29, "name": "Soil_Dirt"}, {"x": 8, "y": 0, "z": 29, "name": "Rock_Calcite_Brick_Smooth"}, {"x": 8, "y": 6, "z": 29, "name": "Rock_Calcite_Brick_Smooth_Half"}, {"x": 8, "y": -3, "z": 30, "name": "Soil_Dirt"}, {"x": 8, "y": -2, "z": 30, "name": "Soil_Dirt"}, {"x": 8, "y": -1, "z": 30, "name": "Soil_Dirt"}, {"x": 8, "y": 0, "z": 30, "name": "Rock_Calcite_Brick_Smooth"}, {"x": 8, "y": 6, "z": 30, "name": "Rock_Calcite_Brick_Smooth_Half"}, {"x": 8, "y": -3, "z": 31, "name": "Soil_Dirt"}, {"x": 8, "y": -2, "z": 31, "name": "Soil_Dirt"}, {"x": 8, "y": -1, "z": 31, "name": "Soil_Dirt"}, {"x": 8, "y": 0, "z": 31, "name": "Soil_Dirt"}, {"x": 8, "y": 1, "z": 31, "name": "Rock_Calcite_Brick_Decorative"}, {"x": 8, "y": 2, "z": 31, "name": "Rock_Lime_Brick_Smooth"}, {"x": 8, "y": 3, "z": 31, "name": "Rock_Lime_Brick_Smooth"}, {"x": 8, "y": 4, "z": 31, "name": "Rock_Lime_Brick_Smooth"}, {"x": 8, "y": 5, "z": 31, "name": "Rock_Calcite_Brick"}, {"x": 8, "y": 6, "z": 31, "name": "Rock_Calcite_Brick"}, {"x": 9, "y": -3, "z": 0, "name": "Soil_Dirt"}, {"x": 9, "y": -2, "z": 0, "name": "Soil_Dirt"}, {"x": 9, "y": -1, "z": 0, "name": "Soil_Dirt"}, {"x": 9, "y": 0, "z": 0, "name": "Soil_Grass"}, {"x": 9, "y": -3, "z": 1, "name": "Soil_Dirt"}, {"x": 9, "y": -2, "z": 1, "name": "Soil_Dirt"}, {"x": 9, "y": -1, "z": 1, "name": "Soil_Dirt"}, {"x": 9, "y": 0, "z": 1, "name": "Soil_Grass"}, {"x": 9, "y": -3, "z": 2, "name": "Soil_Dirt"}, {"x": 9, "y": -2, "z": 2, "name": "Soil_Dirt"}, {"x": 9, "y": -1, "z": 2, "name": "Soil_Dirt"}, {"x": 9, "y": 0, "z": 2, "name": "Soil_Grass"}, {"x": 9, "y": -3, "z": 3, "name": "Soil_Dirt"}, {"x": 9, "y": -2, "z": 3, "name": "Soil_Dirt"}, {"x": 9, "y": -1, "z": 3, "name": "Soil_Dirt"}, {"x": 9, "y": 0, "z": 3, "name": "Soil_Grass"}, {"x": 9, "y": -3, "z": 4, "name": "Soil_Dirt"}, {"x": 9, "y": -2, "z": 4, "name": "Soil_Dirt"}, {"x": 9, "y": -1, "z": 4, "name": "Soil_Dirt"}, {"x": 9, "y": 0, "z": 4, "name": "Soil_Grass"}, {"x": 9, "y": -3, "z": 5, "name": "Soil_Dirt"}, {"x": 9, "y": -2, "z": 5, "name": "Soil_Dirt"}, {"x": 9, "y": -1, "z": 5, "name": "Soil_Dirt"}, {"x": 9, "y": 0, "z": 5, "name": "Soil_Grass"}, {"x": 9, "y": -3, "z": 6, "name": "Soil_Dirt"}, {"x": 9, "y": -2, "z": 6, "name": "Soil_Dirt"}, {"x": 9, "y": -1, "z": 6, "name": "Soil_Grass"}, {"x": 9, "y": -3, "z": 7, "name": "Soil_Dirt"}, {"x": 9, "y": -2, "z": 7, "name": "Soil_Dirt"}, {"x": 9, "y": -1, "z": 7, "name": "Soil_Grass"}, {"x": 9, "y": -3, "z": 8, "name": "Soil_Dirt"}, {"x": 9, "y": -2, "z": 8, "name": "Soil_Dirt"}, {"x": 9, "y": -1, "z": 8, "name": "Soil_Grass"}, {"x": 9, "y": -3, "z": 9, "name": "Soil_Dirt"}, {"x": 9, "y": -2, "z": 9, "name": "Soil_Dirt"}, {"x": 9, "y": -1, "z": 9, "name": "Soil_Grass"}, {"x": 9, "y": -3, "z": 10, "name": "Soil_Dirt"}, {"x": 9, "y": -2, "z": 10, "name": "Soil_Dirt"}, {"x": 9, "y": -1, "z": 10, "name": "Soil_Grass"}, {"x": 9, "y": 1, "z": 10, "name": "Rock_Calcite_Brick_Decorative"}, {"x": 9, "y": 2, "z": 10, "name": "Rock_Lime_Brick_Smooth"}, {"x": 9, "y": 3, "z": 10, "name": "Rock_Lime_Brick_Smooth"}, {"x": 9, "y": 4, "z": 10, "name": "Rock_Lime_Brick_Smooth"}, {"x": 9, "y": 5, "z": 10, "name": "Rock_Calcite_Brick"}, {"x": 9, "y": -3, "z": 11, "name": "Soil_Dirt"}, {"x": 9, "y": -2, "z": 11, "name": "Soil_Dirt"}, {"x": 9, "y": -1, "z": 11, "name": "Soil_Grass"}, {"x": 9, "y": 1, "z": 11, "name": "Rock_Calcite_Brick_Decorative"}, {"x": 9, "y": 2, "z": 11, "name": "Rock_Lime_Brick_Smooth"}, {"x": 9, "y": 3, "z": 11, "name": "Rock_Lime_Brick_Smooth"}, {"x": 9, "y": 4, "z": 11, "name": "Rock_Lime_Brick_Smooth"}, {"x": 9, "y": 5, "z": 11, "name": "Rock_Calcite_Brick"}, {"x": 9, "y": -3, "z": 12, "name": "Soil_Dirt"}, {"x": 9, "y": -2, "z": 12, "name": "Soil_Dirt"}, {"x": 9, "y": -1, "z": 12, "name": "Soil_Grass"}, {"x": 9, "y": 1, "z": 12, "name": "Rock_Calcite_Brick_Decorative"}, {"x": 9, "y": 2, "z": 12, "name": "Rock_Lime_Brick_Smooth"}, {"x": 9, "y": 3, "z": 12, "name": "Rock_Lime_Brick_Smooth"}, {"x": 9, "y": 4, "z": 12, "name": "Rock_Lime_Brick_Smooth"}, {"x": 9, "y": 5, "z": 12, "name": "Rock_Calcite_Brick"}, {"x": 9, "y": -3, "z": 13, "name": "Soil_Dirt"}, {"x": 9, "y": -2, "z": 13, "name": "Soil_Dirt"}, {"x": 9, "y": -1, "z": 13, "name": "Soil_Grass"}, {"x": 9, "y": 1, "z": 13, "name": "Rock_Calcite_Brick_Decorative"}, {"x": 9, "y": 2, "z": 13, "name": "Rock_Lime_Brick_Smooth"}, {"x": 9, "y": 3, "z": 13, "name": "Rock_Lime_Brick_Smooth"}, {"x": 9, "y": 4, "z": 13, "name": "Rock_Lime_Brick_Smooth"}, {"x": 9, "y": 5, "z": 13, "name": "Rock_Calcite_Brick"}, {"x": 9, "y": -3, "z": 14, "name": "Soil_Dirt"}, {"x": 9, "y": -2, "z": 14, "name": "Soil_Dirt"}, {"x": 9, "y": -1, "z": 14, "name": "Soil_Grass"}, {"x": 9, "y": 1, "z": 14, "name": "Rock_Calcite_Brick_Decorative"}, {"x": 9, "y": 2, "z": 14, "name": "Rock_Lime_Brick_Smooth"}, {"x": 9, "y": 3, "z": 14, "name": "Rock_Lime_Brick_Smooth"}, {"x": 9, "y": 4, "z": 14, "name": "Rock_Lime_Brick_Smooth"}, {"x": 9, "y": 5, "z": 14, "name": "Rock_Calcite_Brick"}, {"x": 9, "y": -3, "z": 15, "name": "Soil_Dirt"}, {"x": 9, "y": -2, "z": 15, "name": "Soil_Dirt"}, {"x": 9, "y": -1, "z": 15, "name": "Soil_Grass"}, {"x": 9, "y": 1, "z": 15, "name": "Rock_Calcite_Brick_Decorative"}, {"x": 9, "y": 2, "z": 15, "name": "Rock_Lime_Brick_Smooth"}, {"x": 9, "y": 3, "z": 15, "name": "Rock_Lime_Brick_Smooth"}, {"x": 9, "y": 4, "z": 15, "name": "Rock_Lime_Brick_Smooth"}, {"x": 9, "y": 5, "z": 15, "name": "Rock_Calcite_Brick"}, {"x": 9, "y": -3, "z": 16, "name": "Soil_Dirt"}, {"x": 9, "y": -2, "z": 16, "name": "Soil_Dirt"}, {"x": 9, "y": -1, "z": 16, "name": "Soil_Grass"}, {"x": 9, "y": 1, "z": 16, "name": "Rock_Calcite_Brick_Decorative"}, {"x": 9, "y": 2, "z": 16, "name": "Rock_Lime_Brick_Smooth"}, {"x": 9, "y": 3, "z": 16, "name": "Rock_Lime_Brick_Smooth"}, {"x": 9, "y": 4, "z": 16, "name": "Rock_Lime_Brick_Smooth"}, {"x": 9, "y": 5, "z": 16, "name": "Rock_Calcite_Brick"}, {"x": 9, "y": -3, "z": 17, "name": "Soil_Dirt"}, {"x": 9, "y": -2, "z": 17, "name": "Soil_Dirt"}, {"x": 9, "y": -1, "z": 17, "name": "Soil_Grass"}, {"x": 9, "y": -3, "z": 18, "name": "Soil_Dirt"}, {"x": 9, "y": -2, "z": 18, "name": "Soil_Dirt"}, {"x": 9, "y": -1, "z": 18, "name": "Soil_Grass"}, {"x": 9, "y": 1, "z": 18, "name": "Rock_Calcite_Brick_Decorative"}, {"x": 9, "y": 2, "z": 18, "name": "Rock_Lime_Brick_Smooth"}, {"x": 9, "y": 3, "z": 18, "name": "Rock_Lime_Brick_Smooth"}, {"x": 9, "y": 4, "z": 18, "name": "Rock_Lime_Brick_Smooth"}, {"x": 9, "y": 5, "z": 18, "name": "Rock_Calcite_Brick"}, {"x": 9, "y": -3, "z": 19, "name": "Soil_Dirt"}, {"x": 9, "y": -2, "z": 19, "name": "Soil_Dirt"}, {"x": 9, "y": -1, "z": 19, "name": "Soil_Dirt"}, {"x": 9, "y": 0, "z": 19, "name": "Soil_Dirt"}, {"x": 9, "y": 1, "z": 19, "name": "Rock_Calcite_Brick_Decorative"}, {"x": 9, "y": 2, "z": 19, "name": "Rock_Lime_Brick_Smooth"}, {"x": 9, "y": 3, "z": 19, "name": "Rock_Lime_Brick_Smooth"}, {"x": 9, "y": 4, "z": 19, "name": "Rock_Lime_Brick_Smooth"}, {"x": 9, "y": 5, "z": 19, "name": "Rock_Calcite_Brick"}, {"x": 9, "y": -3, "z": 20, "name": "Soil_Dirt"}, {"x": 9, "y": -2, "z": 20, "name": "Soil_Dirt"}, {"x": 9, "y": -1, "z": 20, "name": "Soil_Dirt"}, {"x": 9, "y": 0, "z": 20, "name": "Soil_Dirt"}, {"x": 9, "y": 1, "z": 20, "name": "Rock_Calcite_Brick_Decorative"}, {"x": 9, "y": 2, "z": 20, "name": "Rock_Lime_Brick_Smooth"}, {"x": 9, "y": 3, "z": 20, "name": "Rock_Lime_Brick_Smooth"}, {"x": 9, "y": 4, "z": 20, "name": "Rock_Lime_Brick_Smooth"}, {"x": 9, "y": 5, "z": 20, "name": "Rock_Calcite_Brick"}, {"x": 9, "y": -3, "z": 21, "name": "Soil_Dirt"}, {"x": 9, "y": -2, "z": 21, "name": "Soil_Dirt"}, {"x": 9, "y": -1, "z": 21, "name": "Soil_Dirt"}, {"x": 9, "y": 0, "z": 21, "name": "Soil_Dirt"}, {"x": 9, "y": 1, "z": 21, "name": "Rock_Calcite_Brick_Decorative"}, {"x": 9, "y": 2, "z": 21, "name": "Rock_Lime_Brick_Smooth"}, {"x": 9, "y": 3, "z": 21, "name": "Rock_Lime_Brick_Smooth"}, {"x": 9, "y": 4, "z": 21, "name": "Rock_Lime_Brick_Smooth"}, {"x": 9, "y": 5, "z": 21, "name": "Rock_Calcite_Brick"}, {"x": 9, "y": -3, "z": 22, "name": "Soil_Dirt"}, {"x": 9, "y": -2, "z": 22, "name": "Soil_Dirt"}, {"x": 9, "y": -1, "z": 22, "name": "Soil_Dirt"}, {"x": 9, "y": 0, "z": 22, "name": "Rock_Calcite_Brick_Smooth"}, {"x": 9, "y": 5, "z": 22, "name": "Rock_Calcite_Brick"}, {"x": 9, "y": -3, "z": 23, "name": "Soil_Dirt"}, {"x": 9, "y": -2, "z": 23, "name": "Soil_Dirt"}, {"x": 9, "y": -1, "z": 23, "name": "Soil_Dirt"}, {"x": 9, "y": 0, "z": 23, "name": "Rock_Calcite_Brick_Smooth"}, {"x": 9, "y": 5, "z": 23, "name": "Rock_Calcite_Brick"}, {"x": 9, "y": -3, "z": 24, "name": "Soil_Dirt"}, {"x": 9, "y": -2, "z": 24, "name": "Soil_Dirt"}, {"x": 9, "y": -1, "z": 24, "name": "Soil_Dirt"}, {"x": 9, "y": 0, "z": 24, "name": "Rock_Calcite_Brick_Smooth"}, {"x": 9, "y": 5, "z": 24, "name": "Rock_Calcite_Brick"}, {"x": 9, "y": 6, "z": 24, "name": "Rock_Calcite_Brick_Smooth_Half"}, {"x": 9, "y": -3, "z": 25, "name": "Soil_Dirt"}, {"x": 9, "y": -2, "z": 25, "name": "Soil_Dirt"}, {"x": 9, "y": -1, "z": 25, "name": "Soil_Dirt"}, {"x": 9, "y": 0, "z": 25, "name": "Rock_Calcite_Brick_Smooth"}, {"x": 9, "y": 5, "z": 25, "name": "Rock_Calcite_Brick"}, {"x": 9, "y": -3, "z": 26, "name": "Soil_Dirt"}, {"x": 9, "y": -2, "z": 26, "name": "Soil_Dirt"}, {"x": 9, "y": -1, "z": 26, "name": "Soil_Dirt"}, {"x": 9, "y": 0, "z": 26, "name": "Soil_Dirt"}, {"x": 9, "y": 1, "z": 26, "name": "Rock_Calcite_Brick_Decorative"}, {"x": 9, "y": 2, "z": 26, "name": "Rock_Lime_Brick_Smooth"}, {"x": 9, "y": 3, "z": 26, "name": "Rock_Lime_Brick_Smooth"}, {"x": 9, "y": 4, "z": 26, "name": "Rock_Lime_Brick_Smooth"}, {"x": 9, "y": 5, "z": 26, "name": "Rock_Calcite_Brick"}, {"x": 9, "y": -3, "z": 27, "name": "Soil_Dirt"}, {"x": 9, "y": -2, "z": 27, "name": "Soil_Dirt"}, {"x": 9, "y": -1, "z": 27, "name": "Soil_Dirt"}, {"x": 9, "y": 0, "z": 27, "name": "Soil_Dirt"}, {"x": 9, "y": 1, "z": 27, "name": "Rock_Calcite_Brick_Decorative"}, {"x": 9, "y": 2, "z": 27, "name": "Rock_Lime_Brick_Smooth"}, {"x": 9, "y": 3, "z": 27, "name": "Rock_Lime_Brick_Smooth"}, {"x": 9, "y": 4, "z": 27, "name": "Rock_Lime_Brick_Smooth"}, {"x": 9, "y": 5, "z": 27, "name": "Rock_Calcite_Brick"}, {"x": 9, "y": -3, "z": 28, "name": "Soil_Dirt"}, {"x": 9, "y": -2, "z": 28, "name": "Soil_Dirt"}, {"x": 9, "y": -1, "z": 28, "name": "Soil_Dirt"}, {"x": 9, "y": 0, "z": 28, "name": "Soil_Dirt"}, {"x": 9, "y": 1, "z": 28, "name": "Rock_Calcite_Brick_Decorative"}, {"x": 9, "y": 2, "z": 28, "name": "Rock_Lime_Brick_Smooth"}, {"x": 9, "y": 3, "z": 28, "name": "Rock_Lime_Brick_Smooth"}, {"x": 9, "y": 4, "z": 28, "name": "Rock_Lime_Brick_Smooth"}, {"x": 9, "y": 5, "z": 28, "name": "Rock_Calcite_Brick"}, {"x": 9, "y": -3, "z": 29, "name": "Soil_Dirt"}, {"x": 9, "y": -2, "z": 29, "name": "Soil_Dirt"}, {"x": 9, "y": -1, "z": 29, "name": "Soil_Dirt"}, {"x": 9, "y": 0, "z": 29, "name": "Soil_Dirt"}, {"x": 9, "y": 1, "z": 29, "name": "Rock_Calcite_Brick_Decorative"}, {"x": 9, "y": 2, "z": 29, "name": "Rock_Lime_Brick_Smooth"}, {"x": 9, "y": 3, "z": 29, "name": "Rock_Lime_Brick_Smooth"}, {"x": 9, "y": 4, "z": 29, "name": "Rock_Lime_Brick_Smooth"}, {"x": 9, "y": 5, "z": 29, "name": "Rock_Calcite_Brick"}, {"x": 9, "y": -3, "z": 30, "name": "Soil_Dirt"}, {"x": 9, "y": -2, "z": 30, "name": "Soil_Dirt"}, {"x": 9, "y": -1, "z": 30, "name": "Soil_Dirt"}, {"x": 9, "y": 0, "z": 30, "name": "Soil_Dirt"}, {"x": 9, "y": 1, "z": 30, "name": "Rock_Calcite_Brick_Decorative"}, {"x": 9, "y": 2, "z": 30, "name": "Rock_Lime_Brick_Smooth"}, {"x": 9, "y": 3, "z": 30, "name": "Rock_Lime_Brick_Smooth"}, {"x": 9, "y": 4, "z": 30, "name": "Rock_Lime_Brick_Smooth"}, {"x": 9, "y": 5, "z": 30, "name": "Rock_Calcite_Brick"}, {"x": 9, "y": -3, "z": 31, "name": "Soil_Dirt"}, {"x": 9, "y": -2, "z": 31, "name": "Soil_Dirt"}, {"x": 9, "y": -1, "z": 31, "name": "Soil_Dirt"}, {"x": 9, "y": 0, "z": 31, "name": "Soil_Grass"}, {"x": 10, "y": -3, "z": 0, "name": "Soil_Dirt"}, {"x": 10, "y": -2, "z": 0, "name": "Soil_Dirt"}, {"x": 10, "y": -1, "z": 0, "name": "Soil_Dirt"}, {"x": 10, "y": 0, "z": 0, "name": "Soil_Grass"}, {"x": 10, "y": -3, "z": 1, "name": "Soil_Dirt"}, {"x": 10, "y": -2, "z": 1, "name": "Soil_Dirt"}, {"x": 10, "y": -1, "z": 1, "name": "Soil_Dirt"}, {"x": 10, "y": 0, "z": 1, "name": "Soil_Grass"}, {"x": 10, "y": -3, "z": 2, "name": "Soil_Dirt"}, {"x": 10, "y": -2, "z": 2, "name": "Soil_Dirt"}, {"x": 10, "y": -1, "z": 2, "name": "Soil_Dirt"}, {"x": 10, "y": 0, "z": 2, "name": "Soil_Grass"}, {"x": 10, "y": -3, "z": 3, "name": "Soil_Dirt"}, {"x": 10, "y": -2, "z": 3, "name": "Soil_Dirt"}, {"x": 10, "y": -1, "z": 3, "name": "Soil_Dirt"}, {"x": 10, "y": 0, "z": 3, "name": "Soil_Grass"}, {"x": 10, "y": -3, "z": 4, "name": "Soil_Dirt"}, {"x": 10, "y": -2, "z": 4, "name": "Soil_Dirt"}, {"x": 10, "y": -1, "z": 4, "name": "Soil_Dirt"}, {"x": 10, "y": 0, "z": 4, "name": "Soil_Grass"}, {"x": 10, "y": -3, "z": 5, "name": "Soil_Dirt"}, {"x": 10, "y": -2, "z": 5, "name": "Soil_Dirt"}, {"x": 10, "y": -1, "z": 5, "name": "Soil_Dirt"}, {"x": 10, "y": 0, "z": 5, "name": "Soil_Grass"}, {"x": 10, "y": -3, "z": 6, "name": "Soil_Dirt"}, {"x": 10, "y": -2, "z": 6, "name": "Soil_Dirt"}, {"x": 10, "y": -1, "z": 6, "name": "Soil_Grass"}, {"x": 10, "y": -3, "z": 7, "name": "Soil_Dirt"}, {"x": 10, "y": -2, "z": 7, "name": "Soil_Dirt"}, {"x": 10, "y": -1, "z": 7, "name": "Soil_Grass"}, {"x": 10, "y": -3, "z": 8, "name": "Soil_Dirt"}, {"x": 10, "y": -2, "z": 8, "name": "Soil_Dirt"}, {"x": 10, "y": -1, "z": 8, "name": "Soil_Grass"}, {"x": 10, "y": -3, "z": 9, "name": "Soil_Dirt"}, {"x": 10, "y": -2, "z": 9, "name": "Soil_Dirt"}, {"x": 10, "y": -1, "z": 9, "name": "Soil_Grass"}, {"x": 10, "y": -3, "z": 10, "name": "Soil_Dirt"}, {"x": 10, "y": -2, "z": 10, "name": "Soil_Dirt"}, {"x": 10, "y": -1, "z": 10, "name": "Soil_Grass"}, {"x": 10, "y": -3, "z": 11, "name": "Soil_Dirt"}, {"x": 10, "y": -2, "z": 11, "name": "Soil_Dirt"}, {"x": 10, "y": -1, "z": 11, "name": "Soil_Grass"}, {"x": 10, "y": -3, "z": 12, "name": "Soil_Dirt"}, {"x": 10, "y": -2, "z": 12, "name": "Soil_Dirt"}, {"x": 10, "y": -1, "z": 12, "name": "Soil_Grass"}, {"x": 10, "y": -3, "z": 13, "name": "Soil_Dirt"}, {"x": 10, "y": -2, "z": 13, "name": "Soil_Dirt"}, {"x": 10, "y": -1, "z": 13, "name": "Soil_Grass"}, {"x": 10, "y": -3, "z": 14, "name": "Soil_Dirt"}, {"x": 10, "y": -2, "z": 14, "name": "Soil_Dirt"}, {"x": 10, "y": -1, "z": 14, "name": "Soil_Grass"}, {"x": 10, "y": -3, "z": 15, "name": "Soil_Dirt"}, {"x": 10, "y": -2, "z": 15, "name": "Soil_Dirt"}, {"x": 10, "y": -1, "z": 15, "name": "Soil_Grass"}, {"x": 10, "y": -3, "z": 16, "name": "Soil_Dirt"}, {"x": 10, "y": -2, "z": 16, "name": "Soil_Dirt"}, {"x": 10, "y": -1, "z": 16, "name": "Soil_Grass"}, {"x": 10, "y": -3, "z": 17, "name": "Soil_Dirt"}, {"x": 10, "y": -2, "z": 17, "name": "Soil_Dirt"}, {"x": 10, "y": -1, "z": 17, "name": "Soil_Grass"}, {"x": 10, "y": -3, "z": 18, "name": "Soil_Dirt"}, {"x": 10, "y": -2, "z": 18, "name": "Soil_Dirt"}, {"x": 10, "y": -1, "z": 18, "name": "Soil_Grass"}, {"x": 10, "y": -3, "z": 19, "name": "Soil_Dirt"}, {"x": 10, "y": -2, "z": 19, "name": "Soil_Dirt"}, {"x": 10, "y": -1, "z": 19, "name": "Soil_Dirt"}, {"x": 10, "y": 0, "z": 19, "name": "Soil_Grass"}, {"x": 10, "y": -3, "z": 20, "name": "Soil_Dirt"}, {"x": 10, "y": -2, "z": 20, "name": "Soil_Dirt"}, {"x": 10, "y": -1, "z": 20, "name": "Soil_Dirt"}, {"x": 10, "y": 0, "z": 20, "name": "Soil_Dirt"}, {"x": 10, "y": 1, "z": 20, "name": "Rock_Calcite_Brick_Decorative"}, {"x": 10, "y": 2, "z": 20, "name": "Rock_Lime_Brick_Smooth"}, {"x": 10, "y": 3, "z": 20, "name": "Rock_Lime_Brick_Smooth"}, {"x": 10, "y": 4, "z": 20, "name": "Rock_Lime_Brick_Smooth"}, {"x": 10, "y": 5, "z": 20, "name": "Rock_Calcite_Brick"}, {"x": 10, "y": -3, "z": 21, "name": "Soil_Dirt"}, {"x": 10, "y": -2, "z": 21, "name": "Soil_Dirt"}, {"x": 10, "y": -1, "z": 21, "name": "Soil_Dirt"}, {"x": 10, "y": 0, "z": 21, "name": "Rock_Calcite_Brick_Smooth"}, {"x": 10, "y": 5, "z": 21, "name": "Rock_Calcite_Brick_Smooth_Half", "rotation": 8}, {"x": 10, "y": -3, "z": 22, "name": "Soil_Dirt"}, {"x": 10, "y": -2, "z": 22, "name": "Soil_Dirt"}, {"x": 10, "y": -1, "z": 22, "name": "Soil_Dirt"}, {"x": 10, "y": 0, "z": 22, "name": "Rock_Calcite_Brick_Smooth"},