{"version": 8, "blockIdVersion": 11, "anchorX": 0, "anchorY": 0, "anchorZ": 0, "blocks": [{"x": 0, "y": 0, "z": 0, "name": "Soil_Grass"}, {"x": 0, "y": 0, "z": 1, "name": "Soil_Grass"}, {"x": 0, "y": 0, "z": 2, "name": "Soil_Grass"}, {"x": 0, "y": 0, "z": 3, "name": "Soil_Grass"}, {"x": 0, "y": 0, "z": 4, "name": "Soil_Grass"}, {"x": 0, "y": 0, "z": 5, "name": "Soil_Grass"}, {"x": 0, "y": 0, "z": 6, "name": "Soil_Grass"}, {"x": 0, "y": 0, "z": 7, "name": "Soil_Grass"}, {"x": 0, "y": 0, "z": 8, "name": "Soil_Grass"}, {"x": 0, "y": 0, "z": 9, "name": "Soil_Grass"}, {"x": 0, "y": 0, "z": 10, "name": "Soil_Grass"}, {"x": 0, "y": 0, "z": 11, "name": "Soil_Grass"}, {"x": 0, "y": 0, "z": 12, "name": "Soil_Grass"}, {"x": 0, "y": 7, "z": 12, "name": "Plant_Leaves_Beech"}, {"x": 0, "y": 8, "z": 12, "name": "Plant_Leaves_Beech"}, {"x": 0, "y": 0, "z": 13, "name": "Soil_Grass"}, {"x": 0, "y": 7, "z": 13, "name": "Plant_Leaves_Beech"}, {"x": 0, "y": 8, "z": 13, "name": "Plant_Leaves_Beech"}, {"x": 0, "y": 11, "z": 13, "name": "Plant_Leaves_Beech"}, {"x": 0, "y": 0, "z": 14, "name": "Soil_Grass"}, {"x": 0, "y": 7, "z": 14, "name": "Plant_Leaves_Beech"}, {"x": 0, "y": 8, "z": 14, "name": "Plant_Leaves_Beech"}, {"x": 0, "y": 9, "z": 14, "name": "Plant_Leaves_Beech"}, {"x": 0, "y": 11, "z": 14, "name": "Plant_Leaves_Beech"}, {"x": 0, "y": 12, "z": 14, "name": "Plant_Leaves_Beech"}, {"x": 0, "y": 0, "z": 15, "name": "Soil_Grass"}, {"x": 0, "y": 7, "z": 15, "name": "Wood_Beech_Branch_Corner", "rotation": 3}, {"x": 0, "y": 8, "z": 15, "name": "Plant_Leaves_Beech"}, {"x": 0, "y": 9, "z": 15, "name": "Plant_Leaves_Beech"}, {"x": 0, "y": 10, "z": 15, "name": "Plant_Leaves_Beech"}, {"x": 0, "y": 12, "z": 15, "name": "Plant_Leaves_Beech"}, {"x": 0, "y": 0, "z": 16, "name": "Soil_Grass"}, {"x": 0, "y": 7, "z": 16, "name": "Plant_Leaves_Beech"}, {"x": 0, "y": 8, "z": 16, "name": "Plant_Leaves_Beech"}, {"x": 0, "y": 9, "z": 16, "name": "Plant_Leaves_Beech"}, {"x": 0, "y": 0, "z": 17, "name": "Soil_Grass"}, {"x": 0, "y": 8, "z": 17, "name": "Plant_Leaves_Beech"}, {"x": 0, "y": 10, "z": 17, "name": "Plant_Leaves_Beech"}, {"x": 0, "y": 0, "z": 18, "name": "Soil_Grass"}, {"x": 0, "y": 0, "z": 19, "name": "Soil_Grass"}, {"x": 0, "y": 0, "z": 20, "name": "Soil_Grass"}, {"x": 0, "y": 0, "z": 21, "name": "Soil_Grass"}, {"x": 0, "y": 0, "z": 22, "name": "Soil_Grass"}, {"x": 0, "y": 0, "z": 23, "name": "Soil_Grass"}, {"x": 0, "y": 0, "z": 24, "name": "Soil_Grass"}, {"x": 0, "y": 7, "z": 24, "name": "Plant_Leaves_Beech"}, {"x": 0, "y": 8, "z": 24, "name": "Plant_Leaves_Beech"}, {"x": 0, "y": 0, "z": 25, "name": "Soil_Grass"}, {"x": 0, "y": 7, "z": 25, "name": "Plant_Leaves_Beech"}, {"x": 0, "y": 8, "z": 25, "name": "Plant_Leaves_Beech"}, {"x": 0, "y": 11, "z": 25, "name": "Plant_Leaves_Beech"}, {"x": 0, "y": 0, "z": 26, "name": "Soil_Grass"}, {"x": 0, "y": 7, "z": 26, "name": "Plant_Leaves_Beech"}, {"x": 0, "y": 8, "z": 26, "name": "Plant_Leaves_Beech"}, {"x": 0, "y": 9, "z": 26, "name": "Plant_Leaves_Beech"}, {"x": 0, "y": 11, "z": 26, "name": "Plant_Leaves_Beech"}, {"x": 0, "y": 12, "z": 26, "name": "Plant_Leaves_Beech"}, {"x": 0, "y": 0, "z": 27, "name": "Soil_Grass"}, {"x": 0, "y": 7, "z": 27, "name": "Wood_Beech_Branch_Corner", "rotation": 3}, {"x": 0, "y": 8, "z": 27, "name": "Plant_Leaves_Beech"}, {"x": 0, "y": 9, "z": 27, "name": "Plant_Leaves_Beech"}, {"x": 0, "y": 10, "z": 27, "name": "Plant_Leaves_Beech"}, {"x": 0, "y": 12, "z": 27, "name": "Plant_Leaves_Beech"}, {"x": 0, "y": 0, "z": 28, "name": "Soil_Grass"}, {"x": 0, "y": 7, "z": 28, "name": "Plant_Leaves_Beech"}, {"x": 0, "y": 8, "z": 28, "name": "Plant_Leaves_Beech"}, {"x": 0, "y": 9, "z": 28, "name": "Plant_Leaves_Beech"}, {"x": 0, "y": 0, "z": 29, "name": "Soil_Grass"}, {"x": 0, "y": 8, "z": 29, "name": "Plant_Leaves_Beech"}, {"x": 0, "y": 10, "z": 29, "name": "Plant_Leaves_Beech"}, {"x": 0, "y": 0, "z": 30, "name": "Soil_Grass"}, {"x": 0, "y": 0, "z": 31, "name": "Soil_Grass"}, {"x": 0, "y": 0, "z": 32, "name": "Soil_Grass"}, {"x": 0, "y": 0, "z": 33, "name": "Soil_Grass"}, {"x": 0, "y": 0, "z": 34, "name": "Soil_Grass"}, {"x": 0, "y": 0, "z": 35, "name": "Soil_Grass"}, {"x": 0, "y": 0, "z": 36, "name": "Soil_Grass"}, {"x": 0, "y": 0, "z": 37, "name": "Soil_Grass"}, {"x": 0, "y": 7, "z": 37, "name": "Plant_Leaves_Beech"}, {"x": 0, "y": 8, "z": 37, "name": "Plant_Leaves_Beech"}, {"x": 0, "y": 0, "z": 38, "name": "Soil_Grass"}, {"x": 0, "y": 7, "z": 38, "name": "Plant_Leaves_Beech"}, {"x": 0, "y": 8, "z": 38, "name": "Plant_Leaves_Beech"}, {"x": 0, "y": 11, "z": 38, "name": "Plant_Leaves_Beech"}, {"x": 0, "y": 0, "z": 39, "name": "Soil_Grass"}, {"x": 0, "y": 7, "z": 39, "name": "Plant_Leaves_Beech"}, {"x": 0, "y": 8, "z": 39, "name": "Plant_Leaves_Beech"}, {"x": 0, "y": 9, "z": 39, "name": "Plant_Leaves_Beech"}, {"x": 0, "y": 11, "z": 39, "name": "Plant_Leaves_Beech"}, {"x": 0, "y": 12, "z": 39, "name": "Plant_Leaves_Beech"}, {"x": 0, "y": 0, "z": 40, "name": "Soil_Grass"}, {"x": 0, "y": 7, "z": 40, "name": "Wood_Beech_Branch_Corner", "rotation": 3}, {"x": 0, "y": 8, "z": 40, "name": "Plant_Leaves_Beech"}, {"x": 0, "y": 9, "z": 40, "name": "Plant_Leaves_Beech"}, {"x": 0, "y": 10, "z": 40, "name": "Plant_Leaves_Beech"}, {"x": 0, "y": 12, "z": 40, "name": "Plant_Leaves_Beech"}, {"x": 0, "y": 0, "z": 41, "name": "Soil_Grass"}, {"x": 0, "y": 7, "z": 41, "name": "Plant_Leaves_Beech"}, {"x": 0, "y": 8, "z": 41, "name": "Plant_Leaves_Beech"}, {"x": 0, "y": 9, "z": 41, "name": "Plant_Leaves_Beech"}, {"x": 0, "y": 0, "z": 42, "name": "Soil_Grass"}, {"x": 0, "y": 8, "z": 42, "name": "Plant_Leaves_Beech"}, {"x": 0, "y": 10, "z": 42, "name": "Plant_Leaves_Beech"}, {"x": 0, "y": 0, "z": 43, "name": "Soil_Grass"}, {"x": 0, "y": 0, "z": 44, "name": "Soil_Grass"}, {"x": 0, "y": 0, "z": 45, "name": "Soil_Grass"}, {"x": 0, "y": 0, "z": 46, "name": "Soil_Grass"}, {"x": 0, "y": 0, "z": 47, "name": "Soil_Grass"}, {"x": 0, "y": 0, "z": 48, "name": "Soil_Grass"}, {"x": 0, "y": 0, "z": 49, "name": "Soil_Grass"}, {"x": 0, "y": 0, "z": 50, "name": "Soil_Grass"}, {"x": 0, "y": 0, "z": 51, "name": "Soil_Grass"}, {"x": 0, "y": 0, "z": 52, "name": "Soil_Grass"}, {"x": 0, "y": 0, "z": 53, "name": "Soil_Grass"}, {"x": 0, "y": 0, "z": 54, "name": "Soil_Grass"}, {"x": 0, "y": 0, "z": 55, "name": "Soil_Grass"}, {"x": 0, "y": 0, "z": 56, "name": "Soil_Grass"}, {"x": 0, "y": 0, "z": 57, "name": "Soil_Grass"}, {"x": 0, "y": 0, "z": 58, "name": "Soil_Grass"}, {"x": 0, "y": 0, "z": 59, "name": "Soil_Grass"}, {"x": 0, "y": 0, "z": 60, "name": "Soil_Grass"}, {"x": 0, "y": 0, "z": 61, "name": "Soil_Grass"}, {"x": 0, "y": 0, "z": 62, "name": "Soil_Grass"}, {"x": 0, "y": 0, "z": 63, "name": "Soil_Grass"}, {"x": 1, "y": 0, "z": 0, "name": "Soil_Grass"}, {"x": 1, "y": 0, "z": 1, "name": "Soil_Grass"}, {"x": 1, "y": 0, "z": 2, "name": "Soil_Grass"}, {"x": 1, "y": 0, "z": 3, "name": "Soil_Grass"}, {"x": 1, "y": 0, "z": 4, "name": "Soil_Grass"}, {"x": 1, "y": 0, "z": 5, "name": "Soil_Grass"}, {"x": 1, "y": 0, "z": 6, "name": "Soil_Grass"}, {"x": 1, "y": 0, "z": 7, "name": "Soil_Grass"}, {"x": 1, "y": 0, "z": 8, "name": "Soil_Grass"}, {"x": 1, "y": 0, "z": 9, "name": "Soil_Grass"}, {"x": 1, "y": 0, "z": 10, "name": "Soil_Grass"}, {"x": 1, "y": 0, "z": 11, "name": "Soil_Grass"}, {"x": 1, "y": 7, "z": 11, "name": "Plant_Leaves_Beech"}, {"x": 1, "y": 0, "z": 12, "name": "Soil_Grass"}, {"x": 1, "y": 7, "z": 12, "name": "Plant_Leaves_Beech"}, {"x": 1, "y": 8, "z": 12, "name": "Plant_Leaves_Beech"}, {"x": 1, "y": 0, "z": 13, "name": "Soil_Grass"}, {"x": 1, "y": 7, "z": 13, "name": "Plant_Leaves_Beech"}, {"x": 1, "y": 11, "z": 13, "name": "Plant_Leaves_Beech"}, {"x": 1, "y": 0, "z": 14, "name": "Soil_Grass"}, {"x": 1, "y": 7, "z": 14, "name": "Plant_Leaves_Beech"}, {"x": 1, "y": 11, "z": 14, "name": "Plant_Leaves_Beech"}, {"x": 1, "y": 12, "z": 14, "name": "Plant_Leaves_Beech"}, {"x": 1, "y": 13, "z": 14, "name": "Plant_Leaves_Beech"}, {"x": 1, "y": 15, "z": 14, "name": "Plant_Leaves_Beech"}, {"x": 1, "y": 16, "z": 14, "name": "Plant_Leaves_Beech"}, {"x": 1, "y": 0, "z": 15, "name": "Soil_Grass"}, {"x": 1, "y": 7, "z": 15, "name": "Wood_Beech_Branch_Long", "rotation": 5}, {"x": 1, "y": 11, "z": 15, "name": "Plant_Leaves_Beech"}, {"x": 1, "y": 12, "z": 15, "name": "Plant_Leaves_Beech"}, {"x": 1, "y": 13, "z": 15, "name": "Plant_Leaves_Beech"}, {"x": 1, "y": 15, "z": 15, "name": "Plant_Leaves_Beech"}, {"x": 1, "y": 16, "z": 15, "name": "Plant_Leaves_Beech"}, {"x": 1, "y": 0, "z": 16, "name": "Soil_Grass"}, {"x": 1, "y": 10, "z": 16, "name": "Plant_Leaves_Beech"}, {"x": 1, "y": 12, "z": 16, "name": "Plant_Leaves_Beech"}, {"x": 1, "y": 13, "z": 16, "name": "Plant_Leaves_Beech"}, {"x": 1, "y": 15, "z": 16, "name": "Plant_Leaves_Beech"}, {"x": 1, "y": 16, "z": 16, "name": "Plant_Leaves_Beech"}, {"x": 1, "y": 0, "z": 17, "name": "Soil_Grass"}, {"x": 1, "y": 10, "z": 17, "name": "Plant_Leaves_Beech"}, {"x": 1, "y": 11, "z": 17, "name": "Plant_Leaves_Beech"}, {"x": 1, "y": 15, "z": 17, "name": "Plant_Leaves_Beech"}, {"x": 1, "y": 0, "z": 18, "name": "Soil_Grass"}, {"x": 1, "y": 7, "z": 18, "name": "Plant_Leaves_Beech"}, {"x": 1, "y": 8, "z": 18, "name": "Plant_Leaves_Beech"}, {"x": 1, "y": 10, "z": 18, "name": "Plant_Leaves_Beech"}, {"x": 1, "y": 11, "z": 18, "name": "Plant_Leaves_Beech"}, {"x": 1, "y": 0, "z": 19, "name": "Soil_Grass"}, {"x": 1, "y": 0, "z": 20, "name": "Soil_Grass"}, {"x": 1, "y": 0, "z": 21, "name": "Soil_Grass"}, {"x": 1, "y": 0, "z": 22, "name": "Soil_Grass"}, {"x": 1, "y": 0, "z": 23, "name": "Soil_Grass"}, {"x": 1, "y": 7, "z": 23, "name": "Plant_Leaves_Beech"}, {"x": 1, "y": 0, "z": 24, "name": "Soil_Grass"}, {"x": 1, "y": 7, "z": 24, "name": "Plant_Leaves_Beech"}, {"x": 1, "y": 8, "z": 24, "name": "Plant_Leaves_Beech"}, {"x": 1, "y": 0, "z": 25, "name": "Soil_Grass"}, {"x": 1, "y": 7, "z": 25, "name": "Plant_Leaves_Beech"}, {"x": 1, "y": 11, "z": 25, "name": "Plant_Leaves_Beech"}, {"x": 1, "y": 0, "z": 26, "name": "Soil_Grass"}, {"x": 1, "y": 7, "z": 26, "name": "Plant_Leaves_Beech"}, {"x": 1, "y": 11, "z": 26, "name": "Plant_Leaves_Beech"}, {"x": 1, "y": 12, "z": 26, "name": "Plant_Leaves_Beech"}, {"x": 1, "y": 13, "z": 26, "name": "Plant_Leaves_Beech"}, {"x": 1, "y": 15, "z": 26, "name": "Plant_Leaves_Beech"}, {"x": 1, "y": 16, "z": 26, "name": "Plant_Leaves_Beech"}, {"x": 1, "y": 0, "z": 27, "name": "Soil_Grass"}, {"x": 1, "y": 7, "z": 27, "name": "Wood_Beech_Branch_Long", "rotation": 5}, {"x": 1, "y": 11, "z": 27, "name": "Plant_Leaves_Beech"}, {"x": 1, "y": 12, "z": 27, "name": "Plant_Leaves_Beech"}, {"x": 1, "y": 13, "z": 27, "name": "Plant_Leaves_Beech"}, {"x": 1, "y": 15, "z": 27, "name": "Plant_Leaves_Beech"}, {"x": 1, "y": 16, "z": 27, "name": "Plant_Leaves_Beech"}, {"x": 1, "y": 0, "z": 28, "name": "Soil_Grass"}, {"x": 1, "y": 10, "z": 28, "name": "Plant_Leaves_Beech"}, {"x": 1, "y": 12, "z": 28, "name": "Plant_Leaves_Beech"}, {"x": 1, "y": 13, "z": 28, "name": "Plant_Leaves_Beech"}, {"x": 1, "y": 15, "z": 28, "name": "Plant_Leaves_Beech"}, {"x": 1, "y": 16, "z": 28, "name": "Plant_Leaves_Beech"}, {"x": 1, "y": 0, "z": 29, "name": "Soil_Grass"}, {"x": 1, "y": 10, "z": 29, "name": "Plant_Leaves_Beech"}, {"x": 1, "y": 11, "z": 29, "name": "Plant_Leaves_Beech"}, {"x": 1, "y": 15, "z": 29, "name": "Plant_Leaves_Beech"}, {"x": 1, "y": 0, "z": 30, "name": "Soil_Grass"}, {"x": 1, "y": 7, "z": 30, "name": "Plant_Leaves_Beech"}, {"x": 1, "y": 8, "z": 30, "name": "Plant_Leaves_Beech"}, {"x": 1, "y": 10, "z": 30, "name": "Plant_Leaves_Beech"}, {"x": 1, "y": 11, "z": 30, "name": "Plant_Leaves_Beech"}, {"x": 1, "y": 0, "z": 31, "name": "Soil_Grass"}, {"x": 1, "y": 0, "z": 32, "name": "Soil_Grass"}, {"x": 1, "y": 0, "z": 33, "name": "Soil_Grass"}, {"x": 1, "y": 0, "z": 34, "name": "Soil_Grass"}, {"x": 1, "y": 0, "z": 35, "name": "Soil_Grass"}, {"x": 1, "y": 0, "z": 36, "name": "Soil_Grass"}, {"x": 1, "y": 7, "z": 36, "name": "Plant_Leaves_Beech"}, {"x": 1, "y": 0, "z": 37, "name": "Soil_Grass"}, {"x": 1, "y": 7, "z": 37, "name": "Plant_Leaves_Beech"}, {"x": 1, "y": 8, "z": 37, "name": "Plant_Leaves_Beech"}, {"x": 1, "y": 0, "z": 38, "name": "Soil_Grass"}, {"x": 1, "y": 7, "z": 38, "name": "Plant_Leaves_Beech"}, {"x": 1, "y": 11, "z": 38, "name": "Plant_Leaves_Beech"}, {"x": 1, "y": 0, "z": 39, "name": "Soil_Grass"}, {"x": 1, "y": 7, "z": 39, "name": "Plant_Leaves_Beech"}, {"x": 1, "y": 11, "z": 39, "name": "Plant_Leaves_Beech"}, {"x": 1, "y": 12, "z": 39, "name": "Plant_Leaves_Beech"}, {"x": 1, "y": 13, "z": 39, "name": "Plant_Leaves_Beech"}, {"x": 1, "y": 15, "z": 39, "name": "Plant_Leaves_Beech"}, {"x": 1, "y": 16, "z": 39, "name": "Plant_Leaves_Beech"}, {"x": 1, "y": 0, "z": 40, "name": "Soil_Grass"}, {"x": 1, "y": 7, "z": 40, "name": "Wood_Beech_Branch_Long", "rotation": 5}, {"x": 1, "y": 11, "z": 40, "name": "Plant_Leaves_Beech"}, {"x": 1, "y": 12, "z": 40, "name": "Plant_Leaves_Beech"}, {"x": 1, "y": 13, "z": 40, "name": "Plant_Leaves_Beech"}, {"x": 1, "y": 15, "z": 40, "name": "Plant_Leaves_Beech"}, {"x": 1, "y": 16, "z": 40, "name": "Plant_Leaves_Beech"}, {"x": 1, "y": 0, "z": 41, "name": "Soil_Grass"}, {"x": 1, "y": 10, "z": 41, "name": "Plant_Leaves_Beech"}, {"x": 1, "y": 12, "z": 41, "name": "Plant_Leaves_Beech"}, {"x": 1, "y": 13, "z": 41, "name": "Plant_Leaves_Beech"}, {"x": 1, "y": 15, "z": 41, "name": "Plant_Leaves_Beech"}, {"x": 1, "y": 16, "z": 41, "name": "Plant_Leaves_Beech"}, {"x": 1, "y": 0, "z": 42, "name": "Soil_Grass"}, {"x": 1, "y": 10, "z": 42, "name": "Plant_Leaves_Beech"}, {"x": 1, "y": 11, "z": 42, "name": "Plant_Leaves_Beech"}, {"x": 1, "y": 15, "z": 42, "name": "Plant_Leaves_Beech"}, {"x": 1, "y": 0, "z": 43, "name": "Soil_Grass"}, {"x": 1, "y": 7, "z": 43, "name": "Plant_Leaves_Beech"}, {"x": 1, "y": 8, "z": 43, "name": "Plant_Leaves_Beech"}, {"x": 1, "y": 10, "z": 43, "name": "Plant_Leaves_Beech"}, {"x": 1, "y": 11, "z": 43, "name": "Plant_Leaves_Beech"}, {"x": 1, "y": 0, "z": 44, "name": "Soil_Grass"}, {"x": 1, "y": 0, "z": 45, "name": "Soil_Grass"}, {"x": 1, "y": 0, "z": 46, "name": "Soil_Grass"}, {"x": 1, "y": 0, "z": 47, "name": "Soil_Grass"}, {"x": 1, "y": 0, "z": 48, "name": "Soil_Grass"}, {"x": 1, "y": 0, "z": 49, "name": "Soil_Grass"}, {"x": 1, "y": 0, "z": 50, "name": "Soil_Grass"}, {"x": 1, "y": 0, "z": 51, "name": "Soil_Grass"}, {"x": 1, "y": 0, "z": 52, "name": "Soil_Grass"}, {"x": 1, "y": 7, "z": 52, "name": "Plant_Leaves_Beech"}, {"x": 1, "y": 0, "z": 53, "name": "Soil_Grass"}, {"x": 1, "y": 7, "z": 53, "name": "Plant_Leaves_Beech"}, {"x": 1, "y": 8, "z": 53, "name": "Plant_Leaves_Beech"}, {"x": 1, "y": 0, "z": 54, "name": "Soil_Grass"}, {"x": 1, "y": 7, "z": 54, "name": "Plant_Leaves_Beech"}, {"x": 1, "y": 8, "z": 54, "name": "Plant_Leaves_Beech"}, {"x": 1, "y": 9, "z": 54, "name": "Plant_Leaves_Beech"}, {"x": 1, "y": 0, "z": 55, "name": "Soil_Grass"}, {"x": 1, "y": 7, "z": 55, "name": "Plant_Leaves_Beech"}, {"x": 1, "y": 8, "z": 55, "name": "Plant_Leaves_Beech"}, {"x": 1, "y": 0, "z": 56, "name": "Soil_Grass"}, {"x": 1, "y": 0, "z": 57, "name": "Soil_Grass"}, {"x": 1, "y": 0, "z": 58, "name": "Soil_Grass"}, {"x": 1, "y": 0, "z": 59, "name": "Soil_Grass"}, {"x": 1, "y": 0, "z": 60, "name": "Soil_Grass"}, {"x": 1, "y": 0, "z": 61, "name": "Soil_Grass"}, {"x": 1, "y": 0, "z": 62, "name": "Soil_Grass"}, {"x": 1, "y": 0, "z": 63, "name": "Soil_Grass"}, {"x": 2, "y": 0, "z": 0, "name": "Soil_Grass"}, {"x": 2, "y": 0, "z": 1, "name": "Soil_Grass"}, {"x": 2, "y": 0, "z": 2, "name": "Soil_Grass"}, {"x": 2, "y": 7, "z": 2, "name": "Plant_Leaves_Beech"}, {"x": 2, "y": 0, "z": 3, "name": "Soil_Grass"}, {"x": 2, "y": 7, "z": 3, "name": "Plant_Leaves_Beech"}, {"x": 2, "y": 8, "z": 3, "name": "Plant_Leaves_Beech"}, {"x": 2, "y": 0, "z": 4, "name": "Soil_Grass"}, {"x": 2, "y": 7, "z": 4, "name": "Plant_Leaves_Beech"}, {"x": 2, "y": 8, "z": 4, "name": "Plant_Leaves_Beech"}, {"x": 2, "y": 9, "z": 4, "name": "Plant_Leaves_Beech"}, {"x": 2, "y": 0, "z": 5, "name": "Soil_Grass"}, {"x": 2, "y": 7, "z": 5, "name": "Plant_Leaves_Beech"}, {"x": 2, "y": 8, "z": 5, "name": "Plant_Leaves_Beech"}, {"x": 2, "y": 0, "z": 6, "name": "Soil_Grass"}, {"x": 2, "y": 0, "z": 7, "name": "Soil_Grass"}, {"x": 2, "y": 0, "z": 8, "name": "Soil_Grass"}, {"x": 2, "y": 0, "z": 9, "name": "Soil_Grass"}, {"x": 2, "y": 0, "z": 10, "name": "Soil_Grass"}, {"x": 2, "y": 0, "z": 11, "name": "Soil_Grass"}, {"x": 2, "y": 11, "z": 11, "name": "Plant_Leaves_Beech"}, {"x": 2, "y": 0, "z": 12, "name": "Soil_Grass"}, {"x": 2, "y": 10, "z": 12, "name": "Plant_Leaves_Beech"}, {"x": 2, "y": 11, "z": 12, "name": "Plant_Leaves_Beech"}, {"x": 2, "y": 12, "z": 12, "name": "Plant_Leaves_Beech"}, {"x": 2, "y": 0, "z": 13, "name": "Soil_Grass"}, {"x": 2, "y": 10, "z": 13, "name": "Plant_Leaves_Beech"}, {"x": 2, "y": 15, "z": 13, "name": "Plant_Leaves_Beech"}, {"x": 2, "y": 16, "z": 13, "name": "Plant_Leaves_Beech"}, {"x": 2, "y": 0, "z": 14, "name": "Soil_Grass"}, {"x": 2, "y": 12, "z": 14, "name": "Plant_Leaves_Beech"}, {"x": 2, "y": 13, "z": 14, "name": "Plant_Leaves_Beech"}, {"x": 2, "y": 15, "z": 14, "name": "Plant_Leaves_Beech"}, {"x": 2, "y": 16, "z": 14, "name": "Plant_Leaves_Beech"}, {"x": 2, "y": 17, "z": 14, "name": "Plant_Leaves_Beech"}, {"x": 2, "y": 0, "z": 15, "name": "Soil_Grass"}, {"x": 2, "y": 7, "z": 15, "name": "Wood_Beech_Branch_Long", "rotation": 5}, {"x": 2, "y": 12, "z": 15, "name": "Wood_Beech_Branch_Long", "rotation": 5}, {"x": 2, "y": 13, "z": 15, "name": "Plant_Leaves_Beech"}, {"x": 2, "y": 15, "z": 15, "name": "Wood_Beech_Branch_Corner", "rotation": 3}, {"x": 2, "y": 16, "z": 15, "name": "Plant_Leaves_Beech"}, {"x": 2, "y": 17, "z": 15, "name": "Plant_Leaves_Beech"}, {"x": 2, "y": 0, "z": 16, "name": "Soil_Grass"}, {"x": 2, "y": 12, "z": 16, "name": "Plant_Leaves_Beech"}, {"x": 2, "y": 13, "z": 16, "name": "Plant_Leaves_Beech"}, {"x": 2, "y": 15, "z": 16, "name": "Plant_Leaves_Beech"}, {"x": 2, "y": 16, "z": 16, "name": "Plant_Leaves_Beech"}, {"x": 2, "y": 17, "z": 16, "name": "Plant_Leaves_Beech"}, {"x": 2, "y": 0, "z": 17, "name": "Soil_Grass"}, {"x": 2, "y": 10, "z": 17, "name": "Wood_Beech_Branch_Corner", "rotation": 3}, {"x": 2, "y": 11, "z": 17, "name": "Plant_Leaves_Beech"}, {"x": 2, "y": 15, "z": 17, "name": "Plant_Leaves_Beech"}, {"x": 2, "y": 16, "z": 17, "name": "Plant_Leaves_Beech"}, {"x": 2, "y": 0, "z": 18, "name": "Soil_Grass"}, {"x": 2, "y": 8, "z": 18, "name": "Plant_Leaves_Beech"}, {"x": 2, "y": 10, "z": 18, "name": "Plant_Leaves_Beech"}, {"x": 2, "y": 11, "z": 18, "name": "Plant_Leaves_Beech"}, {"x": 2, "y": 16, "z": 18, "name": "Plant_Leaves_Beech"}, {"x": 2, "y": 0, "z": 19, "name": "Soil_Grass"}, {"x": 2, "y": 7, "z": 19, "name": "Plant_Leaves_Beech"}, {"x": 2, "y": 8, "z": 19, "name": "Plant_Leaves_Beech"}, {"x": 2, "y": 0, "z": 20, "name": "Soil_Grass"}, {"x": 2, "y": 0, "z": 21, "name": "Soil_Grass"}, {"x": 2, "y": 0, "z": 22, "name": "Soil_Grass"}, {"x": 2, "y": 0, "z": 23, "name": "Soil_Grass"}, {"x": 2, "y": 11, "z": 23, "name": "Plant_Leaves_Beech"}, {"x": 2, "y": 0, "z": 24, "name": "Soil_Grass"}, {"x": 2, "y": 10, "z": 24, "name": "Plant_Leaves_Beech"}, {"x": 2, "y": 11, "z": 24, "name": "Plant_Leaves_Beech"}, {"x": 2, "y": 12, "z": 24, "name": "Plant_Leaves_Beech"}, {"x": 2, "y": 0, "z": 25, "name": "Soil_Grass"}, {"x": 2, "y": 10, "z": 25, "name": "Plant_Leaves_Beech"}, {"x": 2, "y": 15, "z": 25, "name": "Plant_Leaves_Beech"}, {"x": 2, "y": 16, "z": 25, "name": "Plant_Leaves_Beech"}, {"x": 2, "y": 0, "z": 26, "name": "Soil_Grass"}, {"x": 2, "y": 12, "z": 26, "name": "Plant_Leaves_Beech"}, {"x": 2, "y": 13, "z": 26, "name": "Plant_Leaves_Beech"}, {"x": 2, "y": 15, "z": 26, "name": "Plant_Leaves_Beech"}, {"x": 2, "y": 16, "z": 26, "name": "Plant_Leaves_Beech"}, {"x": 2, "y": 17, "z": 26, "name": "Plant_Leaves_Beech"}, {"x": 2, "y": 0, "z": 27, "name": "Soil_Grass"}, {"x": 2, "y": 7, "z": 27, "name": "Wood_Beech_Branch_Long", "rotation": 5}, {"x": 2, "y": 12, "z": 27, "name": "Wood_Beech_Branch_Long", "rotation": 5}, {"x": 2, "y": 13, "z": 27, "name": "Plant_Leaves_Beech"}, {"x": 2, "y": 15, "z": 27, "name": "Wood_Beech_Branch_Corner", "rotation": 3}, {"x": 2, "y": 16, "z": 27, "name": "Plant_Leaves_Beech"}, {"x": 2, "y": 17, "z": 27, "name": "Plant_Leaves_Beech"}, {"x": 2, "y": 0, "z": 28, "name": "Soil_Grass"}, {"x": 2, "y": 12, "z": 28, "name": "Plant_Leaves_Beech"}, {"x": 2, "y": 13, "z": 28, "name": "Plant_Leaves_Beech"}, {"x": 2, "y": 15, "z": 28, "name": "Plant_Leaves_Beech"}, {"x": 2, "y": 16, "z": 28, "name": "Plant_Leaves_Beech"}, {"x": 2, "y": 17, "z": 28, "name": "Plant_Leaves_Beech"}, {"x": 2, "y": 0, "z": 29, "name": "Soil_Grass"}, {"x": 2, "y": 10, "z": 29, "name": "Wood_Beech_Branch_Corner", "rotation": 3}, {"x": 2, "y": 11, "z": 29, "name": "Plant_Leaves_Beech"}, {"x": 2, "y": 15, "z": 29, "name": "Plant_Leaves_Beech"}, {"x": 2, "y": 16, "z": 29, "name": "Plant_Leaves_Beech"}, {"x": 2, "y": 0, "z": 30, "name": "Soil_Grass"}, {"x": 2, "y": 8, "z": 30, "name": "Plant_Leaves_Beech"}, {"x": 2, "y": 10, "z": 30, "name": "Plant_Leaves_Beech"}, {"x": 2, "y": 11, "z": 30, "name": "Plant_Leaves_Beech"}, {"x": 2, "y": 16, "z": 30, "name": "Plant_Leaves_Beech"}, {"x": 2, "y": 0, "z": 31, "name": "Soil_Grass"}, {"x": 2, "y": 7, "z": 31, "name": "Plant_Leaves_Beech"}, {"x": 2, "y": 8, "z": 31, "name": "Plant_Leaves_Beech"}, {"x": 2, "y": 0, "z": 32, "name": "Soil_Grass"}, {"x": 2, "y": 0, "z": 33, "name": "Soil_Grass"}, {"x": 2, "y": 0, "z": 34, "name": "Soil_Grass"}, {"x": 2, "y": 0, "z": 35, "name": "Soil_Grass"}, {"x": 2, "y": 0, "z": 36, "name": "Soil_Grass"}, {"x": 2, "y": 11, "z": 36, "name": "Plant_Leaves_Beech"}, {"x": 2, "y": 0, "z": 37, "name": "Soil_Grass"}, {"x": 2, "y": 10, "z": 37, "name": "Plant_Leaves_Beech"}, {"x": 2, "y": 11, "z": 37, "name": "Plant_Leaves_Beech"}, {"x": 2, "y": 12, "z": 37, "name": "Plant_Leaves_Beech"}, {"x": 2, "y": 0, "z": 38, "name": "Soil_Grass"}, {"x": 2, "y": 10, "z": 38, "name": "Plant_Leaves_Beech"}, {"x": 2, "y": 15, "z": 38, "name": "Plant_Leaves_Beech"}, {"x": 2, "y": 16, "z": 38, "name": "Plant_Leaves_Beech"}, {"x": 2, "y": 0, "z": 39, "name": "Soil_Grass"}, {"x": 2, "y": 12, "z": 39, "name": "Plant_Leaves_Beech"}, {"x": 2, "y": 13, "z": 39, "name": "Plant_Leaves_Beech"}, {"x": 2, "y": 15, "z": 39, "name": "Plant_Leaves_Beech"}, {"x": 2, "y": 16, "z": 39, "name": "Plant_Leaves_Beech"}, {"x": 2, "y": 17, "z": 39, "name": "Plant_Leaves_Beech"}, {"x": 2, "y": 0, "z": 40, "name": "Soil_Grass"}, {"x": 2, "y": 7, "z": 40, "name": "Wood_Beech_Branch_Long", "rotation": 5}, {"x": 2, "y": 12, "z": 40, "name": "Wood_Beech_Branch_Long", "rotation": 5}, {"x": 2, "y": 13, "z": 40, "name": "Plant_Leaves_Beech"}, {"x": 2, "y": 15, "z": 40, "name": "Wood_Beech_Branch_Corner", "rotation": 3}, {"x": 2, "y": 16, "z": 40, "name": "Plant_Leaves_Beech"}, {"x": 2, "y": 17, "z": 40, "name": "Plant_Leaves_Beech"}, {"x": 2, "y": 0, "z": 41, "name": "Soil_Grass"}, {"x": 2, "y": 12, "z": 41, "name": "Plant_Leaves_Beech"}, {"x": 2, "y": 13, "z": 41, "name": "Plant_Leaves_Beech"}, {"x": 2, "y": 15, "z": 41, "name": "Plant_Leaves_Beech"}, {"x": 2, "y": 16, "z": 41, "name": "Plant_Leaves_Beech"}, {"x": 2, "y": 17, "z": 41, "name": "Plant_Leaves_Beech"}, {"x": 2, "y": 0, "z": 42, "name": "Soil_Grass"}, {"x": 2, "y": 10, "z": 42, "name": "Wood_Beech_Branch_Corner", "rotation": 3}, {"x": 2, "y": 11, "z": 42, "name": "Plant_Leaves_Beech"}, {"x": 2, "y": 15, "z": 42, "name": "Plant_Leaves_Beech"}, {"x": 2, "y": 16, "z": 42, "name": "Plant_Leaves_Beech"}, {"x": 2, "y": 0, "z": 43, "name": "Soil_Grass"}, {"x": 2, "y": 8, "z": 43, "name": "Plant_Leaves_Beech"}, {"x": 2, "y": 10, "z": 43, "name": "Plant_Leaves_Beech"}, {"x": 2, "y": 11, "z": 43, "name": "Plant_Leaves_Beech"}, {"x": 2, "y": 16, "z": 43, "name": "Plant_Leaves_Beech"}, {"x": 2, "y": 0, "z": 44, "name": "Soil_Grass"}, {"x": 2, "y": 7, "z": 44, "name": "Plant_Leaves_Beech"}, {"x": 2, "y": 8, "z": 44, "name": "Plant_Leaves_Beech"}, {"x": 2, "y": 0, "z": 45, "name": "Soil_Grass"}, {"x": 2, "y": 0, "z": 46, "name": "Soil_Grass"}, {"x": 2, "y": 0, "z": 47, "name": "Soil_Grass"}, {"x": 2, "y": 0, "z": 48, "name": "Soil_Grass"}, {"x": 2, "y": 0, "z": 49, "name": "Soil_Grass"}, {"x": 2, "y": 0, "z": 50, "name": "Soil_Grass"}, {"x": 2, "y": 0, "z": 51, "name": "Soil_Grass"}, {"x": 2, "y": 7, "z": 51, "name": "Plant_Leaves_Beech"}, {"x": 2, "y": 8, "z": 51, "name": "Plant_Leaves_Beech"}, {"x": 2, "y": 0, "z": 52, "name": "Soil_Grass"}, {"x": 2, "y": 7, "z": 52, "name": "Plant_Leaves_Beech"}, {"x": 2, "y": 8, "z": 52, "name": "Plant_Leaves_Beech"}, {"x": 2, "y": 11, "z": 52, "name": "Plant_Leaves_Beech"}, {"x": 2, "y": 0, "z": 53, "name": "Soil_Grass"}, {"x": 2, "y": 7, "z": 53, "name": "Plant_Leaves_Beech"}, {"x": 2, "y": 8, "z": 53, "name": "Plant_Leaves_Beech"}, {"x": 2, "y": 9, "z": 53, "name": "Plant_Leaves_Beech"}, {"x": 2, "y": 11, "z": 53, "name": "Plant_Leaves_Beech"}, {"x": 2, "y": 12, "z": 53, "name": "Plant_Leaves_Beech"}, {"x": 2, "y": 0, "z": 54, "name": "Soil_Grass"}, {"x": 2, "y": 7, "z": 54, "name": "Wood_Beech_Branch_Corner", "rotation": 3}, {"x": 2, "y": 8, "z": 54, "name": "Plant_Leaves_Beech"}, {"x": 2, "y": 9, "z": 54, "name": "Plant_Leaves_Beech"}, {"x": 2, "y": 10, "z": 54, "name": "Plant_Leaves_Beech"}, {"x": 2, "y": 12, "z": 54, "name": "Plant_Leaves_Beech"}, {"x": 2, "y": 0, "z": 55, "name": "Soil_Grass"}, {"x": 2, "y": 7, "z": 55, "name": "Plant_Leaves_Beech"}, {"x": 2, "y": 8, "z": 55, "name": "Plant_Leaves_Beech"}, {"x": 2, "y": 9, "z": 55, "name": "Plant_Leaves_Beech"}, {"x": 2, "y": 0, "z": 56, "name": "Soil_Grass"}, {"x": 2, "y": 8, "z": 56, "name": "Plant_Leaves_Beech"}, {"x": 2, "y": 10, "z": 56, "name": "Plant_Leaves_Beech"}, {"x": 2, "y": 0, "z": 57, "name": "Soil_Grass"}, {"x": 2, "y": 0, "z": 58, "name": "Soil_Grass"}, {"x": 2, "y": 0, "z": 59, "name": "Soil_Grass"}, {"x": 2, "y": 0, "z": 60, "name": "Soil_Grass"}, {"x": 2, "y": 0, "z": 61, "name": "Soil_Grass"}, {"x": 2, "y": 0, "z": 62, "name": "Soil_Grass"}, {"x": 2, "y": 0, "z": 63, "name": "Soil_Grass"}, {"x": 3, "y": 0, "z": 0, "name": "Soil_Grass"}, {"x": 3, "y": 0, "z": 1, "name": "Soil_Grass"}, {"x": 3, "y": 7, "z": 1, "name": "Plant_Leaves_Beech"}, {"x": 3, "y": 8, "z": 1, "name": "Plant_Leaves_Beech"}, {"x": 3, "y": 0, "z": 2, "name": "Soil_Grass"}, {"x": 3, "y": 7, "z": 2, "name": "Plant_Leaves_Beech"}, {"x": 3, "y": 8, "z": 2, "name": "Plant_Leaves_Beech"}, {"x": 3, "y": 11, "z": 2, "name": "Plant_Leaves_Beech"}, {"x": 3, "y": 0, "z": 3, "name": "Soil_Grass"}, {"x": 3, "y": 7, "z": 3, "name": "Plant_Leaves_Beech"}, {"x": 3, "y": 8, "z": 3, "name": "Plant_Leaves_Beech"}, {"x": 3, "y": 9, "z": 3, "name": "Plant_Leaves_Beech"}, {"x": 3, "y": 11, "z": 3, "name": "Plant_Leaves_Beech"}, {"x": 3, "y": 12, "z": 3, "name": "Plant_Leaves_Beech"}, {"x": 3, "y": 0, "z": 4, "name": "Soil_Grass"}, {"x": 3, "y": 7, "z": 4, "name": "Wood_Beech_Branch_Corner", "rotation": 3}, {"x": 3, "y": 8, "z": 4, "name": "Plant_Leaves_Beech"}, {"x": 3, "y": 9, "z": 4, "name": "Plant_Leaves_Beech"}, {"x": 3, "y": 10, "z": 4, "name": "Plant_Leaves_Beech"}, {"x": 3, "y": 12, "z": 4, "name": "Plant_Leaves_Beech"}, {"x": 3, "y": 0, "z": 5, "name": "Soil_Grass"}, {"x": 3, "y": 7, "z": 5, "name": "Plant_Leaves_Beech"}, {"x": 3, "y": 8, "z": 5, "name": "Plant_Leaves_Beech"}, {"x": 3, "y": 9, "z": 5, "name": "Plant_Leaves_Beech"}, {"x": 3, "y": 0, "z": 6, "name": "Soil_Grass"}, {"x": 3, "y": 8, "z": 6, "name": "Plant_Leaves_Beech"}, {"x": 3, "y": 10, "z": 6, "name": "Plant_Leaves_Beech"}, {"x": 3, "y": 0, "z": 7, "name": "Soil_Grass"}, {"x": 3, "y": 0, "z": 8, "name": "Soil_Grass"}, {"x": 3, "y": 0, "z": 9, "name": "Soil_Grass"}, {"x": 3, "y": 7, "z": 9, "name": "Plant_Leaves_Beech"}, {"x": 3, "y": 8, "z": 9, "name": "Plant_Leaves_Beech"}, {"x": 3, "y": 0, "z": 10, "name": "Soil_Grass"}, {"x": 3, "y": 7, "z": 10, "name": "Plant_Leaves_Beech"}, {"x": 3, "y": 8, "z": 10, "name": "Plant_Leaves_Beech"}, {"x": 3, "y": 9, "z": 10, "name": "Plant_Leaves_Beech"}, {"x": 3, "y": 0, "z": 11, "name": "Soil_Grass"}, {"x": 3, "y": 11, "z": 11, "name": "Plant_Leaves_Beech"}, {"x": 3, "y": 12, "z": 11, "name": "Plant_Leaves_Beech"}, {"x": 3, "y": 16, "z": 11, "name": "Plant_Leaves_Beech"}, {"x": 3, "y": 0, "z": 12, "name": "Soil_Grass"}, {"x": 3, "y": 10, "z": 12, "name": "Plant_Leaves_Beech"}, {"x": 3, "y": 11, "z": 12, "name": "Plant_Leaves_Beech"}, {"x": 3, "y": 12, "z": 12, "name": "Plant_Leaves_Beech"}, {"x": 3, "y": 15, "z": 12, "name": "Plant_Leaves_Beech"}, {"x": 3, "y": 16, "z": 12, "name": "Plant_Leaves_Beech"}, {"x": 3, "y": 17, "z": 12, "name": "Plant_Leaves_Beech"}, {"x": 3, "y": 0, "z": 13, "name": "Soil_Grass"}, {"x": 3, "y": 7, "z": 13, "name": "Wood_Beech_Branch_Corner", "rotation": 3}, {"x": 3, "y": 8, "z": 13, "name": "Wood_Beech_Branch_Long"}, {"x": 3, "y": 9, "z": 13, "name": "Wood_Beech_Branch_Long"}, {"x": 3, "y": 10, "z": 13, "name": "Wood_Beech_Branch_Long"}, {"x": 3, "y": 11, "z": 13, "name": "Plant_Leaves_Beech"}, {"x": 3, "y": 15, "z": 13, "name": "Plant_Leaves_Beech"}, {"x": 3, "y": 0, "z": 14, "name": "Soil_Grass"}, {"x": 3, "y": 15, "z": 14, "name": "Wood_Beech_Branch_Long", "rotation": 4}, {"x": 3, "y": 17, "z": 14, "name": "Plant_Leaves_Beech"}, {"x": 3, "y": 19, "z": 14, "name": "Plant_Leaves_Beech"}, {"x": 3, "y": 20, "z": 14, "name": "Plant_Leaves_Beech"}, {"x": 3, "y": 0, "z": 15, "name": "Soil_Grass"}, {"x": 3, "y": 7, "z": 15, "name": "Wood_Beech_Trunk_Full"}, {"x": 3, "y": 12, "z": 15, "name": "Wood_Beech_Branch_Long", "rotation": 5}, {"x": 3, "y": 15, "z": 15, "name": "Wood_Beech_Trunk_Full"}, {"x": 3, "y": 17, "z": 15, "name": "Plant_Leaves_Beech"}, {"x": 3, "y": 18, "z": 15, "name": "Plant_Leaves_Beech"}, {"x": 3, "y": 20, "z": 15, "name": "Plant_Leaves_Beech"}, {"x": 3, "y": 0, "z": 16, "name": "Soil_Grass"}, {"x": 3, "y": 7, "z": 16, "name": "Wood_Beech_Branch_Long", "rotation": 4}, {"x": 3, "y": 15, "z": 16, "name": "Wood_Beech_Branch_Corner"}, {"x": 3, "y": 16, "z": 16, "name": "Wood_Beech_Branch_Long"}, {"x": 3, "y": 17, "z": 16, "name": "Wood_Beech_Branch_Long"}, {"x": 3, "y": 18, "z": 16, "name": "Plant_Leaves_Beech"}, {"x": 3, "y": 20, "z": 16, "name": "Plant_Leaves_Beech"}, {"x": 3, "y": 0, "z": 17, "name": "Soil_Grass"}, {"x": 3, "y": 7, "z": 17, "name": "Wood_Beech_Branch_Long", "rotation": 4}, {"x": 3, "y": 10, "z": 17, "name": "Wood_Beech_Branch_Long", "rotation": 5}, {"x": 3, "y": 17, "z": 17, "name": "Plant_Leaves_Beech"}, {"x": 3, "y": 0, "z": 18, "name": "Soil_Grass"}, {"x": 3, "y": 7, "z": 18, "name": "Wood_Beech_Branch_Long", "rotation": 4}, {"x": 3, "y": 9, "z": 18, "name": "Plant_Leaves_Beech"}, {"x": 3, "y": 14, "z": 18, "name": "Plant_Leaves_Beech"}, {"x": 3, "y": 15, "z": 18, "name": "Plant_Leaves_Beech"}, {"x": 3, "y": 16, "z": 18, "name": "Plant_Leaves_Beech"}, {"x": 3, "y": 17, "z": 18, "name": "Plant_Leaves_Beech"}, {"x": 3, "y": 0, "z": 19, "name": "Soil_Grass"}, {"x": 3, "y": 7, "z": 19, "name": "Wood_Beech_Branch_Corner"}, {"x": 3, "y": 8, "z": 19, "name": "Plant_Leaves_Beech"}, {"x": 3, "y": 9, "z": 19, "name": "Plant_Leaves_Beech"}, {"x": 3, "y": 0, "z": 20, "name": "Soil_Grass"}, {"x": 3, "y": 7, "z": 20, "name": "Plant_Leaves_Beech"}, {"x": 3, "y": 8, "z": 20, "name": "Plant_Leaves_Beech"}, {"x": 3, "y": 10, "z": 20, "name": "Plant_Leaves_Beech"}, {"x": 3, "y": 11, "z": 20, "name": "Plant_Leaves_Beech"}, {"x": 3, "y": 0, "z": 21, "name": "Soil_Grass"}, {"x": 3, "y": 7, "z": 21, "name": "Plant_Leaves_Beech"}, {"x": 3, "y": 8, "z": 21, "name": "Plant_Leaves_Beech"}, {"x": 3, "y": 0, "z": 22, "name": "Soil_Grass"}, {"x": 3, "y": 7, "z": 22, "name": "Plant_Leaves_Beech"}, {"x": 3, "y": 8, "z": 22, "name": "Plant_Leaves_Beech"}, {"x": 3, "y": 9, "z": 22, "name": "Plant_Leaves_Beech"}, {"x": 3, "y": 0, "z": 23, "name": "Soil_Grass"}, {"x": 3, "y": 11, "z": 23, "name": "Plant_Leaves_Beech"}, {"x": 3, "y": 12, "z": 23, "name": "Plant_Leaves_Beech"}, {"x": 3, "y": 16, "z": 23, "name": "Plant_Leaves_Beech"}, {"x": 3, "y": 0, "z": 24, "name": "Soil_Grass"}, {"x": 3, "y": 10, "z": 24, "name": "Plant_Leaves_Beech"}, {"x": 3, "y": 11, "z": 24, "name": "Plant_Leaves_Beech"}, {"x": 3, "y": 12, "z": 24, "name": "Plant_Leaves_Beech"}, {"x": 3, "y": 15, "z": 24, "name": "Plant_Leaves_Beech"}, {"x": 3, "y": 16, "z": 24, "name": "Plant_Leaves_Beech"}, {"x": 3, "y": 17, "z": 24, "name": "Plant_Leaves_Beech"}, {"x": 3, "y": 0, "z": 25, "name": "Soil_Grass"}, {"x": 3, "y": 7, "z": 25, "name": "Wood_Beech_Branch_Corner", "rotation": 3}, {"x": 3, "y": 8, "z": 25, "name": "Wood_Beech_Branch_Long"}, {"x": 3, "y": 9, "z": 25, "name": "Wood_Beech_Branch_Long"}, {"x": 3, "y": 10, "z": 25, "name": "Wood_Beech_Branch_Long"}, {"x": 3, "y": 11, "z": 25, "name": "Plant_Leaves_Beech"}, {"x": 3, "y": 15, "z": 25, "name": "Plant_Leaves_Beech"}, {"x": 3, "y": 0, "z": 26, "name": "Soil_Grass"}, {"x": 3, "y": 15, "z": 26, "name": "Wood_Beech_Branch_Long", "rotation": 4}, {"x": 3, "y": 17, "z": 26, "name": "Plant_Leaves_Beech"}, {"x": 3, "y": 19, "z": 26, "name": "Plant_Leaves_Beech"}, {"x": 3, "y": 20, "z": 26, "name": "Plant_Leaves_Beech"}, {"x": 3, "y": 0, "z": 27, "name": "Soil_Grass"}, {"x": 3, "y": 7, "z": 27, "name": "Wood_Beech_Trunk_Full"}, {"x": 3, "y": 12, "z": 27, "name": "Wood_Beech_Branch_Long", "rotation": 5}, {"x": 3, "y": 15, "z": 27, "name": "Wood_Beech_Trunk_Full"}, {"x": 3, "y": 17, "z": 27, "name": "Plant_Leaves_Beech"}, {"x": 3, "y": 18, "z": 27, "name": "Plant_Leaves_Beech"}, {"x": 3, "y": 20, "z": 27, "name": "Plant_Leaves_Beech"}, {"x": 3, "y": 0, "z": 28, "name": "Soil_Grass"}, {"x": 3, "y": 7, "z": 28, "name": "Wood_Beech_Branch_Long", "rotation": 4}, {"x": 3, "y": 15, "z": 28, "name": "Wood_Beech_Branch_Corner"}, {"x": 3, "y": 16, "z": 28, "name": "Wood_Beech_Branch_Long"}, {"x": 3, "y": 17, "z": 28, "name": "Wood_Beech_Branch_Long"}, {"x": 3, "y": 18, "z": 28, "name": "Plant_Leaves_Beech"}, {"x": 3, "y": 20, "z": 28, "name": "Plant_Leaves_Beech"}, {"x": 3, "y": 0, "z": 29, "name": "Soil_Grass"}, {"x": 3, "y": 7, "z": 29, "name": "Wood_Beech_Branch_Long", "rotation": 4}, {"x": 3, "y": 10, "z": 29, "name": "Wood_Beech_Branch_Long", "rotation": 5}, {"x": 3, "y": 17, "z": 29, "name": "Plant_Leaves_Beech"}, {"x": 3, "y": 0, "z": 30, "name": "Soil_Grass"}, {"x": 3, "y": 7, "z": 30, "name": "Wood_Beech_Branch_Long", "rotation": 4}, {"x": 3, "y": 9, "z": 30, "name": "Plant_Leaves_Beech"}, {"x": 3, "y": 14, "z": 30, "name": "Plant_Leaves_Beech"}, {"x": 3, "y": 15, "z": 30, "name": "Plant_Leaves_Beech"}, {"x": 3, "y": 16, "z": 30, "name": "Plant_Leaves_Beech"}, {"x": 3, "y": 17, "z": 30, "name": "Plant_Leaves_Beech"}, {"x": 3, "y": 0, "z": 31, "name": "Soil_Grass"}, {"x": 3, "y": 7, "z": 31, "name": "Wood_Beech_Branch_Corner"}, {"x": 3, "y": 8, "z": 31, "name": "Plant_Leaves_Beech"}, {"x": 3, "y": 9, "z": 31, "name": "Plant_Leaves_Beech"}, {"x": 3, "y": 0, "z": 32, "name": "Soil_Grass"}, {"x": 3, "y": 7, "z": 32, "name": "Plant_Leaves_Beech"}, {"x": 3, "y": 8, "z": 32, "name": "Plant_Leaves_Beech"}, {"x": 3, "y": 10, "z": 32, "name": "Plant_Leaves_Beech"}, {"x": 3, "y": 11, "z": 32, "name": "Plant_Leaves_Beech"}, {"x": 3, "y": 0, "z": 33, "name": "Soil_Grass"}, {"x": 3, "y": 0, "z": 34, "name": "Soil_Grass"}, {"x": 3, "y": 7, "z": 34, "name": "Plant_Leaves_Beech"}, {"x": 3, "y": 8, "z": 34, "name": "Plant_Leaves_Beech"}, {"x": 3, "y": 0, "z": 35, "name": "Soil_Grass"}, {"x": 3, "y": 7, "z": 35, "name": "Plant_Leaves_Beech"}, {"x": 3, "y": 8, "z": 35, "name": "Plant_Leaves_Beech"}, {"x": 3, "y": 9, "z": 35, "name": "Plant_Leaves_Beech"}, {"x": 3, "y": 0, "z": 36, "name": "Soil_Grass"}, {"x": 3, "y": 11, "z": 36, "name": "Plant_Leaves_Beech"}, {"x": 3, "y": 12, "z": 36, "name": "Plant_Leaves_Beech"}, {"x": 3, "y": 16, "z": 36, "name": "Plant_Leaves_Beech"}, {"x": 3, "y": 0, "z": 37, "name": "Soil_Grass"}, {"x": 3, "y": 10, "z": 37, "name": "Plant_Leaves_Beech"}, {"x": 3, "y": 11, "z": 37, "name": "Plant_Leaves_Beech"}, {"x": 3, "y": 12, "z": 37, "name": "Plant_Leaves_Beech"}, {"x": 3, "y": 15, "z": 37, "name": "Plant_Leaves_Beech"}, {"x": 3, "y": 16, "z": 37, "name": "Plant_Leaves_Beech"}, {"x": 3, "y": 17, "z": 37, "name": "Plant_Leaves_Beech"}, {"x": 3, "y": 0, "z": 38, "name": "Soil_Grass"}, {"x": 3, "y": 7, "z": 38, "name": "Wood_Beech_Branch_Corner", "rotation": 3}, {"x": 3, "y": 8, "z": 38, "name": "Wood_Beech_Branch_Long"}, {"x": 3, "y": 9, "z": 38, "name": "Wood_Beech_Branch_Long"}, {"x": 3, "y": 10, "z": 38, "name": "Wood_Beech_Branch_Long"}, {"x": 3, "y": 11, "z": 38, "name": "Plant_Leaves_Beech"}, {"x": 3, "y": 15, "z": 38, "name": "Plant_Leaves_Beech"}, {"x": 3, "y": 0, "z": 39, "name": "Soil_Grass"}, {"x": 3, "y": 15, "z": 39, "name": "Wood_Beech_Branch_Long", "rotation": 4}, {"x": 3, "y": 17, "z": 39, "name": "Plant_Leaves_Beech"}, {"x": 3, "y": 19, "z": 39, "name": "Plant_Leaves_Beech"}, {"x": 3, "y": 20, "z": 39, "name": "Plant_Leaves_Beech"}, {"x": 3, "y": 0, "z": 40, "name": "Soil_Grass"}, {"x": 3, "y": 7, "z": 40, "name": "Wood_Beech_Trunk_Full"}, {"x": 3, "y": 12, "z": 40, "name": "Wood_Beech_Branch_Long", "rotation": 5}, {"x": 3, "y": 15, "z": 40, "name": "Wood_Beech_Trunk_Full"}, {"x": 3, "y": 17, "z": 40, "name": "Plant_Leaves_Beech"}, {"x": 3, "y": 18, "z": 40, "name": "Plant_Leaves_Beech"}, {"x": 3, "y": 20, "z": 40, "name": "Plant_Leaves_Beech"}, {"x": 3, "y": 0, "z": 41, "name": "Soil_Grass"}, {"x": 3, "y": 7, "z": 41, "name": "Wood_Beech_Branch_Long", "rotation": 4}, {"x": 3, "y": 15, "z": 41, "name": "Wood_Beech_Branch_Corner"}, {"x": 3, "y": 16, "z": 41, "name": "Wood_Beech_Branch_Long"}, {"x": 3, "y": 17, "z": 41, "name": "Wood_Beech_Branch_Long"}, {"x": 3, "y": 18, "z": 41, "name": "Plant_Leaves_Beech"}, {"x": 3, "y": 20, "z": 41, "name": "Plant_Leaves_Beech"}, {"x": 3, "y": 0, "z": 42, "name": "Soil_Grass"}, {"x": 3, "y": 7, "z": 42, "name": "Wood_Beech_Branch_Long", "rotation": 4}, {"x": 3, "y": 10, "z": 42, "name": "Wood_Beech_Branch_Long", "rotation": 5}, {"x": 3, "y": 17, "z": 42, "name": "Plant_Leaves_Beech"}, {"x": 3, "y": 0, "z": 43, "name": "Soil_Grass"}, {"x": 3, "y": 7, "z": 43, "name": "Wood_Beech_Branch_Long", "rotation": 4}, {"x": 3, "y": 9, "z": 43, "name": "Plant_Leaves_Beech"}, {"x": 3, "y": 14, "z": 43, "name": "Plant_Leaves_Beech"}, {"x": 3, "y": 15, "z": 43, "name": "Plant_Leaves_Beech"}, {"x": 3, "y": 16, "z": 43, "name": "Plant_Leaves_Beech"}, {"x": 3, "y": 17, "z": 43, "name": "Plant_Leaves_Beech"}, {"x": 3, "y": 0, "z": 44, "name": "Soil_Grass"}, {"x": 3, "y": 7, "z": 44, "name": "Wood_Beech_Branch_Corner"}, {"x": 3, "y": 8, "z": 44, "name": "Plant_Leaves_Beech"}, {"x": 3, "y": 9, "z": 44, "name": "Plant_Leaves_Beech"}, {"x": 3, "y": 0, "z": 45, "name": "Soil_Grass"}, {"x": 3, "y": 7, "z": 45, "name": "Plant_Leaves_Beech"}, {"x": 3, "y": 8, "z": 45, "name": "Plant_Leaves_Beech"}, {"x": 3, "y": 10, "z": 45, "name": "Plant_Leaves_Beech"}, {"x": 3, "y": 11, "z": 45, "name": "Plant_Leaves_Beech"}, {"x": 3, "y": 0, "z": 46, "name": "Soil_Grass"}, {"x": 3, "y": 0, "z": 47, "name": "Soil_Grass"}, {"x": 3, "y": 0, "z": 48, "name": "Soil_Grass"}, {"x": 3, "y": 0, "z": 49, "name": "Soil_Grass"}, {"x": 3, "y": 0, "z": 50, "name": "Soil_Grass"}, {"x": 3, "y": 7, "z": 50, "name": "Plant_Leaves_Beech"}, {"x": 3, "y": 0, "z": 51, "name": "Soil_Grass"}, {"x": 3, "y": 7, "z": 51, "name": "Plant_Leaves_Beech"}, {"x": 3, "y": 8, "z": 51, "name": "Plant_Leaves_Beech"}, {"x": 3, "y": 0, "z": 52, "name": "Soil_Grass"}, {"x": 3, "y": 7, "z": 52, "name": "Plant_Leaves_Beech"}, {"x": 3, "y": 11, "z": 52, "name": "Plant_Leaves_Beech"}, {"x": 3, "y": 0, "z": 53, "name": "Soil_Grass"}, {"x": 3, "y": 7, "z": 53, "name": "Plant_Leaves_Beech"}, {"x": 3, "y": 11, "z": 53, "name": "Plant_Leaves_Beech"}, {"x": 3, "y": 12, "z": 53, "name": "Plant_Leaves_Beech"}, {"x": 3, "y": 13, "z": 53, "name": "Plant_Leaves_Beech"}, {"x": 3, "y": 15, "z": 53, "name": "Plant_Leaves_Beech"}, {"x": 3, "y": 16, "z": 53, "name": "Plant_Leaves_Beech"}, {"x": 3, "y": 0, "z": 54, "name": "Soil_Grass"}, {"x": 3, "y": 7, "z": 54, "name": "Wood_Beech_Branch_Long", "rotation": 5}, {"x": 3, "y": 11, "z": 54, "name": "Plant_Leaves_Beech"}, {"x": 3, "y": 12, "z": 54, "name": "Plant_Leaves_Beech"}, {"x": 3, "y": 13, "z": 54, "name": "Plant_Leaves_Beech"}, {"x": 3, "y": 15, "z": 54, "name": "Plant_Leaves_Beech"}, {"x": 3, "y": 16, "z": 54, "name": "Plant_Leaves_Beech"}, {"x": 3, "y": 0, "z": 55, "name": "Soil_Grass"}, {"x": 3, "y": 10, "z": 55, "name": "Plant_Leaves_Beech"}, {"x": 3, "y": 12, "z": 55, "name": "Plant_Leaves_Beech"}, {"x": 3, "y": 13, "z": 55, "name": "Plant_Leaves_Beech"}, {"x": 3, "y": 15, "z": 55, "name": "Plant_Leaves_Beech"}, {"x": 3, "y": 16, "z": 55, "name": "Plant_Leaves_Beech"}, {"x": 3, "y": 0, "z": 56, "name": "Soil_Grass"}, {"x": 3, "y": 10, "z": 56, "name": "Plant_Leaves_Beech"}, {"x": 3, "y": 11, "z": 56, "name": "Plant_Leaves_Beech"}, {"x": 3, "y": 15, "z": 56, "name": "Plant_Leaves_Beech"}, {"x": 3, "y": 0, "z": 57, "name": "Soil_Grass"}, {"x": 3, "y": 7, "z": 57, "name": "Plant_Leaves_Beech"}, {"x": 3, "y": 8, "z": 57, "name": "Plant_Leaves_Beech"}, {"x": 3, "y": 10, "z": 57, "name": "Plant_Leaves_Beech"}, {"x": 3, "y": 11, "z": 57, "name": "Plant_Leaves_Beech"}, {"x": 3, "y": 0, "z": 58, "name": "Soil_Grass"}, {"x": 3, "y": 0, "z": 59, "name": "Soil_Grass"}, {"x": 3, "y": 0, "z": 60, "name": "Soil_Grass"}, {"x": 3, "y": 0, "z": 61, "name": "Soil_Grass"}, {"x": 3, "y": 0, "z": 62, "name": "Soil_Grass"}, {"x": 3, "y": 0, "z": 63, "name": "Soil_Grass"}, {"x": 4, "y": 0, "z": 0, "name": "Soil_Grass"}, {"x": 4, "y": 7, "z": 0, "name": "Plant_Leaves_Beech"}, {"x": 4, "y": 0, "z": 1, "name": "Soil_Grass"}, {"x": 4, "y": 7, "z": 1, "name": "Plant_Leaves_Beech"}, {"x": 4, "y": 8, "z": 1, "name": "Plant_Leaves_Beech"}, {"x": 4, "y": 0, "z": 2, "name": "Soil_Grass"}, {"x": 4, "y": 7, "z": 2, "name": "Plant_Leaves_Beech"}, {"x": 4, "y": 11, "z": 2, "name": "Plant_Leaves_Beech"}, {"x": 4, "y": 0, "z": 3, "name": "Soil_Grass"}, {"x": 4, "y": 7, "z": 3, "name": "Plant_Leaves_Beech"}, {"x": 4, "y": 11, "z": 3, "name": "Plant_Leaves_Beech"}, {"x": 4, "y": 12, "z": 3, "name": "Plant_Leaves_Beech"}, {"x": 4, "y": 13, "z": 3, "name": "Plant_Leaves_Beech"}, {"x": 4, "y": 15, "z": 3, "name": "Plant_Leaves_Beech"}, {"x": 4, "y": 16, "z": 3, "name": "Plant_Leaves_Beech"}, {"x": 4, "y": 0, "z": 4, "name": "Soil_Grass"}, {"x": 4, "y": 7, "z": 4, "name": "Wood_Beech_Branch_Long", "rotation": 5}, {"x": 4, "y": 11, "z": 4, "name": "Plant_Leaves_Beech"}, {"x": 4, "y": 12, "z": 4, "name": "Plant_Leaves_Beech"}, {"x": 4, "y": 13, "z": 4, "name": "Plant_Leaves_Beech"}, {"x": 4, "y": 15, "z": 4, "name": "Plant_Leaves_Beech"}, {"x": 4, "y": 16, "z": 4, "name": "Plant_Leaves_Beech"}, {"x": 4, "y": 0, "z": 5, "name": "Soil_Grass"}, {"x": 4, "y": 10, "z": 5, "name": "Plant_Leaves_Beech"}, {"x": 4, "y": 12, "z": 5, "name": "Plant_Leaves_Beech"}, {"x": 4, "y": 13, "z": 5, "name": "Plant_Leaves_Beech"}, {"x": 4, "y": 15, "z": 5, "name": "Plant_Leaves_Beech"}, {"x": 4, "y": 16, "z": 5, "name": "Plant_Leaves_Beech"}, {"x": 4, "y": 0, "z": 6, "name": "Soil_Grass"}, {"x": 4, "y": 10, "z": 6, "name": "Plant_Leaves_Beech"}, {"x": 4, "y": 11, "z": 6, "name": "Plant_Leaves_Beech"}, {"x": 4, "y": 15, "z": 6, "name": "Plant_Leaves_Beech"}, {"x": 4, "y": 0, "z": 7, "name": "Soil_Grass"}, {"x": 4, "y": 7, "z": 7, "name": "Plant_Leaves_Beech"}, {"x": 4, "y": 8, "z": 7, "name": "Plant_Leaves_Beech"}, {"x": 4, "y": 10, "z": 7, "name": "Plant_Leaves_Beech"}, {"x": 4, "y": 11, "z": 7, "name": "Plant_Leaves_Beech"}, {"x": 4, "y": 0, "z": 8, "name": "Soil_Grass"}, {"x": 4, "y": 0, "z": 9, "name": "Soil_Grass"}, {"x": 4, "y": 7, "z": 9, "name": "Plant_Leaves_Beech"}, {"x": 4, "y": 9, "z": 9, "name": "Plant_Leaves_Beech"}, {"x": 4, "y": 0, "z": 10, "name": "Soil_Grass"}, {"x": 4, "y": 7, "z": 10, "name": "Plant_Leaves_Beech"}, {"x": 4, "y": 8, "z": 10, "name": "Plant_Leaves_Beech"}, {"x": 4, "y": 9, "z": 10, "name": "Plant_Leaves_Beech"}, {"x": 4, "y": 0, "z": 11, "name": "Soil_Grass"}, {"x": 4, "y": 12, "z": 11, "name": "Plant_Leaves_Beech"}, {"x": 4, "y": 13, "z": 11, "name": "Plant_Leaves_Beech"}, {"x": 4, "y": 16, "z": 11, "name": "Plant_Leaves_Beech"}, {"x": 4, "y": 17, "z": 11, "name": "Plant_Leaves_Beech"}, {"x": 4, "y": 0, "z": 12, "name": "Soil_Grass"}, {"x": 4, "y": 12, "z": 12, "name": "Plant_Leaves_Beech"}, {"x": 4, "y": 13, "z": 12, "name": "Plant_Leaves_Beech"}, {"x": 4, "y": 16, "z": 12, "name": "Plant_Leaves_Beech"}, {"x": 4, "y": 17, "z": 12, "name": "Plant_Leaves_Beech"}, {"x": 4, "y": 0, "z": 13, "name": "Soil_Grass"}, {"x": 4, "y": 7, "z": 13, "name": "Wood_Beech_Trunk_Full"}, {"x": 4, "y": 0, "z": 14, "name": "Soil_Grass"}, {"x": 4, "y": 19, "z": 14, "name": "Plant_Leaves_Beech"}, {"x": 4, "y": 20, "z": 14, "name": "Plant_Leaves_Beech"}, {"x": 4, "y": 0, "z": 15, "name": "Soil_Grass"}, {"x": 4, "y": 7, "z": 15, "name": "Wood_Beech_Trunk_Full"}, {"x": 4, "y": 12, "z": 15, "name": "Wood_Beech_Branch_Long", "rotation": 5}, {"x": 4, "y": 15, "z": 15, "name": "Wood_Beech_Trunk_Full"}, {"x": 4, "y": 17, "z": 15, "name": "Wood_Beech_Branch_Corner", "rotation": 3}, {"x": 4, "y": 18, "z": 15, "name": "Wood_Beech_Branch_Long"}, {"x": 4, "y": 19, "z": 15, "name": "Wood_Beech_Branch_Long"}, {"x": 4, "y": 20, "z": 15, "name": "Wood_Beech_Branch_Long"}, {"x": 4, "y": 21, "z": 15, "name": "Plant_Leaves_Beech"}, {"x": 4, "y": 0, "z": 16, "name": "Soil_Grass"}, {"x": 4, "y": 20, "z": 16, "name": "Plant_Leaves_Beech"}, {"x": 4, "y": 21, "z": 16, "name": "Plant_Leaves_Beech"}, {"x": 4, "y": 0, "z": 17, "name": "Soil_Grass"}, {"x": 4, "y": 10, "z": 17, "name": "Wood_Beech_Branch_Long", "rotation": 5}, {"x": 4, "y": 19, "z": 17, "name": "Plant_Leaves_Beech"}, {"x": 4, "y": 20, "z": 17, "name": "Plant_Leaves_Beech"}, {"x": 4, "y": 0, "z": 18, "name": "Soil_Grass"}, {"x": 4, "y": 14, "z": 18, "name": "Plant_Leaves_Beech"}, {"x": 4, "y": 15, "z": 18, "name": "Plant_Leaves_Beech"}, {"x": 4, "y": 16, "z": 18, "name": "Plant_Leaves_Beech"}, {"x": 4, "y": 19, "z": 18, "name": "Plant_Leaves_Beech"}, {"x": 4, "y": 0, "z": 19, "name": "Soil_Grass"}, {"x": 4, "y": 5, "z": 19, "name": "Plant_Leaves_Beech"}, {"x": 4, "y": 6, "z": 19, "name": "Plant_Leaves_Beech"}, {"x": 4, "y": 8, "z": 19, "name": "Plant_Leaves_Beech"}, {"x": 4, "y": 9, "z": 19, "name": "Plant_Leaves_Beech"}, {"x": 4, "y": 14, "z": 19, "name": "Plant_Leaves_Beech"}, {"x": 4, "y": 15, "z": 19, "name": "Plant_Leaves_Beech"}, {"x": 4, "y": 0, "z": 20, "name": "Soil_Grass"}, {"x": 4, "y": 5, "z": 20, "name": "Plant_Leaves_Beech"}, {"x": 4, "y": 6, "z": 20, "name": "Plant_Leaves_Beech"}, {"x": 4, "y": 7, "z": 20, "name": "Plant_Leaves_Beech"}, {"x": 4, "y": 8, "z": 20, "name": "Plant_Leaves_Beech"}, {"x": 4, "y": 10, "z": 20, "name": "Plant_Leaves_Beech"}, {"x": 4, "y": 11, "z": 20, "name": "Plant_Leaves_Beech"}, {"x": 4, "y": 0, "z": 21, "name": "Soil_Grass"}, {"x": 4, "y": 7, "z": 21, "name": "Plant_Leaves_Beech"}, {"x": 4, "y": 9, "z": 21, "name": "Plant_Leaves_Beech"}, {"x": 4, "y": 10, "z": 21, "name": "Plant_Leaves_Beech"}, {"x": 4, "y": 11, "z": 21, "name": "Plant_Leaves_Beech"}, {"x": 4, "y": 0, "z": 22, "name": "Soil_Grass"}, {"x": 4, "y": 7, "z": 22, "name": "Plant_Leaves_Beech"}, {"x": 4, "y": 8, "z": 22, "name": "Plant_Leaves_Beech"}, {"x": 4, "y": 9, "z": 22, "name": "Plant_Leaves_Beech"}, {"x": 4, "y": 0, "z": 23, "name": "Soil_Grass"}, {"x": 4, "y": 12, "z": 23, "name": "Plant_Leaves_Beech"}, {"x": 4, "y": 13, "z": 23, "name": "Plant_Leaves_Beech"}, {"x": 4, "y": 16, "z": 23, "name": "Plant_Leaves_Beech"}, {"x": 4, "y": 17, "z": 23, "name": "Plant_Leaves_Beech"}, {"x": 4, "y": 0, "z": 24, "name": "Soil_Grass"}, {"x": 4, "y": 12, "z": 24, "name": "Plant_Leaves_Beech"}, {"x": 4, "y": 13, "z": 24, "name": "Plant_Leaves_Beech"}, {"x": 4, "y": 16, "z": 24, "name": "Plant_Leaves_Beech"}, {"x": 4, "y": 17, "z": 24, "name": "Plant_Leaves_Beech"}, {"x": 4, "y": 0, "z": 25, "name": "Soil_Grass"}, {"x": 4, "y": 7, "z": 25, "name": "Wood_Beech_Trunk_Full"}, {"x": 4, "y": 0, "z": 26, "name": "Soil_Grass"}, {"x": 4, "y": 19, "z": 26, "name": "Plant_Leaves_Beech"}, {"x": 4, "y": 20, "z": 26, "name": "Plant_Leaves_Beech"}, {"x": 4, "y": 0, "z": 27, "name": "Soil_Grass"}, {"x": 4, "y": 7, "z": 27, "name": "Wood_Beech_Trunk_Full"}, {"x": 4, "y": 12, "z": 27, "name": "Wood_Beech_Branch_Long", "rotation": 5}, {"x": 4, "y": 15, "z": 27, "name": "Wood_Beech_Trunk_Full"}, {"x": 4, "y": 17, "z": 27, "name": "Wood_Beech_Branch_Corner", "rotation": 3}, {"x": 4, "y": 18, "z": 27, "name": "Wood_Beech_Branch_Long"}, {"x": 4, "y": 19, "z": 27, "name": "Wood_Beech_Branch_Long"}, {"x": 4, "y": 20, "z": 27, "name": "Wood_Beech_Branch_Long"}, {"x": 4, "y": 21, "z": 27, "name": "Plant_Leaves_Beech"}, {"x": 4, "y": 0, "z": 28, "name": "Soil_Grass"}, {"x": 4, "y": 20, "z": 28, "name": "Plant_Leaves_Beech"}, {"x": 4, "y": 21, "z": 28, "name": "Plant_Leaves_Beech"}, {"x": 4, "y": 0, "z": 29, "name": "Soil_Grass"}, {"x": 4, "y": 10, "z": 29, "name": "Wood_Beech_Branch_Long", "rotation": 5}, {"x": 4, "y": 19, "z": 29, "name": "Plant_Leaves_Beech"}, {"x": 4, "y": 20, "z": 29, "name": "Plant_Leaves_Beech"}, {"x": 4, "y": 0, "z": 30, "name": "Soil_Grass"}, {"x": 4, "y": 14, "z": 30, "name": "Plant_Leaves_Beech"}, {"x": 4, "y": 15, "z": 30, "name": "Plant_Leaves_Beech"}, {"x": 4, "y": 16, "z": 30, "name": "Plant_Leaves_Beech"}, {"x": 4, "y": 19, "z": 30, "name": "Plant_Leaves_Beech"}, {"x": 4, "y": 0, "z": 31, "name": "Soil_Grass"}, {"x": 4, "y": 5, "z": 31, "name": "Plant_Leaves_Beech"}, {"x": 4, "y": 6, "z": 31, "name": "Plant_Leaves_Beech"}, {"x": 4, "y": 8, "z": 31, "name": "Plant_Leaves_Beech"}, {"x": 4, "y": 9, "z": 31, "name": "Plant_Leaves_Beech"}, {"x": 4, "y": 14, "z": 31, "name": "Plant_Leaves_Beech"}, {"x": 4, "y": 15, "z": 31, "name": "Plant_Leaves_Beech"}, {"x": 4, "y": 0, "z": 32, "name": "Soil_Grass"}, {"x": 4, "y": 5, "z": 32, "name": "Plant_Leaves_Beech"}, {"x": 4, "y": 6, "z": 32, "name": "Plant_Leaves_Beech"}, {"x": 4, "y": 7, "z": 32, "name": "Plant_Leaves_Beech"}, {"x": 4, "y": 8, "z": 32, "name": "Plant_Leaves_Beech"}, {"x": 4, "y": 10, "z": 32, "name": "Plant_Leaves_Beech"}, {"x": 4, "y": 11, "z": 32, "name": "Plant_Leaves_Beech"}, {"x": 4, "y": 0, "z": 33, "name": "Soil_Grass"}, {"x": 4, "y": 10, "z": 33, "name": "Plant_Leaves_Beech"}, {"x": 4, "y": 11, "z": 33, "name": "Plant_Leaves_Beech"}, {"x": 4, "y": 0, "z": 34, "name": "Soil_Grass"}, {"x": 4, "y": 7, "z": 34, "name": "Plant_Leaves_Beech"}, {"x": 4, "y": 9, "z": 34, "name": "Plant_Leaves_Beech"}, {"x": 4, "y": 0, "z": 35, "name": "Soil_Grass"}, {"x": 4, "y": 7, "z": 35, "name": "Plant_Leaves_Beech"}, {"x": 4, "y": 8, "z": 35, "name": "Plant_Leaves_Beech"}, {"x": 4, "y": 9, "z": 35, "name": "Plant_Leaves_Beech"}, {"x": 4, "y": 0, "z": 36, "name": "Soil_Grass"}, {"x": 4, "y": 12, "z": 36, "name": "Plant_Leaves_Beech"}, {"x": 4, "y": 13, "z": 36, "name": "Plant_Leaves_Beech"}, {"x": 4, "y": 16, "z": 36, "name": "Plant_Leaves_Beech"}, {"x": 4, "y": 17, "z": 36, "name": "Plant_Leaves_Beech"}, {"x": 4, "y": 0, "z": 37, "name": "Soil_Grass"}, {"x": 4, "y": 12, "z": 37, "name": "Plant_Leaves_Beech"}, {"x": 4, "y": 13, "z": 37, "name": "Plant_Leaves_Beech"}, {"x": 4, "y": 16, "z": 37, "name": "Plant_Leaves_Beech"}, {"x": 4, "y": 17, "z": 37, "name": "Plant_Leaves_Beech"}, {"x": 4, "y": 0, "z": 38, "name": "Soil_Grass"}, {"x": 4, "y": 7, "z": 38, "name": "Wood_Beech_Trunk_Full"}, {"x": 4, "y": 0, "z": 39, "name": "Soil_Grass"}, {"x": 4, "y": 19, "z": 39, "name": "Plant_Leaves_Beech"}, {"x": 4, "y": 20, "z": 39, "name": "Plant_Leaves_Beech"}, {"x": 4, "y": 0, "z": 40, "name": "Soil_Grass"}, {"x": 4, "y": 7, "z": 40, "name": "Wood_Beech_Trunk_Full"}, {"x": 4, "y": 12, "z": 40, "name": "Wood_Beech_Branch_Long", "rotation": 5}, {"x": 4, "y": 15, "z": 40, "name": "Wood_Beech_Trunk_Full"}, {"x": 4, "y": 17, "z": 40, "name": "Wood_Beech_Branch_Corner", "rotation": 3}, {"x": 4, "y": 18, "z": 40, "name": "Wood_Beech_Branch_Long"}, {"x": 4, "y": 19, "z": 40, "name": "Wood_Beech_Branch_Long"}, {"x": 4, "y": 20, "z": 40, "name": "Wood_Beech_Branch_Long"}, {"x": 4, "y": 21, "z": 40, "name": "Plant_Leaves_Beech"}, {"x": 4, "y": 0, "z": 41, "name": "Soil_Grass"}, {"x": 4, "y": 20, "z": 41, "name": "Plant_Leaves_Beech"}, {"x": 4, "y": 21, "z": 41, "name": "Plant_Leaves_Beech"}, {"x": 4, "y": 0, "z": 42, "name": "Soil_Grass"}, {"x": 4, "y": 10, "z": 42, "name": "Wood_Beech_Branch_Long", "rotation": 5}, {"x": 4, "y": 19, "z": 42, "name": "Plant_Leaves_Beech"}, {"x": 4, "y": 20, "z": 42, "name": "Plant_Leaves_Beech"}, {"x": 4, "y": 0, "z": 43, "name": "Soil_Grass"}, {"x": 4, "y": 14, "z": 43, "name": "Plant_Leaves_Beech"}, {"x": 4, "y": 15, "z": 43, "name": "Plant_Leaves_Beech"}, {"x": 4, "y": 16, "z": 43, "name": "Plant_Leaves_Beech"}, {"x": 4, "y": 19, "z": 43, "name": "Plant_Leaves_Beech"}, {"x": 4, "y": 0, "z": 44, "name": "Soil_Grass"}, {"x": 4, "y": 5, "z": 44, "name": "Plant_Leaves_Beech"}, {"x": 4, "y": 6, "z": 44, "name": "Plant_Leaves_Beech"}, {"x": 4, "y": 8, "z": 44, "name": "Plant_Leaves_Beech"}, {"x": 4, "y": 9, "z": 44, "name": "Plant_Leaves_Beech"}, {"x": 4, "y": 14, "z": 44, "name": "Plant_Leaves_Beech"}, {"x": 4, "y": 15, "z": 44, "name": "Plant_Leaves_Beech"}, {"x": 4, "y": 0, "z": 45, "name": "Soil_Grass"}, {"x": 4, "y": 5, "z": 45, "name": "Plant_Leaves_Beech"}, {"x": 4, "y": 6, "z": 45, "name": "Plant_Leaves_Beech"}, {"x": 4, "y": 7, "z": 45, "name": "Plant_Leaves_Beech"}, {"x": 4, "y": 8, "z": 45, "name": "Plant_Leaves_Beech"}, {"x": 4, "y": 10, "z": 45, "name": "Plant_Leaves_Beech"}, {"x": 4, "y": 11, "z": 45, "name": "Plant_Leaves_Beech"}, {"x": 4, "y": 0, "z": 46, "name": "Soil_Grass"}, {"x": 4, "y": 10, "z": 46, "name": "Plant_Leaves_Beech"}, {"x": 4, "y": 11, "z": 46, "name": "Plant_Leaves_Beech"}, {"x": 4, "y": 0, "z": 47, "name": "Soil_Grass"}, {"x": 4, "y": 0, "z": 48, "name": "Soil_Grass"}, {"x": 4, "y": 0, "z": 49, "name": "Soil_Grass"}, {"x": 4, "y": 0, "z": 50, "name": "Soil_Grass"}, {"x": 4, "y": 11, "z": 50, "name": "Plant_Leaves_Beech"}, {"x": 4, "y": 0, "z": 51, "name": "Soil_Grass"}, {"x": 4, "y": 10, "z": 51, "name": "Plant_Leaves_Beech"}, {"x": 4, "y": 11, "z": 51, "name": "Plant_Leaves_Beech"}, {"x": 4, "y": 12, "z": 51, "name": "Plant_Leaves_Beech"}, {"x": 4, "y": 0, "z": 52, "name": "Soil_Grass"}, {"x": 4, "y": 10, "z": 52, "name": "Plant_Leaves_Beech"}, {"x": 4, "y": 15, "z": 52, "name": "Plant_Leaves_Beech"}, {"x": 4, "y": 16, "z": 52, "name": "Plant_Leaves_Beech"}, {"x": 4, "y": 0, "z": 53, "name": "Soil_Grass"}, {"x": 4, "y": 12, "z": 53, "name": "Plant_Leaves_Beech"}, {"x": 4, "y": 13, "z": 53, "name": "Plant_Leaves_Beech"}, {"x": 4, "y": 15, "z": 53, "name": "Plant_Leaves_Beech"}, {"x": 4, "y": 16, "z": 53, "name": "Plant_Leaves_Beech"}, {"x": 4, "y": 17, "z": 53, "name": "Plant_Leaves_Beech"}, {"x": 4, "y": 0, "z": 54, "name": "Soil_Grass"}, {"x": 4, "y": 7, "z": 54, "name": "Wood_Beech_Branch_Long", "rotation": 5}, {"x": 4, "y": 12, "z": 54, "name": "Wood_Beech_Branch_Long", "rotation": 5}, {"x": 4, "y": 13, "z": 54, "name": "Plant_Leaves_Beech"}, {"x": 4, "y": 15, "z": 54, "name": "Wood_Beech_Branch_Corner", "rotation": 3}, {"x": 4, "y": 16, "z": 54, "name": "Plant_Leaves_Beech"}, {"x": 4, "y": 17, "z": 54, "name": "Plant_Leaves_Beech"}, {"x": 4, "y": 0, "z": 55, "name": "Soil_Grass"}, {"x": 4, "y": 12, "z": 55, "name": "Plant_Leaves_Beech"}, {"x": 4, "y": 13, "z": 55, "name": "Plant_Leaves_Beech"}, {"x": 4, "y": 15, "z": 55, "name": "Plant_Leaves_Beech"}, {"x": 4, "y": 16, "z": 55, "name": "Plant_Leaves_Beech"}, {"x": 4, "y": 17, "z": 55, "name": "Plant_Leaves_Beech"}, {"x": 4, "y": 0, "z": 56, "name": "Soil_Grass"}, {"x": 4, "y": 10, "z": 56, "name": "Wood_Beech_Branch_Corner", "rotation": 3}, {"x": 4, "y": 11, "z": 56, "name": "Plant_Leaves_Beech"}, {"x": 4, "y": 15, "z": 56, "name": "Plant_Leaves_Beech"}, {"x": 4, "y": 16, "z": 56, "name": "Plant_Leaves_Beech"}, {"x": 4, "y": 0, "z": 57, "name": "Soil_Grass"}, {"x": 4, "y": 8, "z": 57, "name": "Plant_Leaves_Beech"}, {"x": 4, "y": 10, "z": 57, "name": "Plant_Leaves_Beech"}, {"x": 4, "y": 11, "z": 57, "name": "Plant_Leaves_Beech"}, {"x": 4, "y": 16, "z": 57, "name": "Plant_Leaves_Beech"}, {"x": 4, "y": 0, "z": 58, "name": "Soil_Grass"}, {"x": 4, "y": 7, "z": 58, "name": "Plant_Leaves_Beech"}, {"x": 4, "y": 8, "z": 58, "name": "Plant_Leaves_Beech"}, {"x": 4, "y": 0, "z": 59, "name": "Soil_Grass"}, {"x": 4, "y": 0, "z": 60, "name": "Soil_Grass"}, {"x": 4, "y": 0, "z": 61, "name": "Soil_Grass"}, {"x": 4, "y": 0, "z": 62, "name": "Soil_Grass"}, {"x": 4, "y": 0, "z": 63, "name": "Soil_Grass"}, {"x": 5, "y": 0, "z": 0, "name": "Soil_Grass"}, {"x": 5, "y": 11, "z": 0, "name": "Plant_Leaves_Beech"}, {"x": 5, "y": 0, "z": 1, "name": "Soil_Grass"}, {"x": 5, "y": 10, "z": 1, "name": "Plant_Leaves_Beech"}, {"x": 5, "y": 11, "z": 1, "name": "Plant_Leaves_Beech"}, {"x": 5, "y": 12, "z": 1, "name": "Plant_Leaves_Beech"}, {"x": 5, "y": 0, "z": 2, "name": "Soil_Grass"}, {"x": 5, "y": 10, "z": 2, "name": "Plant_Leaves_Beech"}, {"x": 5, "y": 15, "z": 2, "name": "Plant_Leaves_Beech"}, {"x": 5, "y": 16, "z": 2, "name": "Plant_Leaves_Beech"}, {"x": 5, "y": 0, "z": 3, "name": "Soil_Grass"}, {"x": 5, "y": 12, "z": 3, "name": "Plant_Leaves_Beech"}, {"x": 5, "y": 13, "z": 3, "name": "Plant_Leaves_Beech"}, {"x": 5, "y": 15, "z": 3, "name": "Plant_Leaves_Beech"}, {"x": 5, "y": 16, "z": 3, "name": "Plant_Leaves_Beech"}, {"x": 5, "y": 17, "z": 3, "name": "Plant_Leaves_Beech"}, {"x": 5, "y": 0, "z": 4, "name": "Soil_Grass"}, {"x": 5, "y": 7, "z": 4, "name": "Wood_Beech_Branch_Long", "rotation": 5}, {"x": 5, "y": 12, "z": 4, "name": "Wood_Beech_Branch_Long", "rotation": 5}, {"x": 5, "y": 13, "z": 4, "name": "Plant_Leaves_Beech"}, {"x": 5, "y": 15, "z": 4, "name": "Wood_Beech_Branch_Corner", "rotation": 3}, {"x": 5, "y": 16, "z": 4, "name": "Plant_Leaves_Beech"}, {"x": 5, "y": 17, "z": 4, "name": "Plant_Leaves_Beech"}, {"x": 5, "y": 0, "z": 5, "name": "Soil_Grass"}, {"x": 5, "y": 12, "z": 5, "name": "Plant_Leaves_Beech"}, {"x": 5, "y": 13, "z": 5, "name": "Plant_Leaves_Beech"}, {"x": 5, "y": 15, "z": 5, "name": "Plant_Leaves_Beech"}, {"x": 5, "y": 16, "z": 5, "name": "Plant_Leaves_Beech"}, {"x": 5, "y": 17, "z": 5, "name": "Plant_Leaves_Beech"}, {"x": 5, "y": 0, "z": 6, "name": "Soil_Grass"}, {"x": 5, "y": 10, "z": 6, "name": "Wood_Beech_Branch_Corner", "rotation": 3}, {"x": 5, "y": 11, "z": 6, "name": "Plant_Leaves_Beech"}, {"x": 5, "y": 15, "z": 6, "name": "Plant_Leaves_Beech"}, {"x": 5, "y": 16, "z": 6, "name": "Plant_Leaves_Beech"}, {"x": 5, "y": 0, "z": 7, "name": "Soil_Grass"}, {"x": 5, "y": 8, "z": 7, "name": "Plant_Leaves_Beech"}, {"x": 5, "y": 10, "z": 7, "name": "Plant_Leaves_Beech"}, {"x": 5, "y": 11, "z": 7, "name": "Plant_Leaves_Beech"}, {"x": 5, "y": 16, "z": 7, "name": "Plant_Leaves_Beech"}, {"x": 5, "y": 0, "z": 8, "name": "Soil_Grass"}, {"x": 5, "y": 7, "z": 8, "name": "Plant_Leaves_Beech"}, {"x": 5, "y": 8, "z": 8, "name": "Plant_Leaves_Beech"}, {"x": 5, "y": 0, "z": 9, "name": "Soil_Grass"}, {"x": 5, "y": 7, "z": 9, "name": "Plant_Leaves_Beech"}, {"x": 5, "y": 8, "z": 9, "name": "Plant_Leaves_Beech"}, {"x": 5, "y": 9, "z": 9, "name": "Plant_Leaves_Beech"}, {"x": 5, "y": 0, "z": 10, "name": "Soil_Grass"}, {"x": 5, "y": 7, "z": 10, "name": "Wood_Beech_Branch_Long", "rotation": 4}, {"x": 5, "y": 8, "z": 10, "name": "Plant_Leaves_Beech"}, {"x": 5, "y": 9, "z": 10, "name": "Plant_Leaves_Beech"}, {"x": 5, "y": 10, "z": 10, "name": "Plant_Leaves_Beech"}, {"x": 5, "y": 12, "z": 10, "name": "Plant_Leaves_Beech"}, {"x": 5, "y": 13, "z": 10, "name": "Plant_Leaves_Beech"}, {"x": 5, "y": 0, "z": 11, "name": "Soil_Grass"}, {"x": 5, "y": 7, "z": 11, "name": "Wood_Beech_Branch_Long", "rotation": 4}, {"x": 5, "y": 12, "z": 11, "name": "Plant_Leaves_Beech"}, {"x": 5, "y": 13, "z": 11, "name": "Plant_Leaves_Beech"}, {"x": 5, "y": 16, "z": 11, "name": "Plant_Leaves_Beech"}, {"x": 5, "y": 17, "z": 11, "name": "Plant_Leaves_Beech"}, {"x": 5, "y": 0, "z": 12, "name": "Soil_Grass"}, {"x": 5, "y": 7, "z": 12, "name": "Wood_Beech_Branch_Long", "rotation": 4}, {"x": 5, "y": 12, "z": 12, "name": "Wood_Beech_Branch_Long", "rotation": 4}, {"x": 5, "y": 13, "z": 12, "name": "Plant_Leaves_Beech"}, {"x": 5, "y": 15, "z": 12, "name": "Wood_Beech_Branch_Corner", "rotation": 2}, {"x": 5, "y": 16, "z": 12, "name": "Wood_Beech_Branch_Long"}, {"x": 5, "y": 17, "z": 12, "name": "Plant_Leaves_Beech"}, {"x": 5, "y": 18, "z": 12, "name": "Plant_Leaves_Beech"}, {"x": 5, "y": 19, "z": 12, "name": "Plant_Leaves_Beech"}, {"x": 5, "y": 0, "z": 13, "name": "Soil_Grass"}, {"x": 5, "y": 7, "z": 13, "name": "Wood_Beech_Trunk_Full"}, {"x": 5, "y": 12, "z": 13, "name": "Wood_Beech_Branch_Long", "rotation": 4}, {"x": 5, "y": 15, "z": 13, "name": "Wood_Beech_Trunk_Full"}, {"x": 5, "y": 18, "z": 13, "name": "Plant_Leaves_Beech"}, {"x": 5, "y": 19, "z": 13, "name": "Plant_Leaves_Beech"}, {"x": 5, "y": 0, "z": 14, "name": "Soil_Grass"}, {"x": 5, "y": 7, "z": 14, "name": "Wood_Beech_Trunk_Full"}, {"x": 5, "y": 12, "z": 14, "name": "Wood_Beech_Branch_Long", "rotation": 4}, {"x": 5, "y": 15, "z": 14, "name": "Wood_Beech_Trunk_Full"}, {"x": 5, "y": 18, "z": 14, "name": "Wood_Beech_Branch_Long", "rotation": 4}, {"x": 5, "y": 21, "z": 14, "name": "Plant_Leaves_Beech"}, {"x": 5, "y": 0, "z": 15, "name": "Soil_Dirt"}, {"x": 5, "y": 1, "z": 15, "name": "Wood_Beech_Trunk"}, {"x": 5, "y": 2, "z": 15, "name": "Wood_Beech_Trunk"}, {"x": 5, "y": 3, "z": 15, "name": "Wood_Beech_Trunk"}, {"x": 5, "y": 4, "z": 15, "name": "Wood_Beech_Trunk"}, {"x": 5, "y": 5, "z": 15, "name": "Wood_Beech_Trunk"}, {"x": 5, "y": 6, "z": 15, "name": "Wood_Beech_Trunk"}, {"x": 5, "y": 7, "z": 15, "name": "Wood_Beech_Trunk"}, {"x": 5, "y": 8, "z": 15, "name": "Wood_Beech_Trunk"}, {"x": 5, "y": 9, "z": 15, "name": "Wood_Beech_Trunk"}, {"x": 5, "y": 10, "z": 15, "name": "Wood_Beech_Trunk"}, {"x": 5, "y": 11, "z": 15, "name": "Wood_Beech_Trunk"}, {"x": 5, "y": 12, "z": 15, "name": "Wood_Beech_Trunk"}, {"x": 5, "y": 13, "z": 15, "name": "Wood_Beech_Trunk"}, {"x": 5, "y": 14, "z": 15, "name": "Wood_Beech_Trunk"}, {"x": 5, "y": 15, "z": 15, "name": "Wood_Beech_Trunk"}, {"x": 5, "y": 16, "z": 15, "name": "Wood_Beech_Trunk"}, {"x": 5, "y": 17, "z": 15, "name": "Wood_Beech_Trunk"}, {"x": 5, "y": 18, "z": 15, "name": "Wood_Beech_Trunk_Full"}, {"x": 5, "y": 22, "z": 15, "name": "Plant_Leaves_Beech"}, {"x": 5, "y": 0, "z": 16, "name": "Soil_Grass"}, {"x": 5, "y": 5, "z": 16, "name": "Wood_Beech_Branch_Long", "rotation": 4}, {"x": 5, "y": 10, "z": 16, "name": "Wood_Beech_Trunk_Full"}, {"x": 5, "y": 15, "z": 16, "name": "Wood_Beech_Branch_Long", "rotation": 4}, {"x": 5, "y": 18, "z": 16, "name": "Wood_Beech_Branch_Corner"}, {"x": 5, "y": 19, "z": 16, "name": "Plant_Leaves_Beech"}, {"x": 5, "y": 20, "z": 16, "name": "Plant_Leaves_Beech"}, {"x": 5, "y": 22, "z": 16, "name": "Plant_Leaves_Beech"}, {"x": 5, "y": 0, "z": 17, "name": "Soil_Grass"}, {"x": 5, "y": 5, "z": 17, "name": "Wood_Beech_Branch_Long", "rotation": 4}, {"x": 5, "y": 10, "z": 17, "name": "Wood_Beech_Trunk_Full"}, {"x": 5, "y": 15, "z": 17, "name": "Wood_Beech_Branch_Long", "rotation": 4}, {"x": 5, "y": 19, "z": 17, "name": "Plant_Leaves_Beech"}, {"x": 5, "y": 20, "z": 17, "name": "Plant_Leaves_Beech"}, {"x": 5, "y": 0, "z": 18, "name": "Soil_Grass"}, {"x": 5, "y": 5, "z": 18, "name": "Wood_Beech_Branch_Long", "rotation": 4}, {"x": 5, "y": 10, "z": 18, "name": "Wood_Beech_Branch_Long", "rotation": 4}, {"x": 5, "y": 15, "z": 18, "name": "Wood_Beech_Branch_Corner"}, {"x": 5, "y": 16, "z": 18, "name": "Plant_Leaves_Beech"}, {"x": 5, "y": 18, "z": 18, "name": "Plant_Leaves_Beech"}, {"x": 5, "y": 19, "z": 18, "name": "Plant_Leaves_Beech"}, {"x": 5, "y": 20, "z": 18, "name": "Plant_Leaves_Beech"}, {"x": 5, "y": 0, "z": 19, "name": "Soil_Grass"}, {"x": 5, "y": 5, "z": 19, "name": "Wood_Beech_Branch_Corner"}, {"x": 5, "y": 6, "z": 19, "name": "Plant_Leaves_Beech"}, {"x": 5, "y": 8, "z": 19, "name": "Plant_Leaves_Beech"}, {"x": 5, "y": 10, "z": 19, "name": "Wood_Beech_Branch_Long", "rotation": 4}, {"x": 5, "y": 14, "z": 19, "name": "Plant_Leaves_Beech"}, {"x": 5, "y": 15, "z": 19, "name": "Plant_Leaves_Beech"}, {"x": 5, "y": 16, "z": 19, "name": "Plant_Leaves_Beech"}, {"x": 5, "y": 0, "z": 20, "name": "Soil_Grass"}, {"x": 5, "y": 5, "z": 20, "name": "Plant_Leaves_Beech"}, {"x": 5, "y": 6, "z": 20, "name": "Plant_Leaves_Beech"}, {"x": 5, "y": 10, "z": 20, "name": "Wood_Beech_Branch_Corner"}, {"x": 5, "y": 11, "z": 20, "name": "Plant_Leaves_Beech"}, {"x": 5, "y": 12, "z": 20, "name": "Plant_Leaves_Beech"}, {"x": 5, "y": 0, "z": 21, "name": "Soil_Grass"}, {"x": 5, "y": 7, "z": 21, "name": "Plant_Leaves_Beech"}, {"x": 5, "y": 8, "z": 21, "name": "Plant_Leaves_Beech"}, {"x": 5, "y": 9, "z": 21, "name": "Plant_Leaves_Beech"}, {"x": 5, "y": 10, "z": 21, "name": "Plant_Leaves_Beech"}, {"x": 5, "y": 11, "z": 21, "name": "Plant_Leaves_Beech"}, {"x": 5, "y": 12, "z": 21, "name": "Plant_Leaves_Beech"}, {"x": 5, "y": 0, "z": 22, "name": "Soil_Grass"}, {"x": 5, "y": 7, "z": 22, "name": "Wood_Beech_Branch_Long", "rotation": 4}, {"x": 5, "y": 8, "z": 22, "name": "Plant_Leaves_Beech"}, {"x": 5, "y": 9, "z": 22, "name": "Plant_Leaves_Beech"}, {"x": 5, "y": 10, "z": 22, "name": "Plant_Leaves_Beech"}, {"x": 5, "y": 12, "z": 22, "name": "Plant_Leaves_Beech"}, {"x": 5, "y": 13, "z": 22, "name": "Plant_Leaves_Beech"}, {"x": 5, "y": 0, "z": 23, "name": "Soil_Grass"}, {"x": 5, "y": 7, "z": 23, "name": "Wood_Beech_Branch_Long", "rotation": 4}, {"x": 5, "y": 12, "z": 23, "name": "Plant_Leaves_Beech"}, {"x": 5, "y": 13, "z": 23, "name": "Plant_Leaves_Beech"}, {"x": 5, "y": 16, "z": 23, "name": "Plant_Leaves_Beech"}, {"x": 5, "y": 17, "z": 23, "name": "Plant_Leaves_Beech"}, {"x": 5, "y": 0, "z": 24, "name": "Soil_Grass"}, {"x": 5, "y": 7, "z": 24, "name": "Wood_Beech_Branch_Long", "rotation": 4}, {"x": 5, "y": 12, "z": 24, "name": "Wood_Beech_Branch_Long", "rotation": 4}, {"x": 5, "y": 13, "z": 24, "name": "Plant_Leaves_Beech"}, {"x": 5, "y": 15, "z": 24, "name": "Wood_Beech_Branch_Corner", "rotation": 2}, {"x": 5, "y": 16, "z": 24, "name": "Wood_Beech_Branch_Long"}, {"x": 5, "y": 17, "z": 24, "name": "Plant_Leaves_Beech"}, {"x": 5, "y": 18, "z": 24, "name": "Plant_Leaves_Beech"}, {"x": 5, "y": 19, "z": 24, "name": "Plant_Leaves_Beech"}, {"x": 5, "y": 0, "z": 25, "name": "Soil_Grass"}, {"x": 5, "y": 7, "z": 25, "name": "Wood_Beech_Trunk_Full"}, {"x": 5, "y": 12, "z": 25, "name": "Wood_Beech_Branch_Long", "rotation": 4}, {"x": 5, "y": 15, "z": 25, "name": "Wood_Beech_Trunk_Full"}, {"x": 5, "y": 18, "z": 25, "name": "Plant_Leaves_Beech"}, {"x": 5, "y": 19, "z": 25, "name": "Plant_Leaves_Beech"}, {"x": 5, "y": 0, "z": 26, "name": "Soil_Grass"}, {"x": 5, "y": 7, "z": 26, "name": "Wood_Beech_Trunk_Full"}, {"x": 5, "y": 12, "z": 26, "name": "Wood_Beech_Branch_Long", "rotation": 4}, {"x": 5, "y": 15, "z": 26, "name": "Wood_Beech_Trunk_Full"}, {"x": 5, "y": 18, "z": 26, "name": "Wood_Beech_Branch_Long", "rotation": 4}, {"x": 5, "y": 21, "z": 26, "name": "Plant_Leaves_Beech"}, {"x": 5, "y": 0, "z": 27, "name": "Soil_Dirt"}, {"x": 5, "y": 1, "z": 27, "name": "Wood_Beech_Trunk"}, {"x": 5, "y": 2, "z": 27, "name": "Wood_Beech_Trunk"}, {"x": 5, "y": 3, "z": 27, "name": "Wood_Beech_Trunk"}, {"x": 5, "y": 4, "z": 27, "name": "Wood_Beech_Trunk"}, {"x": 5, "y": 5, "z": 27, "name": "Wood_Beech_Trunk"}, {"x": 5, "y": 6, "z": 27, "name": "Wood_Beech_Trunk"}, {"x": 5, "y": 7, "z": 27, "name": "Wood_Beech_Trunk"}, {"x": 5, "y": 8, "z": 27, "name": "Wood_Beech_Trunk"}, {"x": 5, "y": 9, "z": 27, "name": "Wood_Beech_Trunk"}, {"x": 5, "y": 10, "z": 27, "name": "Wood_Beech_Trunk"}, {"x": 5, "y": 11, "z": 27, "name": "Wood_Beech_Trunk"}, {"x": 5, "y": 12, "z": 27, "name": "Wood_Beech_Trunk"}, {"x": 5, "y": 13, "z": 27, "name": "Wood_Beech_Trunk"}, {"x": 5, "y": 14, "z": 27, "name": "Wood_Beech_Trunk"}, {"x": 5, "y": 15, "z": 27, "name": "Wood_Beech_Trunk"}, {"x": 5, "y": 16, "z": 27, "name": "Wood_Beech_Trunk"}, {"x": 5, "y": 17, "z": 27, "name": "Wood_Beech_Trunk"}, {"x": 5, "y": 18, "z": 27, "name": "Wood_Beech_Trunk_Full"}, {"x": 5, "y": 22, "z": 27, "name": "Plant_Leaves_Beech"}, {"x": 5, "y": 0, "z": 28, "name": "Soil_Grass"}, {"x": 5, "y": 5, "z": 28, "name": "Wood_Beech_Branch_Long", "rotation": 4}, {"x": 5, "y": 10, "z": 28, "name": "Wood_Beech_Trunk_Full"}, {"x": 5, "y": 15, "z": 28, "name": "Wood_Beech_Branch_Long", "rotation": 4}, {"x": 5, "y": 18, "z": 28, "name": "Wood_Beech_Branch_Corner"}, {"x": 5, "y": 19, "z": 28, "name": "Plant_Leaves_Beech"}, {"x": 5, "y": 20, "z": 28, "name": "Plant_Leaves_Beech"}, {"x": 5, "y": 22, "z": 28, "name": "Plant_Leaves_Beech"}, {"x": 5, "y": 0, "z": 29, "name": "Soil_Grass"}, {"x": 5, "y": 5, "z": 29, "name": "Wood_Beech_Branch_Long", "rotation": 4}, {"x": 5, "y": 10, "z": 29, "name": "Wood_Beech_Trunk_Full"}, {"x": 5, "y": 15, "z": 29, "name": "Wood_Beech_Branch_Long", "rotation": 4}, {"x": 5, "y": 19, "z": 29, "name": "Plant_Leaves_Beech"}, {"x": 5, "y": 20, "z": 29, "name": "Plant_Leaves_Beech"}, {"x": 5, "y": 0, "z": 30, "name": "Soil_Grass"}, {"x": 5, "y": 5, "z": 30, "name": "Wood_Beech_Branch_Long", "rotation": 4}, {"x": 5, "y": 10, "z": 30, "name": "Wood_Beech_Branch_Long", "rotation": 4}, {"x": 5, "y": 15, "z": 30, "name": "Wood_Beech_Branch_Corner"}, {"x": 5, "y": 16, "z": 30, "name": "Plant_Leaves_Beech"}, {"x": 5, "y": 18, "z": 30, "name": "Plant_Leaves_Beech"}, {"x": 5, "y": 19, "z": 30, "name": "Plant_Leaves_Beech"}, {"x": 5, "y": 20, "z": 30, "name": "Plant_Leaves_Beech"}, {"x": 5, "y": 0, "z": 31, "name": "Soil_Grass"}, {"x": 5, "y": 5, "z": 31, "name": "Wood_Beech_Branch_Corner"}, {"x": 5, "y": 6, "z": 31, "name": "Plant_Leaves_Beech"}, {"x": 5, "y": 8, "z": 31, "name": "Plant_Leaves_Beech"}, {"x": 5, "y": 10, "z": 31, "name": "Wood_Beech_Branch_Long", "rotation": 4}, {"x": 5, "y": 14, "z": 31, "name": "Plant_Leaves_Beech"}, {"x": 5, "y": 15, "z": 31, "name": "Plant_Leaves_Beech"}, {"x": 5, "y": 16, "z": 31, "name": "Plant_Leaves_Beech"}, {"x": 5, "y": 0, "z": 32, "name": "Soil_Grass"}, {"x": 5, "y": 5, "z": 32, "name": "Plant_Leaves_Beech"}, {"x": 5, "y": 6, "z": 32, "name": "Plant_Leaves_Beech"}, {"x": 5, "y": 10, "z": 32, "name": "Wood_Beech_Branch_Corner"}, {"x": 5, "y": 11, "z": 32, "name": "Plant_Leaves_Beech"}, {"x": 5, "y": 12, "z": 32, "name": "Plant_Leaves_Beech"}, {"x": 5, "y": 0, "z": 33, "name": "Soil_Grass"}, {"x": 5, "y": 10, "z": 33, "name": "Plant_Leaves_Beech"}, {"x": 5, "y": 11, "z": 33, "name": "Plant_Leaves_Beech"}, {"x": 5, "y": 12, "z": 33, "name": "Plant_Leaves_Beech"}, {"x": 5, "y": 0, "z": 34, "name": "Soil_Grass"}, {"x": 5, "y": 7, "z": 34, "name": "Plant_Leaves_Beech"}, {"x": 5, "y": 8, "z": 34, "name": "Plant_Leaves_Beech"}, {"x": 5, "y": 9, "z": 34, "name": "Plant_Leaves_Beech"}, {"x": 5, "y": 0, "z": 35, "name": "Soil_Grass"}, {"x": 5, "y": 7, "z": 35, "name": "Wood_Beech_Branch_Long", "rotation": 4}, {"x": 5, "y": 8, "z": 35, "name": "Plant_Leaves_Beech"}, {"x": 5, "y": 9, "z": 35, "name": "Plant_Leaves_Beech"}, {"x": 5, "y": 10, "z": 35, "name": "Plant_Leaves_Beech"}, {"x": 5, "y": 12, "z": 35, "name": "Plant_Leaves_Beech"}, {"x": 5, "y": 13, "z": 35, "name": "Plant_Leaves_Beech"}, {"x": 5, "y": 0, "z": 36, "name": "Soil_Grass"}, {"x": 5, "y": 7, "z": 36, "name": "Wood_Beech_Branch_Long", "rotation": 4}, {"x": 5, "y": 12, "z": 36, "name": "Plant_Leaves_Beech"}, {"x": 5, "y": 13, "z": 36, "name": "Plant_Leaves_Beech"}, {"x": 5, "y": 16, "z": 36, "name": "Plant_Leaves_Beech"}, {"x": 5, "y": 17, "z": 36, "name": "Plant_Leaves_Beech"}, {"x": 5, "y": 0, "z": 37, "name": "Soil_Grass"}, {"x": 5, "y": 7, "z": 37, "name": "Wood_Beech_Branch_Long", "rotation": 4}, {"x": 5, "y": 12, "z": 37, "name": "Wood_Beech_Branch_Long", "rotation": 4}, {"x": 5, "y": 13, "z": 37, "name": "Plant_Leaves_Beech"}, {"x": 5, "y": 15, "z": 37, "name": "Wood_Beech_Branch_Corner", "rotation": 2}, {"x": 5, "y": 16, "z": 37, "name": "Wood_Beech_Branch_Long"}, {"x": 5, "y": 17, "z": 37, "name": "Plant_Leaves_Beech"}, {"x": 5, "y": 18, "z": 37, "name": "Plant_Leaves_Beech"}, {"x": 5, "y": 19, "z": 37, "name": "Plant_Leaves_Beech"}, {"x": 5, "y": 0, "z": 38, "name": "Soil_Grass"}, {"x": 5, "y": 7, "z": 38, "name": "Wood_Beech_Trunk_Full"}, {"x": 5, "y": 12, "z": 38, "name": "Wood_Beech_Branch_Long", "rotation": 4}, {"x": 5, "y": 15, "z": 38, "name": "Wood_Beech_Trunk_Full"}, {"x": 5, "y": 18, "z": 38, "name": "Plant_Leaves_Beech"}, {"x": 5, "y": 19, "z": 38, "name": "Plant_Leaves_Beech"}, {"x": 5, "y": 0, "z": 39, "name": "Soil_Grass"}, {"x": 5, "y": 7, "z": 39, "name": "Wood_Beech_Trunk_Full"}, {"x": 5, "y": 12, "z": 39, "name": "Wood_Beech_Branch_Long", "rotation": 4}, {"x": 5, "y": 15, "z": 39, "name": "Wood_Beech_Trunk_Full"}, {"x": 5, "y": 18, "z": 39, "name": "Wood_Beech_Branch_Long", "rotation": 4}, {"x": 5, "y": 21, "z": 39, "name": "Plant_Leaves_Beech"}, {"x": 5, "y": 0, "z": 40, "name": "Soil_Dirt"}, {"x": 5, "y": 1, "z": 40, "name": "Wood_Beech_Trunk"}, {"x": 5, "y": 2, "z": 40, "name": "Wood_Beech_Trunk"}, {"x": 5, "y": 3, "z": 40, "name": "Wood_Beech_Trunk"}, {"x": 5, "y": 4, "z": 40, "name": "Wood_Beech_Trunk"}, {"x": 5, "y": 5, "z": 40, "name": "Wood_Beech_Trunk"}, {"x": 5, "y": 6, "z": 40, "name": "Wood_Beech_Trunk"}, {"x": 5, "y": 7, "z": 40, "name": "Wood_Beech_Trunk"}, {"x": 5, "y": 8, "z": 40, "name": "Wood_Beech_Trunk"}, {"x": 5, "y": 9, "z": 40, "name": "Wood_Beech_Trunk"}, {"x": 5, "y": 10, "z": 40, "name": "Wood_Beech_Trunk"}, {"x": 5, "y": 11, "z": 40, "name": "Wood_Beech_Trunk"}, {"x": 5, "y": 12, "z": 40, "name": "Wood_Beech_Trunk"}, {"x": 5, "y": 13, "z": 40, "name": "Wood_Beech_Trunk"}, {"x": 5, "y": 14, "z": 40, "name": "Wood_Beech_Trunk"}, {"x": 5, "y": 15, "z": 40, "name": "Wood_Beech_Trunk"}, {"x": 5, "y": 16, "z": 40, "name": "Wood_Beech_Trunk"}, {"x": 5, "y": 17, "z": 40, "name": "Wood_Beech_Trunk"}, {"x": 5, "y": 18, "z": 40, "name": "Wood_Beech_Trunk_Full"}, {"x": 5, "y": 22, "z": 40, "name": "Plant_Leaves_Beech"}, {"x": 5, "y": 0, "z": 41, "name": "Soil_Grass"}, {"x": 5, "y": 5, "z": 41, "name": "Wood_Beech_Branch_Long", "rotation": 4}, {"x": 5, "y": 10, "z": 41, "name": "Wood_Beech_Trunk_Full"}, {"x": 5, "y": 15, "z": 41, "name": "Wood_Beech_Branch_Long", "rotation": 4}, {"x": 5, "y": 18, "z": 41, "name": "Wood_Beech_Branch_Corner"}, {"x": 5, "y": 19, "z": 41, "name": "Plant_Leaves_Beech"}, {"x": 5, "y": 20, "z": 41, "name": "Plant_Leaves_Beech"}, {"x": 5, "y": 22, "z": 41, "name": "Plant_Leaves_Beech"}, {"x": 5, "y": 0, "z": 42, "name": "Soil_Grass"}, {"x": 5, "y": 5, "z": 42, "name": "Wood_Beech_Branch_Long", "rotation": 4}, {"x": 5, "y": 10, "z": 42, "name": "Wood_Beech_Trunk_Full"}, {"x": 5, "y": 15, "z": 42, "name": "Wood_Beech_Branch_Long", "rotation": 4}, {"x": 5, "y": 19, "z": 42, "name": "Plant_Leaves_Beech"}, {"x": 5, "y": 20, "z": 42, "name": "Plant_Leaves_Beech"}, {"x": 5, "y": 0, "z": 43, "name": "Soil_Grass"}, {"x": 5, "y": 5, "z": 43, "name": "Wood_Beech_Branch_Long", "rotation": 4}, {"x": 5, "y": 10, "z": 43, "name": "Wood_Beech_Branch_Long", "rotation": 4}, {"x": 5, "y": 15, "z": 43, "name": "Wood_Beech_Branch_Corner"}, {"x": 5, "y": 16, "z": 43, "name": "Plant_Leaves_Beech"}, {"x": 5, "y": 18, "z": 43, "name": "Plant_Leaves_Beech"}, {"x": 5, "y": 19, "z": 43, "name": "Plant_Leaves_Beech"}, {"x": 5, "y": 20, "z": 43, "name": "Plant_Leaves_Beech"}, {"x": 5, "y": 0, "z": 44, "name": "Soil_Grass"}, {"x": 5, "y": 5, "z": 44, "name": "Wood_Beech_Branch_Corner"}, {"x": 5, "y": 6, "z": 44, "name": "Plant_Leaves_Beech"}, {"x": 5, "y": 8, "z": 44, "name": "Plant_Leaves_Beech"}, {"x": 5, "y": 10, "z": 44, "name": "Wood_Beech_Branch_Long", "rotation": 4}, {"x": 5, "y": 14, "z": 44, "name": "Plant_Leaves_Beech"}, {"x": 5, "y": 15, "z": 44, "name": "Plant_Leaves_Beech"}, {"x": 5, "y": 16, "z": 44, "name": "Plant_Leaves_Beech"}, {"x": 5, "y": 0, "z": 45, "name": "Soil_Grass"}, {"x": 5, "y": 5, "z": 45, "name": "Plant_Leaves_Beech"}, {"x": 5, "y": 6, "z": 45, "name": "Plant_Leaves_Beech"}, {"x": 5, "y": 10, "z": 45, "name": "Wood_Beech_Branch_Corner"}, {"x": 5, "y": 11, "z": 45, "name": "Plant_Leaves_Beech"}, {"x": 5, "y": 12, "z": 45, "name": "Plant_Leaves_Beech"}, {"x": 5, "y": 0, "z": 46, "name": "Soil_Grass"}, {"x": 5, "y": 10, "z": 46, "name": "Plant_Leaves_Beech"}, {"x": 5, "y": 11, "z": 46, "name": "Plant_Leaves_Beech"}, {"x": 5, "y": 12, "z": 46, "name": "Plant_Leaves_Beech"}, {"x": 5, "y": 0, "z": 47, "name": "Soil_Grass"}, {"x": 5, "y": 0, "z": 48, "name": "Soil_Grass"}, {"x": 5, "y": 7, "z": 48, "name": "Plant_Leaves_Beech"}, {"x": 5, "y": 8, "z": 48, "name": "Plant_Leaves_Beech"}, {"x": 5, "y": 0, "z": 49, "name": "Soil_Grass"}, {"x": 5, "y": 7, "z": 49, "name": "Plant_Leaves_Beech"}, {"x": 5, "y": 8, "z": 49, "name": "Plant_Leaves_Beech"}, {"x": 5, "y": 9, "z": 49, "name": "Plant_Leaves_Beech"}, {"x": 5, "y": 0, "z": 50, "name": "Soil_Grass"}, {"x": 5, "y": 11, "z": 50, "name": "Plant_Leaves_Beech"}, {"x": 5, "y": 12, "z": 50, "name": "Plant_Leaves_Beech"}, {"x": 5, "y": 16, "z": 50, "name": "Plant_Leaves_Beech"}, {"x": 5, "y": 0, "z": 51, "name": "Soil_Grass"}, {"x": 5, "y": 10, "z": 51, "name": "Plant_Leaves_Beech"}, {"x": 5, "y": 11, "z": 51, "name": "Plant_Leaves_Beech"}, {"x": 5, "y": 12, "z": 51, "name": "Plant_Leaves_Beech"}, {"x": 5, "y": 15, "z": 51, "name": "Plant_Leaves_Beech"}, {"x": 5, "y": 16, "z": 51, "name": "Plant_Leaves_Beech"}, {"x": 5, "y": 17, "z": 51, "name": "Plant_Leaves_Beech"}, {"x": 5, "y": 0, "z": 52, "name": "Soil_Grass"}, {"x": 5, "y": 7, "z": 52, "name": "Wood_Beech_Branch_Corner", "rotation": 3}, {"x": 5, "y": 8, "z": 52, "name": "Wood_Beech_Branch_Long"}, {"x": 5, "y": 9, "z": 52, "name": "Wood_Beech_Branch_Long"}, {"x": 5, "y": 10, "z": 52, "name": "Wood_Beech_Branch_Long"}, {"x": 5, "y": 11, "z": 52, "name": "Plant_Leaves_Beech"}, {"x": 5, "y": 15, "z": 52, "name": "Plant_Leaves_Beech"}, {"x": 5, "y": 0, "z": 53, "name": "Soil_Grass"}, {"x": 5, "y": 15, "z": 53, "name": "Wood_Beech_Branch_Long", "rotation": 4}, {"x": 5, "y": 17, "z": 53, "name": "Plant_Leaves_Beech"}, {"x": 5, "y": 19, "z": 53, "name": "Plant_Leaves_Beech"}, {"x": 5, "y": 20, "z": 53, "name": "Plant_Leaves_Beech"}, {"x": 5, "y": 0, "z": 54, "name": "Soil_Grass"}, {"x": 5, "y": 7, "z": 54, "name": "Wood_Beech_Trunk_Full"}, {"x": 5, "y": 12, "z": 54, "name": "Wood_Beech_Branch_Long", "rotation": 5}, {"x": 5, "y": 15, "z": 54, "name": "Wood_Beech_Trunk_Full"}, {"x": 5, "y": 17, "z": 54, "name": "Plant_Leaves_Beech"}, {"x": 5, "y": 18, "z": 54, "name": "Plant_Leaves_Beech"}, {"x": 5, "y": 20, "z": 54, "name": "Plant_Leaves_Beech"}, {"x": 5, "y": 0, "z": 55, "name": "Soil_Grass"}, {"x": 5, "y": 7, "z": 55, "name": "Wood_Beech_Branch_Long", "rotation": 4}, {"x": 5, "y": 15, "z": 55, "name": "Wood_Beech_Branch_Corner"}, {"x": 5, "y": 16, "z": 55, "name": "Wood_Beech_Branch_Long"}, {"x": 5, "y": 17, "z": 55, "name": "Wood_Beech_Branch_Long"}, {"x": 5, "y": 18, "z": 55, "name": "Plant_Leaves_Beech"}, {"x": 5, "y": 20, "z": 55, "name": "Plant_Leaves_Beech"}, {"x": 5, "y": 0, "z": 56, "name": "Soil_Grass"}, {"x": 5, "y": 7, "z": 56, "name": "Wood_Beech_Branch_Long", "rotation": 4}, {"x": 5, "y": 10, "z": 56, "name": "Wood_Beech_Branch_Long", "rotation": 5}, {"x": 5, "y": 17, "z": 56, "name": "Plant_Leaves_Beech"}, {"x": 5, "y": 0, "z": 57, "name": "Soil_Grass"}, {"x": 5, "y": 7, "z": 57, "name": "Wood_Beech_Branch_Long", "rotation": 4}, {"x": 5, "y": 9, "z": 57, "name": "Plant_Leaves_Beech"}, {"x": 5, "y": 14, "z": 57, "name": "Plant_Leaves_Beech"}, {"x": 5, "y": 15, "z": 57, "name": "Plant_Leaves_Beech"}, {"x": 5, "y": 16, "z": 57, "name": "Plant_Leaves_Beech"}, {"x": 5, "y": 17, "z": 57, "name": "Plant_Leaves_Beech"}, {"x": 5, "y": 0, "z": 58, "name": "Soil_Grass"}, {"x": 5, "y": 7, "z": 58, "name": "Wood_Beech_Branch_Corner"}, {"x": 5, "y": 8, "z": 58, "name": "Plant_Leaves_Beech"}, {"x": 5, "y": 9, "z": 58, "name": "Plant_Leaves_Beech"}, {"x": 5, "y": 0, "z": 59, "name": "Soil_Grass"}, {"x": 5, "y": 7, "z": 59, "name": "Plant_Leaves_Beech"}, {"x": 5, "y": 8, "z": 59, "name": "Plant_Leaves_Beech"}, {"x": 5, "y": 10, "z": 59, "name": "Plant_Leaves_Beech"}, {"x": 5, "y": 11, "z": 59, "name": "Plant_Leaves_Beech"}, {"x": 5, "y": 0, "z": 60, "name": "Soil_Grass"}, {"x": 5, "y": 0, "z": 61, "name": "Soil_Grass"}, {"x": 5, "y": 0, "z": 62, "name": "Soil_Grass"}, {"x": 5, "y": 0, "z": 63, "name": "Soil_Grass"}, {"x": 6, "y": 0, "z": 0, "name": "Soil_Grass"}, {"x": 6, "y": 11, "z": 0, "name": "Plant_Leaves_Beech"}, {"x": 6, "y": 12, "z": 0, "name": "Plant_Leaves_Beech"}, {"x": 6, "y": 16, "z": 0, "name": "Plant_Leaves_Beech"}, {"x": 6, "y": 0, "z": 1, "name": "Soil_Grass"}, {"x": 6, "y": 10, "z": 1, "name": "Plant_Leaves_Beech"}, {"x": 6, "y": 11, "z": 1, "name": "Plant_Leaves_Beech"}, {"x": 6, "y": 12, "z": 1, "name": "Plant_Leaves_Beech"}, {"x": 6, "y": 15, "z": 1, "name": "Plant_Leaves_Beech"}, {"x": 6, "y": 16, "z": 1, "name": "Plant_Leaves_Beech"}, {"x": 6, "y": 17, "z": 1, "name": "Plant_Leaves_Beech"}, {"x": 6, "y": 0, "z": 2, "name": "Soil_Grass"}, {"x": 6, "y": 7, "z": 2, "name": "Wood_Beech_Branch_Corner", "rotation": 3}, {"x": 6, "y": 8, "z": 2, "name": "Wood_Beech_Branch_Long"}, {"x": 6, "y": 9, "z": 2, "name": "Wood_Beech_Branch_Long"}, {"x": 6, "y": 10, "z": 2, "name": "Wood_Beech_Branch_Long"}, {"x": 6, "y": 11, "z": 2, "name": "Plant_Leaves_Beech"}, {"x": 6, "y": 15, "z": 2, "name": "Plant_Leaves_Beech"}, {"x": 6, "y": 0, "z": 3, "name": "Soil_Grass"}, {"x": 6, "y": 15, "z": 3, "name": "Wood_Beech_Branch_Long", "rotation": 4}, {"x": 6, "y": 17, "z": 3, "name": "Plant_Leaves_Beech"}, {"x": 6, "y": 19, "z": 3, "name": "Plant_Leaves_Beech"}, {"x": 6, "y": 20, "z": 3, "name": "Plant_Leaves_Beech"}, {"x": 6, "y": 0, "z": 4, "name": "Soil_Grass"}, {"x": 6, "y": 7, "z": 4, "name": "Wood_Beech_Trunk_Full"}, {"x": 6, "y": 12, "z": 4, "name": "Wood_Beech_Branch_Long", "rotation": 5}, {"x": 6, "y": 15, "z": 4, "name": "Wood_Beech_Trunk_Full"}, {"x": 6, "y": 17, "z": 4, "name": "Plant_Leaves_Beech"}, {"x": 6, "y": 18, "z": 4, "name": "Plant_Leaves_Beech"}, {"x": 6, "y": 20, "z": 4, "name": "Plant_Leaves_Beech"}, {"x": 6, "y": 0, "z": 5, "name": "Soil_Grass"}, {"x": 6, "y": 7, "z": 5, "name": "Wood_Beech_Branch_Long", "rotation": 4}, {"x": 6, "y": 15, "z": 5, "name": "Wood_Beech_Branch_Corner"}, {"x": 6, "y": 16, "z": 5, "name": "Wood_Beech_Branch_Long"}, {"x": 6, "y": 17, "z": 5, "name": "Wood_Beech_Branch_Long"}, {"x": 6, "y": 18, "z": 5, "name": "Plant_Leaves_Beech"}, {"x": 6, "y": 20, "z": 5, "name": "Plant_Leaves_Beech"}, {"x": 6, "y": 0, "z": 6, "name": "Soil_Grass"}, {"x": 6, "y": 7, "z": 6, "name": "Wood_Beech_Branch_Long", "rotation": 4}, {"x": 6, "y": 10, "z": 6, "name": "Wood_Beech_Branch_Long", "rotation": 5}, {"x": 6, "y": 17, "z": 6, "name": "Plant_Leaves_Beech"}, {"x": 6, "y": 0, "z": 7, "name": "Soil_Grass"}, {"x": 6, "y": 7, "z": 7, "name": "Wood_Beech_Branch_Long", "rotation": 4}, {"x": 6, "y": 9, "z": 7, "name": "Plant_Leaves_Beech"}, {"x": 6, "y": 14, "z": 7, "name": "Plant_Leaves_Beech"}, {"x": 6, "y": 15, "z": 7, "name": "Plant_Leaves_Beech"}, {"x": 6, "y": 16, "z": 7, "name": "Plant_Leaves_Beech"}, {"x": 6, "y": 17, "z": 7, "name": "Plant_Leaves_Beech"}, {"x": 6, "y": 0, "z": 8, "name": "Soil_Grass"}, {"x": 6, "y": 7, "z": 8, "name": "Wood_Beech_Branch_Corner"}, {"x": 6, "y": 8, "z": 8, "name": "Plant_Leaves_Beech"}, {"x": 6, "y": 9, "z": 8, "name": "Plant_Leaves_Beech"}, {"x": 6, "y": 0, "z": 9, "name": "Soil_Grass"}, {"x": 6, "y": 7, "z": 9, "name": "Plant_Leaves_Beech"}, {"x": 6, "y": 8, "z": 9, "name": "Plant_Leaves_Beech"}, {"x": 6, "y": 10, "z": 9, "name": "Plant_Leaves_Beech"}, {"x": 6, "y": 11, "z": 9, "name": "Plant_Leaves_Beech"}, {"x": 6, "y": 0, "z": 10, "name": "Soil_Grass"}, {"x": 6, "y": 7, "z": 10, "name": "Plant_Leaves_Beech"}, {"x": 6, "y": 8, "z": 10, "name": "Plant_Leaves_Beech"}, {"x": 6, "y": 9, "z": 10, "name": "Plant_Leaves_Beech"}, {"x": 6, "y": 10, "z": 10, "name": "Plant_Leaves_Beech"}, {"x": 6, "y": 11, "z": 10, "name": "Plant_Leaves_Beech"}, {"x": 6, "y": 12, "z": 10, "name": "Plant_Leaves_Beech"}, {"x": 6, "y": 0, "z": 11, "name": "Soil_Grass"}, {"x": 6, "y": 10, "z": 11, "name": "Plant_Leaves_Beech"}, {"x": 6, "y": 11, "z": 11, "name": "Plant_Leaves_Beech"}, {"x": 6, "y": 12, "z": 11, "name": "Plant_Leaves_Beech"}, {"x": 6, "y": 13, "z": 11, "name": "Plant_Leaves_Beech"}, {"x": 6, "y": 16, "z": 11, "name": "Plant_Leaves_Beech"}, {"x": 6, "y": 0, "z": 12, "name": "Soil_Grass"}, {"x": 6, "y": 10, "z": 12, "name": "Plant_Leaves_Beech"}, {"x": 6, "y": 11, "z": 12, "name": "Plant_Leaves_Beech"}, {"x": 6, "y": 12, "z": 12, "name": "Plant_Leaves_Beech"}, {"x": 6, "y": 13, "z": 12, "name": "Plant_Leaves_Beech"}, {"x": 6, "y": 16, "z": 12, "name": "Plant_Leaves_Beech"}, {"x": 6, "y": 17, "z": 12, "name": "Plant_Leaves_Beech"}, {"x": 6, "y": 0, "z": 13, "name": "Soil_Grass"}, {"x": 6, "y": 7, "z": 13, "name": "Wood_Beech_Trunk_Full"}, {"x": 6, "y": 8, "z": 13, "name": "Wood_Beech_Trunk_Full"}, {"x": 6, "y": 15, "z": 13, "name": "Wood_Beech_Branch_Long", "rotation": 5}, {"x": 6, "y": 18, "z": 13, "name": "Plant_Leaves_Beech"}, {"x": 6, "y": 19, "z": 13, "name": "Plant_Leaves_Beech"}, {"x": 6, "y": 0, "z": 14, "name": "Soil_Grass"}, {"x": 6, "y": 18, "z": 14, "name": "Plant_Leaves_Beech"}, {"x": 6, "y": 19, "z": 14, "name": "Plant_Leaves_Beech"}, {"x": 6, "y": 21, "z": 14, "name": "Plant_Leaves_Beech"}, {"x": 6, "y": 22, "z": 14, "name": "Plant_Leaves_Beech"}, {"x": 6, "y": 0, "z": 15, "name": "Soil_Grass"}, {"x": 6, "y": 6, "z": 15, "name": "Wood_Beech_Branch_Long", "rotation": 5}, {"x": 6, "y": 10, "z": 15, "name": "Wood_Beech_Trunk_Full"}, {"x": 6, "y": 13, "z": 15, "name": "Wood_Beech_Trunk_Full"}, {"x": 6, "y": 16, "z": 15, "name": "Wood_Beech_Branch_Long", "rotation": 5}, {"x": 6, "y": 18, "z": 15, "name": "Wood_Beech_Branch_Corner", "rotation": 1}, {"x": 6, "y": 19, "z": 15, "name": "Wood_Beech_Branch_Long"}, {"x": 6, "y": 20, "z": 15, "name": "Wood_Beech_Branch_Long"}, {"x": 6, "y": 21, "z": 15, "name": "Wood_Beech_Branch_Long"}, {"x": 6, "y": 22, "z": 15, "name": "Plant_Leaves_Beech"}, {"x": 6, "y": 0, "z": 16, "name": "Soil_Grass"}, {"x": 6, "y": 19, "z": 16, "name": "Plant_Leaves_Beech"}, {"x": 6, "y": 21, "z": 16, "name": "Plant_Leaves_Beech"}, {"x": 6, "y": 22, "z": 16, "name": "Plant_Leaves_Beech"}, {"x": 6, "y": 0, "z": 17, "name": "Soil_Grass"}, {"x": 6, "y": 19, "z": 17, "name": "Plant_Leaves_Beech"}, {"x": 6, "y": 20, "z": 17, "name": "Plant_Leaves_Beech"}, {"x": 6, "y": 0, "z": 18, "name": "Soil_Grass"}, {"x": 6, "y": 5, "z": 18, "name": "Plant_Leaves_Beech"}, {"x": 6, "y": 14, "z": 18, "name": "Plant_Leaves_Beech"}, {"x": 6, "y": 15, "z": 18, "name": "Plant_Leaves_Beech"}, {"x": 6, "y": 16, "z": 18, "name": "Plant_Leaves_Beech"}, {"x": 6, "y": 18, "z": 18, "name": "Plant_Leaves_Beech"}, {"x": 6, "y": 19, "z": 18, "name": "Plant_Leaves_Beech"}, {"x": 6, "y": 0, "z": 19, "name": "Soil_Grass"}, {"x": 6, "y": 5, "z": 19, "name": "Plant_Leaves_Beech"}, {"x": 6, "y": 6, "z": 19, "name": "Plant_Leaves_Beech"}, {"x": 6, "y": 11, "z": 19, "name": "Plant_Leaves_Beech"}, {"x": 6, "y": 12, "z": 19, "name": "Plant_Leaves_Beech"}, {"x": 6, "y": 14, "z": 19, "name": "Plant_Leaves_Beech"}, {"x": 6, "y": 15, "z": 19, "name": "Plant_Leaves_Beech"}, {"x": 6, "y": 0, "z": 20, "name": "Soil_Grass"}, {"x": 6, "y": 5, "z": 20, "name": "Plant_Leaves_Beech"}, {"x": 6, "y": 6, "z": 20, "name": "Plant_Leaves_Beech"}, {"x": 6, "y": 10, "z": 20, "name": "Plant_Leaves_Beech"}, {"x": 6, "y": 11, "z": 20, "name": "Plant_Leaves_Beech"}, {"x": 6, "y": 12, "z": 20, "name": "Plant_Leaves_Beech"}, {"x": 6, "y": 0, "z": 21, "name": "Soil_Grass"}, {"x": 6, "y": 5, "z": 21, "name": "Plant_Leaves_Beech"}, {"x": 6, "y": 7, "z": 21, "name": "Plant_Leaves_Beech"}, {"x": 6, "y": 8, "z": 21, "name": "Plant_Leaves_Beech"}, {"x": 6, "y": 10, "z": 21, "name": "Plant_Leaves_Beech"}, {"x": 6, "y": 11, "z": 21, "name": "Plant_Leaves_Beech"}, {"x": 6, "y": 0, "z": 22, "name": "Soil_Grass"}, {"x": 6, "y": 7, "z": 22, "name": "Plant_Leaves_Beech"}, {"x": 6, "y": 8, "z": 22, "name": "Plant_Leaves_Beech"}, {"x": 6, "y": 9, "z": 22, "name": "Plant_Leaves_Beech"}, {"x": 6, "y": 10, "z": 22, "name": "Plant_Leaves_Beech"}, {"x": 6, "y": 11, "z": 22, "name": "Plant_Leaves_Beech"}, {"x": 6, "y": 12, "z": 22, "name": "Plant_Leaves_Beech"}, {"x": 6, "y": 0, "z": 23, "name": "Soil_Grass"}, {"x": 6, "y": 10, "z": 23, "name": "Plant_Leaves_Beech"}, {"x": 6, "y": 11, "z": 23, "name": "Plant_Leaves_Beech"}, {"x": 6, "y": 12, "z": 23, "name": "Plant_Leaves_Beech"}, {"x": 6, "y": 13, "z": 23, "name": "Plant_Leaves_Beech"}, {"x": 6, "y": 16, "z": 23, "name": "Plant_Leaves_Beech"}, {"x": 6, "y": 0, "z": 24, "name": "Soil_Grass"}, {"x": 6, "y": 10, "z": 24, "name": "Plant_Leaves_Beech"}, {"x": 6, "y": 11, "z": 24, "name": "Plant_Leaves_Beech"}, {"x": 6, "y": 12, "z": 24, "name": "Plant_Leaves_Beech"}, {"x": 6, "y": 13, "z": 24, "name": "Plant_Leaves_Beech"}, {"x": 6, "y": 16, "z": 24, "name": "Plant_Leaves_Beech"}, {"x": 6, "y": 17, "z": 24, "name": "Plant_Leaves_Beech"}, {"x": 6, "y": 0, "z": 25, "name": "Soil_Grass"}, {"x": 6, "y": 7, "z": 25, "name": "Wood_Beech_Trunk_Full"}, {"x": 6, "y": 8, "z": 25, "name": "Wood_Beech_Trunk_Full"}, {"x": 6, "y": 15, "z": 25, "name": "Wood_Beech_Branch_Long", "rotation": 5}, {"x": 6, "y": 18, "z": 25, "name": "Plant_Leaves_Beech"}, {"x": 6, "y": 19, "z": 25, "name": "Plant_Leaves_Beech"}, {"x": 6, "y": 0, "z": 26, "name": "Soil_Grass"}, {"x": 6, "y": 18, "z": 26, "name": "Plant_Leaves_Beech"}, {"x": 6, "y": 19, "z": 26, "name": "Plant_Leaves_Beech"}, {"x": 6, "y": 21, "z": 26, "name": "Plant_Leaves_Beech"}, {"x": 6, "y": 22, "z": 26, "name": "Plant_Leaves_Beech"}, {"x": 6, "y": 0, "z": 27, "name": "Soil_Grass"}, {"x": 6, "y": 6, "z": 27, "name": "Wood_Beech_Branch_Long", "rotation": 5}, {"x": 6, "y": 10, "z": 27, "name": "Wood_Beech_Trunk_Full"}, {"x": 6, "y": 13, "z": 27, "name": "Wood_Beech_Trunk_Full"}, {"x": 6, "y": 16, "z": 27, "name": "Wood_Beech_Branch_Long", "rotation": 5}, {"x": 6, "y": 18, "z": 27, "name": "Wood_Beech_Branch_Corner", "rotation": 1}, {"x": 6, "y": 19, "z": 27, "name": "Wood_Beech_Branch_Long"}, {"x": 6, "y": 20, "z": 27, "name": "Wood_Beech_Branch_Long"}, {"x": 6, "y": 21, "z": 27, "name": "Wood_Beech_Branch_Long"}, {"x": 6, "y": 22, "z": 27, "name": "Plant_Leaves_Beech"}, {"x": 6, "y": 0, "z": 28, "name": "Soil_Grass"}, {"x": 6, "y": 19, "z": 28, "name": "Plant_Leaves_Beech"}, {"x": 6, "y": 21, "z": 28, "name": "Plant_Leaves_Beech"}, {"x": 6, "y": 22, "z": 28, "name": "Plant_Leaves_Beech"}, {"x": 6, "y": 0, "z": 29, "name": "Soil_Grass"}, {"x": 6, "y": 19, "z": 29, "name": "Plant_Leaves_Beech"}, {"x": 6, "y": 20, "z": 29, "name": "Plant_Leaves_Beech"}, {"x": 6, "y": 0, "z": 30, "name": "Soil_Grass"}, {"x": 6, "y": 5, "z": 30, "name": "Plant_Leaves_Beech"}, {"x": 6, "y": 14, "z": 30, "name": "Plant_Leaves_Beech"}, {"x": 6, "y": 15, "z": 30, "name": "Plant_Leaves_Beech"}, {"x": 6, "y": 16, "z": 30, "name": "Plant_Leaves_Beech"}, {"x": 6, "y": 18, "z": 30, "name": "Plant_Leaves_Beech"}, {"x": 6, "y": 19, "z": 30, "name": "Plant_Leaves_Beech"}, {"x": 6, "y": 0, "z": 31, "name": "Soil_Grass"}, {"x": 6, "y": 5, "z": 31, "name": "Plant_Leaves_Beech"}, {"x": 6, "y": 6, "z": 31, "name": "Plant_Leaves_Beech"}, {"x": 6, "y": 11, "z": 31, "name": "Plant_Leaves_Beech"}, {"x": 6, "y": 12, "z": 31, "name": "Plant_Leaves_Beech"}, {"x": 6, "y": 14, "z": 31, "name": "Plant_Leaves_Beech"}, {"x": 6, "y": 15, "z": 31, "name": "Plant_Leaves_Beech"}, {"x": 6, "y": 0, "z": 32, "name": "Soil_Grass"}, {"x": 6, "y": 5, "z": 32, "name": "Plant_Leaves_Beech"}, {"x": 6, "y": 6, "z": 32, "name": "Plant_Leaves_Beech"}, {"x": 6, "y": 10, "z": 32, "name": "Plant_Leaves_Beech"}, {"x": 6, "y": 11, "z": 32, "name": "Plant_Leaves_Beech"}, {"x": 6, "y": 12, "z": 32, "name": "Plant_Leaves_Beech"}, {"x": 6, "y": 0, "z": 33, "name": "Soil_Grass"}, {"x": 6, "y": 5, "z": 33, "name": "Plant_Leaves_Beech"}, {"x": 6, "y": 10, "z": 33, "name": "Plant_Leaves_Beech"}, {"x": 6, "y": 11, "z": 33, "name": "Plant_Leaves_Beech"}, {"x": 6, "y": 0, "z": 34, "name": "Soil_Grass"}, {"x": 6, "y": 7, "z": 34, "name": "Plant_Leaves_Beech"}, {"x": 6, "y": 8, "z": 34, "name": "Plant_Leaves_Beech"}, {"x": 6, "y": 0, "z": 35, "name": "Soil_Grass"}, {"x": 6, "y": 7, "z": 35, "name": "Plant_Leaves_Beech"}, {"x": 6, "y": 8, "z": 35, "name": "Plant_Leaves_Beech"}, {"x": 6, "y": 9, "z": 35, "name": "Plant_Leaves_Beech"}, {"x": 6, "y": 10, "z": 35, "name": "Plant_Leaves_Beech"}, {"x": 6, "y": 11, "z": 35, "name": "Plant_Leaves_Beech"}, {"x": 6, "y": 12, "z": 35, "name": "Plant_Leaves_Beech"}, {"x": 6, "y": 0, "z": 36, "name": "Soil_Grass"}, {"x": 6, "y": 10, "z": 36, "name": "Plant_Leaves_Beech"}, {"x": 6, "y": 11, "z": 36, "name": "Plant_Leaves_Beech"}, {"x": 6, "y": 12, "z": 36, "name": "Plant_Leaves_Beech"}, {"x": 6, "y": 13, "z": 36, "name": "Plant_Leaves_Beech"}, {"x": 6, "y": 16, "z": 36, "name": "Plant_Leaves_Beech"}, {"x": 6, "y": 0, "z": 37, "name": "Soil_Grass"}, {"x": 6, "y": 10, "z": 37, "name": "Plant_Leaves_Beech"}, {"x": 6, "y": 11, "z": 37, "name": "Plant_Leaves_Beech"}, {"x": 6, "y": 12, "z": 37, "name": "Plant_Leaves_Beech"}, {"x": 6, "y": 13, "z": 37, "name": "Plant_Leaves_Beech"}, {"x": 6, "y": 16, "z": 37, "name": "Plant_Leaves_Beech"}, {"x": 6, "y": 17, "z": 37, "name": "Plant_Leaves_Beech"}, {"x": 6, "y": 0, "z": 38, "name": "Soil_Grass"}, {"x": 6, "y": 7, "z": 38, "name": "Wood_Beech_Trunk_Full"}, {"x": 6, "y": 8, "z": 38, "name": "Wood_Beech_Trunk_Full"}, {"x": 6, "y": 15, "z": 38, "name": "Wood_Beech_Branch_Long", "rotation": 5}, {"x": 6, "y": 18, "z": 38, "name": "Plant_Leaves_Beech"}, {"x": 6, "y": 19, "z": 38, "name": "Plant_Leaves_Beech"}, {"x": 6, "y": 0, "z": 39, "name": "Soil_Grass"}, {"x": 6, "y": 18, "z": 39, "name": "Plant_Leaves_Beech"}, {"x": 6, "y": 19, "z": 39, "name": "Plant_Leaves_Beech"}, {"x": 6, "y": 21, "z": 39, "name": "Plant_Leaves_Beech"}, {"x": 6, "y": 22, "z": 39, "name": "Plant_Leaves_Beech"}, {"x": 6, "y": 0, "z": 40, "name": "Soil_Grass"}, {"x": 6, "y": 6, "z": 40, "name": "Wood_Beech_Branch_Long", "rotation": 5}, {"x": 6, "y": 10, "z": 40, "name": "Wood_Beech_Trunk_Full"}, {"x": 6, "y": 13, "z": 40, "name": "Wood_Beech_Trunk_Full"}, {"x": 6, "y": 16, "z": 40, "name": "Wood_Beech_Branch_Long", "rotation": 5}, {"x": 6, "y": 18, "z": 40, "name": "Wood_Beech_Branch_Corner", "rotation": 1}, {"x": 6, "y": 19, "z": 40, "name": "Wood_Beech_Branch_Long"}, {"x": 6, "y": 20, "z": 40, "name": "Wood_Beech_Branch_Long"}, {"x": 6, "y": 21, "z": 40, "name": "Wood_Beech_Branch_Long"}, {"x": 6, "y": 22, "z": 40, "name": "Plant_Leaves_Beech"}, {"x": 6, "y": 0, "z": 41, "name": "Soil_Grass"}, {"x": 6, "y": 19, "z": 41, "name": "Plant_Leaves_Beech"}, {"x": 6, "y": 21, "z": 41, "name": "Plant_Leaves_Beech"}, {"x": 6, "y": 22, "z": 41, "name": "Plant_Leaves_Beech"}, {"x": 6, "y": 0, "z": 42, "name": "Soil_Grass"}, {"x": 6, "y": 19, "z": 42, "name": "Plant_Leaves_Beech"}, {"x": 6, "y": 20, "z": 42, "name": "Plant_Leaves_Beech"}, {"x": 6, "y": 0, "z": 43, "name": "Soil_Grass"}, {"x": 6, "y": 5, "z": 43, "name": "Plant_Leaves_Beech"}, {"x": 6, "y": 14, "z": 43, "name": "Plant_Leaves_Beech"}, {"x": 6, "y": 15, "z": 43, "name": "Plant_Leaves_Beech"}, {"x": 6, "y": 16, "z": 43, "name": "Plant_Leaves_Beech"}, {"x": 6, "y": 18, "z": 43, "name": "Plant_Leaves_Beech"}, {"x": 6, "y": 19, "z": 43, "name": "Plant_Leaves_Beech"}, {"x": 6, "y": 0, "z": 44, "name": "Soil_Grass"}, {"x": 6, "y": 5, "z": 44, "name": "Plant_Leaves_Beech"}, {"x": 6, "y": 6, "z": 44, "name": "Plant_Leaves_Beech"}, {"x": 6, "y": 11, "z": 44, "name": "Plant_Leaves_Beech"}, {"x": 6, "y": 12, "z": 44, "name": "Plant_Leaves_Beech"}, {"x": 6, "y": 14, "z": 44, "name": "Plant_Leaves_Beech"}, {"x": 6, "y": 15, "z": 44, "name": "Plant_Leaves_Beech"}, {"x": 6, "y": 0, "z": 45, "name": "Soil_Grass"}, {"x": 6, "y": 5, "z": 45, "name": "Plant_Leaves_Beech"}, {"x": 6, "y": 6, "z": 45, "name": "Plant_Leaves_Beech"}, {"x": 6, "y": 10, "z": 45, "name": "Plant_Leaves_Beech"}, {"x": 6, "y": 11, "z": 45, "name": "Plant_Leaves_Beech"}, {"x": 6, "y": 12, "z": 45, "name": "Plant_Leaves_Beech"}, {"x": 6, "y": 0, "z": 46, "name": "Soil_Grass"}, {"x": 6, "y": 5, "z": 46, "name": "Plant_Leaves_Beech"}, {"x": 6, "y": 10, "z": 46, "name": "Plant_Leaves_Beech"}, {"x": 6, "y": 11, "z": 46, "name": "Plant_Leaves_Beech"}, {"x": 6, "y": 0, "z": 47, "name": "Soil_Grass"}, {"x": 6, "y": 0, "z": 48, "name": "Soil_Grass"}, {"x": 6, "y": 7, "z": 48, "name": "Plant_Leaves_Beech"}, {"x": 6, "y": 9, "z": 48, "name": "Plant_Leaves_Beech"}, {"x": 6, "y": 0, "z": 49, "name": "Soil_Grass"}, {"x": 6, "y": 7, "z": 49, "name": "Plant_Leaves_Beech"}, {"x": 6, "y": 8, "z": 49, "name": "Plant_Leaves_Beech"}, {"x": 6, "y": 9, "z": 49, "name": "Plant_Leaves_Beech"}, {"x": 6, "y": 0, "z": 50, "name": "Soil_Grass"}, {"x": 6, "y": 12, "z": 50, "name": "Plant_Leaves_Beech"}, {"x": 6, "y": 13, "z": 50, "name": "Plant_Leaves_Beech"}, {"x": 6, "y": 16, "z": 50, "name": "Plant_Leaves_Beech"}, {"x": 6, "y": 17, "z": 50, "name": "Plant_Leaves_Beech"}, {"x": 6, "y": 0, "z": 51, "name": "Soil_Grass"}, {"x": 6, "y": 12, "z": 51, "name": "Plant_Leaves_Beech"}, {"x": 6, "y": 13, "z": 51, "name": "Plant_Leaves_Beech"}, {"x": 6, "y": 16, "z": 51, "name": "Plant_Leaves_Beech"}, {"x": 6, "y": 17, "z": 51, "name": "Plant_Leaves_Beech"}, {"x": 6, "y": 0, "z": 52, "name": "Soil_Grass"}, {"x": 6, "y": 7, "z": 52, "name": "Wood_Beech_Trunk_Full"}, {"x": 6, "y": 0, "z": 53, "name": "Soil_Grass"}, {"x": 6, "y": 19, "z": 53, "name": "Plant_Leaves_Beech"}, {"x": 6, "y": 20, "z": 53, "name": "Plant_Leaves_Beech"}, {"x": 6, "y": 0, "z": 54, "name": "Soil_Grass"}, {"x": 6, "y": 7, "z": 54, "name": "Wood_Beech_Trunk_Full"}, {"x": 6, "y": 12, "z": 54, "name": "Wood_Beech_Branch_Long", "rotation": 5}, {"x": 6, "y": 15, "z": 54, "name": "Wood_Beech_Trunk_Full"}, {"x": 6, "y": 17, "z": 54, "name": "Wood_Beech_Branch_Corner", "rotation": 3}, {"x": 6, "y": 18, "z": 54, "name": "Wood_Beech_Branch_Long"}, {"x": 6, "y": 19, "z": 54, "name": "Wood_Beech_Branch_Long"}, {"x": 6, "y": 20, "z": 54, "name": "Wood_Beech_Branch_Long"}, {"x": 6, "y": 21, "z": 54, "name": "Plant_Leaves_Beech"}, {"x": 6, "y": 0, "z": 55, "name": "Soil_Grass"}, {"x": 6, "y": 20, "z": 55, "name": "Plant_Leaves_Beech"}, {"x": 6, "y": 21, "z": 55, "name": "Plant_Leaves_Beech"}, {"x": 6, "y": 0, "z": 56, "name": "Soil_Grass"}, {"x": 6, "y": 10, "z": 56, "name": "Wood_Beech_Branch_Long", "rotation": 5}, {"x": 6, "y": 19, "z": 56, "name": "Plant_Leaves_Beech"}, {"x": 6, "y": 20, "z": 56, "name": "Plant_Leaves_Beech"}, {"x": 6, "y": 0, "z": 57, "name": "Soil_Grass"}, {"x": 6, "y": 14, "z": 57, "name": "Plant_Leaves_Beech"}, {"x": 6, "y": 15, "z": 57, "name": "Plant_Leaves_Beech"}, {"x": 6, "y": 16, "z": 57, "name": "Plant_Leaves_Beech"}, {"x": 6, "y": 19, "z": 57, "name": "Plant_Leaves_Beech"}, {"x": 6, "y": 0, "z": 58, "name": "Soil_Grass"}, {"x": 6, "y": 5, "z": 58, "name": "Plant_Leaves_Beech"}, {"x": 6, "y": 6, "z": 58, "name": "Plant_Leaves_Beech"}, {"x": 6, "y": 8, "z": 58, "name": "Plant_Leaves_Beech"}, {"x": 6, "y": 9, "z": 58, "name": "Plant_Leaves_Beech"}, {"x": 6, "y": 14, "z": 58, "name": "Plant_Leaves_Beech"}, {"x": 6, "y": 15, "z": 58, "name": "Plant_Leaves_Beech"}, {"x": 6, "y": 0, "z": 59, "name": "Soil_Grass"}, {"x": 6, "y": 5, "z": 59, "name": "Plant_Leaves_Beech"}, {"x": 6, "y": 6, "z": 59, "name": "Plant_Leaves_Beech"}, {"x": 6, "y": 7, "z": 59, "name": "Plant_Leaves_Beech"}, {"x": 6, "y": 8, "z": 59, "name": "Plant_Leaves_Beech"}, {"x": 6, "y": 10, "z": 59, "name": "Plant_Leaves_Beech"}, {"x": 6, "y": 11, "z": 59, "name": "Plant_Leaves_Beech"},