{"version": 8, "blockIdVersion": 11, "anchorX": 0, "anchorY": 0, "anchorZ": 0, "blocks": [{"x": 0, "y": -3, "z": 0, "name": "Soil_Dirt"}, {"x": 0, "y": -2, "z": 0, "name": "Soil_Dirt"}, {"x": 0, "y": -1, "z": 0, "name": "Soil_Dirt"}, {"x": 0, "y": 0, "z": 0, "name": "Soil_Grass"}, {"x": 0, "y": -3, "z": 1, "name": "Soil_Dirt"}, {"x": 0, "y": -2, "z": 1, "name": "Soil_Dirt"}, {"x": 0, "y": -1, "z": 1, "name": "Soil_Dirt"}, {"x": 0, "y": 0, "z": 1, "name": "Soil_Grass"}, {"x": 0, "y": -3, "z": 2, "name": "Soil_Dirt"}, {"x": 0, "y": -2, "z": 2, "name": "Soil_Dirt"}, {"x": 0, "y": -1, "z": 2, "name": "Soil_Dirt"}, {"x": 0, "y": 0, "z": 2, "name": "Soil_Grass"}, {"x": 0, "y": -3, "z": 3, "name": "Soil_Dirt"}, {"x": 0, "y": -2, "z": 3, "name": "Soil_Dirt"}, {"x": 0, "y": -1, "z": 3, "name": "Soil_Dirt"}, {"x": 0, "y": 0, "z": 3, "name": "Soil_Grass"}, {"x": 0, "y": -3, "z": 4, "name": "Soil_Dirt"}, {"x": 0, "y": -2, "z": 4, "name": "Soil_Dirt"}, {"x": 0, "y": -1, "z": 4, "name": "Soil_Dirt"}, {"x": 0, "y": 0, "z": 4, "name": "Soil_Grass"}, {"x": 0, "y": -3, "z": 5, "name": "Soil_Dirt"}, {"x": 0, "y": -2, "z": 5, "name": "Soil_Dirt"}, {"x": 0, "y": -1, "z": 5, "name": "Soil_Dirt"}, {"x": 0, "y": 0, "z": 5, "name": "Soil_Grass"}, {"x": 0, "y": -3, "z": 6, "name": "Soil_Dirt"}, {"x": 0, "y": -2, "z": 6, "name": "Soil_Dirt"}, {"x": 0, "y": -1, "z": 6, "name": "Soil_Dirt"}, {"x": 0, "y": 0, "z": 6, "name": "Soil_Grass"}, {"x": 0, "y": -3, "z": 7, "name": "Soil_Dirt"}, {"x": 0, "y": -2, "z": 7, "name": "Soil_Dirt"}, {"x": 0, "y": -1, "z": 7, "name": "Soil_Dirt"}, {"x": 0, "y": 0, "z": 7, "name": "Soil_Grass"}, {"x": 0, "y": -3, "z": 8, "name": "Soil_Dirt"}, {"x": 0, "y": -2, "z": 8, "name": "Soil_Dirt"}, {"x": 0, "y": -1, "z": 8, "name": "Soil_Dirt"}, {"x": 0, "y": 0, "z": 8, "name": "Soil_Grass"}, {"x": 0, "y": 6, "z": 8, "name": "Soil_Grass", "rotation": 1}, {"x": 0, "y": -3, "z": 9, "name": "Soil_Dirt"}, {"x": 0, "y": -2, "z": 9, "name": "Soil_Dirt"}, {"x": 0, "y": -1, "z": 9, "name": "Soil_Dirt"}, {"x": 0, "y": 0, "z": 9, "name": "Soil_Grass"}, {"x": 0, "y": 5, "z": 9, "name": "Soil_Dirt"}, {"x": 0, "y": 6, "z": 9, "name": "Soil_Grass", "rotation": 1}, {"x": 0, "y": -3, "z": 10, "name": "Soil_Dirt"}, {"x": 0, "y": -2, "z": 10, "name": "Soil_Dirt"}, {"x": 0, "y": -1, "z": 10, "name": "Soil_Dirt"}, {"x": 0, "y": 0, "z": 10, "name": "Soil_Grass"}, {"x": 0, "y": 5, "z": 10, "name": "Soil_Dirt"}, {"x": 0, "y": 6, "z": 10, "name": "Soil_Grass", "rotation": 1}, {"x": 0, "y": -3, "z": 11, "name": "Soil_Dirt"}, {"x": 0, "y": -2, "z": 11, "name": "Soil_Dirt"}, {"x": 0, "y": -1, "z": 11, "name": "Soil_Dirt"}, {"x": 0, "y": 0, "z": 11, "name": "Soil_Grass"}, {"x": 0, "y": 5, "z": 11, "name": "Soil_Dirt"}, {"x": 0, "y": 6, "z": 11, "name": "Soil_Grass", "rotation": 1}, {"x": 0, "y": -3, "z": 12, "name": "Soil_Dirt"}, {"x": 0, "y": -2, "z": 12, "name": "Soil_Dirt"}, {"x": 0, "y": -1, "z": 12, "name": "Soil_Dirt"}, {"x": 0, "y": 0, "z": 12, "name": "Soil_Grass"}, {"x": 0, "y": 5, "z": 12, "name": "Rock_Basalt"}, {"x": 0, "y": 6, "z": 12, "name": "Soil_Grass", "rotation": 1}, {"x": 0, "y": -3, "z": 13, "name": "Soil_Dirt"}, {"x": 0, "y": -2, "z": 13, "name": "Soil_Dirt"}, {"x": 0, "y": -1, "z": 13, "name": "Soil_Dirt"}, {"x": 0, "y": 0, "z": 13, "name": "Soil_Grass"}, {"x": 0, "y": 5, "z": 13, "name": "Rock_Basalt"}, {"x": 0, "y": 6, "z": 13, "name": "Soil_Grass", "rotation": 1}, {"x": 0, "y": -3, "z": 14, "name": "Soil_Dirt"}, {"x": 0, "y": -2, "z": 14, "name": "Soil_Dirt"}, {"x": 0, "y": -1, "z": 14, "name": "Soil_Dirt"}, {"x": 0, "y": 0, "z": 14, "name": "Soil_Grass"}, {"x": 0, "y": 6, "z": 14, "name": "Soil_Grass", "rotation": 1}, {"x": 0, "y": -3, "z": 15, "name": "Soil_Dirt"}, {"x": 0, "y": -2, "z": 15, "name": "Soil_Dirt"}, {"x": 0, "y": -1, "z": 15, "name": "Soil_Dirt"}, {"x": 0, "y": 0, "z": 15, "name": "Soil_Grass"}, {"x": 0, "y": -3, "z": 16, "name": "Soil_Dirt"}, {"x": 0, "y": -2, "z": 16, "name": "Soil_Dirt"}, {"x": 0, "y": -1, "z": 16, "name": "Soil_Dirt"}, {"x": 0, "y": 0, "z": 16, "name": "Soil_Grass"}, {"x": 0, "y": -3, "z": 17, "name": "Soil_Dirt"}, {"x": 0, "y": -2, "z": 17, "name": "Soil_Dirt"}, {"x": 0, "y": -1, "z": 17, "name": "Soil_Dirt"}, {"x": 0, "y": 0, "z": 17, "name": "Soil_Grass"}, {"x": 0, "y": -3, "z": 18, "name": "Soil_Dirt"}, {"x": 0, "y": -2, "z": 18, "name": "Soil_Dirt"}, {"x": 0, "y": -1, "z": 18, "name": "Soil_Dirt"}, {"x": 0, "y": 0, "z": 18, "name": "Soil_Grass"}, {"x": 0, "y": -3, "z": 19, "name": "Soil_Dirt"}, {"x": 0, "y": -2, "z": 19, "name": "Soil_Dirt"}, {"x": 0, "y": -1, "z": 19, "name": "Soil_Dirt"}, {"x": 0, "y": 0, "z": 19, "name": "Soil_Grass"}, {"x": 0, "y": -3, "z": 20, "name": "Soil_Dirt"}, {"x": 0, "y": -2, "z": 20, "name": "Soil_Dirt"}, {"x": 0, "y": -1, "z": 20, "name": "Soil_Dirt"}, {"x": 0, "y": 0, "z": 20, "name": "Soil_Grass"}, {"x": 0, "y": -3, "z": 21, "name": "Soil_Dirt"}, {"x": 0, "y": -2, "z": 21, "name": "Soil_Dirt"}, {"x": 0, "y": -1, "z": 21, "name": "Soil_Dirt"}, {"x": 0, "y": 0, "z": 21, "name": "Soil_Grass"}, {"x": 0, "y": 6, "z": 21, "name": "Plant_Leaves_Beech"}, {"x": 0, "y": 11, "z": 21, "name": "Plant_Leaves_Beech"}, {"x": 0, "y": 12, "z": 21, "name": "Plant_Leaves_Beech"}, {"x": 0, "y": -3, "z": 22, "name": "Soil_Dirt"}, {"x": 0, "y": -2, "z": 22, "name": "Soil_Dirt"}, {"x": 0, "y": -1, "z": 22, "name": "Soil_Dirt"}, {"x": 0, "y": 0, "z": 22, "name": "Soil_Grass"}, {"x": 0, "y": 11, "z": 22, "name": "Plant_Leaves_Beech"}, {"x": 0, "y": 12, "z": 22, "name": "Plant_Leaves_Beech"}, {"x": 0, "y": 13, "z": 22, "name": "Plant_Leaves_Beech"}, {"x": 0, "y": -3, "z": 23, "name": "Soil_Dirt"}, {"x": 0, "y": -2, "z": 23, "name": "Soil_Dirt"}, {"x": 0, "y": -1, "z": 23, "name": "Soil_Dirt"}, {"x": 0, "y": 0, "z": 23, "name": "Soil_Grass"}, {"x": 0, "y": 11, "z": 23, "name": "Plant_Leaves_Beech"}, {"x": 0, "y": 12, "z": 23, "name": "Plant_Leaves_Beech"}, {"x": 0, "y": -3, "z": 24, "name": "Soil_Dirt"}, {"x": 0, "y": -2, "z": 24, "name": "Soil_Dirt"}, {"x": 0, "y": -1, "z": 24, "name": "Soil_Dirt"}, {"x": 0, "y": 0, "z": 24, "name": "Soil_Grass"}, {"x": 0, "y": -3, "z": 25, "name": "Soil_Dirt"}, {"x": 0, "y": -2, "z": 25, "name": "Soil_Dirt"}, {"x": 0, "y": -1, "z": 25, "name": "Soil_Dirt"}, {"x": 0, "y": 0, "z": 25, "name": "Soil_Grass"}, {"x": 0, "y": -3, "z": 26, "name": "Soil_Dirt"}, {"x": 0, "y": -2, "z": 26, "name": "Soil_Dirt"}, {"x": 0, "y": -1, "z": 26, "name": "Soil_Dirt"}, {"x": 0, "y": 0, "z": 26, "name": "Soil_Grass"}, {"x": 0, "y": -3, "z": 27, "name": "Soil_Dirt"}, {"x": 0, "y": -2, "z": 27, "name": "Soil_Dirt"}, {"x": 0, "y": -1, "z": 27, "name": "Soil_Dirt"}, {"x": 0, "y": 0, "z": 27, "name": "Soil_Grass"}, {"x": 0, "y": 7, "z": 27, "name": "Plant_Leaves_Beech"}, {"x": 0, "y": 11, "z": 27, "name": "Plant_Leaves_Beech"}, {"x": 0, "y": 14, "z": 27, "name": "Plant_Leaves_Beech"}, {"x": 0, "y": 15, "z": 27, "name": "Plant_Leaves_Beech"}, {"x": 0, "y": -3, "z": 28, "name": "Soil_Dirt"}, {"x": 0, "y": -2, "z": 28, "name": "Soil_Dirt"}, {"x": 0, "y": -1, "z": 28, "name": "Soil_Dirt"}, {"x": 0, "y": 0, "z": 28, "name": "Soil_Grass"}, {"x": 0, "y": 14, "z": 28, "name": "Plant_Leaves_Beech"}, {"x": 0, "y": 15, "z": 28, "name": "Plant_Leaves_Beech"}, {"x": 0, "y": -3, "z": 29, "name": "Soil_Dirt"}, {"x": 0, "y": -2, "z": 29, "name": "Soil_Dirt"}, {"x": 0, "y": -1, "z": 29, "name": "Soil_Dirt"}, {"x": 0, "y": 0, "z": 29, "name": "Soil_Grass"}, {"x": 0, "y": 6, "z": 29, "name": "Plant_Leaves_Beech"}, {"x": 0, "y": 14, "z": 29, "name": "Plant_Leaves_Beech"}, {"x": 0, "y": 15, "z": 29, "name": "Plant_Leaves_Beech"}, {"x": 0, "y": -3, "z": 30, "name": "Soil_Dirt"}, {"x": 0, "y": -2, "z": 30, "name": "Soil_Dirt"}, {"x": 0, "y": -1, "z": 30, "name": "Soil_Dirt"}, {"x": 0, "y": 0, "z": 30, "name": "Soil_Grass"}, {"x": 0, "y": 6, "z": 30, "name": "Plant_Leaves_Beech"}, {"x": 0, "y": 15, "z": 30, "name": "Plant_Leaves_Beech"}, {"x": 0, "y": -3, "z": 31, "name": "Soil_Dirt"}, {"x": 0, "y": -2, "z": 31, "name": "Soil_Dirt"}, {"x": 0, "y": -1, "z": 31, "name": "Soil_Dirt"}, {"x": 0, "y": 0, "z": 31, "name": "Soil_Grass"}, {"x": 0, "y": 6, "z": 31, "name": "Wood_Beech_Branch_Long", "rotation": 5}, {"x": 0, "y": 11, "z": 31, "name": "Wood_Beech_Branch_Long", "rotation": 5}, {"x": 1, "y": -3, "z": 0, "name": "Soil_Dirt"}, {"x": 1, "y": -2, "z": 0, "name": "Soil_Dirt"}, {"x": 1, "y": -1, "z": 0, "name": "Soil_Dirt"}, {"x": 1, "y": 0, "z": 0, "name": "Soil_Grass"}, {"x": 1, "y": -3, "z": 1, "name": "Soil_Dirt"}, {"x": 1, "y": -2, "z": 1, "name": "Soil_Dirt"}, {"x": 1, "y": -1, "z": 1, "name": "Soil_Dirt"}, {"x": 1, "y": 0, "z": 1, "name": "Soil_Grass"}, {"x": 1, "y": -3, "z": 2, "name": "Soil_Dirt"}, {"x": 1, "y": -2, "z": 2, "name": "Soil_Dirt"}, {"x": 1, "y": -1, "z": 2, "name": "Soil_Dirt"}, {"x": 1, "y": 0, "z": 2, "name": "Soil_Grass"}, {"x": 1, "y": -3, "z": 3, "name": "Soil_Dirt"}, {"x": 1, "y": -2, "z": 3, "name": "Soil_Dirt"}, {"x": 1, "y": -1, "z": 3, "name": "Soil_Dirt"}, {"x": 1, "y": 0, "z": 3, "name": "Soil_Grass"}, {"x": 1, "y": -3, "z": 4, "name": "Soil_Dirt"}, {"x": 1, "y": -2, "z": 4, "name": "Soil_Dirt"}, {"x": 1, "y": -1, "z": 4, "name": "Soil_Dirt"}, {"x": 1, "y": 0, "z": 4, "name": "Soil_Grass"}, {"x": 1, "y": -3, "z": 5, "name": "Soil_Dirt"}, {"x": 1, "y": -2, "z": 5, "name": "Soil_Dirt"}, {"x": 1, "y": -1, "z": 5, "name": "Soil_Dirt"}, {"x": 1, "y": 0, "z": 5, "name": "Soil_Grass"}, {"x": 1, "y": -3, "z": 6, "name": "Soil_Dirt"}, {"x": 1, "y": -2, "z": 6, "name": "Soil_Dirt"}, {"x": 1, "y": -1, "z": 6, "name": "Soil_Dirt"}, {"x": 1, "y": 0, "z": 6, "name": "Soil_Grass"}, {"x": 1, "y": 6, "z": 6, "name": "Soil_Grass", "rotation": 1}, {"x": 1, "y": -3, "z": 7, "name": "Soil_Dirt"}, {"x": 1, "y": -2, "z": 7, "name": "Soil_Dirt"}, {"x": 1, "y": -1, "z": 7, "name": "Soil_Dirt"}, {"x": 1, "y": 0, "z": 7, "name": "Soil_Grass"}, {"x": 1, "y": 3, "z": 7, "name": "Rock_Basalt"}, {"x": 1, "y": 4, "z": 7, "name": "Rock_Basalt"}, {"x": 1, "y": 5, "z": 7, "name": "Soil_Dirt"}, {"x": 1, "y": 6, "z": 7, "name": "Soil_Grass", "rotation": 1}, {"x": 1, "y": 7, "z": 7, "name": "Plant_Grass_Winter_Short", "rotation": 1}, {"x": 1, "y": -3, "z": 8, "name": "Soil_Dirt"}, {"x": 1, "y": -2, "z": 8, "name": "Soil_Dirt"}, {"x": 1, "y": -1, "z": 8, "name": "Soil_Dirt"}, {"x": 1, "y": 0, "z": 8, "name": "Soil_Grass"}, {"x": 1, "y": 2, "z": 8, "name": "Rock_Basalt"}, {"x": 1, "y": 3, "z": 8, "name": "Rock_Basalt"}, {"x": 1, "y": 4, "z": 8, "name": "Rock_Basalt"}, {"x": 1, "y": 5, "z": 8, "name": "Soil_Dirt"}, {"x": 1, "y": 6, "z": 8, "name": "Soil_Grass", "rotation": 1}, {"x": 1, "y": -3, "z": 9, "name": "Soil_Dirt"}, {"x": 1, "y": -2, "z": 9, "name": "Soil_Dirt"}, {"x": 1, "y": -1, "z": 9, "name": "Soil_Dirt"}, {"x": 1, "y": 0, "z": 9, "name": "Soil_Dirt"}, {"x": 1, "y": 1, "z": 9, "name": "Rock_Basalt"}, {"x": 1, "y": 2, "z": 9, "name": "Rock_Basalt"}, {"x": 1, "y": 3, "z": 9, "name": "Rock_Basalt"}, {"x": 1, "y": 4, "z": 9, "name": "Rock_Basalt"}, {"x": 1, "y": 5, "z": 9, "name": "Soil_Dirt"}, {"x": 1, "y": 6, "z": 9, "name": "Soil_Grass", "rotation": 1}, {"x": 1, "y": -3, "z": 10, "name": "Soil_Dirt"}, {"x": 1, "y": -2, "z": 10, "name": "Soil_Dirt"}, {"x": 1, "y": -1, "z": 10, "name": "Soil_Dirt"}, {"x": 1, "y": 0, "z": 10, "name": "Soil_Dirt"}, {"x": 1, "y": 1, "z": 10, "name": "Rock_Basalt"}, {"x": 1, "y": 2, "z": 10, "name": "Rock_Basalt"}, {"x": 1, "y": 3, "z": 10, "name": "Rock_Basalt"}, {"x": 1, "y": 4, "z": 10, "name": "Rock_Basalt"}, {"x": 1, "y": 5, "z": 10, "name": "Soil_Dirt"}, {"x": 1, "y": 6, "z": 10, "name": "Soil_Grass", "rotation": 1}, {"x": 1, "y": -3, "z": 11, "name": "Soil_Dirt"}, {"x": 1, "y": -2, "z": 11, "name": "Soil_Dirt"}, {"x": 1, "y": -1, "z": 11, "name": "Soil_Dirt"}, {"x": 1, "y": 0, "z": 11, "name": "Soil_Dirt"}, {"x": 1, "y": 1, "z": 11, "name": "Rock_Basalt"}, {"x": 1, "y": 2, "z": 11, "name": "Rock_Basalt"}, {"x": 1, "y": 3, "z": 11, "name": "Rock_Basalt"}, {"x": 1, "y": 4, "z": 11, "name": "Rock_Basalt"}, {"x": 1, "y": 5, "z": 11, "name": "Soil_Dirt"}, {"x": 1, "y": 6, "z": 11, "name": "Soil_Grass", "rotation": 1}, {"x": 1, "y": -3, "z": 12, "name": "Soil_Dirt"}, {"x": 1, "y": -2, "z": 12, "name": "Soil_Dirt"}, {"x": 1, "y": -1, "z": 12, "name": "Soil_Dirt"}, {"x": 1, "y": 0, "z": 12, "name": "Soil_Dirt"}, {"x": 1, "y": 1, "z": 12, "name": "Rock_Basalt"}, {"x": 1, "y": 2, "z": 12, "name": "Rock_Basalt"}, {"x": 1, "y": 3, "z": 12, "name": "Rock_Basalt"}, {"x": 1, "y": 4, "z": 12, "name": "Rock_Basalt"}, {"x": 1, "y": 5, "z": 12, "name": "Rock_Basalt"}, {"x": 1, "y": 6, "z": 12, "name": "Soil_Grass", "rotation": 1}, {"x": 1, "y": -3, "z": 13, "name": "Soil_Dirt"}, {"x": 1, "y": -2, "z": 13, "name": "Soil_Dirt"}, {"x": 1, "y": -1, "z": 13, "name": "Soil_Dirt"}, {"x": 1, "y": 0, "z": 13, "name": "Soil_Dirt"}, {"x": 1, "y": 1, "z": 13, "name": "Rock_Basalt"}, {"x": 1, "y": 2, "z": 13, "name": "Rock_Basalt"}, {"x": 1, "y": 3, "z": 13, "name": "Rock_Basalt"}, {"x": 1, "y": 4, "z": 13, "name": "Rock_Basalt"}, {"x": 1, "y": 5, "z": 13, "name": "Soil_Dirt"}, {"x": 1, "y": 6, "z": 13, "name": "Soil_Grass", "rotation": 1}, {"x": 1, "y": -3, "z": 14, "name": "Soil_Dirt"}, {"x": 1, "y": -2, "z": 14, "name": "Soil_Dirt"}, {"x": 1, "y": -1, "z": 14, "name": "Soil_Dirt"}, {"x": 1, "y": 0, "z": 14, "name": "Soil_Grass"}, {"x": 1, "y": 2, "z": 14, "name": "Rock_Basalt"}, {"x": 1, "y": 3, "z": 14, "name": "Rock_Basalt"}, {"x": 1, "y": 4, "z": 14, "name": "Rock_Basalt"}, {"x": 1, "y": 5, "z": 14, "name": "Soil_Dirt"}, {"x": 1, "y": 6, "z": 14, "name": "Soil_Grass", "rotation": 1}, {"x": 1, "y": -3, "z": 15, "name": "Soil_Dirt"}, {"x": 1, "y": -2, "z": 15, "name": "Soil_Dirt"}, {"x": 1, "y": -1, "z": 15, "name": "Soil_Dirt"}, {"x": 1, "y": 0, "z": 15, "name": "Soil_Grass"}, {"x": 1, "y": 3, "z": 15, "name": "Rock_Basalt"}, {"x": 1, "y": 4, "z": 15, "name": "Rock_Basalt"}, {"x": 1, "y": 5, "z": 15, "name": "Soil_Dirt"}, {"x": 1, "y": 6, "z": 15, "name": "Soil_Grass", "rotation": 1}, {"x": 1, "y": -3, "z": 16, "name": "Soil_Dirt"}, {"x": 1, "y": -2, "z": 16, "name": "Soil_Dirt"}, {"x": 1, "y": -1, "z": 16, "name": "Soil_Dirt"}, {"x": 1, "y": 0, "z": 16, "name": "Soil_Grass"}, {"x": 1, "y": 5, "z": 16, "name": "Soil_Dirt"}, {"x": 1, "y": 6, "z": 16, "name": "Soil_Grass", "rotation": 1}, {"x": 1, "y": -3, "z": 17, "name": "Soil_Dirt"}, {"x": 1, "y": -2, "z": 17, "name": "Soil_Dirt"}, {"x": 1, "y": -1, "z": 17, "name": "Soil_Dirt"}, {"x": 1, "y": 0, "z": 17, "name": "Soil_Grass"}, {"x": 1, "y": -3, "z": 18, "name": "Soil_Dirt"}, {"x": 1, "y": -2, "z": 18, "name": "Soil_Dirt"}, {"x": 1, "y": -1, "z": 18, "name": "Soil_Dirt"}, {"x": 1, "y": 0, "z": 18, "name": "Soil_Grass"}, {"x": 1, "y": -3, "z": 19, "name": "Soil_Dirt"}, {"x": 1, "y": -2, "z": 19, "name": "Soil_Dirt"}, {"x": 1, "y": -1, "z": 19, "name": "Soil_Dirt"}, {"x": 1, "y": 0, "z": 19, "name": "Soil_Grass"}, {"x": 1, "y": -3, "z": 20, "name": "Soil_Dirt"}, {"x": 1, "y": -2, "z": 20, "name": "Soil_Dirt"}, {"x": 1, "y": -1, "z": 20, "name": "Soil_Dirt"}, {"x": 1, "y": 0, "z": 20, "name": "Soil_Grass"}, {"x": 1, "y": -3, "z": 21, "name": "Soil_Dirt"}, {"x": 1, "y": -2, "z": 21, "name": "Soil_Dirt"}, {"x": 1, "y": -1, "z": 21, "name": "Soil_Dirt"}, {"x": 1, "y": 0, "z": 21, "name": "Soil_Grass"}, {"x": 1, "y": -3, "z": 22, "name": "Soil_Dirt"}, {"x": 1, "y": -2, "z": 22, "name": "Soil_Dirt"}, {"x": 1, "y": -1, "z": 22, "name": "Soil_Dirt"}, {"x": 1, "y": 0, "z": 22, "name": "Soil_Grass"}, {"x": 1, "y": -3, "z": 23, "name": "Soil_Dirt"}, {"x": 1, "y": -2, "z": 23, "name": "Soil_Dirt"}, {"x": 1, "y": -1, "z": 23, "name": "Soil_Dirt"}, {"x": 1, "y": 0, "z": 23, "name": "Soil_Grass"}, {"x": 1, "y": -3, "z": 24, "name": "Soil_Dirt"}, {"x": 1, "y": -2, "z": 24, "name": "Soil_Dirt"}, {"x": 1, "y": -1, "z": 24, "name": "Soil_Dirt"}, {"x": 1, "y": 0, "z": 24, "name": "Soil_Grass"}, {"x": 1, "y": -3, "z": 25, "name": "Soil_Dirt"}, {"x": 1, "y": -2, "z": 25, "name": "Soil_Dirt"}, {"x": 1, "y": -1, "z": 25, "name": "Soil_Dirt"}, {"x": 1, "y": 0, "z": 25, "name": "Soil_Grass"}, {"x": 1, "y": -3, "z": 26, "name": "Soil_Dirt"}, {"x": 1, "y": -2, "z": 26, "name": "Soil_Dirt"}, {"x": 1, "y": -1, "z": 26, "name": "Soil_Dirt"}, {"x": 1, "y": 0, "z": 26, "name": "Soil_Grass"}, {"x": 1, "y": -3, "z": 27, "name": "Soil_Dirt"}, {"x": 1, "y": -2, "z": 27, "name": "Soil_Dirt"}, {"x": 1, "y": -1, "z": 27, "name": "Soil_Dirt"}, {"x": 1, "y": 0, "z": 27, "name": "Soil_Grass"}, {"x": 1, "y": 14, "z": 27, "name": "Plant_Leaves_Beech"}, {"x": 1, "y": -3, "z": 28, "name": "Soil_Dirt"}, {"x": 1, "y": -2, "z": 28, "name": "Soil_Dirt"}, {"x": 1, "y": -1, "z": 28, "name": "Soil_Dirt"}, {"x": 1, "y": 0, "z": 28, "name": "Soil_Grass"}, {"x": 1, "y": 14, "z": 28, "name": "Plant_Leaves_Beech"}, {"x": 1, "y": 15, "z": 28, "name": "Plant_Leaves_Beech"}, {"x": 1, "y": -3, "z": 29, "name": "Soil_Dirt"}, {"x": 1, "y": -2, "z": 29, "name": "Soil_Dirt"}, {"x": 1, "y": -1, "z": 29, "name": "Soil_Dirt"}, {"x": 1, "y": 0, "z": 29, "name": "Soil_Grass"}, {"x": 1, "y": 6, "z": 29, "name": "Plant_Leaves_Beech"}, {"x": 1, "y": 12, "z": 29, "name": "Plant_Leaves_Beech"}, {"x": 1, "y": 15, "z": 29, "name": "Plant_Leaves_Beech"}, {"x": 1, "y": -3, "z": 30, "name": "Soil_Dirt"}, {"x": 1, "y": -2, "z": 30, "name": "Soil_Dirt"}, {"x": 1, "y": -1, "z": 30, "name": "Soil_Dirt"}, {"x": 1, "y": 0, "z": 30, "name": "Soil_Grass"}, {"x": 1, "y": 6, "z": 30, "name": "Plant_Leaves_Beech"}, {"x": 1, "y": 7, "z": 30, "name": "Plant_Leaves_Beech"}, {"x": 1, "y": 12, "z": 30, "name": "Plant_Leaves_Beech"}, {"x": 1, "y": 13, "z": 30, "name": "Plant_Leaves_Beech"}, {"x": 1, "y": 15, "z": 30, "name": "Plant_Leaves_Beech"}, {"x": 1, "y": -3, "z": 31, "name": "Soil_Dirt"}, {"x": 1, "y": -2, "z": 31, "name": "Soil_Dirt"}, {"x": 1, "y": -1, "z": 31, "name": "Soil_Dirt"}, {"x": 1, "y": 0, "z": 31, "name": "Soil_Grass"}, {"x": 1, "y": 6, "z": 31, "name": "Wood_Beech_Branch_Corner", "rotation": 1}, {"x": 1, "y": 7, "z": 31, "name": "Plant_Leaves_Beech"}, {"x": 1, "y": 9, "z": 31, "name": "Plant_Leaves_Beech"}, {"x": 1, "y": 11, "z": 31, "name": "Wood_Beech_Branch_Long", "rotation": 5}, {"x": 1, "y": 15, "z": 31, "name": "Plant_Leaves_Beech"}, {"x": 2, "y": -3, "z": 0, "name": "Soil_Dirt"}, {"x": 2, "y": -2, "z": 0, "name": "Soil_Dirt"}, {"x": 2, "y": -1, "z": 0, "name": "Soil_Dirt"}, {"x": 2, "y": 0, "z": 0, "name": "Soil_Grass"}, {"x": 2, "y": -3, "z": 1, "name": "Soil_Dirt"}, {"x": 2, "y": -2, "z": 1, "name": "Soil_Dirt"}, {"x": 2, "y": -1, "z": 1, "name": "Soil_Dirt"}, {"x": 2, "y": 0, "z": 1, "name": "Soil_Grass"}, {"x": 2, "y": -3, "z": 2, "name": "Soil_Dirt"}, {"x": 2, "y": -2, "z": 2, "name": "Soil_Dirt"}, {"x": 2, "y": -1, "z": 2, "name": "Soil_Dirt"}, {"x": 2, "y": 0, "z": 2, "name": "Soil_Grass"}, {"x": 2, "y": -3, "z": 3, "name": "Soil_Dirt"}, {"x": 2, "y": -2, "z": 3, "name": "Soil_Dirt"}, {"x": 2, "y": -1, "z": 3, "name": "Soil_Dirt"}, {"x": 2, "y": 0, "z": 3, "name": "Soil_Grass"}, {"x": 2, "y": -3, "z": 4, "name": "Soil_Dirt"}, {"x": 2, "y": -2, "z": 4, "name": "Soil_Dirt"}, {"x": 2, "y": -1, "z": 4, "name": "Soil_Dirt"}, {"x": 2, "y": 0, "z": 4, "name": "Soil_Grass"}, {"x": 2, "y": -3, "z": 5, "name": "Soil_Dirt"}, {"x": 2, "y": -2, "z": 5, "name": "Soil_Dirt"}, {"x": 2, "y": -1, "z": 5, "name": "Soil_Dirt"}, {"x": 2, "y": 0, "z": 5, "name": "Soil_Grass"}, {"x": 2, "y": 3, "z": 5, "name": "Rock_Basalt"}, {"x": 2, "y": 4, "z": 5, "name": "Rock_Basalt"}, {"x": 2, "y": 5, "z": 5, "name": "Soil_Dirt"}, {"x": 2, "y": 6, "z": 5, "name": "Soil_Grass", "rotation": 1}, {"x": 2, "y": -3, "z": 6, "name": "Soil_Dirt"}, {"x": 2, "y": -2, "z": 6, "name": "Soil_Dirt"}, {"x": 2, "y": -1, "z": 6, "name": "Soil_Dirt"}, {"x": 2, "y": 0, "z": 6, "name": "Soil_Dirt"}, {"x": 2, "y": 1, "z": 6, "name": "Rock_Basalt"}, {"x": 2, "y": 2, "z": 6, "name": "Rock_Basalt"}, {"x": 2, "y": 3, "z": 6, "name": "Rock_Basalt"}, {"x": 2, "y": 4, "z": 6, "name": "Rock_Basalt"}, {"x": 2, "y": 5, "z": 6, "name": "Soil_Dirt"}, {"x": 2, "y": 6, "z": 6, "name": "Soil_Grass", "rotation": 1}, {"x": 2, "y": 7, "z": 6, "name": "Plant_Grass_Winter", "rotation": 1}, {"x": 2, "y": -3, "z": 7, "name": "Soil_Dirt"}, {"x": 2, "y": -2, "z": 7, "name": "Rock_Basalt"}, {"x": 2, "y": -1, "z": 7, "name": "Rock_Basalt"}, {"x": 2, "y": 0, "z": 7, "name": "Rock_Basalt"}, {"x": 2, "y": 1, "z": 7, "name": "Rock_Basalt"}, {"x": 2, "y": 2, "z": 7, "name": "Rock_Basalt"}, {"x": 2, "y": 3, "z": 7, "name": "Rock_Basalt"}, {"x": 2, "y": 4, "z": 7, "name": "Rock_Basalt"}, {"x": 2, "y": 5, "z": 7, "name": "Soil_Dirt"}, {"x": 2, "y": 6, "z": 7, "name": "Soil_Grass", "rotation": 1}, {"x": 2, "y": 7, "z": 7, "name": "Plant_Grass_Winter", "rotation": 1}, {"x": 2, "y": -3, "z": 8, "name": "Rock_Basalt"}, {"x": 2, "y": -2, "z": 8, "name": "Rock_Basalt"}, {"x": 2, "y": -1, "z": 8, "name": "Rock_Basalt"}, {"x": 2, "y": 0, "z": 8, "name": "Wood_Redwood_Trunk", "support": 15, "rotation": 1}, {"x": 2, "y": 1, "z": 8, "name": "Rock_Basalt"}, {"x": 2, "y": 2, "z": 8, "name": "Rock_Basalt"}, {"x": 2, "y": 3, "z": 8, "name": "Rock_Basalt"}, {"x": 2, "y": 4, "z": 8, "name": "Rock_Basalt"}, {"x": 2, "y": 5, "z": 8, "name": "Soil_Dirt"}, {"x": 2, "y": 6, "z": 8, "name": "Soil_Grass", "rotation": 1}, {"x": 2, "y": 7, "z": 8, "name": "Plant_Grass_Winter_Short", "rotation": 1}, {"x": 2, "y": -3, "z": 9, "name": "Rock_Basalt"}, {"x": 2, "y": -2, "z": 9, "name": "Rock_Basalt"}, {"x": 2, "y": -1, "z": 9, "name": "Rock_Basalt"}, {"x": 2, "y": 0, "z": 9, "name": "Rock_Basalt"}, {"x": 2, "y": 1, "z": 9, "name": "Wood_Redwood_Trunk", "support": 15, "rotation": 1}, {"x": 2, "y": 2, "z": 9, "name": "Rock_Basalt"}, {"x": 2, "y": 3, "z": 9, "name": "Rock_Basalt"}, {"x": 2, "y": 4, "z": 9, "name": "Rock_Basalt"}, {"x": 2, "y": 5, "z": 9, "name": "Soil_Dirt"}, {"x": 2, "y": 6, "z": 9, "name": "Soil_Needles"}, {"x": 2, "y": -3, "z": 10, "name": "Rock_Basalt"}, {"x": 2, "y": -2, "z": 10, "name": "Rock_Basalt"}, {"x": 2, "y": -1, "z": 10, "name": "Rock_Basalt"}, {"x": 2, "y": 0, "z": 10, "name": "Rock_Basalt"}, {"x": 2, "y": 1, "z": 10, "name": "Rock_Basalt"}, {"x": 2, "y": 2, "z": 10, "name": "Rock_Basalt"}, {"x": 2, "y": 3, "z": 10, "name": "Rock_Basalt"}, {"x": 2, "y": 4, "z": 10, "name": "Rock_Basalt"}, {"x": 2, "y": 5, "z": 10, "name": "Soil_Dirt"}, {"x": 2, "y": 6, "z": 10, "name": "Soil_Needles"}, {"x": 2, "y": -3, "z": 11, "name": "Rock_Basalt"}, {"x": 2, "y": -2, "z": 11, "name": "Rock_Basalt"}, {"x": 2, "y": -1, "z": 11, "name": "Rock_Basalt"}, {"x": 2, "y": 0, "z": 11, "name": "Rock_Basalt"}, {"x": 2, "y": 1, "z": 11, "name": "Rock_Basalt"}, {"x": 2, "y": 2, "z": 11, "name": "Rock_Basalt"}, {"x": 2, "y": 3, "z": 11, "name": "Rock_Basalt"}, {"x": 2, "y": 4, "z": 11, "name": "Rock_Basalt"}, {"x": 2, "y": 5, "z": 11, "name": "Soil_Dirt"}, {"x": 2, "y": 6, "z": 11, "name": "Soil_Needles"}, {"x": 2, "y": -3, "z": 12, "name": "Rock_Basalt"}, {"x": 2, "y": -2, "z": 12, "name": "Rock_Basalt"}, {"x": 2, "y": -1, "z": 12, "name": "Rock_Basalt"}, {"x": 2, "y": 0, "z": 12, "name": "Rock_Basalt"}, {"x": 2, "y": 1, "z": 12, "name": "Rock_Basalt"}, {"x": 2, "y": 2, "z": 12, "name": "Rock_Basalt"}, {"x": 2, "y": 3, "z": 12, "name": "Rock_Basalt"}, {"x": 2, "y": 4, "z": 12, "name": "Rock_Basalt"}, {"x": 2, "y": 5, "z": 12, "name": "Rock_Basalt"}, {"x": 2, "y": 6, "z": 12, "name": "Soil_Needles"}, {"x": 2, "y": -3, "z": 13, "name": "Rock_Basalt"}, {"x": 2, "y": -2, "z": 13, "name": "Rock_Basalt"}, {"x": 2, "y": -1, "z": 13, "name": "Rock_Basalt"}, {"x": 2, "y": 0, "z": 13, "name": "Rock_Basalt"}, {"x": 2, "y": 1, "z": 13, "name": "Rock_Basalt"}, {"x": 2, "y": 2, "z": 13, "name": "Rock_Basalt"}, {"x": 2, "y": 3, "z": 13, "name": "Rock_Basalt"}, {"x": 2, "y": 4, "z": 13, "name": "Rock_Basalt"}, {"x": 2, "y": 5, "z": 13, "name": "Soil_Dirt"}, {"x": 2, "y": 6, "z": 13, "name": "Soil_Needles"}, {"x": 2, "y": -3, "z": 14, "name": "Rock_Basalt"}, {"x": 2, "y": -2, "z": 14, "name": "Rock_Basalt"}, {"x": 2, "y": -1, "z": 14, "name": "Rock_Basalt"}, {"x": 2, "y": 0, "z": 14, "name": "Rock_Basalt"}, {"x": 2, "y": 1, "z": 14, "name": "Rock_Basalt"}, {"x": 2, "y": 2, "z": 14, "name": "Rock_Basalt"}, {"x": 2, "y": 3, "z": 14, "name": "Rock_Basalt"}, {"x": 2, "y": 4, "z": 14, "name": "Rock_Basalt"}, {"x": 2, "y": 5, "z": 14, "name": "Soil_Dirt"}, {"x": 2, "y": 6, "z": 14, "name": "Soil_Grass", "rotation": 1}, {"x": 2, "y": -3, "z": 15, "name": "Soil_Dirt"}, {"x": 2, "y": -2, "z": 15, "name": "Rock_Basalt"}, {"x": 2, "y": -1, "z": 15, "name": "Rock_Basalt"}, {"x": 2, "y": 0, "z": 15, "name": "Rock_Basalt"}, {"x": 2, "y": 1, "z": 15, "name": "Rock_Basalt"}, {"x": 2, "y": 2, "z": 15, "name": "Rock_Basalt"}, {"x": 2, "y": 3, "z": 15, "name": "Rock_Basalt"}, {"x": 2, "y": 4, "z": 15, "name": "Rock_Basalt"}, {"x": 2, "y": 5, "z": 15, "name": "Soil_Dirt"}, {"x": 2, "y": 6, "z": 15, "name": "Soil_Grass", "rotation": 1}, {"x": 2, "y": 7, "z": 15, "name": "Plant_Flower_Flax_Blue", "rotation": 1}, {"x": 2, "y": -3, "z": 16, "name": "Soil_Dirt"}, {"x": 2, "y": -2, "z": 16, "name": "Soil_Dirt"}, {"x": 2, "y": -1, "z": 16, "name": "Soil_Dirt"}, {"x": 2, "y": 0, "z": 16, "name": "Rock_Basalt"}, {"x": 2, "y": 1, "z": 16, "name": "Rock_Basalt"}, {"x": 2, "y": 2, "z": 16, "name": "Rock_Basalt"}, {"x": 2, "y": 3, "z": 16, "name": "Rock_Basalt"}, {"x": 2, "y": 4, "z": 16, "name": "Rock_Basalt"}, {"x": 2, "y": 5, "z": 16, "name": "Soil_Dirt"}, {"x": 2, "y": 6, "z": 16, "name": "Soil_Grass", "rotation": 1}, {"x": 2, "y": -3, "z": 17, "name": "Soil_Dirt"}, {"x": 2, "y": -2, "z": 17, "name": "Soil_Dirt"}, {"x": 2, "y": -1, "z": 17, "name": "Soil_Dirt"}, {"x": 2, "y": 0, "z": 17, "name": "Soil_Grass"}, {"x": 2, "y": 4, "z": 17, "name": "Rock_Basalt"}, {"x": 2, "y": 5, "z": 17, "name": "Soil_Dirt"}, {"x": 2, "y": 6, "z": 17, "name": "Soil_Grass", "rotation": 1}, {"x": 2, "y": -3, "z": 18, "name": "Soil_Dirt"}, {"x": 2, "y": -2, "z": 18, "name": "Soil_Dirt"}, {"x": 2, "y": -1, "z": 18, "name": "Soil_Dirt"}, {"x": 2, "y": 0, "z": 18, "name": "Soil_Grass"}, {"x": 2, "y": -3, "z": 19, "name": "Soil_Dirt"}, {"x": 2, "y": -2, "z": 19, "name": "Soil_Dirt"}, {"x": 2, "y": -1, "z": 19, "name": "Soil_Dirt"}, {"x": 2, "y": 0, "z": 19, "name": "Soil_Grass"}, {"x": 2, "y": -3, "z": 20, "name": "Soil_Dirt"}, {"x": 2, "y": -2, "z": 20, "name": "Soil_Dirt"}, {"x": 2, "y": -1, "z": 20, "name": "Soil_Dirt"}, {"x": 2, "y": 0, "z": 20, "name": "Soil_Grass"}, {"x": 2, "y": -3, "z": 21, "name": "Soil_Dirt"}, {"x": 2, "y": -2, "z": 21, "name": "Soil_Dirt"}, {"x": 2, "y": -1, "z": 21, "name": "Soil_Dirt"}, {"x": 2, "y": 0, "z": 21, "name": "Soil_Grass"}, {"x": 2, "y": -3, "z": 22, "name": "Soil_Dirt"}, {"x": 2, "y": -2, "z": 22, "name": "Soil_Dirt"}, {"x": 2, "y": -1, "z": 22, "name": "Soil_Dirt"}, {"x": 2, "y": 0, "z": 22, "name": "Soil_Grass"}, {"x": 2, "y": -3, "z": 23, "name": "Soil_Dirt"}, {"x": 2, "y": -2, "z": 23, "name": "Soil_Dirt"}, {"x": 2, "y": -1, "z": 23, "name": "Soil_Dirt"}, {"x": 2, "y": 0, "z": 23, "name": "Soil_Grass"}, {"x": 2, "y": -3, "z": 24, "name": "Soil_Dirt"}, {"x": 2, "y": -2, "z": 24, "name": "Soil_Dirt"}, {"x": 2, "y": -1, "z": 24, "name": "Soil_Dirt"}, {"x": 2, "y": 0, "z": 24, "name": "Soil_Grass"}, {"x": 2, "y": -3, "z": 25, "name": "Soil_Dirt"}, {"x": 2, "y": -2, "z": 25, "name": "Soil_Dirt"}, {"x": 2, "y": -1, "z": 25, "name": "Soil_Dirt"}, {"x": 2, "y": 0, "z": 25, "name": "Soil_Grass"}, {"x": 2, "y": -3, "z": 26, "name": "Soil_Dirt"}, {"x": 2, "y": -2, "z": 26, "name": "Soil_Dirt"}, {"x": 2, "y": -1, "z": 26, "name": "Soil_Dirt"}, {"x": 2, "y": 0, "z": 26, "name": "Soil_Grass"}, {"x": 2, "y": -3, "z": 27, "name": "Soil_Dirt"}, {"x": 2, "y": -2, "z": 27, "name": "Soil_Dirt"}, {"x": 2, "y": -1, "z": 27, "name": "Soil_Dirt"}, {"x": 2, "y": 0, "z": 27, "name": "Soil_Grass"}, {"x": 2, "y": -3, "z": 28, "name": "Soil_Dirt"}, {"x": 2, "y": -2, "z": 28, "name": "Soil_Dirt"}, {"x": 2, "y": -1, "z": 28, "name": "Soil_Dirt"}, {"x": 2, "y": 0, "z": 28, "name": "Soil_Grass"}, {"x": 2, "y": -3, "z": 29, "name": "Soil_Dirt"}, {"x": 2, "y": -2, "z": 29, "name": "Soil_Dirt"}, {"x": 2, "y": -1, "z": 29, "name": "Soil_Dirt"}, {"x": 2, "y": 0, "z": 29, "name": "Soil_Grass"}, {"x": 2, "y": 6, "z": 29, "name": "Plant_Leaves_Beech"}, {"x": 2, "y": 11, "z": 29, "name": "Plant_Leaves_Beech"}, {"x": 2, "y": 12, "z": 29, "name": "Plant_Leaves_Beech"}, {"x": 2, "y": -3, "z": 30, "name": "Soil_Dirt"}, {"x": 2, "y": -2, "z": 30, "name": "Soil_Dirt"}, {"x": 2, "y": -1, "z": 30, "name": "Soil_Dirt"}, {"x": 2, "y": 0, "z": 30, "name": "Soil_Grass"}, {"x": 2, "y": 6, "z": 30, "name": "Plant_Leaves_Beech"}, {"x": 2, "y": 7, "z": 30, "name": "Plant_Leaves_Beech"}, {"x": 2, "y": 11, "z": 30, "name": "Plant_Leaves_Beech"}, {"x": 2, "y": 12, "z": 30, "name": "Plant_Leaves_Beech"}, {"x": 2, "y": 13, "z": 30, "name": "Plant_Leaves_Beech"}, {"x": 2, "y": -3, "z": 31, "name": "Soil_Dirt"}, {"x": 2, "y": -2, "z": 31, "name": "Soil_Dirt"}, {"x": 2, "y": -1, "z": 31, "name": "Soil_Dirt"}, {"x": 2, "y": 0, "z": 31, "name": "Soil_Grass"}, {"x": 2, "y": 6, "z": 31, "name": "Plant_Leaves_Beech"}, {"x": 2, "y": 7, "z": 31, "name": "Plant_Leaves_Beech"}, {"x": 2, "y": 11, "z": 31, "name": "Wood_Beech_Branch_Corner", "rotation": 1}, {"x": 2, "y": 12, "z": 31, "name": "Plant_Leaves_Beech"}, {"x": 2, "y": 13, "z": 31, "name": "Plant_Leaves_Beech"}, {"x": 3, "y": -3, "z": 0, "name": "Soil_Dirt"}, {"x": 3, "y": -2, "z": 0, "name": "Soil_Dirt"}, {"x": 3, "y": -1, "z": 0, "name": "Soil_Dirt"}, {"x": 3, "y": 0, "z": 0, "name": "Soil_Grass"}, {"x": 3, "y": -3, "z": 1, "name": "Soil_Dirt"}, {"x": 3, "y": -2, "z": 1, "name": "Soil_Dirt"}, {"x": 3, "y": -1, "z": 1, "name": "Soil_Dirt"}, {"x": 3, "y": 0, "z": 1, "name": "Soil_Grass"}, {"x": 3, "y": -3, "z": 2, "name": "Soil_Dirt"}, {"x": 3, "y": -2, "z": 2, "name": "Soil_Dirt"}, {"x": 3, "y": -1, "z": 2, "name": "Soil_Dirt"}, {"x": 3, "y": 0, "z": 2, "name": "Soil_Grass"}, {"x": 3, "y": -3, "z": 3, "name": "Soil_Dirt"}, {"x": 3, "y": -2, "z": 3, "name": "Soil_Dirt"}, {"x": 3, "y": -1, "z": 3, "name": "Soil_Dirt"}, {"x": 3, "y": 0, "z": 3, "name": "Soil_Grass"}, {"x": 3, "y": 3, "z": 3, "name": "Plant_Crop_Mushroom_Block_Yellow", "rotation": 1}, {"x": 3, "y": 4, "z": 3, "name": "Plant_Moss_Rug_Green", "rotation": 1}, {"x": 3, "y": -3, "z": 4, "name": "Soil_Dirt"}, {"x": 3, "y": -2, "z": 4, "name": "Soil_Dirt"}, {"x": 3, "y": -1, "z": 4, "name": "Soil_Dirt"}, {"x": 3, "y": 0, "z": 4, "name": "Soil_Grass"}, {"x": 3, "y": 3, "z": 4, "name": "Plant_Crop_Mushroom_Block_Yellow", "rotation": 1}, {"x": 3, "y": -3, "z": 5, "name": "Soil_Dirt"}, {"x": 3, "y": -2, "z": 5, "name": "Soil_Dirt"}, {"x": 3, "y": -1, "z": 5, "name": "Rock_Basalt"}, {"x": 3, "y": 0, "z": 5, "name": "Rock_Basalt"}, {"x": 3, "y": 1, "z": 5, "name": "Rock_Basalt"}, {"x": 3, "y": 2, "z": 5, "name": "Rock_Basalt"}, {"x": 3, "y": 3, "z": 5, "name": "Rock_Basalt"}, {"x": 3, "y": 4, "z": 5, "name": "Rock_Basalt"}, {"x": 3, "y": 5, "z": 5, "name": "Soil_Dirt"}, {"x": 3, "y": 6, "z": 5, "name": "Soil_Grass", "rotation": 1}, {"x": 3, "y": 7, "z": 5, "name": "Plant_Grass_Winter_Tall", "rotation": 1}, {"x": 3, "y": 8, "z": 5, "name": "Plant_Grass_Winter_Tall", "filler": 1024, "rotation": 1}, {"x": 3, "y": -3, "z": 6, "name": "Soil_Dirt"}, {"x": 3, "y": -2, "z": 6, "name": "Rock_Basalt"}, {"x": 3, "y": -1, "z": 6, "name": "Rock_Basalt"}, {"x": 3, "y": 0, "z": 6, "name": "Rock_Basalt"}, {"x": 3, "y": 1, "z": 6, "name": "Rock_Basalt"}, {"x": 3, "y": 2, "z": 6, "name": "Rock_Basalt"}, {"x": 3, "y": 3, "z": 6, "name": "Rock_Basalt"}, {"x": 3, "y": 4, "z": 6, "name": "Rock_Basalt"}, {"x": 3, "y": 5, "z": 6, "name": "Soil_Dirt"}, {"x": 3, "y": 6, "z": 6, "name": "Soil_Grass", "rotation": 1}, {"x": 3, "y": 7, "z": 6, "name": "Plant_Grass_Winter_Tall", "rotation": 1}, {"x": 3, "y": 8, "z": 6, "name": "Plant_Grass_Winter_Tall", "filler": 1024, "rotation": 1}, {"x": 3, "y": -3, "z": 7, "name": "Rock_Basalt"}, {"x": 3, "y": -2, "z": 7, "name": "Rock_Basalt"}, {"x": 3, "y": -1, "z": 7, "name": "Rock_Basalt"}, {"x": 3, "y": 0, "z": 7, "name": "Rock_Basalt"}, {"x": 3, "y": 2, "z": 7, "name": "Rock_Basalt"}, {"x": 3, "y": 3, "z": 7, "name": "Rock_Basalt"}, {"x": 3, "y": 4, "z": 7, "name": "Rock_Basalt"}, {"x": 3, "y": 5, "z": 7, "name": "Soil_Dirt"}, {"x": 3, "y": 6, "z": 7, "name": "Soil_Grass", "rotation": 1}, {"x": 3, "y": 7, "z": 7, "name": "Plant_Grass_Winter", "rotation": 1}, {"x": 3, "y": -3, "z": 8, "name": "Rock_Basalt"}, {"x": 3, "y": -2, "z": 8, "name": "Rock_Basalt"}, {"x": 3, "y": -1, "z": 8, "name": "Rock_Basalt"}, {"x": 3, "y": 0, "z": 8, "name": "Rock_Basalt"}, {"x": 3, "y": 2, "z": 8, "name": "Rock_Basalt"}, {"x": 3, "y": 3, "z": 8, "name": "Rock_Basalt"}, {"x": 3, "y": 4, "z": 8, "name": "Rock_Basalt"}, {"x": 3, "y": 5, "z": 8, "name": "Soil_Dirt"}, {"x": 3, "y": 6, "z": 8, "name": "Soil_Needles"}, {"x": 3, "y": -3, "z": 9, "name": "Rock_Basalt"}, {"x": 3, "y": -2, "z": 9, "name": "Rock_Basalt"}, {"x": 3, "y": -1, "z": 9, "name": "Rock_Basalt"}, {"x": 3, "y": 0, "z": 9, "name": "Wood_Redwood_Trunk", "support": 15, "rotation": 1}, {"x": 3, "y": 1, "z": 9, "name": "Wood_Redwood_Trunk", "support": 15, "rotation": 1}, {"x": 3, "y": 2, "z": 9, "name": "Wood_Redwood_Trunk", "support": 15, "rotation": 1}, {"x": 3, "y": 3, "z": 9, "name": "Rock_Basalt"}, {"x": 3, "y": 4, "z": 9, "name": "Rock_Basalt"}, {"x": 3, "y": 5, "z": 9, "name": "Soil_Dirt"}, {"x": 3, "y": 6, "z": 9, "name": "Soil_Needles"}, {"x": 3, "y": -3, "z": 10, "name": "Rock_Basalt"}, {"x": 3, "y": -2, "z": 10, "name": "Rock_Basalt"}, {"x": 3, "y": -1, "z": 10, "name": "Rock_Basalt"}, {"x": 3, "y": 0, "z": 10, "name": "Rock_Basalt"}, {"x": 3, "y": 1, "z": 10, "name": "Wood_Redwood_Trunk", "support": 15, "rotation": 1}, {"x": 3, "y": 2, "z": 10, "name": "Wood_Redwood_Trunk", "support": 15, "rotation": 1}, {"x": 3, "y": 3, "z": 10, "name": "Rock_Basalt"}, {"x": 3, "y": 4, "z": 10, "name": "Rock_Basalt"}, {"x": 3, "y": 5, "z": 10, "name": "Soil_Dirt"}, {"x": 3, "y": 6, "z": 10, "name": "Soil_Needles"}, {"x": 3, "y": 7, "z": 10, "name": "Plant_Crop_Mushroom_Common_Brown", "components": {"Components": {"FarmingBlock": {"LastTickGameTime": "0001-01-01T12:00:00Z"}}}, "rotation": 1}, {"x": 3, "y": -3, "z": 11, "name": "Rock_Basalt"}, {"x": 3, "y": -2, "z": 11, "name": "Rock_Basalt"}, {"x": 3, "y": -1, "z": 11, "name": "Rock_Basalt"}, {"x": 3, "y": 0, "z": 11, "name": "Rock_Basalt"}, {"x": 3, "y": 1, "z": 11, "name": "Rock_Basalt"}, {"x": 3, "y": 2, "z": 11, "name": "Rock_Basalt"}, {"x": 3, "y": 3, "z": 11, "name": "Rock_Basalt"}, {"x": 3, "y": 4, "z": 11, "name": "Rock_Basalt"}, {"x": 3, "y": 5, "z": 11, "name": "Rock_Basalt"}, {"x": 3, "y": 6, "z": 11, "name": "Soil_Needles"}, {"x": 3, "y": -3, "z": 12, "name": "Rock_Basalt"}, {"x": 3, "y": -2, "z": 12, "name": "Rock_Basalt"}, {"x": 3, "y": -1, "z": 12, "name": "Rock_Basalt"}, {"x": 3, "y": 0, "z": 12, "name": "Rock_Basalt"}, {"x": 3, "y": 1, "z": 12, "name": "Rock_Basalt"}, {"x": 3, "y": 2, "z": 12, "name": "Rock_Basalt"}, {"x": 3, "y": 3, "z": 12, "name": "Rock_Basalt"}, {"x": 3, "y": 4, "z": 12, "name": "Rock_Basalt"}, {"x": 3, "y": 5, "z": 12, "name": "Rock_Basalt"}, {"x": 3, "y": 6, "z": 12, "name": "Soil_Needles"}, {"x": 3, "y": -3, "z": 13, "name": "Rock_Basalt"}, {"x": 3, "y": -2, "z": 13, "name": "Rock_Basalt"}, {"x": 3, "y": -1, "z": 13, "name": "Rock_Basalt"}, {"x": 3, "y": 0, "z": 13, "name": "Rock_Basalt"}, {"x": 3, "y": 1, "z": 13, "name": "Rock_Basalt"}, {"x": 3, "y": 2, "z": 13, "name": "Rock_Basalt"}, {"x": 3, "y": 3, "z": 13, "name": "Rock_Basalt"}, {"x": 3, "y": 4, "z": 13, "name": "Rock_Basalt"}, {"x": 3, "y": 5, "z": 13, "name": "Soil_Dirt"}, {"x": 3, "y": 6, "z": 13, "name": "Soil_Needles"}, {"x": 3, "y": -3, "z": 14, "name": "Rock_Basalt"}, {"x": 3, "y": -2, "z": 14, "name": "Rock_Basalt"}, {"x": 3, "y": -1, "z": 14, "name": "Wood_Redwood_Trunk", "support": 15, "rotation": 1}, {"x": 3, "y": 0, "z": 14, "name": "Wood_Redwood_Trunk", "support": 15, "rotation": 1}, {"x": 3, "y": 1, "z": 14, "name": "Wood_Redwood_Trunk", "support": 15, "rotation": 1}, {"x": 3, "y": 2, "z": 14, "name": "Wood_Redwood_Trunk", "support": 15, "rotation": 1}, {"x": 3, "y": 3, "z": 14, "name": "Rock_Basalt"}, {"x": 3, "y": 4, "z": 14, "name": "Rock_Basalt"}, {"x": 3, "y": 5, "z": 14, "name": "Soil_Dirt"}, {"x": 3, "y": 6, "z": 14, "name": "Soil_Needles"}, {"x": 3, "y": -3, "z": 15, "name": "Rock_Basalt"}, {"x": 3, "y": -2, "z": 15, "name": "Rock_Basalt"}, {"x": 3, "y": -1, "z": 15, "name": "Rock_Basalt"}, {"x": 3, "y": 0, "z": 15, "name": "Rock_Basalt"}, {"x": 3, "y": 1, "z": 15, "name": "Wood_Redwood_Trunk", "support": 15, "rotation": 1}, {"x": 3, "y": 2, "z": 15, "name": "Wood_Redwood_Trunk", "support": 15, "rotation": 1}, {"x": 3, "y": 3, "z": 15, "name": "Rock_Basalt"}, {"x": 3, "y": 4, "z": 15, "name": "Rock_Basalt"}, {"x": 3, "y": 5, "z": 15, "name": "Soil_Dirt"}, {"x": 3, "y": 6, "z": 15, "name": "Soil_Grass", "rotation": 1}, {"x": 3, "y": -3, "z": 16, "name": "Rock_Basalt"}, {"x": 3, "y": -2, "z": 16, "name": "Rock_Basalt"}, {"x": 3, "y": -1, "z": 16, "name": "Rock_Basalt"}, {"x": 3, "y": 0, "z": 16, "name": "Rock_Basalt"}, {"x": 3, "y": 1, "z": 16, "name": "Rock_Basalt"}, {"x": 3, "y": 2, "z": 16, "name": "Rock_Basalt"}, {"x": 3, "y": 3, "z": 16, "name": "Rock_Basalt"}, {"x": 3, "y": 4, "z": 16, "name": "Rock_Basalt"}, {"x": 3, "y": 5, "z": 16, "name": "Soil_Dirt"}, {"x": 3, "y": 6, "z": 16, "name": "Soil_Grass", "rotation": 1}, {"x": 3, "y": 7, "z": 16, "name": "Plant_Flower_Flax_Blue", "rotation": 1}, {"x": 3, "y": -3, "z": 17, "name": "Soil_Dirt"}, {"x": 3, "y": -2, "z": 17, "name": "Soil_Dirt"}, {"x": 3, "y": -1, "z": 17, "name": "Soil_Dirt"}, {"x": 3, "y": 0, "z": 17, "name": "Soil_Dirt"}, {"x": 3, "y": 1, "z": 17, "name": "Rock_Basalt"}, {"x": 3, "y": 2, "z": 17, "name": "Rock_Basalt"}, {"x": 3, "y": 3, "z": 17, "name": "Rock_Basalt"}, {"x": 3, "y": 4, "z": 17, "name": "Rock_Basalt"}, {"x": 3, "y": 5, "z": 17, "name": "Soil_Dirt"}, {"x": 3, "y": 6, "z": 17, "name": "Soil_Grass", "rotation": 1}, {"x": 3, "y": -3, "z": 18, "name": "Soil_Dirt"}, {"x": 3, "y": -2, "z": 18, "name": "Soil_Dirt"}, {"x": 3, "y": -1, "z": 18, "name": "Soil_Dirt"}, {"x": 3, "y": 0, "z": 18, "name": "Soil_Grass"}, {"x": 3, "y": 5, "z": 18, "name": "Soil_Dirt"}, {"x": 3, "y": 6, "z": 18, "name": "Soil_Grass", "rotation": 1}, {"x": 3, "y": -3, "z": 19, "name": "Soil_Dirt"}, {"x": 3, "y": -2, "z": 19, "name": "Soil_Dirt"}, {"x": 3, "y": -1, "z": 19, "name": "Soil_Dirt"}, {"x": 3, "y": 0, "z": 19, "name": "Soil_Grass"}, {"x": 3, "y": -3, "z": 20, "name": "Soil_Dirt"}, {"x": 3, "y": -2, "z": 20, "name": "Soil_Dirt"}, {"x": 3, "y": -1, "z": 20, "name": "Soil_Dirt"}, {"x": 3, "y": 0, "z": 20, "name": "Soil_Grass"}, {"x": 3, "y": -3, "z": 21, "name": "Soil_Dirt"}, {"x": 3, "y": -2, "z": 21, "name": "Soil_Dirt"}, {"x": 3, "y": -1, "z": 21, "name": "Soil_Dirt"}, {"x": 3, "y": 0, "z": 21, "name": "Soil_Grass"}, {"x": 3, "y": -3, "z": 22, "name": "Soil_Dirt"}, {"x": 3, "y": -2, "z": 22, "name": "Soil_Dirt"}, {"x": 3, "y": -1, "z": 22, "name": "Soil_Dirt"}, {"x": 3, "y": 0, "z": 22, "name": "Soil_Grass"}, {"x": 3, "y": -3, "z": 23, "name": "Soil_Dirt"}, {"x": 3, "y": -2, "z": 23, "name": "Soil_Dirt"}, {"x": 3, "y": -1, "z": 23, "name": "Soil_Dirt"}, {"x": 3, "y": 0, "z": 23, "name": "Soil_Grass"}, {"x": 3, "y": -3, "z": 24, "name": "Soil_Dirt"}, {"x": 3, "y": -2, "z": 24, "name": "Soil_Dirt"}, {"x": 3, "y": -1, "z": 24, "name": "Soil_Dirt"}, {"x": 3, "y": 0, "z": 24, "name": "Soil_Grass"}, {"x": 3, "y": -3, "z": 25, "name": "Soil_Dirt"}, {"x": 3, "y": -2, "z": 25, "name": "Soil_Dirt"}, {"x": 3, "y": -1, "z": 25, "name": "Soil_Dirt"}, {"x": 3, "y": 0, "z": 25, "name": "Soil_Grass"}, {"x": 3, "y": -3, "z": 26, "name": "Soil_Dirt"}, {"x": 3, "y": -2, "z": 26, "name": "Soil_Dirt"}, {"x": 3, "y": -1, "z": 26, "name": "Soil_Dirt"}, {"x": 3, "y": 0, "z": 26, "name": "Soil_Grass"}, {"x": 3, "y": -3, "z": 27, "name": "Soil_Dirt"}, {"x": 3, "y": -2, "z": 27, "name": "Soil_Dirt"}, {"x": 3, "y": -1, "z": 27, "name": "Soil_Dirt"}, {"x": 3, "y": 0, "z": 27, "name": "Soil_Grass"}, {"x": 3, "y": -3, "z": 28, "name": "Soil_Dirt"}, {"x": 3, "y": -2, "z": 28, "name": "Soil_Dirt"}, {"x": 3, "y": -1, "z": 28, "name": "Soil_Dirt"}, {"x": 3, "y": 0, "z": 28, "name": "Soil_Grass"}, {"x": 3, "y": -3, "z": 29, "name": "Soil_Dirt"}, {"x": 3, "y": -2, "z": 29, "name": "Soil_Dirt"}, {"x": 3, "y": -1, "z": 29, "name": "Soil_Dirt"}, {"x": 3, "y": 0, "z": 29, "name": "Soil_Grass"}, {"x": 3, "y": 8, "z": 29, "name": "Plant_Leaves_Beech"}, {"x": 3, "y": 9, "z": 29, "name": "Plant_Leaves_Beech"}, {"x": 3, "y": 10, "z": 29, "name": "Plant_Leaves_Beech"}, {"x": 3, "y": -3, "z": 30, "name": "Soil_Dirt"}, {"x": 3, "y": -2, "z": 30, "name": "Soil_Dirt"}, {"x": 3, "y": -1, "z": 30, "name": "Soil_Dirt"}, {"x": 3, "y": 0, "z": 30, "name": "Soil_Grass"}, {"x": 3, "y": 6, "z": 30, "name": "Plant_Leaves_Beech"}, {"x": 3, "y": 8, "z": 30, "name": "Plant_Leaves_Beech"}, {"x": 3, "y": 9, "z": 30, "name": "Plant_Leaves_Beech"}, {"x": 3, "y": 10, "z": 30, "name": "Plant_Leaves_Beech"}, {"x": 3, "y": 11, "z": 30, "name": "Plant_Leaves_Beech"}, {"x": 3, "y": 12, "z": 30, "name": "Plant_Leaves_Beech"}, {"x": 3, "y": -3, "z": 31, "name": "Soil_Dirt"}, {"x": 3, "y": -2, "z": 31, "name": "Soil_Dirt"}, {"x": 3, "y": -1, "z": 31, "name": "Soil_Dirt"}, {"x": 3, "y": 0, "z": 31, "name": "Soil_Grass"}, {"x": 3, "y": 8, "z": 31, "name": "Plant_Leaves_Beech"}, {"x": 3, "y": 9, "z": 31, "name": "Plant_Leaves_Beech"}, {"x": 3, "y": 11, "z": 31, "name": "Plant_Leaves_Beech"}, {"x": 3, "y": 12, "z": 31, "name": "Plant_Leaves_Beech"}, {"x": 3, "y": 13, "z": 31, "name": "Plant_Leaves_Beech"}, {"x": 4, "y": -3, "z": 0, "name": "Soil_Dirt"}, {"x": 4, "y": -2, "z": 0, "name": "Soil_Dirt"}, {"x": 4, "y": -1, "z": 0, "name": "Soil_Dirt"}, {"x": 4, "y": 0, "z": 0, "name": "Soil_Grass"}, {"x": 4, "y": -3, "z": 1, "name": "Soil_Dirt"}, {"x": 4, "y": -2, "z": 1, "name": "Soil_Dirt"}, {"x": 4, "y": -1, "z": 1, "name": "Soil_Dirt"}, {"x": 4, "y": 0, "z": 1, "name": "Soil_Grass"}, {"x": 4, "y": -3, "z": 2, "name": "Soil_Dirt"}, {"x": 4, "y": -2, "z": 2, "name": "Soil_Dirt"}, {"x": 4, "y": -1, "z": 2, "name": "Soil_Dirt"}, {"x": 4, "y": 0, "z": 2, "name": "Soil_Grass"}, {"x": 4, "y": 3, "z": 2, "name": "Plant_Crop_Mushroom_Block_Yellow", "rotation": 1}, {"x": 4, "y": 4, "z": 2, "name": "Plant_Moss_Rug_Green", "rotation": 1}, {"x": 4, "y": -3, "z": 3, "name": "Soil_Dirt"}, {"x": 4, "y": -2, "z": 3, "name": "Soil_Dirt"}, {"x": 4, "y": -1, "z": 3, "name": "Soil_Dirt"}, {"x": 4, "y": 0, "z": 3, "name": "Wood_Redwood_Trunk_Full", "rotation": 1}, {"x": 4, "y": 3, "z": 3, "name": "Plant_Crop_Mushroom_Block_Yellow", "rotation": 1}, {"x": 4, "y": 4, "z": 3, "name": "Plant_Moss_Rug_Green", "rotation": 1}, {"x": 4, "y": -3, "z": 4, "name": "Soil_Dirt"}, {"x": 4, "y": -2, "z": 4, "name": "Soil_Dirt"}, {"x": 4, "y": -1, "z": 4, "name": "Soil_Dirt"}, {"x": 4, "y": 0, "z": 4, "name": "Wood_Redwood_Trunk", "support": 15, "rotation": 1}, {"x": 4, "y": 1, "z": 4, "name": "Wood_Redwood_Trunk", "support": 15, "rotation": 1}, {"x": 4, "y": 2, "z": 4, "name": "Wood_Redwood_Trunk", "support": 15, "rotation": 1}, {"x": 4, "y": 3, "z": 4, "name": "Wood_Redwood_Trunk", "support": 15, "rotation": 1}, {"x": 4, "y": 4, "z": 4, "name": "Rock_Basalt"}, {"x": 4, "y": 5, "z": 4, "name": "Soil_Dirt"}, {"x": 4, "y": 6, "z": 4, "name": "Soil_Grass", "rotation": 1}, {"x": 4, "y": 7, "z": 4, "name": "Plant_Grass_Winter", "rotation": 1}, {"x": 4, "y": -3, "z": 5, "name": "Rock_Basalt"}, {"x": 4, "y": -2, "z": 5, "name": "Rock_Basalt"}, {"x": 4, "y": -1, "z": 5, "name": "Rock_Basalt"}, {"x": 4, "y": 0, "z": 5, "name": "Rock_Basalt"}, {"x": 4, "y": 1, "z": 5, "name": "Rock_Basalt"}, {"x": 4, "y": 2, "z": 5, "name": "Wood_Redwood_Roots", "rotation": 1}, {"x": 4, "y": 3, "z": 5, "name": "Wood_Redwood_Trunk", "support": 15, "rotation": 1}, {"x": 4, "y": 4, "z": 5, "name": "Wood_Redwood_Trunk", "support": 15, "rotation": 1}, {"x": 4, "y": 5, "z": 5, "name": "Wood_Redwood_Trunk", "support": 15, "rotation": 1}, {"x": 4, "y": 6, "z": 5, "name": "Soil_Grass", "rotation": 1}, {"x": 4, "y": 7, "z": 5, "name": "Plant_Grass_Winter_Tall", "rotation": 1}, {"x": 4, "y": 8, "z": 5, "name": "Plant_Grass_Winter_Tall", "filler": 1024, "rotation": 1}, {"x": 4, "y": -3, "z": 6, "name": "Rock_Basalt"}, {"x": 4, "y": -2, "z": 6, "name": "Rock_Basalt"}, {"x": 4, "y": -1, "z": 6, "name": "Rock_Basalt"}, {"x": 4, "y": 0, "z": 6, "name": "Rock_Basalt"}, {"x": 4, "y": 4, "z": 6, "name": "Rock_Basalt"}, {"x": 4, "y": 5, "z": 6, "name": "Soil_Dirt"}, {"x": 4, "y": 6, "z": 6, "name": "Soil_Grass", "rotation": 1}, {"x": 4, "y": 7, "z": 6, "name": "Plant_Grass_Winter_Tall", "rotation": 1}, {"x": 4, "y": 8, "z": 6, "name": "Plant_Grass_Winter_Tall", "filler": 1024, "rotation": 1}, {"x": 4, "y": -3, "z": 7, "name": "Rock_Basalt"}, {"x": 4, "y": -2, "z": 7, "name": "Rock_Basalt"}, {"x": 4, "y": -1, "z": 7, "name": "Rock_Basalt"}, {"x": 4, "y": 0, "z": 7, "name": "Rock_Basalt"}, {"x": 4, "y": 4, "z": 7, "name": "Rock_Basalt"}, {"x": 4, "y": 5, "z": 7, "name": "Soil_Dirt"}, {"x": 4, "y": 6, "z": 7, "name": "Soil_Grass", "rotation": 1}, {"x": 4, "y": -3, "z": 8, "name": "Rock_Basalt"}, {"x": 4, "y": -2, "z": 8, "name": "Rock_Basalt"}, {"x": 4, "y": -1, "z": 8, "name": "Rock_Basalt"}, {"x": 4, "y": 0, "z": 8, "name": "Rock_Basalt"}, {"x": 4, "y": 3, "z": 8, "name": "Rock_Basalt"}, {"x": 4, "y": 4, "z": 8, "name": "Rock_Basalt"}, {"x": 4, "y": 5, "z": 8, "name": "Soil_Dirt"}, {"x": 4, "y": 6, "z": 8, "name": "Soil_Needles"}, {"x": 4, "y": 7, "z": 8, "name": "Plant_Crop_Mushroom_Common_Brown", "components": {"Components": {"FarmingBlock": {"LastTickGameTime": "0001-01-01T12:00:00Z"}}}, "rotation": 1}, {"x": 4, "y": -3, "z": 9, "name": "Rock_Basalt"}, {"x": 4, "y": -2, "z": 9, "name": "Rock_Basalt"}, {"x": 4, "y": -1, "z": 9, "name": "Rock_Basalt"}, {"x": 4, "y": 0, "z": 9, "name": "Wood_Redwood_Trunk_Full", "rotation": 5}, {"x": 4, "y": 2, "z": 9, "name": "Wood_Redwood_Trunk_Full", "support": 1, "rotation": 1}, {"x": 4, "y": 3, "z": 9, "name": "Rock_Basalt"}, {"x": 4, "y": 4, "z": 9, "name": "Rock_Basalt"}, {"x": 4, "y": 5, "z": 9, "name": "Soil_Dirt"}, {"x": 4, "y": 6, "z": 9, "name": "Soil_Needles"}, {"x": 4, "y": 7, "z": 9, "name": "Plant_Crop_Mushroom_Common_Brown", "components": {"Components": {"FarmingBlock": {"LastTickGameTime": "0001-01-01T12:00:00Z"}}}, "rotation": 1}, {"x": 4, "y": -3, "z": 10, "name": "Rock_Basalt"}, {"x": 4, "y": -2, "z": 10, "name": "Rock_Basalt"}, {"x": 4, "y": -1, "z": 10, "name": "Rock_Basalt"}, {"x": 4, "y": 1, "z": 10, "name": "Wood_Redwood_Trunk", "support": 15, "rotation": 5}, {"x": 4, "y": 2, "z": 10, "name": "Wood_Redwood_Trunk_Full", "rotation": 1}, {"x": 4, "y": 3, "z": 10, "name": "Wood_Redwood_Trunk", "support": 15, "rotation": 1}, {"x": 4, "y": 4, "z": 10, "name": "Rock_Basalt"}, {"x": 4, "y": 5, "z": 10, "name": "Soil_Dirt"}, {"x": 4, "y": 6, "z": 10, "name": "Soil_Needles"}, {"x": 4, "y": -3, "z": 11, "name": "Rock_Basalt"}, {"x": 4, "y": -2, "z": 11, "name": "Rock_Basalt"}, {"x": 4, "y": -1, "z": 11, "name": "Rock_Basalt"}, {"x": 4, "y": 0, "z": 11, "name": "Rock_Basalt"}, {"x": 4, "y": 1, "z": 11, "name": "Wood_Redwood_Roots", "rotation": 1}, {"x": 4, "y": 2, "z": 11, "name": "Wood_Redwood_Trunk", "support": 15, "rotation": 1}, {"x": 4, "y": 3, "z": 11, "name": "Wood_Redwood_Trunk", "support": 15, "rotation": 1}, {"x": 4, "y": 4, "z": 11, "name": "Rock_Basalt"}, {"x": 4, "y": 5, "z": 11, "name": "Soil_Dirt"}, {"x": 4, "y": 6, "z": 11, "name": "Soil_Needles"}, {"x": 4, "y": -3, "z": 12, "name": "Rock_Basalt"}, {"x": 4, "y": -2, "z": 12, "name": "Rock_Basalt"}, {"x": 4, "y": -1, "z": 12, "name": "Rock_Basalt"}, {"x": 4, "y": 0, "z": 12, "name": "Rock_Basalt"}, {"x": 4, "y": 1, "z": 12, "name": "Rock_Basalt"}, {"x": 4, "y": 2, "z": 12, "name": "Rock_Basalt"}, {"x": 4, "y": 3, "z": 12, "name": "Rock_Basalt"}, {"x": 4, "y": 4, "z": 12, "name": "Rock_Basalt"}, {"x": 4, "y": 5, "z": 12, "name": "Soil_Dirt"}, {"x": 4, "y": 6, "z": 12, "name": "Soil_Needles"}, {"x": 4, "y": -3, "z": 13, "name": "Rock_Basalt"}, {"x": 4, "y": -2, "z": 13, "name": "Rock_Basalt"}, {"x": 4, "y": -1, "z": 13, "name": "Rock_Basalt"}, {"x": 4, "y": 0, "z": 13, "name": "Rock_Basalt"}, {"x": 4, "y": 1, "z": 13, "name": "Rock_Basalt"}, {"x": 4, "y": 2, "z": 13, "name": "Rock_Basalt"}, {"x": 4, "y": 3, "z": 13, "name": "Wood_Redwood_Trunk", "support": 15, "rotation": 1}, {"x": 4, "y": 4, "z": 13, "name": "Wood_Redwood_Trunk", "support": 15, "rotation": 1}, {"x": 4, "y": 5, "z": 13, "name": "Wood_Redwood_Trunk", "support": 15, "rotation": 1}, {"x": 4, "y": 6, "z": 13, "name": "Soil_Needles"}, {"x": 4, "y": -3, "z": 14, "name": "Rock_Basalt"}, {"x": 4, "y": -2, "z": 14, "name": "Rock_Basalt"}, {"x": 4, "y": -1, "z": 14, "name": "Rock_Basalt"}, {"x": 4, "y": 0, "z": 14, "name": "Rock_Basalt"}, {"x": 4, "y": 1, "z": 14, "name": "Wood_Redwood_Trunk", "support": 15, "rotation": 1}, {"x": 4, "y": 2, "z": 14, "name": "Wood_Redwood_Trunk", "support": 15, "rotation": 1}, {"x": 4, "y": 3, "z": 14, "name": "Wood_Redwood_Trunk", "support": 15, "rotation": 1}, {"x": 4, "y": 4, "z": 14, "name": "Wood_Redwood_Trunk", "support": 15, "rotation": 1}, {"x": 4, "y": 5, "z": 14, "name": "Wood_Redwood_Trunk", "support": 15, "rotation": 1}, {"x": 4, "y": 6, "z": 14, "name": "Soil_Needles"}, {"x": 4, "y": -3, "z": 15, "name": "Rock_Basalt"}, {"x": 4, "y": -2, "z": 15, "name": "Rock_Basalt"}, {"x": 4, "y": -1, "z": 15, "name": "Rock_Basalt"}, {"x": 4, "y": 0, "z": 15, "name": "Wood_Redwood_Trunk", "support": 15, "rotation": 1}, {"x": 4, "y": 1, "z": 15, "name": "Wood_Redwood_Trunk", "support": 15, "rotation": 1}, {"x": 4, "y": 2, "z": 15, "name": "Wood_Redwood_Trunk", "support": 15, "rotation": 1}, {"x": 4, "y": 3, "z": 15, "name": "Rock_Basalt"}, {"x": 4, "y": 4, "z": 15, "name": "Rock_Basalt"}, {"x": 4, "y": 5, "z": 15, "name": "Soil_Dirt"}, {"x": 4, "y": 6, "z": 15, "name": "Soil_Grass", "rotation": 1}, {"x": 4, "y": -3, "z": 16, "name": "Rock_Basalt"}, {"x": 4, "y": -2, "z": 16, "name": "Rock_Basalt"}, {"x": 4, "y": -1, "z": 16, "name": "Rock_Basalt"}, {"x": 4, "y": 0, "z": 16, "name": "Rock_Basalt"}, {"x": 4, "y": 1, "z": 16, "name": "Rock_Basalt"}, {"x": 4, "y": 2, "z": 16, "name": "Rock_Basalt"}, {"x": 4, "y": 3, "z": 16, "name": "Rock_Basalt"}, {"x": 4, "y": 4, "z": 16, "name": "Rock_Basalt"}, {"x": 4, "y": 5, "z": 16, "name": "Soil_Dirt"}, {"x": 4, "y": 6, "z": 16, "name": "Soil_Grass", "rotation": 1}, {"x": 4, "y": 7, "z": 16, "name": "Plant_Flower_Flax_Blue", "rotation": 1}, {"x": 4, "y": -3, "z": 17, "name": "Rock_Basalt"}, {"x": 4, "y": -2, "z": 17, "name": "Rock_Basalt"}, {"x": 4, "y": -1, "z": 17, "name": "Rock_Basalt"}, {"x": 4, "y": 0, "z": 17, "name": "Rock_Basalt"}, {"x": 4, "y": 1, "z": 17, "name": "Rock_Basalt"}, {"x": 4, "y": 2, "z": 17, "name": "Rock_Basalt"}, {"x": 4, "y": 3, "z": 17, "name": "Rock_Basalt"}, {"x": 4, "y": 4, "z": 17, "name": "Rock_Basalt"}, {"x": 4, "y": 5, "z": 17, "name": "Soil_Dirt"}, {"x": 4, "y": 6, "z": 17, "name": "Soil_Grass", "rotation": 1}, {"x": 4, "y": -3, "z": 18, "name": "Soil_Dirt"}, {"x": 4, "y": -2, "z": 18, "name": "Soil_Dirt"}, {"x": 4, "y": -1, "z": 18, "name": "Soil_Dirt"}, {"x": 4, "y": 0, "z": 18, "name": "Soil_Grass"}, {"x": 4, "y": 3, "z": 18, "name": "Rock_Basalt"}, {"x": 4, "y": 4, "z": 18, "name": "Rock_Basalt"}, {"x": 4, "y": 5, "z": 18, "name": "Soil_Dirt"}, {"x": 4, "y": 6, "z": 18, "name": "Soil_Grass", "rotation": 1}, {"x": 4, "y": -3, "z": 19, "name": "Soil_Dirt"}, {"x": 4, "y": -2, "z": 19, "name": "Soil_Dirt"}, {"x": 4, "y": -1, "z": 19, "name": "Soil_Dirt"}, {"x": 4, "y": 0, "z": 19, "name": "Soil_Grass"}, {"x": 4, "y": -3, "z": 20, "name": "Soil_Dirt"}, {"x": 4, "y": -2, "z": 20, "name": "Soil_Dirt"}, {"x": 4, "y": -1, "z": 20, "name": "Soil_Dirt"}, {"x": 4, "y": 0, "z": 20, "name": "Soil_Grass"}, {"x": 4, "y": -3, "z": 21, "name": "Soil_Dirt"}, {"x": 4, "y": -2, "z": 21, "name": "Soil_Dirt"}, {"x": 4, "y": -1, "z": 21, "name": "Soil_Dirt"}, {"x": 4, "y": 0, "z": 21, "name": "Soil_Grass"}, {"x": 4, "y": -3, "z": 22, "name": "Soil_Dirt"}, {"x": 4, "y": -2, "z": 22, "name": "Soil_Dirt"}, {"x": 4, "y": -1, "z": 22, "name": "Soil_Dirt"}, {"x": 4, "y": 0, "z": 22, "name": "Soil_Grass"}, {"x": 4, "y": -3, "z": 23, "name": "Soil_Dirt"}, {"x": 4, "y": -2, "z": 23, "name": "Soil_Dirt"}, {"x": 4, "y": -1, "z": 23, "name": "Soil_Dirt"}, {"x": 4, "y": 0, "z": 23, "name": "Soil_Grass"}, {"x": 4, "y": -3, "z": 24, "name": "Soil_Dirt"}, {"x": 4, "y": -2, "z": 24, "name": "Soil_Dirt"}, {"x": 4, "y": -1, "z": 24, "name": "Soil_Dirt"}, {"x": 4, "y": 0, "z": 24, "name": "Soil_Grass"}, {"x": 4, "y": -3, "z": 25, "name": "Soil_Dirt"}, {"x": 4, "y": -2, "z": 25, "name": "Soil_Dirt"}, {"x": 4, "y": -1, "z": 25, "name": "Soil_Dirt"}, {"x": 4, "y": 0, "z": 25, "name": "Soil_Grass"}, {"x": 4, "y": -3, "z": 26, "name": "Soil_Dirt"}, {"x": 4, "y": -2, "z": 26, "name": "Soil_Dirt"}, {"x": 4, "y": -1, "z": 26, "name": "Soil_Dirt"}, {"x": 4, "y": 0, "z": 26, "name": "Soil_Grass"}, {"x": 4, "y": -3, "z": 27, "name": "Soil_Dirt"}, {"x": 4, "y": -2, "z": 27, "name": "Soil_Dirt"}, {"x": 4, "y": -1, "z": 27, "name": "Soil_Dirt"}, {"x": 4, "y": 0, "z": 27, "name": "Soil_Grass"}, {"x": 4, "y": 8, "z": 27, "name": "Plant_Leaves_Beech"}, {"x": 4, "y": 9, "z": 27, "name": "Plant_Leaves_Beech"}, {"x": 4, "y": -3, "z": 28, "name": "Soil_Dirt"}, {"x": 4, "y": -2, "z": 28, "name": "Soil_Dirt"}, {"x": 4, "y": -1, "z": 28, "name": "Soil_Dirt"}, {"x": 4, "y": 0, "z": 28, "name": "Soil_Grass"}, {"x": 4, "y": 8, "z": 28, "name": "Plant_Leaves_Beech"}, {"x": 4, "y": 9, "z": 28, "name": "Plant_Leaves_Beech"}, {"x": 4, "y": 10, "z": 28, "name": "Plant_Leaves_Beech"}, {"x": 4, "y": -3, "z": 29, "name": "Soil_Dirt"}, {"x": 4, "y": -2, "z": 29, "name": "Soil_Dirt"}, {"x": 4, "y": -1, "z": 29, "name": "Soil_Dirt"}, {"x": 4, "y": 0, "z": 29, "name": "Soil_Grass"}, {"x": 4, "y": 8, "z": 29, "name": "Plant_Leaves_Beech"}, {"x": 4, "y": 9, "z": 29, "name": "Plant_Leaves_Beech"}, {"x": 4, "y": 10, "z": 29, "name": "Plant_Leaves_Beech"}, {"x": 4, "y": 11, "z": 29, "name": "Plant_Leaves_Beech"}, {"x": 4, "y": 12, "z": 29, "name": "Plant_Leaves_Beech"}, {"x": 4, "y": -3, "z": 30, "name": "Soil_Dirt"}, {"x": 4, "y": -2, "z": 30, "name": "Soil_Dirt"}, {"x": 4, "y": -1, "z": 30, "name": "Soil_Dirt"}, {"x": 4, "y": 0, "z": 30, "name": "Soil_Grass"}, {"x": 4, "y": 6, "z": 30, "name": "Plant_Leaves_Beech"}, {"x": 4, "y": 9, "z": 30, "name": "Wood_Beech_Branch_Long", "rotation": 5}, {"x": 4, "y": 10, "z": 30, "name": "Plant_Leaves_Beech"}, {"x": 4, "y": 11, "z": 30, "name": "Plant_Leaves_Beech"}, {"x": 4, "y": 14, "z": 30, "name": "Plant_Leaves_Beech"}, {"x": 4, "y": -3, "z": 31, "name": "Soil_Dirt"}, {"x": 4, "y": -2, "z": 31, "name": "Soil_Dirt"}, {"x": 4, "y": -1, "z": 31, "name": "Soil_Dirt"}, {"x": 4, "y": 0, "z": 31, "name": "Soil_Grass"}, {"x": 4, "y": 8, "z": 31, "name": "Plant_Leaves_Beech"}, {"x": 4, "y": 9, "z": 31, "name": "Plant_Leaves_Beech"}, {"x": 4, "y": 10, "z": 31, "name": "Plant_Leaves_Beech"}, {"x": 4, "y": 11, "z": 31, "name": "Plant_Leaves_Beech"}, {"x": 5, "y": -3, "z": 0, "name": "Soil_Dirt"}, {"x": 5, "y": -2, "z": 0, "name": "Soil_Dirt"}, {"x": 5, "y": -1, "z": 0, "name": "Soil_Dirt"}, {"x": 5, "y": 0, "z": 0, "name": "Soil_Grass"}, {"x": 5, "y": -3, "z": 1, "name": "Soil_Dirt"}, {"x": 5, "y": -2, "z": 1, "name": "Soil_Dirt"}, {"x": 5, "y": -1, "z": 1, "name": "Soil_Dirt"}, {"x": 5, "y": 0, "z": 1, "name": "Soil_Grass"}, {"x": 5, "y": -3, "z": 2, "name": "Soil_Dirt"}, {"x": 5, "y": -2, "z": 2, "name": "Soil_Dirt"}, {"x": 5, "y": -1, "z": 2, "name": "Soil_Dirt"}, {"x": 5, "y": 0, "z": 2, "name": "Soil_Grass"}, {"x": 5, "y": 3, "z": 2, "name": "Plant_Crop_Mushroom_Block_Yellow", "rotation": 1}, {"x": 5, "y": -3, "z": 3, "name": "Soil_Dirt"}, {"x": 5, "y": -2, "z": 3, "name": "Wood_Redwood_Roots", "rotation": 1}, {"x": 5, "y": -1, "z": 3, "name": "Wood_Redwood_Trunk", "support": 15, "rotation": 1}, {"x": 5, "y": 0, "z": 3, "name": "Wood_Redwood_Trunk", "support": 15, "rotation": 1}, {"x": 5, "y": 1, "z": 3, "name": "Wood_Redwood_Trunk_Full", "rotation": 1}, {"x": 5, "y": 2, "z": 3, "name": "Plant_Crop_Mushroom_Shelve_Yellow", "rotation": 1}, {"x": 5, "y": 3, "z": 3, "name": "Plant_Crop_Mushroom_Block_Yellow", "rotation": 1}, {"x": 5, "y": 4, "z": 3, "name": "Plant_Moss_Rug_Green", "rotation": 1}, {"x": 5, "y": -3, "z": 4, "name": "Soil_Dirt"}, {"x": 5, "y": -2, "z": 4, "name": "Soil_Dirt"}, {"x": 5, "y": -1, "z": 4, "name": "Soil_Dirt"}, {"x": 5, "y": 0, "z": 4, "name": "Rock_Basalt"}, {"x": 5, "y": 1, "z": 4, "name": "Wood_Redwood_Trunk", "support": 15, "rotation": 1}, {"x": 5, "y": 2, "z": 4, "name": "Wood_Redwood_Trunk", "support": 15, "rotation": 1}, {"x": 5, "y": 3, "z": 4, "name": "Wood_Redwood_Trunk", "support": 15, "rotation": 1}, {"x": 5, "y": 4, "z": 4, "name": "Wood_Redwood_Trunk", "support": 15, "rotation": 1}, {"x": 5, "y": 5, "z": 4, "name": "Soil_Dirt"}, {"x": 5, "y": 6, "z": 4, "name": "Soil_Grass", "rotation": 1}, {"x": 5, "y": 7, "z": 4, "name": "Plant_Grass_Winter", "rotation": 1}, {"x": 5, "y": -3, "z": 5, "name": "Rock_Basalt"}, {"x": 5, "y": -2, "z": 5, "name": "Rock_Basalt"}, {"x": 5, "y": -1, "z": 5, "name": "Rock_Basalt"}, {"x": 5, "y": 0, "z": 5, "name": "Rock_Basalt"}, {"x": 5, "y": 1, "z": 5, "name": "Wood_Redwood_Trunk_Full", "rotation": 1}, {"x": 5, "y": 4, "z": 5, "name": "Wood_Redwood_Trunk_Full", "rotation": 1}, {"x": 5, "y": 5, "z": 5, "name": "Wood_Redwood_Trunk", "support": 15, "rotation": 1}, {"x": 5, "y": 6, "z": 5, "name": "Soil_Grass", "rotation": 1}, {"x": 5, "y": 7, "z": 5, "name": "Plant_Grass_Winter_Tall", "rotation": 1}, {"x": 5, "y": 8, "z": 5, "name": "Plant_Grass_Winter_Tall", "filler": 1024, "rotation": 1}, {"x": 5, "y": -3, "z": 6, "name": "Rock_Basalt"}, {"x": 5, "y": -2, "z": 6, "name": "Rock_Basalt"}, {"x": 5, "y": -1, "z": 6, "name": "Rock_Basalt"}, {"x": 5, "y": 0, "z": 6, "name": "Rock_Basalt"}, {"x": 5, "y": 5, "z": 6, "name": "Wood_Redwood_Trunk_Full", "rotation": 1}, {"x": 5, "y": 6, "z": 6, "name": "Wood_Redwood_Trunk", "support": 15, "rotation": 1}, {"x": 5, "y": -3, "z": 7, "name": "Rock_Basalt"}, {"x": 5, "y": -2, "z": 7, "name": "Rock_Basalt"}, {"x": 5, "y": -1, "z": 7, "name": "Rock_Basalt"}, {"x": 5, "y": 0, "z": 7, "name": "Rock_Basalt"}, {"x": 5, "y": 5, "z": 7, "name": "Rock_Basalt"}, {"x": 5, "y": 6, "z": 7, "name": "Soil_Grass", "rotation": 1}, {"x": 5, "y": 7, "z": 7, "name": "Plant_Grass_Winter_Short", "rotation": 1}, {"x": 5, "y": -3, "z": 8, "name": "Rock_Basalt"}, {"x": 5, "y": -2, "z": 8, "name": "Rock_Basalt"}, {"x": 5, "y": -1, "z": 8, "name": "Rock_Basalt"}, {"x": 5, "y": 0, "z": 8, "name": "Wood_Redwood_Trunk_Full", "rotation": 6}, {"x": 5, "y": 4, "z": 8, "name": "Wood_Redwood_Trunk", "support": 15, "rotation": 1}, {"x": 5, "y": 5, "z": 8, "name": "Wood_Redwood_Trunk", "support": 15, "rotation": 1}, {"x": 5, "y": 6, "z": 8, "name": "Soil_Needles"}, {"x": 5, "y": 10, "z": 8, "name": "Rock_Basalt"}, {"x": 5, "y": 11, "z": 8, "name": "Soil_Grass", "rotation": 1}, {"x": 5, "y": 12, "z": 8, "name": "Plant_Grass_Winter_Short", "rotation": 1}, {"x": 5, "y": -3, "z": 9, "name": "Rock_Basalt"}, {"x": 5, "y": -2, "z": 9, "name": "Rock_Basalt"}, {"x": 5, "y": -1, "z": 9, "name": "Rock_Basalt"}, {"x": 5, "y": 0, "z": 9, "name": "Wood_Redwood_Trunk_Full", "rotation": 5}, {"x": 5, "y": 5, "z": 9, "name": "Wood_Redwood_Trunk_Full", "rotation": 1}, {"x": 5, "y": 6, "z": 9, "name": "Wood_Redwood_Trunk", "support": 15, "rotation": 1}, {"x": 5, "y": 7, "z": 9, "name": "Wood_Redwood_Trunk_Full", "rotation": 1}, {"x": 5, "y": 10, "z": 9, "name": "Rock_Basalt"}, {"x": 5, "y": 11, "z": 9, "name": "Soil_Grass", "rotation": 1}, {"x": 5, "y": 12, "z": 9, "name": "Plant_Grass_Winter", "rotation": 1}, {"x": 5, "y": -3, "z": 10, "name": "Rock_Basalt"}, {"x": 5, "y": -2, "z": 10, "name": "Rock_Basalt"}, {"x": 5, "y": -1, "z": 10, "name": "Rock_Basalt"}, {"x": 5, "y": 0, "z": 10, "name": "Rock_Basalt"}, {"x": 5, "y": 1, "z": 10, "name": "Wood_Redwood_Trunk", "support": 15}, {"x": 5, "y": 2, "z": 10, "name": "Furniture_Kweebec_Candle"}, {"x": 5, "y": 4, "z": 10, "name": "Rock_Basalt"}, {"x": 5, "y": 5, "z": 10, "name": "Rock_Basalt"}, {"x": 5, "y": 6, "z": 10, "name": "Soil_Needles"}, {"x": 5, "y": -3, "z": 11, "name": "Rock_Basalt"}, {"x": 5, "y": -2, "z": 11, "name": "Rock_Basalt"}, {"x": 5, "y": -1, "z": 11, "name": "Rock_Basalt"}, {"x": 5, "y": 0, "z": 11, "name": "Rock_Basalt"}, {"x": 5, "y": 1, "z": 11, "name": "Wood_Redwood_Trunk", "support": 15, "rotation": 4}, {"x": 5, "y": 2, "z": 11, "name": "Wood_Redwood_Trunk_Full", "rotation": 1}, {"x": 5, "y": 3, "z": 11, "name": "Wood_Redwood_Trunk", "support": 15, "rotation": 1}, {"x": 5, "y": 4, "z": 11, "name": "Wood_Redwood_Trunk", "support": 15, "rotation": 1}, {"x": 5, "y": 5, "z": 11, "name": "Wood_Redwood_Trunk", "support": 15, "rotation": 1}, {"x": 5, "y": 6, "z": 11, "name": "Soil_Needles"}, {"x": 5, "y": 7, "z": 11, "name": "Plant_Crop_Mushroom_Common_Brown", "components": {"Components": {"FarmingBlock": {"LastTickGameTime": "0001-01-01T12:00:00Z"}}}, "rotation": 1}, {"x": 5, "y": -3, "z": 12, "name": "Rock_Basalt"}, {"x": 5, "y": -2, "z": 12, "name": "Rock_Basalt"}, {"x": 5, "y": -1, "z": 12, "name": "Rock_Basalt"}, {"x": 5, "y": 0, "z": 12, "name": "Rock_Basalt"}, {"x": 5, "y": 1, "z": 12, "name": "Rock_Basalt"}, {"x": 5, "y": 2, "z": 12, "name": "Rock_Basalt"}, {"x": 5, "y": 3, "z": 12, "name": "Rock_Basalt"}, {"x": 5, "y": 4, "z": 12, "name": "Wood_Redwood_Trunk", "support": 15, "rotation": 1}, {"x": 5, "y": 5, "z": 12, "name": "Wood_Redwood_Trunk", "support": 15, "rotation": 1}, {"x": 5, "y": 6, "z": 12, "name": "Wood_Redwood_Trunk", "support": 15, "rotation": 1}, {"x": 5, "y": 7, "z": 12, "name": "Wood_Redwood_Trunk_Full", "rotation": 1}, {"x": 5, "y": 8, "z": 12, "name": "Plant_Moss_Short_Green", "rotation": 1}, {"x": 5, "y": -3, "z": 13, "name": "Rock_Basalt"}, {"x": 5, "y": -2, "z": 13, "name": "Rock_Basalt"}, {"x": 5, "y": -1, "z": 13, "name": "Rock_Basalt"}, {"x": 5, "y": 0, "z": 13, "name": "Rock_Basalt"}, {"x": 5, "y": 1, "z": 13, "name": "Rock_Basalt"}, {"x": 5, "y": 2, "z": 13, "name": "Rock_Basalt"}, {"x": 5, "y": 3, "z": 13, "name": "Wood_Redwood_Trunk", "support": 15, "rotation": 1}, {"x": 5, "y": 4, "z": 13, "name": "Wood_Redwood_Trunk", "support": 15, "rotation": 1}, {"x": 5, "y": 5, "z": 13, "name": "Wood_Redwood_Trunk", "support": 15, "rotation": 1}, {"x": 5, "y": 6, "z": 13, "name": "Wood_Redwood_Trunk", "support": 15, "rotation": 1}, {"x": 5, "y": 7, "z": 13, "name": "Wood_Redwood_Trunk_Full", "rotation": 1}, {"x": 5, "y": -3, "z": 14, "name": "Rock_Basalt"}, {"x": 5, "y": -2, "z": 14, "name": "Rock_Basalt"}, {"x": 5, "y": -1, "z": 14, "name": "Rock_Basalt"}, {"x": 5, "y": 0, "z": 14, "name": "Rock_Basalt"}, {"x": 5, "y": 1, "z": 14, "name": "Rock_Basalt"}, {"x": 5, "y": 2, "z": 14, "name": "K2_Slot_Sign"}, {"x": 5, "y": 3, "z": 14, "name": "Wood_Redwood_Trunk", "support": 15, "rotation": 1}, {"x": 5, "y": 4, "z": 14, "name": "Wood_Redwood_Trunk", "support": 15, "rotation": 1}, {"x": 5, "y": 5, "z": 14, "name": "Wood_Redwood_Trunk", "support": 15, "rotation": 1}, {"x": 5, "y": 6, "z": 14, "name": "Soil_Needles"}, {"x": 5, "y": -3, "z": 15, "name": "Rock_Basalt"}, {"x": 5, "y": -2, "z": 15, "name": "Rock_Basalt"}, {"x": 5, "y": -1, "z": 15, "name": "Rock_Basalt"}, {"x": 5, "y": 0, "z": 15, "name": "Rock_Basalt"}, {"x": 5, "y": 1, "z": 15, "name": "K2_Slot_Station_Bin"}, {"x": 5, "y": 4, "z": 15, "name": "Rock_Basalt"}, {"x": 5, "y": 5, "z": 15, "name": "Soil_Dirt"}, {"x": 5, "y": 6, "z": 15, "name": "Soil_Needles"}, {"x": 5, "y": -3, "z": 16, "name": "Rock_Basalt"}, {"x": 5, "y": -2, "z": 16, "name": "Rock_Basalt"}, {"x": 5, "y": -1, "z": 16, "name": "Rock_Basalt"}, {"x": 5, "y": 0, "z": 16, "name": "Rock_Basalt"}, {"x": 5, "y": 1, "z": 16, "name": "K2_Slot_Station_Wash"}, {"x": 5, "y": 4, "z": 16, "name": "Rock_Basalt"}, {"x": 5, "y": 5, "z": 16, "name": "Soil_Dirt"}, {"x": 5, "y": 6, "z": 16, "name": "Soil_Grass", "rotation": 1}, {"x": 5, "y": -3, "z": 17, "name": "Rock_Basalt"}, {"x": 5, "y": -2, "z": 17, "name": "Rock_Basalt"}, {"x": 5, "y": -1, "z": 17, "name": "Rock_Basalt"}, {"x": 5, "y": 0, "z": 17, "name": "Rock_Basalt"}, {"x": 5, "y": 1, "z": 17, "name": "K2_Slot_Station_Rack"}, {"x": 5, "y": 4, "z": 17, "name": "Rock_Basalt"}, {"x": 5, "y": 5, "z": 17, "name": "Soil_Dirt"}, {"x": 5, "y": 6, "z": 17, "name": "Soil_Grass", "rotation": 1}, {"x": 5, "y": -3, "z": 18, "name": "Soil_Dirt"}, {"x": 5, "y": -2, "z": 18, "name": "Soil_Dirt"}, {"x": 5, "y": -1, "z": 18, "name": "Soil_Dirt"}, {"x": 5, "y": 0, "z": 18, "name": "Rock_Basalt"}, {"x": 5, "y": 1, "z": 18, "name": "Rock_Basalt"}, {"x": 5, "y": 2, "z": 18, "name": "Rock_Basalt"}, {"x": 5, "y": 3, "z": 18, "name": "Rock_Basalt"}, {"x": 5, "y": 4, "z": 18, "name": "Rock_Basalt"}, {"x": 5, "y": 5, "z": 18, "name": "Soil_Dirt"}, {"x": 5, "y": 6, "z": 18, "name": "Soil_Grass", "rotation": 1}, {"x": 5, "y": -3, "z": 19, "name": "Soil_Dirt"}, {"x": 5, "y": -2, "z": 19, "name": "Soil_Dirt"}, {"x": 5, "y": -1, "z": 19, "name": "Soil_Dirt"}, {"x": 5, "y": 0, "z": 19, "name": "Soil_Grass"}, {"x": 5, "y": -3, "z": 20, "name": "Soil_Dirt"}, {"x": 5, "y": -2, "z": 20, "name": "Soil_Dirt"}, {"x": 5, "y": -1, "z": 20, "name": "Soil_Dirt"}, {"x": 5, "y": 0, "z": 20, "name": "Soil_Grass"}, {"x": 5, "y": -3, "z": 21, "name": "Soil_Dirt"}, {"x": 5, "y": -2, "z": 21, "name": "Soil_Dirt"}, {"x": 5, "y": -1, "z": 21, "name": "Soil_Dirt"}, {"x": 5, "y": 0, "z": 21, "name": "Soil_Grass"}, {"x": 5, "y": -3, "z": 22, "name": "Soil_Dirt"}, {"x": 5, "y": -2, "z": 22, "name": "Soil_Dirt"}, {"x": 5, "y": -1, "z": 22, "name": "Soil_Dirt"}, {"x": 5, "y": 0, "z": 22, "name": "Soil_Grass"}, {"x": 5, "y": -3, "z": 23, "name": "Soil_Dirt"}, {"x": 5, "y": -2, "z": 23, "name": "Soil_Dirt"}, {"x": 5, "y": -1, "z": 23, "name": "Soil_Dirt"}, {"x": 5, "y": 0, "z": 23, "name": "Soil_Grass"}, {"x": 5, "y": -3, "z": 24, "name": "Soil_Dirt"}, {"x": 5, "y": -2, "z": 24, "name": "Soil_Dirt"}, {"x": 5, "y": -1, "z": 24, "name": "Soil_Dirt"}, {"x": 5, "y": 0, "z": 24, "name": "Soil_Grass"}, {"x": 5, "y": -3, "z": 25, "name": "Soil_Dirt"}, {"x": 5, "y": -2, "z": 25, "name": "Soil_Dirt"}, {"x": 5, "y": -1, "z": 25, "name": "Soil_Dirt"}, {"x": 5, "y": 0, "z": 25, "name": "Soil_Grass"}, {"x": 5, "y": -3, "z": 26, "name": "Soil_Dirt"}, {"x": 5, "y": -2, "z": 26, "name": "Soil_Dirt"}, {"x": 5, "y": -1, "z": 26, "name": "Soil_Dirt"}, {"x": 5, "y": 0, "z": 26, "name": "Soil_Grass"}, {"x": 5, "y": 9, "z": 26, "name": "Plant_Leaves_Beech"}, {"x": 5, "y": -3, "z": 27, "name": "Soil_Dirt"}, {"x": 5, "y": -2, "z": 27, "name": "Soil_Dirt"}, {"x": 5, "y": -1, "z": 27, "name": "Soil_Dirt"}, {"x": 5, "y": 0, "z": 27, "name": "Soil_Grass"}, {"x": 5, "y": 8, "z": 27, "name": "Plant_Leaves_Beech"}, {"x": 5, "y": 9, "z": 27, "name": "Plant_Leaves_Beech"}, {"x": 5, "y": 10, "z": 27, "name": "Plant_Leaves_Beech"}, {"x": 5, "y": -3, "z": 28, "name": "Soil_Dirt"}, {"x": 5, "y": -2, "z": 28, "name": "Soil_Dirt"}, {"x": 5, "y": -1, "z": 28, "name": "Soil_Dirt"}, {"x": 5, "y": 0, "z": 28, "name": "Soil_Grass"}, {"x": 5, "y": 8, "z": 28, "name": "Plant_Leaves_Beech"}, {"x": 5, "y": 9, "z": 28, "name": "Plant_Leaves_Beech"}, {"x": 5, "y": 10, "z": 28, "name": "Plant_Leaves_Beech"}, {"x": 5, "y": -3, "z": 29, "name": "Soil_Dirt"}, {"x": 5, "y": -2, "z": 29, "name": "Soil_Dirt"}, {"x": 5, "y": -1, "z": 29, "name": "Soil_Dirt"}, {"x": 5, "y": 0, "z": 29, "name": "Soil_Grass"}, {"x": 5, "y": 6, "z": 29, "name": "Plant_Leaves_Beech"}, {"x": 5, "y": 12, "z": 29, "name": "Plant_Leaves_Beech"}, {"x": 5, "y": 13, "z": 29, "name": "Plant_Leaves_Beech"}, {"x": 5, "y": 14, "z": 29, "name": "Plant_Leaves_Beech"}, {"x": 5, "y": -3, "z": 30, "name": "Soil_Dirt"}, {"x": 5, "y": -2, "z": 30, "name": "Soil_Dirt"}, {"x": 5, "y": -1, "z": 30, "name": "Soil_Dirt"}, {"x": 5, "y": 0, "z": 30, "name": "Soil_Grass"}, {"x": 5, "y": 6, "z": 30, "name": "Plant_Leaves_Beech"}, {"x": 5, "y": 7, "z": 30, "name": "Plant_Leaves_Beech"}, {"x": 5, "y": 9, "z": 30, "name": "Wood_Beech_Branch_Long", "rotation": 5}, {"x": 5, "y": 12, "z": 30, "name": "Plant_Leaves_Beech"}, {"x": 5, "y": 13, "z": 30, "name": "Plant_Leaves_Beech"}, {"x": 5, "y": 14, "z": 30, "name": "Plant_Leaves_Beech"}, {"x": 5, "y": 15, "z": 30, "name": "Plant_Leaves_Beech"}, {"x": 5, "y": -3, "z": 31, "name": "Soil_Dirt"}, {"x": 5, "y": -2, "z": 31, "name": "Soil_Dirt"}, {"x": 5, "y": -1, "z": 31, "name": "Soil_Dirt"}, {"x": 5, "y": 0, "z": 31, "name": "Soil_Grass"}, {"x": 5, "y": 6, "z": 31, "name": "Plant_Leaves_Beech"}, {"x": 5, "y": 12, "z": 31, "name": "Plant_Leaves_Beech"}, {"x": 5, "y": 13, "z": 31, "name": "Plant_Leaves_Beech"}, {"x": 5, "y": 14, "z": 31, "name": "Plant_Leaves_Beech"}, {"x": 6, "y": -3, "z": 0, "name": "Soil_Dirt"}, {"x": 6, "y": -2, "z": 0, "name": "Soil_Dirt"}, {"x": 6, "y": -1, "z": 0, "name": "Soil_Dirt"}, {"x": 6, "y": 0, "z": 0, "name": "Soil_Grass"}, {"x": 6, "y": -3, "z": 1, "name": "Soil_Dirt"}, {"x": 6, "y": -2, "z": 1, "name": "Soil_Dirt"}, {"x": 6, "y": -1, "z": 1, "name": "Soil_Dirt"}, {"x": 6, "y": 0, "z": 1, "name": "Soil_Grass"}, {"x": 6, "y": -3, "z": 2, "name": "Soil_Dirt"}, {"x": 6, "y": -2, "z": 2, "name": "Soil_Dirt"}, {"x": 6, "y": -1, "z": 2, "name": "Soil_Dirt"}, {"x": 6, "y": 0, "z": 2, "name": "Soil_Grass"}, {"x": 6, "y": -3, "z": 3, "name": "Soil_Dirt"}, {"x": 6, "y": -2, "z": 3, "name": "Soil_Dirt"}, {"x": 6, "y": -1, "z": 3, "name": "Soil_Dirt"}, {"x": 6, "y": 0, "z": 3, "name": "Soil_Grass"}, {"x": 6, "y": 3, "z": 3, "name": "Plant_Crop_Mushroom_Block_Yellow", "rotation": 1}, {"x": 6, "y": 5, "z": 3, "name": "Rock_Basalt"}, {"x": 6, "y": 6, "z": 3, "name": "Soil_Grass", "rotation": 1}, {"x": 6, "y": -3, "z": 4, "name": "Soil_Dirt"}, {"x": 6, "y": -2, "z": 4, "name": "Soil_Dirt"}, {"x": 6, "y": -1, "z": 4, "name": "Rock_Basalt"}, {"x": 6, "y": 0, "z": 4, "name": "Rock_Basalt"}, {"x": 6, "y": 1, "z": 4, "name": "Soil_Needles"}, {"x": 6, "y": 2, "z": 4, "name": "Soil_Needles"}, {"x": 6, "y": 3, "z": 4, "name": "Wood_Redwood_Trunk", "support": 15, "rotation": 1}, {"x": 6, "y": 4, "z": 4, "name": "Wood_Redwood_Trunk", "support": 15, "rotation": 1}, {"x": 6, "y": 5, "z": 4, "name": "Rock_Basalt"}, {"x": 6, "y": 6, "z": 4, "name": "Soil_Grass", "rotation": 1}, {"x": 6, "y": -3, "z": 5, "name": "Rock_Basalt"}, {"x": 6, "y": -2, "z": 5, "name": "Rock_Basalt"}, {"x": 6, "y": -1, "z": 5, "name": "Rock_Basalt"}, {"x": 6, "y": 0, "z": 5, "name": "Rock_Basalt"}, {"x": 6, "y": 1, "z": 5, "name": "Wood_Redwood_Trunk_Full", "rotation": 1}, {"x": 6, "y": 2, "z": 5, "name": "Furniture_Kweebec_Candle", "rotation": 1}, {"x": 6, "y": 5, "z": 5, "name": "Wood_Redwood_Trunk_Full", "rotation": 1}, {"x": 6, "y": 6, "z": 5, "name": "Wood_Redwood_Trunk", "support": 15, "rotation": 1}, {"x": 6, "y": 7, "z": 5, "name": "Soil_Grass", "rotation": 1}, {"x": 6, "y": -3, "z": 6, "name": "Rock_Basalt"}, {"x": 6, "y": -2, "z": 6, "name": "Rock_Basalt"}, {"x": 6, "y": -1, "z": 6, "name": "Rock_Basalt"}, {"x": 6, "y": 0, "z": 6, "name": "Rock_Basalt"}, {"x": 6, "y": 5, "z": 6, "name": "Wood_Redwood_Trunk_Full", "rotation": 1}, {"x": 6, "y": 6, "z": 6, "name": "Wood_Redwood_Trunk", "support": 15, "rotation": 1}, {"x": 6, "y": 7, "z": 6, "name": "Wood_Redwood_Trunk_Full", "rotation": 1}, {"x": 6, "y": 8, "z": 6, "name": "Plant_Moss_Rug_Green", "rotation": 1}, {"x": 6, "y": -3, "z": 7, "name": "Rock_Basalt"}, {"x": 6, "y": -2, "z": 7, "name": "Rock_Basalt"}, {"x": 6, "y": -1, "z": 7, "name": "Rock_Basalt"}, {"x": 6, "y": 0, "z": 7, "name": "Wood_Redwood_Trunk_Full", "rotation": 5}, {"x": 6, "y": 6, "z": 7, "name": "Wood_Redwood_Trunk_Full", "rotation": 1}, {"x": 6, "y": 7, "z": 7, "name": "Soil_Grass", "rotation": 1}, {"x": 6, "y": 10, "z": 7, "name": "Rock_Basalt"}, {"x": 6, "y": 11, "z": 7, "name": "Soil_Grass", "rotation": 1}, {"x": 6, "y": 12, "z": 7, "name": "Plant_Grass_Winter", "rotation": 1}, {"x": 6, "y": -3, "z": 8, "name": "Rock_Basalt"}, {"x": 6, "y": -2, "z": 8, "name": "Rock_Basalt"}, {"x": 6, "y": -1, "z": 8, "name": "Rock_Basalt"}, {"x": 6, "y": 0, "z": 8, "name": "Rock_Basalt"}, {"x": 6, "y": 6, "z": 8, "name": "Rock_Basalt"}, {"x": 6, "y": 7, "z": 8, "name": "Soil_Dirt"}, {"x": 6, "y": 8, "z": 8, "name": "Rock_Basalt"}, {"x": 6, "y": 9, "z": 8, "name": "Rock_Basalt"}, {"x": 6, "y": 10, "z": 8, "name": "Rock_Basalt"}, {"x": 6, "y": 11, "z": 8, "name": "Soil_Grass", "rotation": 1}, {"x": 6, "y": 12, "z": 8, "name": "Plant_Grass_Winter_Tall", "rotation": 1}, {"x": 6, "y": 13, "z": 8, "name": "Plant_Grass_Winter_Tall", "filler": 1024, "rotation": 1}, {"x": 6, "y": -3, "z": 9, "name": "Rock_Basalt"}, {"x": 6, "y": -2, "z": 9, "name": "Rock_Basalt"}, {"x": 6, "y": -1, "z": 9, "name": "Rock_Basalt"}, {"x": 6, "y": 0, "z": 9, "name": "Rock_Basalt"}, {"x": 6, "y": 6, "z": 9, "name": "Wood_Redwood_Trunk_Full", "rotation": 1}, {"x": 6, "y": 7, "z": 9, "name": "Wood_Redwood_Trunk", "rotation": 1}, {"x": 6, "y": 8, "z": 9, "name": "Wood_Redwood_Trunk_Full", "rotation": 1}, {"x": 6, "y": 9, "z": 9, "name": "Rock_Basalt"}, {"x": 6, "y": 10, "z": 9, "name": "Rock_Basalt"}, {"x": 6, "y": 11, "z": 9, "name": "Soil_Grass", "rotation": 1}, {"x": 6, "y": 12, "z": 9, "name": "Plant_Grass_Winter_Tall", "rotation": 1}, {"x": 6, "y": 13, "z": 9, "name": "Plant_Grass_Winter_Tall", "filler": 1024, "rotation": 1}, {"x": 6, "y": -3, "z": 10, "name": "Rock_Basalt"}, {"x": 6, "y": -2, "z": 10, "name": "Rock_Basalt"}, {"x": 6, "y": -1, "z": 10, "name": "Rock_Basalt"}, {"x": 6, "y": 0, "z": 10, "name": "Rock_Basalt"}, {"x": 6, "y": 6, "z": 10, "name": "Rock_Basalt"}, {"x": 6, "y": 7, "z": 10, "name": "Soil_Grass", "rotation": 1}, {"x": 6, "y": 9, "z": 10, "name": "Rock_Basalt"}, {"x": 6, "y": 10, "z": 10, "name": "Rock_Basalt"}, {"x": 6, "y": 11, "z": 10, "name": "Soil_Grass", "rotation": 1}, {"x": 6, "y": -3, "z": 11, "name": "Rock_Basalt"}, {"x": 6, "y": -2, "z": 11, "name": "Rock_Basalt"}, {"x": 6, "y": -1, "z": 11, "name": "Rock_Basalt"}, {"x": 6, "y": 0, "z": 11, "name": "Rock_Basalt"}, {"x": 6, "y": 3, "z": 11, "name": "Wood_Redwood_Trunk_Full", "support": 2, "rotation": 1}, {"x": 6, "y": 4, "z": 11, "name": "Wood_Redwood_Trunk_Full", "rotation": 1}, {"x": 6, "y": 5, "z": 11, "name": "Wood_Redwood_Trunk", "support": 15, "rotation": 1}, {"x": 6, "y": 6, "z": 11, "name": "Soil_Dirt"}, {"x": 6, "y": 7, "z": 11, "name": "Wood_Redwood_Trunk", "rotation": 1}, {"x": 6, "y": 8, "z": 11, "name": "Wood_Redwood_Trunk_Full", "rotation": 1}, {"x": 6, "y": -3, "z": 12, "name": "Rock_Basalt"}, {"x": 6, "y": -2, "z": 12, "name": "Rock_Basalt"}, {"x": 6, "y": -1, "z": 12, "name": "Rock_Basalt"}, {"x": 6, "y": 0, "z": 12, "name": "Rock_Basalt"}, {"x": 6, "y": 4, "z": 12, "name": "Wood_Redwood_Trunk_Full", "support": 1, "rotation": 1}, {"x": 6, "y": 5, "z": 12, "name": "Wood_Redwood_Trunk", "support": 15, "rotation": 1}, {"x": 6, "y": 6, "z": 12, "name": "Wood_Redwood_Trunk", "support": 15, "rotation": 1}, {"x": 6, "y": 7, "z": 12, "name": "Wood_Redwood_Trunk", "rotation": 1}, {"x": 6, "y": 8, "z": 12, "name": "Wood_Redwood_Trunk_Full", "rotation": 1}, {"x": 6, "y": -3, "z": 13, "name": "Rock_Basalt"}, {"x": 6, "y": -2, "z": 13, "name": "Rock_Basalt"}, {"x": 6, "y": -1, "z": 13, "name": "Rock_Basalt"}, {"x": 6, "y": 0, "z": 13, "name": "Rock_Basalt"}, {"x": 6, "y": 1, "z": 13, "name": "K2_Slot_Station_Combine"}, {"x": 6, "y": 3, "z": 13, "name": "Rock_Basalt"}, {"x": 6, "y": 4, "z": 13, "name": "Rock_Basalt"}, {"x": 6, "y": 5, "z": 13, "name": "Wood_Redwood_Trunk", "support": 15, "rotation": 1}, {"x": 6, "y": 6, "z": 13, "name": "Wood_Redwood_Trunk", "support": 15, "rotation": 1}, {"x": 6, "y": 7, "z": 13, "name": "Soil_Needles"}, {"x": 6, "y": -3, "z": 14, "name": "Rock_Basalt"}, {"x": 6, "y": -2, "z": 14, "name": "Rock_Basalt"}, {"x": 6, "y": -1, "z": 14, "name": "Rock_Basalt"}, {"x": 6, "y": 0, "z": 14, "name": "Rock_Basalt"}, {"x": 6, "y": 4, "z": 14, "name": "Rock_Basalt"}, {"x": 6, "y": 5, "z": 14, "name": "Rock_Basalt"}, {"x": 6, "y": 6, "z": 14, "name": "Soil_Dirt"}, {"x": 6, "y": 7, "z": 14, "name": "Soil_Needles"}, {"x": 6, "y": -3, "z": 15, "name": "Rock_Basalt"}, {"x": 6, "y": -2, "z": 15, "name": "Rock_Basalt"}, {"x": 6, "y": -1, "z": 15, "name": "Rock_Basalt"}, {"x": 6, "y": 0, "z": 15, "name": "Rock_Basalt"}, {"x": 6, "y": 4, "z": 15, "name": "Rock_Basalt"}, {"x": 6, "y": 5, "z": 15, "name": "Rock_Basalt"}, {"x": 6, "y": 6, "z": 15, "name": "Soil_Dirt"}, {"x": 6, "y": 7, "z": 15, "name": "Soil_Needles"}, {"x": 6, "y": -3, "z": 16, "name": "Rock_Basalt"}, {"x": 6, "y": -2, "z": 16, "name": "Rock_Basalt"}, {"x": 6, "y": -1, "z": 16, "name": "Rock_Basalt"}, {"x": 6, "y": 0, "z": 16, "name": "Rock_Basalt"}, {"x": 6, "y": 4, "z": 16, "name": "Rock_Basalt"}, {"x": 6, "y": 5, "z": 16, "name": "Rock_Basalt"}, {"x": 6, "y": 6, "z": 16, "name": "Soil_Grass", "rotation": 1}, {"x": 6, "y": -3, "z": 17, "name": "Rock_Basalt"}, {"x": 6, "y": -2, "z": 17, "name": "Rock_Basalt"}, {"x": 6, "y": -1, "z": 17, "name": "Rock_Basalt"}, {"x": 6, "y": 0, "z": 17, "name": "Rock_Basalt"}, {"x": 6, "y": 1, "z": 17, "name": "K2_Slot_Station_Heat"}, {"x": 6, "y": 4, "z": 17, "name": "Rock_Basalt"}, {"x": 6, "y": 5, "z": 17, "name": "Rock_Basalt"}, {"x": 6, "y": 6, "z": 17, "name": "Soil_Grass", "rotation": 1}, {"x": 6, "y": -3, "z": 18, "name": "Soil_Dirt"}, {"x": 6, "y": -2, "z": 18, "name": "Rock_Basalt"}, {"x": 6, "y": -1, "z": 18, "name": "Rock_Basalt"}, {"x": 6, "y": 0, "z": 18, "name": "Rock_Basalt"}, {"x": 6, "y": 1, "z": 18, "name": "Rock_Basalt"}, {"x": 6, "y": 2, "z": 18, "name": "Rock_Basalt"}, {"x": 6, "y": 3, "z": 18, "name": "Rock_Basalt"}, {"x": 6, "y": 4, "z": 18, "name": "Rock_Basalt"}, {"x": 6, "y": 5, "z": 18, "name": "Soil_Dirt"}, {"x": 6, "y": 6, "z": 18, "name": "Soil_Grass", "rotation": 1}, {"x": 6, "y": 7, "z": 18, "name": "Plant_Grass_Winter_Short", "rotation": 1}, {"x": 6, "y": -3, "z": 19, "name": "Soil_Dirt"}, {"x": 6, "y": -2, "z": 19, "name": "Soil_Dirt"}, {"x": 6, "y": -1, "z": 19, "name": "Soil_Dirt"}, {"x": 6, "y": 0, "z": 19, "name": "Soil_Grass"}, {"x": 6, "y": 4, "z": 19, "name": "Rock_Basalt"}, {"x": 6, "y": 5, "z": 19, "name": "Soil_Dirt"}, {"x": 6, "y": 6, "z": 19, "name": "Soil_Grass", "rotation": 1}, {"x": 6, "y": -3, "z": 20, "name": "Soil_Dirt"}, {"x": 6, "y": -2, "z": 20, "name": "Soil_Dirt"}, {"x": 6, "y": -1, "z": 20, "name": "Soil_Dirt"}, {"x": 6, "y": 0, "z": 20, "name": "Soil_Grass"}, {"x": 6, "y": -3, "z": 21, "name": "Soil_Dirt"}, {"x": 6, "y": -2, "z": 21, "name": "Soil_Dirt"}, {"x": 6, "y": -1, "z": 21, "name": "Soil_Dirt"}, {"x": 6, "y": 0, "z": 21, "name": "K2_Slot_Arrival"}, {"x": 6, "y": -3, "z": 22, "name": "Soil_Dirt"}, {"x": 6, "y": -2, "z": 22, "name": "Soil_Dirt"}, {"x": 6, "y": -1, "z": 22, "name": "Soil_Dirt"}, {"x": 6, "y": 0, "z": 22, "name": "Soil_Grass"}, {"x": 6, "y": -3, "z": 23, "name": "Soil_Dirt"}, {"x": 6, "y": -2, "z": 23, "name": "Soil_Dirt"}, {"x": 6, "y": -1, "z": 23, "name": "Soil_Dirt"}, {"x": 6, "y": 0, "z": 23, "name": "Soil_Grass"}, {"x": 6, "y": -3, "z": 24, "name": "Soil_Dirt"}, {"x": 6, "y": -2, "z": 24, "name": "Soil_Dirt"}, {"x": 6, "y": -1, "z": 24, "name": "Soil_Dirt"}, {"x": 6, "y": 0, "z": 24, "name": "Soil_Grass"}, {"x": 6, "y": -3, "z": 25, "name": "Soil_Dirt"}, {"x": 6, "y": -2, "z": 25, "name": "Soil_Dirt"}, {"x": 6, "y": -1, "z": 25, "name": "Soil_Dirt"}, {"x": 6, "y": 0, "z": 25, "name": "Soil_Grass"}, {"x": 6, "y": 6, "z": 25, "name": "Plant_Leaves_Beech"}, {"x": 6, "y": 8, "z": 25, "name": "Plant_Leaves_Beech"}, {"x": 6, "y": -3, "z": 26, "name": "Soil_Dirt"}, {"x": 6, "y": -2, "z": 26, "name": "Soil_Dirt"}, {"x": 6, "y": -1, "z": 26, "name": "Soil_Dirt"}, {"x": 6, "y": 0, "z": 26, "name": "Soil_Grass"}, {"x": 6, "y": 8, "z": 26, "name": "Plant_Leaves_Beech"}, {"x": 6, "y": 9, "z": 26, "name": "Plant_Leaves_Beech"}, {"x": 6, "y": 15, "z": 26, "name": "Plant_Leaves_Beech"}, {"x": 6, "y": -3, "z": 27, "name": "Soil_Dirt"}, {"x": 6, "y": -2, "z": 27, "name": "Soil_Dirt"}, {"x": 6, "y": -1, "z": 27, "name": "Soil_Dirt"}, {"x": 6, "y": 0, "z": 27, "name": "Soil_Grass"}, {"x": 6, "y": 11, "z": 27, "name": "Plant_Leaves_Beech"}, {"x": 6, "y": -3, "z": 28, "name": "Soil_Dirt"}, {"x": 6, "y": -2, "z": 28, "name": "Soil_Dirt"}, {"x": 6, "y": -1, "z": 28, "name": "Soil_Dirt"}, {"x": 6, "y": 0, "z": 28, "name": "Soil_Grass"}, {"x": 6, "y": 9, "z": 28, "name": "Plant_Leaves_Beech"}, {"x": 6, "y": 10, "z": 28, "name": "Plant_Leaves_Beech"}, {"x": 6, "y": 11, "z": 28, "name": "Plant_Leaves_Beech"}, {"x": 6, "y": 12, "z": 28, "name": "Plant_Leaves_Beech"}, {"x": 6, "y": -3, "z": 29, "name": "Soil_Dirt"}, {"x": 6, "y": -2, "z": 29, "name": "Soil_Dirt"}, {"x": 6, "y": -1, "z": 29, "name": "Soil_Dirt"}, {"x": 6, "y": 0, "z": 29, "name": "Soil_Grass"}, {"x": 6, "y": 7, "z": 29, "name": "Plant_Leaves_Beech"}, {"x": 6, "y": 9, "z": 29, "name": "Wood_Beech_Branch_Long", "rotation": 4}, {"x": 6, "y": 12, "z": 29, "name": "Plant_Leaves_Beech"}, {"x": 6, "y": 13, "z": 29, "name": "Plant_Leaves_Beech"}, {"x": 6, "y": 15, "z": 29, "name": "Plant_Leaves_Beech"}, {"x": 6, "y": -3, "z": 30, "name": "Soil_Dirt"}, {"x": 6, "y": -2, "z": 30, "name": "Soil_Dirt"}, {"x": 6, "y": -1, "z": 30, "name": "Soil_Dirt"}, {"x": 6, "y": 0, "z": 30, "name": "Soil_Grass"}, {"x": 6, "y": 6, "z": 30, "name": "Wood_Beech_Branch_Long", "rotation": 5}, {"x": 6, "y": 7, "z": 30, "name": "Plant_Leaves_Beech"}, {"x": 6, "y": 8, "z": 30, "name": "Wood_Beech_Trunk_Full"}, {"x": 6, "y": 9, "z": 30, "name": "Wood_Beech_Trunk_Full"}, {"x": 6, "y": 10, "z": 30, "name": "Wood_Beech_Branch_Long"}, {"x": 6, "y": 11, "z": 30, "name": "Wood_Beech_Branch_Long"}, {"x": 6, "y": 12, "z": 30, "name": "Plant_Leaves_Beech"}, {"x": 6, "y": 13, "z": 30, "name": "Plant_Leaves_Beech"}, {"x": 6, "y": 14, "z": 30, "name": "Wood_Beech_Branch_Long", "rotation": 5}, {"x": 6, "y": 15, "z": 30, "name": "Plant_Leaves_Beech"}, {"x": 6, "y": -3, "z": 31, "name": "Soil_Dirt"}, {"x": 6, "y": -2, "z": 31, "name": "Soil_Dirt"}, {"x": 6, "y": -1, "z": 31, "name": "Soil_Dirt"}, {"x": 6, "y": 0, "z": 31, "name": "Soil_Grass"}, {"x": 6, "y": 6, "z": 31, "name": "Plant_Leaves_Beech"}, {"x": 6, "y": 12, "z": 31, "name": "Plant_Leaves_Beech"}, {"x": 6, "y": 14, "z": 31, "name": "Plant_Leaves_Beech"}, {"x": 7, "y": -3, "z": 0, "name": "Soil_Dirt"}, {"x": 7, "y": -2, "z": 0, "name": "Soil_Dirt"}, {"x": 7, "y": -1, "z": 0, "name": "Soil_Dirt"}, {"x": 7, "y": 0, "z": 0, "name": "Soil_Grass"}, {"x": 7, "y": -3, "z": 1, "name": "Soil_Dirt"}, {"x": 7, "y": -2, "z": 1, "name": "Soil_Dirt"}, {"x": 7, "y": -1, "z": 1, "name": "Soil_Dirt"}, {"x": 7, "y": 0, "z": 1, "name": "Soil_Grass"}, {"x": 7, "y": 2, "z": 1, "name": "Furniture_Kweebec_Lantern", "rotation": 1}, {"x": 7, "y": 3, "z": 1, "name": "Wood_Redwood_Branch_Corner", "support": 2, "rotation": 35}, {"x": 7, "y": -3, "z": 2, "name": "Soil_Dirt"}, {"x": 7, "y": -2, "z": 2, "name": "Soil_Dirt"}, {"x": 7, "y": -1, "z": 2, "name": "Soil_Dirt"}, {"x": 7, "y": 0, "z": 2, "name": "Soil_Grass"}, {"x": 7, "y": 6, "z": 2, "name": "Plant_Crop_Mushroom_Block_Yellow", "rotation": 1}, {"x": 7, "y": -3, "z": 3, "name": "Soil_Dirt"}, {"x": 7, "y": -2, "z": 3, "name": "Wood_Redwood_Trunk_Full", "rotation": 1}, {"x": 7, "y": -1, "z": 3, "name": "Wood_Redwood_Trunk", "support": 15, "rotation": 1}, {"x": 7, "y": 0, "z": 3, "name": "Wood_Redwood_Trunk_Full", "rotation": 1}, {"x": 7, "y": 1, "z": 3, "name": "Wood_Redwood_Branch_Corner", "rotation": 35}, {"x": 7, "y": 4, "z": 3, "name": "Wood_Redwood_Trunk", "support": 15, "rotation": 1}, {"x": 7, "y": 5, "z": 3, "name": "Rock_Basalt"}, {"x": 7, "y": 6, "z": 3, "name": "Soil_Dirt"}, {"x": 7, "y": 7, "z": 3, "name": "Soil_Grass", "rotation": 1}, {"x": 7, "y": -3, "z": 4, "name": "Wood_Redwood_Trunk", "support": 15, "rotation": 1}, {"x": 7, "y": -2, "z": 4, "name": "Wood_Redwood_Trunk", "support": 15, "rotation": 1}, {"x": 7, "y": -1, "z": 4, "name": "Rock_Basalt"}, {"x": 7, "y": 0, "z": 4, "name": "Rock_Basalt"}, {"x": 7, "y": 1, "z": 4, "name": "Soil_Needles"}, {"x": 7, "y": 2, "z": 4, "name": "Furniture_Kweebec_Window", "rotation": 2}, {"x": 7, "y": 3, "z": 4, "name": "Soil_Needles"}, {"x": 7, "y": 4, "z": 4, "name": "Wood_Redwood_Trunk", "support": 15, "rotation": 1}, {"x": 7, "y": 5, "z": 4, "name": "Rock_Basalt"}, {"x": 7, "y": 6, "z": 4, "name": "Soil_Dirt"}, {"x": 7, "y": 7, "z": 4, "name": "Soil_Grass", "rotation": 1}, {"x": 7, "y": -3, "z": 5, "name": "Rock_Basalt"}, {"x": 7, "y": -2, "z": 5, "name": "Rock_Basalt"}, {"x": 7, "y": -1, "z": 5, "name": "Rock_Basalt"}, {"x": 7, "y": 0, "z": 5, "name": "Rock_Basalt"}, {"x": 7, "y": 5, "z": 5, "name": "Rock_Basalt"}, {"x": 7, "y": 6, "z": 5, "name": "Soil_Dirt"}, {"x": 7, "y": 7, "z": 5, "name": "Soil_Grass", "rotation": 1}, {"x": 7, "y": 8, "z": 5, "name": "Plant_Grass_Winter_Short", "rotation": 1}, {"x": 7, "y": -3, "z": 6, "name": "Rock_Basalt"}, {"x": 7, "y": -2, "z": 6, "name": "Rock_Basalt"}, {"x": 7, "y": -1, "z": 6, "name": "Rock_Basalt"}, {"x": 7, "y": 0, "z": 6, "name": "Rock_Basalt"}, {"x": 7, "y": 6, "z": 6, "name": "Wood_Redwood_Trunk_Full", "rotation": 1}, {"x": 7, "y": 7, "z": 6, "name": "Wood_Redwood_Trunk_Full", "rotation": 1}, {"x": 7, "y": 8, "z": 6, "name": "Plant_Moss_Rug_Green", "rotation": 1}, {"x": 7, "y": -3, "z": 7, "name": "Rock_Basalt"}, {"x": 7, "y": -2, "z": 7, "name": "Rock_Basalt"}, {"x": 7, "y": -1, "z": 7, "name": "Rock_Basalt"}, {"x": 7, "y": 0, "z": 7, "name": "Wood_Redwood_Trunk_Full", "rotation": 5}, {"x": 7, "y": 6, "z": 7, "name": "Wood_Redwood_Trunk_Full", "rotation": 1}, {"x": 7, "y": 7, "z": 7, "name": "Wood_Redwood_Trunk_Full", "rotation": 1}, {"x": 7, "y": 8, "z": 7, "name": "Plant_Moss_Rug_Green", "rotation": 1}, {"x": 7, "y": 9, "z": 7, "name": "Rock_Basalt"}, {"x": 7, "y": 10, "z": 7, "name": "Rock_Basalt"}, {"x": 7, "y": 11, "z": 7, "name": "Soil_Grass", "rotation": 1}, {"x": 7, "y": -3, "z": 8, "name": "Rock_Basalt"}, {"x": 7, "y": -2, "z": 8, "name": "Rock_Basalt"}, {"x": 7, "y": -1, "z": 8, "name": "Rock_Basalt"}, {"x": 7, "y": 0, "z": 8, "name": "Rock_Basalt"}, {"x": 7, "y": 1, "z": 8, "name": "K2_Slot_Chair", "rotation": 1}, {"x": 7, "y": 6, "z": 8, "name": "Rock_Basalt"}, {"x": 7, "y": 7, "z": 8, "name": "Wood_Redwood_Trunk", "rotation": 1}, {"x": 7, "y": 8, "z": 8, "name": "Wood_Redwood_Trunk", "rotation": 1}, {"x": 7, "y": 9, "z": 8, "name": "Wood_Redwood_Trunk", "rotation": 1}, {"x": 7, "y": 10, "z": 8, "name": "Wood_Redwood_Trunk", "rotation": 1}, {"x": 7, "y": 11, "z": 8, "name": "Wood_Redwood_Trunk", "rotation": 1}, {"x": 7, "y": 12, "z": 8, "name": "Wood_Redwood_Trunk_Full", "rotation": 1}, {"x": 7, "y": -3, "z": 9, "name": "Rock_Basalt"}, {"x": 7, "y": -2, "z": 9, "name": "Rock_Basalt"}, {"x": 7, "y": -1, "z": 9, "name": "Rock_Basalt"}, {"x": 7, "y": 0, "z": 9, "name": "Rock_Basalt"}, {"x": 7, "y": 6, "z": 9, "name": "Rock_Basalt"}, {"x": 7, "y": 7, "z": 9, "name": "Wood_Redwood_Trunk", "rotation": 1}, {"x": 7, "y": 8, "z": 9, "name": "Wood_Redwood_Trunk", "rotation": 1}, {"x": 7, "y": 9, "z": 9, "name": "Wood_Redwood_Trunk", "rotation": 1}, {"x": 7, "y": 10, "z": 9, "name": "Wood_Redwood_Trunk", "rotation": 1}, {"x": 7, "y": 11, "z": 9, "name": "Wood_Redwood_Trunk", "rotation": 1}, {"x": 7, "y": 12, "z": 9, "name": "Wood_Redwood_Trunk", "rotation": 1}, {"x": 7, "y": 13, "z": 9, "name": "Wood_Redwood_Trunk", "rotation": 1}, {"x": 7, "y": 14, "z": 9, "name": "Wood_Redwood_Trunk", "rotation": 1}, {"x": 7, "y": 15, "z": 9, "name": "Wood_Redwood_Trunk", "rotation": 1}, {"x": 7, "y": -3, "z": 10, "name": "Rock_Basalt"}, {"x": 7, "y": -2, "z": 10, "name": "Rock_Basalt"}, {"x": 7, "y": -1, "z": 10, "name": "Rock_Basalt"}, {"x": 7, "y": 0, "z": 10, "name": "Rock_Basalt"}, {"x": 7, "y": 6, "z": 10, "name": "Rock_Basalt"}, {"x": 7, "y": 7, "z": 10, "name": "Wood_Redwood_Trunk", "rotation": 1}, {"x": 7, "y": 8, "z": 10, "name": "Wood_Redwood_Trunk", "rotation": 1}, {"x": 7, "y": 9, "z": 10, "name": "Wood_Redwood_Trunk_Full", "rotation": 1}, {"x": 7, "y": 10, "z": 10, "name": "Rock_Basalt"}, {"x": 7, "y": 11, "z": 10, "name": "Soil_Grass", "rotation": 1}, {"x": 7, "y": -3, "z": 11, "name": "Rock_Basalt"}, {"x": 7, "y": -2, "z": 11, "name": "Rock_Basalt"}, {"x": 7, "y": -1, "z": 11, "name": "Rock_Basalt"}, {"x": 7, "y": 0, "z": 11, "name": "Rock_Basalt"}, {"x": 7, "y": 6, "z": 11, "name": "Rock_Basalt"}, {"x": 7, "y": 7, "z": 11, "name": "Wood_Redwood_Trunk", "rotation": 1}, {"x": 7, "y": 8, "z": 11, "name": "Wood_Redwood_Trunk_Full", "rotation": 1}, {"x": 7, "y": 9, "z": 11, "name": "Rock_Basalt"}, {"x": 7, "y": -3, "z": 12, "name": "Rock_Basalt"}, {"x": 7, "y": -2, "z": 12, "name": "Rock_Basalt"}, {"x": 7, "y": -1, "z": 12, "name": "Rock_Basalt"}, {"x": 7, "y": 0, "z": 12, "name": "Plant_Moss_Block_Green", "rotation": 1}, {"x": 7, "y": 5, "z": 12, "name": "Rock_Basalt"}, {"x": 7, "y": 6, "z": 12, "name": "Soil_Dirt"}, {"x": 7, "y": 7, "z": 12, "name": "Soil_Needles"}, {"x": 7, "y": -3, "z": 13, "name": "Rock_Basalt"}, {"x": 7, "y": -2, "z": 13, "name": "Rock_Basalt"}, {"x": 7, "y": -1, "z": 13, "name": "Rock_Basalt"}, {"x": 7, "y": 0, "z": 13, "name": "Rock_Basalt"}, {"x": 7, "y": 1, "z": 13, "name": "K2_Slot_Station_Combine"}, {"x": 7, "y": 3, "z": 13, "name": "Rock_Basalt"}, {"x": 7, "y": 4, "z": 13, "name": "Rock_Basalt"}, {"x": 7, "y": 5, "z": 13, "name": "Rock_Basalt"}, {"x": 7, "y": 6, "z": 13, "name": "Soil_Dirt"}, {"x": 7, "y": 7, "z": 13, "name": "Soil_Needles"}, {"x": 7, "y": -3, "z": 14, "name": "Rock_Basalt"}, {"x": 7, "y": -2, "z": 14, "name": "Rock_Basalt"}, {"x": 7, "y": -1, "z": 14, "name": "Rock_Basalt"}, {"x": 7, "y": 0, "z": 14, "name": "Rock_Basalt"}, {"x": 7, "y": 4, "z": 14, "name": "Rock_Basalt"}, {"x": 7, "y": 5, "z": 14, "name": "Rock_Basalt"}, {"x": 7, "y": 6, "z": 14, "name": "Soil_Dirt"}, {"x": 7, "y": 7, "z": 14, "name": "Soil_Needles"}, {"x": 7, "y": -3, "z": 15, "name": "Rock_Basalt"}, {"x": 7, "y": -2, "z": 15, "name": "Rock_Basalt"}, {"x": 7, "y": -1, "z": 15, "name": "Rock_Basalt"}, {"x": 7, "y": 0, "z": 15, "name": "Rock_Basalt"}, {"x": 7, "y": 4, "z": 15, "name": "Rock_Basalt"}, {"x": 7, "y": 5, "z": 15, "name": "Rock_Basalt"}, {"x": 7, "y": 6, "z": 15, "name": "Soil_Dirt"}, {"x": 7, "y": 7, "z": 15, "name": "Soil_Needles"}, {"x": 7, "y": -3, "z": 16, "name": "Rock_Basalt"}, {"x": 7, "y": -2, "z": 16, "name": "Rock_Basalt"}, {"x": 7, "y": -1, "z": 16, "name": "Rock_Basalt"}, {"x": 7, "y": 0, "z": 16, "name": "Rock_Basalt"}, {"x": 7, "y": 4, "z": 16, "name": "Rock_Basalt"}, {"x": 7, "y": 5, "z": 16, "name": "Rock_Basalt"}, {"x": 7, "y": 6, "z": 16, "name": "Soil_Dirt"}, {"x": 7, "y": 7, "z": 16, "name": "Soil_Needles"}, {"x": 7, "y": -3, "z": 17, "name": "Rock_Basalt"}, {"x": 7, "y": -2, "z": 17, "name": "Rock_Basalt"}, {"x": 7, "y": -1, "z": 17, "name": "Rock_Basalt"}, {"x": 7, "y": 0, "z": 17, "name": "Rock_Basalt"}, {"x": 7, "y": 1, "z": 17, "name": "K2_Slot_Station_Press"}, {"x": 7, "y": 4, "z": 17, "name": "Rock_Basalt"}, {"x": 7, "y": 5, "z": 17, "name": "Rock_Basalt"}, {"x": 7, "y": 6, "z": 17, "name": "Soil_Dirt"}, {"x": 7, "y": 7, "z": 17, "name": "Soil_Grass", "rotation": 1}, {"x": 7, "y": -3, "z": 18, "name": "Rock_Basalt"}, {"x": 7, "y": -2, "z": 18, "name": "Rock_Basalt"}, {"x": 7, "y": -1, "z": 18, "name": "Rock_Basalt"}, {"x": 7, "y": 0, "z": 18, "name": "Rock_Basalt"}, {"x": 7, "y": 1, "z": 18, "name": "Rock_Basalt"}, {"x": 7, "y": 2, "z": 18, "name": "Rock_Basalt"}, {"x": 7, "y": 3, "z": 18, "name": "Rock_Basalt"}, {"x": 7, "y": 4, "z": 18, "name": "Rock_Basalt"}, {"x": 7, "y": 5, "z": 18, "name": "Soil_Dirt"}, {"x": 7, "y": 6, "z": 18, "name": "Soil_Dirt"}, {"x": 7, "y": 7, "z": 18, "name": "Soil_Grass", "rotation": 1}, {"x": 7, "y": 8, "z": 18, "name": "Plant_Grass_Winter_Short", "rotation": 1}, {"x": 7, "y": -3, "z": 19, "name": "Soil_Dirt"}, {"x": 7, "y": -2, "z": 19, "name": "Soil_Dirt"}, {"x": 7, "y": -1, "z": 19, "name": "Soil_Dirt"}, {"x": 7, "y": 0, "z": 19, "name": "Soil_Dirt"}, {"x": 7, "y": 1, "z": 19, "name": "Rock_Basalt"}, {"x": 7, "y": 2, "z": 19, "name": "Rock_Basalt"}, {"x": 7, "y": 3, "z": 19, "name": "Rock_Basalt"}, {"x": 7, "y": 4, "z": 19, "name": "Rock_Basalt"}, {"x": 7, "y": 5, "z": 19, "name": "Soil_Dirt"}, {"x": 7, "y": 6, "z": 19, "name": "Soil_Grass", "rotation": 1}, {"x": 7, "y": 7, "z": 19, "name": "Plant_Grass_Winter_Short", "rotation": 1}, {"x": 7, "y": -3, "z": 20, "name": "Soil_Dirt"}, {"x": 7, "y": -2, "z": 20, "name": "Soil_Dirt"}, {"x": 7, "y": -1, "z": 20, "name": "Soil_Dirt"}, {"x": 7, "y": 0, "z": 20, "name": "Soil_Grass"}, {"x": 7, "y": 6, "z": 20, "name": "Soil_Grass", "rotation": 1}, {"x": 7, "y": -3, "z": 21, "name": "Soil_Dirt"}, {"x": 7, "y": -2, "z": 21, "name": "Soil_Dirt"}, {"x": 7, "y": -1, "z": 21, "name": "Soil_Dirt"}, {"x": 7, "y": 0, "z": 21, "name": "Soil_Grass"}, {"x": 7, "y": -3, "z": 22, "name": "Soil_Dirt"}, {"x": 7, "y": -2, "z": 22, "name": "Soil_Dirt"}, {"x": 7, "y": -1, "z": 22, "name": "Soil_Dirt"}, {"x": 7, "y": 0, "z": 22, "name": "Soil_Grass"}, {"x": 7, "y": -3, "z": 23, "name": "Soil_Dirt"}, {"x": 7, "y": -2, "z": 23, "name": "Soil_Dirt"}, {"x": 7, "y": -1, "z": 23, "name": "Soil_Dirt"}, {"x": 7, "y": 0, "z": 23, "name": "Soil_Grass"}, {"x": 7, "y": 7, "z": 23, "name": "Plant_Leaves_Beech"}, {"x": 7, "y": -3, "z": 24, "name": "Soil_Dirt"}, {"x": 7, "y": -2, "z": 24, "name": "Soil_Dirt"}, {"x": 7, "y": -1, "z": 24, "name": "Soil_Dirt"}, {"x": 7, "y": 0, "z": 24, "name": "Soil_Grass"}, {"x": 7, "y": 6, "z": 24, "name": "Plant_Leaves_Beech"}, {"x": 7, "y": 8, "z": 24, "name": "Plant_Leaves_Beech"}, {"x": 7, "y": 9, "z": 24, "name": "Plant_Leaves_Beech"}, {"x": 7, "y": 11, "z": 24, "name": "Plant_Leaves_Beech"}, {"x": 7, "y": -3, "z": 25, "name": "Soil_Dirt"}, {"x": 7, "y": -2, "z": 25, "name": "Soil_Dirt"}, {"x": 7, "y": -1, "z": 25, "name": "Soil_Dirt"}, {"x": 7, "y": 0, "z": 25, "name": "Soil_Grass"}, {"x": 7, "y": 6, "z": 25, "name": "Plant_Leaves_Beech"}, {"x": 7, "y": 7, "z": 25, "name": "Plant_Leaves_Beech"}, {"x": 7, "y": 8, "z": 25, "name": "Plant_Leaves_Beech"}, {"x": 7, "y": 9, "z": 25, "name": "Plant_Leaves_Beech"}, {"x": 7, "y": 10, "z": 25, "name": "Plant_Leaves_Beech"}, {"x": 7, "y": 11, "z": 25, "name": "Plant_Leaves_Beech"}, {"x": 7, "y": 14, "z": 25, "name": "Plant_Leaves_Beech"}, {"x": 7, "y": 15, "z": 25, "name": "Plant_Leaves_Beech"}, {"x": 7, "y": -3, "z": 26, "name": "Soil_Dirt"}, {"x": 7, "y": -2, "z": 26, "name": "Soil_Dirt"}, {"x": 7, "y": -1, "z": 26, "name": "Soil_Dirt"}, {"x": 7, "y": 0, "z": 26, "name": "Soil_Grass"}, {"x": 7, "y": 6, "z": 26, "name": "Plant_Leaves_Beech"}, {"x": 7, "y": 7, "z": 26, "name": "Plant_Leaves_Beech"}, {"x": 7, "y": 8, "z": 26, "name": "Plant_Leaves_Beech"}, {"x": 7, "y": 9, "z": 26, "name": "Plant_Leaves_Beech"}, {"x": 7, "y": 10, "z": 26, "name": "Plant_Leaves_Beech"}, {"x": 7, "y": 11, "z": 26, "name": "Plant_Leaves_Beech"}, {"x": 7, "y": 14, "z": 26, "name": "Plant_Leaves_Beech"}, {"x": 7, "y": 15, "z": 26, "name": "Plant_Leaves_Beech"}, {"x": 7, "y": -3, "z": 27, "name": "Soil_Dirt"}, {"x": 7, "y": -2, "z": 27, "name": "Soil_Dirt"}, {"x": 7, "y": -1, "z": 27, "name": "Soil_Dirt"}, {"x": 7, "y": 0, "z": 27, "name": "Soil_Grass"}, {"x": 7, "y": 11, "z": 27, "name": "Plant_Leaves_Beech"}, {"x": 7, "y": 12, "z": 27, "name": "Plant_Leaves_Beech"}, {"x": 7, "y": -3, "z": 28, "name": "Soil_Dirt"}, {"x": 7, "y": -2, "z": 28, "name": "Soil_Dirt"}, {"x": 7, "y": -1, "z": 28, "name": "Soil_Dirt"}, {"x": 7, "y": 0, "z": 28, "name": "Soil_Grass"}, {"x": 7, "y": 9, "z": 28, "name": "Wood_Beech_Branch_Long", "rotation": 5}, {"x": 7, "y": 12, "z": 28, "name": "Plant_Leaves_Beech"}, {"x": 7, "y": 13, "z": 28, "name": "Plant_Leaves_Beech"}, {"x": 7, "y": -3, "z": 29, "name": "Soil_Dirt"}, {"x": 7, "y": -2, "z": 29, "name": "Soil_Dirt"}, {"x": 7, "y": -1, "z": 29, "name": "Soil_Dirt"}, {"x": 7, "y": 0, "z": 29, "name": "Soil_Grass"}, {"x": 7, "y": 12, "z": 29, "name": "Plant_Leaves_Beech"}, {"x": 7, "y": -3, "z": 30, "name": "Soil_Dirt"}, {"x": 7, "y": -2, "z": 30, "name": "Soil_Dirt"}, {"x": 7, "y": -1, "z": 30, "name": "Soil_Dirt"}, {"x": 7, "y": 0, "z": 30, "name": "Soil_Grass"}, {"x": 7, "y": 6, "z": 30, "name": "Wood_Beech_Branch_Long", "rotation": 5}, {"x": 7, "y": 8, "z": 30, "name": "Wood_Beech_Trunk_Full"}, {"x": 7, "y": 14, "z": 30, "name": "Wood_Beech_Branch_Long", "rotation": 5}, {"x": 7, "y": -3, "z": 31, "name": "Soil_Dirt"}, {"x": 7, "y": -2, "z": 31, "name": "Soil_Dirt"}, {"x": 7, "y": -1, "z": 31, "name": "Soil_Dirt"}, {"x": 7, "y": 0, "z": 31, "name": "Soil_Grass"}, {"x": 8, "y": -3, "z": 0, "name": "Soil_Dirt"}, {"x": 8, "y": -2, "z": 0, "name": "Soil_Dirt"}, {"x": 8, "y": -1, "z": 0, "name": "Soil_Dirt"}, {"x": 8, "y": 0, "z": 0, "name": "Soil_Grass"}, {"x": 8, "y": 6, "z": 0, "name": "Plant_Crop_Mushroom_Block_Yellow", "rotation": 1}, {"x": 8, "y": -3, "z": 1, "name": "Soil_Dirt"}, {"x": 8, "y": -2, "z": 1, "name": "Soil_Dirt"}, {"x": 8, "y": -1, "z": 1, "name": "Soil_Dirt"}, {"x": 8, "y": 0, "z": 1, "name": "Soil_Grass"}, {"x": 8, "y": 2, "z": 1, "name": "Wood_Redwood_Branch_Corner", "rotation": 2}, {"x": 8, "y": 3, "z": 1, "name": "Wood_Redwood_Branch_Corner", "support": 1, "rotation": 33}, {"x": 8, "y": 6, "z": 1, "name": "Plant_Crop_Mushroom_Block_Yellow", "rotation": 1}, {"x": 8, "y": -3, "z": 2, "name": "Soil_Dirt"}, {"x": 8, "y": -2, "z": 2, "name": "Soil_Dirt"}, {"x": 8, "y": -1, "z": 2, "name": "Soil_Dirt"}, {"x": 8, "y": 0, "z": 2, "name": "Soil_Dirt"}, {"x": 8, "y": 1, "z": 2, "name": "Wood_Redwood_Trunk_Full", "rotation": 1}, {"x": 8, "y": 2, "z": 2, "name": "Wood_Redwood_Trunk", "support": 15, "rotation": 1}, {"x": 8, "y": 3, "z": 2, "name": "Wood_Redwood_Trunk", "support": 15, "rotation": 1}, {"x": 8, "y": 4, "z": 2, "name": "Wood_Redwood_Trunk_Full", "rotation": 1}, {"x": 8, "y": 6, "z": 2, "name": "Plant_Crop_Mushroom_Block_Yellow", "rotation": 1}, {"x": 8, "y": -3, "z": 3, "name": "Soil_Dirt"}, {"x": 8, "y": -2, "z": 3, "name": "Soil_Dirt"}, {"x": 8, "y": -1, "z": 3, "name": "Soil_Dirt"}, {"x": 8, "y": 0, "z": 3, "name": "Wood_Redwood_Trunk_Full", "rotation": 1}, {"x": 8, "y": 1, "z": 3, "name": "Wood_Redwood_Trunk", "support": 15, "rotation": 1}, {"x": 8, "y": 2, "z": 3, "name": "Wood_Redwood_Trunk", "support": 15, "rotation": 1}, {"x": 8, "y": 3, "z": 3, "name": "Wood_Redwood_Trunk", "support": 15, "rotation": 1}, {"x": 8, "y": 4, "z": 3, "name": "Wood_Redwood_Trunk", "support": 15, "rotation": 1}, {"x": 8, "y": 5, "z": 3, "name": "Wood_Redwood_Trunk", "support": 15, "rotation": 1}, {"x": 8, "y": 6, "z": 3, "name": "Wood_Redwood_Trunk_Full", "rotation": 1}, {"x": 8, "y": -3, "z": 4, "name": "Soil_Dirt"}, {"x": 8, "y": -2, "z": 4, "name": "Rock_Basalt"}, {"x": 8, "y": -1, "z": 4, "name": "Rock_Basalt"}, {"x": 8, "y": 0, "z": 4, "name": "Rock_Basalt"}, {"x": 8, "y": 1, "z": 4, "name": "Wood_Redwood_Trunk", "support": 15, "rotation": 1}, {"x": 8, "y": 2, "z": 4, "name": "Wood_Redwood_Trunk", "support": 15, "rotation": 1}, {"x": 8, "y": 3, "z": 4, "name": "Wood_Redwood_Trunk", "support": 15, "rotation": 1}, {"x": 8, "y": 4, "z": 4, "name": "Wood_Redwood_Trunk", "support": 15, "rotation": 1}, {"x": 8, "y": 5, "z": 4, "name": "Wood_Redwood_Trunk", "support": 15, "rotation": 1}, {"x": 8, "y": 6, "z": 4, "name": "Wood_Redwood_Trunk", "support": 15, "rotation": 1}, {"x": 8, "y": 7, "z": 4, "name": "Soil_Grass", "rotation": 1}, {"x": 8, "y": -3, "z": 5, "name": "Rock_Basalt"}, {"x": 8, "y": -2, "z": 5, "name": "Rock_Basalt"}, {"x": 8, "y": -1, "z": 5, "name": "Rock_Basalt"}, {"x": 8, "y": 0, "z": 5, "name": "Rock_Basalt"}, {"x": 8, "y": 5, "z": 5, "name": "Rock_Basalt"},