{"version": 8, "blockIdVersion": 11, "anchorX": 0, "anchorY": 0, "anchorZ": 0, "blocks": [{"x": 0, "y": -3, "z": 0, "name": "Soil_Dirt"}, {"x": 0, "y": -2, "z": 0, "name": "Soil_Dirt"}, {"x": 0, "y": -1, "z": 0, "name": "Soil_Dirt"}, {"x": 0, "y": 0, "z": 0, "name": "Soil_Grass"}, {"x": 0, "y": -3, "z": 1, "name": "Soil_Dirt"}, {"x": 0, "y": -2, "z": 1, "name": "Soil_Dirt"}, {"x": 0, "y": -1, "z": 1, "name": "Soil_Dirt"}, {"x": 0, "y": 0, "z": 1, "name": "Soil_Grass"}, {"x": 0, "y": -3, "z": 2, "name": "Soil_Dirt"}, {"x": 0, "y": -2, "z": 2, "name": "Soil_Dirt"}, {"x": 0, "y": -1, "z": 2, "name": "Soil_Dirt"}, {"x": 0, "y": 0, "z": 2, "name": "Soil_Grass"}, {"x": 0, "y": -3, "z": 3, "name": "Soil_Dirt"}, {"x": 0, "y": -2, "z": 3, "name": "Soil_Dirt"}, {"x": 0, "y": -1, "z": 3, "name": "Soil_Dirt", "support": 15}, {"x": 0, "y": 0, "z": 3, "name": "Soil_Grass"}, {"x": 0, "y": -3, "z": 4, "name": "Soil_Dirt"}, {"x": 0, "y": -2, "z": 4, "name": "Soil_Dirt"}, {"x": 0, "y": -1, "z": 4, "name": "Soil_Dirt", "support": 15}, {"x": 0, "y": 0, "z": 4, "name": "Soil_Grass", "support": 15}, {"x": 0, "y": -3, "z": 5, "name": "Soil_Dirt"}, {"x": 0, "y": -2, "z": 5, "name": "Soil_Dirt"}, {"x": 0, "y": -1, "z": 5, "name": "Wood_Ash_Trunk_Full"}, {"x": 0, "y": 0, "z": 5, "name": "Wood_Ash_Trunk", "support": 15}, {"x": 0, "y": 1, "z": 5, "name": "Wood_Ash_Trunk_Full"}, {"x": 0, "y": -3, "z": 6, "name": "Soil_Dirt"}, {"x": 0, "y": -2, "z": 6, "name": "Soil_Dirt"}, {"x": 0, "y": -1, "z": 6, "name": "Wood_Ash_Trunk_Full"}, {"x": 0, "y": 0, "z": 6, "name": "Wood_Ash_Trunk_Full"}, {"x": 0, "y": -3, "z": 7, "name": "Soil_Dirt"}, {"x": 0, "y": -2, "z": 7, "name": "Soil_Dirt"}, {"x": 0, "y": -1, "z": 7, "name": "Soil_Dirt"}, {"x": 0, "y": 0, "z": 7, "name": "Soil_Grass"}, {"x": 0, "y": -3, "z": 8, "name": "Soil_Dirt"}, {"x": 0, "y": -2, "z": 8, "name": "Soil_Dirt"}, {"x": 0, "y": -1, "z": 8, "name": "Soil_Dirt"}, {"x": 0, "y": 0, "z": 8, "name": "Soil_Grass"}, {"x": 0, "y": -3, "z": 9, "name": "Soil_Dirt"}, {"x": 0, "y": -2, "z": 9, "name": "Soil_Dirt"}, {"x": 0, "y": -1, "z": 9, "name": "Soil_Dirt"}, {"x": 0, "y": 0, "z": 9, "name": "Soil_Grass"}, {"x": 0, "y": -3, "z": 10, "name": "Soil_Dirt"}, {"x": 0, "y": -2, "z": 10, "name": "Soil_Dirt"}, {"x": 0, "y": -1, "z": 10, "name": "Soil_Dirt", "support": 15}, {"x": 0, "y": 0, "z": 10, "name": "Soil_Grass", "support": 15}, {"x": 0, "y": -3, "z": 11, "name": "Soil_Dirt"}, {"x": 0, "y": -2, "z": 11, "name": "Soil_Dirt", "support": 15}, {"x": 0, "y": -1, "z": 11, "name": "Soil_Dirt"}, {"x": 0, "y": 0, "z": 11, "name": "Soil_Grass"}, {"x": 0, "y": -3, "z": 12, "name": "Soil_Dirt"}, {"x": 0, "y": -2, "z": 12, "name": "Soil_Dirt"}, {"x": 0, "y": -1, "z": 12, "name": "Soil_Dirt"}, {"x": 0, "y": 0, "z": 12, "name": "Soil_Grass"}, {"x": 0, "y": -3, "z": 13, "name": "Soil_Dirt"}, {"x": 0, "y": -2, "z": 13, "name": "Soil_Dirt"}, {"x": 0, "y": -1, "z": 13, "name": "Soil_Dirt"}, {"x": 0, "y": 0, "z": 13, "name": "Soil_Grass"}, {"x": 0, "y": -3, "z": 14, "name": "Soil_Dirt"}, {"x": 0, "y": -2, "z": 14, "name": "Soil_Dirt"}, {"x": 0, "y": -1, "z": 14, "name": "Soil_Dirt"}, {"x": 0, "y": 0, "z": 14, "name": "Soil_Grass"}, {"x": 0, "y": -3, "z": 15, "name": "Soil_Dirt"}, {"x": 0, "y": -2, "z": 15, "name": "Soil_Dirt"}, {"x": 0, "y": -1, "z": 15, "name": "Soil_Dirt"}, {"x": 0, "y": 0, "z": 15, "name": "Soil_Grass"}, {"x": 0, "y": -3, "z": 16, "name": "Soil_Dirt"}, {"x": 0, "y": -2, "z": 16, "name": "Soil_Dirt"}, {"x": 0, "y": -1, "z": 16, "name": "Soil_Dirt"}, {"x": 0, "y": 0, "z": 16, "name": "Soil_Grass"}, {"x": 0, "y": -3, "z": 17, "name": "Soil_Dirt"}, {"x": 0, "y": -2, "z": 17, "name": "Soil_Dirt"}, {"x": 0, "y": -1, "z": 17, "name": "Soil_Dirt"}, {"x": 0, "y": 0, "z": 17, "name": "Soil_Grass"}, {"x": 0, "y": -3, "z": 18, "name": "Soil_Dirt"}, {"x": 0, "y": -2, "z": 18, "name": "Soil_Dirt"}, {"x": 0, "y": -1, "z": 18, "name": "Soil_Dirt"}, {"x": 0, "y": 0, "z": 18, "name": "Soil_Grass"}, {"x": 0, "y": -3, "z": 19, "name": "Soil_Dirt"}, {"x": 0, "y": -2, "z": 19, "name": "Soil_Dirt"}, {"x": 0, "y": -1, "z": 19, "name": "Soil_Dirt"}, {"x": 0, "y": 0, "z": 19, "name": "Soil_Grass"}, {"x": 0, "y": -3, "z": 20, "name": "Soil_Dirt"}, {"x": 0, "y": -2, "z": 20, "name": "Soil_Dirt"}, {"x": 0, "y": -1, "z": 20, "name": "Soil_Dirt"}, {"x": 0, "y": 0, "z": 20, "name": "Soil_Grass"}, {"x": 0, "y": -3, "z": 21, "name": "Soil_Dirt"}, {"x": 0, "y": -2, "z": 21, "name": "Soil_Dirt"}, {"x": 0, "y": -1, "z": 21, "name": "Soil_Dirt"}, {"x": 0, "y": 0, "z": 21, "name": "Soil_Grass"}, {"x": 0, "y": -3, "z": 22, "name": "Soil_Dirt"}, {"x": 0, "y": -2, "z": 22, "name": "Soil_Dirt"}, {"x": 0, "y": -1, "z": 22, "name": "Soil_Dirt"}, {"x": 0, "y": 0, "z": 22, "name": "Soil_Grass"}, {"x": 0, "y": -3, "z": 23, "name": "Soil_Dirt", "support": 15}, {"x": 0, "y": -2, "z": 23, "name": "Soil_Dirt"}, {"x": 0, "y": -1, "z": 23, "name": "Soil_Dirt"}, {"x": 0, "y": 0, "z": 23, "name": "Soil_Grass"}, {"x": 0, "y": -3, "z": 24, "name": "Soil_Dirt"}, {"x": 0, "y": -2, "z": 24, "name": "Soil_Dirt", "support": 15}, {"x": 0, "y": -1, "z": 24, "name": "Soil_Dirt", "support": 15}, {"x": 0, "y": 0, "z": 24, "name": "Soil_Grass"}, {"x": 0, "y": -3, "z": 25, "name": "Soil_Dirt"}, {"x": 0, "y": -2, "z": 25, "name": "Soil_Dirt"}, {"x": 0, "y": -1, "z": 25, "name": "Soil_Dirt", "support": 15}, {"x": 0, "y": 0, "z": 25, "name": "Soil_Grass"}, {"x": 0, "y": -3, "z": 26, "name": "Soil_Dirt"}, {"x": 0, "y": -2, "z": 26, "name": "Soil_Dirt"}, {"x": 0, "y": -1, "z": 26, "name": "Soil_Dirt", "support": 15}, {"x": 0, "y": 0, "z": 26, "name": "Soil_Grass", "support": 15}, {"x": 0, "y": -3, "z": 27, "name": "Soil_Dirt"}, {"x": 0, "y": -2, "z": 27, "name": "Soil_Dirt"}, {"x": 0, "y": -1, "z": 27, "name": "Soil_Dirt"}, {"x": 0, "y": 0, "z": 27, "name": "Soil_Grass", "support": 15}, {"x": 0, "y": -3, "z": 28, "name": "Soil_Dirt"}, {"x": 0, "y": -2, "z": 28, "name": "Soil_Dirt"}, {"x": 0, "y": -1, "z": 28, "name": "Soil_Dirt"}, {"x": 0, "y": 0, "z": 28, "name": "Soil_Grass"}, {"x": 0, "y": -3, "z": 29, "name": "Soil_Dirt"}, {"x": 0, "y": -2, "z": 29, "name": "Soil_Dirt"}, {"x": 0, "y": -1, "z": 29, "name": "Soil_Dirt"}, {"x": 0, "y": 0, "z": 29, "name": "Soil_Grass"}, {"x": 0, "y": -3, "z": 30, "name": "Soil_Dirt"}, {"x": 0, "y": -2, "z": 30, "name": "Soil_Dirt"}, {"x": 0, "y": -1, "z": 30, "name": "Soil_Dirt"}, {"x": 0, "y": 0, "z": 30, "name": "Soil_Grass"}, {"x": 0, "y": -3, "z": 31, "name": "Soil_Dirt"}, {"x": 0, "y": -2, "z": 31, "name": "Soil_Dirt"}, {"x": 0, "y": -1, "z": 31, "name": "Soil_Dirt"}, {"x": 0, "y": 0, "z": 31, "name": "Soil_Grass"}, {"x": 1, "y": -3, "z": 0, "name": "Soil_Dirt"}, {"x": 1, "y": -2, "z": 0, "name": "Soil_Dirt"}, {"x": 1, "y": -1, "z": 0, "name": "Soil_Dirt"}, {"x": 1, "y": 0, "z": 0, "name": "Soil_Grass"}, {"x": 1, "y": -3, "z": 1, "name": "Soil_Dirt"}, {"x": 1, "y": -2, "z": 1, "name": "Soil_Dirt"}, {"x": 1, "y": -1, "z": 1, "name": "Soil_Dirt"}, {"x": 1, "y": 0, "z": 1, "name": "Soil_Grass"}, {"x": 1, "y": -3, "z": 2, "name": "Soil_Dirt"}, {"x": 1, "y": -2, "z": 2, "name": "Soil_Dirt"}, {"x": 1, "y": -1, "z": 2, "name": "Soil_Dirt"}, {"x": 1, "y": 0, "z": 2, "name": "Soil_Grass"}, {"x": 1, "y": -3, "z": 3, "name": "Soil_Dirt"}, {"x": 1, "y": -2, "z": 3, "name": "Soil_Dirt"}, {"x": 1, "y": -1, "z": 3, "name": "Soil_Dirt"}, {"x": 1, "y": 0, "z": 3, "name": "Soil_Grass"}, {"x": 1, "y": -3, "z": 4, "name": "Soil_Dirt"}, {"x": 1, "y": -2, "z": 4, "name": "Wood_Ash_Trunk_Full"}, {"x": 1, "y": -1, "z": 4, "name": "Wood_Ash_Trunk", "support": 15}, {"x": 1, "y": 0, "z": 4, "name": "Wood_Ash_Trunk_Full"}, {"x": 1, "y": -3, "z": 5, "name": "Soil_Dirt"}, {"x": 1, "y": -2, "z": 5, "name": "Soil_Dirt"}, {"x": 1, "y": -1, "z": 5, "name": "Wood_Ash_Trunk_Full", "rotation": 5}, {"x": 1, "y": 0, "z": 5, "name": "Wood_Ash_Trunk", "support": 15}, {"x": 1, "y": 1, "z": 5, "name": "Wood_Ash_Trunk", "support": 15}, {"x": 1, "y": 2, "z": 5, "name": "Wood_Ash_Trunk_Full"}, {"x": 1, "y": -3, "z": 6, "name": "Soil_Dirt"}, {"x": 1, "y": -2, "z": 6, "name": "Soil_Dirt"}, {"x": 1, "y": -1, "z": 6, "name": "Soil_Dirt"}, {"x": 1, "y": 0, "z": 6, "name": "Wood_Ash_Trunk_Full"}, {"x": 1, "y": -3, "z": 7, "name": "Soil_Dirt"}, {"x": 1, "y": -2, "z": 7, "name": "Soil_Dirt"}, {"x": 1, "y": -1, "z": 7, "name": "Soil_Dirt"}, {"x": 1, "y": 0, "z": 7, "name": "Soil_Grass", "support": 15}, {"x": 1, "y": -3, "z": 8, "name": "Soil_Dirt"}, {"x": 1, "y": -2, "z": 8, "name": "Soil_Dirt"}, {"x": 1, "y": -1, "z": 8, "name": "Soil_Dirt"}, {"x": 1, "y": 0, "z": 8, "name": "Soil_Grass"}, {"x": 1, "y": -3, "z": 9, "name": "Soil_Dirt"}, {"x": 1, "y": -2, "z": 9, "name": "Soil_Dirt"}, {"x": 1, "y": -1, "z": 9, "name": "Soil_Dirt"}, {"x": 1, "y": 0, "z": 9, "name": "Soil_Grass"}, {"x": 1, "y": -3, "z": 10, "name": "Soil_Dirt"}, {"x": 1, "y": -2, "z": 10, "name": "Soil_Dirt"}, {"x": 1, "y": -1, "z": 10, "name": "Soil_Dirt"}, {"x": 1, "y": 0, "z": 10, "name": "Soil_Grass", "support": 15}, {"x": 1, "y": -3, "z": 11, "name": "Soil_Dirt"}, {"x": 1, "y": -2, "z": 11, "name": "Soil_Dirt"}, {"x": 1, "y": -1, "z": 11, "name": "Soil_Dirt"}, {"x": 1, "y": 0, "z": 11, "name": "Soil_Grass", "support": 15}, {"x": 1, "y": -3, "z": 12, "name": "Soil_Dirt"}, {"x": 1, "y": -2, "z": 12, "name": "Soil_Dirt"}, {"x": 1, "y": -1, "z": 12, "name": "Soil_Dirt"}, {"x": 1, "y": 0, "z": 12, "name": "Soil_Grass"}, {"x": 1, "y": -3, "z": 13, "name": "Soil_Dirt"}, {"x": 1, "y": -2, "z": 13, "name": "Soil_Dirt"}, {"x": 1, "y": -1, "z": 13, "name": "Soil_Dirt"}, {"x": 1, "y": 0, "z": 13, "name": "Soil_Grass"}, {"x": 1, "y": -3, "z": 14, "name": "Soil_Dirt"}, {"x": 1, "y": -2, "z": 14, "name": "Soil_Dirt"}, {"x": 1, "y": -1, "z": 14, "name": "Soil_Dirt"}, {"x": 1, "y": 0, "z": 14, "name": "Soil_Grass"}, {"x": 1, "y": -3, "z": 15, "name": "Soil_Dirt"}, {"x": 1, "y": -2, "z": 15, "name": "Soil_Dirt"}, {"x": 1, "y": -1, "z": 15, "name": "Soil_Dirt"}, {"x": 1, "y": 0, "z": 15, "name": "Soil_Grass"}, {"x": 1, "y": -3, "z": 16, "name": "Soil_Dirt"}, {"x": 1, "y": -2, "z": 16, "name": "Soil_Dirt"}, {"x": 1, "y": -1, "z": 16, "name": "Soil_Dirt"}, {"x": 1, "y": 0, "z": 16, "name": "Soil_Grass"}, {"x": 1, "y": -3, "z": 17, "name": "Soil_Dirt"}, {"x": 1, "y": -2, "z": 17, "name": "Soil_Dirt"}, {"x": 1, "y": -1, "z": 17, "name": "Soil_Dirt"}, {"x": 1, "y": 0, "z": 17, "name": "Soil_Grass"}, {"x": 1, "y": -3, "z": 18, "name": "Soil_Dirt"}, {"x": 1, "y": -2, "z": 18, "name": "Soil_Dirt"}, {"x": 1, "y": -1, "z": 18, "name": "Soil_Dirt"}, {"x": 1, "y": 0, "z": 18, "name": "Soil_Grass"}, {"x": 1, "y": -3, "z": 19, "name": "Soil_Dirt"}, {"x": 1, "y": -2, "z": 19, "name": "Soil_Dirt"}, {"x": 1, "y": -1, "z": 19, "name": "Soil_Dirt"}, {"x": 1, "y": 0, "z": 19, "name": "Soil_Grass"}, {"x": 1, "y": -3, "z": 20, "name": "Soil_Dirt"}, {"x": 1, "y": -2, "z": 20, "name": "Soil_Dirt"}, {"x": 1, "y": -1, "z": 20, "name": "Soil_Dirt"}, {"x": 1, "y": 0, "z": 20, "name": "Soil_Grass"}, {"x": 1, "y": -3, "z": 21, "name": "Soil_Dirt"}, {"x": 1, "y": -2, "z": 21, "name": "Soil_Dirt"}, {"x": 1, "y": -1, "z": 21, "name": "Soil_Dirt"}, {"x": 1, "y": 0, "z": 21, "name": "Soil_Grass"}, {"x": 1, "y": -3, "z": 22, "name": "Soil_Dirt"}, {"x": 1, "y": -2, "z": 22, "name": "Soil_Dirt"}, {"x": 1, "y": -1, "z": 22, "name": "Soil_Dirt"}, {"x": 1, "y": 0, "z": 22, "name": "Soil_Grass"}, {"x": 1, "y": -3, "z": 23, "name": "Soil_Dirt"}, {"x": 1, "y": -2, "z": 23, "name": "Soil_Dirt", "support": 15}, {"x": 1, "y": -1, "z": 23, "name": "Soil_Dirt"}, {"x": 1, "y": 0, "z": 23, "name": "Soil_Grass"}, {"x": 1, "y": -3, "z": 24, "name": "Soil_Dirt"}, {"x": 1, "y": -2, "z": 24, "name": "Soil_Dirt", "support": 15}, {"x": 1, "y": -1, "z": 24, "name": "Soil_Dirt", "support": 15}, {"x": 1, "y": 0, "z": 24, "name": "Soil_Grass"}, {"x": 1, "y": -3, "z": 25, "name": "Soil_Dirt"}, {"x": 1, "y": -2, "z": 25, "name": "Soil_Dirt"}, {"x": 1, "y": -1, "z": 25, "name": "Soil_Dirt", "support": 15}, {"x": 1, "y": 0, "z": 25, "name": "Soil_Grass", "support": 15}, {"x": 1, "y": -3, "z": 26, "name": "Soil_Dirt"}, {"x": 1, "y": -2, "z": 26, "name": "Soil_Dirt"}, {"x": 1, "y": -1, "z": 26, "name": "Soil_Dirt"}, {"x": 1, "y": 0, "z": 26, "name": "Soil_Grass", "support": 15}, {"x": 1, "y": -3, "z": 27, "name": "Soil_Dirt"}, {"x": 1, "y": -2, "z": 27, "name": "Soil_Dirt"}, {"x": 1, "y": -1, "z": 27, "name": "Soil_Dirt"}, {"x": 1, "y": 0, "z": 27, "name": "Soil_Grass"}, {"x": 1, "y": -3, "z": 28, "name": "Soil_Dirt"}, {"x": 1, "y": -2, "z": 28, "name": "Soil_Dirt"}, {"x": 1, "y": -1, "z": 28, "name": "Soil_Dirt"}, {"x": 1, "y": 0, "z": 28, "name": "Soil_Grass"}, {"x": 1, "y": -3, "z": 29, "name": "Soil_Dirt"}, {"x": 1, "y": -2, "z": 29, "name": "Soil_Dirt"}, {"x": 1, "y": -1, "z": 29, "name": "Soil_Dirt"}, {"x": 1, "y": 0, "z": 29, "name": "Soil_Grass"}, {"x": 1, "y": -3, "z": 30, "name": "Soil_Dirt"}, {"x": 1, "y": -2, "z": 30, "name": "Soil_Dirt"}, {"x": 1, "y": -1, "z": 30, "name": "Soil_Dirt"}, {"x": 1, "y": 0, "z": 30, "name": "Soil_Grass"}, {"x": 1, "y": -3, "z": 31, "name": "Soil_Dirt"}, {"x": 1, "y": -2, "z": 31, "name": "Soil_Dirt"}, {"x": 1, "y": -1, "z": 31, "name": "Soil_Dirt"}, {"x": 1, "y": 0, "z": 31, "name": "Soil_Grass"}, {"x": 2, "y": -3, "z": 0, "name": "Soil_Dirt"}, {"x": 2, "y": -2, "z": 0, "name": "Soil_Dirt"}, {"x": 2, "y": -1, "z": 0, "name": "Soil_Dirt"}, {"x": 2, "y": 0, "z": 0, "name": "Soil_Grass"}, {"x": 2, "y": -3, "z": 1, "name": "Soil_Dirt"}, {"x": 2, "y": -2, "z": 1, "name": "Soil_Dirt"}, {"x": 2, "y": -1, "z": 1, "name": "Soil_Dirt"}, {"x": 2, "y": 0, "z": 1, "name": "Soil_Grass"}, {"x": 2, "y": -3, "z": 2, "name": "Wood_Ash_Trunk_Full"}, {"x": 2, "y": -2, "z": 2, "name": "Soil_Dirt"}, {"x": 2, "y": -1, "z": 2, "name": "Soil_Dirt"}, {"x": 2, "y": 0, "z": 2, "name": "Soil_Grass"}, {"x": 2, "y": -3, "z": 3, "name": "Wood_Ash_Trunk", "support": 15}, {"x": 2, "y": -2, "z": 3, "name": "Wood_Ash_Trunk", "support": 15}, {"x": 2, "y": -1, "z": 3, "name": "Wood_Ash_Trunk_Full"}, {"x": 2, "y": 0, "z": 3, "name": "Soil_Grass"}, {"x": 2, "y": -3, "z": 4, "name": "Wood_Ash_Trunk", "support": 15}, {"x": 2, "y": -2, "z": 4, "name": "Wood_Ash_Trunk", "support": 15}, {"x": 2, "y": -1, "z": 4, "name": "Wood_Ash_Trunk", "support": 15}, {"x": 2, "y": 0, "z": 4, "name": "Wood_Ash_Trunk", "support": 15}, {"x": 2, "y": 1, "z": 4, "name": "Wood_Ash_Trunk", "support": 15}, {"x": 2, "y": 2, "z": 4, "name": "Wood_Ash_Trunk", "support": 15}, {"x": 2, "y": 3, "z": 4, "name": "Wood_Ash_Trunk", "support": 15}, {"x": 2, "y": 4, "z": 4, "name": "Wood_Ash_Trunk_Full"}, {"x": 2, "y": -3, "z": 5, "name": "Wood_Ash_Trunk", "support": 15}, {"x": 2, "y": -2, "z": 5, "name": "Wood_Ash_Trunk", "support": 15}, {"x": 2, "y": -1, "z": 5, "name": "Wood_Ash_Trunk", "support": 15}, {"x": 2, "y": 0, "z": 5, "name": "Wood_Ash_Trunk", "support": 15}, {"x": 2, "y": 1, "z": 5, "name": "Wood_Ash_Trunk", "support": 15}, {"x": 2, "y": 2, "z": 5, "name": "Wood_Ash_Trunk", "support": 15}, {"x": 2, "y": 3, "z": 5, "name": "Wood_Ash_Trunk_Full"}, {"x": 2, "y": -3, "z": 6, "name": "Soil_Dirt"}, {"x": 2, "y": -2, "z": 6, "name": "Soil_Dirt"}, {"x": 2, "y": -1, "z": 6, "name": "Soil_Dirt"}, {"x": 2, "y": 0, "z": 6, "name": "Soil_Grass", "support": 15}, {"x": 2, "y": -3, "z": 7, "name": "Soil_Dirt"}, {"x": 2, "y": -2, "z": 7, "name": "Soil_Dirt"}, {"x": 2, "y": -1, "z": 7, "name": "Soil_Dirt"}, {"x": 2, "y": 0, "z": 7, "name": "Soil_Grass", "support": 15}, {"x": 2, "y": -3, "z": 8, "name": "Soil_Dirt"}, {"x": 2, "y": -2, "z": 8, "name": "Soil_Dirt"}, {"x": 2, "y": -1, "z": 8, "name": "Soil_Dirt"}, {"x": 2, "y": 0, "z": 8, "name": "Soil_Grass", "support": 15}, {"x": 2, "y": -3, "z": 9, "name": "Soil_Dirt"}, {"x": 2, "y": -2, "z": 9, "name": "Soil_Dirt"}, {"x": 2, "y": -1, "z": 9, "name": "Soil_Dirt"}, {"x": 2, "y": 0, "z": 9, "name": "Soil_Grass", "support": 15}, {"x": 2, "y": -3, "z": 10, "name": "Soil_Dirt"}, {"x": 2, "y": -2, "z": 10, "name": "Soil_Dirt"}, {"x": 2, "y": -1, "z": 10, "name": "Soil_Dirt"}, {"x": 2, "y": 0, "z": 10, "name": "Soil_Grass"}, {"x": 2, "y": -3, "z": 11, "name": "Soil_Dirt"}, {"x": 2, "y": -2, "z": 11, "name": "Soil_Dirt"}, {"x": 2, "y": -1, "z": 11, "name": "Soil_Dirt"}, {"x": 2, "y": 0, "z": 11, "name": "Soil_Grass"}, {"x": 2, "y": -3, "z": 12, "name": "Soil_Dirt"}, {"x": 2, "y": -2, "z": 12, "name": "Soil_Dirt"}, {"x": 2, "y": -1, "z": 12, "name": "Soil_Dirt"}, {"x": 2, "y": 0, "z": 12, "name": "Soil_Grass"}, {"x": 2, "y": -3, "z": 13, "name": "Soil_Dirt"}, {"x": 2, "y": -2, "z": 13, "name": "Soil_Dirt"}, {"x": 2, "y": -1, "z": 13, "name": "Soil_Dirt"}, {"x": 2, "y": 0, "z": 13, "name": "Soil_Grass"}, {"x": 2, "y": -3, "z": 14, "name": "Soil_Dirt"}, {"x": 2, "y": -2, "z": 14, "name": "Soil_Dirt"}, {"x": 2, "y": -1, "z": 14, "name": "Soil_Dirt"}, {"x": 2, "y": 0, "z": 14, "name": "Soil_Grass"}, {"x": 2, "y": -3, "z": 15, "name": "Soil_Dirt"}, {"x": 2, "y": -2, "z": 15, "name": "Soil_Dirt"}, {"x": 2, "y": -1, "z": 15, "name": "Soil_Dirt"}, {"x": 2, "y": 0, "z": 15, "name": "Soil_Grass"}, {"x": 2, "y": -3, "z": 16, "name": "Soil_Dirt"}, {"x": 2, "y": -2, "z": 16, "name": "Soil_Dirt"}, {"x": 2, "y": -1, "z": 16, "name": "Soil_Dirt"}, {"x": 2, "y": 0, "z": 16, "name": "Soil_Grass"}, {"x": 2, "y": -3, "z": 17, "name": "Soil_Dirt"}, {"x": 2, "y": -2, "z": 17, "name": "Soil_Dirt"}, {"x": 2, "y": -1, "z": 17, "name": "Soil_Dirt"}, {"x": 2, "y": 0, "z": 17, "name": "Soil_Grass"}, {"x": 2, "y": -3, "z": 18, "name": "Soil_Dirt"}, {"x": 2, "y": -2, "z": 18, "name": "Soil_Dirt"}, {"x": 2, "y": -1, "z": 18, "name": "Soil_Dirt"}, {"x": 2, "y": 0, "z": 18, "name": "Soil_Grass"}, {"x": 2, "y": -3, "z": 19, "name": "Soil_Dirt"}, {"x": 2, "y": -2, "z": 19, "name": "Soil_Dirt"}, {"x": 2, "y": -1, "z": 19, "name": "Soil_Dirt"}, {"x": 2, "y": 0, "z": 19, "name": "Soil_Grass"}, {"x": 2, "y": -3, "z": 20, "name": "Soil_Dirt"}, {"x": 2, "y": -2, "z": 20, "name": "Soil_Dirt"}, {"x": 2, "y": -1, "z": 20, "name": "Soil_Dirt"}, {"x": 2, "y": 0, "z": 20, "name": "Soil_Grass"}, {"x": 2, "y": -3, "z": 21, "name": "Soil_Dirt"}, {"x": 2, "y": -2, "z": 21, "name": "Soil_Dirt"}, {"x": 2, "y": -1, "z": 21, "name": "Soil_Dirt"}, {"x": 2, "y": 0, "z": 21, "name": "Soil_Grass"}, {"x": 2, "y": -3, "z": 22, "name": "Soil_Dirt"}, {"x": 2, "y": -2, "z": 22, "name": "Soil_Dirt"}, {"x": 2, "y": -1, "z": 22, "name": "Soil_Dirt"}, {"x": 2, "y": 0, "z": 22, "name": "Soil_Grass"}, {"x": 2, "y": -3, "z": 23, "name": "Soil_Dirt"}, {"x": 2, "y": -2, "z": 23, "name": "Soil_Dirt"}, {"x": 2, "y": -1, "z": 23, "name": "Soil_Dirt", "support": 15}, {"x": 2, "y": 0, "z": 23, "name": "Soil_Grass", "support": 15}, {"x": 2, "y": -3, "z": 24, "name": "Soil_Dirt"}, {"x": 2, "y": -2, "z": 24, "name": "Soil_Dirt"}, {"x": 2, "y": -1, "z": 24, "name": "Soil_Dirt", "support": 15}, {"x": 2, "y": 0, "z": 24, "name": "Soil_Grass", "support": 15}, {"x": 2, "y": -3, "z": 25, "name": "Soil_Dirt"}, {"x": 2, "y": -2, "z": 25, "name": "Soil_Dirt"}, {"x": 2, "y": -1, "z": 25, "name": "Soil_Dirt"}, {"x": 2, "y": 0, "z": 25, "name": "Soil_Grass", "support": 15}, {"x": 2, "y": -3, "z": 26, "name": "Soil_Dirt"}, {"x": 2, "y": -2, "z": 26, "name": "Soil_Dirt"}, {"x": 2, "y": -1, "z": 26, "name": "Soil_Dirt"}, {"x": 2, "y": 0, "z": 26, "name": "Soil_Grass"}, {"x": 2, "y": -3, "z": 27, "name": "Soil_Dirt"}, {"x": 2, "y": -2, "z": 27, "name": "Soil_Dirt"}, {"x": 2, "y": -1, "z": 27, "name": "Soil_Dirt"}, {"x": 2, "y": 0, "z": 27, "name": "Soil_Grass"}, {"x": 2, "y": -3, "z": 28, "name": "Soil_Dirt"}, {"x": 2, "y": -2, "z": 28, "name": "Soil_Dirt", "support": 15}, {"x": 2, "y": -1, "z": 28, "name": "Soil_Dirt", "support": 15}, {"x": 2, "y": 0, "z": 28, "name": "Soil_Grass", "support": 15}, {"x": 2, "y": -3, "z": 29, "name": "Soil_Dirt", "support": 15}, {"x": 2, "y": -2, "z": 29, "name": "Soil_Dirt", "support": 15}, {"x": 2, "y": -1, "z": 29, "name": "Soil_Dirt"}, {"x": 2, "y": 0, "z": 29, "name": "Soil_Grass"}, {"x": 2, "y": -3, "z": 30, "name": "Soil_Dirt"}, {"x": 2, "y": -2, "z": 30, "name": "Soil_Dirt"}, {"x": 2, "y": -1, "z": 30, "name": "Soil_Dirt"}, {"x": 2, "y": 0, "z": 30, "name": "Soil_Grass"}, {"x": 2, "y": -3, "z": 31, "name": "Soil_Dirt"}, {"x": 2, "y": -2, "z": 31, "name": "Soil_Dirt"}, {"x": 2, "y": -1, "z": 31, "name": "Soil_Dirt"}, {"x": 2, "y": 0, "z": 31, "name": "Soil_Grass"}, {"x": 3, "y": -3, "z": 0, "name": "Soil_Dirt"}, {"x": 3, "y": -2, "z": 0, "name": "Soil_Dirt"}, {"x": 3, "y": -1, "z": 0, "name": "Soil_Dirt"}, {"x": 3, "y": 0, "z": 0, "name": "Soil_Grass"}, {"x": 3, "y": -3, "z": 1, "name": "Soil_Dirt"}, {"x": 3, "y": -2, "z": 1, "name": "Soil_Dirt"}, {"x": 3, "y": -1, "z": 1, "name": "Soil_Dirt"}, {"x": 3, "y": 0, "z": 1, "name": "Soil_Grass"}, {"x": 3, "y": -3, "z": 2, "name": "Wood_Ash_Trunk", "support": 15}, {"x": 3, "y": -2, "z": 2, "name": "Wood_Ash_Trunk_Full"}, {"x": 3, "y": -1, "z": 2, "name": "Soil_Dirt"}, {"x": 3, "y": 0, "z": 2, "name": "Soil_Grass"}, {"x": 3, "y": -3, "z": 3, "name": "Wood_Ash_Trunk", "support": 15}, {"x": 3, "y": -2, "z": 3, "name": "Wood_Ash_Trunk", "support": 15}, {"x": 3, "y": -1, "z": 3, "name": "Wood_Ash_Trunk", "support": 15}, {"x": 3, "y": 0, "z": 3, "name": "Wood_Ash_Trunk", "support": 15}, {"x": 3, "y": 1, "z": 3, "name": "Wood_Ash_Trunk", "support": 15}, {"x": 3, "y": 2, "z": 3, "name": "Wood_Ash_Trunk", "support": 15}, {"x": 3, "y": 3, "z": 3, "name": "Wood_Ash_Trunk", "support": 15}, {"x": 3, "y": 4, "z": 3, "name": "Wood_Ash_Trunk_Full"}, {"x": 3, "y": -3, "z": 4, "name": "Wood_Ash_Trunk", "support": 15}, {"x": 3, "y": -2, "z": 4, "name": "Wood_Ash_Trunk", "support": 15}, {"x": 3, "y": -1, "z": 4, "name": "Wood_Ash_Trunk", "support": 15}, {"x": 3, "y": 0, "z": 4, "name": "Wood_Ash_Trunk", "support": 15}, {"x": 3, "y": 1, "z": 4, "name": "Wood_Ash_Trunk", "support": 15}, {"x": 3, "y": 2, "z": 4, "name": "Wood_Ash_Trunk", "support": 15}, {"x": 3, "y": 3, "z": 4, "name": "Wood_Ash_Trunk", "support": 15}, {"x": 3, "y": 4, "z": 4, "name": "Wood_Ash_Trunk", "support": 15}, {"x": 3, "y": 5, "z": 4, "name": "Wood_Ash_Trunk_Full"}, {"x": 3, "y": -3, "z": 5, "name": "Soil_Dirt"}, {"x": 3, "y": -2, "z": 5, "name": "Wood_Ash_Trunk_Full"}, {"x": 3, "y": -1, "z": 5, "name": "Wood_Ash_Trunk", "support": 15}, {"x": 3, "y": 0, "z": 5, "name": "Wood_Ash_Trunk", "support": 15}, {"x": 3, "y": 1, "z": 5, "name": "Wood_Ash_Trunk", "support": 15}, {"x": 3, "y": 2, "z": 5, "name": "Wood_Ash_Trunk", "support": 15}, {"x": 3, "y": 3, "z": 5, "name": "Wood_Ash_Trunk", "support": 15}, {"x": 3, "y": 4, "z": 5, "name": "Wood_Ash_Trunk_Full"}, {"x": 3, "y": -3, "z": 6, "name": "Soil_Dirt"}, {"x": 3, "y": -2, "z": 6, "name": "Soil_Dirt"}, {"x": 3, "y": -1, "z": 6, "name": "Soil_Dirt", "support": 15}, {"x": 3, "y": 0, "z": 6, "name": "Soil_Grass", "support": 15}, {"x": 3, "y": -3, "z": 7, "name": "Soil_Dirt"}, {"x": 3, "y": -2, "z": 7, "name": "Soil_Dirt"}, {"x": 3, "y": -1, "z": 7, "name": "Soil_Dirt"}, {"x": 3, "y": 0, "z": 7, "name": "Soil_Grass", "support": 15}, {"x": 3, "y": -3, "z": 8, "name": "Soil_Dirt"}, {"x": 3, "y": -2, "z": 8, "name": "Soil_Dirt"}, {"x": 3, "y": -1, "z": 8, "name": "Soil_Dirt"}, {"x": 3, "y": 0, "z": 8, "name": "Soil_Grass", "support": 15}, {"x": 3, "y": -3, "z": 9, "name": "Soil_Dirt"}, {"x": 3, "y": -2, "z": 9, "name": "Soil_Dirt"}, {"x": 3, "y": -1, "z": 9, "name": "Soil_Dirt"}, {"x": 3, "y": 0, "z": 9, "name": "Soil_Grass", "support": 15}, {"x": 3, "y": -3, "z": 10, "name": "Soil_Dirt"}, {"x": 3, "y": -2, "z": 10, "name": "Soil_Dirt"}, {"x": 3, "y": -1, "z": 10, "name": "Soil_Dirt"}, {"x": 3, "y": 0, "z": 10, "name": "Soil_Grass", "support": 15}, {"x": 3, "y": -3, "z": 11, "name": "Soil_Dirt"}, {"x": 3, "y": -2, "z": 11, "name": "Soil_Dirt"}, {"x": 3, "y": -1, "z": 11, "name": "Soil_Dirt"}, {"x": 3, "y": 0, "z": 11, "name": "Soil_Grass"}, {"x": 3, "y": -3, "z": 12, "name": "Soil_Dirt"}, {"x": 3, "y": -2, "z": 12, "name": "Soil_Dirt"}, {"x": 3, "y": -1, "z": 12, "name": "Soil_Dirt"}, {"x": 3, "y": 0, "z": 12, "name": "Soil_Grass"}, {"x": 3, "y": -3, "z": 13, "name": "Soil_Dirt"}, {"x": 3, "y": -2, "z": 13, "name": "Soil_Dirt"}, {"x": 3, "y": -1, "z": 13, "name": "Soil_Dirt"}, {"x": 3, "y": 0, "z": 13, "name": "Soil_Grass"}, {"x": 3, "y": -3, "z": 14, "name": "Soil_Dirt"}, {"x": 3, "y": -2, "z": 14, "name": "Soil_Dirt"}, {"x": 3, "y": -1, "z": 14, "name": "Soil_Dirt"}, {"x": 3, "y": 0, "z": 14, "name": "Soil_Grass"}, {"x": 3, "y": -3, "z": 15, "name": "Soil_Dirt"}, {"x": 3, "y": -2, "z": 15, "name": "Soil_Dirt"}, {"x": 3, "y": -1, "z": 15, "name": "Soil_Dirt"}, {"x": 3, "y": 0, "z": 15, "name": "Soil_Grass"}, {"x": 3, "y": -3, "z": 16, "name": "Soil_Dirt"}, {"x": 3, "y": -2, "z": 16, "name": "Soil_Dirt"}, {"x": 3, "y": -1, "z": 16, "name": "Soil_Dirt"}, {"x": 3, "y": 0, "z": 16, "name": "Soil_Grass"}, {"x": 3, "y": -3, "z": 17, "name": "Soil_Dirt"}, {"x": 3, "y": -2, "z": 17, "name": "Soil_Dirt"}, {"x": 3, "y": -1, "z": 17, "name": "Soil_Dirt"}, {"x": 3, "y": 0, "z": 17, "name": "Soil_Grass"}, {"x": 3, "y": -3, "z": 18, "name": "Soil_Dirt"}, {"x": 3, "y": -2, "z": 18, "name": "Soil_Dirt"}, {"x": 3, "y": -1, "z": 18, "name": "Soil_Dirt"}, {"x": 3, "y": 0, "z": 18, "name": "Soil_Grass"}, {"x": 3, "y": -3, "z": 19, "name": "Soil_Dirt"}, {"x": 3, "y": -2, "z": 19, "name": "Soil_Dirt"}, {"x": 3, "y": -1, "z": 19, "name": "Soil_Dirt"}, {"x": 3, "y": 0, "z": 19, "name": "Soil_Grass"}, {"x": 3, "y": -3, "z": 20, "name": "Soil_Dirt"}, {"x": 3, "y": -2, "z": 20, "name": "Soil_Dirt"}, {"x": 3, "y": -1, "z": 20, "name": "Soil_Dirt"}, {"x": 3, "y": 0, "z": 20, "name": "Soil_Grass"}, {"x": 3, "y": -3, "z": 21, "name": "Soil_Dirt"}, {"x": 3, "y": -2, "z": 21, "name": "Soil_Dirt"}, {"x": 3, "y": -1, "z": 21, "name": "Soil_Dirt"}, {"x": 3, "y": 0, "z": 21, "name": "Soil_Grass"}, {"x": 3, "y": -3, "z": 22, "name": "Soil_Dirt"}, {"x": 3, "y": -2, "z": 22, "name": "Soil_Dirt"}, {"x": 3, "y": -1, "z": 22, "name": "Soil_Dirt"}, {"x": 3, "y": 0, "z": 22, "name": "Soil_Grass"}, {"x": 3, "y": -3, "z": 23, "name": "Soil_Dirt"}, {"x": 3, "y": -2, "z": 23, "name": "Soil_Dirt"}, {"x": 3, "y": -1, "z": 23, "name": "Soil_Dirt"}, {"x": 3, "y": 0, "z": 23, "name": "Soil_Grass"}, {"x": 3, "y": -3, "z": 24, "name": "Soil_Dirt"}, {"x": 3, "y": -2, "z": 24, "name": "Soil_Dirt"}, {"x": 3, "y": -1, "z": 24, "name": "Soil_Dirt", "support": 15}, {"x": 3, "y": 0, "z": 24, "name": "Soil_Grass"}, {"x": 3, "y": -3, "z": 25, "name": "Soil_Dirt"}, {"x": 3, "y": -2, "z": 25, "name": "Soil_Dirt"}, {"x": 3, "y": -1, "z": 25, "name": "Soil_Dirt", "support": 15}, {"x": 3, "y": 0, "z": 25, "name": "Soil_Grass"}, {"x": 3, "y": -3, "z": 26, "name": "Soil_Dirt"}, {"x": 3, "y": -2, "z": 26, "name": "Soil_Dirt"}, {"x": 3, "y": -1, "z": 26, "name": "Soil_Dirt"}, {"x": 3, "y": 0, "z": 26, "name": "Soil_Grass", "support": 15}, {"x": 3, "y": -3, "z": 27, "name": "Soil_Dirt", "support": 15}, {"x": 3, "y": -2, "z": 27, "name": "Soil_Dirt", "support": 15}, {"x": 3, "y": -1, "z": 27, "name": "Soil_Dirt", "support": 15}, {"x": 3, "y": 0, "z": 27, "name": "Soil_Grass", "support": 15}, {"x": 3, "y": -3, "z": 28, "name": "Soil_Dirt", "support": 15}, {"x": 3, "y": -2, "z": 28, "name": "Soil_Dirt", "support": 15}, {"x": 3, "y": -1, "z": 28, "name": "Soil_Dirt", "support": 15}, {"x": 3, "y": 0, "z": 28, "name": "Soil_Grass", "support": 15}, {"x": 3, "y": -3, "z": 29, "name": "Soil_Dirt", "support": 15}, {"x": 3, "y": -2, "z": 29, "name": "Soil_Dirt", "support": 15}, {"x": 3, "y": -1, "z": 29, "name": "Soil_Dirt", "support": 15}, {"x": 3, "y": 0, "z": 29, "name": "Soil_Grass", "support": 15}, {"x": 3, "y": -3, "z": 30, "name": "Soil_Dirt"}, {"x": 3, "y": -2, "z": 30, "name": "Soil_Dirt"}, {"x": 3, "y": -1, "z": 30, "name": "Soil_Dirt"}, {"x": 3, "y": 0, "z": 30, "name": "Soil_Grass"}, {"x": 3, "y": -3, "z": 31, "name": "Soil_Dirt"}, {"x": 3, "y": -2, "z": 31, "name": "Soil_Dirt"}, {"x": 3, "y": -1, "z": 31, "name": "Soil_Dirt"}, {"x": 3, "y": 0, "z": 31, "name": "Soil_Grass"}, {"x": 4, "y": -3, "z": 0, "name": "Soil_Dirt"}, {"x": 4, "y": -2, "z": 0, "name": "Soil_Dirt"}, {"x": 4, "y": -1, "z": 0, "name": "Soil_Dirt"}, {"x": 4, "y": 0, "z": 0, "name": "Soil_Grass"}, {"x": 4, "y": -3, "z": 1, "name": "Soil_Dirt"}, {"x": 4, "y": -2, "z": 1, "name": "Soil_Dirt"}, {"x": 4, "y": -1, "z": 1, "name": "Soil_Dirt"}, {"x": 4, "y": 0, "z": 1, "name": "Soil_Grass"}, {"x": 4, "y": -3, "z": 2, "name": "Soil_Dirt"}, {"x": 4, "y": -2, "z": 2, "name": "Soil_Dirt"}, {"x": 4, "y": -1, "z": 2, "name": "Soil_Dirt"}, {"x": 4, "y": 0, "z": 2, "name": "Soil_Grass"}, {"x": 4, "y": 5, "z": 2, "name": "Wood_Ash_Trunk_Full"}, {"x": 4, "y": 6, "z": 2, "name": "Wood_Ash_Trunk", "support": 15}, {"x": 4, "y": 7, "z": 2, "name": "Wood_Ash_Trunk_Full"}, {"x": 4, "y": -3, "z": 3, "name": "Soil_Dirt"}, {"x": 4, "y": -2, "z": 3, "name": "Soil_Dirt"}, {"x": 4, "y": -1, "z": 3, "name": "Soil_Dirt"}, {"x": 4, "y": 0, "z": 3, "name": "Wood_Ash_Trunk_Full"}, {"x": 4, "y": 1, "z": 3, "name": "Wood_Ash_Trunk", "support": 15}, {"x": 4, "y": 2, "z": 3, "name": "Wood_Ash_Trunk", "support": 15}, {"x": 4, "y": 3, "z": 3, "name": "Wood_Ash_Trunk", "support": 15}, {"x": 4, "y": 4, "z": 3, "name": "Wood_Ash_Trunk", "support": 15}, {"x": 4, "y": 5, "z": 3, "name": "Wood_Ash_Trunk", "support": 15}, {"x": 4, "y": 6, "z": 3, "name": "Wood_Ash_Trunk", "support": 15}, {"x": 4, "y": 7, "z": 3, "name": "Wood_Ash_Trunk_Full"}, {"x": 4, "y": -3, "z": 4, "name": "Wood_Ash_Trunk", "support": 15}, {"x": 4, "y": -2, "z": 4, "name": "Wood_Ash_Trunk", "support": 15}, {"x": 4, "y": -1, "z": 4, "name": "Wood_Ash_Trunk", "support": 15}, {"x": 4, "y": 0, "z": 4, "name": "Wood_Ash_Trunk", "support": 15}, {"x": 4, "y": 1, "z": 4, "name": "Wood_Ash_Trunk", "support": 15}, {"x": 4, "y": 2, "z": 4, "name": "Wood_Ash_Trunk", "support": 15}, {"x": 4, "y": 3, "z": 4, "name": "Wood_Ash_Trunk", "support": 15}, {"x": 4, "y": 4, "z": 4, "name": "Wood_Ash_Trunk", "support": 15}, {"x": 4, "y": 5, "z": 4, "name": "Wood_Ash_Trunk", "support": 15}, {"x": 4, "y": 6, "z": 4, "name": "Wood_Ash_Trunk_Full"}, {"x": 4, "y": -3, "z": 5, "name": "Soil_Dirt"}, {"x": 4, "y": -2, "z": 5, "name": "Soil_Dirt"}, {"x": 4, "y": -1, "z": 5, "name": "Soil_Dirt", "support": 15}, {"x": 4, "y": 0, "z": 5, "name": "Soil_Dirt", "support": 15}, {"x": 4, "y": 1, "z": 5, "name": "Wood_Ash_Trunk_Full"}, {"x": 4, "y": 2, "z": 5, "name": "Wood_Ash_Trunk", "support": 15}, {"x": 4, "y": 3, "z": 5, "name": "Wood_Ash_Trunk", "support": 15}, {"x": 4, "y": 4, "z": 5, "name": "Wood_Ash_Trunk", "support": 15}, {"x": 4, "y": 5, "z": 5, "name": "Wood_Ash_Trunk_Full"}, {"x": 4, "y": -3, "z": 6, "name": "Soil_Dirt"}, {"x": 4, "y": -2, "z": 6, "name": "Soil_Dirt"}, {"x": 4, "y": -1, "z": 6, "name": "Soil_Dirt", "support": 15}, {"x": 4, "y": 0, "z": 6, "name": "Soil_Grass", "support": 15}, {"x": 4, "y": -3, "z": 7, "name": "Soil_Dirt"}, {"x": 4, "y": -2, "z": 7, "name": "Soil_Dirt"}, {"x": 4, "y": -1, "z": 7, "name": "Soil_Dirt", "support": 15}, {"x": 4, "y": 0, "z": 7, "name": "Soil_Grass", "support": 15}, {"x": 4, "y": -3, "z": 8, "name": "Soil_Dirt"}, {"x": 4, "y": -2, "z": 8, "name": "Soil_Dirt"}, {"x": 4, "y": -1, "z": 8, "name": "Soil_Dirt"}, {"x": 4, "y": 0, "z": 8, "name": "Soil_Grass", "support": 15}, {"x": 4, "y": -3, "z": 9, "name": "Soil_Dirt"}, {"x": 4, "y": -2, "z": 9, "name": "Soil_Dirt"}, {"x": 4, "y": -1, "z": 9, "name": "Soil_Dirt"}, {"x": 4, "y": 0, "z": 9, "name": "Soil_Grass", "support": 15}, {"x": 4, "y": -3, "z": 10, "name": "Soil_Dirt"}, {"x": 4, "y": -2, "z": 10, "name": "Soil_Dirt"}, {"x": 4, "y": -1, "z": 10, "name": "Soil_Dirt"}, {"x": 4, "y": 0, "z": 10, "name": "Soil_Grass"}, {"x": 4, "y": -3, "z": 11, "name": "Soil_Dirt"}, {"x": 4, "y": -2, "z": 11, "name": "Soil_Dirt"}, {"x": 4, "y": -1, "z": 11, "name": "Soil_Dirt"}, {"x": 4, "y": 0, "z": 11, "name": "Soil_Grass"}, {"x": 4, "y": -3, "z": 12, "name": "Soil_Dirt"}, {"x": 4, "y": -2, "z": 12, "name": "Soil_Dirt"}, {"x": 4, "y": -1, "z": 12, "name": "Soil_Dirt"}, {"x": 4, "y": 0, "z": 12, "name": "Soil_Grass"}, {"x": 4, "y": -3, "z": 13, "name": "Soil_Dirt"}, {"x": 4, "y": -2, "z": 13, "name": "Soil_Dirt"}, {"x": 4, "y": -1, "z": 13, "name": "Soil_Dirt"}, {"x": 4, "y": 0, "z": 13, "name": "Soil_Grass"}, {"x": 4, "y": -3, "z": 14, "name": "Soil_Dirt"}, {"x": 4, "y": -2, "z": 14, "name": "Soil_Dirt"}, {"x": 4, "y": -1, "z": 14, "name": "Soil_Dirt"}, {"x": 4, "y": 0, "z": 14, "name": "Soil_Grass"}, {"x": 4, "y": -3, "z": 15, "name": "Soil_Dirt"}, {"x": 4, "y": -2, "z": 15, "name": "Soil_Dirt"}, {"x": 4, "y": -1, "z": 15, "name": "Soil_Dirt"}, {"x": 4, "y": 0, "z": 15, "name": "Soil_Grass"}, {"x": 4, "y": 3, "z": 15, "name": "Prefab_Spawner_Block", "components": {"Components": {"PrefabSpawner": {"PrefabPath": "Npc.Kweebec.Swamp.Guards.*", "FitHeightmap": false, "InheritSeed": true, "InheritHeightCondition": true}}}}, {"x": 4, "y": -3, "z": 16, "name": "Soil_Dirt"}, {"x": 4, "y": -2, "z": 16, "name": "Soil_Dirt"}, {"x": 4, "y": -1, "z": 16, "name": "Soil_Dirt"}, {"x": 4, "y": 0, "z": 16, "name": "Soil_Grass"}, {"x": 4, "y": -3, "z": 17, "name": "Soil_Dirt"}, {"x": 4, "y": -2, "z": 17, "name": "Soil_Dirt"}, {"x": 4, "y": -1, "z": 17, "name": "Soil_Dirt"}, {"x": 4, "y": 0, "z": 17, "name": "Soil_Grass"}, {"x": 4, "y": -3, "z": 18, "name": "Soil_Dirt"}, {"x": 4, "y": -2, "z": 18, "name": "Soil_Dirt"}, {"x": 4, "y": -1, "z": 18, "name": "Soil_Dirt"}, {"x": 4, "y": 0, "z": 18, "name": "Soil_Grass"}, {"x": 4, "y": -3, "z": 19, "name": "Soil_Dirt"}, {"x": 4, "y": -2, "z": 19, "name": "Soil_Dirt"}, {"x": 4, "y": -1, "z": 19, "name": "Soil_Dirt"}, {"x": 4, "y": 0, "z": 19, "name": "Soil_Grass"}, {"x": 4, "y": -3, "z": 20, "name": "Soil_Dirt"}, {"x": 4, "y": -2, "z": 20, "name": "Soil_Dirt"}, {"x": 4, "y": -1, "z": 20, "name": "Soil_Dirt"}, {"x": 4, "y": 0, "z": 20, "name": "Soil_Grass"}, {"x": 4, "y": -3, "z": 21, "name": "Soil_Dirt"}, {"x": 4, "y": -2, "z": 21, "name": "Soil_Dirt"}, {"x": 4, "y": -1, "z": 21, "name": "Soil_Dirt"}, {"x": 4, "y": 0, "z": 21, "name": "Soil_Grass"}, {"x": 4, "y": -3, "z": 22, "name": "Soil_Dirt"}, {"x": 4, "y": -2, "z": 22, "name": "Soil_Dirt"}, {"x": 4, "y": -1, "z": 22, "name": "Soil_Dirt"}, {"x": 4, "y": 0, "z": 22, "name": "Soil_Grass"}, {"x": 4, "y": -3, "z": 23, "name": "Soil_Dirt"}, {"x": 4, "y": -2, "z": 23, "name": "Soil_Dirt"}, {"x": 4, "y": -1, "z": 23, "name": "Soil_Dirt"}, {"x": 4, "y": 0, "z": 23, "name": "Soil_Grass"}, {"x": 4, "y": -3, "z": 24, "name": "Soil_Dirt"}, {"x": 4, "y": -2, "z": 24, "name": "Soil_Dirt", "support": 15}, {"x": 4, "y": -1, "z": 24, "name": "Soil_Dirt"}, {"x": 4, "y": 0, "z": 24, "name": "Soil_Grass"}, {"x": 4, "y": -3, "z": 25, "name": "Soil_Dirt"}, {"x": 4, "y": -2, "z": 25, "name": "Soil_Dirt"}, {"x": 4, "y": -1, "z": 25, "name": "Soil_Dirt"}, {"x": 4, "y": 0, "z": 25, "name": "Soil_Grass"}, {"x": 4, "y": -3, "z": 26, "name": "Soil_Dirt"}, {"x": 4, "y": -2, "z": 26, "name": "Soil_Dirt"}, {"x": 4, "y": -1, "z": 26, "name": "Soil_Dirt", "support": 15}, {"x": 4, "y": 0, "z": 26, "name": "Soil_Grass"}, {"x": 4, "y": -3, "z": 27, "name": "Soil_Dirt", "support": 15}, {"x": 4, "y": -2, "z": 27, "name": "Soil_Dirt", "support": 15}, {"x": 4, "y": -1, "z": 27, "name": "Soil_Dirt", "support": 15}, {"x": 4, "y": 0, "z": 27, "name": "Soil_Grass", "support": 15}, {"x": 4, "y": -3, "z": 28, "name": "Soil_Dirt", "support": 15}, {"x": 4, "y": -2, "z": 28, "name": "Soil_Dirt", "support": 15}, {"x": 4, "y": -1, "z": 28, "name": "Soil_Dirt", "support": 15}, {"x": 4, "y": 0, "z": 28, "name": "Soil_Grass", "support": 15}, {"x": 4, "y": -3, "z": 29, "name": "Soil_Dirt", "support": 15}, {"x": 4, "y": -2, "z": 29, "name": "Soil_Dirt", "support": 15}, {"x": 4, "y": -1, "z": 29, "name": "Soil_Dirt", "support": 15}, {"x": 4, "y": 0, "z": 29, "name": "Soil_Grass", "support": 15}, {"x": 4, "y": -3, "z": 30, "name": "Soil_Dirt"}, {"x": 4, "y": -2, "z": 30, "name": "Soil_Dirt"}, {"x": 4, "y": -1, "z": 30, "name": "Soil_Dirt"}, {"x": 4, "y": 0, "z": 30, "name": "Soil_Grass"}, {"x": 4, "y": -3, "z": 31, "name": "Soil_Dirt"}, {"x": 4, "y": -2, "z": 31, "name": "Soil_Dirt"}, {"x": 4, "y": -1, "z": 31, "name": "Soil_Dirt"}, {"x": 4, "y": 0, "z": 31, "name": "Soil_Grass"}, {"x": 5, "y": -3, "z": 0, "name": "Soil_Dirt"}, {"x": 5, "y": -2, "z": 0, "name": "Soil_Dirt"}, {"x": 5, "y": -1, "z": 0, "name": "Soil_Dirt"}, {"x": 5, "y": 0, "z": 0, "name": "Soil_Grass"}, {"x": 5, "y": 3, "z": 0, "name": "Wood_Ash_Trunk_Full"}, {"x": 5, "y": 4, "z": 0, "name": "Wood_Ash_Trunk", "support": 15}, {"x": 5, "y": 5, "z": 0, "name": "Wood_Ash_Trunk_Full"}, {"x": 5, "y": -3, "z": 1, "name": "Soil_Dirt"}, {"x": 5, "y": -2, "z": 1, "name": "Soil_Dirt"}, {"x": 5, "y": -1, "z": 1, "name": "Soil_Dirt"}, {"x": 5, "y": 0, "z": 1, "name": "Soil_Grass"}, {"x": 5, "y": 4, "z": 1, "name": "Wood_Ash_Trunk_Full"}, {"x": 5, "y": 5, "z": 1, "name": "Wood_Ash_Trunk", "support": 15}, {"x": 5, "y": 6, "z": 1, "name": "Wood_Ash_Trunk", "support": 15}, {"x": 5, "y": 7, "z": 1, "name": "Wood_Ash_Trunk", "support": 15}, {"x": 5, "y": 8, "z": 1, "name": "Wood_Ash_Trunk_Full"}, {"x": 5, "y": -3, "z": 2, "name": "Soil_Dirt"}, {"x": 5, "y": -2, "z": 2, "name": "Soil_Dirt"}, {"x": 5, "y": -1, "z": 2, "name": "Soil_Dirt"}, {"x": 5, "y": 0, "z": 2, "name": "Soil_Grass"}, {"x": 5, "y": 4, "z": 2, "name": "Wood_Ash_Trunk_Full"}, {"x": 5, "y": 5, "z": 2, "name": "Wood_Ash_Trunk", "support": 15}, {"x": 5, "y": 6, "z": 2, "name": "Wood_Ash_Trunk", "support": 15}, {"x": 5, "y": 7, "z": 2, "name": "Wood_Ash_Trunk", "support": 15}, {"x": 5, "y": 8, "z": 2, "name": "Wood_Ash_Trunk", "support": 15}, {"x": 5, "y": 9, "z": 2, "name": "Wood_Ash_Trunk_Full"}, {"x": 5, "y": -3, "z": 3, "name": "Soil_Dirt", "support": 15}, {"x": 5, "y": -2, "z": 3, "name": "Soil_Dirt", "support": 15}, {"x": 5, "y": -1, "z": 3, "name": "Soil_Dirt", "support": 15}, {"x": 5, "y": 0, "z": 3, "name": "Soil_Grass"}, {"x": 5, "y": 1, "z": 3, "name": "Wood_Ash_Roots"}, {"x": 5, "y": 2, "z": 3, "name": "Wood_Ash_Trunk_Full"}, {"x": 5, "y": 3, "z": 3, "name": "Wood_Ash_Trunk", "support": 15}, {"x": 5, "y": 4, "z": 3, "name": "Wood_Ash_Trunk", "support": 15}, {"x": 5, "y": 5, "z": 3, "name": "Wood_Ash_Trunk", "support": 15}, {"x": 5, "y": 6, "z": 3, "name": "Wood_Ash_Trunk", "support": 15}, {"x": 5, "y": 7, "z": 3, "name": "Wood_Ash_Trunk", "support": 15}, {"x": 5, "y": 8, "z": 3, "name": "Wood_Ash_Trunk", "support": 15}, {"x": 5, "y": 9, "z": 3, "name": "Wood_Ash_Trunk", "support": 15}, {"x": 5, "y": 10, "z": 3, "name": "Wood_Ash_Trunk_Full"}, {"x": 5, "y": -3, "z": 4, "name": "Soil_Dirt"}, {"x": 5, "y": -2, "z": 4, "name": "Wood_Ash_Trunk_Full"}, {"x": 5, "y": -1, "z": 4, "name": "Wood_Ash_Trunk", "support": 15}, {"x": 5, "y": 0, "z": 4, "name": "Wood_Ash_Trunk", "support": 15}, {"x": 5, "y": 1, "z": 4, "name": "Wood_Ash_Trunk", "support": 15}, {"x": 5, "y": 2, "z": 4, "name": "Wood_Ash_Trunk", "support": 15}, {"x": 5, "y": 3, "z": 4, "name": "Wood_Ash_Trunk", "support": 15}, {"x": 5, "y": 4, "z": 4, "name": "Wood_Ash_Trunk", "support": 15}, {"x": 5, "y": 5, "z": 4, "name": "Wood_Ash_Trunk", "support": 15}, {"x": 5, "y": 6, "z": 4, "name": "Wood_Ash_Trunk", "support": 15}, {"x": 5, "y": 7, "z": 4, "name": "Wood_Ash_Trunk", "support": 15}, {"x": 5, "y": 8, "z": 4, "name": "Wood_Ash_Trunk", "support": 15}, {"x": 5, "y": 9, "z": 4, "name": "Wood_Ash_Trunk", "support": 15}, {"x": 5, "y": 10, "z": 4, "name": "Wood_Ash_Trunk_Full"}, {"x": 5, "y": -3, "z": 5, "name": "Soil_Dirt"}, {"x": 5, "y": -2, "z": 5, "name": "Soil_Dirt"}, {"x": 5, "y": -1, "z": 5, "name": "Soil_Dirt", "support": 15}, {"x": 5, "y": 0, "z": 5, "name": "Soil_Grass", "support": 15}, {"x": 5, "y": 3, "z": 5, "name": "Wood_Ash_Trunk_Full"}, {"x": 5, "y": 4, "z": 5, "name": "Wood_Ash_Trunk", "support": 15}, {"x": 5, "y": 5, "z": 5, "name": "Wood_Ash_Trunk", "support": 15}, {"x": 5, "y": 6, "z": 5, "name": "Wood_Ash_Trunk", "support": 15}, {"x": 5, "y": 7, "z": 5, "name": "Wood_Ash_Trunk_Full"}, {"x": 5, "y": -3, "z": 6, "name": "Soil_Dirt"}, {"x": 5, "y": -2, "z": 6, "name": "Soil_Dirt"}, {"x": 5, "y": -1, "z": 6, "name": "Soil_Dirt", "support": 15}, {"x": 5, "y": 0, "z": 6, "name": "Soil_Grass", "support": 15}, {"x": 5, "y": -3, "z": 7, "name": "Soil_Dirt"}, {"x": 5, "y": -2, "z": 7, "name": "Soil_Dirt"}, {"x": 5, "y": -1, "z": 7, "name": "Soil_Dirt", "support": 15}, {"x": 5, "y": 0, "z": 7, "name": "Soil_Grass", "support": 15}, {"x": 5, "y": -3, "z": 8, "name": "Soil_Dirt"}, {"x": 5, "y": -2, "z": 8, "name": "Soil_Dirt"}, {"x": 5, "y": -1, "z": 8, "name": "Soil_Dirt"}, {"x": 5, "y": 0, "z": 8, "name": "Soil_Grass"}, {"x": 5, "y": -3, "z": 9, "name": "Soil_Dirt"}, {"x": 5, "y": -2, "z": 9, "name": "Soil_Dirt"}, {"x": 5, "y": -1, "z": 9, "name": "Soil_Dirt"}, {"x": 5, "y": 0, "z": 9, "name": "Soil_Grass"}, {"x": 5, "y": -3, "z": 10, "name": "Soil_Dirt"}, {"x": 5, "y": -2, "z": 10, "name": "Soil_Dirt"}, {"x": 5, "y": -1, "z": 10, "name": "Soil_Dirt"}, {"x": 5, "y": 0, "z": 10, "name": "Soil_Grass"}, {"x": 5, "y": -3, "z": 11, "name": "Soil_Dirt"}, {"x": 5, "y": -2, "z": 11, "name": "Soil_Dirt"}, {"x": 5, "y": -1, "z": 11, "name": "Soil_Dirt"}, {"x": 5, "y": 0, "z": 11, "name": "Soil_Grass"}, {"x": 5, "y": -3, "z": 12, "name": "Soil_Dirt"}, {"x": 5, "y": -2, "z": 12, "name": "Soil_Dirt"}, {"x": 5, "y": -1, "z": 12, "name": "Soil_Dirt"}, {"x": 5, "y": 0, "z": 12, "name": "Soil_Grass"}, {"x": 5, "y": -3, "z": 13, "name": "Soil_Dirt"}, {"x": 5, "y": -2, "z": 13, "name": "Soil_Dirt"}, {"x": 5, "y": -1, "z": 13, "name": "Soil_Dirt"}, {"x": 5, "y": 0, "z": 13, "name": "Soil_Grass"}, {"x": 5, "y": -3, "z": 14, "name": "Soil_Dirt"}, {"x": 5, "y": -2, "z": 14, "name": "Soil_Dirt"}, {"x": 5, "y": -1, "z": 14, "name": "Soil_Dirt"}, {"x": 5, "y": 0, "z": 14, "name": "Soil_Grass"}, {"x": 5, "y": -3, "z": 15, "name": "Soil_Dirt"}, {"x": 5, "y": -2, "z": 15, "name": "Soil_Dirt"}, {"x": 5, "y": -1, "z": 15, "name": "Soil_Dirt"}, {"x": 5, "y": 0, "z": 15, "name": "Soil_Grass"}, {"x": 5, "y": -3, "z": 16, "name": "Soil_Dirt"}, {"x": 5, "y": -2, "z": 16, "name": "Soil_Dirt"}, {"x": 5, "y": -1, "z": 16, "name": "Soil_Dirt"}, {"x": 5, "y": 0, "z": 16, "name": "Soil_Grass"}, {"x": 5, "y": -3, "z": 17, "name": "Soil_Dirt"}, {"x": 5, "y": -2, "z": 17, "name": "Soil_Dirt"}, {"x": 5, "y": -1, "z": 17, "name": "Soil_Dirt"}, {"x": 5, "y": 0, "z": 17, "name": "Soil_Grass"}, {"x": 5, "y": -3, "z": 18, "name": "Soil_Dirt"}, {"x": 5, "y": -2, "z": 18, "name": "Soil_Dirt"}, {"x": 5, "y": -1, "z": 18, "name": "Soil_Dirt"}, {"x": 5, "y": 0, "z": 18, "name": "Soil_Grass"}, {"x": 5, "y": -3, "z": 19, "name": "Soil_Dirt"}, {"x": 5, "y": -2, "z": 19, "name": "Soil_Dirt"}, {"x": 5, "y": -1, "z": 19, "name": "Soil_Dirt"}, {"x": 5, "y": 0, "z": 19, "name": "Soil_Grass"}, {"x": 5, "y": -3, "z": 20, "name": "Soil_Dirt"}, {"x": 5, "y": -2, "z": 20, "name": "Soil_Dirt"}, {"x": 5, "y": -1, "z": 20, "name": "Soil_Dirt"}, {"x": 5, "y": 0, "z": 20, "name": "Soil_Grass"}, {"x": 5, "y": -3, "z": 21, "name": "Soil_Dirt"}, {"x": 5, "y": -2, "z": 21, "name": "Soil_Dirt"}, {"x": 5, "y": -1, "z": 21, "name": "Soil_Dirt"}, {"x": 5, "y": 0, "z": 21, "name": "Soil_Grass"}, {"x": 5, "y": -3, "z": 22, "name": "Soil_Dirt"}, {"x": 5, "y": -2, "z": 22, "name": "Soil_Dirt"}, {"x": 5, "y": -1, "z": 22, "name": "Soil_Dirt"}, {"x": 5, "y": 0, "z": 22, "name": "Soil_Grass"}, {"x": 5, "y": -3, "z": 23, "name": "Soil_Dirt", "support": 15}, {"x": 5, "y": -2, "z": 23, "name": "Soil_Dirt", "support": 15}, {"x": 5, "y": -1, "z": 23, "name": "Soil_Dirt"}, {"x": 5, "y": 0, "z": 23, "name": "Soil_Grass"}, {"x": 5, "y": -3, "z": 24, "name": "Soil_Dirt"}, {"x": 5, "y": -2, "z": 24, "name": "Soil_Dirt", "support": 15}, {"x": 5, "y": -1, "z": 24, "name": "Soil_Dirt"}, {"x": 5, "y": 0, "z": 24, "name": "Soil_Grass"}, {"x": 5, "y": -3, "z": 25, "name": "Wood_Ash_Trunk_Full"}, {"x": 5, "y": -2, "z": 25, "name": "Soil_Dirt"}, {"x": 5, "y": -1, "z": 25, "name": "Soil_Dirt"}, {"x": 5, "y": 0, "z": 25, "name": "Soil_Grass"}, {"x": 5, "y": -3, "z": 26, "name": "Wood_Ash_Trunk_Full"}, {"x": 5, "y": -2, "z": 26, "name": "Wood_Ash_Trunk_Full"}, {"x": 5, "y": -1, "z": 26, "name": "Soil_Dirt", "support": 15}, {"x": 5, "y": 0, "z": 26, "name": "Soil_Grass"}, {"x": 5, "y": -3, "z": 27, "name": "Wood_Ash_Trunk_Full"}, {"x": 5, "y": -2, "z": 27, "name": "Wood_Ash_Trunk", "support": 15}, {"x": 5, "y": -1, "z": 27, "name": "Wood_Ash_Trunk_Full"}, {"x": 5, "y": 0, "z": 27, "name": "Soil_Grass", "support": 15}, {"x": 5, "y": -3, "z": 28, "name": "Wood_Ash_Trunk", "support": 15}, {"x": 5, "y": -2, "z": 28, "name": "Wood_Ash_Trunk_Full"}, {"x": 5, "y": -1, "z": 28, "name": "Soil_Dirt"}, {"x": 5, "y": 0, "z": 28, "name": "Soil_Grass"}, {"x": 5, "y": -3, "z": 29, "name": "Wood_Ash_Trunk_Full"}, {"x": 5, "y": -2, "z": 29, "name": "Soil_Dirt"}, {"x": 5, "y": -1, "z": 29, "name": "Soil_Dirt"}, {"x": 5, "y": 0, "z": 29, "name": "Soil_Grass"}, {"x": 5, "y": -3, "z": 30, "name": "Soil_Dirt"}, {"x": 5, "y": -2, "z": 30, "name": "Soil_Dirt"}, {"x": 5, "y": -1, "z": 30, "name": "Soil_Dirt"}, {"x": 5, "y": 0, "z": 30, "name": "Soil_Grass"}, {"x": 5, "y": -3, "z": 31, "name": "Soil_Dirt"}, {"x": 5, "y": -2, "z": 31, "name": "Soil_Dirt"}, {"x": 5, "y": -1, "z": 31, "name": "Soil_Dirt"}, {"x": 5, "y": 0, "z": 31, "name": "Soil_Grass"}, {"x": 6, "y": -3, "z": 0, "name": "Soil_Dirt"}, {"x": 6, "y": -2, "z": 0, "name": "Soil_Dirt"}, {"x": 6, "y": -1, "z": 0, "name": "Soil_Dirt"}, {"x": 6, "y": 0, "z": 0, "name": "Soil_Grass"}, {"x": 6, "y": 2, "z": 0, "name": "Wood_Ash_Trunk_Full"}, {"x": 6, "y": 3, "z": 0, "name": "Wood_Ash_Trunk", "support": 15}, {"x": 6, "y": 4, "z": 0, "name": "Wood_Ash_Trunk", "support": 15}, {"x": 6, "y": 5, "z": 0, "name": "Wood_Ash_Trunk", "support": 15}, {"x": 6, "y": 6, "z": 0, "name": "Wood_Ash_Trunk_Full"}, {"x": 6, "y": 38, "z": 0, "name": "Plant_Leaves_Ash"}, {"x": 6, "y": 39, "z": 0, "name": "Plant_Leaves_Ash"}, {"x": 6, "y": -3, "z": 1, "name": "Soil_Dirt"}, {"x": 6, "y": -2, "z": 1, "name": "Soil_Dirt"}, {"x": 6, "y": -1, "z": 1, "name": "Soil_Dirt"}, {"x": 6, "y": 0, "z": 1, "name": "Soil_Grass"}, {"x": 6, "y": 2, "z": 1, "name": "Wood_Ash_Roots"}, {"x": 6, "y": 3, "z": 1, "name": "Wood_Ash_Trunk_Full"}, {"x": 6, "y": 4, "z": 1, "name": "Wood_Ash_Trunk", "support": 15}, {"x": 6, "y": 5, "z": 1, "name": "Wood_Ash_Trunk", "support": 15}, {"x": 6, "y": 6, "z": 1, "name": "Wood_Ash_Trunk", "support": 15}, {"x": 6, "y": 7, "z": 1, "name": "Wood_Ash_Trunk", "support": 15}, {"x": 6, "y": 8, "z": 1, "name": "Wood_Ash_Trunk", "support": 15}, {"x": 6, "y": 9, "z": 1, "name": "Wood_Ash_Trunk_Full"}, {"x": 6, "y": 37, "z": 1, "name": "Plant_Leaves_Ash"}, {"x": 6, "y": 38, "z": 1, "name": "Plant_Leaves_Ash"}, {"x": 6, "y": -3, "z": 2, "name": "Soil_Dirt", "support": 15}, {"x": 6, "y": -2, "z": 2, "name": "Soil_Dirt"}, {"x": 6, "y": -1, "z": 2, "name": "Soil_Dirt"}, {"x": 6, "y": 0, "z": 2, "name": "Soil_Grass"}, {"x": 6, "y": 3, "z": 2, "name": "Wood_Ash_Trunk_Full"}, {"x": 6, "y": 4, "z": 2, "name": "Wood_Ash_Trunk", "support": 15}, {"x": 6, "y": 5, "z": 2, "name": "Wood_Ash_Trunk", "support": 15}, {"x": 6, "y": 6, "z": 2, "name": "Wood_Ash_Trunk", "support": 15}, {"x": 6, "y": 7, "z": 2, "name": "Wood_Ash_Trunk", "support": 15}, {"x": 6, "y": 8, "z": 2, "name": "Wood_Ash_Trunk", "support": 15}, {"x": 6, "y": 9, "z": 2, "name": "Wood_Ash_Trunk", "support": 15}, {"x": 6, "y": 10, "z": 2, "name": "Wood_Ash_Trunk", "support": 15}, {"x": 6, "y": 11, "z": 2, "name": "Wood_Ash_Trunk_Full"}, {"x": 6, "y": 36, "z": 2, "name": "Plant_Leaves_Ash"}, {"x": 6, "y": 37, "z": 2, "name": "Plant_Leaves_Ash"}, {"x": 6, "y": 38, "z": 2, "name": "Plant_Leaves_Ash"}, {"x": 6, "y": -3, "z": 3, "name": "Soil_Dirt"}, {"x": 6, "y": -2, "z": 3, "name": "Soil_Dirt", "support": 15}, {"x": 6, "y": -1, "z": 3, "name": "Soil_Dirt", "support": 15}, {"x": 6, "y": 0, "z": 3, "name": "Soil_Grass"}, {"x": 6, "y": 2, "z": 3, "name": "Wood_Ash_Trunk_Full", "rotation": 5}, {"x": 6, "y": 3, "z": 3, "name": "Wood_Ash_Trunk", "support": 15}, {"x": 6, "y": 4, "z": 3, "name": "Wood_Ash_Trunk", "support": 15}, {"x": 6, "y": 5, "z": 3, "name": "Wood_Ash_Trunk", "support": 15}, {"x": 6, "y": 6, "z": 3, "name": "Wood_Ash_Trunk", "support": 15}, {"x": 6, "y": 7, "z": 3, "name": "Wood_Ash_Trunk", "support": 15}, {"x": 6, "y": 8, "z": 3, "name": "Wood_Ash_Trunk", "support": 15}, {"x": 6, "y": 9, "z": 3, "name": "Wood_Ash_Trunk", "support": 15}, {"x": 6, "y": 10, "z": 3, "name": "Wood_Ash_Trunk", "support": 15}, {"x": 6, "y": 11, "z": 3, "name": "Wood_Ash_Trunk_Full"}, {"x": 6, "y": 36, "z": 3, "name": "Plant_Leaves_Ash"}, {"x": 6, "y": 37, "z": 3, "name": "Plant_Leaves_Ash"}, {"x": 6, "y": 38, "z": 3, "name": "Plant_Leaves_Ash"}, {"x": 6, "y": 39, "z": 3, "name": "Plant_Leaves_Ash"}, {"x": 6, "y": -3, "z": 4, "name": "Soil_Dirt"}, {"x": 6, "y": -2, "z": 4, "name": "Soil_Dirt"}, {"x": 6, "y": -1, "z": 4, "name": "Soil_Dirt", "support": 15}, {"x": 6, "y": 0, "z": 4, "name": "Wood_Ash_Trunk_Full"}, {"x": 6, "y": 1, "z": 4, "name": "Wood_Ash_Trunk", "support": 15}, {"x": 6, "y": 2, "z": 4, "name": "Wood_Ash_Trunk", "support": 15}, {"x": 6, "y": 3, "z": 4, "name": "Wood_Ash_Trunk", "support": 15}, {"x": 6, "y": 4, "z": 4, "name": "Wood_Ash_Trunk", "support": 15}, {"x": 6, "y": 5, "z": 4, "name": "Wood_Ash_Trunk", "support": 15}, {"x": 6, "y": 6, "z": 4, "name": "Wood_Ash_Trunk", "support": 15}, {"x": 6, "y": 7, "z": 4, "name": "Wood_Ash_Trunk", "support": 15}, {"x": 6, "y": 8, "z": 4, "name": "Wood_Ash_Trunk", "support": 15}, {"x": 6, "y": 9, "z": 4, "name": "Wood_Ash_Trunk", "support": 15}, {"x": 6, "y": 10, "z": 4, "name": "Wood_Ash_Trunk", "support": 15}, {"x": 6, "y": 11, "z": 4, "name": "Wood_Ash_Trunk_Full"}, {"x": 6, "y": 37, "z": 4, "name": "Plant_Leaves_Ash"}, {"x": 6, "y": 38, "z": 4, "name": "Plant_Leaves_Ash"}, {"x": 6, "y": 39, "z": 4, "name": "Plant_Leaves_Ash"}, {"x": 6, "y": -3, "z": 5, "name": "Soil_Dirt"}, {"x": 6, "y": -2, "z": 5, "name": "Soil_Dirt"}, {"x": 6, "y": -1, "z": 5, "name": "Soil_Dirt"}, {"x": 6, "y": 0, "z": 5, "name": "Soil_Grass"}, {"x": 6, "y": 4, "z": 5, "name": "Wood_Ash_Trunk_Full"}, {"x": 6, "y": 5, "z": 5, "name": "Wood_Ash_Trunk", "support": 15}, {"x": 6, "y": 6, "z": 5, "name": "Wood_Ash_Trunk", "support": 15}, {"x": 6, "y": 7, "z": 5, "name": "Wood_Ash_Trunk", "support": 15}, {"x": 6, "y": 8, "z": 5, "name": "Wood_Ash_Trunk", "support": 15}, {"x": 6, "y": 9, "z": 5, "name": "Wood_Ash_Trunk_Full"}, {"x": 6, "y": 12, "z": 5, "name": "Plant_Moss_Wall_Green_Dark", "rotation": 3}, {"x": 6, "y": 37, "z": 5, "name": "Plant_Leaves_Ash"}, {"x": 6, "y": -3, "z": 6, "name": "Soil_Dirt"}, {"x": 6, "y": -2, "z": 6, "name": "Soil_Dirt"}, {"x": 6, "y": -1, "z": 6, "name": "Soil_Dirt"}, {"x": 6, "y": 0, "z": 6, "name": "Soil_Grass"}, {"x": 6, "y": -3, "z": 7, "name": "Soil_Dirt"}, {"x": 6, "y": -2, "z": 7, "name": "Soil_Dirt"}, {"x": 6, "y": -1, "z": 7, "name": "Soil_Dirt"}, {"x": 6, "y": 0, "z": 7, "name": "Soil_Grass"}, {"x": 6, "y": -3, "z": 8, "name": "Soil_Dirt"}, {"x": 6, "y": -2, "z": 8, "name": "Soil_Dirt"}, {"x": 6, "y": -1, "z": 8, "name": "Soil_Dirt"}, {"x": 6, "y": 0, "z": 8, "name": "Soil_Grass"}, {"x": 6, "y": -3, "z": 9, "name": "Soil_Dirt"}, {"x": 6, "y": -2, "z": 9, "name": "Soil_Dirt"}, {"x": 6, "y": -1, "z": 9, "name": "Soil_Dirt"}, {"x": 6, "y": 0, "z": 9, "name": "Soil_Grass"}, {"x": 6, "y": -3, "z": 10, "name": "Soil_Dirt"}, {"x": 6, "y": -2, "z": 10, "name": "Soil_Dirt"}, {"x": 6, "y": -1, "z": 10, "name": "Soil_Dirt"}, {"x": 6, "y": 0, "z": 10, "name": "Soil_Grass"}, {"x": 6, "y": -3, "z": 11, "name": "Soil_Dirt"}, {"x": 6, "y": -2, "z": 11, "name": "Soil_Dirt"}, {"x": 6, "y": -1, "z": 11, "name": "Soil_Dirt"}, {"x": 6, "y": 0, "z": 11, "name": "Soil_Grass"}, {"x": 6, "y": 3, "z": 11, "name": "Wood_Ash_Roots"}, {"x": 6, "y": 4, "z": 11, "name": "Wood_Ash_Trunk", "support": 15}, {"x": 6, "y": 5, "z": 11, "name": "Wood_Ash_Trunk", "support": 15}, {"x": 6, "y": 6, "z": 11, "name": "Wood_Ash_Trunk", "support": 15}, {"x": 6, "y": 7, "z": 11, "name": "Wood_Ash_Trunk_Full"}, {"x": 6, "y": -3, "z": 12, "name": "Soil_Dirt"}, {"x": 6, "y": -2, "z": 12, "name": "Soil_Dirt"}, {"x": 6, "y": -1, "z": 12, "name": "Soil_Dirt"}, {"x": 6, "y": 0, "z": 12, "name": "Soil_Grass"}, {"x": 6, "y": -3, "z": 13, "name": "Soil_Dirt"}, {"x": 6, "y": -2, "z": 13, "name": "Soil_Dirt"}, {"x": 6, "y": -1, "z": 13, "name": "Soil_Dirt"}, {"x": 6, "y": 0, "z": 13, "name": "Soil_Grass"}, {"x": 6, "y": -3, "z": 14, "name": "Soil_Dirt"}, {"x": 6, "y": -2, "z": 14, "name": "Soil_Dirt"}, {"x": 6, "y": -1, "z": 14, "name": "Soil_Dirt"}, {"x": 6, "y": 0, "z": 14, "name": "Soil_Grass", "support": 15}, {"x": 6, "y": -3, "z": 15, "name": "Soil_Dirt", "support": 15}, {"x": 6, "y": -2, "z": 15, "name": "Soil_Dirt", "support": 15}, {"x": 6, "y": -1, "z": 15, "name": "Soil_Dirt"}, {"x": 6, "y": 0, "z": 15, "name": "Soil_Grass"}, {"x": 6, "y": -3, "z": 16, "name": "Soil_Dirt"}, {"x": 6, "y": -2, "z": 16, "name": "Soil_Dirt"}, {"x": 6, "y": -1, "z": 16, "name": "Soil_Dirt"}, {"x": 6, "y": 0, "z": 16, "name": "Soil_Grass"}, {"x": 6, "y": -3, "z": 17, "name": "Soil_Dirt"}, {"x": 6, "y": -2, "z": 17, "name": "Soil_Dirt"}, {"x": 6, "y": -1, "z": 17, "name": "Soil_Dirt"}, {"x": 6, "y": 0, "z": 17, "name": "Soil_Grass"}, {"x": 6, "y": -3, "z": 18, "name": "Soil_Dirt"}, {"x": 6, "y": -2, "z": 18, "name": "Soil_Dirt"}, {"x": 6, "y": -1, "z": 18, "name": "Soil_Dirt"}, {"x": 6, "y": 0, "z": 18, "name": "Soil_Grass"}, {"x": 6, "y": -3, "z": 19, "name": "Soil_Dirt"}, {"x": 6, "y": -2, "z": 19, "name": "Soil_Dirt"}, {"x": 6, "y": -1, "z": 19, "name": "Soil_Dirt"}, {"x": 6, "y": 0, "z": 19, "name": "Soil_Grass"}, {"x": 6, "y": -3, "z": 20, "name": "Wood_Ash_Trunk_Full"}, {"x": 6, "y": -2, "z": 20, "name": "Soil_Dirt"}, {"x": 6, "y": -1, "z": 20, "name": "Soil_Dirt"}, {"x": 6, "y": 0, "z": 20, "name": "Soil_Grass"}, {"x": 6, "y": -3, "z": 21, "name": "Wood_Ash_Trunk_Full"}, {"x": 6, "y": -2, "z": 21, "name": "Wood_Ash_Trunk", "support": 15}, {"x": 6, "y": -1, "z": 21, "name": "Wood_Ash_Trunk_Full"}, {"x": 6, "y": 0, "z": 21, "name": "Soil_Grass"}, {"x": 6, "y": -3, "z": 22, "name": "Soil_Dirt"}, {"x": 6, "y": -2, "z": 22, "name": "Soil_Dirt"}, {"x": 6, "y": -1, "z": 22, "name": "Wood_Ash_Trunk_Full"}, {"x": 6, "y": 0, "z": 22, "name": "Soil_Grass"}, {"x": 6, "y": -3, "z": 23, "name": "Soil_Dirt", "support": 15}, {"x": 6, "y": -2, "z": 23, "name": "Soil_Dirt"}, {"x": 6, "y": -1, "z": 23, "name": "Soil_Dirt"}, {"x": 6, "y": 0, "z": 23, "name": "Soil_Grass"}, {"x": 6, "y": 2, "z": 23, "name": "Wood_Ash_Trunk_Full"}, {"x": 6, "y": 3, "z": 23, "name": "Wood_Ash_Trunk_Full"}, {"x": 6, "y": -3, "z": 24, "name": "Soil_Dirt", "support": 15}, {"x": 6, "y": -2, "z": 24, "name": "Soil_Dirt"}, {"x": 6, "y": -1, "z": 24, "name": "Soil_Dirt"}, {"x": 6, "y": 0, "z": 24, "name": "Soil_Grass"}, {"x": 6, "y": 3, "z": 24, "name": "Wood_Ash_Trunk_Full"}, {"x": 6, "y": 4, "z": 24, "name": "Wood_Ash_Trunk_Full"}, {"x": 6, "y": -3, "z": 25, "name": "Wood_Ash_Trunk_Full"}, {"x": 6, "y": -2, "z": 25, "name": "Soil_Dirt"}, {"x": 6, "y": -1, "z": 25, "name": "Soil_Dirt"}, {"x": 6, "y": 0, "z": 25, "name": "Soil_Grass"}, {"x": 6, "y": 2, "z": 25, "name": "Wood_Ash_Trunk_Full"}, {"x": 6, "y": 3, "z": 25, "name": "Wood_Ash_Trunk_Full"}, {"x": 6, "y": -3, "z": 26, "name": "Wood_Ash_Trunk", "support": 15}, {"x": 6, "y": -2, "z": 26, "name": "Wood_Ash_Trunk", "support": 15}, {"x": 6, "y": -1, "z": 26, "name": "Wood_Ash_Trunk", "support": 15}, {"x": 6, "y": 0, "z": 26, "name": "Wood_Ash_Trunk", "support": 15}, {"x": 6, "y": 1, "z": 26, "name": "Wood_Ash_Trunk", "support": 15}, {"x": 6, "y": 2, "z": 26, "name": "Wood_Ash_Trunk_Full"}, {"x": 6, "y": -3, "z": 27, "name": "Wood_Ash_Trunk_Full"}, {"x": 6, "y": -2, "z": 27, "name": "Wood_Ash_Trunk", "support": 15}, {"x": 6, "y": -1, "z": 27, "name": "Wood_Ash_Trunk", "support": 15}, {"x": 6, "y": 0, "z": 27, "name": "Wood_Ash_Trunk_Full"}, {"x": 6, "y": -3, "z": 28, "name": "Wood_Ash_Trunk", "support": 15}, {"x": 6, "y": -2, "z": 28, "name": "Wood_Ash_Trunk", "support": 15}, {"x": 6, "y": -1, "z": 28, "name": "Wood_Ash_Trunk_Full"}, {"x": 6, "y": 0, "z": 28, "name": "Soil_Grass"}, {"x": 6, "y": -3, "z": 29, "name": "Soil_Dirt"}, {"x": 6, "y": -2, "z": 29, "name": "Soil_Dirt"}, {"x": 6, "y": -1, "z": 29, "name": "Soil_Dirt"}, {"x": 6, "y": 0, "z": 29, "name": "Soil_Grass"}, {"x": 6, "y": -3, "z": 30, "name": "Soil_Dirt"}, {"x": 6, "y": -2, "z": 30, "name": "Soil_Dirt"}, {"x": 6, "y": -1, "z": 30, "name": "Soil_Dirt"}, {"x": 6, "y": 0, "z": 30, "name": "Soil_Grass"}, {"x": 6, "y": -3, "z": 31, "name": "Soil_Dirt"}, {"x": 6, "y": -2, "z": 31, "name": "Soil_Dirt"}, {"x": 6, "y": -1, "z": 31, "name": "Soil_Dirt"}, {"x": 6, "y": 0, "z": 31, "name": "Soil_Grass"}, {"x": 7, "y": -3, "z": 0, "name": "Soil_Dirt"}, {"x": 7, "y": -2, "z": 0, "name": "Soil_Dirt"}, {"x": 7, "y": -1, "z": 0, "name": "Soil_Dirt"}, {"x": 7, "y": 0, "z": 0, "name": "Soil_Grass"}, {"x": 7, "y": 2, "z": 0, "name": "Wood_Ash_Trunk_Full"}, {"x": 7, "y": 3, "z": 0, "name": "Wood_Ash_Trunk", "support": 15}, {"x": 7, "y": 4, "z": 0, "name": "Wood_Ash_Trunk", "support": 15}, {"x": 7, "y": 5, "z": 0, "name": "Wood_Ash_Trunk_Full"}, {"x": 7, "y": 9, "z": 0, "name": "Wood_Ash_Trunk_Full"}, {"x": 7, "y": 10, "z": 0, "name": "Wood_Ash_Trunk_Full"}, {"x": 7, "y": 24, "z": 0, "name": "Plant_Leaves_Ash"}, {"x": 7, "y": 25, "z": 0, "name": "Plant_Leaves_Ash"}, {"x": 7, "y": 26, "z": 0, "name": "Plant_Leaves_Ash"}, {"x": 7, "y": 27, "z": 0, "name": "Plant_Leaves_Ash"}, {"x": 7, "y": 28, "z": 0, "name": "Plant_Leaves_Ash"}, {"x": 7, "y": 29, "z": 0, "name": "Plant_Leaves_Ash"}, {"x": 7, "y": 30, "z": 0, "name": "Plant_Leaves_Ash"}, {"x": 7, "y": 31, "z": 0, "name": "Plant_Leaves_Ash"}, {"x": 7, "y": 37, "z": 0, "name": "Wood_Ash_Roots"}, {"x": 7, "y": 38, "z": 0, "name": "Wood_Ash_Trunk_Full"}, {"x": 7, "y": 39, "z": 0, "name": "Plant_Leaves_Ash"}, {"x": 7, "y": 40, "z": 0, "name": "Plant_Leaves_Ash"}, {"x": 7, "y": -3, "z": 1, "name": "Soil_Dirt"}, {"x": 7, "y": -2, "z": 1, "name": "Soil_Dirt"}, {"x": 7, "y": -1, "z": 1, "name": "Soil_Dirt"}, {"x": 7, "y": 0, "z": 1, "name": "Soil_Grass"}, {"x": 7, "y": 4, "z": 1, "name": "Wood_Ash_Trunk_Full"}, {"x": 7, "y": 5, "z": 1, "name": "Wood_Ash_Trunk", "support": 15}, {"x": 7, "y": 6, "z": 1, "name": "Wood_Ash_Trunk", "support": 15}, {"x": 7, "y": 7, "z": 1, "name": "Wood_Ash_Trunk", "support": 15}, {"x": 7, "y": 8, "z": 1, "name": "Wood_Ash_Trunk", "support": 15}, {"x": 7, "y": 9, "z": 1, "name": "Wood_Ash_Trunk", "support": 15}, {"x": 7, "y": 10, "z": 1, "name": "Wood_Ash_Trunk", "support": 15}, {"x": 7, "y": 11, "z": 1, "name": "Wood_Ash_Trunk_Full"}, {"x": 7, "y": 22, "z": 1, "name": "Plant_Leaves_Ash"}, {"x": 7, "y": 23, "z": 1, "name": "Plant_Leaves_Ash"}, {"x": 7, "y": 24, "z": 1, "name": "Plant_Leaves_Ash"}, {"x": 7, "y": 25, "z": 1, "name": "Plant_Leaves_Ash"}, {"x": 7, "y": 36, "z": 1, "name": "Plant_Leaves_Ash"}, {"x": 7, "y": 37, "z": 1, "name": "Plant_Leaves_Ash"}, {"x": 7, "y": 38, "z": 1, "name": "Plant_Leaves_Ash"}, {"x": 7, "y": 39, "z": 1, "name": "Plant_Leaves_Ash"}, {"x": 7, "y": 40, "z": 1, "name": "Plant_Leaves_Ash"}, {"x": 7, "y": -3, "z": 2, "name": "Soil_Dirt", "support": 15}, {"x": 7, "y": -2, "z": 2, "name": "Soil_Dirt", "support": 15}, {"x": 7, "y": -1, "z": 2, "name": "Soil_Dirt"}, {"x": 7, "y": 0, "z": 2, "name": "Soil_Grass"}, {"x": 7, "y": 5, "z": 2, "name": "Wood_Ash_Trunk_Full"}, {"x": 7, "y": 6, "z": 2, "name": "Wood_Ash_Trunk", "support": 15}, {"x": 7, "y": 7, "z": 2, "name": "Wood_Ash_Trunk", "support": 15}, {"x": 7, "y": 8, "z": 2, "name": "Wood_Ash_Trunk", "support": 15}, {"x": 7, "y": 9, "z": 2, "name": "Wood_Ash_Trunk", "support": 15}, {"x": 7, "y": 10, "z": 2, "name": "Wood_Ash_Trunk", "support": 15}, {"x": 7, "y": 11, "z": 2, "name": "Wood_Ash_Trunk_Full"}, {"x": 7, "y": 25, "z": 2, "name": "Plant_Leaves_Ash"}, {"x": 7, "y": 26, "z": 2, "name": "Plant_Leaves_Ash"}, {"x": 7, "y": 27, "z": 2, "name": "Plant_Leaves_Ash"}, {"x": 7, "y": 28, "z": 2, "name": "Plant_Leaves_Ash"}, {"x": 7, "y": 36, "z": 2, "name": "Plant_Leaves_Ash"}, {"x": 7, "y": 37, "z": 2, "name": "Plant_Leaves_Ash"}, {"x": 7, "y": 38, "z": 2, "name": "Plant_Leaves_Ash"}, {"x": 7, "y": 39, "z": 2, "name": "Plant_Leaves_Ash"}, {"x": 7, "y": 40, "z": 2, "name": "Plant_Leaves_Ash"}, {"x": 7, "y": -3, "z": 3, "name": "Soil_Dirt", "support": 15}, {"x": 7, "y": -2, "z": 3, "name": "Soil_Dirt", "support": 15}, {"x": 7, "y": -1, "z": 3, "name": "Soil_Dirt", "support": 15}, {"x": 7, "y": 0, "z": 3, "name": "Soil_Grass"}, {"x": 7, "y": 5, "z": 3, "name": "Wood_Ash_Trunk_Full"}, {"x": 7, "y": 6, "z": 3, "name": "Wood_Ash_Trunk", "support": 15}, {"x": 7, "y": 7, "z": 3, "name": "Wood_Ash_Trunk", "support": 15}, {"x": 7, "y": 8, "z": 3, "name": "Wood_Ash_Trunk", "support": 15}, {"x": 7, "y": 9, "z": 3, "name": "Wood_Ash_Trunk", "support": 15}, {"x": 7, "y": 10, "z": 3, "name": "Wood_Ash_Trunk", "support": 15}, {"x": 7, "y": 11, "z": 3, "name": "Wood_Ash_Trunk", "support": 15}, {"x": 7, "y": 12, "z": 3, "name": "Wood_Ash_Trunk_Full"}, {"x": 7, "y": 28, "z": 3, "name": "Plant_Leaves_Ash"}, {"x": 7, "y": 29, "z": 3, "name": "Plant_Leaves_Ash"}, {"x": 7, "y": 30, "z": 3, "name": "Plant_Leaves_Ash"}, {"x": 7, "y": 31, "z": 3, "name": "Plant_Leaves_Ash"}, {"x": 7, "y": 36, "z": 3, "name": "Plant_Leaves_Ash"}, {"x": 7, "y": 37, "z": 3, "name": "Wood_Ash_Trunk_Full"}, {"x": 7, "y": 38, "z": 3, "name": "Wood_Ash_Trunk_Full"}, {"x": 7, "y": 39, "z": 3, "name": "Plant_Leaves_Ash"}, {"x": 7, "y": -3, "z": 4, "name": "Soil_Dirt"}, {"x": 7, "y": -2, "z": 4, "name": "Soil_Dirt"}, {"x": 7, "y": -1, "z": 4, "name": "Soil_Dirt"}, {"x": 7, "y": 0, "z": 4, "name": "Soil_Grass"}, {"x": 7, "y": 6, "z": 4, "name": "Wood_Ash_Trunk_Full"}, {"x": 7, "y": 7, "z": 4, "name": "Wood_Ash_Trunk", "support": 15}, {"x": 7, "y": 8, "z": 4, "name": "Wood_Ash_Trunk", "support": 15}, {"x": 7, "y": 9, "z": 4, "name": "Wood_Ash_Trunk", "support": 15}, {"x": 7, "y": 10, "z": 4, "name": "Wood_Ash_Trunk", "support": 15}, {"x": 7, "y": 11, "z": 4, "name": "Wood_Ash_Trunk", "support": 15}, {"x": 7, "y": 12, "z": 4, "name": "Wood_Ash_Trunk_Full"}, {"x": 7, "y": 13, "z": 4, "name": "Plant_Moss_Rug_Green_Dark"}, {"x": 7, "y": 30, "z": 4, "name": "Plant_Leaves_Ash"}, {"x": 7, "y": 31, "z": 4, "name": "Plant_Leaves_Ash"}, {"x": 7, "y": 32, "z": 4, "name": "Plant_Leaves_Ash"}, {"x": 7, "y": 33, "z": 4, "name": "Plant_Leaves_Ash"}, {"x": 7, "y": 34, "z": 4, "name": "Plant_Leaves_Ash"}, {"x": 7, "y": 35, "z": 4, "name": "Plant_Leaves_Ash"}, {"x": 7, "y": 36, "z": 4, "name": "Plant_Leaves_Ash"}, {"x": 7, "y": 37, "z": 4, "name": "Plant_Leaves_Ash"}, {"x": 7, "y": 38, "z": 4, "name": "Plant_Leaves_Ash"}, {"x": 7, "y": 39, "z": 4, "name": "Plant_Leaves_Ash"}, {"x": 7, "y": -3, "z": 5, "name": "Soil_Dirt"}, {"x": 7, "y": -2, "z": 5, "name": "Soil_Dirt"}, {"x": 7, "y": -1, "z": 5, "name": "Soil_Dirt"}, {"x": 7, "y": 0, "z": 5, "name": "Soil_Grass"}, {"x": 7, "y": 7, "z": 5, "name": "Wood_Ash_Trunk_Full"}, {"x": 7, "y": 8, "z": 5, "name": "Wood_Ash_Trunk", "support": 15}, {"x": 7, "y": 9, "z": 5, "name": "Wood_Ash_Trunk", "support": 15}, {"x": 7, "y": 10, "z": 5, "name": "Wood_Ash_Trunk", "support": 15}, {"x": 7, "y": 11, "z": 5, "name": "Wood_Ash_Trunk", "support": 15}, {"x": 7, "y": 12, "z": 5, "name": "Wood_Ash_Trunk_Full"}, {"x": 7, "y": 13, "z": 5, "name": "Plant_Moss_Rug_Green_Dark"}, {"x": 7, "y": 37, "z": 5, "name": "Plant_Leaves_Ash"}, {"x": 7, "y": 38, "z": 5, "name": "Plant_Leaves_Ash"}, {"x": 7, "y": -3, "z": 6, "name": "Soil_Dirt"}, {"x": 7, "y": -2, "z": 6, "name": "Soil_Dirt"}, {"x": 7, "y": -1, "z": 6, "name": "Soil_Dirt"}, {"x": 7, "y": 0, "z": 6, "name": "Soil_Grass"}, {"x": 7, "y": 39, "z": 6, "name": "Plant_Leaves_Ash"}, {"x": 7, "y": -3, "z": 7, "name": "Soil_Dirt"}, {"x": 7, "y": -2, "z": 7, "name": "Soil_Dirt"}, {"x": 7, "y": -1, "z": 7, "name": "Soil_Dirt"}, {"x": 7, "y": 0, "z": 7, "name": "Soil_Grass"}, {"x": 7, "y": -3, "z": 8, "name": "Soil_Dirt"}, {"x": 7, "y": -2, "z": 8, "name": "Soil_Dirt"}, {"x": 7, "y": -1, "z": 8, "name": "Soil_Dirt"}, {"x": 7, "y": 0, "z": 8, "name": "Soil_Grass"}, {"x": 7, "y": -3, "z": 9, "name": "Soil_Dirt"}, {"x": 7, "y": -2, "z": 9, "name": "Soil_Dirt"}, {"x": 7, "y": -1, "z": 9, "name": "Soil_Dirt"}, {"x": 7, "y": 0, "z": 9, "name": "Soil_Grass"}, {"x": 7, "y": -3, "z": 10, "name": "Soil_Dirt"}, {"x": 7, "y": -2, "z": 10, "name": "Soil_Dirt"}, {"x": 7, "y": -1, "z": 10, "name": "Soil_Dirt"}, {"x": 7, "y": 0, "z": 10, "name": "Soil_Grass"}, {"x": 7, "y": 7, "z": 10, "name": "Wood_Ash_Trunk_Full"}, {"x": 7, "y": 8, "z": 10, "name": "Wood_Ash_Trunk_Full"}, {"x": 7, "y": -3, "z": 11, "name": "Soil_Dirt"}, {"x": 7, "y": -2, "z": 11, "name": "Soil_Dirt"}, {"x": 7, "y": -1, "z": 11, "name": "Soil_Dirt"}, {"x": 7, "y": 0, "z": 11, "name": "Soil_Grass"}, {"x": 7, "y": 6, "z": 11, "name": "Wood_Ash_Trunk_Full"}, {"x": 7, "y": 7, "z": 11, "name": "Wood_Ash_Trunk", "support": 15}, {"x": 7, "y": 8, "z": 11, "name": "Wood_Ash_Trunk_Full"}, {"x": 7, "y": -3, "z": 12, "name": "Soil_Dirt"}, {"x": 7, "y": -2, "z": 12, "name": "Soil_Dirt"}, {"x": 7, "y": -1, "z": 12, "name": "Soil_Dirt"}, {"x": 7, "y": 0, "z": 12, "name": "Soil_Grass"}, {"x": 7, "y": -3, "z": 13, "name": "Soil_Dirt"}, {"x": 7, "y": -2, "z": 13, "name": "Soil_Dirt"}, {"x": 7, "y": -1, "z": 13, "name": "Soil_Dirt"}, {"x": 7, "y": 0, "z": 13, "name": "Soil_Grass", "support": 15}, {"x": 7, "y": -3, "z": 14, "name": "Soil_Dirt"}, {"x": 7, "y": -2, "z": 14, "name": "Soil_Dirt"}, {"x": 7, "y": -1, "z": 14, "name": "Soil_Dirt", "support": 15}, {"x": 7, "y": 0, "z": 14, "name": "Soil_Grass", "support": 15}, {"x": 7, "y": -3, "z": 15, "name": "Soil_Dirt", "support": 15}, {"x": 7, "y": -2, "z": 15, "name": "Soil_Dirt", "support": 15}, {"x": 7, "y": -1, "z": 15, "name": "Soil_Dirt", "support": 15}, {"x": 7, "y": 0, "z": 15, "name": "Soil_Grass"}, {"x": 7, "y": -3, "z": 16, "name": "Soil_Dirt"}, {"x": 7, "y": -2, "z": 16, "name": "Soil_Dirt"}, {"x": 7, "y": -1, "z": 16, "name": "Soil_Dirt"}, {"x": 7, "y": 0, "z": 16, "name": "Soil_Grass"}, {"x": 7, "y": -3, "z": 17, "name": "Soil_Dirt"}, {"x": 7, "y": -2, "z": 17, "name": "Soil_Dirt"}, {"x": 7, "y": -1, "z": 17, "name": "Soil_Dirt"}, {"x": 7, "y": 0, "z": 17, "name": "Soil_Grass"}, {"x": 7, "y": -3, "z": 18, "name": "Soil_Dirt"}, {"x": 7, "y": -2, "z": 18, "name": "Soil_Dirt"}, {"x": 7, "y": -1, "z": 18, "name": "Soil_Dirt"}, {"x": 7, "y": 0, "z": 18, "name": "Soil_Grass"}, {"x": 7, "y": -3, "z": 19, "name": "Soil_Dirt"}, {"x": 7, "y": -2, "z": 19, "name": "Soil_Dirt"}, {"x": 7, "y": -1, "z": 19, "name": "Soil_Dirt"}, {"x": 7, "y": 0, "z": 19, "name": "Soil_Grass"}, {"x": 7, "y": -3, "z": 20, "name": "Soil_Dirt"}, {"x": 7, "y": -2, "z": 20, "name": "Soil_Dirt"}, {"x": 7, "y": -1, "z": 20, "name": "Soil_Dirt"}, {"x": 7, "y": 0, "z": 20, "name": "Soil_Grass"}, {"x": 7, "y": -3, "z": 21, "name": "Wood_Ash_Trunk_Full"}, {"x": 7, "y": -2, "z": 21, "name": "Wood_Ash_Trunk", "support": 15}, {"x": 7, "y": -1, "z": 21, "name": "Wood_Ash_Trunk_Full"}, {"x": 7, "y": 0, "z": 21, "name": "Soil_Grass"}, {"x": 7, "y": -3, "z": 22, "name": "Wood_Ash_Trunk_Full"}, {"x": 7, "y": -2, "z": 22, "name": "Soil_Dirt"}, {"x": 7, "y": -1, "z": 22, "name": "Wood_Ash_Trunk_Full"}, {"x": 7, "y": 0, "z": 22, "name": "Wood_Ash_Trunk", "support": 15}, {"x": 7, "y": 1, "z": 22, "name": "Wood_Ash_Trunk", "support": 15}, {"x": 7, "y": 2, "z": 22, "name": "Wood_Ash_Trunk", "support": 15}, {"x": 7, "y": 3, "z": 22, "name": "Wood_Ash_Trunk_Full"}, {"x": 7, "y": -3, "z": 23, "name": "Soil_Dirt"}, {"x": 7, "y": -2, "z": 23, "name": "Soil_Dirt"}, {"x": 7, "y": -1, "z": 23, "name": "Soil_Dirt"}, {"x": 7, "y": 0, "z": 23, "name": "Wood_Ash_Trunk_Full"}, {"x": 7, "y": 1, "z": 23, "name": "Wood_Ash_Trunk", "support": 15}, {"x": 7, "y": 2, "z": 23, "name": "Wood_Ash_Trunk", "support": 15}, {"x": 7, "y": 3, "z": 23, "name": "Wood_Ash_Trunk", "support": 15}, {"x": 7, "y": 4, "z": 23, "name": "Wood_Ash_Trunk_Full"}, {"x": 7, "y": -3, "z": 24, "name": "Soil_Dirt"}, {"x": 7, "y": -2, "z": 24, "name": "Soil_Dirt"}, {"x": 7, "y": -1, "z": 24, "name": "Soil_Dirt"}, {"x": 7, "y": 0, "z": 24, "name": "Soil_Dirt"}, {"x": 7, "y": 1, "z": 24, "name": "Wood_Ash_Trunk_Full"}, {"x": 7, "y": 2, "z": 24, "name": "Wood_Ash_Trunk", "support": 15}, {"x": 7, "y": 3, "z": 24, "name": "Wood_Ash_Trunk", "support": 15}, {"x": 7, "y": 4, "z": 24, "name": "Wood_Ash_Trunk", "support": 15}, {"x": 7, "y": 5, "z": 24, "name": "Wood_Ash_Trunk", "support": 15}, {"x": 7, "y": 6, "z": 24, "name": "Wood_Ash_Trunk", "support": 15}, {"x": 7, "y": 7, "z": 24, "name": "Wood_Ash_Trunk_Full"}, {"x": 7, "y": -3, "z": 25, "name": "Soil_Dirt"}, {"x": 7, "y": -2, "z": 25, "name": "Soil_Dirt"}, {"x": 7, "y": -1, "z": 25, "name": "Soil_Dirt"}, {"x": 7, "y": 0, "z": 25, "name": "Wood_Ash_Trunk_Full"}, {"x": 7, "y": 1, "z": 25, "name": "Wood_Ash_Trunk", "support": 15}, {"x": 7, "y": 2, "z": 25, "name": "Wood_Ash_Trunk", "support": 15}, {"x": 7, "y": 3, "z": 25, "name": "Wood_Ash_Trunk", "support": 15}, {"x": 7, "y": 4, "z": 25, "name": "Wood_Ash_Trunk", "support": 15}, {"x": 7, "y": 5, "z": 25, "name": "Wood_Ash_Trunk_Full"}, {"x": 7, "y": 8, "z": 25, "name": "Plant_Moss_Wall_Green_Dark", "rotation": 3}, {"x": 7, "y": -3, "z": 26, "name": "Soil_Dirt"}, {"x": 7, "y": -2, "z": 26, "name": "Wood_Ash_Trunk_Full"}, {"x": 7, "y": -1, "z": 26, "name": "Wood_Ash_Trunk", "support": 15}, {"x": 7, "y": 0, "z": 26, "name": "Wood_Ash_Trunk", "support": 15}, {"x": 7, "y": 1, "z": 26, "name": "Wood_Ash_Trunk", "support": 15}, {"x": 7, "y": 2, "z": 26, "name": "Wood_Ash_Trunk", "support": 15}, {"x": 7, "y": 3, "z": 26, "name": "Wood_Ash_Trunk_Full"}, {"x": 7, "y": -3, "z": 27, "name": "Wood_Ash_Trunk_Full"}, {"x": 7, "y": -2, "z": 27, "name": "Wood_Ash_Trunk", "support": 15}, {"x": 7, "y": -1, "z": 27, "name": "Wood_Ash_Trunk", "support": 15}, {"x": 7, "y": 0, "z": 27, "name": "Wood_Ash_Trunk", "support": 15}, {"x": 7, "y": 1, "z": 27, "name": "Wood_Ash_Trunk", "support": 15}, {"x": 7, "y": 2, "z": 27, "name": "Wood_Ash_Trunk_Full"}, {"x": 7, "y": -3, "z": 28, "name": "Wood_Ash_Trunk_Full"}, {"x": 7, "y": -2, "z": 28, "name": "Wood_Ash_Trunk", "support": 15}, {"x": 7, "y": -1, "z": 28, "name": "Wood_Ash_Trunk", "support": 15}, {"x": 7, "y": 0, "z": 28, "name": "Wood_Ash_Trunk_Full"}, {"x": 7, "y": -3, "z": 29, "name": "Soil_Dirt"}, {"x": 7, "y": -2, "z": 29, "name": "Soil_Dirt"}, {"x": 7, "y": -1, "z": 29, "name": "Soil_Dirt"}, {"x": 7, "y": 0, "z": 29, "name": "Soil_Grass"}, {"x": 7, "y": -3, "z": 30, "name": "Soil_Dirt"}, {"x": 7, "y": -2, "z": 30, "name": "Soil_Dirt"}, {"x": 7, "y": -1, "z": 30, "name": "Soil_Dirt"}, {"x": 7, "y": 0, "z": 30, "name": "Soil_Grass"}, {"x": 7, "y": -3, "z": 31, "name": "Soil_Dirt"}, {"x": 7, "y": -2, "z": 31, "name": "Soil_Dirt"}, {"x": 7, "y": -1, "z": 31, "name": "Soil_Dirt"}, {"x": 7, "y": 0, "z": 31, "name": "Soil_Grass"}, {"x": 8, "y": -3, "z": 0, "name": "Soil_Dirt"}, {"x": 8, "y": -2, "z": 0, "name": "Soil_Dirt"}, {"x": 8, "y": -1, "z": 0, "name": "Soil_Dirt"}, {"x": 8, "y": 0, "z": 0, "name": "Soil_Grass"}, {"x": 8, "y": 9, "z": 0, "name": "Wood_Ash_Trunk_Full"}, {"x": 8, "y": 10, "z": 0, "name": "Wood_Ash_Trunk_Full"}, {"x": 8, "y": 31, "z": 0, "name": "Plant_Leaves_Ash"}, {"x": 8, "y": 32, "z": 0, "name": "Plant_Leaves_Ash"}, {"x": 8, "y": 33, "z": 0, "name": "Plant_Leaves_Ash"}, {"x": 8, "y": 34, "z": 0, "name": "Plant_Leaves_Ash"}, {"x": 8, "y": 35, "z": 0, "name": "Plant_Leaves_Ash"}, {"x": 8, "y": 36, "z": 0, "name": "Plant_Leaves_Ash"}, {"x": 8, "y": 38, "z": 0, "name": "Wood_Ash_Trunk_Full"}, {"x": 8, "y": 39, "z": 0, "name": "Wood_Ash_Trunk_Full"}, {"x": 8, "y": 40, "z": 0, "name": "Plant_Leaves_Ash"}, {"x": 8, "y": 42, "z": 0, "name": "Wood_Ash_Trunk", "rotation": 4}, {"x": 8, "y": -3, "z": 1, "name": "Soil_Dirt"}, {"x": 8, "y": -2, "z": 1, "name": "Soil_Dirt"}, {"x": 8, "y": -1, "z": 1, "name": "Soil_Dirt"}, {"x": 8, "y": 0, "z": 1, "name": "Soil_Grass"}, {"x": 8, "y": 8, "z": 1, "name": "Wood_Ash_Trunk_Full"}, {"x": 8, "y": 9, "z": 1, "name": "Wood_Ash_Trunk", "support": 15}, {"x": 8, "y": 10, "z": 1, "name": "Wood_Ash_Trunk_Full"}, {"x": 8, "y": 39, "z": 1, "name": "Plant_Leaves_Ash"}, {"x": 8, "y": 40, "z": 1, "name": "Plant_Leaves_Ash"}, {"x": 8, "y": -3, "z": 2, "name": "Soil_Dirt", "support": 15}, {"x": 8, "y": -2, "z": 2, "name": "Soil_Dirt"}, {"x": 8, "y": -1, "z": 2, "name": "Soil_Dirt"}, {"x": 8, "y": 0, "z": 2, "name": "Soil_Grass"}, {"x": 8, "y": 5, "z": 2, "name": "Wood_Ash_Roots"}, {"x": 8, "y": 6, "z": 2, "name": "Wood_Ash_Trunk", "support": 15}, {"x": 8, "y": 7, "z": 2, "name": "Wood_Ash_Trunk", "support": 15}, {"x": 8, "y": 8, "z": 2, "name": "Wood_Ash_Trunk", "support": 15}, {"x": 8, "y": 9, "z": 2, "name": "Wood_Ash_Trunk", "support": 15}, {"x": 8, "y": 10, "z": 2, "name": "Wood_Ash_Trunk", "support": 15}, {"x": 8, "y": 11, "z": 2, "name": "Wood_Ash_Trunk_Full"}, {"x": 8, "y": 39, "z": 2, "name": "Plant_Leaves_Ash"}, {"x": 8, "y": 40, "z": 2, "name": "Plant_Leaves_Ash"}, {"x": 8, "y": -3, "z": 3, "name": "Soil_Dirt", "support": 15}, {"x": 8, "y": -2, "z": 3, "name": "Soil_Dirt", "support": 15}, {"x": 8, "y": -1, "z": 3, "name": "Soil_Dirt"}, {"x": 8, "y": 0, "z": 3, "name": "Soil_Grass"}, {"x": 8, "y": 7, "z": 3, "name": "Wood_Ash_Trunk_Full"}, {"x": 8, "y": 8, "z": 3, "name": "Wood_Ash_Trunk", "support": 15}, {"x": 8, "y": 9, "z": 3, "name": "Wood_Ash_Trunk", "support": 15}, {"x": 8, "y": 10, "z": 3, "name": "Wood_Ash_Trunk", "support": 15}, {"x": 8, "y": 11, "z": 3, "name": "Wood_Ash_Trunk", "support": 15}, {"x": 8, "y": 12, "z": 3, "name": "Wood_Ash_Trunk_Full"}, {"x": 8, "y": 13, "z": 3, "name": "Plant_Moss_Rug_Green_Dark"}, {"x": 8, "y": 38, "z": 3, "name": "Wood_Ash_Trunk_Full"}, {"x": 8, "y": 39, "z": 3, "name": "Plant_Leaves_Ash"}, {"x": 8, "y": 40, "z": 3, "name": "Plant_Leaves_Ash"}, {"x": 8, "y": 41, "z": 3, "name": "Plant_Leaves_Ash"}, {"x": 8, "y": -3, "z": 4, "name": "Soil_Dirt"}, {"x": 8, "y": -2, "z": 4, "name": "Soil_Dirt"}, {"x": 8, "y": -1, "z": 4, "name": "Soil_Dirt"}, {"x": 8, "y": 0, "z": 4, "name": "Soil_Grass"}, {"x": 8, "y": 8, "z": 4, "name": "Wood_Ash_Trunk_Full"}, {"x": 8, "y": 9, "z": 4, "name": "Wood_Ash_Trunk", "support": 15}, {"x": 8, "y": 10, "z": 4, "name": "Wood_Ash_Trunk", "support": 15}, {"x": 8, "y": 11, "z": 4, "name": "Wood_Ash_Trunk", "support": 15}, {"x": 8, "y": 12, "z": 4, "name": "Wood_Ash_Trunk", "support": 15}, {"x": 8, "y": 13, "z": 4, "name": "Wood_Ash_Trunk_Full"}, {"x": 8, "y": 14, "z": 4, "name": "Plant_Moss_Rug_Green_Dark"}, {"x": 8, "y": 39, "z": 4, "name": "Plant_Leaves_Ash"}, {"x": 8, "y": 40, "z": 4, "name": "Plant_Leaves_Ash"}, {"x": 8, "y": -3, "z": 5, "name": "Soil_Dirt"}, {"x": 8, "y": -2, "z": 5, "name": "Soil_Dirt"}, {"x": 8, "y": -1, "z": 5, "name": "Soil_Dirt"}, {"x": 8, "y": 0, "z": 5, "name": "Soil_Grass"}, {"x": 8, "y": 8, "z": 5, "name": "Wood_Ash_Trunk_Full"}, {"x": 8, "y": 9, "z": 5, "name": "Wood_Ash_Trunk", "support": 15}, {"x": 8, "y": 10, "z": 5, "name": "Wood_Ash_Trunk", "support": 15}, {"x": 8, "y": 11, "z": 5, "name": "Wood_Ash_Trunk", "support": 15}, {"x": 8, "y": 12, "z": 5, "name": "Wood_Ash_Trunk", "support": 15}, {"x": 8, "y": 13, "z": 5, "name": "Wood_Ash_Trunk_Full"}, {"x": 8, "y": 14, "z": 5, "name": "Plant_Moss_Rug_Green_Dark"}, {"x": 8, "y": 36, "z": 5, "name": "Plant_Leaves_Ash"}, {"x": 8, "y": 37, "z": 5, "name": "Plant_Leaves_Ash"}, {"x": 8, "y": 38, "z": 5, "name": "Plant_Leaves_Ash"}, {"x": 8, "y": -3, "z": 6, "name": "Soil_Dirt"}, {"x": 8, "y": -2, "z": 6, "name": "Soil_Dirt"}, {"x": 8, "y": -1, "z": 6, "name": "Soil_Dirt"}, {"x": 8, "y": 0, "z": 6, "name": "Soil_Grass"}, {"x": 8, "y": 10, "z": 6, "name": "Wood_Ash_Trunk_Full"}, {"x": 8, "y": 11, "z": 6, "name": "Wood_Ash_Trunk", "support": 15}, {"x": 8, "y": 12, "z": 6, "name": "Wood_Ash_Trunk_Full"}, {"x": 8, "y": 36, "z": 6, "name": "Plant_Leaves_Ash"}, {"x": 8, "y": 39, "z": 6, "name": "Plant_Leaves_Ash"}, {"x": 8, "y": 40, "z": 6, "name": "Plant_Leaves_Ash"}, {"x": 8, "y": -3, "z": 7, "name": "Soil_Dirt"}, {"x": 8, "y": -2, "z": 7, "name": "Soil_Dirt"}, {"x": 8, "y": -1, "z": 7, "name": "Soil_Dirt"}, {"x": 8, "y": 0, "z": 7, "name": "Soil_Grass"}, {"x": 8, "y": 39, "z": 7, "name": "Plant_Leaves_Ash"}, {"x": 8, "y": -3, "z": 8, "name": "Soil_Dirt"}, {"x": 8, "y": -2, "z": 8, "name": "Soil_Dirt"}, {"x": 8, "y": -1, "z": 8, "name": "Soil_Dirt"}, {"x": 8, "y": 0, "z": 8, "name": "Soil_Grass"}, {"x": 8, "y": 9, "z": 8, "name": "Wood_Ash_Trunk_Full"}, {"x": 8, "y": 10, "z": 8, "name": "Wood_Ash_Trunk_Full"}, {"x": 8, "y": -3, "z": 9, "name": "Soil_Dirt"}, {"x": 8, "y": -2, "z": 9, "name": "Soil_Dirt"}, {"x": 8, "y": -1, "z": 9, "name": "Soil_Dirt"}, {"x": 8, "y": 0, "z": 9, "name": "Soil_Grass"}, {"x": 8, "y": 7, "z": 9, "name": "Wood_Ash_Roots"}, {"x": 8, "y": 8, "z": 9, "name": "Wood_Ash_Trunk_Full"}, {"x": 8, "y": 9, "z": 9, "name": "Wood_Ash_Trunk_Full"}, {"x": 8, "y": -3, "z": 10, "name": "Soil_Dirt"}, {"x": 8, "y": -2, "z": 10, "name": "Soil_Dirt"}, {"x": 8, "y": -1, "z": 10, "name": "Soil_Dirt"}, {"x": 8, "y": 0, "z": 10, "name": "Soil_Grass"}, {"x": 8, "y": 8, "z": 10, "name": "Wood_Ash_Trunk_Full"}, {"x": 8, "y": -3, "z": 11, "name": "Soil_Dirt"}, {"x": 8, "y": -2, "z": 11, "name": "Soil_Dirt"}, {"x": 8, "y": -1, "z": 11, "name": "Soil_Dirt"}, {"x": 8, "y": 0, "z": 11, "name": "Soil_Grass"}, {"x": 8, "y": -3, "z": 12, "name": "Soil_Dirt"}, {"x": 8, "y": -2, "z": 12, "name": "Soil_Dirt"}, {"x": 8, "y": -1, "z": 12, "name": "Soil_Dirt"}, {"x": 8, "y": 0, "z": 12, "name": "Soil_Grass"}, {"x": 8, "y": -3, "z": 13, "name": "Soil_Dirt"}, {"x": 8, "y": -2, "z": 13, "name": "Soil_Dirt"}, {"x": 8, "y": -1, "z": 13, "name": "Soil_Dirt"}, {"x": 8, "y": 0, "z": 13, "name": "Soil_Grass"}, {"x": 8, "y": -3, "z": 14, "name": "Soil_Dirt"}, {"x": 8, "y": -2, "z": 14, "name": "Soil_Dirt"}, {"x": 8, "y": -1, "z": 14, "name": "Soil_Dirt"}, {"x": 8, "y": 0, "z": 14, "name": "Soil_Grass"}, {"x": 8, "y": -3, "z": 15, "name": "Soil_Dirt"}, {"x": 8, "y": -2, "z": 15, "name": "Soil_Dirt"}, {"x": 8, "y": -1, "z": 15, "name": "Soil_Dirt"}, {"x": 8, "y": 0, "z": 15, "name": "Soil_Grass"}, {"x": 8, "y": -3, "z": 16, "name": "Soil_Dirt"}, {"x": 8, "y": -2, "z": 16, "name": "Soil_Dirt"}, {"x": 8, "y": -1, "z": 16, "name": "Soil_Dirt"}, {"x": 8, "y": 0, "z": 16, "name": "Soil_Grass"}, {"x": 8, "y": -3, "z": 17, "name": "Soil_Dirt"}, {"x": 8, "y": -2, "z": 17, "name": "Soil_Dirt"}, {"x": 8, "y": -1, "z": 17, "name": "Soil_Dirt"}, {"x": 8, "y": 0, "z": 17, "name": "Soil_Grass"}, {"x": 8, "y": -3, "z": 18, "name": "Soil_Dirt"}, {"x": 8, "y": -2, "z": 18, "name": "Soil_Dirt"}, {"x": 8, "y": -1, "z": 18, "name": "Soil_Dirt"}, {"x": 8, "y": 0, "z": 18, "name": "Soil_Grass"}, {"x": 8, "y": -3, "z": 19, "name": "Soil_Dirt"}, {"x": 8, "y": -2, "z": 19, "name": "Soil_Dirt"}, {"x": 8, "y": -1, "z": 19, "name": "Soil_Dirt"}, {"x": 8, "y": 0, "z": 19, "name": "Soil_Grass"}, {"x": 8, "y": -3, "z": 20, "name": "Soil_Dirt"}, {"x": 8, "y": -2, "z": 20, "name": "Soil_Dirt"}, {"x": 8, "y": -1, "z": 20, "name": "Soil_Dirt"}, {"x": 8, "y": 0, "z": 20, "name": "Soil_Grass"}, {"x": 8, "y": -3, "z": 21, "name": "Soil_Dirt"}, {"x": 8, "y": -2, "z": 21, "name": "Soil_Dirt"}, {"x": 8, "y": -1, "z": 21, "name": "Wood_Ash_Trunk_Full"}, {"x": 8, "y": 0, "z": 21, "name": "Wood_Ash_Trunk_Full"}, {"x": 8, "y": -3, "z": 22, "name": "Soil_Dirt"}, {"x": 8, "y": -2, "z": 22, "name": "Wood_Ash_Trunk_Full"}, {"x": 8, "y": -1, "z": 22, "name": "Wood_Ash_Trunk", "support": 15}, {"x": 8, "y": 0, "z": 22, "name": "Wood_Ash_Trunk", "support": 15}, {"x": 8, "y": 1, "z": 22, "name": "Wood_Ash_Trunk_Full"}, {"x": 8, "y": -3, "z": 23, "name": "Soil_Dirt"}, {"x": 8, "y": -2, "z": 23, "name": "Soil_Dirt"}, {"x": 8, "y": -1, "z": 23, "name": "Wood_Ash_Trunk_Full"}, {"x": 8, "y": 0, "z": 23, "name": "Wood_Ash_Trunk", "support": 15}, {"x": 8, "y": 1, "z": 23, "name": "Wood_Ash_Trunk", "support": 15}, {"x": 8, "y": 2, "z": 23, "name": "Wood_Ash_Trunk", "support": 15}, {"x": 8, "y": 3, "z": 23, "name": "Wood_Ash_Trunk", "support": 15}, {"x": 8, "y": 4, "z": 23, "name": "Wood_Ash_Trunk", "support": 15}, {"x": 8, "y": 5, "z": 23, "name": "Wood_Ash_Trunk", "support": 15}, {"x": 8, "y": 6, "z": 23, "name": "Wood_Ash_Trunk", "support": 15}, {"x": 8, "y": 7, "z": 23, "name": "Wood_Ash_Trunk_Full"}, {"x": 8, "y": -3, "z": 24, "name": "Soil_Dirt"}, {"x": 8, "y": -2, "z": 24, "name": "Soil_Dirt"}, {"x": 8, "y": -1, "z": 24, "name": "Soil_Dirt"}, {"x": 8, "y": 0, "z": 24, "name": "Soil_Dirt"}, {"x": 8, "y": 1, "z": 24, "name": "Wood_Ash_Trunk_Full"}, {"x": 8, "y": 3, "z": 24, "name": "Wood_Ash_Trunk_Full"}, {"x": 8, "y": 4, "z": 24, "name": "Wood_Ash_Trunk", "support": 15}, {"x": 8, "y": 5, "z": 24, "name": "Wood_Ash_Trunk", "support": 15}, {"x": 8, "y": 6, "z": 24, "name": "Wood_Ash_Trunk", "support": 15}, {"x": 8, "y": 7, "z": 24, "name": "Wood_Ash_Trunk", "support": 15}, {"x": 8, "y": 8, "z": 24, "name": "Wood_Ash_Trunk_Full"}, {"x": 8, "y": -3, "z": 25, "name": "Soil_Dirt"}, {"x": 8, "y": -2, "z": 25, "name": "Soil_Dirt"}, {"x": 8, "y": -1, "z": 25, "name": "Soil_Dirt"}, {"x": 8, "y": 0, "z": 25, "name": "Soil_Grass"}, {"x": 8, "y": 2, "z": 25, "name": "Wood_Ash_Trunk_Full"}, {"x": 8, "y": 3, "z": 25, "name": "Wood_Ash_Trunk", "support": 15}, {"x": 8, "y": 4, "z": 25, "name": "Wood_Ash_Trunk", "support": 15}, {"x": 8, "y": 5, "z": 25, "name": "Wood_Ash_Trunk", "support": 15}, {"x": 8, "y": 6, "z": 25, "name": "Wood_Ash_Trunk", "support": 15}, {"x": 8, "y": 7, "z": 25, "name": "Wood_Ash_Trunk", "support": 15}, {"x": 8, "y": 8, "z": 25, "name": "Wood_Ash_Trunk_Full"}, {"x": 8, "y": 9, "z": 25, "name": "Plant_Moss_Rug_Green_Dark"}, {"x": 8, "y": -3, "z": 26, "name": "Soil_Dirt"}, {"x": 8, "y": -2, "z": 26, "name": "Soil_Dirt"}, {"x": 8, "y": -1, "z": 26, "name": "Soil_Dirt"}, {"x": 8, "y": 0, "z": 26, "name": "Wood_Ash_Trunk_Full"}, {"x": 8, "y": 1, "z": 26, "name": "Wood_Ash_Trunk", "support": 15}, {"x": 8, "y": 2, "z": 26, "name": "Wood_Ash_Trunk_Full"}, {"x": 8, "y": 7, "z": 26, "name": "Wood_Ash_Trunk_Full"}, {"x": 8, "y": -3, "z": 27, "name": "Soil_Dirt"}, {"x": 8, "y": -2, "z": 27, "name": "Wood_Ash_Trunk_Full"}, {"x": 8, "y": -1, "z": 27, "name": "Wood_Ash_Trunk", "support": 15}, {"x": 8, "y": 0, "z": 27, "name": "Wood_Ash_Trunk", "support": 15}, {"x": 8, "y": 1, "z": 27, "name": "Wood_Ash_Trunk_Full"}, {"x": 8, "y": -3, "z": 28, "name": "Soil_Dirt"}, {"x": 8, "y": -2, "z": 28, "name": "Soil_Dirt"}, {"x": 8, "y": -1, "z": 28, "name": "Soil_Dirt"}, {"x": 8, "y": 0, "z": 28, "name": "Soil_Grass"}, {"x": 8, "y": -3, "z": 29, "name": "Soil_Dirt"}, {"x": 8, "y": -2, "z": 29, "name": "Soil_Dirt"}, {"x": 8, "y": -1, "z": 29, "name": "Soil_Dirt"}, {"x": 8, "y": 0, "z": 29, "name": "Soil_Grass"}, {"x": 8, "y": -3, "z": 30, "name": "Soil_Dirt"}, {"x": 8, "y": -2, "z": 30, "name": "Soil_Dirt"}, {"x": 8, "y": -1, "z": 30, "name": "Soil_Dirt"}, {"x": 8, "y": 0, "z": 30, "name": "Soil_Grass"}, {"x": 8, "y": -3, "z": 31, "name": "Soil_Dirt"}, {"x": 8, "y": -2, "z": 31, "name": "Soil_Dirt"}, {"x": 8, "y": -1, "z": 31, "name": "Soil_Dirt"}, {"x": 8, "y": 0, "z": 31, "name": "Soil_Grass"}, {"x": 9, "y": -3, "z": 0, "name": "Soil_Dirt"}, {"x": 9, "y": -2, "z": 0, "name": "Soil_Dirt"}, {"x": 9, "y": -1, "z": 0, "name": "Soil_Dirt"}, {"x": 9, "y": 0, "z": 0, "name": "Soil_Grass"}, {"x": 9, "y": 39, "z": 0, "name": "Wood_Ash_Trunk_Full"}, {"x": 9, "y": 40, "z": 0, "name": "Furniture_Kweebec_Platform"}, {"x": 9, "y": 41, "z": 0, "name": "Wood_Hardwood_Planks_Half"}, {"x": 9, "y": -3, "z": 1, "name": "Soil_Dirt"}, {"x": 9, "y": -2, "z": 1, "name": "Soil_Dirt"}, {"x": 9, "y": -1, "z": 1, "name": "Soil_Dirt"}, {"x": 9, "y": 0, "z": 1, "name": "Soil_Grass"}, {"x": 9, "y": 39, "z": 1, "name": "Wood_Ash_Trunk_Full"}, {"x": 9, "y": 40, "z": 1, "name": "Furniture_Kweebec_Platform"}, {"x": 9, "y": -3, "z": 2, "name": "Soil_Dirt"}, {"x": 9, "y": -2, "z": 2, "name": "Soil_Dirt"}, {"x": 9, "y": -1, "z": 2, "name": "Soil_Dirt"}, {"x": 9, "y": 0, "z": 2, "name": "Soil_Grass"}, {"x": 9, "y": 13, "z": 2, "name": "Plant_Moss_Wall_Green_Dark", "rotation": 2}, {"x": 9, "y": 40, "z": 2, "name": "Furniture_Kweebec_Platform"}, {"x": 9, "y": -3, "z": 3, "name": "Soil_Dirt"}, {"x": 9, "y": -2, "z": 3, "name": "Soil_Dirt"}, {"x": 9, "y": -1, "z": 3, "name": "Soil_Dirt"}, {"x": 9, "y": 0, "z": 3, "name": "Soil_Grass"}, {"x": 9, "y": 9, "z": 3, "name": "Wood_Ash_Trunk_Full"}, {"x": 9, "y": 10, "z": 3, "name": "Wood_Ash_Trunk", "support": 15}, {"x": 9, "y": 11, "z": 3, "name": "Wood_Ash_Trunk", "support": 15}, {"x": 9, "y": 12, "z": 3, "name": "Wood_Ash_Trunk", "support": 15}, {"x": 9, "y": 13, "z": 3, "name": "Wood_Ash_Trunk_Full"}, {"x": 9, "y": 14, "z": 3, "name": "Wood_Ash_Trunk_Full", "support": 15}, {"x": 9, "y": 15, "z": 3, "name": "Wood_Ash_Trunk_Full", "support": 15}, {"x": 9, "y": 16, "z": 3, "name": "Furniture_Kweebec_Lantern"}, {"x": 9, "y": 38, "z": 3, "name": "Wood_Ash_Trunk_Full"}, {"x": 9, "y": 39, "z": 3, "name": "Wood_Ash_Trunk_Full"}, {"x": 9, "y": 40, "z": 3, "name": "Plant_Leaves_Ash"}, {"x": 9, "y": -3, "z": 4, "name": "Soil_Dirt"}, {"x": 9, "y": -2, "z": 4, "name": "Soil_Dirt"}, {"x": 9, "y": -1, "z": 4, "name": "Soil_Dirt"}, {"x": 9, "y": 0, "z": 4, "name": "Soil_Grass"}, {"x": 9, "y": 9, "z": 4, "name": "Wood_Ash_Trunk_Full"}, {"x": 9, "y": 10, "z": 4, "name": "Wood_Ash_Trunk", "support": 15}, {"x": 9, "y": 11, "z": 4, "name": "Wood_Ash_Trunk", "support": 15}, {"x": 9, "y": 12, "z": 4, "name": "Wood_Ash_Trunk", "support": 15}, {"x": 9, "y": 13, "z": 4, "name": "Wood_Ash_Trunk_Full"}, {"x": 9, "y": 14, "z": 4, "name": "Wood_Ash_Trunk_Full", "support": 15}, {"x": 9, "y": 15, "z": 4, "name": "Wood_Hardwood_Fence", "rotation": 3}, {"x": 9, "y": 16, "z": 4, "name": "K2_Slot_Barrier"}, {"x": 9, "y": 17, "z": 4, "name": "K2_Slot_Barrier"}, {"x": 9, "y": 18, "z": 4, "name": "K2_Slot_Barrier"}, {"x": 9, "y": 19, "z": 4, "name": "K2_Slot_Barrier"}, {"x": 9, "y": 40, "z": 4, "name": "Plant_Leaves_Ash"}, {"x": 9, "y": 41, "z": 4, "name": "Plant_Leaves_Ash"}, {"x": 9, "y": -3, "z": 5, "name": "Soil_Dirt"}, {"x": 9, "y": -2, "z": 5, "name": "Soil_Dirt"}, {"x": 9, "y": -1, "z": 5, "name": "Soil_Dirt"}, {"x": 9, "y": 0, "z": 5, "name": "Soil_Grass"}, {"x": 9, "y": 9, "z": 5, "name": "Wood_Ash_Roots"}, {"x": 9, "y": 10, "z": 5, "name": "Wood_Ash_Trunk", "support": 15}, {"x": 9, "y": 11, "z": 5, "name": "Wood_Ash_Trunk", "support": 15}, {"x": 9, "y": 12, "z": 5, "name": "Wood_Ash_Trunk", "support": 15}, {"x": 9, "y": 13, "z": 5, "name": "Wood_Ash_Trunk_Full"}, {"x": 9, "y": 14, "z": 5, "name": "Wood_Ash_Trunk_Full", "support": 15}, {"x": 9, "y": 15, "z": 5, "name": "Wood_Hardwood_Fence", "rotation": 3}, {"x": 9, "y": 16, "z": 5, "name": "K2_Slot_Barrier"}, {"x": 9, "y": 17, "z": 5, "name": "K2_Slot_Barrier"}, {"x": 9, "y": 18, "z": 5, "name": "K2_Slot_Barrier"}, {"x": 9, "y": 19, "z": 5, "name": "K2_Slot_Barrier"}, {"x": 9, "y": 37, "z": 5, "name": "Plant_Leaves_Ash"}, {"x": 9, "y": 38, "z": 5, "name": "Plant_Leaves_Ash"}, {"x": 9, "y": 40, "z": 5, "name": "Plant_Leaves_Ash"}, {"x": 9, "y": -3, "z": 6, "name": "Soil_Dirt"}, {"x": 9, "y": -2, "z": 6, "name": "Soil_Dirt"}, {"x": 9, "y": -1, "z": 6, "name": "Soil_Dirt"}, {"x": 9, "y": 0, "z": 6, "name": "Soil_Grass"}, {"x": 9, "y": 10, "z": 6, "name": "Wood_Ash_Trunk_Full"}, {"x": 9, "y": 11, "z": 6, "name": "Wood_Ash_Trunk", "support": 15}, {"x": 9, "y": 12, "z": 6, "name": "Wood_Ash_Trunk", "support": 15}, {"x": 9, "y": 13, "z": 6, "name": "Wood_Ash_Trunk", "support": 15}, {"x": 9, "y": 14, "z": 6, "name": "Wood_Ash_Trunk_Full"}, {"x": 9, "y": 15, "z": 6, "name": "Wood_Hardwood_Fence", "rotation": 3}, {"x": 9, "y": 16, "z": 6, "name": "K2_Slot_Barrier"}, {"x": 9, "y": 17, "z": 6, "name": "K2_Slot_Barrier"}, {"x": 9, "y": 18, "z": 6, "name": "K2_Slot_Barrier"}, {"x": 9, "y": 19, "z": 6, "name": "K2_Slot_Barrier"}, {"x": 9, "y": 37, "z": 6, "name": "Plant_Leaves_Ash"}, {"x": 9, "y": 38, "z": 6, "name": "Plant_Leaves_Ash"}, {"x": 9, "y": 39, "z": 6, "name": "Plant_Leaves_Ash"}, {"x": 9, "y": 40, "z": 6, "name": "Plant_Leaves_Ash"}, {"x": 9, "y": -3, "z": 7, "name": "Soil_Dirt"}, {"x": 9, "y": -2, "z": 7, "name": "Soil_Dirt"}, {"x": 9, "y": -1, "z": 7, "name": "Soil_Dirt"}, {"x": 9, "y": 0, "z": 7, "name": "Soil_Grass"}, {"x": 9, "y": 10, "z": 7, "name": "Wood_Ash_Trunk_Full"}, {"x": 9, "y": 11, "z": 7, "name": "Wood_Ash_Trunk", "support": 15}, {"x": 9, "y": 12, "z": 7, "name": "Wood_Ash_Trunk", "support": 15}, {"x": 9, "y": 13, "z": 7, "name": "Wood_Ash_Trunk_Full"}, {"x": 9, "y": 14, "z": 7, "name": "Wood_Ash_Trunk_Full", "support": 15, "rotation": 4}, {"x": 9, "y": 15, "z": 7, "name": "Wood_Ash_Trunk_Full", "support": 15}, {"x": 9, "y": 16, "z": 7, "name": "Furniture_Kweebec_Lantern"}, {"x": 9, "y": 17, "z": 7, "name": "K2_Slot_Barrier"}, {"x": 9, "y": 18, "z": 7, "name": "K2_Slot_Barrier"}, {"x": 9, "y": 19, "z": 7, "name": "K2_Slot_Barrier"}, {"x": 9, "y": 38, "z": 7, "name": "Plant_Leaves_Ash"}, {"x": 9, "y": 39, "z": 7, "name": "Plant_Leaves_Ash"}, {"x": 9, "y": 40, "z": 7, "name": "Plant_Leaves_Ash"}, {"x": 9, "y": -3, "z": 8, "name": "Soil_Dirt"}, {"x": 9, "y": -2, "z": 8, "name": "Soil_Dirt"}, {"x": 9, "y": -1, "z": 8, "name": "Soil_Dirt"}, {"x": 9, "y": 0, "z": 8, "name": "Soil_Grass"}, {"x": 9, "y": 9, "z": 8, "name": "Wood_Ash_Trunk_Full"}, {"x": 9, "y": 10, "z": 8, "name": "Wood_Ash_Trunk", "support": 15}, {"x": 9, "y": 11, "z": 8, "name": "Wood_Ash_Trunk", "support": 15}, {"x": 9, "y": 12, "z": 8, "name": "Wood_Ash_Trunk_Full"}, {"x": 9, "y": 14, "z": 8, "name": "Wood_Ash_Trunk_Full", "support": 15, "rotation": 4}, {"x": 9, "y": 15, "z": 8, "name": "Wood_Hardwood_Fence", "rotation": 3}, {"x": 9, "y": 16, "z": 8, "name": "K2_Slot_Barrier"}, {"x": 9, "y": 17, "z": 8, "name": "K2_Slot_Barrier"}, {"x": 9, "y": 18, "z": 8, "name": "K2_Slot_Barrier"}, {"x": 9, "y": 19, "z": 8, "name": "K2_Slot_Barrier"}, {"x": 9, "y": 39, "z": 8, "name": "Plant_Leaves_Ash"}, {"x": 9, "y": -3, "z": 9, "name": "Soil_Dirt"}, {"x": 9, "y": -2, "z": 9, "name": "Soil_Dirt"}, {"x": 9, "y": -1, "z": 9, "name": "Soil_Dirt"}, {"x": 9, "y": 0, "z": 9, "name": "Soil_Grass"}, {"x": 9, "y": 9, "z": 9, "name": "Wood_Ash_Trunk_Full"}, {"x": 9, "y": 10, "z": 9, "name": "Wood_Ash_Trunk_Full"}, {"x": 9, "y": 14, "z": 9, "name": "Wood_Ash_Trunk_Full", "support": 15, "rotation": 4}, {"x": 9, "y": 15, "z": 9, "name": "Wood_Ash_Trunk_Full", "support": 15}, {"x": 9, "y": 16, "z": 9, "name": "K2_Slot_Barrier"}, {"x": 9, "y": 17, "z": 9, "name": "K2_Slot_Barrier"}, {"x": 9, "y": 18, "z": 9, "name": "K2_Slot_Barrier"}, {"x": 9, "y": 19, "z": 9, "name": "K2_Slot_Barrier"}, {"x": 9, "y": -3, "z": 10, "name": "Soil_Dirt"}, {"x": 9, "y": -2, "z": 10, "name": "Soil_Dirt"}, {"x": 9, "y": -1, "z": 10, "name": "Soil_Dirt"}, {"x": 9, "y": 0, "z": 10, "name": "Soil_Grass"}, {"x": 9, "y": -3, "z": 11, "name": "Soil_Dirt"}, {"x": 9, "y": -2, "z": 11, "name": "Soil_Dirt"}, {"x": 9, "y": -1, "z": 11, "name": "Soil_Dirt"}, {"x": 9, "y": 0, "z": 11, "name": "Soil_Grass"}, {"x": 9, "y": -3, "z": 12, "name": "Soil_Dirt"}, {"x": 9, "y": -2, "z": 12, "name": "Soil_Dirt"}, {"x": 9, "y": -1, "z": 12, "name": "Soil_Dirt"}, {"x": 9, "y": 0, "z": 12, "name": "Soil_Grass"}, {"x": 9, "y": -3, "z": 13, "name": "Wood_Ash_Trunk", "support": 15}, {"x": 9, "y": -2, "z": 13, "name": "Wood_Ash_Trunk_Full"}, {"x": 9, "y": -1, "z": 13, "name": "Soil_Dirt"}, {"x": 9, "y": 0, "z": 13, "name": "Soil_Grass"}, {"x": 9, "y": -3, "z": 14, "name": "Wood_Ash_Trunk", "support": 15}, {"x": 9, "y": -2, "z": 14, "name": "Wood_Ash_Trunk", "support": 15}, {"x": 9, "y": -1, "z": 14, "name": "Wood_Ash_Trunk_Full"}, {"x": 9, "y": 0, "z": 14, "name": "Soil_Grass", "support": 15}, {"x": 9, "y": -3, "z": 15, "name": "Wood_Ash_Trunk", "support": 15}, {"x": 9, "y": -2, "z": 15, "name": "Wood_Ash_Trunk_Full"}, {"x": 9, "y": -1, "z": 15, "name": "Soil_Dirt", "support": 15}, {"x": 9, "y": 0, "z": 15, "name": "Soil_Grass", "support": 15}, {"x": 9, "y": -3, "z": 16, "name": "Soil_Dirt"}, {"x": 9, "y": -2, "z": 16, "name": "Soil_Dirt"}, {"x": 9, "y": -1, "z": 16, "name": "Soil_Dirt"}, {"x": 9, "y": 0, "z": 16, "name": "Soil_Grass"}, {"x": 9, "y": -3, "z": 17, "name": "Soil_Dirt"}, {"x": 9, "y": -2, "z": 17, "name": "Soil_Dirt"}, {"x": 9, "y": -1, "z": 17, "name": "Soil_Dirt"}, {"x": 9, "y": 0, "z": 17, "name": "Soil_Grass"}, {"x": 9, "y": -3, "z": 18, "name": "Soil_Dirt"}, {"x": 9, "y": -2, "z": 18, "name": "Soil_Dirt"}, {"x": 9, "y": -1, "z": 18, "name": "Soil_Dirt"}, {"x": 9, "y": 0, "z": 18, "name": "Soil_Grass"}, {"x": 9, "y": -3, "z": 19, "name": "Soil_Dirt"}, {"x": 9, "y": -2, "z": 19, "name": "Soil_Dirt"}, {"x": 9, "y": -1, "z": 19, "name": "Soil_Dirt"}, {"x": 9, "y": 0, "z": 19, "name": "Soil_Grass"}, {"x": 9, "y": -3, "z": 20, "name": "Soil_Dirt"}, {"x": 9, "y": -2, "z": 20, "name": "Soil_Dirt"}, {"x": 9, "y": -1, "z": 20, "name": "Soil_Dirt"}, {"x": 9, "y": 0, "z": 20, "name": "Soil_Grass"}, {"x": 9, "y": -3, "z": 21, "name": "Soil_Dirt"}, {"x": 9, "y": -2, "z": 21, "name": "Soil_Dirt"}, {"x": 9, "y": -1, "z": 21, "name": "Soil_Dirt"}, {"x": 9, "y": 0, "z": 21, "name": "Soil_Grass"}, {"x": 9, "y": -3, "z": 22, "name": "Soil_Dirt"}, {"x": 9, "y": -2, "z": 22, "name": "Soil_Dirt"}, {"x": 9, "y": -1, "z": 22, "name": "Wood_Ash_Trunk_Full"}, {"x": 9, "y": 0, "z": 22, "name": "Wood_Ash_Trunk_Full"}, {"x": 9, "y": -3, "z": 23, "name": "Soil_Dirt"}, {"x": 9, "y": -2, "z": 23, "name": "Soil_Dirt"}, {"x": 9, "y": -1, "z": 23, "name": "Soil_Dirt"}, {"x": 9, "y": 0, "z": 23, "name": "Wood_Ash_Trunk_Full"}, {"x": 9, "y": 1, "z": 23, "name": "Wood_Ash_Trunk_Full"}, {"x": 9, "y": -3, "z": 24, "name": "Soil_Dirt"}, {"x": 9, "y": -2, "z": 24, "name": "Soil_Dirt"}, {"x": 9, "y": -1, "z": 24, "name": "Soil_Dirt"}, {"x": 9, "y": 0, "z": 24, "name": "Soil_Grass"}, {"x": 9, "y": 4, "z": 24, "name": "Wood_Ash_Trunk_Full"}, {"x": 9, "y": 5, "z": 24, "name": "Wood_Ash_Trunk", "support": 15}, {"x": 9, "y": 6, "z": 24, "name": "Wood_Ash_Trunk", "support": 15}, {"x": 9, "y": 7, "z": 24, "name": "Wood_Ash_Trunk_Full"}, {"x": 9, "y": 8, "z": 24, "name": "Plant_Moss_Rug_Green_Dark"}, {"x": 9, "y": -3, "z": 25, "name": "Soil_Dirt"}, {"x": 9, "y": -2, "z": 25, "name": "Soil_Dirt"}, {"x": 9, "y": -1, "z": 25, "name": "Soil_Dirt"}, {"x": 9, "y": 0, "z": 25, "name": "Soil_Grass"}, {"x": 9, "y": 5, "z": 25, "name": "Wood_Ash_Trunk_Full"}, {"x": 9, "y": 6, "z": 25, "name": "Wood_Ash_Trunk", "support": 15}, {"x": 9, "y": 7, "z": 25, "name": "Wood_Ash_Trunk", "support": 15}, {"x": 9, "y": 8, "z": 25, "name": "Wood_Ash_Trunk_Full"}, {"x": 9, "y": 9, "z": 25, "name": "Plant_Moss_Rug_Green_Dark"}, {"x": 9, "y": -3, "z": 26, "name": "Soil_Dirt"}, {"x": 9, "y": -2, "z": 26, "name": "Soil_Dirt"}, {"x": 9, "y": -1, "z": 26, "name": "Soil_Dirt"}, {"x": 9, "y": 0, "z": 26, "name": "Soil_Grass"}, {"x": 9, "y": 6, "z": 26, "name": "Wood_Ash_Trunk_Full"}, {"x": 9, "y": 7, "z": 26, "name": "Wood_Ash_Trunk", "support": 15}, {"x": 9, "y": 8, "z": 26, "name": "Wood_Ash_Trunk_Full"}, {"x": 9, "y": -3, "z": 27, "name": "Soil_Dirt"}, {"x": 9, "y": -2, "z": 27, "name": "Soil_Dirt"}, {"x": 9, "y": -1, "z": 27, "name": "Soil_Dirt"}, {"x": 9, "y": 0, "z": 27, "name": "Soil_Grass"}, {"x": 9, "y": -3, "z": 28, "name": "Soil_Dirt"}, {"x": 9, "y": -2, "z": 28, "name": "Soil_Dirt"}, {"x": 9, "y": -1, "z": 28, "name": "Soil_Dirt"}, {"x": 9, "y": 0, "z": 28, "name": "Soil_Grass"}, {"x": 9, "y": -3, "z": 29, "name": "Soil_Dirt"}, {"x": 9, "y": -2, "z": 29, "name": "Soil_Dirt"}, {"x": 9, "y": -1, "z": 29, "name": "Soil_Dirt"}, {"x": 9, "y": 0, "z": 29, "name": "Soil_Grass"}, {"x": 9, "y": -3, "z": 30, "name": "Soil_Dirt"}, {"x": 9, "y": -2, "z": 30, "name": "Soil_Dirt"}, {"x": 9, "y": -1, "z": 30, "name": "Soil_Dirt"}, {"x": 9, "y": 0, "z": 30, "name": "Soil_Grass"}, {"x": 9, "y": -3, "z": 31, "name": "Soil_Dirt"}, {"x": 9, "y": -2, "z": 31, "name": "Soil_Dirt"}, {"x": 9, "y": -1, "z": 31, "name": "Soil_Dirt"}, {"x": 9, "y": 0, "z": 31, "name": "Soil_Grass"}, {"x": 10, "y": -3, "z": 0, "name": "Wood_Ash_Trunk", "support": 15}, {"x": 10, "y": -2, "z": 0, "name": "Wood_Ash_Trunk_Full"}, {"x": 10, "y": -1, "z": 0, "name": "Soil_Dirt"}, {"x": 10, "y": 0, "z": 0, "name": "Soil_Grass"}, {"x": 10, "y": 40, "z": 0, "name": "Furniture_Kweebec_Platform"}, {"x": 10, "y": 41, "z": 0, "name": "Wood_Hardwood_Planks_Half"}, {"x": 10, "y": -3, "z": 1, "name": "Soil_Dirt"}, {"x": 10, "y": -2, "z": 1, "name": "Soil_Dirt"}, {"x": 10, "y": -1, "z": 1, "name": "Soil_Dirt"}, {"x": 10, "y": 0, "z": 1, "name": "Soil_Grass"}, {"x": 10, "y": 39, "z": 1, "name": "Wood_Ash_Trunk_Full"}, {"x": 10, "y": 40, "z": 1, "name": "Wood_Ash_Trunk_Full"}, {"x": 10, "y": 41, "z": 1, "name": "Wood_Hardwood_Planks_Half"}, {"x": 10, "y": -3, "z": 2, "name": "Soil_Dirt"}, {"x": 10, "y": -2, "z": 2, "name": "Soil_Dirt"}, {"x": 10, "y": -1, "z": 2, "name": "Soil_Dirt"}, {"x": 10, "y": 0, "z": 2, "name": "Soil_Grass"}, {"x": 10, "y": 39, "z": 2, "name": "Wood_Ash_Trunk_Full"}, {"x": 10, "y": 40, "z": 2, "name": "Furniture_Kweebec_Platform", "rotation": 1}, {"x": 10, "y": -3, "z": 3, "name": "Soil_Dirt"}, {"x": 10, "y": -2, "z": 3, "name": "Soil_Dirt"}, {"x": 10, "y": -1, "z": 3, "name": "Soil_Dirt"}, {"x": 10, "y": 0, "z": 3, "name": "Soil_Grass"}, {"x": 10, "y": 10, "z": 3, "name": "Wood_Ash_Trunk_Full"}, {"x": 10, "y": 11, "z": 3, "name": "Wood_Ash_Trunk", "support": 15}, {"x": 10, "y": 12, "z": 3, "name": "Wood_Ash_Trunk", "support": 15}, {"x": 10, "y": 13, "z": 3, "name": "Wood_Ash_Trunk_Full"}, {"x": 10, "y": 14, "z": 3, "name": "Wood_Ash_Trunk_Full", "support": 15, "rotation": 5}, {"x": 10, "y": 15, "z": 3, "name": "Wood_Hardwood_Fence", "rotation": 2}, {"x": 10, "y": 16, "z": 3, "name": "K2_Slot_Barrier"}, {"x": 10, "y": 17, "z": 3, "name": "K2_Slot_Barrier"}, {"x": 10, "y": 18, "z": 3, "name": "K2_Slot_Barrier"}, {"x": 10, "y": 39, "z": 3, "name": "Wood_Ash_Trunk_Full"}, {"x": 10, "y": -3, "z": 4, "name": "Soil_Dirt"}, {"x": 10, "y": -2, "z": 4, "name": "Soil_Dirt"}, {"x": 10, "y": -1, "z": 4, "name": "Soil_Dirt"}, {"x": 10, "y": 0, "z": 4, "name": "Soil_Grass"}, {"x": 10, "y": 9, "z": 4, "name": "Wood_Ash_Roots"}, {"x": 10, "y": 10, "z": 4, "name": "Wood_Ash_Trunk", "support": 15}, {"x": 10, "y": 11, "z": 4, "name": "Wood_Ash_Trunk", "support": 15}, {"x": 10, "y": 12, "z": 4, "name": "Wood_Ash_Trunk", "support": 15}, {"x": 10, "y": 13, "z": 4, "name": "Wood_Ash_Trunk", "support": 15}, {"x": 10, "y": 14, "z": 4, "name": "Wood_Ash_Trunk_Full"}, {"x": 10, "y": 19, "z": 4, "name": "K2_Slot_Barrier"}, {"x": 10, "y": 39, "z": 4, "name": "Wood_Ash_Trunk_Full"}, {"x": 10, "y": -3, "z": 5, "name": "Soil_Dirt"}, {"x": 10, "y": -2, "z": 5, "name": "Soil_Dirt"}, {"x": 10, "y": -1, "z": 5, "name": "Soil_Dirt"}, {"x": 10, "y": 0, "z": 5, "name": "Soil_Grass"}, {"x": 10, "y": 9, "z": 5, "name": "Wood_Ash_Roots"}, {"x": 10, "y": 10, "z": 5, "name": "Wood_Ash_Trunk", "support": 15}, {"x": 10, "y": 11, "z": 5, "name": "Wood_Ash_Trunk", "support": 15}, {"x": 10, "y": 12, "z": 5, "name": "Wood_Ash_Trunk", "support": 15}, {"x": 10, "y": 13, "z": 5, "name": "Wood_Ash_Trunk", "support": 15}, {"x": 10, "y": 14, "z": 5, "name": "Wood_Ash_Trunk_Full"}, {"x": 10, "y": 15, "z": 5, "name": "K2_Slot_Chair", "rotation": 2}, {"x": 10, "y": 19, "z": 5, "name": "K2_Slot_Barrier"}, {"x": 10, "y": -3, "z": 6, "name": "Soil_Dirt"}, {"x": 10, "y": -2, "z": 6, "name": "Soil_Dirt"}, {"x": 10, "y": -1, "z": 6, "name": "Soil_Dirt"}, {"x": 10, "y": 0, "z": 6, "name": "Soil_Grass"}, {"x": 10, "y": 10, "z": 6, "name": "Wood_Ash_Trunk_Full"}, {"x": 10, "y": 11, "z": 6, "name": "Wood_Ash_Trunk", "support": 15}, {"x": 10, "y": 12, "z": 6, "name": "Wood_Ash_Trunk", "support": 15}, {"x": 10, "y": 13, "z": 6, "name": "Wood_Ash_Trunk", "support": 15},